{"type":"orderbook_delta","sid":1,"seq":751,"msg":{"market_ticker":"KXBTC15M-26MAY141815-15","market_id":"9b5194ce-fa5b-4fa6-a79f-003263374118","price_dollars":"0.1200","delta_fp":"-2.00","side":"no","ts":"2026-05-14T22:08:38.297702Z","ts_ms":1778796518297}}

{"type":"orderbook_delta","sid":1,"seq":752,"msg":{"market_ticker":"KXBTC15M-26MAY141815-15","market_id":"9b5194ce-fa5b-4fa6-a79f-003263374118","price_dollars":"0.6800","delta_fp":"-10.00","side":"yes","ts":"2026-05-14T22:08:38.308427Z","ts_ms":1778796518308}}

{"type":"orderbook_delta","sid":1,"seq":753,"msg":{"market_ticker":"KXBTC15M-26MAY141815-15","market_id":"9b5194ce-fa5b-4fa6-a79f-003263374118","price_dollars":"0.6900","delta_fp":"10.00","side":"yes","ts":"2026-05-14T22:08:38.308427Z","ts_ms":1778796518308}}

{"type":"orderbook_delta","sid":1,"seq":754,"msg":{"market_ticker":"KXBTC15M-26MAY141815-15","market_id":"9b5194ce-fa5b-4fa6-a79f-003263374118","price_dollars":"0.2900","delta_fp":"100.00","side":"no","ts":"2026-05-14T22:08:38.31407Z","ts_ms":1778796518314}}

{"type":"orderbook_delta","sid":1,"seq":755,"msg":{"market_ticker":"KXBTC15M-26MAY141815-15","market_id":"9b5194ce-fa5b-4fa6-a79f-003263374118","price_dollars":"0.3000","delta_fp":"3.00","side":"no","ts":"2026-05-14T22:08:38.316221Z","ts_ms":1778796518316}}

{"type":"orderbook_delta","sid":1,"seq":756,"msg":{"market_ticker":"KXBTC15M-26MAY141815-15","market_id":"9b5194ce-fa5b-4fa6-a79f-003263374118","price_dollars":"0.6200","delta_fp":"-1.00","side":"yes","ts":"2026-05-14T22:08:38.318945Z","ts_ms":1778796518318}}

{"type":"orderbook_delta","sid":1,"seq":757,"msg":{"market_ticker":"KXBTC15M-26MAY141815-15","market_id":"9b5194ce-fa5b-4fa6-a79f-003263374118","price_dollars":"0.3000","delta_fp":"-4.13","side":"no","ts":"2026-05-14T22:08:38.319857Z","ts_ms":1778796518319}}

{"type":"orderbook_delta","sid":1,"seq":758,"msg":{"market_ticker":"KXBTC15M-26MAY141815-15","market_id":"9b5194ce-fa5b-4fa6-a79f-003263374118","price_dollars":"0.6300","delta_fp":"-2.00","side":"yes","ts":"2026-05-14T22:08:38.325833Z","ts_ms":1778796518325}}

{"type":"orderbook_delta","sid":1,"seq":759,"msg":{"market_ticker":"KXBTC15M-26MAY141815-15","market_id":"9b5194ce-fa5b-4fa6-a79f-003263374118","price_dollars":"0.6400","delta_fp":"2.00","side":"yes","ts":"2026-05-14T22:08:38.325833Z","ts_ms":1778796518325}}

{"type":"orderbook_delta","sid":1,"seq":760,"msg":{"market_ticker":"KXBTC15M-26MAY141815-15","market_id":"9b5194ce-fa5b-4fa6-a79f-003263374118","price_dollars":"0.6800","delta_fp":"-36.00","side":"yes","ts":"2026-05-14T22:08:38.381289Z","ts_ms":1778796518381}}

{"type":"orderbook_delta","sid":1,"seq":761,"msg":{"market_ticker":"KXBTC15M-26MAY141815-15","market_id":"9b5194ce-fa5b-4fa6-a79f-003263374118","price_dollars":"0.6900","delta_fp":"17.00","side":"yes","ts":"2026-05-14T22:08:38.381289Z","ts_ms":1778796518381}}

{"type":"orderbook_delta","sid":1,"seq":762,"msg":{"market_ticker":"KXBTC15M-26MAY141815-15","market_id":"9b5194ce-fa5b-4fa6-a79f-003263374118","price_dollars":"0.5900","delta_fp":"7.00","side":"yes","ts":"2026-05-14T22:08:38.388131Z","ts_ms":1778796518388}}

{"type":"orderbook_delta","sid":1,"seq":763,"msg":{"market_ticker":"KXBTC15M-26MAY141815-15","market_id":"9b5194ce-fa5b-4fa6-a79f-003263374118","price_dollars":"0.6300","delta_fp":"1.00","side":"yes","ts":"2026-05-14T22:08:38.413243Z","ts_ms":1778796518413}}

{"type":"orderbook_delta","sid":1,"seq":764,"msg":{"market_ticker":"KXBTC15M-26MAY141815-15","market_id":"9b5194ce-fa5b-4fa6-a79f-003263374118","price_dollars":"0.0500","delta_fp":"2.00","side":"no","ts":"2026-05-14T22:08:38.433492Z","ts_ms":1778796518433}}

{"type":"orderbook_delta","sid":1,"seq":765,"msg":{"market_ticker":"KXBTC15M-26MAY141815-15","market_id":"9b5194ce-fa5b-4fa6-a79f-003263374118","price_dollars":"0.3000","delta_fp":"-3.00","side":"no","ts":"2026-05-14T22:08:38.442812Z","ts_ms":1778796518442}}

{"type":"orderbook_delta","sid":1,"seq":766,"msg":{"market_ticker":"KXBTC15M-26MAY141815-15","market_id":"9b5194ce-fa5b-4fa6-a79f-003263374118","price_dollars":"0.6100","delta_fp":"251.00","side":"yes","ts":"2026-05-14T22:08:38.47637Z","ts_ms":1778796518476}}

{"type":"orderbook_delta","sid":1,"seq":767,"msg":{"market_ticker":"KXBTC15M-26MAY141815-15","market_id":"9b5194ce-fa5b-4fa6-a79f-003263374118","price_dollars":"0.2100","delta_fp":"8.13","side":"no","ts":"2026-05-14T22:08:38.518624Z","ts_ms":1778796518518}}

{"type":"orderbook_delta","sid":1,"seq":768,"msg":{"market_ticker":"KXBTC15M-26MAY141815-15","market_id":"9b5194ce-fa5b-4fa6-a79f-003263374118","price_dollars":"0.0600","delta_fp":"-860.00","side":"yes","ts":"2026-05-14T22:08:38.520125Z","ts_ms":1778796518520}}

{"type":"orderbook_delta","sid":1,"seq":769,"msg":{"market_ticker":"KXBTC15M-26MAY141815-15","market_id":"9b5194ce-fa5b-4fa6-a79f-003263374118","price_dollars":"0.0700","delta_fp":"811.00","side":"yes","ts":"2026-05-14T22:08:38.520125Z","ts_ms":1778796518520}}

{"type":"orderbook_delta","sid":1,"seq":770,"msg":{"market_ticker":"KXBTC15M-26MAY141815-15","market_id":"9b5194ce-fa5b-4fa6-a79f-003263374118","price_dollars":"0.0400","delta_fp":"-774.00","side":"yes","ts":"2026-05-14T22:08:38.523763Z","ts_ms":1778796518523}}

{"type":"orderbook_delta","sid":1,"seq":771,"msg":{"market_ticker":"KXBTC15M-26MAY141815-15","market_id":"9b5194ce-fa5b-4fa6-a79f-003263374118","price_dollars":"0.0500","delta_fp":"855.00","side":"yes","ts":"2026-05-14T22:08:38.523763Z","ts_ms":1778796518523}}

{"type":"orderbook_delta","sid":1,"seq":772,"msg":{"market_ticker":"KXBTC15M-26MAY141815-15","market_id":"9b5194ce-fa5b-4fa6-a79f-003263374118","price_dollars":"0.0800","delta_fp":"-847.00","side":"yes","ts":"2026-05-14T22:08:38.60126Z","ts_ms":1778796518601}}

{"type":"orderbook_delta","sid":1,"seq":773,"msg":{"market_ticker":"KXBTC15M-26MAY141815-15","market_id":"9b5194ce-fa5b-4fa6-a79f-003263374118","price_dollars":"0.0900","delta_fp":"849.00","side":"yes","ts":"2026-05-14T22:08:38.60126Z","ts_ms":1778796518601}}

{"type":"orderbook_delta","sid":1,"seq":774,"msg":{"market_ticker":"KXBTC15M-26MAY141815-15","market_id":"9b5194ce-fa5b-4fa6-a79f-003263374118","price_dollars":"0.3000","delta_fp":"6.00","side":"no","ts":"2026-05-14T22:08:38.697337Z","ts_ms":1778796518697}}

{"type":"orderbook_delta","sid":1,"seq":775,"msg":{"market_ticker":"KXBTC15M-26MAY141815-15","market_id":"9b5194ce-fa5b-4fa6-a79f-003263374118","price_dollars":"0.2800","delta_fp":"81.00","side":"no","ts":"2026-05-14T22:08:38.729545Z","ts_ms":1778796518729}}

{"type":"orderbook_delta","sid":1,"seq":776,"msg":{"market_ticker":"KXBTC15M-26MAY141815-15","market_id":"9b5194ce-fa5b-4fa6-a79f-003263374118","price_dollars":"0.5800","delta_fp":"1.00","side":"yes","ts":"2026-05-14T22:08:38.779637Z","ts_ms":1778796518779}}

{"type":"orderbook_delta","sid":1,"seq":777,"msg":{"market_ticker":"KXBTC15M-26MAY141815-15","market_id":"9b5194ce-fa5b-4fa6-a79f-003263374118","price_dollars":"0.5600","delta_fp":"1.00","side":"yes","ts":"2026-05-14T22:08:38.780843Z","ts_ms":1778796518780}}

{"type":"orderbook_delta","sid":1,"seq":778,"msg":{"market_ticker":"KXBTC15M-26MAY141815-15","market_id":"9b5194ce-fa5b-4fa6-a79f-003263374118","price_dollars":"0.3000","delta_fp":"1.00","side":"no","ts":"2026-05-14T22:08:38.78293Z","ts_ms":1778796518782}}

{"type":"orderbook_delta","sid":1,"seq":779,"msg":{"market_ticker":"KXBTC15M-26MAY141815-15","market_id":"9b5194ce-fa5b-4fa6-a79f-003263374118","price_dollars":"0.6400","delta_fp":"-2.00","side":"yes","ts":"2026-05-14T22:08:38.804043Z","ts_ms":1778796518804}}

{"type":"orderbook_delta","sid":1,"seq":780,"msg":{"market_ticker":"KXBTC15M-26MAY141815-15","market_id":"9b5194ce-fa5b-4fa6-a79f-003263374118","price_dollars":"0.6300","delta_fp":"2.00","side":"yes","ts":"2026-05-14T22:08:38.804043Z","ts_ms":1778796518804}}

{"type":"orderbook_delta","sid":1,"seq":781,"msg":{"market_ticker":"KXBTC15M-26MAY141815-15","market_id":"9b5194ce-fa5b-4fa6-a79f-003263374118","price_dollars":"0.1100","delta_fp":"-2.00","side":"no","ts":"2026-05-14T22:08:38.805352Z","ts_ms":1778796518805}}

{"type":"orderbook_delta","sid":1,"seq":782,"msg":{"market_ticker":"KXBTC15M-26MAY141815-15","market_id":"9b5194ce-fa5b-4fa6-a79f-003263374118","price_dollars":"0.6100","delta_fp":"2.00","side":"yes","ts":"2026-05-14T22:08:38.814846Z","ts_ms":1778796518814}}

{"type":"orderbook_delta","sid":1,"seq":783,"msg":{"market_ticker":"KXBTC15M-26MAY141815-15","market_id":"9b5194ce-fa5b-4fa6-a79f-003263374118","price_dollars":"0.2700","delta_fp":"-2.00","side":"no","ts":"2026-05-14T22:08:38.826897Z","ts_ms":1778796518826}}

{"type":"orderbook_delta","sid":1,"seq":784,"msg":{"market_ticker":"KXBTC15M-26MAY141815-15","market_id":"9b5194ce-fa5b-4fa6-a79f-003263374118","price_dollars":"0.2800","delta_fp":"2.00","side":"no","ts":"2026-05-14T22:08:38.826897Z","ts_ms":1778796518826}}

{"type":"orderbook_delta","sid":1,"seq":785,"msg":{"market_ticker":"KXBTC15M-26MAY141815-15","market_id":"9b5194ce-fa5b-4fa6-a79f-003263374118","price_dollars":"0.0400","delta_fp":"2.00","side":"no","ts":"2026-05-14T22:08:38.85534Z","ts_ms":1778796518855}}

{"type":"orderbook_delta","sid":1,"seq":786,"msg":{"market_ticker":"KXBTC15M-26MAY141815-15","market_id":"9b5194ce-fa5b-4fa6-a79f-003263374118","price_dollars":"0.6100","delta_fp":"-2.00","side":"yes","ts":"2026-05-14T22:08:38.863833Z","ts_ms":1778796518863}}

{"type":"orderbook_delta","sid":1,"seq":787,"msg":{"market_ticker":"KXBTC15M-26MAY141815-15","market_id":"9b5194ce-fa5b-4fa6-a79f-003263374118","price_dollars":"0.6900","delta_fp":"-10.00","side":"yes","ts":"2026-05-14T22:08:38.869556Z","ts_ms":1778796518869}}

{"type":"orderbook_delta","sid":1,"seq":788,"msg":{"market_ticker":"KXBTC15M-26MAY141815-15","market_id":"9b5194ce-fa5b-4fa6-a79f-003263374118","price_dollars":"0.6900","delta_fp":"-17.00","side":"yes","ts":"2026-05-14T22:08:38.869556Z","ts_ms":1778796518869}}

{"type":"orderbook_delta","sid":1,"seq":789,"msg":{"market_ticker":"KXBTC15M-26MAY141815-15","market_id":"9b5194ce-fa5b-4fa6-a79f-003263374118","price_dollars":"0.6800","delta_fp":"-2.81","side":"yes","ts":"2026-05-14T22:08:38.869556Z","ts_ms":1778796518869}}

{"type":"orderbook_delta","sid":1,"seq":790,"msg":{"market_ticker":"KXBTC15M-26MAY141815-15","market_id":"9b5194ce-fa5b-4fa6-a79f-003263374118","price_dollars":"0.2800","delta_fp":"-14.00","side":"no","ts":"2026-05-14T22:08:38.904756Z","ts_ms":1778796518904}}

{"type":"orderbook_delta","sid":1,"seq":791,"msg":{"market_ticker":"KXBTC15M-26MAY141815-15","market_id":"9b5194ce-fa5b-4fa6-a79f-003263374118","price_dollars":"0.3000","delta_fp":"10.00","side":"no","ts":"2026-05-14T22:08:38.923365Z","ts_ms":1778796518923}}

{"type":"orderbook_delta","sid":1,"seq":792,"msg":{"market_ticker":"KXBTC15M-26MAY141815-15","market_id":"9b5194ce-fa5b-4fa6-a79f-003263374118","price_dollars":"0.6900","delta_fp":"2.00","side":"yes","ts":"2026-05-14T22:08:38.926323Z","ts_ms":1778796518926}}

{"type":"orderbook_delta","sid":1,"seq":793,"msg":{"market_ticker":"KXBTC15M-26MAY141815-15","market_id":"9b5194ce-fa5b-4fa6-a79f-003263374118","price_dollars":"0.3000","delta_fp":"-1.00","side":"no","ts":"2026-05-14T22:08:38.943462Z","ts_ms":1778796518943}}

{"type":"orderbook_delta","sid":1,"seq":794,"msg":{"market_ticker":"KXBTC15M-26MAY141815-15","market_id":"9b5194ce-fa5b-4fa6-a79f-003263374118","price_dollars":"0.5600","delta_fp":"-1.00","side":"yes","ts":"2026-05-14T22:08:38.944314Z","ts_ms":1778796518944}}

{"type":"orderbook_delta","sid":1,"seq":795,"msg":{"market_ticker":"KXBTC15M-26MAY141815-15","market_id":"9b5194ce-fa5b-4fa6-a79f-003263374118","price_dollars":"0.3000","delta_fp":"-6.00","side":"no","ts":"2026-05-14T22:08:38.976025Z","ts_ms":1778796518976}}

{"type":"orderbook_delta","sid":1,"seq":796,"msg":{"market_ticker":"KXBTC15M-26MAY141815-15","market_id":"9b5194ce-fa5b-4fa6-a79f-003263374118","price_dollars":"0.6900","delta_fp":"1.00","side":"yes","ts":"2026-05-14T22:08:38.98539Z","ts_ms":1778796518985}}

{"type":"orderbook_delta","sid":1,"seq":797,"msg":{"market_ticker":"KXBTC15M-26MAY141815-15","market_id":"9b5194ce-fa5b-4fa6-a79f-003263374118","price_dollars":"0.3000","delta_fp":"-20.51","side":"no","ts":"2026-05-14T22:08:39.008097Z","ts_ms":1778796519008}}

{"type":"orderbook_delta","sid":1,"seq":798,"msg":{"market_ticker":"KXBTC15M-26MAY141815-15","market_id":"9b5194ce-fa5b-4fa6-a79f-003263374118","price_dollars":"0.2700","delta_fp":"-10.00","side":"no","ts":"2026-05-14T22:08:39.016086Z","ts_ms":1778796519016}}

{"type":"orderbook_delta","sid":1,"seq":799,"msg":{"market_ticker":"KXBTC15M-26MAY141815-15","market_id":"9b5194ce-fa5b-4fa6-a79f-003263374118","price_dollars":"0.2900","delta_fp":"10.00","side":"no","ts":"2026-05-14T22:08:39.016086Z","ts_ms":1778796519016}}

{"type":"orderbook_delta","sid":1,"seq":800,"msg":{"market_ticker":"KXBTC15M-26MAY141815-15","market_id":"9b5194ce-fa5b-4fa6-a79f-003263374118","price_dollars":"0.3000","delta_fp":"-10.00","side":"no","ts":"2026-05-14T22:08:39.02706Z","ts_ms":1778796519027}}

{"type":"orderbook_delta","sid":1,"seq":801,"msg":{"market_ticker":"KXBTC15M-26MAY141815-15","market_id":"9b5194ce-fa5b-4fa6-a79f-003263374118","price_dollars":"0.2900","delta_fp":"21.00","side":"no","ts":"2026-05-14T22:08:39.02706Z","ts_ms":1778796519027}}

{"type":"orderbook_delta","sid":1,"seq":802,"msg":{"market_ticker":"KXBTC15M-26MAY141815-15","market_id":"9b5194ce-fa5b-4fa6-a79f-003263374118","price_dollars":"0.6700","delta_fp":"10.00","side":"yes","ts":"2026-05-14T22:08:39.037542Z","ts_ms":1778796519037}}

{"type":"orderbook_delta","sid":1,"seq":803,"msg":{"market_ticker":"KXBTC15M-26MAY141815-15","market_id":"9b5194ce-fa5b-4fa6-a79f-003263374118","price_dollars":"0.2900","delta_fp":"-21.00","side":"no","ts":"2026-05-14T22:08:39.076673Z","ts_ms":1778796519076}}

{"type":"orderbook_delta","sid":1,"seq":804,"msg":{"market_ticker":"KXBTC15M-26MAY141815-15","market_id":"9b5194ce-fa5b-4fa6-a79f-003263374118","price_dollars":"0.3000","delta_fp":"10.00","side":"no","ts":"2026-05-14T22:08:39.076673Z","ts_ms":1778796519076}}

{"type":"orderbook_delta","sid":1,"seq":805,"msg":{"market_ticker":"KXBTC15M-26MAY141815-15","market_id":"9b5194ce-fa5b-4fa6-a79f-003263374118","price_dollars":"0.6300","delta_fp":"-2.00","side":"yes","ts":"2026-05-14T22:08:39.121054Z","ts_ms":1778796519121}}

{"type":"orderbook_delta","sid":1,"seq":806,"msg":{"market_ticker":"KXBTC15M-26MAY141815-15","market_id":"9b5194ce-fa5b-4fa6-a79f-003263374118","price_dollars":"0.6400","delta_fp":"2.00","side":"yes","ts":"2026-05-14T22:08:39.121054Z","ts_ms":1778796519121}}

{"type":"orderbook_delta","sid":1,"seq":807,"msg":{"market_ticker":"KXBTC15M-26MAY141815-15","market_id":"9b5194ce-fa5b-4fa6-a79f-003263374118","price_dollars":"0.2800","delta_fp":"-2.00","side":"no","ts":"2026-05-14T22:08:39.122885Z","ts_ms":1778796519122}}

{"type":"orderbook_delta","sid":1,"seq":808,"msg":{"market_ticker":"KXBTC15M-26MAY141815-15","market_id":"9b5194ce-fa5b-4fa6-a79f-003263374118","price_dollars":"0.2700","delta_fp":"2.00","side":"no","ts":"2026-05-14T22:08:39.122885Z","ts_ms":1778796519122}}

{"type":"orderbook_delta","sid":1,"seq":809,"msg":{"market_ticker":"KXBTC15M-26MAY141815-15","market_id":"9b5194ce-fa5b-4fa6-a79f-003263374118","price_dollars":"0.3000","delta_fp":"-10.00","side":"no","ts":"2026-05-14T22:08:39.155936Z","ts_ms":1778796519155}}

{"type":"orderbook_delta","sid":1,"seq":810,"msg":{"market_ticker":"KXBTC15M-26MAY141815-15","market_id":"9b5194ce-fa5b-4fa6-a79f-003263374118","price_dollars":"0.2900","delta_fp":"21.00","side":"no","ts":"2026-05-14T22:08:39.155936Z","ts_ms":1778796519155}}

{"type":"orderbook_delta","sid":1,"seq":811,"msg":{"market_ticker":"KXBTC15M-26MAY141815-15","market_id":"9b5194ce-fa5b-4fa6-a79f-003263374118","price_dollars":"0.2900","delta_fp":"-21.00","side":"no","ts":"2026-05-14T22:08:39.180691Z","ts_ms":1778796519180}}

{"type":"orderbook_delta","sid":1,"seq":812,"msg":{"market_ticker":"KXBTC15M-26MAY141815-15","market_id":"9b5194ce-fa5b-4fa6-a79f-003263374118","price_dollars":"0.3000","delta_fp":"10.00","side":"no","ts":"2026-05-14T22:08:39.180691Z","ts_ms":1778796519180}}

{"type":"orderbook_delta","sid":1,"seq":813,"msg":{"market_ticker":"KXBTC15M-26MAY141815-15","market_id":"9b5194ce-fa5b-4fa6-a79f-003263374118","price_dollars":"0.6700","delta_fp":"-10.00","side":"yes","ts":"2026-05-14T22:08:39.223961Z","ts_ms":1778796519223}}

{"type":"orderbook_delta","sid":1,"seq":814,"msg":{"market_ticker":"KXBTC15M-26MAY141815-15","market_id":"9b5194ce-fa5b-4fa6-a79f-003263374118","price_dollars":"0.6800","delta_fp":"10.00","side":"yes","ts":"2026-05-14T22:08:39.223961Z","ts_ms":1778796519223}}

{"type":"orderbook_delta","sid":1,"seq":815,"msg":{"market_ticker":"KXBTC15M-26MAY141815-15","market_id":"9b5194ce-fa5b-4fa6-a79f-003263374118","price_dollars":"0.6900","delta_fp":"-1.00","side":"yes","ts":"2026-05-14T22:08:39.253597Z","ts_ms":1778796519253}}

{"type":"orderbook_delta","sid":1,"seq":816,"msg":{"market_ticker":"KXBTC15M-26MAY141815-15","market_id":"9b5194ce-fa5b-4fa6-a79f-003263374118","price_dollars":"0.3000","delta_fp":"-0.44","side":"no","ts":"2026-05-14T22:08:39.303356Z","ts_ms":1778796519303}}

{"type":"orderbook_delta","sid":1,"seq":817,"msg":{"market_ticker":"KXBTC15M-26MAY141815-15","market_id":"9b5194ce-fa5b-4fa6-a79f-003263374118","price_dollars":"0.1000","delta_fp":"-2.00","side":"no","ts":"2026-05-14T22:08:39.327759Z","ts_ms":1778796519327}}

{"type":"orderbook_delta","sid":1,"seq":818,"msg":{"market_ticker":"KXBTC15M-26MAY141815-15","market_id":"9b5194ce-fa5b-4fa6-a79f-003263374118","price_dollars":"0.2600","delta_fp":"-150.00","side":"no","ts":"2026-05-14T22:08:39.365107Z","ts_ms":1778796519365}}

{"type":"orderbook_delta","sid":1,"seq":819,"msg":{"market_ticker":"KXBTC15M-26MAY141815-15","market_id":"9b5194ce-fa5b-4fa6-a79f-003263374118","price_dollars":"0.2700","delta_fp":"150.00","side":"no","ts":"2026-05-14T22:08:39.365107Z","ts_ms":1778796519365}}

{"type":"orderbook_delta","sid":1,"seq":820,"msg":{"market_ticker":"KXBTC15M-26MAY141815-15","market_id":"9b5194ce-fa5b-4fa6-a79f-003263374118","price_dollars":"0.6100","delta_fp":"-150.00","side":"yes","ts":"2026-05-14T22:08:39.388433Z","ts_ms":1778796519388}}

{"type":"orderbook_delta","sid":1,"seq":821,"msg":{"market_ticker":"KXBTC15M-26MAY141815-15","market_id":"9b5194ce-fa5b-4fa6-a79f-003263374118","price_dollars":"0.6000","delta_fp":"150.00","side":"yes","ts":"2026-05-14T22:08:39.388433Z","ts_ms":1778796519388}}

{"type":"orderbook_delta","sid":1,"seq":822,"msg":{"market_ticker":"KXBTC15M-26MAY141815-15","market_id":"9b5194ce-fa5b-4fa6-a79f-003263374118","price_dollars":"0.6800","delta_fp":"12.00","side":"yes","ts":"2026-05-14T22:08:39.418872Z","ts_ms":1778796519418}}

{"type":"orderbook_delta","sid":1,"seq":823,"msg":{"market_ticker":"KXBTC15M-26MAY141815-15","market_id":"9b5194ce-fa5b-4fa6-a79f-003263374118","price_dollars":"0.5900","delta_fp":"1.00","side":"yes","ts":"2026-05-14T22:08:39.42334Z","ts_ms":1778796519423}}

{"type":"orderbook_delta","sid":1,"seq":824,"msg":{"market_ticker":"KXBTC15M-26MAY141815-15","market_id":"9b5194ce-fa5b-4fa6-a79f-003263374118","price_dollars":"0.3000","delta_fp":"1.00","side":"no","ts":"2026-05-14T22:08:39.423947Z","ts_ms":1778796519423}}

{"type":"orderbook_delta","sid":1,"seq":825,"msg":{"market_ticker":"KXBTC15M-26MAY141815-15","market_id":"9b5194ce-fa5b-4fa6-a79f-003263374118","price_dollars":"0.2800","delta_fp":"1.00","side":"no","ts":"2026-05-14T22:08:39.424361Z","ts_ms":1778796519424}}

{"type":"orderbook_delta","sid":1,"seq":826,"msg":{"market_ticker":"KXBTC15M-26MAY141815-15","market_id":"9b5194ce-fa5b-4fa6-a79f-003263374118","price_dollars":"0.0300","delta_fp":"2.00","side":"no","ts":"2026-05-14T22:08:39.479814Z","ts_ms":1778796519479}}

{"type":"orderbook_delta","sid":1,"seq":827,"msg":{"market_ticker":"KXBTC15M-26MAY141815-15","market_id":"9b5194ce-fa5b-4fa6-a79f-003263374118","price_dollars":"0.5800","delta_fp":"-15.00","side":"yes","ts":"2026-05-14T22:08:39.553857Z","ts_ms":1778796519553}}

{"type":"orderbook_delta","sid":1,"seq":828,"msg":{"market_ticker":"KXBTC15M-26MAY141815-15","market_id":"9b5194ce-fa5b-4fa6-a79f-003263374118","price_dollars":"0.5900","delta_fp":"15.00","side":"yes","ts":"2026-05-14T22:08:39.553857Z","ts_ms":1778796519553}}

{"type":"orderbook_delta","sid":1,"seq":829,"msg":{"market_ticker":"KXBTC15M-26MAY141815-15","market_id":"9b5194ce-fa5b-4fa6-a79f-003263374118","price_dollars":"0.2900","delta_fp":"-10.00","side":"no","ts":"2026-05-14T22:08:39.630417Z","ts_ms":1778796519630}}

{"type":"orderbook_delta","sid":1,"seq":830,"msg":{"market_ticker":"KXBTC15M-26MAY141815-15","market_id":"9b5194ce-fa5b-4fa6-a79f-003263374118","price_dollars":"0.2800","delta_fp":"10.00","side":"no","ts":"2026-05-14T22:08:39.630417Z","ts_ms":1778796519630}}

{"type":"orderbook_delta","sid":1,"seq":831,"msg":{"market_ticker":"KXBTC15M-26MAY141815-15","market_id":"9b5194ce-fa5b-4fa6-a79f-003263374118","price_dollars":"0.3000","delta_fp":"-10.00","side":"no","ts":"2026-05-14T22:08:39.637813Z","ts_ms":1778796519637}}

{"type":"orderbook_delta","sid":1,"seq":832,"msg":{"market_ticker":"KXBTC15M-26MAY141815-15","market_id":"9b5194ce-fa5b-4fa6-a79f-003263374118","price_dollars":"0.2900","delta_fp":"19.00","side":"no","ts":"2026-05-14T22:08:39.637813Z","ts_ms":1778796519637}}

{"type":"orderbook_delta","sid":1,"seq":833,"msg":{"market_ticker":"KXBTC15M-26MAY141815-15","market_id":"9b5194ce-fa5b-4fa6-a79f-003263374118","price_dollars":"0.0900","delta_fp":"-2.00","side":"no","ts":"2026-05-14T22:08:39.63961Z","ts_ms":1778796519639}}

{"type":"orderbook_delta","sid":1,"seq":834,"msg":{"market_ticker":"KXBTC15M-26MAY141815-15","market_id":"9b5194ce-fa5b-4fa6-a79f-003263374118","price_dollars":"0.2800","delta_fp":"-1.00","side":"no","ts":"2026-05-14T22:08:39.650502Z","ts_ms":1778796519650}}

{"type":"orderbook_delta","sid":1,"seq":835,"msg":{"market_ticker":"KXBTC15M-26MAY141815-15","market_id":"9b5194ce-fa5b-4fa6-a79f-003263374118","price_dollars":"0.3000","delta_fp":"-1.00","side":"no","ts":"2026-05-14T22:08:39.651565Z","ts_ms":1778796519651}}

{"type":"orderbook_delta","sid":1,"seq":836,"msg":{"market_ticker":"KXBTC15M-26MAY141815-15","market_id":"9b5194ce-fa5b-4fa6-a79f-003263374118","price_dollars":"0.5900","delta_fp":"-1.00","side":"yes","ts":"2026-05-14T22:08:39.652515Z","ts_ms":1778796519652}}

{"type":"orderbook_delta","sid":1,"seq":837,"msg":{"market_ticker":"KXBTC15M-26MAY141815-15","market_id":"9b5194ce-fa5b-4fa6-a79f-003263374118","price_dollars":"0.5800","delta_fp":"-1.00","side":"yes","ts":"2026-05-14T22:08:39.653481Z","ts_ms":1778796519653}}

{"type":"orderbook_delta","sid":1,"seq":838,"msg":{"market_ticker":"KXBTC15M-26MAY141815-15","market_id":"9b5194ce-fa5b-4fa6-a79f-003263374118","price_dollars":"0.6700","delta_fp":"2.00","side":"yes","ts":"2026-05-14T22:08:39.673068Z","ts_ms":1778796519673}}

{"type":"orderbook_delta","sid":1,"seq":839,"msg":{"market_ticker":"KXBTC15M-26MAY141815-15","market_id":"9b5194ce-fa5b-4fa6-a79f-003263374118","price_dollars":"0.6900","delta_fp":"-1.00","side":"yes","ts":"2026-05-14T22:08:39.713639Z","ts_ms":1778796519713}}

{"type":"orderbook_delta","sid":1,"seq":840,"msg":{"market_ticker":"KXBTC15M-26MAY141815-15","market_id":"9b5194ce-fa5b-4fa6-a79f-003263374118","price_dollars":"0.6900","delta_fp":"-1.00","side":"yes","ts":"2026-05-14T22:08:39.713639Z","ts_ms":1778796519713}}

{"type":"orderbook_delta","sid":1,"seq":841,"msg":{"market_ticker":"KXBTC15M-26MAY141815-15","market_id":"9b5194ce-fa5b-4fa6-a79f-003263374118","price_dollars":"0.6800","delta_fp":"-8.63","side":"yes","ts":"2026-05-14T22:08:39.713639Z","ts_ms":1778796519713}}

{"type":"orderbook_delta","sid":1,"seq":842,"msg":{"market_ticker":"KXBTC15M-26MAY141815-15","market_id":"9b5194ce-fa5b-4fa6-a79f-003263374118","price_dollars":"0.6100","delta_fp":"2.00","side":"yes","ts":"2026-05-14T22:08:39.724294Z","ts_ms":1778796519724}}

{"type":"orderbook_delta","sid":1,"seq":843,"msg":{"market_ticker":"KXBTC15M-26MAY141815-15","market_id":"9b5194ce-fa5b-4fa6-a79f-003263374118","price_dollars":"0.3000","delta_fp":"13.00","side":"no","ts":"2026-05-14T22:08:39.75374Z","ts_ms":1778796519753}}

{"type":"orderbook_delta","sid":1,"seq":844,"msg":{"market_ticker":"KXBTC15M-26MAY141815-15","market_id":"9b5194ce-fa5b-4fa6-a79f-003263374118","price_dollars":"0.6100","delta_fp":"-2.00","side":"yes","ts":"2026-05-14T22:08:39.861947Z","ts_ms":1778796519861}}

{"type":"orderbook_delta","sid":1,"seq":845,"msg":{"market_ticker":"KXBTC15M-26MAY141815-15","market_id":"9b5194ce-fa5b-4fa6-a79f-003263374118","price_dollars":"0.2900","delta_fp":"-19.00","side":"no","ts":"2026-05-14T22:08:39.917068Z","ts_ms":1778796519917}}

{"type":"orderbook_delta","sid":1,"seq":846,"msg":{"market_ticker":"KXBTC15M-26MAY141815-15","market_id":"9b5194ce-fa5b-4fa6-a79f-003263374118","price_dollars":"0.3000","delta_fp":"10.00","side":"no","ts":"2026-05-14T22:08:39.917068Z","ts_ms":1778796519917}}

{"type":"orderbook_delta","sid":1,"seq":847,"msg":{"market_ticker":"KXBTC15M-26MAY141815-15","market_id":"9b5194ce-fa5b-4fa6-a79f-003263374118","price_dollars":"0.6100","delta_fp":"2.00","side":"yes","ts":"2026-05-14T22:08:39.979195Z","ts_ms":1778796519979}}

{"type":"orderbook_delta","sid":1,"seq":848,"msg":{"market_ticker":"KXBTC15M-26MAY141815-15","market_id":"9b5194ce-fa5b-4fa6-a79f-003263374118","price_dollars":"0.6200","delta_fp":"-75.00","side":"yes","ts":"2026-05-14T22:08:40.002357Z","ts_ms":1778796520002}}

{"type":"orderbook_delta","sid":1,"seq":849,"msg":{"market_ticker":"KXBTC15M-26MAY141815-15","market_id":"9b5194ce-fa5b-4fa6-a79f-003263374118","price_dollars":"0.6800","delta_fp":"75.00","side":"yes","ts":"2026-05-14T22:08:40.002357Z","ts_ms":1778796520002}}

{"type":"orderbook_delta","sid":1,"seq":850,"msg":{"market_ticker":"KXBTC15M-26MAY141815-15","market_id":"9b5194ce-fa5b-4fa6-a79f-003263374118","price_dollars":"0.3000","delta_fp":"-54.05","side":"no","ts":"2026-05-14T22:08:40.003565Z","ts_ms":1778796520003}}

{"type":"orderbook_delta","sid":1,"seq":851,"msg":{"market_ticker":"KXBTC15M-26MAY141815-15","market_id":"9b5194ce-fa5b-4fa6-a79f-003263374118","price_dollars":"0.2400","delta_fp":"75.00","side":"no","ts":"2026-05-14T22:08:40.003565Z","ts_ms":1778796520003}}

{"type":"orderbook_delta","sid":1,"seq":852,"msg":{"market_ticker":"KXBTC15M-26MAY141815-15","market_id":"9b5194ce-fa5b-4fa6-a79f-003263374118","price_dollars":"0.6100","delta_fp":"-2.00","side":"yes","ts":"2026-05-14T22:08:40.019107Z","ts_ms":1778796520019}}

{"type":"orderbook_delta","sid":1,"seq":853,"msg":{"market_ticker":"KXBTC15M-26MAY141815-15","market_id":"9b5194ce-fa5b-4fa6-a79f-003263374118","price_dollars":"0.3000","delta_fp":"-6.94","side":"no","ts":"2026-05-14T22:08:40.026187Z","ts_ms":1778796520026}}

{"type":"orderbook_delta","sid":1,"seq":854,"msg":{"market_ticker":"KXBTC15M-26MAY141815-15","market_id":"9b5194ce-fa5b-4fa6-a79f-003263374118","price_dollars":"0.3000","delta_fp":"-1.00","side":"no","ts":"2026-05-14T22:08:40.042643Z","ts_ms":1778796520042}}

{"type":"orderbook_delta","sid":1,"seq":855,"msg":{"market_ticker":"KXBTC15M-26MAY141815-15","market_id":"9b5194ce-fa5b-4fa6-a79f-003263374118","price_dollars":"0.3000","delta_fp":"-10.00","side":"no","ts":"2026-05-14T22:08:40.055926Z","ts_ms":1778796520055}}

{"type":"orderbook_delta","sid":1,"seq":856,"msg":{"market_ticker":"KXBTC15M-26MAY141815-15","market_id":"9b5194ce-fa5b-4fa6-a79f-003263374118","price_dollars":"0.2900","delta_fp":"19.00","side":"no","ts":"2026-05-14T22:08:40.055926Z","ts_ms":1778796520055}}

{"type":"orderbook_delta","sid":1,"seq":857,"msg":{"market_ticker":"KXBTC15M-26MAY141815-15","market_id":"9b5194ce-fa5b-4fa6-a79f-003263374118","price_dollars":"0.6800","delta_fp":"-10.00","side":"yes","ts":"2026-05-14T22:08:40.057681Z","ts_ms":1778796520057}}

{"type":"orderbook_delta","sid":1,"seq":858,"msg":{"market_ticker":"KXBTC15M-26MAY141815-15","market_id":"9b5194ce-fa5b-4fa6-a79f-003263374118","price_dollars":"0.6900","delta_fp":"10.00","side":"yes","ts":"2026-05-14T22:08:40.057681Z","ts_ms":1778796520057}}

{"type":"orderbook_delta","sid":1,"seq":859,"msg":{"market_ticker":"KXBTC15M-26MAY141815-15","market_id":"9b5194ce-fa5b-4fa6-a79f-003263374118","price_dollars":"0.2700","delta_fp":"-400.00","side":"no","ts":"2026-05-14T22:08:40.088313Z","ts_ms":1778796520088}}

{"type":"orderbook_delta","sid":1,"seq":860,"msg":{"market_ticker":"KXBTC15M-26MAY141815-15","market_id":"9b5194ce-fa5b-4fa6-a79f-003263374118","price_dollars":"0.2600","delta_fp":"400.00","side":"no","ts":"2026-05-14T22:08:40.088313Z","ts_ms":1778796520088}}

{"type":"orderbook_delta","sid":1,"seq":861,"msg":{"market_ticker":"KXBTC15M-26MAY141815-15","market_id":"9b5194ce-fa5b-4fa6-a79f-003263374118","price_dollars":"0.6900","delta_fp":"100.00","side":"yes","ts":"2026-05-14T22:08:40.109118Z","ts_ms":1778796520109}}

{"type":"orderbook_delta","sid":1,"seq":862,"msg":{"market_ticker":"KXBTC15M-26MAY141815-15","market_id":"9b5194ce-fa5b-4fa6-a79f-003263374118","price_dollars":"0.6900","delta_fp":"-10.00","side":"yes","ts":"2026-05-14T22:08:40.11201Z","ts_ms":1778796520112}}

{"type":"orderbook_delta","sid":1,"seq":863,"msg":{"market_ticker":"KXBTC15M-26MAY141815-15","market_id":"9b5194ce-fa5b-4fa6-a79f-003263374118","price_dollars":"0.6800","delta_fp":"10.00","side":"yes","ts":"2026-05-14T22:08:40.11201Z","ts_ms":1778796520112}}

{"type":"orderbook_delta","sid":1,"seq":864,"msg":{"market_ticker":"KXBTC15M-26MAY141815-15","market_id":"9b5194ce-fa5b-4fa6-a79f-003263374118","price_dollars":"0.0200","delta_fp":"2.00","side":"no","ts":"2026-05-14T22:08:40.112823Z","ts_ms":1778796520112}}

{"type":"orderbook_delta","sid":1,"seq":865,"msg":{"market_ticker":"KXBTC15M-26MAY141815-15","market_id":"9b5194ce-fa5b-4fa6-a79f-003263374118","price_dollars":"0.3000","delta_fp":"-5.06","side":"no","ts":"2026-05-14T22:08:40.134748Z","ts_ms":1778796520134}}

{"type":"orderbook_delta","sid":1,"seq":866,"msg":{"market_ticker":"KXBTC15M-26MAY141815-15","market_id":"9b5194ce-fa5b-4fa6-a79f-003263374118","price_dollars":"0.6100","delta_fp":"2.00","side":"yes","ts":"2026-05-14T22:08:40.146653Z","ts_ms":1778796520146}}

{"type":"orderbook_delta","sid":1,"seq":867,"msg":{"market_ticker":"KXBTC15M-26MAY141815-15","market_id":"9b5194ce-fa5b-4fa6-a79f-003263374118","price_dollars":"0.0800","delta_fp":"-2.00","side":"no","ts":"2026-05-14T22:08:40.152405Z","ts_ms":1778796520152}}

{"type":"orderbook_delta","sid":1,"seq":868,"msg":{"market_ticker":"KXBTC15M-26MAY141815-15","market_id":"9b5194ce-fa5b-4fa6-a79f-003263374118","price_dollars":"0.2900","delta_fp":"-24.67","side":"no","ts":"2026-05-14T22:08:40.155545Z","ts_ms":1778796520155}}

{"type":"orderbook_delta","sid":1,"seq":869,"msg":{"market_ticker":"KXBTC15M-26MAY141815-15","market_id":"9b5194ce-fa5b-4fa6-a79f-003263374118","price_dollars":"0.2900","delta_fp":"-19.00","side":"no","ts":"2026-05-14T22:08:40.160378Z","ts_ms":1778796520160}}

{"type":"orderbook_delta","sid":1,"seq":870,"msg":{"market_ticker":"KXBTC15M-26MAY141815-15","market_id":"9b5194ce-fa5b-4fa6-a79f-003263374118","price_dollars":"0.3000","delta_fp":"10.00","side":"no","ts":"2026-05-14T22:08:40.160378Z","ts_ms":1778796520160}}

{"type":"orderbook_delta","sid":1,"seq":871,"msg":{"market_ticker":"KXBTC15M-26MAY141815-15","market_id":"9b5194ce-fa5b-4fa6-a79f-003263374118","price_dollars":"0.3000","delta_fp":"-10.00","side":"no","ts":"2026-05-14T22:08:40.161955Z","ts_ms":1778796520161}}

{"type":"orderbook_delta","sid":1,"seq":872,"msg":{"market_ticker":"KXBTC15M-26MAY141815-15","market_id":"9b5194ce-fa5b-4fa6-a79f-003263374118","price_dollars":"0.2900","delta_fp":"-126.29","side":"no","ts":"2026-05-14T22:08:40.161955Z","ts_ms":1778796520161}}

{"type":"orderbook_delta","sid":1,"seq":873,"msg":{"market_ticker":"KXBTC15M-26MAY141815-15","market_id":"9b5194ce-fa5b-4fa6-a79f-003263374118","price_dollars":"0.2400","delta_fp":"-75.00","side":"no","ts":"2026-05-14T22:08:40.181942Z","ts_ms":1778796520181}}

{"type":"orderbook_delta","sid":1,"seq":874,"msg":{"market_ticker":"KXBTC15M-26MAY141815-15","market_id":"9b5194ce-fa5b-4fa6-a79f-003263374118","price_dollars":"0.2900","delta_fp":"75.00","side":"no","ts":"2026-05-14T22:08:40.181942Z","ts_ms":1778796520181}}

{"type":"orderbook_delta","sid":1,"seq":875,"msg":{"market_ticker":"KXBTC15M-26MAY141815-15","market_id":"9b5194ce-fa5b-4fa6-a79f-003263374118","price_dollars":"0.6800","delta_fp":"-12.00","side":"yes","ts":"2026-05-14T22:08:40.203679Z","ts_ms":1778796520203}}

{"type":"orderbook_delta","sid":1,"seq":876,"msg":{"market_ticker":"KXBTC15M-26MAY141815-15","market_id":"9b5194ce-fa5b-4fa6-a79f-003263374118","price_dollars":"0.2800","delta_fp":"81.00","side":"no","ts":"2026-05-14T22:08:40.210023Z","ts_ms":1778796520210}}

{"type":"orderbook_delta","sid":1,"seq":877,"msg":{"market_ticker":"KXBTC15M-26MAY141815-15","market_id":"9b5194ce-fa5b-4fa6-a79f-003263374118","price_dollars":"0.6900","delta_fp":"200.00","side":"yes","ts":"2026-05-14T22:08:40.210511Z","ts_ms":1778796520210}}

{"type":"orderbook_delta","sid":1,"seq":878,"msg":{"market_ticker":"KXBTC15M-26MAY141815-15","market_id":"9b5194ce-fa5b-4fa6-a79f-003263374118","price_dollars":"0.6800","delta_fp":"-75.00","side":"yes","ts":"2026-05-14T22:08:40.216489Z","ts_ms":1778796520216}}

{"type":"orderbook_delta","sid":1,"seq":879,"msg":{"market_ticker":"KXBTC15M-26MAY141815-15","market_id":"9b5194ce-fa5b-4fa6-a79f-003263374118","price_dollars":"0.6200","delta_fp":"75.00","side":"yes","ts":"2026-05-14T22:08:40.216489Z","ts_ms":1778796520216}}

{"type":"orderbook_delta","sid":1,"seq":880,"msg":{"market_ticker":"KXBTC15M-26MAY141815-15","market_id":"9b5194ce-fa5b-4fa6-a79f-003263374118","price_dollars":"0.6300","delta_fp":"-1.00","side":"yes","ts":"2026-05-14T22:08:40.220198Z","ts_ms":1778796520220}}

{"type":"orderbook_delta","sid":1,"seq":881,"msg":{"market_ticker":"KXBTC15M-26MAY141815-15","market_id":"9b5194ce-fa5b-4fa6-a79f-003263374118","price_dollars":"0.6800","delta_fp":"24.00","side":"yes","ts":"2026-05-14T22:08:40.232425Z","ts_ms":1778796520232}}

{"type":"orderbook_delta","sid":1,"seq":882,"msg":{"market_ticker":"KXBTC15M-26MAY141815-15","market_id":"9b5194ce-fa5b-4fa6-a79f-003263374118","price_dollars":"0.6200","delta_fp":"2.00","side":"yes","ts":"2026-05-14T22:08:40.245166Z","ts_ms":1778796520245}}

{"type":"orderbook_delta","sid":1,"seq":883,"msg":{"market_ticker":"KXBTC15M-26MAY141815-15","market_id":"9b5194ce-fa5b-4fa6-a79f-003263374118","price_dollars":"0.6200","delta_fp":"-2.00","side":"yes","ts":"2026-05-14T22:08:40.265669Z","ts_ms":1778796520265}}

{"type":"orderbook_delta","sid":1,"seq":884,"msg":{"market_ticker":"KXBTC15M-26MAY141815-15","market_id":"9b5194ce-fa5b-4fa6-a79f-003263374118","price_dollars":"0.1900","delta_fp":"-40.00","side":"yes","ts":"2026-05-14T22:08:40.272904Z","ts_ms":1778796520272}}

{"type":"orderbook_delta","sid":1,"seq":885,"msg":{"market_ticker":"KXBTC15M-26MAY141815-15","market_id":"9b5194ce-fa5b-4fa6-a79f-003263374118","price_dollars":"0.2000","delta_fp":"40.00","side":"yes","ts":"2026-05-14T22:08:40.272904Z","ts_ms":1778796520272}}

{"type":"orderbook_delta","sid":1,"seq":886,"msg":{"market_ticker":"KXBTC15M-26MAY141815-15","market_id":"9b5194ce-fa5b-4fa6-a79f-003263374118","price_dollars":"0.6900","delta_fp":"-45.00","side":"yes","ts":"2026-05-14T22:08:40.276788Z","ts_ms":1778796520276}}

{"type":"orderbook_delta","sid":1,"seq":887,"msg":{"market_ticker":"KXBTC15M-26MAY141815-15","market_id":"9b5194ce-fa5b-4fa6-a79f-003263374118","price_dollars":"0.2900","delta_fp":"-75.00","side":"no","ts":"2026-05-14T22:08:40.289651Z","ts_ms":1778796520289}}

{"type":"orderbook_delta","sid":1,"seq":888,"msg":{"market_ticker":"KXBTC15M-26MAY141815-15","market_id":"9b5194ce-fa5b-4fa6-a79f-003263374118","price_dollars":"0.3000","delta_fp":"75.00","side":"no","ts":"2026-05-14T22:08:40.289651Z","ts_ms":1778796520289}}

{"type":"orderbook_delta","sid":1,"seq":889,"msg":{"market_ticker":"KXBTC15M-26MAY141815-15","market_id":"9b5194ce-fa5b-4fa6-a79f-003263374118","price_dollars":"0.6600","delta_fp":"-1100.00","side":"yes","ts":"2026-05-14T22:08:40.297193Z","ts_ms":1778796520297}}

{"type":"orderbook_delta","sid":1,"seq":890,"msg":{"market_ticker":"KXBTC15M-26MAY141815-15","market_id":"9b5194ce-fa5b-4fa6-a79f-003263374118","price_dollars":"0.6700","delta_fp":"1100.00","side":"yes","ts":"2026-05-14T22:08:40.297193Z","ts_ms":1778796520297}}

{"type":"orderbook_delta","sid":1,"seq":891,"msg":{"market_ticker":"KXBTC15M-26MAY141815-15","market_id":"9b5194ce-fa5b-4fa6-a79f-003263374118","price_dollars":"0.6700","delta_fp":"-1000.00","side":"yes","ts":"2026-05-14T22:08:40.299862Z","ts_ms":1778796520299}}

{"type":"orderbook_delta","sid":1,"seq":892,"msg":{"market_ticker":"KXBTC15M-26MAY141815-15","market_id":"9b5194ce-fa5b-4fa6-a79f-003263374118","price_dollars":"0.6800","delta_fp":"1000.00","side":"yes","ts":"2026-05-14T22:08:40.299862Z","ts_ms":1778796520299}}

{"type":"orderbook_delta","sid":1,"seq":893,"msg":{"market_ticker":"KXBTC15M-26MAY141815-15","market_id":"9b5194ce-fa5b-4fa6-a79f-003263374118","price_dollars":"0.2900","delta_fp":"-1000.00","side":"no","ts":"2026-05-14T22:08:40.302967Z","ts_ms":1778796520302}}

{"type":"orderbook_delta","sid":1,"seq":894,"msg":{"market_ticker":"KXBTC15M-26MAY141815-15","market_id":"9b5194ce-fa5b-4fa6-a79f-003263374118","price_dollars":"0.2700","delta_fp":"1000.00","side":"no","ts":"2026-05-14T22:08:40.302967Z","ts_ms":1778796520302}}

{"type":"orderbook_delta","sid":1,"seq":895,"msg":{"market_ticker":"KXBTC15M-26MAY141815-15","market_id":"9b5194ce-fa5b-4fa6-a79f-003263374118","price_dollars":"0.3000","delta_fp":"-13.99","side":"no","ts":"2026-05-14T22:08:40.311599Z","ts_ms":1778796520311}}

{"type":"orderbook_delta","sid":1,"seq":896,"msg":{"market_ticker":"KXBTC15M-26MAY141815-15","market_id":"9b5194ce-fa5b-4fa6-a79f-003263374118","price_dollars":"0.2800","delta_fp":"-81.00","side":"no","ts":"2026-05-14T22:08:40.312694Z","ts_ms":1778796520312}}

{"type":"orderbook_delta","sid":1,"seq":897,"msg":{"market_ticker":"KXBTC15M-26MAY141815-15","market_id":"9b5194ce-fa5b-4fa6-a79f-003263374118","price_dollars":"0.6400","delta_fp":"1.00","side":"yes","ts":"2026-05-14T22:08:40.316523Z","ts_ms":1778796520316}}

{"type":"orderbook_delta","sid":1,"seq":898,"msg":{"market_ticker":"KXBTC15M-26MAY141815-15","market_id":"9b5194ce-fa5b-4fa6-a79f-003263374118","price_dollars":"0.2900","delta_fp":"-100.00","side":"no","ts":"2026-05-14T22:08:40.324933Z","ts_ms":1778796520324}}

{"type":"orderbook_delta","sid":1,"seq":899,"msg":{"market_ticker":"KXBTC15M-26MAY141815-15","market_id":"9b5194ce-fa5b-4fa6-a79f-003263374118","price_dollars":"0.3000","delta_fp":"100.00","side":"no","ts":"2026-05-14T22:08:40.324933Z","ts_ms":1778796520324}}

{"type":"orderbook_delta","sid":1,"seq":900,"msg":{"market_ticker":"KXBTC15M-26MAY141815-15","market_id":"9b5194ce-fa5b-4fa6-a79f-003263374118","price_dollars":"0.6400","delta_fp":"-1.00","side":"yes","ts":"2026-05-14T22:08:40.327433Z","ts_ms":1778796520327}}

{"type":"orderbook_delta","sid":1,"seq":901,"msg":{"market_ticker":"KXBTC15M-26MAY141815-15","market_id":"9b5194ce-fa5b-4fa6-a79f-003263374118","price_dollars":"0.2900","delta_fp":"-10.00","side":"no","ts":"2026-05-14T22:08:40.329084Z","ts_ms":1778796520329}}

{"type":"orderbook_delta","sid":1,"seq":902,"msg":{"market_ticker":"KXBTC15M-26MAY141815-15","market_id":"9b5194ce-fa5b-4fa6-a79f-003263374118","price_dollars":"0.6500","delta_fp":"-81.00","side":"yes","ts":"2026-05-14T22:08:40.345999Z","ts_ms":1778796520345}}

{"type":"orderbook_delta","sid":1,"seq":903,"msg":{"market_ticker":"KXBTC15M-26MAY141815-15","market_id":"9b5194ce-fa5b-4fa6-a79f-003263374118","price_dollars":"0.6600","delta_fp":"81.00","side":"yes","ts":"2026-05-14T22:08:40.345999Z","ts_ms":1778796520345}}

{"type":"orderbook_delta","sid":1,"seq":904,"msg":{"market_ticker":"KXBTC15M-26MAY141815-15","market_id":"9b5194ce-fa5b-4fa6-a79f-003263374118","price_dollars":"0.6800","delta_fp":"-10.00","side":"yes","ts":"2026-05-14T22:08:40.348241Z","ts_ms":1778796520348}}

{"type":"orderbook_delta","sid":1,"seq":905,"msg":{"market_ticker":"KXBTC15M-26MAY141815-15","market_id":"9b5194ce-fa5b-4fa6-a79f-003263374118","price_dollars":"0.6900","delta_fp":"10.00","side":"yes","ts":"2026-05-14T22:08:40.348241Z","ts_ms":1778796520348}}

{"type":"orderbook_delta","sid":1,"seq":906,"msg":{"market_ticker":"KXBTC15M-26MAY141815-15","market_id":"9b5194ce-fa5b-4fa6-a79f-003263374118","price_dollars":"0.2800","delta_fp":"-10.00","side":"no","ts":"2026-05-14T22:08:40.354289Z","ts_ms":1778796520354}}

{"type":"orderbook_delta","sid":1,"seq":907,"msg":{"market_ticker":"KXBTC15M-26MAY141815-15","market_id":"9b5194ce-fa5b-4fa6-a79f-003263374118","price_dollars":"0.2700","delta_fp":"10.00","side":"no","ts":"2026-05-14T22:08:40.354289Z","ts_ms":1778796520354}}

{"type":"orderbook_delta","sid":1,"seq":908,"msg":{"market_ticker":"KXBTC15M-26MAY141815-15","market_id":"9b5194ce-fa5b-4fa6-a79f-003263374118","price_dollars":"0.6900","delta_fp":"-5.17","side":"yes","ts":"2026-05-14T22:08:40.389729Z","ts_ms":1778796520389}}

{"type":"orderbook_delta","sid":1,"seq":909,"msg":{"market_ticker":"KXBTC15M-26MAY141815-15","market_id":"9b5194ce-fa5b-4fa6-a79f-003263374118","price_dollars":"0.2000","delta_fp":"-40.00","side":"yes","ts":"2026-05-14T22:08:40.403917Z","ts_ms":1778796520403}}

{"type":"orderbook_delta","sid":1,"seq":910,"msg":{"market_ticker":"KXBTC15M-26MAY141815-15","market_id":"9b5194ce-fa5b-4fa6-a79f-003263374118","price_dollars":"0.1900","delta_fp":"40.00","side":"yes","ts":"2026-05-14T22:08:40.403917Z","ts_ms":1778796520403}}

{"type":"orderbook_delta","sid":1,"seq":911,"msg":{"market_ticker":"KXBTC15M-26MAY141815-15","market_id":"9b5194ce-fa5b-4fa6-a79f-003263374118","price_dollars":"0.3000","delta_fp":"-61.01","side":"no","ts":"2026-05-14T22:08:40.416462Z","ts_ms":1778796520416}}

{"type":"orderbook_delta","sid":1,"seq":912,"msg":{"market_ticker":"KXBTC15M-26MAY141815-15","market_id":"9b5194ce-fa5b-4fa6-a79f-003263374118","price_dollars":"0.2400","delta_fp":"75.00","side":"no","ts":"2026-05-14T22:08:40.416462Z","ts_ms":1778796520416}}

{"type":"orderbook_delta","sid":1,"seq":913,"msg":{"market_ticker":"KXBTC15M-26MAY141815-15","market_id":"9b5194ce-fa5b-4fa6-a79f-003263374118","price_dollars":"0.6200","delta_fp":"2.00","side":"yes","ts":"2026-05-14T22:08:40.418328Z","ts_ms":1778796520418}}

{"type":"orderbook_delta","sid":1,"seq":914,"msg":{"market_ticker":"KXBTC15M-26MAY141815-15","market_id":"9b5194ce-fa5b-4fa6-a79f-003263374118","price_dollars":"0.6300","delta_fp":"1.00","side":"yes","ts":"2026-05-14T22:08:40.420052Z","ts_ms":1778796520420}}

{"type":"orderbook_delta","sid":1,"seq":915,"msg":{"market_ticker":"KXBTC15M-26MAY141815-15","market_id":"9b5194ce-fa5b-4fa6-a79f-003263374118","price_dollars":"0.3000","delta_fp":"18.00","side":"no","ts":"2026-05-14T22:08:40.446056Z","ts_ms":1778796520446}}

{"type":"orderbook_delta","sid":1,"seq":916,"msg":{"market_ticker":"KXBTC15M-26MAY141815-15","market_id":"9b5194ce-fa5b-4fa6-a79f-003263374118","price_dollars":"0.5900","delta_fp":"1.00","side":"yes","ts":"2026-05-14T22:08:40.453217Z","ts_ms":1778796520453}}

{"type":"orderbook_delta","sid":1,"seq":917,"msg":{"market_ticker":"KXBTC15M-26MAY141815-15","market_id":"9b5194ce-fa5b-4fa6-a79f-003263374118","price_dollars":"0.5800","delta_fp":"1.00","side":"yes","ts":"2026-05-14T22:08:40.454241Z","ts_ms":1778796520454}}

{"type":"orderbook_delta","sid":1,"seq":918,"msg":{"market_ticker":"KXBTC15M-26MAY141815-15","market_id":"9b5194ce-fa5b-4fa6-a79f-003263374118","price_dollars":"0.3000","delta_fp":"1.00","side":"no","ts":"2026-05-14T22:08:40.455281Z","ts_ms":1778796520455}}

{"type":"orderbook_delta","sid":1,"seq":919,"msg":{"market_ticker":"KXBTC15M-26MAY141815-15","market_id":"9b5194ce-fa5b-4fa6-a79f-003263374118","price_dollars":"0.2800","delta_fp":"1.00","side":"no","ts":"2026-05-14T22:08:40.456379Z","ts_ms":1778796520456}}

{"type":"orderbook_delta","sid":1,"seq":920,"msg":{"market_ticker":"KXBTC15M-26MAY141815-15","market_id":"9b5194ce-fa5b-4fa6-a79f-003263374118","price_dollars":"0.3000","delta_fp":"-6.99","side":"no","ts":"2026-05-14T22:08:40.512917Z","ts_ms":1778796520512}}

{"type":"orderbook_delta","sid":1,"seq":921,"msg":{"market_ticker":"KXBTC15M-26MAY141815-15","market_id":"9b5194ce-fa5b-4fa6-a79f-003263374118","price_dollars":"0.2700","delta_fp":"-150.00","side":"no","ts":"2026-05-14T22:08:40.56849Z","ts_ms":1778796520568}}

{"type":"orderbook_delta","sid":1,"seq":922,"msg":{"market_ticker":"KXBTC15M-26MAY141815-15","market_id":"9b5194ce-fa5b-4fa6-a79f-003263374118","price_dollars":"0.2600","delta_fp":"150.00","side":"no","ts":"2026-05-14T22:08:40.56849Z","ts_ms":1778796520568}}

{"type":"orderbook_delta","sid":1,"seq":923,"msg":{"market_ticker":"KXBTC15M-26MAY141815-15","market_id":"9b5194ce-fa5b-4fa6-a79f-003263374118","price_dollars":"0.6000","delta_fp":"-150.00","side":"yes","ts":"2026-05-14T22:08:40.585991Z","ts_ms":1778796520585}}

{"type":"orderbook_delta","sid":1,"seq":924,"msg":{"market_ticker":"KXBTC15M-26MAY141815-15","market_id":"9b5194ce-fa5b-4fa6-a79f-003263374118","price_dollars":"0.6100","delta_fp":"150.00","side":"yes","ts":"2026-05-14T22:08:40.585991Z","ts_ms":1778796520585}}

{"type":"orderbook_delta","sid":1,"seq":925,"msg":{"market_ticker":"KXBTC15M-26MAY141815-15","market_id":"9b5194ce-fa5b-4fa6-a79f-003263374118","price_dollars":"0.6400","delta_fp":"-2.00","side":"yes","ts":"2026-05-14T22:08:40.607792Z","ts_ms":1778796520607}}

{"type":"orderbook_delta","sid":1,"seq":926,"msg":{"market_ticker":"KXBTC15M-26MAY141815-15","market_id":"9b5194ce-fa5b-4fa6-a79f-003263374118","price_dollars":"0.6500","delta_fp":"2.00","side":"yes","ts":"2026-05-14T22:08:40.607792Z","ts_ms":1778796520607}}

{"type":"orderbook_delta","sid":1,"seq":927,"msg":{"market_ticker":"KXBTC15M-26MAY141815-15","market_id":"9b5194ce-fa5b-4fa6-a79f-003263374118","price_dollars":"0.3000","delta_fp":"-18.00","side":"no","ts":"2026-05-14T22:08:40.618912Z","ts_ms":1778796520618}}

{"type":"orderbook_delta","sid":1,"seq":928,"msg":{"market_ticker":"KXBTC15M-26MAY141815-15","market_id":"9b5194ce-fa5b-4fa6-a79f-003263374118","price_dollars":"0.2700","delta_fp":"-2.00","side":"no","ts":"2026-05-14T22:08:40.635479Z","ts_ms":1778796520635}}

{"type":"orderbook_delta","sid":1,"seq":929,"msg":{"market_ticker":"KXBTC15M-26MAY141815-15","market_id":"9b5194ce-fa5b-4fa6-a79f-003263374118","price_dollars":"0.2600","delta_fp":"2.00","side":"no","ts":"2026-05-14T22:08:40.635479Z","ts_ms":1778796520635}}

{"type":"orderbook_delta","sid":1,"seq":930,"msg":{"market_ticker":"KXBTC15M-26MAY141815-15","market_id":"9b5194ce-fa5b-4fa6-a79f-003263374118","price_dollars":"0.0700","delta_fp":"-2.00","side":"no","ts":"2026-05-14T22:08:40.666696Z","ts_ms":1778796520666}}

{"type":"orderbook_delta","sid":1,"seq":931,"msg":{"market_ticker":"KXBTC15M-26MAY141815-15","market_id":"9b5194ce-fa5b-4fa6-a79f-003263374118","price_dollars":"0.2800","delta_fp":"-1.00","side":"no","ts":"2026-05-14T22:08:40.683198Z","ts_ms":1778796520683}}

{"type":"orderbook_delta","sid":1,"seq":932,"msg":{"market_ticker":"KXBTC15M-26MAY141815-15","market_id":"9b5194ce-fa5b-4fa6-a79f-003263374118","price_dollars":"0.3000","delta_fp":"-1.00","side":"no","ts":"2026-05-14T22:08:40.683597Z","ts_ms":1778796520683}}

{"type":"orderbook_delta","sid":1,"seq":933,"msg":{"market_ticker":"KXBTC15M-26MAY141815-15","market_id":"9b5194ce-fa5b-4fa6-a79f-003263374118","price_dollars":"0.5900","delta_fp":"-1.00","side":"yes","ts":"2026-05-14T22:08:40.683819Z","ts_ms":1778796520683}}

{"type":"orderbook_delta","sid":1,"seq":934,"msg":{"market_ticker":"KXBTC15M-26MAY141815-15","market_id":"9b5194ce-fa5b-4fa6-a79f-003263374118","price_dollars":"0.5800","delta_fp":"-1.00","side":"yes","ts":"2026-05-14T22:08:40.68422Z","ts_ms":1778796520684}}

{"type":"orderbook_delta","sid":1,"seq":935,"msg":{"market_ticker":"KXBTC15M-26MAY141815-15","market_id":"9b5194ce-fa5b-4fa6-a79f-003263374118","price_dollars":"0.2900","delta_fp":"13.00","side":"no","ts":"2026-05-14T22:08:40.703225Z","ts_ms":1778796520703}}

{"type":"orderbook_delta","sid":1,"seq":936,"msg":{"market_ticker":"KXBTC15M-26MAY141815-15","market_id":"9b5194ce-fa5b-4fa6-a79f-003263374118","price_dollars":"0.2400","delta_fp":"-75.00","side":"no","ts":"2026-05-14T22:08:40.718065Z","ts_ms":1778796520718}}

{"type":"orderbook_delta","sid":1,"seq":937,"msg":{"market_ticker":"KXBTC15M-26MAY141815-15","market_id":"9b5194ce-fa5b-4fa6-a79f-003263374118","price_dollars":"0.3000","delta_fp":"75.00","side":"no","ts":"2026-05-14T22:08:40.718065Z","ts_ms":1778796520718}}

{"type":"orderbook_delta","sid":1,"seq":938,"msg":{"market_ticker":"KXBTC15M-26MAY141815-15","market_id":"9b5194ce-fa5b-4fa6-a79f-003263374118","price_dollars":"0.6200","delta_fp":"-2.00","side":"yes","ts":"2026-05-14T22:08:40.745732Z","ts_ms":1778796520745}}

{"type":"orderbook_delta","sid":1,"seq":939,"msg":{"market_ticker":"KXBTC15M-26MAY141815-15","market_id":"9b5194ce-fa5b-4fa6-a79f-003263374118","price_dollars":"0.3000","delta_fp":"-7.64","side":"no","ts":"2026-05-14T22:08:40.78339Z","ts_ms":1778796520783}}

{"type":"orderbook_delta","sid":1,"seq":940,"msg":{"market_ticker":"KXBTC15M-26MAY141815-15","market_id":"9b5194ce-fa5b-4fa6-a79f-003263374118","price_dollars":"0.3000","delta_fp":"-85.37","side":"no","ts":"2026-05-14T22:08:40.784942Z","ts_ms":1778796520784}}

{"type":"orderbook_delta","sid":1,"seq":941,"msg":{"market_ticker":"KXBTC15M-26MAY141815-15","market_id":"9b5194ce-fa5b-4fa6-a79f-003263374118","price_dollars":"0.3000","delta_fp":"-75.00","side":"no","ts":"2026-05-14T22:08:40.784942Z","ts_ms":1778796520784}}

{"type":"orderbook_delta","sid":1,"seq":942,"msg":{"market_ticker":"KXBTC15M-26MAY141815-15","market_id":"9b5194ce-fa5b-4fa6-a79f-003263374118","price_dollars":"0.2900","delta_fp":"-104.96","side":"no","ts":"2026-05-14T22:08:40.784942Z","ts_ms":1778796520784}}

{"type":"orderbook_delta","sid":1,"seq":943,"msg":{"market_ticker":"KXBTC15M-26MAY141815-15","market_id":"9b5194ce-fa5b-4fa6-a79f-003263374118","price_dollars":"0.3000","delta_fp":"75.00","side":"no","ts":"2026-05-14T22:08:40.825436Z","ts_ms":1778796520825}}

{"type":"orderbook_delta","sid":1,"seq":944,"msg":{"market_ticker":"KXBTC15M-26MAY141815-15","market_id":"9b5194ce-fa5b-4fa6-a79f-003263374118","price_dollars":"0.2900","delta_fp":"100.00","side":"no","ts":"2026-05-14T22:08:40.837147Z","ts_ms":1778796520837}}

{"type":"orderbook_delta","sid":1,"seq":945,"msg":{"market_ticker":"KXBTC15M-26MAY141815-15","market_id":"9b5194ce-fa5b-4fa6-a79f-003263374118","price_dollars":"0.2900","delta_fp":"-100.00","side":"no","ts":"2026-05-14T22:08:40.880586Z","ts_ms":1778796520880}}

{"type":"orderbook_delta","sid":1,"seq":946,"msg":{"market_ticker":"KXBTC15M-26MAY141815-15","market_id":"9b5194ce-fa5b-4fa6-a79f-003263374118","price_dollars":"0.3000","delta_fp":"100.00","side":"no","ts":"2026-05-14T22:08:40.880586Z","ts_ms":1778796520880}}

{"type":"orderbook_delta","sid":1,"seq":947,"msg":{"market_ticker":"KXBTC15M-26MAY141815-15","market_id":"9b5194ce-fa5b-4fa6-a79f-003263374118","price_dollars":"0.2900","delta_fp":"30.00","side":"no","ts":"2026-05-14T22:08:40.934965Z","ts_ms":1778796520934}}

{"type":"orderbook_delta","sid":1,"seq":948,"msg":{"market_ticker":"KXBTC15M-26MAY141815-15","market_id":"9b5194ce-fa5b-4fa6-a79f-003263374118","price_dollars":"0.0600","delta_fp":"-2.00","side":"no","ts":"2026-05-14T22:08:40.981069Z","ts_ms":1778796520981}}

{"type":"orderbook_delta","sid":1,"seq":949,"msg":{"market_ticker":"KXBTC15M-26MAY141815-15","market_id":"9b5194ce-fa5b-4fa6-a79f-003263374118","price_dollars":"0.2900","delta_fp":"10.00","side":"no","ts":"2026-05-14T22:08:41.007779Z","ts_ms":1778796521007}}

{"type":"orderbook_delta","sid":1,"seq":950,"msg":{"market_ticker":"KXBTC15M-26MAY141815-15","market_id":"9b5194ce-fa5b-4fa6-a79f-003263374118","price_dollars":"0.2700","delta_fp":"-10.00","side":"no","ts":"2026-05-14T22:08:41.05156Z","ts_ms":1778796521051}}

{"type":"orderbook_delta","sid":1,"seq":951,"msg":{"market_ticker":"KXBTC15M-26MAY141815-15","market_id":"9b5194ce-fa5b-4fa6-a79f-003263374118","price_dollars":"0.2800","delta_fp":"10.00","side":"no","ts":"2026-05-14T22:08:41.05156Z","ts_ms":1778796521051}}

{"type":"orderbook_delta","sid":1,"seq":952,"msg":{"market_ticker":"KXBTC15M-26MAY141815-15","market_id":"9b5194ce-fa5b-4fa6-a79f-003263374118","price_dollars":"0.1900","delta_fp":"-40.00","side":"yes","ts":"2026-05-14T22:08:41.062759Z","ts_ms":1778796521062}}

{"type":"orderbook_delta","sid":1,"seq":953,"msg":{"market_ticker":"KXBTC15M-26MAY141815-15","market_id":"9b5194ce-fa5b-4fa6-a79f-003263374118","price_dollars":"0.2000","delta_fp":"40.00","side":"yes","ts":"2026-05-14T22:08:41.062759Z","ts_ms":1778796521062}}

{"type":"orderbook_delta","sid":1,"seq":954,"msg":{"market_ticker":"KXBTC15M-26MAY141815-15","market_id":"9b5194ce-fa5b-4fa6-a79f-003263374118","price_dollars":"0.2900","delta_fp":"-30.00","side":"no","ts":"2026-05-14T22:08:41.066059Z","ts_ms":1778796521066}}

{"type":"orderbook_delta","sid":1,"seq":955,"msg":{"market_ticker":"KXBTC15M-26MAY141815-15","market_id":"9b5194ce-fa5b-4fa6-a79f-003263374118","price_dollars":"0.6900","delta_fp":"2.00","side":"yes","ts":"2026-05-14T22:08:41.137336Z","ts_ms":1778796521137}}

{"type":"orderbook_delta","sid":1,"seq":956,"msg":{"market_ticker":"KXBTC15M-26MAY141815-15","market_id":"9b5194ce-fa5b-4fa6-a79f-003263374118","price_dollars":"0.2600","delta_fp":"-2.00","side":"no","ts":"2026-05-14T22:08:41.291669Z","ts_ms":1778796521291}}

{"type":"orderbook_delta","sid":1,"seq":957,"msg":{"market_ticker":"KXBTC15M-26MAY141815-15","market_id":"9b5194ce-fa5b-4fa6-a79f-003263374118","price_dollars":"0.2700","delta_fp":"2.00","side":"no","ts":"2026-05-14T22:08:41.291669Z","ts_ms":1778796521291}}

{"type":"orderbook_delta","sid":1,"seq":958,"msg":{"market_ticker":"KXBTC15M-26MAY141815-15","market_id":"9b5194ce-fa5b-4fa6-a79f-003263374118","price_dollars":"0.0500","delta_fp":"-2.00","side":"no","ts":"2026-05-14T22:08:41.29782Z","ts_ms":1778796521297}}

{"type":"orderbook_delta","sid":1,"seq":959,"msg":{"market_ticker":"KXBTC15M-26MAY141815-15","market_id":"9b5194ce-fa5b-4fa6-a79f-003263374118","price_dollars":"0.3000","delta_fp":"30.00","side":"no","ts":"2026-05-14T22:08:41.298044Z","ts_ms":1778796521298}}

{"type":"orderbook_delta","sid":1,"seq":960,"msg":{"market_ticker":"KXBTC15M-26MAY141815-15","market_id":"9b5194ce-fa5b-4fa6-a79f-003263374118","price_dollars":"0.2000","delta_fp":"-40.00","side":"yes","ts":"2026-05-14T22:08:41.31148Z","ts_ms":1778796521311}}

{"type":"orderbook_delta","sid":1,"seq":961,"msg":{"market_ticker":"KXBTC15M-26MAY141815-15","market_id":"9b5194ce-fa5b-4fa6-a79f-003263374118","price_dollars":"0.1900","delta_fp":"40.00","side":"yes","ts":"2026-05-14T22:08:41.31148Z","ts_ms":1778796521311}}

{"type":"orderbook_delta","sid":1,"seq":962,"msg":{"market_ticker":"KXBTC15M-26MAY141815-15","market_id":"9b5194ce-fa5b-4fa6-a79f-003263374118","price_dollars":"0.6500","delta_fp":"-2.00","side":"yes","ts":"2026-05-14T22:08:41.312581Z","ts_ms":1778796521312}}

{"type":"orderbook_delta","sid":1,"seq":963,"msg":{"market_ticker":"KXBTC15M-26MAY141815-15","market_id":"9b5194ce-fa5b-4fa6-a79f-003263374118","price_dollars":"0.6400","delta_fp":"2.00","side":"yes","ts":"2026-05-14T22:08:41.312581Z","ts_ms":1778796521312}}

{"type":"orderbook_delta","sid":1,"seq":964,"msg":{"market_ticker":"KXBTC15M-26MAY141815-15","market_id":"9b5194ce-fa5b-4fa6-a79f-003263374118","price_dollars":"0.3000","delta_fp":"-27.98","side":"no","ts":"2026-05-14T22:08:41.342848Z","ts_ms":1778796521342}}

{"type":"orderbook_delta","sid":1,"seq":965,"msg":{"market_ticker":"KXBTC15M-26MAY141815-15","market_id":"9b5194ce-fa5b-4fa6-a79f-003263374118","price_dollars":"0.3000","delta_fp":"-0.10","side":"no","ts":"2026-05-14T22:08:41.367123Z","ts_ms":1778796521367}}

{"type":"orderbook_delta","sid":1,"seq":966,"msg":{"market_ticker":"KXBTC15M-26MAY141815-15","market_id":"9b5194ce-fa5b-4fa6-a79f-003263374118","price_dollars":"0.3000","delta_fp":"-46.92","side":"no","ts":"2026-05-14T22:08:41.392673Z","ts_ms":1778796521392}}

{"type":"orderbook_delta","sid":1,"seq":967,"msg":{"market_ticker":"KXBTC15M-26MAY141815-15","market_id":"9b5194ce-fa5b-4fa6-a79f-003263374118","price_dollars":"0.3000","delta_fp":"-16.04","side":"no","ts":"2026-05-14T22:08:41.392673Z","ts_ms":1778796521392}}

{"type":"orderbook_delta","sid":1,"seq":968,"msg":{"market_ticker":"KXBTC15M-26MAY141815-15","market_id":"9b5194ce-fa5b-4fa6-a79f-003263374118","price_dollars":"0.6000","delta_fp":"1.00","side":"yes","ts":"2026-05-14T22:08:41.409424Z","ts_ms":1778796521409}}

{"type":"orderbook_delta","sid":1,"seq":969,"msg":{"market_ticker":"KXBTC15M-26MAY141815-15","market_id":"9b5194ce-fa5b-4fa6-a79f-003263374118","price_dollars":"0.5800","delta_fp":"1.00","side":"yes","ts":"2026-05-14T22:08:41.409841Z","ts_ms":1778796521409}}

{"type":"orderbook_delta","sid":1,"seq":970,"msg":{"market_ticker":"KXBTC15M-26MAY141815-15","market_id":"9b5194ce-fa5b-4fa6-a79f-003263374118","price_dollars":"0.3000","delta_fp":"1.00","side":"no","ts":"2026-05-14T22:08:41.41045Z","ts_ms":1778796521410}}

{"type":"orderbook_delta","sid":1,"seq":971,"msg":{"market_ticker":"KXBTC15M-26MAY141815-15","market_id":"9b5194ce-fa5b-4fa6-a79f-003263374118","price_dollars":"0.2800","delta_fp":"1.00","side":"no","ts":"2026-05-14T22:08:41.411613Z","ts_ms":1778796521411}}

{"type":"orderbook_delta","sid":1,"seq":972,"msg":{"market_ticker":"KXBTC15M-26MAY141815-15","market_id":"9b5194ce-fa5b-4fa6-a79f-003263374118","price_dollars":"0.3000","delta_fp":"75.00","side":"no","ts":"2026-05-14T22:08:41.424806Z","ts_ms":1778796521424}}

{"type":"orderbook_delta","sid":1,"seq":973,"msg":{"market_ticker":"KXBTC15M-26MAY141815-15","market_id":"9b5194ce-fa5b-4fa6-a79f-003263374118","price_dollars":"0.3000","delta_fp":"-16.79","side":"no","ts":"2026-05-14T22:08:41.471117Z","ts_ms":1778796521471}}

{"type":"orderbook_delta","sid":1,"seq":974,"msg":{"market_ticker":"KXBTC15M-26MAY141815-15","market_id":"9b5194ce-fa5b-4fa6-a79f-003263374118","price_dollars":"0.6900","delta_fp":"-2.65","side":"yes","ts":"2026-05-14T22:08:41.503902Z","ts_ms":1778796521503}}

{"type":"orderbook_delta","sid":1,"seq":975,"msg":{"market_ticker":"KXBTC15M-26MAY141815-15","market_id":"9b5194ce-fa5b-4fa6-a79f-003263374118","price_dollars":"0.6900","delta_fp":"-1.29","side":"yes","ts":"2026-05-14T22:08:41.516165Z","ts_ms":1778796521516}}

{"type":"orderbook_delta","sid":1,"seq":976,"msg":{"market_ticker":"KXBTC15M-26MAY141815-15","market_id":"9b5194ce-fa5b-4fa6-a79f-003263374118","price_dollars":"0.3000","delta_fp":"32.00","side":"no","ts":"2026-05-14T22:08:41.518905Z","ts_ms":1778796521518}}

{"type":"orderbook_delta","sid":1,"seq":977,"msg":{"market_ticker":"KXBTC15M-26MAY141815-15","market_id":"9b5194ce-fa5b-4fa6-a79f-003263374118","price_dollars":"0.6900","delta_fp":"-10.00","side":"yes","ts":"2026-05-14T22:08:41.557852Z","ts_ms":1778796521557}}

{"type":"orderbook_delta","sid":1,"seq":978,"msg":{"market_ticker":"KXBTC15M-26MAY141815-15","market_id":"9b5194ce-fa5b-4fa6-a79f-003263374118","price_dollars":"0.6800","delta_fp":"10.00","side":"yes","ts":"2026-05-14T22:08:41.557852Z","ts_ms":1778796521557}}

{"type":"orderbook_delta","sid":1,"seq":979,"msg":{"market_ticker":"KXBTC15M-26MAY141815-15","market_id":"9b5194ce-fa5b-4fa6-a79f-003263374118","price_dollars":"0.3000","delta_fp":"-1.00","side":"no","ts":"2026-05-14T22:08:41.587661Z","ts_ms":1778796521587}}

{"type":"orderbook_delta","sid":1,"seq":980,"msg":{"market_ticker":"KXBTC15M-26MAY141815-15","market_id":"9b5194ce-fa5b-4fa6-a79f-003263374118","price_dollars":"0.3000","delta_fp":"-29.00","side":"no","ts":"2026-05-14T22:08:41.739702Z","ts_ms":1778796521739}}

{"type":"orderbook_delta","sid":1,"seq":981,"msg":{"market_ticker":"KXBTC15M-26MAY141815-15","market_id":"9b5194ce-fa5b-4fa6-a79f-003263374118","price_dollars":"0.3000","delta_fp":"-1.00","side":"no","ts":"2026-05-14T22:08:41.739702Z","ts_ms":1778796521739}}

{"type":"orderbook_delta","sid":1,"seq":982,"msg":{"market_ticker":"KXBTC15M-26MAY141815-15","market_id":"9b5194ce-fa5b-4fa6-a79f-003263374118","price_dollars":"0.3000","delta_fp":"-75.00","side":"no","ts":"2026-05-14T22:08:41.739702Z","ts_ms":1778796521739}}

{"type":"orderbook_delta","sid":1,"seq":983,"msg":{"market_ticker":"KXBTC15M-26MAY141815-15","market_id":"9b5194ce-fa5b-4fa6-a79f-003263374118","price_dollars":"0.3000","delta_fp":"-33.92","side":"no","ts":"2026-05-14T22:08:41.739702Z","ts_ms":1778796521739}}

{"type":"orderbook_delta","sid":1,"seq":984,"msg":{"market_ticker":"KXBTC15M-26MAY141815-15","market_id":"9b5194ce-fa5b-4fa6-a79f-003263374118","price_dollars":"0.2400","delta_fp":"75.00","side":"no","ts":"2026-05-14T22:08:41.778278Z","ts_ms":1778796521778}}

{"type":"orderbook_delta","sid":1,"seq":985,"msg":{"market_ticker":"KXBTC15M-26MAY141815-15","market_id":"9b5194ce-fa5b-4fa6-a79f-003263374118","price_dollars":"0.2900","delta_fp":"100.00","side":"no","ts":"2026-05-14T22:08:41.794337Z","ts_ms":1778796521794}}

{"type":"orderbook_delta","sid":1,"seq":986,"msg":{"market_ticker":"KXBTC15M-26MAY141815-15","market_id":"9b5194ce-fa5b-4fa6-a79f-003263374118","price_dollars":"0.3000","delta_fp":"-65.25","side":"no","ts":"2026-05-14T22:08:41.796084Z","ts_ms":1778796521796}}

{"type":"orderbook_delta","sid":1,"seq":987,"msg":{"market_ticker":"KXBTC15M-26MAY141815-15","market_id":"9b5194ce-fa5b-4fa6-a79f-003263374118","price_dollars":"0.6800","delta_fp":"-10.00","side":"yes","ts":"2026-05-14T22:08:41.803924Z","ts_ms":1778796521803}}

{"type":"orderbook_delta","sid":1,"seq":988,"msg":{"market_ticker":"KXBTC15M-26MAY141815-15","market_id":"9b5194ce-fa5b-4fa6-a79f-003263374118","price_dollars":"0.6900","delta_fp":"10.00","side":"yes","ts":"2026-05-14T22:08:41.803924Z","ts_ms":1778796521803}}

{"type":"orderbook_delta","sid":1,"seq":989,"msg":{"market_ticker":"KXBTC15M-26MAY141815-15","market_id":"9b5194ce-fa5b-4fa6-a79f-003263374118","price_dollars":"0.6200","delta_fp":"-75.00","side":"yes","ts":"2026-05-14T22:08:41.814057Z","ts_ms":1778796521814}}

{"type":"orderbook_delta","sid":1,"seq":990,"msg":{"market_ticker":"KXBTC15M-26MAY141815-15","market_id":"9b5194ce-fa5b-4fa6-a79f-003263374118","price_dollars":"0.6900","delta_fp":"75.00","side":"yes","ts":"2026-05-14T22:08:41.814057Z","ts_ms":1778796521814}}

{"type":"orderbook_delta","sid":1,"seq":991,"msg":{"market_ticker":"KXBTC15M-26MAY141815-15","market_id":"9b5194ce-fa5b-4fa6-a79f-003263374118","price_dollars":"0.0400","delta_fp":"-2.00","side":"no","ts":"2026-05-14T22:08:41.815305Z","ts_ms":1778796521815}}

{"type":"orderbook_delta","sid":1,"seq":992,"msg":{"market_ticker":"KXBTC15M-26MAY141815-15","market_id":"9b5194ce-fa5b-4fa6-a79f-003263374118","price_dollars":"0.2800","delta_fp":"81.00","side":"no","ts":"2026-05-14T22:08:41.889214Z","ts_ms":1778796521889}}

{"type":"orderbook_delta","sid":1,"seq":993,"msg":{"market_ticker":"KXBTC15M-26MAY141815-15","market_id":"9b5194ce-fa5b-4fa6-a79f-003263374118","price_dollars":"0.2800","delta_fp":"-10.00","side":"no","ts":"2026-05-14T22:08:41.91741Z","ts_ms":1778796521917}}

{"type":"orderbook_delta","sid":1,"seq":994,"msg":{"market_ticker":"KXBTC15M-26MAY141815-15","market_id":"9b5194ce-fa5b-4fa6-a79f-003263374118","price_dollars":"0.2700","delta_fp":"10.00","side":"no","ts":"2026-05-14T22:08:41.91741Z","ts_ms":1778796521917}}

{"type":"orderbook_delta","sid":1,"seq":995,"msg":{"market_ticker":"KXBTC15M-26MAY141815-15","market_id":"9b5194ce-fa5b-4fa6-a79f-003263374118","price_dollars":"0.6300","delta_fp":"-1.00","side":"yes","ts":"2026-05-14T22:08:41.923802Z","ts_ms":1778796521923}}

{"type":"orderbook_delta","sid":1,"seq":996,"msg":{"market_ticker":"KXBTC15M-26MAY141815-15","market_id":"9b5194ce-fa5b-4fa6-a79f-003263374118","price_dollars":"0.1900","delta_fp":"-40.00","side":"yes","ts":"2026-05-14T22:08:41.931966Z","ts_ms":1778796521931}}

{"type":"orderbook_delta","sid":1,"seq":997,"msg":{"market_ticker":"KXBTC15M-26MAY141815-15","market_id":"9b5194ce-fa5b-4fa6-a79f-003263374118","price_dollars":"0.2000","delta_fp":"40.00","side":"yes","ts":"2026-05-14T22:08:41.931966Z","ts_ms":1778796521931}}

{"type":"orderbook_delta","sid":1,"seq":998,"msg":{"market_ticker":"KXBTC15M-26MAY141815-15","market_id":"9b5194ce-fa5b-4fa6-a79f-003263374118","price_dollars":"0.2800","delta_fp":"-81.00","side":"no","ts":"2026-05-14T22:08:41.972054Z","ts_ms":1778796521972}}

{"type":"orderbook_delta","sid":1,"seq":999,"msg":{"market_ticker":"KXBTC15M-26MAY141815-15","market_id":"9b5194ce-fa5b-4fa6-a79f-003263374118","price_dollars":"0.6900","delta_fp":"-75.00","side":"yes","ts":"2026-05-14T22:08:41.98597Z","ts_ms":1778796521985}}

