{"type":"subscribed","id":1,"msg":{"channel":"orderbook_delta","sid":1}}

{"type":"orderbook_snapshot","sid":1,"seq":1,"msg":{"market_ticker":"KXBTC15M-26MAY141815-15","market_id":"9b5194ce-fa5b-4fa6-a79f-003263374118","yes_dollars_fp":[["0.0010","1502.00"],["0.0020","2526.00"],["0.0030","733.00"],["0.0040","250.00"],["0.0050","100.00"],["0.0060","267.00"],["0.0080","1.00"],["0.0100","1593.49"],["0.0110","173.00"],["0.0120","808.00"],["0.0130","76.00"],["0.0140","171.00"],["0.0150","342.00"],["0.0160","162.00"],["0.0170","58.00"],["0.0180","155.00"],["0.0190","52.00"],["0.0200","965.00"],["0.0210","171.00"],["0.0220","474.00"],["0.0240","100.00"],["0.0250","1.00"],["0.0260","100.00"],["0.0280","100.00"],["0.0300","26577.00"],["0.0310","351.00"],["0.0320","304.00"],["0.0330","1.00"],["0.0340","100.00"],["0.0360","100.00"],["0.0380","100.00"],["0.0400","457.00"],["0.0410","350.00"],["0.0420","294.00"],["0.0440","101.00"],["0.0460","100.00"],["0.0480","100.00"],["0.0500","1429.07"],["0.0520","213.00"],["0.0540","100.00"],["0.0550","1.00"],["0.0560","100.00"],["0.0580","100.00"],["0.0600","493.00"],["0.0620","100.00"],["0.0640","100.00"],["0.0660","101.00"],["0.0680","100.00"],["0.0700","1046.00"],["0.0720","100.00"],["0.0740","100.00"],["0.0760","100.00"],["0.0780","100.00"],["0.0800","167.60"],["0.0820","100.00"],["0.0840","100.00"],["0.0860","100.00"],["0.0880","101.00"],["0.0900","969.00"],["0.0920","100.00"],["0.0940","100.00"],["0.0960","100.00"],["0.0980","100.00"],["0.1000","199.00"],["0.1100","308.00"],["0.1200","108.00"],["0.1300","116.94"],["0.1400","125.00"],["0.1500","173.55"],["0.1600","144.66"],["0.1700","126.09"],["0.1800","100.00"],["0.1900","414.91"],["0.2000","248.81"],["0.2100","100.00"],["0.2200","110.00"],["0.2300","100.00"],["0.2400","118.04"],["0.2500","901.73"],["0.2600","100.00"],["0.2700","101.00"],["0.2800","109.30"],["0.2900","110.00"],["0.3000","168.00"],["0.3100","115.82"],["0.3200","34.00"],["0.3300","155.32"],["0.3400","879.02"],["0.3500","100.00"],["0.3600","110.00"],["0.3700","100.00"],["0.3800","118.56"],["0.3900","100.00"],["0.4000","710.00"],["0.4100","100.00"],["0.4200","100.00"],["0.4300","1061.00"],["0.4400","100.00"],["0.4500","1100.00"],["0.4600","7282.00"],["0.4700","100.00"],["0.4800","120.00"],["0.4900","100.00"],["0.5000","5249.00"],["0.5100","117.00"],["0.5200","100.00"],["0.5300","114.88"],["0.5400","104.85"],["0.5500","235.32"],["0.5600","346.95"],["0.5700","112.32"],["0.5800","178.72"],["0.5900","769.69"],["0.6000","103.66"],["0.6100","183.00"],["0.6200","1451.04"],["0.6300","200.36"]],"no_dollars_fp":[["0.0010","1502.00"],["0.0020","1526.00"],["0.0030","733.00"],["0.0050","100.00"],["0.0060","101.00"],["0.0080","1.00"],["0.0100","29335.89"],["0.0110","83.00"],["0.0120","725.00"],["0.0140","100.00"],["0.0150","276.00"],["0.0160","100.00"],["0.0180","100.00"],["0.0200","1622.00"],["0.0210","171.00"],["0.0220","474.00"],["0.0240","100.00"],["0.0250","1.00"],["0.0260","100.00"],["0.0280","100.00"],["0.0300","830.24"],["0.0310","351.00"],["0.0320","304.00"],["0.0330","1.00"],["0.0340","100.00"],["0.0360","100.00"],["0.0380","100.00"],["0.0400","516.67"],["0.0410","350.00"],["0.0420","294.00"],["0.0440","101.00"],["0.0460","100.00"],["0.0480","100.00"],["0.0500","500.00"],["0.0520","213.00"],["0.0540","100.00"],["0.0550","1.00"],["0.0560","100.00"],["0.0580","100.00"],["0.0600","552.43"],["0.0620","100.00"],["0.0640","100.00"],["0.0660","101.00"],["0.0680","100.00"],["0.0700","406.55"],["0.0720","100.00"],["0.0740","100.00"],["0.0760","100.00"],["0.0780","100.00"],["0.0800","235.35"],["0.0820","100.00"],["0.0840","100.00"],["0.0860","100.00"],["0.0880","101.00"],["0.0900","116.00"],["0.0920","100.00"],["0.0940","100.00"],["0.0960","100.00"],["0.0980","100.00"],["0.1000","237.34"],["0.1100","210.00"],["0.1200","376.29"],["0.1300","217.00"],["0.1400","1116.00"],["0.1500","130.00"],["0.1600","475.00"],["0.1700","110.00"],["0.1800","100.00"],["0.1900","440.37"],["0.2000","9125.00"],["0.2100","1167.00"],["0.2200","103.39"],["0.2300","5099.00"],["0.2400","114.00"],["0.2500","135.00"],["0.2600","94.35"],["0.2700","110.00"],["0.2800","100.00"],["0.2900","434.00"],["0.3000","102.00"],["0.3100","102.00"],["0.3200","698.56"],["0.3300","122.00"],["0.3400","2291.86"],["0.3500","233.76"]]}}

{"type":"orderbook_delta","sid":1,"seq":2,"msg":{"market_ticker":"KXBTC15M-26MAY141815-15","market_id":"9b5194ce-fa5b-4fa6-a79f-003263374118","price_dollars":"0.3400","delta_fp":"-78.00","side":"no","ts":"2026-05-14T22:08:33.694567Z","ts_ms":1778796513694}}

{"type":"orderbook_delta","sid":1,"seq":3,"msg":{"market_ticker":"KXBTC15M-26MAY141815-15","market_id":"9b5194ce-fa5b-4fa6-a79f-003263374118","price_dollars":"0.5900","delta_fp":"-2.00","side":"yes","ts":"2026-05-14T22:08:33.696333Z","ts_ms":1778796513696}}

{"type":"orderbook_delta","sid":1,"seq":4,"msg":{"market_ticker":"KXBTC15M-26MAY141815-15","market_id":"9b5194ce-fa5b-4fa6-a79f-003263374118","price_dollars":"0.6000","delta_fp":"2.00","side":"yes","ts":"2026-05-14T22:08:33.696333Z","ts_ms":1778796513696}}

{"type":"orderbook_delta","sid":1,"seq":5,"msg":{"market_ticker":"KXBTC15M-26MAY141815-15","market_id":"9b5194ce-fa5b-4fa6-a79f-003263374118","price_dollars":"0.5900","delta_fp":"-400.00","side":"yes","ts":"2026-05-14T22:08:33.69861Z","ts_ms":1778796513698}}

{"type":"orderbook_delta","sid":1,"seq":6,"msg":{"market_ticker":"KXBTC15M-26MAY141815-15","market_id":"9b5194ce-fa5b-4fa6-a79f-003263374118","price_dollars":"0.6000","delta_fp":"400.00","side":"yes","ts":"2026-05-14T22:08:33.69861Z","ts_ms":1778796513698}}

{"type":"orderbook_delta","sid":1,"seq":7,"msg":{"market_ticker":"KXBTC15M-26MAY141815-15","market_id":"9b5194ce-fa5b-4fa6-a79f-003263374118","price_dollars":"0.3500","delta_fp":"-81.00","side":"no","ts":"2026-05-14T22:08:33.700718Z","ts_ms":1778796513700}}

{"type":"orderbook_delta","sid":1,"seq":8,"msg":{"market_ticker":"KXBTC15M-26MAY141815-15","market_id":"9b5194ce-fa5b-4fa6-a79f-003263374118","price_dollars":"0.2900","delta_fp":"-75.00","side":"no","ts":"2026-05-14T22:08:33.710287Z","ts_ms":1778796513710}}

{"type":"orderbook_delta","sid":1,"seq":9,"msg":{"market_ticker":"KXBTC15M-26MAY141815-15","market_id":"9b5194ce-fa5b-4fa6-a79f-003263374118","price_dollars":"0.3500","delta_fp":"75.00","side":"no","ts":"2026-05-14T22:08:33.710287Z","ts_ms":1778796513710}}

{"type":"orderbook_delta","sid":1,"seq":10,"msg":{"market_ticker":"KXBTC15M-26MAY141815-15","market_id":"9b5194ce-fa5b-4fa6-a79f-003263374118","price_dollars":"0.3300","delta_fp":"81.00","side":"no","ts":"2026-05-14T22:08:33.711568Z","ts_ms":1778796513711}}

{"type":"orderbook_delta","sid":1,"seq":11,"msg":{"market_ticker":"KXBTC15M-26MAY141815-15","market_id":"9b5194ce-fa5b-4fa6-a79f-003263374118","price_dollars":"0.3200","delta_fp":"-2.00","side":"no","ts":"2026-05-14T22:08:33.720516Z","ts_ms":1778796513720}}

{"type":"orderbook_delta","sid":1,"seq":12,"msg":{"market_ticker":"KXBTC15M-26MAY141815-15","market_id":"9b5194ce-fa5b-4fa6-a79f-003263374118","price_dollars":"0.3100","delta_fp":"2.00","side":"no","ts":"2026-05-14T22:08:33.720516Z","ts_ms":1778796513720}}

{"type":"orderbook_delta","sid":1,"seq":13,"msg":{"market_ticker":"KXBTC15M-26MAY141815-15","market_id":"9b5194ce-fa5b-4fa6-a79f-003263374118","price_dollars":"0.5800","delta_fp":"-75.00","side":"yes","ts":"2026-05-14T22:08:33.743852Z","ts_ms":1778796513743}}

{"type":"orderbook_delta","sid":1,"seq":14,"msg":{"market_ticker":"KXBTC15M-26MAY141815-15","market_id":"9b5194ce-fa5b-4fa6-a79f-003263374118","price_dollars":"0.6300","delta_fp":"75.00","side":"yes","ts":"2026-05-14T22:08:33.743852Z","ts_ms":1778796513743}}

{"type":"orderbook_delta","sid":1,"seq":15,"msg":{"market_ticker":"KXBTC15M-26MAY141815-15","market_id":"9b5194ce-fa5b-4fa6-a79f-003263374118","price_dollars":"0.3500","delta_fp":"-75.00","side":"no","ts":"2026-05-14T22:08:33.744266Z","ts_ms":1778796513744}}

{"type":"orderbook_delta","sid":1,"seq":16,"msg":{"market_ticker":"KXBTC15M-26MAY141815-15","market_id":"9b5194ce-fa5b-4fa6-a79f-003263374118","price_dollars":"0.2900","delta_fp":"75.00","side":"no","ts":"2026-05-14T22:08:33.744266Z","ts_ms":1778796513744}}

{"type":"orderbook_delta","sid":1,"seq":17,"msg":{"market_ticker":"KXBTC15M-26MAY141815-15","market_id":"9b5194ce-fa5b-4fa6-a79f-003263374118","price_dollars":"0.1500","delta_fp":"-40.00","side":"yes","ts":"2026-05-14T22:08:33.745839Z","ts_ms":1778796513745}}

{"type":"orderbook_delta","sid":1,"seq":18,"msg":{"market_ticker":"KXBTC15M-26MAY141815-15","market_id":"9b5194ce-fa5b-4fa6-a79f-003263374118","price_dollars":"0.1400","delta_fp":"40.00","side":"yes","ts":"2026-05-14T22:08:33.745839Z","ts_ms":1778796513745}}

{"type":"orderbook_delta","sid":1,"seq":19,"msg":{"market_ticker":"KXBTC15M-26MAY141815-15","market_id":"9b5194ce-fa5b-4fa6-a79f-003263374118","price_dollars":"0.3500","delta_fp":"-53.05","side":"no","ts":"2026-05-14T22:08:33.767319Z","ts_ms":1778796513767}}

{"type":"orderbook_delta","sid":1,"seq":20,"msg":{"market_ticker":"KXBTC15M-26MAY141815-15","market_id":"9b5194ce-fa5b-4fa6-a79f-003263374118","price_dollars":"0.3500","delta_fp":"-46.95","side":"no","ts":"2026-05-14T22:08:33.767319Z","ts_ms":1778796513767}}

{"type":"orderbook_delta","sid":1,"seq":21,"msg":{"market_ticker":"KXBTC15M-26MAY141815-15","market_id":"9b5194ce-fa5b-4fa6-a79f-003263374118","price_dollars":"0.3200","delta_fp":"-400.00","side":"no","ts":"2026-05-14T22:08:33.79665Z","ts_ms":1778796513796}}

{"type":"orderbook_delta","sid":1,"seq":22,"msg":{"market_ticker":"KXBTC15M-26MAY141815-15","market_id":"9b5194ce-fa5b-4fa6-a79f-003263374118","price_dollars":"0.3100","delta_fp":"400.00","side":"no","ts":"2026-05-14T22:08:33.79665Z","ts_ms":1778796513796}}

{"type":"orderbook_delta","sid":1,"seq":23,"msg":{"market_ticker":"KXBTC15M-26MAY141815-15","market_id":"9b5194ce-fa5b-4fa6-a79f-003263374118","price_dollars":"0.6300","delta_fp":"-75.00","side":"yes","ts":"2026-05-14T22:08:33.80734Z","ts_ms":1778796513807}}

{"type":"orderbook_delta","sid":1,"seq":24,"msg":{"market_ticker":"KXBTC15M-26MAY141815-15","market_id":"9b5194ce-fa5b-4fa6-a79f-003263374118","price_dollars":"0.5700","delta_fp":"75.00","side":"yes","ts":"2026-05-14T22:08:33.80734Z","ts_ms":1778796513807}}

{"type":"orderbook_delta","sid":1,"seq":25,"msg":{"market_ticker":"KXBTC15M-26MAY141815-15","market_id":"9b5194ce-fa5b-4fa6-a79f-003263374118","price_dollars":"0.3500","delta_fp":"-52.76","side":"no","ts":"2026-05-14T22:08:33.808143Z","ts_ms":1778796513808}}

{"type":"orderbook_delta","sid":1,"seq":26,"msg":{"market_ticker":"KXBTC15M-26MAY141815-15","market_id":"9b5194ce-fa5b-4fa6-a79f-003263374118","price_dollars":"0.3100","delta_fp":"-400.00","side":"no","ts":"2026-05-14T22:08:33.839596Z","ts_ms":1778796513839}}

{"type":"orderbook_delta","sid":1,"seq":27,"msg":{"market_ticker":"KXBTC15M-26MAY141815-15","market_id":"9b5194ce-fa5b-4fa6-a79f-003263374118","price_dollars":"0.3200","delta_fp":"400.00","side":"no","ts":"2026-05-14T22:08:33.839596Z","ts_ms":1778796513839}}

{"type":"orderbook_delta","sid":1,"seq":28,"msg":{"market_ticker":"KXBTC15M-26MAY141815-15","market_id":"9b5194ce-fa5b-4fa6-a79f-003263374118","price_dollars":"0.6300","delta_fp":"-66.36","side":"yes","ts":"2026-05-14T22:08:33.845828Z","ts_ms":1778796513845}}

{"type":"orderbook_delta","sid":1,"seq":29,"msg":{"market_ticker":"KXBTC15M-26MAY141815-15","market_id":"9b5194ce-fa5b-4fa6-a79f-003263374118","price_dollars":"0.6300","delta_fp":"-61.86","side":"yes","ts":"2026-05-14T22:08:33.845828Z","ts_ms":1778796513845}}

{"type":"orderbook_delta","sid":1,"seq":30,"msg":{"market_ticker":"KXBTC15M-26MAY141815-15","market_id":"9b5194ce-fa5b-4fa6-a79f-003263374118","price_dollars":"0.2900","delta_fp":"-75.00","side":"no","ts":"2026-05-14T22:08:33.848282Z","ts_ms":1778796513848}}

{"type":"orderbook_delta","sid":1,"seq":31,"msg":{"market_ticker":"KXBTC15M-26MAY141815-15","market_id":"9b5194ce-fa5b-4fa6-a79f-003263374118","price_dollars":"0.3500","delta_fp":"75.00","side":"no","ts":"2026-05-14T22:08:33.848282Z","ts_ms":1778796513848}}

{"type":"orderbook_delta","sid":1,"seq":32,"msg":{"market_ticker":"KXBTC15M-26MAY141815-15","market_id":"9b5194ce-fa5b-4fa6-a79f-003263374118","price_dollars":"0.3400","delta_fp":"-10.00","side":"no","ts":"2026-05-14T22:08:33.85486Z","ts_ms":1778796513854}}

{"type":"orderbook_delta","sid":1,"seq":33,"msg":{"market_ticker":"KXBTC15M-26MAY141815-15","market_id":"9b5194ce-fa5b-4fa6-a79f-003263374118","price_dollars":"0.3300","delta_fp":"16.00","side":"no","ts":"2026-05-14T22:08:33.85486Z","ts_ms":1778796513854}}

{"type":"orderbook_delta","sid":1,"seq":34,"msg":{"market_ticker":"KXBTC15M-26MAY141815-15","market_id":"9b5194ce-fa5b-4fa6-a79f-003263374118","price_dollars":"0.3300","delta_fp":"-10.00","side":"no","ts":"2026-05-14T22:08:33.855176Z","ts_ms":1778796513855}}

{"type":"orderbook_delta","sid":1,"seq":35,"msg":{"market_ticker":"KXBTC15M-26MAY141815-15","market_id":"9b5194ce-fa5b-4fa6-a79f-003263374118","price_dollars":"0.3400","delta_fp":"10.00","side":"no","ts":"2026-05-14T22:08:33.855176Z","ts_ms":1778796513855}}

{"type":"orderbook_delta","sid":1,"seq":36,"msg":{"market_ticker":"KXBTC15M-26MAY141815-15","market_id":"9b5194ce-fa5b-4fa6-a79f-003263374118","price_dollars":"0.6300","delta_fp":"-10.00","side":"yes","ts":"2026-05-14T22:08:33.855867Z","ts_ms":1778796513855}}

{"type":"orderbook_delta","sid":1,"seq":37,"msg":{"market_ticker":"KXBTC15M-26MAY141815-15","market_id":"9b5194ce-fa5b-4fa6-a79f-003263374118","price_dollars":"0.6200","delta_fp":"10.00","side":"yes","ts":"2026-05-14T22:08:33.855867Z","ts_ms":1778796513855}}

{"type":"orderbook_delta","sid":1,"seq":38,"msg":{"market_ticker":"KXBTC15M-26MAY141815-15","market_id":"9b5194ce-fa5b-4fa6-a79f-003263374118","price_dollars":"0.3500","delta_fp":"100.00","side":"no","ts":"2026-05-14T22:08:33.862425Z","ts_ms":1778796513862}}

{"type":"orderbook_delta","sid":1,"seq":39,"msg":{"market_ticker":"KXBTC15M-26MAY141815-15","market_id":"9b5194ce-fa5b-4fa6-a79f-003263374118","price_dollars":"0.3400","delta_fp":"100.00","side":"no","ts":"2026-05-14T22:08:33.867858Z","ts_ms":1778796513867}}

{"type":"orderbook_delta","sid":1,"seq":40,"msg":{"market_ticker":"KXBTC15M-26MAY141815-15","market_id":"9b5194ce-fa5b-4fa6-a79f-003263374118","price_dollars":"0.3400","delta_fp":"-100.00","side":"no","ts":"2026-05-14T22:08:33.880427Z","ts_ms":1778796513880}}

{"type":"orderbook_delta","sid":1,"seq":41,"msg":{"market_ticker":"KXBTC15M-26MAY141815-15","market_id":"9b5194ce-fa5b-4fa6-a79f-003263374118","price_dollars":"0.3500","delta_fp":"-75.00","side":"no","ts":"2026-05-14T22:08:33.887681Z","ts_ms":1778796513887}}

{"type":"orderbook_delta","sid":1,"seq":42,"msg":{"market_ticker":"KXBTC15M-26MAY141815-15","market_id":"9b5194ce-fa5b-4fa6-a79f-003263374118","price_dollars":"0.2900","delta_fp":"75.00","side":"no","ts":"2026-05-14T22:08:33.887681Z","ts_ms":1778796513887}}

{"type":"orderbook_delta","sid":1,"seq":43,"msg":{"market_ticker":"KXBTC15M-26MAY141815-15","market_id":"9b5194ce-fa5b-4fa6-a79f-003263374118","price_dollars":"0.6300","delta_fp":"-1.29","side":"yes","ts":"2026-05-14T22:08:33.891891Z","ts_ms":1778796513891}}

{"type":"orderbook_delta","sid":1,"seq":44,"msg":{"market_ticker":"KXBTC15M-26MAY141815-15","market_id":"9b5194ce-fa5b-4fa6-a79f-003263374118","price_dollars":"0.3300","delta_fp":"-16.00","side":"no","ts":"2026-05-14T22:08:33.896965Z","ts_ms":1778796513896}}

{"type":"orderbook_delta","sid":1,"seq":45,"msg":{"market_ticker":"KXBTC15M-26MAY141815-15","market_id":"9b5194ce-fa5b-4fa6-a79f-003263374118","price_dollars":"0.3400","delta_fp":"13.00","side":"no","ts":"2026-05-14T22:08:33.896965Z","ts_ms":1778796513896}}

{"type":"orderbook_delta","sid":1,"seq":46,"msg":{"market_ticker":"KXBTC15M-26MAY141815-15","market_id":"9b5194ce-fa5b-4fa6-a79f-003263374118","price_dollars":"0.3400","delta_fp":"-764.87","side":"no","ts":"2026-05-14T22:08:33.900729Z","ts_ms":1778796513900}}

{"type":"orderbook_delta","sid":1,"seq":47,"msg":{"market_ticker":"KXBTC15M-26MAY141815-15","market_id":"9b5194ce-fa5b-4fa6-a79f-003263374118","price_dollars":"0.3300","delta_fp":"1000.87","side":"no","ts":"2026-05-14T22:08:33.900729Z","ts_ms":1778796513900}}

{"type":"orderbook_delta","sid":1,"seq":48,"msg":{"market_ticker":"KXBTC15M-26MAY141815-15","market_id":"9b5194ce-fa5b-4fa6-a79f-003263374118","price_dollars":"0.3400","delta_fp":"-236.00","side":"no","ts":"2026-05-14T22:08:33.902783Z","ts_ms":1778796513902}}

{"type":"orderbook_delta","sid":1,"seq":49,"msg":{"market_ticker":"KXBTC15M-26MAY141815-15","market_id":"9b5194ce-fa5b-4fa6-a79f-003263374118","price_dollars":"0.3400","delta_fp":"-10.00","side":"no","ts":"2026-05-14T22:08:33.902986Z","ts_ms":1778796513902}}

{"type":"orderbook_delta","sid":1,"seq":50,"msg":{"market_ticker":"KXBTC15M-26MAY141815-15","market_id":"9b5194ce-fa5b-4fa6-a79f-003263374118","price_dollars":"0.3300","delta_fp":"10.00","side":"no","ts":"2026-05-14T22:08:33.902986Z","ts_ms":1778796513902}}

{"type":"orderbook_delta","sid":1,"seq":51,"msg":{"market_ticker":"KXBTC15M-26MAY141815-15","market_id":"9b5194ce-fa5b-4fa6-a79f-003263374118","price_dollars":"0.5700","delta_fp":"-75.00","side":"yes","ts":"2026-05-14T22:08:33.916409Z","ts_ms":1778796513916}}

{"type":"orderbook_delta","sid":1,"seq":52,"msg":{"market_ticker":"KXBTC15M-26MAY141815-15","market_id":"9b5194ce-fa5b-4fa6-a79f-003263374118","price_dollars":"0.6300","delta_fp":"75.00","side":"yes","ts":"2026-05-14T22:08:33.916409Z","ts_ms":1778796513916}}

{"type":"orderbook_delta","sid":1,"seq":53,"msg":{"market_ticker":"KXBTC15M-26MAY141815-15","market_id":"9b5194ce-fa5b-4fa6-a79f-003263374118","price_dollars":"0.1400","delta_fp":"-40.00","side":"yes","ts":"2026-05-14T22:08:33.930388Z","ts_ms":1778796513930}}

{"type":"orderbook_delta","sid":1,"seq":54,"msg":{"market_ticker":"KXBTC15M-26MAY141815-15","market_id":"9b5194ce-fa5b-4fa6-a79f-003263374118","price_dollars":"0.1500","delta_fp":"40.00","side":"yes","ts":"2026-05-14T22:08:33.930388Z","ts_ms":1778796513930}}

{"type":"orderbook_delta","sid":1,"seq":55,"msg":{"market_ticker":"KXBTC15M-26MAY141815-15","market_id":"9b5194ce-fa5b-4fa6-a79f-003263374118","price_dollars":"0.5600","delta_fp":"-2.00","side":"yes","ts":"2026-05-14T22:08:33.931474Z","ts_ms":1778796513931}}

{"type":"orderbook_delta","sid":1,"seq":56,"msg":{"market_ticker":"KXBTC15M-26MAY141815-15","market_id":"9b5194ce-fa5b-4fa6-a79f-003263374118","price_dollars":"0.3200","delta_fp":"-400.00","side":"no","ts":"2026-05-14T22:08:33.938709Z","ts_ms":1778796513938}}

{"type":"orderbook_delta","sid":1,"seq":57,"msg":{"market_ticker":"KXBTC15M-26MAY141815-15","market_id":"9b5194ce-fa5b-4fa6-a79f-003263374118","price_dollars":"0.3100","delta_fp":"400.00","side":"no","ts":"2026-05-14T22:08:33.938709Z","ts_ms":1778796513938}}

{"type":"orderbook_delta","sid":1,"seq":58,"msg":{"market_ticker":"KXBTC15M-26MAY141815-15","market_id":"9b5194ce-fa5b-4fa6-a79f-003263374118","price_dollars":"0.6300","delta_fp":"-75.00","side":"yes","ts":"2026-05-14T22:08:33.946693Z","ts_ms":1778796513946}}

{"type":"orderbook_delta","sid":1,"seq":59,"msg":{"market_ticker":"KXBTC15M-26MAY141815-15","market_id":"9b5194ce-fa5b-4fa6-a79f-003263374118","price_dollars":"0.5700","delta_fp":"75.00","side":"yes","ts":"2026-05-14T22:08:33.946693Z","ts_ms":1778796513946}}

{"type":"orderbook_delta","sid":1,"seq":60,"msg":{"market_ticker":"KXBTC15M-26MAY141815-15","market_id":"9b5194ce-fa5b-4fa6-a79f-003263374118","price_dollars":"0.6200","delta_fp":"-10.00","side":"yes","ts":"2026-05-14T22:08:33.947486Z","ts_ms":1778796513947}}

{"type":"orderbook_delta","sid":1,"seq":61,"msg":{"market_ticker":"KXBTC15M-26MAY141815-15","market_id":"9b5194ce-fa5b-4fa6-a79f-003263374118","price_dollars":"0.6300","delta_fp":"10.00","side":"yes","ts":"2026-05-14T22:08:33.947486Z","ts_ms":1778796513947}}

{"type":"orderbook_delta","sid":1,"seq":62,"msg":{"market_ticker":"KXBTC15M-26MAY141815-15","market_id":"9b5194ce-fa5b-4fa6-a79f-003263374118","price_dollars":"0.6200","delta_fp":"2.00","side":"yes","ts":"2026-05-14T22:08:33.959866Z","ts_ms":1778796513959}}

{"type":"orderbook_delta","sid":1,"seq":63,"msg":{"market_ticker":"KXBTC15M-26MAY141815-15","market_id":"9b5194ce-fa5b-4fa6-a79f-003263374118","price_dollars":"0.5500","delta_fp":"-15.00","side":"yes","ts":"2026-05-14T22:08:33.974772Z","ts_ms":1778796513974}}

{"type":"orderbook_delta","sid":1,"seq":64,"msg":{"market_ticker":"KXBTC15M-26MAY141815-15","market_id":"9b5194ce-fa5b-4fa6-a79f-003263374118","price_dollars":"0.5600","delta_fp":"15.00","side":"yes","ts":"2026-05-14T22:08:33.974772Z","ts_ms":1778796513974}}

{"type":"orderbook_delta","sid":1,"seq":65,"msg":{"market_ticker":"KXBTC15M-26MAY141815-15","market_id":"9b5194ce-fa5b-4fa6-a79f-003263374118","price_dollars":"0.6000","delta_fp":"-400.00","side":"yes","ts":"2026-05-14T22:08:33.996299Z","ts_ms":1778796513996}}

{"type":"orderbook_delta","sid":1,"seq":66,"msg":{"market_ticker":"KXBTC15M-26MAY141815-15","market_id":"9b5194ce-fa5b-4fa6-a79f-003263374118","price_dollars":"0.6100","delta_fp":"400.00","side":"yes","ts":"2026-05-14T22:08:33.996299Z","ts_ms":1778796513996}}

{"type":"orderbook_delta","sid":1,"seq":67,"msg":{"market_ticker":"KXBTC15M-26MAY141815-15","market_id":"9b5194ce-fa5b-4fa6-a79f-003263374118","price_dollars":"0.3100","delta_fp":"-400.00","side":"no","ts":"2026-05-14T22:08:33.996718Z","ts_ms":1778796513996}}

{"type":"orderbook_delta","sid":1,"seq":68,"msg":{"market_ticker":"KXBTC15M-26MAY141815-15","market_id":"9b5194ce-fa5b-4fa6-a79f-003263374118","price_dollars":"0.3000","delta_fp":"400.00","side":"no","ts":"2026-05-14T22:08:33.996718Z","ts_ms":1778796513996}}

{"type":"orderbook_delta","sid":1,"seq":69,"msg":{"market_ticker":"KXBTC15M-26MAY141815-15","market_id":"9b5194ce-fa5b-4fa6-a79f-003263374118","price_dollars":"0.2900","delta_fp":"-75.00","side":"no","ts":"2026-05-14T22:08:33.999149Z","ts_ms":1778796513999}}

{"type":"orderbook_delta","sid":1,"seq":70,"msg":{"market_ticker":"KXBTC15M-26MAY141815-15","market_id":"9b5194ce-fa5b-4fa6-a79f-003263374118","price_dollars":"0.3500","delta_fp":"75.00","side":"no","ts":"2026-05-14T22:08:33.999149Z","ts_ms":1778796513999}}

{"type":"orderbook_delta","sid":1,"seq":71,"msg":{"market_ticker":"KXBTC15M-26MAY141815-15","market_id":"9b5194ce-fa5b-4fa6-a79f-003263374118","price_dollars":"0.3000","delta_fp":"-400.00","side":"no","ts":"2026-05-14T22:08:34.007086Z","ts_ms":1778796514007}}

{"type":"orderbook_delta","sid":1,"seq":72,"msg":{"market_ticker":"KXBTC15M-26MAY141815-15","market_id":"9b5194ce-fa5b-4fa6-a79f-003263374118","price_dollars":"0.2900","delta_fp":"400.00","side":"no","ts":"2026-05-14T22:08:34.007086Z","ts_ms":1778796514007}}

{"type":"orderbook_delta","sid":1,"seq":73,"msg":{"market_ticker":"KXBTC15M-26MAY141815-15","market_id":"9b5194ce-fa5b-4fa6-a79f-003263374118","price_dollars":"0.3400","delta_fp":"-13.00","side":"no","ts":"2026-05-14T22:08:34.00763Z","ts_ms":1778796514007}}

{"type":"orderbook_delta","sid":1,"seq":74,"msg":{"market_ticker":"KXBTC15M-26MAY141815-15","market_id":"9b5194ce-fa5b-4fa6-a79f-003263374118","price_dollars":"0.3300","delta_fp":"18.00","side":"no","ts":"2026-05-14T22:08:34.00763Z","ts_ms":1778796514007}}

{"type":"orderbook_delta","sid":1,"seq":75,"msg":{"market_ticker":"KXBTC15M-26MAY141815-15","market_id":"9b5194ce-fa5b-4fa6-a79f-003263374118","price_dollars":"0.2300","delta_fp":"-4999.00","side":"no","ts":"2026-05-14T22:08:34.009462Z","ts_ms":1778796514009}}

{"type":"orderbook_delta","sid":1,"seq":76,"msg":{"market_ticker":"KXBTC15M-26MAY141815-15","market_id":"9b5194ce-fa5b-4fa6-a79f-003263374118","price_dollars":"0.2900","delta_fp":"-249.00","side":"no","ts":"2026-05-14T22:08:34.009462Z","ts_ms":1778796514009}}

{"type":"orderbook_delta","sid":1,"seq":77,"msg":{"market_ticker":"KXBTC15M-26MAY141815-15","market_id":"9b5194ce-fa5b-4fa6-a79f-003263374118","price_dollars":"0.2000","delta_fp":"-6249.00","side":"no","ts":"2026-05-14T22:08:34.011089Z","ts_ms":1778796514011}}

{"type":"orderbook_delta","sid":1,"seq":78,"msg":{"market_ticker":"KXBTC15M-26MAY141815-15","market_id":"9b5194ce-fa5b-4fa6-a79f-003263374118","price_dollars":"0.5900","delta_fp":"-249.00","side":"yes","ts":"2026-05-14T22:08:34.01229Z","ts_ms":1778796514012}}

{"type":"orderbook_delta","sid":1,"seq":79,"msg":{"market_ticker":"KXBTC15M-26MAY141815-15","market_id":"9b5194ce-fa5b-4fa6-a79f-003263374118","price_dollars":"0.4600","delta_fp":"-6249.00","side":"yes","ts":"2026-05-14T22:08:34.01269Z","ts_ms":1778796514012}}

{"type":"orderbook_delta","sid":1,"seq":80,"msg":{"market_ticker":"KXBTC15M-26MAY141815-15","market_id":"9b5194ce-fa5b-4fa6-a79f-003263374118","price_dollars":"0.5000","delta_fp":"-4999.00","side":"yes","ts":"2026-05-14T22:08:34.01269Z","ts_ms":1778796514012}}

{"type":"orderbook_delta","sid":1,"seq":81,"msg":{"market_ticker":"KXBTC15M-26MAY141815-15","market_id":"9b5194ce-fa5b-4fa6-a79f-003263374118","price_dollars":"0.3100","delta_fp":"-2.00","side":"no","ts":"2026-05-14T22:08:34.017141Z","ts_ms":1778796514017}}

{"type":"orderbook_delta","sid":1,"seq":82,"msg":{"market_ticker":"KXBTC15M-26MAY141815-15","market_id":"9b5194ce-fa5b-4fa6-a79f-003263374118","price_dollars":"0.2900","delta_fp":"2.00","side":"no","ts":"2026-05-14T22:08:34.017141Z","ts_ms":1778796514017}}

{"type":"orderbook_delta","sid":1,"seq":83,"msg":{"market_ticker":"KXBTC15M-26MAY141815-15","market_id":"9b5194ce-fa5b-4fa6-a79f-003263374118","price_dollars":"0.5600","delta_fp":"-251.00","side":"yes","ts":"2026-05-14T22:08:34.020347Z","ts_ms":1778796514020}}

{"type":"orderbook_delta","sid":1,"seq":84,"msg":{"market_ticker":"KXBTC15M-26MAY141815-15","market_id":"9b5194ce-fa5b-4fa6-a79f-003263374118","price_dollars":"0.1200","delta_fp":"2.00","side":"no","ts":"2026-05-14T22:08:34.032087Z","ts_ms":1778796514032}}

{"type":"orderbook_delta","sid":1,"seq":85,"msg":{"market_ticker":"KXBTC15M-26MAY141815-15","market_id":"9b5194ce-fa5b-4fa6-a79f-003263374118","price_dollars":"0.3500","delta_fp":"-75.00","side":"no","ts":"2026-05-14T22:08:34.03661Z","ts_ms":1778796514036}}

{"type":"orderbook_delta","sid":1,"seq":86,"msg":{"market_ticker":"KXBTC15M-26MAY141815-15","market_id":"9b5194ce-fa5b-4fa6-a79f-003263374118","price_dollars":"0.2900","delta_fp":"75.00","side":"no","ts":"2026-05-14T22:08:34.03661Z","ts_ms":1778796514036}}

{"type":"orderbook_delta","sid":1,"seq":87,"msg":{"market_ticker":"KXBTC15M-26MAY141815-15","market_id":"9b5194ce-fa5b-4fa6-a79f-003263374118","price_dollars":"0.5600","delta_fp":"2.00","side":"yes","ts":"2026-05-14T22:08:34.037946Z","ts_ms":1778796514037}}

{"type":"orderbook_delta","sid":1,"seq":88,"msg":{"market_ticker":"KXBTC15M-26MAY141815-15","market_id":"9b5194ce-fa5b-4fa6-a79f-003263374118","price_dollars":"0.6000","delta_fp":"-2.00","side":"yes","ts":"2026-05-14T22:08:34.037954Z","ts_ms":1778796514037}}

{"type":"orderbook_delta","sid":1,"seq":89,"msg":{"market_ticker":"KXBTC15M-26MAY141815-15","market_id":"9b5194ce-fa5b-4fa6-a79f-003263374118","price_dollars":"0.6200","delta_fp":"2.00","side":"yes","ts":"2026-05-14T22:08:34.037954Z","ts_ms":1778796514037}}

{"type":"orderbook_delta","sid":1,"seq":90,"msg":{"market_ticker":"KXBTC15M-26MAY141815-15","market_id":"9b5194ce-fa5b-4fa6-a79f-003263374118","price_dollars":"0.6100","delta_fp":"-400.00","side":"yes","ts":"2026-05-14T22:08:34.040951Z","ts_ms":1778796514040}}

{"type":"orderbook_delta","sid":1,"seq":91,"msg":{"market_ticker":"KXBTC15M-26MAY141815-15","market_id":"9b5194ce-fa5b-4fa6-a79f-003263374118","price_dollars":"0.6200","delta_fp":"400.00","side":"yes","ts":"2026-05-14T22:08:34.040951Z","ts_ms":1778796514040}}

{"type":"orderbook_delta","sid":1,"seq":92,"msg":{"market_ticker":"KXBTC15M-26MAY141815-15","market_id":"9b5194ce-fa5b-4fa6-a79f-003263374118","price_dollars":"0.6100","delta_fp":"-81.00","side":"yes","ts":"2026-05-14T22:08:34.041989Z","ts_ms":1778796514041}}

{"type":"orderbook_delta","sid":1,"seq":93,"msg":{"market_ticker":"KXBTC15M-26MAY141815-15","market_id":"9b5194ce-fa5b-4fa6-a79f-003263374118","price_dollars":"0.6300","delta_fp":"81.00","side":"yes","ts":"2026-05-14T22:08:34.041989Z","ts_ms":1778796514041}}

{"type":"orderbook_delta","sid":1,"seq":94,"msg":{"market_ticker":"KXBTC15M-26MAY141815-15","market_id":"9b5194ce-fa5b-4fa6-a79f-003263374118","price_dollars":"0.5700","delta_fp":"1.00","side":"yes","ts":"2026-05-14T22:08:34.045181Z","ts_ms":1778796514045}}

{"type":"orderbook_delta","sid":1,"seq":95,"msg":{"market_ticker":"KXBTC15M-26MAY141815-15","market_id":"9b5194ce-fa5b-4fa6-a79f-003263374118","price_dollars":"0.5600","delta_fp":"1.00","side":"yes","ts":"2026-05-14T22:08:34.045642Z","ts_ms":1778796514045}}

{"type":"orderbook_delta","sid":1,"seq":96,"msg":{"market_ticker":"KXBTC15M-26MAY141815-15","market_id":"9b5194ce-fa5b-4fa6-a79f-003263374118","price_dollars":"0.3200","delta_fp":"1.00","side":"no","ts":"2026-05-14T22:08:34.046008Z","ts_ms":1778796514046}}

{"type":"orderbook_delta","sid":1,"seq":97,"msg":{"market_ticker":"KXBTC15M-26MAY141815-15","market_id":"9b5194ce-fa5b-4fa6-a79f-003263374118","price_dollars":"0.3000","delta_fp":"1.00","side":"no","ts":"2026-05-14T22:08:34.046412Z","ts_ms":1778796514046}}

{"type":"orderbook_delta","sid":1,"seq":98,"msg":{"market_ticker":"KXBTC15M-26MAY141815-15","market_id":"9b5194ce-fa5b-4fa6-a79f-003263374118","price_dollars":"0.5700","delta_fp":"-75.00","side":"yes","ts":"2026-05-14T22:08:34.049029Z","ts_ms":1778796514049}}

{"type":"orderbook_delta","sid":1,"seq":99,"msg":{"market_ticker":"KXBTC15M-26MAY141815-15","market_id":"9b5194ce-fa5b-4fa6-a79f-003263374118","price_dollars":"0.6300","delta_fp":"75.00","side":"yes","ts":"2026-05-14T22:08:34.049029Z","ts_ms":1778796514049}}

{"type":"orderbook_delta","sid":1,"seq":100,"msg":{"market_ticker":"KXBTC15M-26MAY141815-15","market_id":"9b5194ce-fa5b-4fa6-a79f-003263374118","price_dollars":"0.5700","delta_fp":"251.00","side":"yes","ts":"2026-05-14T22:08:34.049379Z","ts_ms":1778796514049}}

{"type":"orderbook_delta","sid":1,"seq":101,"msg":{"market_ticker":"KXBTC15M-26MAY141815-15","market_id":"9b5194ce-fa5b-4fa6-a79f-003263374118","price_dollars":"0.5600","delta_fp":"-15.00","side":"yes","ts":"2026-05-14T22:08:34.068178Z","ts_ms":1778796514068}}

{"type":"orderbook_delta","sid":1,"seq":102,"msg":{"market_ticker":"KXBTC15M-26MAY141815-15","market_id":"9b5194ce-fa5b-4fa6-a79f-003263374118","price_dollars":"0.5700","delta_fp":"15.00","side":"yes","ts":"2026-05-14T22:08:34.068178Z","ts_ms":1778796514068}}

{"type":"orderbook_delta","sid":1,"seq":103,"msg":{"market_ticker":"KXBTC15M-26MAY141815-15","market_id":"9b5194ce-fa5b-4fa6-a79f-003263374118","price_dollars":"0.6300","delta_fp":"-10.00","side":"yes","ts":"2026-05-14T22:08:34.104391Z","ts_ms":1778796514104}}

{"type":"orderbook_delta","sid":1,"seq":104,"msg":{"market_ticker":"KXBTC15M-26MAY141815-15","market_id":"9b5194ce-fa5b-4fa6-a79f-003263374118","price_dollars":"0.6300","delta_fp":"10.00","side":"yes","ts":"2026-05-14T22:08:34.110027Z","ts_ms":1778796514110}}

{"type":"orderbook_delta","sid":1,"seq":105,"msg":{"market_ticker":"KXBTC15M-26MAY141815-15","market_id":"9b5194ce-fa5b-4fa6-a79f-003263374118","price_dollars":"0.6400","delta_fp":"100.00","side":"yes","ts":"2026-05-14T22:08:34.110228Z","ts_ms":1778796514110}}

{"type":"orderbook_delta","sid":1,"seq":106,"msg":{"market_ticker":"KXBTC15M-26MAY141815-15","market_id":"9b5194ce-fa5b-4fa6-a79f-003263374118","price_dollars":"0.3500","delta_fp":"-100.00","side":"no","ts":"2026-05-14T22:08:34.110698Z","ts_ms":1778796514110}}

{"type":"orderbook_delta","sid":1,"seq":107,"msg":{"market_ticker":"KXBTC15M-26MAY141815-15","market_id":"9b5194ce-fa5b-4fa6-a79f-003263374118","price_dollars":"0.2900","delta_fp":"-400.00","side":"no","ts":"2026-05-14T22:08:34.113833Z","ts_ms":1778796514113}}

{"type":"orderbook_delta","sid":1,"seq":108,"msg":{"market_ticker":"KXBTC15M-26MAY141815-15","market_id":"9b5194ce-fa5b-4fa6-a79f-003263374118","price_dollars":"0.3000","delta_fp":"400.00","side":"no","ts":"2026-05-14T22:08:34.113833Z","ts_ms":1778796514113}}

{"type":"orderbook_delta","sid":1,"seq":109,"msg":{"market_ticker":"KXBTC15M-26MAY141815-15","market_id":"9b5194ce-fa5b-4fa6-a79f-003263374118","price_dollars":"0.6300","delta_fp":"-10.00","side":"yes","ts":"2026-05-14T22:08:34.145105Z","ts_ms":1778796514145}}

{"type":"orderbook_delta","sid":1,"seq":110,"msg":{"market_ticker":"KXBTC15M-26MAY141815-15","market_id":"9b5194ce-fa5b-4fa6-a79f-003263374118","price_dollars":"0.6400","delta_fp":"10.00","side":"yes","ts":"2026-05-14T22:08:34.145105Z","ts_ms":1778796514145}}

{"type":"orderbook_delta","sid":1,"seq":111,"msg":{"market_ticker":"KXBTC15M-26MAY141815-15","market_id":"9b5194ce-fa5b-4fa6-a79f-003263374118","price_dollars":"0.3300","delta_fp":"-10.00","side":"no","ts":"2026-05-14T22:08:34.147464Z","ts_ms":1778796514147}}

{"type":"orderbook_delta","sid":1,"seq":112,"msg":{"market_ticker":"KXBTC15M-26MAY141815-15","market_id":"9b5194ce-fa5b-4fa6-a79f-003263374118","price_dollars":"0.3200","delta_fp":"10.00","side":"no","ts":"2026-05-14T22:08:34.147464Z","ts_ms":1778796514147}}

{"type":"orderbook_delta","sid":1,"seq":113,"msg":{"market_ticker":"KXBTC15M-26MAY141815-15","market_id":"9b5194ce-fa5b-4fa6-a79f-003263374118","price_dollars":"0.6300","delta_fp":"-75.00","side":"yes","ts":"2026-05-14T22:08:34.150356Z","ts_ms":1778796514150}}

{"type":"orderbook_delta","sid":1,"seq":114,"msg":{"market_ticker":"KXBTC15M-26MAY141815-15","market_id":"9b5194ce-fa5b-4fa6-a79f-003263374118","price_dollars":"0.6400","delta_fp":"75.00","side":"yes","ts":"2026-05-14T22:08:34.150356Z","ts_ms":1778796514150}}

{"type":"orderbook_delta","sid":1,"seq":115,"msg":{"market_ticker":"KXBTC15M-26MAY141815-15","market_id":"9b5194ce-fa5b-4fa6-a79f-003263374118","price_dollars":"0.6300","delta_fp":"-10.00","side":"yes","ts":"2026-05-14T22:08:34.151427Z","ts_ms":1778796514151}}

{"type":"orderbook_delta","sid":1,"seq":116,"msg":{"market_ticker":"KXBTC15M-26MAY141815-15","market_id":"9b5194ce-fa5b-4fa6-a79f-003263374118","price_dollars":"0.6200","delta_fp":"8.00","side":"yes","ts":"2026-05-14T22:08:34.15581Z","ts_ms":1778796514155}}

{"type":"orderbook_delta","sid":1,"seq":117,"msg":{"market_ticker":"KXBTC15M-26MAY141815-15","market_id":"9b5194ce-fa5b-4fa6-a79f-003263374118","price_dollars":"0.3200","delta_fp":"-150.00","side":"no","ts":"2026-05-14T22:08:34.160205Z","ts_ms":1778796514160}}

{"type":"orderbook_delta","sid":1,"seq":118,"msg":{"market_ticker":"KXBTC15M-26MAY141815-15","market_id":"9b5194ce-fa5b-4fa6-a79f-003263374118","price_dollars":"0.3100","delta_fp":"150.00","side":"no","ts":"2026-05-14T22:08:34.160205Z","ts_ms":1778796514160}}

{"type":"orderbook_delta","sid":1,"seq":119,"msg":{"market_ticker":"KXBTC15M-26MAY141815-15","market_id":"9b5194ce-fa5b-4fa6-a79f-003263374118","price_dollars":"0.3400","delta_fp":"100.00","side":"no","ts":"2026-05-14T22:08:34.165487Z","ts_ms":1778796514165}}

{"type":"orderbook_delta","sid":1,"seq":120,"msg":{"market_ticker":"KXBTC15M-26MAY141815-15","market_id":"9b5194ce-fa5b-4fa6-a79f-003263374118","price_dollars":"0.6300","delta_fp":"-24.00","side":"yes","ts":"2026-05-14T22:08:34.168775Z","ts_ms":1778796514168}}

{"type":"orderbook_delta","sid":1,"seq":121,"msg":{"market_ticker":"KXBTC15M-26MAY141815-15","market_id":"9b5194ce-fa5b-4fa6-a79f-003263374118","price_dollars":"0.6500","delta_fp":"13.00","side":"yes","ts":"2026-05-14T22:08:34.168775Z","ts_ms":1778796514168}}

{"type":"orderbook_delta","sid":1,"seq":122,"msg":{"market_ticker":"KXBTC15M-26MAY141815-15","market_id":"9b5194ce-fa5b-4fa6-a79f-003263374118","price_dollars":"0.5600","delta_fp":"-2.00","side":"yes","ts":"2026-05-14T22:08:34.174198Z","ts_ms":1778796514174}}

{"type":"orderbook_delta","sid":1,"seq":123,"msg":{"market_ticker":"KXBTC15M-26MAY141815-15","market_id":"9b5194ce-fa5b-4fa6-a79f-003263374118","price_dollars":"0.1500","delta_fp":"-40.00","side":"yes","ts":"2026-05-14T22:08:34.176032Z","ts_ms":1778796514176}}

{"type":"orderbook_delta","sid":1,"seq":124,"msg":{"market_ticker":"KXBTC15M-26MAY141815-15","market_id":"9b5194ce-fa5b-4fa6-a79f-003263374118","price_dollars":"0.1400","delta_fp":"40.00","side":"yes","ts":"2026-05-14T22:08:34.176032Z","ts_ms":1778796514176}}

{"type":"orderbook_delta","sid":1,"seq":125,"msg":{"market_ticker":"KXBTC15M-26MAY141815-15","market_id":"9b5194ce-fa5b-4fa6-a79f-003263374118","price_dollars":"0.3300","delta_fp":"-18.00","side":"no","ts":"2026-05-14T22:08:34.18025Z","ts_ms":1778796514180}}

{"type":"orderbook_delta","sid":1,"seq":126,"msg":{"market_ticker":"KXBTC15M-26MAY141815-15","market_id":"9b5194ce-fa5b-4fa6-a79f-003263374118","price_dollars":"0.3200","delta_fp":"16.00","side":"no","ts":"2026-05-14T22:08:34.18025Z","ts_ms":1778796514180}}

{"type":"orderbook_delta","sid":1,"seq":127,"msg":{"market_ticker":"KXBTC15M-26MAY141815-15","market_id":"9b5194ce-fa5b-4fa6-a79f-003263374118","price_dollars":"0.6200","delta_fp":"-8.00","side":"yes","ts":"2026-05-14T22:08:34.180383Z","ts_ms":1778796514180}}

{"type":"orderbook_delta","sid":1,"seq":128,"msg":{"market_ticker":"KXBTC15M-26MAY141815-15","market_id":"9b5194ce-fa5b-4fa6-a79f-003263374118","price_dollars":"0.5500","delta_fp":"-150.00","side":"yes","ts":"2026-05-14T22:08:34.187582Z","ts_ms":1778796514187}}

{"type":"orderbook_delta","sid":1,"seq":129,"msg":{"market_ticker":"KXBTC15M-26MAY141815-15","market_id":"9b5194ce-fa5b-4fa6-a79f-003263374118","price_dollars":"0.5600","delta_fp":"150.00","side":"yes","ts":"2026-05-14T22:08:34.187582Z","ts_ms":1778796514187}}

{"type":"orderbook_delta","sid":1,"seq":130,"msg":{"market_ticker":"KXBTC15M-26MAY141815-15","market_id":"9b5194ce-fa5b-4fa6-a79f-003263374118","price_dollars":"0.6200","delta_fp":"-400.00","side":"yes","ts":"2026-05-14T22:08:34.190557Z","ts_ms":1778796514190}}

{"type":"orderbook_delta","sid":1,"seq":131,"msg":{"market_ticker":"KXBTC15M-26MAY141815-15","market_id":"9b5194ce-fa5b-4fa6-a79f-003263374118","price_dollars":"0.6300","delta_fp":"400.00","side":"yes","ts":"2026-05-14T22:08:34.190557Z","ts_ms":1778796514190}}

{"type":"orderbook_delta","sid":1,"seq":132,"msg":{"market_ticker":"KXBTC15M-26MAY141815-15","market_id":"9b5194ce-fa5b-4fa6-a79f-003263374118","price_dollars":"0.3000","delta_fp":"-400.00","side":"no","ts":"2026-05-14T22:08:34.192786Z","ts_ms":1778796514192}}

{"type":"orderbook_delta","sid":1,"seq":133,"msg":{"market_ticker":"KXBTC15M-26MAY141815-15","market_id":"9b5194ce-fa5b-4fa6-a79f-003263374118","price_dollars":"0.2900","delta_fp":"400.00","side":"no","ts":"2026-05-14T22:08:34.192786Z","ts_ms":1778796514192}}

{"type":"orderbook_delta","sid":1,"seq":134,"msg":{"market_ticker":"KXBTC15M-26MAY141815-15","market_id":"9b5194ce-fa5b-4fa6-a79f-003263374118","price_dollars":"0.6400","delta_fp":"-10.00","side":"yes","ts":"2026-05-14T22:08:34.198144Z","ts_ms":1778796514198}}

{"type":"orderbook_delta","sid":1,"seq":135,"msg":{"market_ticker":"KXBTC15M-26MAY141815-15","market_id":"9b5194ce-fa5b-4fa6-a79f-003263374118","price_dollars":"0.6300","delta_fp":"10.00","side":"yes","ts":"2026-05-14T22:08:34.198144Z","ts_ms":1778796514198}}

{"type":"orderbook_delta","sid":1,"seq":136,"msg":{"market_ticker":"KXBTC15M-26MAY141815-15","market_id":"9b5194ce-fa5b-4fa6-a79f-003263374118","price_dollars":"0.3200","delta_fp":"-10.00","side":"no","ts":"2026-05-14T22:08:34.198826Z","ts_ms":1778796514198}}

{"type":"orderbook_delta","sid":1,"seq":137,"msg":{"market_ticker":"KXBTC15M-26MAY141815-15","market_id":"9b5194ce-fa5b-4fa6-a79f-003263374118","price_dollars":"0.3300","delta_fp":"10.00","side":"no","ts":"2026-05-14T22:08:34.198826Z","ts_ms":1778796514198}}

{"type":"orderbook_delta","sid":1,"seq":138,"msg":{"market_ticker":"KXBTC15M-26MAY141815-15","market_id":"9b5194ce-fa5b-4fa6-a79f-003263374118","price_dollars":"0.2400","delta_fp":"-14.00","side":"no","ts":"2026-05-14T22:08:34.212467Z","ts_ms":1778796514212}}

{"type":"orderbook_delta","sid":1,"seq":139,"msg":{"market_ticker":"KXBTC15M-26MAY141815-15","market_id":"9b5194ce-fa5b-4fa6-a79f-003263374118","price_dollars":"0.2200","delta_fp":"14.00","side":"no","ts":"2026-05-14T22:08:34.212467Z","ts_ms":1778796514212}}

{"type":"orderbook_delta","sid":1,"seq":140,"msg":{"market_ticker":"KXBTC15M-26MAY141815-15","market_id":"9b5194ce-fa5b-4fa6-a79f-003263374118","price_dollars":"0.3400","delta_fp":"-100.00","side":"no","ts":"2026-05-14T22:08:34.213002Z","ts_ms":1778796514213}}

{"type":"orderbook_delta","sid":1,"seq":141,"msg":{"market_ticker":"KXBTC15M-26MAY141815-15","market_id":"9b5194ce-fa5b-4fa6-a79f-003263374118","price_dollars":"0.5700","delta_fp":"2.00","side":"yes","ts":"2026-05-14T22:08:34.213089Z","ts_ms":1778796514213}}

{"type":"orderbook_delta","sid":1,"seq":142,"msg":{"market_ticker":"KXBTC15M-26MAY141815-15","market_id":"9b5194ce-fa5b-4fa6-a79f-003263374118","price_dollars":"0.6300","delta_fp":"-400.00","side":"yes","ts":"2026-05-14T22:08:34.219913Z","ts_ms":1778796514219}}

{"type":"orderbook_delta","sid":1,"seq":143,"msg":{"market_ticker":"KXBTC15M-26MAY141815-15","market_id":"9b5194ce-fa5b-4fa6-a79f-003263374118","price_dollars":"0.6200","delta_fp":"400.00","side":"yes","ts":"2026-05-14T22:08:34.219913Z","ts_ms":1778796514219}}

{"type":"orderbook_delta","sid":1,"seq":144,"msg":{"market_ticker":"KXBTC15M-26MAY141815-15","market_id":"9b5194ce-fa5b-4fa6-a79f-003263374118","price_dollars":"0.3300","delta_fp":"100.00","side":"no","ts":"2026-05-14T22:08:34.224466Z","ts_ms":1778796514224}}

{"type":"orderbook_delta","sid":1,"seq":145,"msg":{"market_ticker":"KXBTC15M-26MAY141815-15","market_id":"9b5194ce-fa5b-4fa6-a79f-003263374118","price_dollars":"0.2100","delta_fp":"-1057.00","side":"no","ts":"2026-05-14T22:08:34.239163Z","ts_ms":1778796514239}}

{"type":"orderbook_delta","sid":1,"seq":146,"msg":{"market_ticker":"KXBTC15M-26MAY141815-15","market_id":"9b5194ce-fa5b-4fa6-a79f-003263374118","price_dollars":"0.1500","delta_fp":"884.00","side":"no","ts":"2026-05-14T22:08:34.24096Z","ts_ms":1778796514240}}

{"type":"orderbook_delta","sid":1,"seq":147,"msg":{"market_ticker":"KXBTC15M-26MAY141815-15","market_id":"9b5194ce-fa5b-4fa6-a79f-003263374118","price_dollars":"0.2900","delta_fp":"-2.00","side":"no","ts":"2026-05-14T22:08:34.242707Z","ts_ms":1778796514242}}

{"type":"orderbook_delta","sid":1,"seq":148,"msg":{"market_ticker":"KXBTC15M-26MAY141815-15","market_id":"9b5194ce-fa5b-4fa6-a79f-003263374118","price_dollars":"0.3000","delta_fp":"2.00","side":"no","ts":"2026-05-14T22:08:34.242707Z","ts_ms":1778796514242}}

{"type":"orderbook_delta","sid":1,"seq":149,"msg":{"market_ticker":"KXBTC15M-26MAY141815-15","market_id":"9b5194ce-fa5b-4fa6-a79f-003263374118","price_dollars":"0.6300","delta_fp":"-10.00","side":"yes","ts":"2026-05-14T22:08:34.243467Z","ts_ms":1778796514243}}

{"type":"orderbook_delta","sid":1,"seq":150,"msg":{"market_ticker":"KXBTC15M-26MAY141815-15","market_id":"9b5194ce-fa5b-4fa6-a79f-003263374118","price_dollars":"0.6400","delta_fp":"10.00","side":"yes","ts":"2026-05-14T22:08:34.243467Z","ts_ms":1778796514243}}

{"type":"orderbook_delta","sid":1,"seq":151,"msg":{"market_ticker":"KXBTC15M-26MAY141815-15","market_id":"9b5194ce-fa5b-4fa6-a79f-003263374118","price_dollars":"0.3300","delta_fp":"-10.00","side":"no","ts":"2026-05-14T22:08:34.244101Z","ts_ms":1778796514244}}

{"type":"orderbook_delta","sid":1,"seq":152,"msg":{"market_ticker":"KXBTC15M-26MAY141815-15","market_id":"9b5194ce-fa5b-4fa6-a79f-003263374118","price_dollars":"0.3200","delta_fp":"10.00","side":"no","ts":"2026-05-14T22:08:34.244101Z","ts_ms":1778796514244}}

{"type":"orderbook_delta","sid":1,"seq":153,"msg":{"market_ticker":"KXBTC15M-26MAY141815-15","market_id":"9b5194ce-fa5b-4fa6-a79f-003263374118","price_dollars":"0.6200","delta_fp":"-2.00","side":"yes","ts":"2026-05-14T22:08:34.252826Z","ts_ms":1778796514252}}

{"type":"orderbook_delta","sid":1,"seq":154,"msg":{"market_ticker":"KXBTC15M-26MAY141815-15","market_id":"9b5194ce-fa5b-4fa6-a79f-003263374118","price_dollars":"0.6100","delta_fp":"2.00","side":"yes","ts":"2026-05-14T22:08:34.252826Z","ts_ms":1778796514252}}

{"type":"orderbook_delta","sid":1,"seq":155,"msg":{"market_ticker":"KXBTC15M-26MAY141815-15","market_id":"9b5194ce-fa5b-4fa6-a79f-003263374118","price_dollars":"0.6400","delta_fp":"-75.00","side":"yes","ts":"2026-05-14T22:08:34.253268Z","ts_ms":1778796514253}}

{"type":"orderbook_delta","sid":1,"seq":156,"msg":{"market_ticker":"KXBTC15M-26MAY141815-15","market_id":"9b5194ce-fa5b-4fa6-a79f-003263374118","price_dollars":"0.6500","delta_fp":"75.00","side":"yes","ts":"2026-05-14T22:08:34.253268Z","ts_ms":1778796514253}}

{"type":"orderbook_delta","sid":1,"seq":157,"msg":{"market_ticker":"KXBTC15M-26MAY141815-15","market_id":"9b5194ce-fa5b-4fa6-a79f-003263374118","price_dollars":"0.5700","delta_fp":"-15.00","side":"yes","ts":"2026-05-14T22:08:34.25446Z","ts_ms":1778796514254}}

{"type":"orderbook_delta","sid":1,"seq":158,"msg":{"market_ticker":"KXBTC15M-26MAY141815-15","market_id":"9b5194ce-fa5b-4fa6-a79f-003263374118","price_dollars":"0.5800","delta_fp":"15.00","side":"yes","ts":"2026-05-14T22:08:34.25446Z","ts_ms":1778796514254}}

{"type":"orderbook_delta","sid":1,"seq":159,"msg":{"market_ticker":"KXBTC15M-26MAY141815-15","market_id":"9b5194ce-fa5b-4fa6-a79f-003263374118","price_dollars":"0.1400","delta_fp":"-40.00","side":"yes","ts":"2026-05-14T22:08:34.264947Z","ts_ms":1778796514264}}

{"type":"orderbook_delta","sid":1,"seq":160,"msg":{"market_ticker":"KXBTC15M-26MAY141815-15","market_id":"9b5194ce-fa5b-4fa6-a79f-003263374118","price_dollars":"0.1500","delta_fp":"40.00","side":"yes","ts":"2026-05-14T22:08:34.264947Z","ts_ms":1778796514264}}

{"type":"orderbook_delta","sid":1,"seq":161,"msg":{"market_ticker":"KXBTC15M-26MAY141815-15","market_id":"9b5194ce-fa5b-4fa6-a79f-003263374118","price_dollars":"0.6500","delta_fp":"-1.00","side":"yes","ts":"2026-05-14T22:08:34.271462Z","ts_ms":1778796514271}}

{"type":"orderbook_delta","sid":1,"seq":162,"msg":{"market_ticker":"KXBTC15M-26MAY141815-15","market_id":"9b5194ce-fa5b-4fa6-a79f-003263374118","price_dollars":"0.3000","delta_fp":"-1.00","side":"no","ts":"2026-05-14T22:08:34.275067Z","ts_ms":1778796514275}}

{"type":"orderbook_delta","sid":1,"seq":163,"msg":{"market_ticker":"KXBTC15M-26MAY141815-15","market_id":"9b5194ce-fa5b-4fa6-a79f-003263374118","price_dollars":"0.3200","delta_fp":"-1.00","side":"no","ts":"2026-05-14T22:08:34.275658Z","ts_ms":1778796514275}}

{"type":"orderbook_delta","sid":1,"seq":164,"msg":{"market_ticker":"KXBTC15M-26MAY141815-15","market_id":"9b5194ce-fa5b-4fa6-a79f-003263374118","price_dollars":"0.5700","delta_fp":"-1.00","side":"yes","ts":"2026-05-14T22:08:34.276097Z","ts_ms":1778796514276}}

{"type":"orderbook_delta","sid":1,"seq":165,"msg":{"market_ticker":"KXBTC15M-26MAY141815-15","market_id":"9b5194ce-fa5b-4fa6-a79f-003263374118","price_dollars":"0.5600","delta_fp":"-1.00","side":"yes","ts":"2026-05-14T22:08:34.276684Z","ts_ms":1778796514276}}

{"type":"orderbook_delta","sid":1,"seq":166,"msg":{"market_ticker":"KXBTC15M-26MAY141815-15","market_id":"9b5194ce-fa5b-4fa6-a79f-003263374118","price_dollars":"0.5900","delta_fp":"-1.00","side":"yes","ts":"2026-05-14T22:08:34.315125Z","ts_ms":1778796514315}}

{"type":"orderbook_delta","sid":1,"seq":167,"msg":{"market_ticker":"KXBTC15M-26MAY141815-15","market_id":"9b5194ce-fa5b-4fa6-a79f-003263374118","price_dollars":"0.5800","delta_fp":"-15.00","side":"yes","ts":"2026-05-14T22:08:34.326101Z","ts_ms":1778796514326}}

{"type":"orderbook_delta","sid":1,"seq":168,"msg":{"market_ticker":"KXBTC15M-26MAY141815-15","market_id":"9b5194ce-fa5b-4fa6-a79f-003263374118","price_dollars":"0.5700","delta_fp":"15.00","side":"yes","ts":"2026-05-14T22:08:34.326101Z","ts_ms":1778796514326}}

{"type":"orderbook_delta","sid":1,"seq":169,"msg":{"market_ticker":"KXBTC15M-26MAY141815-15","market_id":"9b5194ce-fa5b-4fa6-a79f-003263374118","price_dollars":"0.1500","delta_fp":"-40.00","side":"yes","ts":"2026-05-14T22:08:34.353961Z","ts_ms":1778796514353}}

{"type":"orderbook_delta","sid":1,"seq":170,"msg":{"market_ticker":"KXBTC15M-26MAY141815-15","market_id":"9b5194ce-fa5b-4fa6-a79f-003263374118","price_dollars":"0.1600","delta_fp":"40.00","side":"yes","ts":"2026-05-14T22:08:34.353961Z","ts_ms":1778796514353}}

{"type":"orderbook_delta","sid":1,"seq":171,"msg":{"market_ticker":"KXBTC15M-26MAY141815-15","market_id":"9b5194ce-fa5b-4fa6-a79f-003263374118","price_dollars":"0.6500","delta_fp":"-1.00","side":"yes","ts":"2026-05-14T22:08:34.356684Z","ts_ms":1778796514356}}

{"type":"orderbook_delta","sid":1,"seq":172,"msg":{"market_ticker":"KXBTC15M-26MAY141815-15","market_id":"9b5194ce-fa5b-4fa6-a79f-003263374118","price_dollars":"0.3400","delta_fp":"-1.47","side":"no","ts":"2026-05-14T22:08:34.362811Z","ts_ms":1778796514362}}

{"type":"orderbook_delta","sid":1,"seq":173,"msg":{"market_ticker":"KXBTC15M-26MAY141815-15","market_id":"9b5194ce-fa5b-4fa6-a79f-003263374118","price_dollars":"0.6000","delta_fp":"1.00","side":"yes","ts":"2026-05-14T22:08:34.408053Z","ts_ms":1778796514408}}

{"type":"orderbook_delta","sid":1,"seq":174,"msg":{"market_ticker":"KXBTC15M-26MAY141815-15","market_id":"9b5194ce-fa5b-4fa6-a79f-003263374118","price_dollars":"0.3300","delta_fp":"-81.00","side":"no","ts":"2026-05-14T22:08:34.409136Z","ts_ms":1778796514409}}

{"type":"orderbook_delta","sid":1,"seq":175,"msg":{"market_ticker":"KXBTC15M-26MAY141815-15","market_id":"9b5194ce-fa5b-4fa6-a79f-003263374118","price_dollars":"0.6300","delta_fp":"-81.00","side":"yes","ts":"2026-05-14T22:08:34.409612Z","ts_ms":1778796514409}}

{"type":"orderbook_delta","sid":1,"seq":176,"msg":{"market_ticker":"KXBTC15M-26MAY141815-15","market_id":"9b5194ce-fa5b-4fa6-a79f-003263374118","price_dollars":"0.2900","delta_fp":"-400.00","side":"no","ts":"2026-05-14T22:08:34.508288Z","ts_ms":1778796514508}}

{"type":"orderbook_delta","sid":1,"seq":177,"msg":{"market_ticker":"KXBTC15M-26MAY141815-15","market_id":"9b5194ce-fa5b-4fa6-a79f-003263374118","price_dollars":"0.3000","delta_fp":"400.00","side":"no","ts":"2026-05-14T22:08:34.508288Z","ts_ms":1778796514508}}

{"type":"orderbook_delta","sid":1,"seq":178,"msg":{"market_ticker":"KXBTC15M-26MAY141815-15","market_id":"9b5194ce-fa5b-4fa6-a79f-003263374118","price_dollars":"0.4700","delta_fp":"6249.00","side":"yes","ts":"2026-05-14T22:08:34.510006Z","ts_ms":1778796514510}}

{"type":"orderbook_delta","sid":1,"seq":179,"msg":{"market_ticker":"KXBTC15M-26MAY141815-15","market_id":"9b5194ce-fa5b-4fa6-a79f-003263374118","price_dollars":"0.6500","delta_fp":"-75.00","side":"yes","ts":"2026-05-14T22:08:34.51726Z","ts_ms":1778796514517}}

{"type":"orderbook_delta","sid":1,"seq":180,"msg":{"market_ticker":"KXBTC15M-26MAY141815-15","market_id":"9b5194ce-fa5b-4fa6-a79f-003263374118","price_dollars":"0.5900","delta_fp":"75.00","side":"yes","ts":"2026-05-14T22:08:34.51726Z","ts_ms":1778796514517}}

{"type":"orderbook_delta","sid":1,"seq":181,"msg":{"market_ticker":"KXBTC15M-26MAY141815-15","market_id":"9b5194ce-fa5b-4fa6-a79f-003263374118","price_dollars":"0.1900","delta_fp":"6249.00","side":"no","ts":"2026-05-14T22:08:34.538412Z","ts_ms":1778796514538}}

{"type":"orderbook_delta","sid":1,"seq":182,"msg":{"market_ticker":"KXBTC15M-26MAY141815-15","market_id":"9b5194ce-fa5b-4fa6-a79f-003263374118","price_dollars":"0.3300","delta_fp":"-100.00","side":"no","ts":"2026-05-14T22:08:34.540826Z","ts_ms":1778796514540}}

{"type":"orderbook_delta","sid":1,"seq":183,"msg":{"market_ticker":"KXBTC15M-26MAY141815-15","market_id":"9b5194ce-fa5b-4fa6-a79f-003263374118","price_dollars":"0.6200","delta_fp":"-400.00","side":"yes","ts":"2026-05-14T22:08:34.543275Z","ts_ms":1778796514543}}

{"type":"orderbook_delta","sid":1,"seq":184,"msg":{"market_ticker":"KXBTC15M-26MAY141815-15","market_id":"9b5194ce-fa5b-4fa6-a79f-003263374118","price_dollars":"0.6100","delta_fp":"400.00","side":"yes","ts":"2026-05-14T22:08:34.543275Z","ts_ms":1778796514543}}

{"type":"orderbook_delta","sid":1,"seq":185,"msg":{"market_ticker":"KXBTC15M-26MAY141815-15","market_id":"9b5194ce-fa5b-4fa6-a79f-003263374118","price_dollars":"0.3000","delta_fp":"-2.00","side":"no","ts":"2026-05-14T22:08:34.550763Z","ts_ms":1778796514550}}

{"type":"orderbook_delta","sid":1,"seq":186,"msg":{"market_ticker":"KXBTC15M-26MAY141815-15","market_id":"9b5194ce-fa5b-4fa6-a79f-003263374118","price_dollars":"0.3100","delta_fp":"2.00","side":"no","ts":"2026-05-14T22:08:34.550763Z","ts_ms":1778796514550}}

{"type":"orderbook_delta","sid":1,"seq":187,"msg":{"market_ticker":"KXBTC15M-26MAY141815-15","market_id":"9b5194ce-fa5b-4fa6-a79f-003263374118","price_dollars":"0.5600","delta_fp":"-5.00","side":"yes","ts":"2026-05-14T22:08:34.551169Z","ts_ms":1778796514551}}

{"type":"orderbook_delta","sid":1,"seq":188,"msg":{"market_ticker":"KXBTC15M-26MAY141815-15","market_id":"9b5194ce-fa5b-4fa6-a79f-003263374118","price_dollars":"0.6100","delta_fp":"-2.00","side":"yes","ts":"2026-05-14T22:08:34.586951Z","ts_ms":1778796514586}}

{"type":"orderbook_delta","sid":1,"seq":189,"msg":{"market_ticker":"KXBTC15M-26MAY141815-15","market_id":"9b5194ce-fa5b-4fa6-a79f-003263374118","price_dollars":"0.6000","delta_fp":"2.00","side":"yes","ts":"2026-05-14T22:08:34.586951Z","ts_ms":1778796514586}}

{"type":"orderbook_delta","sid":1,"seq":190,"msg":{"market_ticker":"KXBTC15M-26MAY141815-15","market_id":"9b5194ce-fa5b-4fa6-a79f-003263374118","price_dollars":"0.5700","delta_fp":"-2.00","side":"yes","ts":"2026-05-14T22:08:34.638531Z","ts_ms":1778796514638}}

{"type":"orderbook_delta","sid":1,"seq":191,"msg":{"market_ticker":"KXBTC15M-26MAY141815-15","market_id":"9b5194ce-fa5b-4fa6-a79f-003263374118","price_dollars":"0.6400","delta_fp":"-100.00","side":"yes","ts":"2026-05-14T22:08:34.642948Z","ts_ms":1778796514642}}

{"type":"orderbook_delta","sid":1,"seq":192,"msg":{"market_ticker":"KXBTC15M-26MAY141815-15","market_id":"9b5194ce-fa5b-4fa6-a79f-003263374118","price_dollars":"0.1100","delta_fp":"2.00","side":"no","ts":"2026-05-14T22:08:34.658079Z","ts_ms":1778796514658}}

{"type":"orderbook_delta","sid":1,"seq":193,"msg":{"market_ticker":"KXBTC15M-26MAY141815-15","market_id":"9b5194ce-fa5b-4fa6-a79f-003263374118","price_dollars":"0.5900","delta_fp":"-75.00","side":"yes","ts":"2026-05-14T22:08:34.670678Z","ts_ms":1778796514670}}

{"type":"orderbook_delta","sid":1,"seq":194,"msg":{"market_ticker":"KXBTC15M-26MAY141815-15","market_id":"9b5194ce-fa5b-4fa6-a79f-003263374118","price_dollars":"0.6500","delta_fp":"75.00","side":"yes","ts":"2026-05-14T22:08:34.670678Z","ts_ms":1778796514670}}

{"type":"orderbook_delta","sid":1,"seq":195,"msg":{"market_ticker":"KXBTC15M-26MAY141815-15","market_id":"9b5194ce-fa5b-4fa6-a79f-003263374118","price_dollars":"0.5600","delta_fp":"2.00","side":"yes","ts":"2026-05-14T22:08:34.675264Z","ts_ms":1778796514675}}

{"type":"orderbook_delta","sid":1,"seq":196,"msg":{"market_ticker":"KXBTC15M-26MAY141815-15","market_id":"9b5194ce-fa5b-4fa6-a79f-003263374118","price_dollars":"0.6500","delta_fp":"-75.00","side":"yes","ts":"2026-05-14T22:08:34.722268Z","ts_ms":1778796514722}}

{"type":"orderbook_delta","sid":1,"seq":197,"msg":{"market_ticker":"KXBTC15M-26MAY141815-15","market_id":"9b5194ce-fa5b-4fa6-a79f-003263374118","price_dollars":"0.5900","delta_fp":"75.00","side":"yes","ts":"2026-05-14T22:08:34.722268Z","ts_ms":1778796514722}}

{"type":"orderbook_delta","sid":1,"seq":198,"msg":{"market_ticker":"KXBTC15M-26MAY141815-15","market_id":"9b5194ce-fa5b-4fa6-a79f-003263374118","price_dollars":"0.3200","delta_fp":"-16.00","side":"no","ts":"2026-05-14T22:08:34.750434Z","ts_ms":1778796514750}}

{"type":"orderbook_delta","sid":1,"seq":199,"msg":{"market_ticker":"KXBTC15M-26MAY141815-15","market_id":"9b5194ce-fa5b-4fa6-a79f-003263374118","price_dollars":"0.3300","delta_fp":"10.00","side":"no","ts":"2026-05-14T22:08:34.750434Z","ts_ms":1778796514750}}

{"type":"orderbook_delta","sid":1,"seq":200,"msg":{"market_ticker":"KXBTC15M-26MAY141815-15","market_id":"9b5194ce-fa5b-4fa6-a79f-003263374118","price_dollars":"0.5700","delta_fp":"2.00","side":"yes","ts":"2026-05-14T22:08:34.761776Z","ts_ms":1778796514761}}

{"type":"orderbook_delta","sid":1,"seq":201,"msg":{"market_ticker":"KXBTC15M-26MAY141815-15","market_id":"9b5194ce-fa5b-4fa6-a79f-003263374118","price_dollars":"0.4700","delta_fp":"-6249.00","side":"yes","ts":"2026-05-14T22:08:34.763087Z","ts_ms":1778796514763}}

{"type":"orderbook_delta","sid":1,"seq":202,"msg":{"market_ticker":"KXBTC15M-26MAY141815-15","market_id":"9b5194ce-fa5b-4fa6-a79f-003263374118","price_dollars":"0.1900","delta_fp":"-6249.00","side":"no","ts":"2026-05-14T22:08:34.764178Z","ts_ms":1778796514764}}

{"type":"orderbook_delta","sid":1,"seq":203,"msg":{"market_ticker":"KXBTC15M-26MAY141815-15","market_id":"9b5194ce-fa5b-4fa6-a79f-003263374118","price_dollars":"0.3100","delta_fp":"-2.00","side":"no","ts":"2026-05-14T22:08:34.770174Z","ts_ms":1778796514770}}

{"type":"orderbook_delta","sid":1,"seq":204,"msg":{"market_ticker":"KXBTC15M-26MAY141815-15","market_id":"9b5194ce-fa5b-4fa6-a79f-003263374118","price_dollars":"0.3200","delta_fp":"2.00","side":"no","ts":"2026-05-14T22:08:34.770174Z","ts_ms":1778796514770}}

{"type":"orderbook_delta","sid":1,"seq":205,"msg":{"market_ticker":"KXBTC15M-26MAY141815-15","market_id":"9b5194ce-fa5b-4fa6-a79f-003263374118","price_dollars":"0.6000","delta_fp":"-2.00","side":"yes","ts":"2026-05-14T22:08:34.773946Z","ts_ms":1778796514773}}

{"type":"orderbook_delta","sid":1,"seq":206,"msg":{"market_ticker":"KXBTC15M-26MAY141815-15","market_id":"9b5194ce-fa5b-4fa6-a79f-003263374118","price_dollars":"0.5900","delta_fp":"2.00","side":"yes","ts":"2026-05-14T22:08:34.773946Z","ts_ms":1778796514773}}

{"type":"orderbook_delta","sid":1,"seq":207,"msg":{"market_ticker":"KXBTC15M-26MAY141815-15","market_id":"9b5194ce-fa5b-4fa6-a79f-003263374118","price_dollars":"0.3000","delta_fp":"-400.00","side":"no","ts":"2026-05-14T22:08:34.788862Z","ts_ms":1778796514788}}

{"type":"orderbook_delta","sid":1,"seq":208,"msg":{"market_ticker":"KXBTC15M-26MAY141815-15","market_id":"9b5194ce-fa5b-4fa6-a79f-003263374118","price_dollars":"0.3100","delta_fp":"400.00","side":"no","ts":"2026-05-14T22:08:34.788862Z","ts_ms":1778796514788}}

{"type":"orderbook_delta","sid":1,"seq":209,"msg":{"market_ticker":"KXBTC15M-26MAY141815-15","market_id":"9b5194ce-fa5b-4fa6-a79f-003263374118","price_dollars":"0.2900","delta_fp":"-75.00","side":"no","ts":"2026-05-14T22:08:34.826709Z","ts_ms":1778796514826}}

{"type":"orderbook_delta","sid":1,"seq":210,"msg":{"market_ticker":"KXBTC15M-26MAY141815-15","market_id":"9b5194ce-fa5b-4fa6-a79f-003263374118","price_dollars":"0.3400","delta_fp":"75.00","side":"no","ts":"2026-05-14T22:08:34.826709Z","ts_ms":1778796514826}}

{"type":"orderbook_delta","sid":1,"seq":211,"msg":{"market_ticker":"KXBTC15M-26MAY141815-15","market_id":"9b5194ce-fa5b-4fa6-a79f-003263374118","price_dollars":"0.5700","delta_fp":"-15.00","side":"yes","ts":"2026-05-14T22:08:34.875548Z","ts_ms":1778796514875}}

{"type":"orderbook_delta","sid":1,"seq":212,"msg":{"market_ticker":"KXBTC15M-26MAY141815-15","market_id":"9b5194ce-fa5b-4fa6-a79f-003263374118","price_dollars":"0.5800","delta_fp":"15.00","side":"yes","ts":"2026-05-14T22:08:34.875548Z","ts_ms":1778796514875}}

{"type":"orderbook_delta","sid":1,"seq":213,"msg":{"market_ticker":"KXBTC15M-26MAY141815-15","market_id":"9b5194ce-fa5b-4fa6-a79f-003263374118","price_dollars":"0.6400","delta_fp":"-10.00","side":"yes","ts":"2026-05-14T22:08:34.911091Z","ts_ms":1778796514911}}

{"type":"orderbook_delta","sid":1,"seq":214,"msg":{"market_ticker":"KXBTC15M-26MAY141815-15","market_id":"9b5194ce-fa5b-4fa6-a79f-003263374118","price_dollars":"0.6300","delta_fp":"10.00","side":"yes","ts":"2026-05-14T22:08:34.911091Z","ts_ms":1778796514911}}

{"type":"orderbook_delta","sid":1,"seq":215,"msg":{"market_ticker":"KXBTC15M-26MAY141815-15","market_id":"9b5194ce-fa5b-4fa6-a79f-003263374118","price_dollars":"0.3200","delta_fp":"-10.00","side":"no","ts":"2026-05-14T22:08:34.91153Z","ts_ms":1778796514911}}

{"type":"orderbook_delta","sid":1,"seq":216,"msg":{"market_ticker":"KXBTC15M-26MAY141815-15","market_id":"9b5194ce-fa5b-4fa6-a79f-003263374118","price_dollars":"0.3300","delta_fp":"10.00","side":"no","ts":"2026-05-14T22:08:34.91153Z","ts_ms":1778796514911}}

{"type":"orderbook_delta","sid":1,"seq":217,"msg":{"market_ticker":"KXBTC15M-26MAY141815-15","market_id":"9b5194ce-fa5b-4fa6-a79f-003263374118","price_dollars":"0.5900","delta_fp":"-75.00","side":"yes","ts":"2026-05-14T22:08:34.914032Z","ts_ms":1778796514914}}

{"type":"orderbook_delta","sid":1,"seq":218,"msg":{"market_ticker":"KXBTC15M-26MAY141815-15","market_id":"9b5194ce-fa5b-4fa6-a79f-003263374118","price_dollars":"0.6500","delta_fp":"75.00","side":"yes","ts":"2026-05-14T22:08:34.914032Z","ts_ms":1778796514914}}

{"type":"orderbook_delta","sid":1,"seq":219,"msg":{"market_ticker":"KXBTC15M-26MAY141815-15","market_id":"9b5194ce-fa5b-4fa6-a79f-003263374118","price_dollars":"0.3400","delta_fp":"-75.00","side":"no","ts":"2026-05-14T22:08:34.914469Z","ts_ms":1778796514914}}

{"type":"orderbook_delta","sid":1,"seq":220,"msg":{"market_ticker":"KXBTC15M-26MAY141815-15","market_id":"9b5194ce-fa5b-4fa6-a79f-003263374118","price_dollars":"0.2700","delta_fp":"75.00","side":"no","ts":"2026-05-14T22:08:34.914469Z","ts_ms":1778796514914}}

{"type":"orderbook_delta","sid":1,"seq":221,"msg":{"market_ticker":"KXBTC15M-26MAY141815-15","market_id":"9b5194ce-fa5b-4fa6-a79f-003263374118","price_dollars":"0.6500","delta_fp":"-11.00","side":"yes","ts":"2026-05-14T22:08:34.927468Z","ts_ms":1778796514927}}

{"type":"orderbook_delta","sid":1,"seq":222,"msg":{"market_ticker":"KXBTC15M-26MAY141815-15","market_id":"9b5194ce-fa5b-4fa6-a79f-003263374118","price_dollars":"0.6400","delta_fp":"25.00","side":"yes","ts":"2026-05-14T22:08:34.927468Z","ts_ms":1778796514927}}

{"type":"orderbook_delta","sid":1,"seq":223,"msg":{"market_ticker":"KXBTC15M-26MAY141815-15","market_id":"9b5194ce-fa5b-4fa6-a79f-003263374118","price_dollars":"0.5700","delta_fp":"-2.00","side":"yes","ts":"2026-05-14T22:08:34.954031Z","ts_ms":1778796514954}}

{"type":"orderbook_delta","sid":1,"seq":224,"msg":{"market_ticker":"KXBTC15M-26MAY141815-15","market_id":"9b5194ce-fa5b-4fa6-a79f-003263374118","price_dollars":"0.6500","delta_fp":"-75.00","side":"yes","ts":"2026-05-14T22:08:34.956896Z","ts_ms":1778796514956}}

{"type":"orderbook_delta","sid":1,"seq":225,"msg":{"market_ticker":"KXBTC15M-26MAY141815-15","market_id":"9b5194ce-fa5b-4fa6-a79f-003263374118","price_dollars":"0.5900","delta_fp":"75.00","side":"yes","ts":"2026-05-14T22:08:34.956896Z","ts_ms":1778796514956}}

{"type":"orderbook_delta","sid":1,"seq":226,"msg":{"market_ticker":"KXBTC15M-26MAY141815-15","market_id":"9b5194ce-fa5b-4fa6-a79f-003263374118","price_dollars":"0.3300","delta_fp":"-10.00","side":"no","ts":"2026-05-14T22:08:34.976291Z","ts_ms":1778796514976}}

{"type":"orderbook_delta","sid":1,"seq":227,"msg":{"market_ticker":"KXBTC15M-26MAY141815-15","market_id":"9b5194ce-fa5b-4fa6-a79f-003263374118","price_dollars":"0.3200","delta_fp":"10.00","side":"no","ts":"2026-05-14T22:08:34.976291Z","ts_ms":1778796514976}}

{"type":"orderbook_delta","sid":1,"seq":228,"msg":{"market_ticker":"KXBTC15M-26MAY141815-15","market_id":"9b5194ce-fa5b-4fa6-a79f-003263374118","price_dollars":"0.6000","delta_fp":"-1.00","side":"yes","ts":"2026-05-14T22:08:34.997468Z","ts_ms":1778796514997}}

{"type":"orderbook_delta","sid":1,"seq":229,"msg":{"market_ticker":"KXBTC15M-26MAY141815-15","market_id":"9b5194ce-fa5b-4fa6-a79f-003263374118","price_dollars":"0.3500","delta_fp":"100.00","side":"no","ts":"2026-05-14T22:08:34.99882Z","ts_ms":1778796514998}}

{"type":"orderbook_delta","sid":1,"seq":230,"msg":{"market_ticker":"KXBTC15M-26MAY141815-15","market_id":"9b5194ce-fa5b-4fa6-a79f-003263374118","price_dollars":"0.3300","delta_fp":"-2.00","side":"no","ts":"2026-05-14T22:08:34.998947Z","ts_ms":1778796514998}}

{"type":"orderbook_delta","sid":1,"seq":231,"msg":{"market_ticker":"KXBTC15M-26MAY141815-15","market_id":"9b5194ce-fa5b-4fa6-a79f-003263374118","price_dollars":"0.6300","delta_fp":"2.00","side":"yes","ts":"2026-05-14T22:08:34.99931Z","ts_ms":1778796514999}}

{"type":"orderbook_delta","sid":1,"seq":232,"msg":{"market_ticker":"KXBTC15M-26MAY141815-15","market_id":"9b5194ce-fa5b-4fa6-a79f-003263374118","price_dollars":"0.3400","delta_fp":"-2.00","side":"no","ts":"2026-05-14T22:08:35.001543Z","ts_ms":1778796515001}}

{"type":"orderbook_delta","sid":1,"seq":233,"msg":{"market_ticker":"KXBTC15M-26MAY141815-15","market_id":"9b5194ce-fa5b-4fa6-a79f-003263374118","price_dollars":"0.6300","delta_fp":"-10.00","side":"yes","ts":"2026-05-14T22:08:35.006294Z","ts_ms":1778796515006}}

{"type":"orderbook_delta","sid":1,"seq":234,"msg":{"market_ticker":"KXBTC15M-26MAY141815-15","market_id":"9b5194ce-fa5b-4fa6-a79f-003263374118","price_dollars":"0.6400","delta_fp":"10.00","side":"yes","ts":"2026-05-14T22:08:35.006294Z","ts_ms":1778796515006}}

{"type":"orderbook_delta","sid":1,"seq":235,"msg":{"market_ticker":"KXBTC15M-26MAY141815-15","market_id":"9b5194ce-fa5b-4fa6-a79f-003263374118","price_dollars":"0.5900","delta_fp":"1.00","side":"yes","ts":"2026-05-14T22:08:35.008745Z","ts_ms":1778796515008}}

{"type":"orderbook_delta","sid":1,"seq":236,"msg":{"market_ticker":"KXBTC15M-26MAY141815-15","market_id":"9b5194ce-fa5b-4fa6-a79f-003263374118","price_dollars":"0.5700","delta_fp":"1.00","side":"yes","ts":"2026-05-14T22:08:35.020943Z","ts_ms":1778796515020}}

{"type":"orderbook_delta","sid":1,"seq":237,"msg":{"market_ticker":"KXBTC15M-26MAY141815-15","market_id":"9b5194ce-fa5b-4fa6-a79f-003263374118","price_dollars":"0.5600","delta_fp":"1.00","side":"yes","ts":"2026-05-14T22:08:35.022066Z","ts_ms":1778796515022}}

{"type":"orderbook_delta","sid":1,"seq":238,"msg":{"market_ticker":"KXBTC15M-26MAY141815-15","market_id":"9b5194ce-fa5b-4fa6-a79f-003263374118","price_dollars":"0.3200","delta_fp":"1.00","side":"no","ts":"2026-05-14T22:08:35.023086Z","ts_ms":1778796515023}}

{"type":"orderbook_delta","sid":1,"seq":239,"msg":{"market_ticker":"KXBTC15M-26MAY141815-15","market_id":"9b5194ce-fa5b-4fa6-a79f-003263374118","price_dollars":"0.3000","delta_fp":"1.00","side":"no","ts":"2026-05-14T22:08:35.024057Z","ts_ms":1778796515024}}

{"type":"orderbook_delta","sid":1,"seq":240,"msg":{"market_ticker":"KXBTC15M-26MAY141815-15","market_id":"9b5194ce-fa5b-4fa6-a79f-003263374118","price_dollars":"0.3200","delta_fp":"-2.00","side":"no","ts":"2026-05-14T22:08:35.047648Z","ts_ms":1778796515047}}

{"type":"orderbook_delta","sid":1,"seq":241,"msg":{"market_ticker":"KXBTC15M-26MAY141815-15","market_id":"9b5194ce-fa5b-4fa6-a79f-003263374118","price_dollars":"0.3000","delta_fp":"2.00","side":"no","ts":"2026-05-14T22:08:35.047648Z","ts_ms":1778796515047}}

{"type":"orderbook_delta","sid":1,"seq":242,"msg":{"market_ticker":"KXBTC15M-26MAY141815-15","market_id":"9b5194ce-fa5b-4fa6-a79f-003263374118","price_dollars":"0.6400","delta_fp":"-10.00","side":"yes","ts":"2026-05-14T22:08:35.057986Z","ts_ms":1778796515057}}

{"type":"orderbook_delta","sid":1,"seq":243,"msg":{"market_ticker":"KXBTC15M-26MAY141815-15","market_id":"9b5194ce-fa5b-4fa6-a79f-003263374118","price_dollars":"0.6300","delta_fp":"10.00","side":"yes","ts":"2026-05-14T22:08:35.057986Z","ts_ms":1778796515057}}

{"type":"orderbook_delta","sid":1,"seq":244,"msg":{"market_ticker":"KXBTC15M-26MAY141815-15","market_id":"9b5194ce-fa5b-4fa6-a79f-003263374118","price_dollars":"0.3200","delta_fp":"-10.00","side":"no","ts":"2026-05-14T22:08:35.058035Z","ts_ms":1778796515058}}

{"type":"orderbook_delta","sid":1,"seq":245,"msg":{"market_ticker":"KXBTC15M-26MAY141815-15","market_id":"9b5194ce-fa5b-4fa6-a79f-003263374118","price_dollars":"0.3300","delta_fp":"10.00","side":"no","ts":"2026-05-14T22:08:35.058035Z","ts_ms":1778796515058}}

{"type":"orderbook_delta","sid":1,"seq":246,"msg":{"market_ticker":"KXBTC15M-26MAY141815-15","market_id":"9b5194ce-fa5b-4fa6-a79f-003263374118","price_dollars":"0.5900","delta_fp":"-75.00","side":"yes","ts":"2026-05-14T22:08:35.067699Z","ts_ms":1778796515067}}

{"type":"orderbook_delta","sid":1,"seq":247,"msg":{"market_ticker":"KXBTC15M-26MAY141815-15","market_id":"9b5194ce-fa5b-4fa6-a79f-003263374118","price_dollars":"0.6400","delta_fp":"75.00","side":"yes","ts":"2026-05-14T22:08:35.067699Z","ts_ms":1778796515067}}

{"type":"orderbook_delta","sid":1,"seq":248,"msg":{"market_ticker":"KXBTC15M-26MAY141815-15","market_id":"9b5194ce-fa5b-4fa6-a79f-003263374118","price_dollars":"0.5700","delta_fp":"2.00","side":"yes","ts":"2026-05-14T22:08:35.074776Z","ts_ms":1778796515074}}

{"type":"orderbook_delta","sid":1,"seq":249,"msg":{"market_ticker":"KXBTC15M-26MAY141815-15","market_id":"9b5194ce-fa5b-4fa6-a79f-003263374118","price_dollars":"0.5900","delta_fp":"-2.00","side":"yes","ts":"2026-05-14T22:08:35.076884Z","ts_ms":1778796515076}}

{"type":"orderbook_delta","sid":1,"seq":250,"msg":{"market_ticker":"KXBTC15M-26MAY141815-15","market_id":"9b5194ce-fa5b-4fa6-a79f-003263374118","price_dollars":"0.6100","delta_fp":"2.00","side":"yes","ts":"2026-05-14T22:08:35.076884Z","ts_ms":1778796515076}}

{"type":"orderbook_delta","sid":1,"seq":251,"msg":{"market_ticker":"KXBTC15M-26MAY141815-15","market_id":"9b5194ce-fa5b-4fa6-a79f-003263374118","price_dollars":"0.1600","delta_fp":"-40.00","side":"yes","ts":"2026-05-14T22:08:35.078066Z","ts_ms":1778796515078}}

{"type":"orderbook_delta","sid":1,"seq":252,"msg":{"market_ticker":"KXBTC15M-26MAY141815-15","market_id":"9b5194ce-fa5b-4fa6-a79f-003263374118","price_dollars":"0.1500","delta_fp":"40.00","side":"yes","ts":"2026-05-14T22:08:35.078066Z","ts_ms":1778796515078}}

{"type":"orderbook_delta","sid":1,"seq":253,"msg":{"market_ticker":"KXBTC15M-26MAY141815-15","market_id":"9b5194ce-fa5b-4fa6-a79f-003263374118","price_dollars":"0.3000","delta_fp":"-2.00","side":"no","ts":"2026-05-14T22:08:35.080782Z","ts_ms":1778796515080}}

{"type":"orderbook_delta","sid":1,"seq":254,"msg":{"market_ticker":"KXBTC15M-26MAY141815-15","market_id":"9b5194ce-fa5b-4fa6-a79f-003263374118","price_dollars":"0.2900","delta_fp":"2.00","side":"no","ts":"2026-05-14T22:08:35.080782Z","ts_ms":1778796515080}}

{"type":"orderbook_delta","sid":1,"seq":255,"msg":{"market_ticker":"KXBTC15M-26MAY141815-15","market_id":"9b5194ce-fa5b-4fa6-a79f-003263374118","price_dollars":"0.3100","delta_fp":"-400.00","side":"no","ts":"2026-05-14T22:08:35.102376Z","ts_ms":1778796515102}}

{"type":"orderbook_delta","sid":1,"seq":256,"msg":{"market_ticker":"KXBTC15M-26MAY141815-15","market_id":"9b5194ce-fa5b-4fa6-a79f-003263374118","price_dollars":"0.3000","delta_fp":"400.00","side":"no","ts":"2026-05-14T22:08:35.102376Z","ts_ms":1778796515102}}

{"type":"orderbook_delta","sid":1,"seq":257,"msg":{"market_ticker":"KXBTC15M-26MAY141815-15","market_id":"9b5194ce-fa5b-4fa6-a79f-003263374118","price_dollars":"0.6100","delta_fp":"-400.00","side":"yes","ts":"2026-05-14T22:08:35.104474Z","ts_ms":1778796515104}}

{"type":"orderbook_delta","sid":1,"seq":258,"msg":{"market_ticker":"KXBTC15M-26MAY141815-15","market_id":"9b5194ce-fa5b-4fa6-a79f-003263374118","price_dollars":"0.6200","delta_fp":"400.00","side":"yes","ts":"2026-05-14T22:08:35.104474Z","ts_ms":1778796515104}}

{"type":"orderbook_delta","sid":1,"seq":259,"msg":{"market_ticker":"KXBTC15M-26MAY141815-15","market_id":"9b5194ce-fa5b-4fa6-a79f-003263374118","price_dollars":"0.6100","delta_fp":"-2.00","side":"yes","ts":"2026-05-14T22:08:35.113829Z","ts_ms":1778796515113}}

{"type":"orderbook_delta","sid":1,"seq":260,"msg":{"market_ticker":"KXBTC15M-26MAY141815-15","market_id":"9b5194ce-fa5b-4fa6-a79f-003263374118","price_dollars":"0.6200","delta_fp":"2.00","side":"yes","ts":"2026-05-14T22:08:35.113829Z","ts_ms":1778796515113}}

{"type":"orderbook_delta","sid":1,"seq":261,"msg":{"market_ticker":"KXBTC15M-26MAY141815-15","market_id":"9b5194ce-fa5b-4fa6-a79f-003263374118","price_dollars":"0.6400","delta_fp":"-75.00","side":"yes","ts":"2026-05-14T22:08:35.129743Z","ts_ms":1778796515129}}

{"type":"orderbook_delta","sid":1,"seq":262,"msg":{"market_ticker":"KXBTC15M-26MAY141815-15","market_id":"9b5194ce-fa5b-4fa6-a79f-003263374118","price_dollars":"0.5800","delta_fp":"75.00","side":"yes","ts":"2026-05-14T22:08:35.129743Z","ts_ms":1778796515129}}

{"type":"orderbook_delta","sid":1,"seq":263,"msg":{"market_ticker":"KXBTC15M-26MAY141815-15","market_id":"9b5194ce-fa5b-4fa6-a79f-003263374118","price_dollars":"0.3000","delta_fp":"-400.00","side":"no","ts":"2026-05-14T22:08:35.141671Z","ts_ms":1778796515141}}

{"type":"orderbook_delta","sid":1,"seq":264,"msg":{"market_ticker":"KXBTC15M-26MAY141815-15","market_id":"9b5194ce-fa5b-4fa6-a79f-003263374118","price_dollars":"0.2900","delta_fp":"400.00","side":"no","ts":"2026-05-14T22:08:35.141671Z","ts_ms":1778796515141}}

{"type":"orderbook_delta","sid":1,"seq":265,"msg":{"market_ticker":"KXBTC15M-26MAY141815-15","market_id":"9b5194ce-fa5b-4fa6-a79f-003263374118","price_dollars":"0.5500","delta_fp":"-50.00","side":"yes","ts":"2026-05-14T22:08:35.157164Z","ts_ms":1778796515157}}

{"type":"orderbook_delta","sid":1,"seq":266,"msg":{"market_ticker":"KXBTC15M-26MAY141815-15","market_id":"9b5194ce-fa5b-4fa6-a79f-003263374118","price_dollars":"0.5700","delta_fp":"50.00","side":"yes","ts":"2026-05-14T22:08:35.157797Z","ts_ms":1778796515157}}

{"type":"orderbook_delta","sid":1,"seq":267,"msg":{"market_ticker":"KXBTC15M-26MAY141815-15","market_id":"9b5194ce-fa5b-4fa6-a79f-003263374118","price_dollars":"0.5800","delta_fp":"-15.00","side":"yes","ts":"2026-05-14T22:08:35.165562Z","ts_ms":1778796515165}}

{"type":"orderbook_delta","sid":1,"seq":268,"msg":{"market_ticker":"KXBTC15M-26MAY141815-15","market_id":"9b5194ce-fa5b-4fa6-a79f-003263374118","price_dollars":"0.5700","delta_fp":"15.00","side":"yes","ts":"2026-05-14T22:08:35.165562Z","ts_ms":1778796515165}}

{"type":"orderbook_delta","sid":1,"seq":269,"msg":{"market_ticker":"KXBTC15M-26MAY141815-15","market_id":"9b5194ce-fa5b-4fa6-a79f-003263374118","price_dollars":"0.5700","delta_fp":"-2.00","side":"yes","ts":"2026-05-14T22:08:35.189369Z","ts_ms":1778796515189}}

{"type":"orderbook_delta","sid":1,"seq":270,"msg":{"market_ticker":"KXBTC15M-26MAY141815-15","market_id":"9b5194ce-fa5b-4fa6-a79f-003263374118","price_dollars":"0.5500","delta_fp":"-2.00","side":"yes","ts":"2026-05-14T22:08:35.213685Z","ts_ms":1778796515213}}

{"type":"orderbook_delta","sid":1,"seq":271,"msg":{"market_ticker":"KXBTC15M-26MAY141815-15","market_id":"9b5194ce-fa5b-4fa6-a79f-003263374118","price_dollars":"0.3000","delta_fp":"-1.00","side":"no","ts":"2026-05-14T22:08:35.251094Z","ts_ms":1778796515251}}

{"type":"orderbook_delta","sid":1,"seq":272,"msg":{"market_ticker":"KXBTC15M-26MAY141815-15","market_id":"9b5194ce-fa5b-4fa6-a79f-003263374118","price_dollars":"0.3200","delta_fp":"-1.00","side":"no","ts":"2026-05-14T22:08:35.251511Z","ts_ms":1778796515251}}

{"type":"orderbook_delta","sid":1,"seq":273,"msg":{"market_ticker":"KXBTC15M-26MAY141815-15","market_id":"9b5194ce-fa5b-4fa6-a79f-003263374118","price_dollars":"0.5700","delta_fp":"-1.00","side":"yes","ts":"2026-05-14T22:08:35.25192Z","ts_ms":1778796515251}}

{"type":"orderbook_delta","sid":1,"seq":274,"msg":{"market_ticker":"KXBTC15M-26MAY141815-15","market_id":"9b5194ce-fa5b-4fa6-a79f-003263374118","price_dollars":"0.5600","delta_fp":"-1.00","side":"yes","ts":"2026-05-14T22:08:35.252321Z","ts_ms":1778796515252}}

{"type":"orderbook_delta","sid":1,"seq":275,"msg":{"market_ticker":"KXBTC15M-26MAY141815-15","market_id":"9b5194ce-fa5b-4fa6-a79f-003263374118","price_dollars":"0.5800","delta_fp":"2.00","side":"yes","ts":"2026-05-14T22:08:35.257008Z","ts_ms":1778796515257}}

{"type":"orderbook_delta","sid":1,"seq":276,"msg":{"market_ticker":"KXBTC15M-26MAY141815-15","market_id":"9b5194ce-fa5b-4fa6-a79f-003263374118","price_dollars":"0.1000","delta_fp":"2.00","side":"no","ts":"2026-05-14T22:08:35.284929Z","ts_ms":1778796515284}}

{"type":"orderbook_delta","sid":1,"seq":277,"msg":{"market_ticker":"KXBTC15M-26MAY141815-15","market_id":"9b5194ce-fa5b-4fa6-a79f-003263374118","price_dollars":"0.3500","delta_fp":"-7.00","side":"no","ts":"2026-05-14T22:08:35.287241Z","ts_ms":1778796515287}}

{"type":"orderbook_delta","sid":1,"seq":278,"msg":{"market_ticker":"KXBTC15M-26MAY141815-15","market_id":"9b5194ce-fa5b-4fa6-a79f-003263374118","price_dollars":"0.5600","delta_fp":"-150.00","side":"yes","ts":"2026-05-14T22:08:35.302525Z","ts_ms":1778796515302}}

{"type":"orderbook_delta","sid":1,"seq":279,"msg":{"market_ticker":"KXBTC15M-26MAY141815-15","market_id":"9b5194ce-fa5b-4fa6-a79f-003263374118","price_dollars":"0.5800","delta_fp":"150.00","side":"yes","ts":"2026-05-14T22:08:35.302525Z","ts_ms":1778796515302}}

{"type":"orderbook_delta","sid":1,"seq":280,"msg":{"market_ticker":"KXBTC15M-26MAY141815-15","market_id":"9b5194ce-fa5b-4fa6-a79f-003263374118","price_dollars":"0.3100","delta_fp":"-150.00","side":"no","ts":"2026-05-14T22:08:35.327667Z","ts_ms":1778796515327}}

{"type":"orderbook_delta","sid":1,"seq":281,"msg":{"market_ticker":"KXBTC15M-26MAY141815-15","market_id":"9b5194ce-fa5b-4fa6-a79f-003263374118","price_dollars":"0.2900","delta_fp":"150.00","side":"no","ts":"2026-05-14T22:08:35.327667Z","ts_ms":1778796515327}}

{"type":"orderbook_delta","sid":1,"seq":282,"msg":{"market_ticker":"KXBTC15M-26MAY141815-15","market_id":"9b5194ce-fa5b-4fa6-a79f-003263374118","price_dollars":"0.5800","delta_fp":"-2.00","side":"yes","ts":"2026-05-14T22:08:35.349475Z","ts_ms":1778796515349}}

{"type":"orderbook_delta","sid":1,"seq":283,"msg":{"market_ticker":"KXBTC15M-26MAY141815-15","market_id":"9b5194ce-fa5b-4fa6-a79f-003263374118","price_dollars":"0.5800","delta_fp":"-75.00","side":"yes","ts":"2026-05-14T22:08:35.362237Z","ts_ms":1778796515362}}

{"type":"orderbook_delta","sid":1,"seq":284,"msg":{"market_ticker":"KXBTC15M-26MAY141815-15","market_id":"9b5194ce-fa5b-4fa6-a79f-003263374118","price_dollars":"0.6400","delta_fp":"75.00","side":"yes","ts":"2026-05-14T22:08:35.362237Z","ts_ms":1778796515362}}

{"type":"orderbook_delta","sid":1,"seq":285,"msg":{"market_ticker":"KXBTC15M-26MAY141815-15","market_id":"9b5194ce-fa5b-4fa6-a79f-003263374118","price_dollars":"0.5700","delta_fp":"2.00","side":"yes","ts":"2026-05-14T22:08:35.386386Z","ts_ms":1778796515386}}

{"type":"orderbook_delta","sid":1,"seq":286,"msg":{"market_ticker":"KXBTC15M-26MAY141815-15","market_id":"9b5194ce-fa5b-4fa6-a79f-003263374118","price_dollars":"0.2900","delta_fp":"-2.00","side":"no","ts":"2026-05-14T22:08:35.401288Z","ts_ms":1778796515401}}

{"type":"orderbook_delta","sid":1,"seq":287,"msg":{"market_ticker":"KXBTC15M-26MAY141815-15","market_id":"9b5194ce-fa5b-4fa6-a79f-003263374118","price_dollars":"0.3000","delta_fp":"2.00","side":"no","ts":"2026-05-14T22:08:35.401288Z","ts_ms":1778796515401}}

{"type":"orderbook_delta","sid":1,"seq":288,"msg":{"market_ticker":"KXBTC15M-26MAY141815-15","market_id":"9b5194ce-fa5b-4fa6-a79f-003263374118","price_dollars":"0.3500","delta_fp":"-93.00","side":"no","ts":"2026-05-14T22:08:35.419627Z","ts_ms":1778796515419}}

{"type":"orderbook_delta","sid":1,"seq":289,"msg":{"market_ticker":"KXBTC15M-26MAY141815-15","market_id":"9b5194ce-fa5b-4fa6-a79f-003263374118","price_dollars":"0.3400","delta_fp":"-98.53","side":"no","ts":"2026-05-14T22:08:35.419627Z","ts_ms":1778796515419}}

{"type":"orderbook_delta","sid":1,"seq":290,"msg":{"market_ticker":"KXBTC15M-26MAY141815-15","market_id":"9b5194ce-fa5b-4fa6-a79f-003263374118","price_dollars":"0.3400","delta_fp":"-175.47","side":"no","ts":"2026-05-14T22:08:35.419627Z","ts_ms":1778796515419}}

{"type":"orderbook_delta","sid":1,"seq":291,"msg":{"market_ticker":"KXBTC15M-26MAY141815-15","market_id":"9b5194ce-fa5b-4fa6-a79f-003263374118","price_dollars":"0.6200","delta_fp":"-2.00","side":"yes","ts":"2026-05-14T22:08:35.423931Z","ts_ms":1778796515423}}

{"type":"orderbook_delta","sid":1,"seq":292,"msg":{"market_ticker":"KXBTC15M-26MAY141815-15","market_id":"9b5194ce-fa5b-4fa6-a79f-003263374118","price_dollars":"0.6100","delta_fp":"2.00","side":"yes","ts":"2026-05-14T22:08:35.423931Z","ts_ms":1778796515423}}

{"type":"orderbook_delta","sid":1,"seq":293,"msg":{"market_ticker":"KXBTC15M-26MAY141815-15","market_id":"9b5194ce-fa5b-4fa6-a79f-003263374118","price_dollars":"0.3400","delta_fp":"100.00","side":"no","ts":"2026-05-14T22:08:35.465259Z","ts_ms":1778796515465}}

{"type":"orderbook_delta","sid":1,"seq":294,"msg":{"market_ticker":"KXBTC15M-26MAY141815-15","market_id":"9b5194ce-fa5b-4fa6-a79f-003263374118","price_dollars":"0.5800","delta_fp":"2.00","side":"yes","ts":"2026-05-14T22:08:35.468561Z","ts_ms":1778796515468}}

{"type":"orderbook_delta","sid":1,"seq":295,"msg":{"market_ticker":"KXBTC15M-26MAY141815-15","market_id":"9b5194ce-fa5b-4fa6-a79f-003263374118","price_dollars":"0.5300","delta_fp":"6249.00","side":"yes","ts":"2026-05-14T22:08:35.482534Z","ts_ms":1778796515482}}

{"type":"orderbook_delta","sid":1,"seq":296,"msg":{"market_ticker":"KXBTC15M-26MAY141815-15","market_id":"9b5194ce-fa5b-4fa6-a79f-003263374118","price_dollars":"0.1600","delta_fp":"6249.00","side":"no","ts":"2026-05-14T22:08:35.510616Z","ts_ms":1778796515510}}

{"type":"orderbook_delta","sid":1,"seq":297,"msg":{"market_ticker":"KXBTC15M-26MAY141815-15","market_id":"9b5194ce-fa5b-4fa6-a79f-003263374118","price_dollars":"0.6400","delta_fp":"-12.94","side":"yes","ts":"2026-05-14T22:08:35.523357Z","ts_ms":1778796515523}}

{"type":"orderbook_delta","sid":1,"seq":298,"msg":{"market_ticker":"KXBTC15M-26MAY141815-15","market_id":"9b5194ce-fa5b-4fa6-a79f-003263374118","price_dollars":"0.5600","delta_fp":"4999.00","side":"yes","ts":"2026-05-14T22:08:35.526343Z","ts_ms":1778796515526}}

{"type":"orderbook_delta","sid":1,"seq":299,"msg":{"market_ticker":"KXBTC15M-26MAY141815-15","market_id":"9b5194ce-fa5b-4fa6-a79f-003263374118","price_dollars":"0.2700","delta_fp":"-10.00","side":"no","ts":"2026-05-14T22:08:35.540249Z","ts_ms":1778796515540}}

{"type":"orderbook_delta","sid":1,"seq":300,"msg":{"market_ticker":"KXBTC15M-26MAY141815-15","market_id":"9b5194ce-fa5b-4fa6-a79f-003263374118","price_dollars":"0.3000","delta_fp":"10.00","side":"no","ts":"2026-05-14T22:08:35.540249Z","ts_ms":1778796515540}}

{"type":"orderbook_delta","sid":1,"seq":301,"msg":{"market_ticker":"KXBTC15M-26MAY141815-15","market_id":"9b5194ce-fa5b-4fa6-a79f-003263374118","price_dollars":"0.5800","delta_fp":"-2.00","side":"yes","ts":"2026-05-14T22:08:35.550705Z","ts_ms":1778796515550}}

{"type":"orderbook_delta","sid":1,"seq":302,"msg":{"market_ticker":"KXBTC15M-26MAY141815-15","market_id":"9b5194ce-fa5b-4fa6-a79f-003263374118","price_dollars":"0.1900","delta_fp":"4999.00","side":"no","ts":"2026-05-14T22:08:35.556618Z","ts_ms":1778796515556}}

{"type":"orderbook_delta","sid":1,"seq":303,"msg":{"market_ticker":"KXBTC15M-26MAY141815-15","market_id":"9b5194ce-fa5b-4fa6-a79f-003263374118","price_dollars":"0.3300","delta_fp":"-10.00","side":"no","ts":"2026-05-14T22:08:35.564573Z","ts_ms":1778796515564}}

{"type":"orderbook_delta","sid":1,"seq":304,"msg":{"market_ticker":"KXBTC15M-26MAY141815-15","market_id":"9b5194ce-fa5b-4fa6-a79f-003263374118","price_dollars":"0.3400","delta_fp":"11.00","side":"no","ts":"2026-05-14T22:08:35.564573Z","ts_ms":1778796515564}}

{"type":"orderbook_delta","sid":1,"seq":305,"msg":{"market_ticker":"KXBTC15M-26MAY141815-15","market_id":"9b5194ce-fa5b-4fa6-a79f-003263374118","price_dollars":"0.6300","delta_fp":"-10.00","side":"yes","ts":"2026-05-14T22:08:35.568895Z","ts_ms":1778796515568}}

{"type":"orderbook_delta","sid":1,"seq":306,"msg":{"market_ticker":"KXBTC15M-26MAY141815-15","market_id":"9b5194ce-fa5b-4fa6-a79f-003263374118","price_dollars":"0.6400","delta_fp":"10.00","side":"yes","ts":"2026-05-14T22:08:35.568895Z","ts_ms":1778796515568}}

{"type":"orderbook_delta","sid":1,"seq":307,"msg":{"market_ticker":"KXBTC15M-26MAY141815-15","market_id":"9b5194ce-fa5b-4fa6-a79f-003263374118","price_dollars":"0.5100","delta_fp":"-7.00","side":"yes","ts":"2026-05-14T22:08:35.57164Z","ts_ms":1778796515571}}

{"type":"orderbook_delta","sid":1,"seq":308,"msg":{"market_ticker":"KXBTC15M-26MAY141815-15","market_id":"9b5194ce-fa5b-4fa6-a79f-003263374118","price_dollars":"0.5400","delta_fp":"7.00","side":"yes","ts":"2026-05-14T22:08:35.57164Z","ts_ms":1778796515571}}

{"type":"orderbook_delta","sid":1,"seq":309,"msg":{"market_ticker":"KXBTC15M-26MAY141815-15","market_id":"9b5194ce-fa5b-4fa6-a79f-003263374118","price_dollars":"0.3200","delta_fp":"81.00","side":"no","ts":"2026-05-14T22:08:35.584327Z","ts_ms":1778796515584}}

{"type":"orderbook_delta","sid":1,"seq":310,"msg":{"market_ticker":"KXBTC15M-26MAY141815-15","market_id":"9b5194ce-fa5b-4fa6-a79f-003263374118","price_dollars":"0.6400","delta_fp":"-12.06","side":"yes","ts":"2026-05-14T22:08:35.641078Z","ts_ms":1778796515641}}

{"type":"orderbook_delta","sid":1,"seq":311,"msg":{"market_ticker":"KXBTC15M-26MAY141815-15","market_id":"9b5194ce-fa5b-4fa6-a79f-003263374118","price_dollars":"0.6400","delta_fp":"-58.96","side":"yes","ts":"2026-05-14T22:08:35.641078Z","ts_ms":1778796515641}}

{"type":"orderbook_delta","sid":1,"seq":312,"msg":{"market_ticker":"KXBTC15M-26MAY141815-15","market_id":"9b5194ce-fa5b-4fa6-a79f-003263374118","price_dollars":"0.5800","delta_fp":"2.00","side":"yes","ts":"2026-05-14T22:08:35.673007Z","ts_ms":1778796515673}}

{"type":"orderbook_delta","sid":1,"seq":313,"msg":{"market_ticker":"KXBTC15M-26MAY141815-15","market_id":"9b5194ce-fa5b-4fa6-a79f-003263374118","price_dollars":"0.3400","delta_fp":"-11.00","side":"no","ts":"2026-05-14T22:08:35.674236Z","ts_ms":1778796515674}}

{"type":"orderbook_delta","sid":1,"seq":314,"msg":{"market_ticker":"KXBTC15M-26MAY141815-15","market_id":"9b5194ce-fa5b-4fa6-a79f-003263374118","price_dollars":"0.3500","delta_fp":"11.00","side":"no","ts":"2026-05-14T22:08:35.68658Z","ts_ms":1778796515686}}

{"type":"orderbook_delta","sid":1,"seq":315,"msg":{"market_ticker":"KXBTC15M-26MAY141815-15","market_id":"9b5194ce-fa5b-4fa6-a79f-003263374118","price_dollars":"0.3500","delta_fp":"-1.00","side":"no","ts":"2026-05-14T22:08:35.70191Z","ts_ms":1778796515701}}

{"type":"orderbook_delta","sid":1,"seq":316,"msg":{"market_ticker":"KXBTC15M-26MAY141815-15","market_id":"9b5194ce-fa5b-4fa6-a79f-003263374118","price_dollars":"0.5400","delta_fp":"-7.00","side":"yes","ts":"2026-05-14T22:08:35.744886Z","ts_ms":1778796515744}}

{"type":"orderbook_delta","sid":1,"seq":317,"msg":{"market_ticker":"KXBTC15M-26MAY141815-15","market_id":"9b5194ce-fa5b-4fa6-a79f-003263374118","price_dollars":"0.3000","delta_fp":"-2.00","side":"no","ts":"2026-05-14T22:08:35.796812Z","ts_ms":1778796515796}}

{"type":"orderbook_delta","sid":1,"seq":318,"msg":{"market_ticker":"KXBTC15M-26MAY141815-15","market_id":"9b5194ce-fa5b-4fa6-a79f-003263374118","price_dollars":"0.3100","delta_fp":"2.00","side":"no","ts":"2026-05-14T22:08:35.796812Z","ts_ms":1778796515796}}

{"type":"orderbook_delta","sid":1,"seq":319,"msg":{"market_ticker":"KXBTC15M-26MAY141815-15","market_id":"9b5194ce-fa5b-4fa6-a79f-003263374118","price_dollars":"0.6100","delta_fp":"-2.00","side":"yes","ts":"2026-05-14T22:08:35.799961Z","ts_ms":1778796515799}}

{"type":"orderbook_delta","sid":1,"seq":320,"msg":{"market_ticker":"KXBTC15M-26MAY141815-15","market_id":"9b5194ce-fa5b-4fa6-a79f-003263374118","price_dollars":"0.6000","delta_fp":"2.00","side":"yes","ts":"2026-05-14T22:08:35.799961Z","ts_ms":1778796515799}}

{"type":"orderbook_delta","sid":1,"seq":321,"msg":{"market_ticker":"KXBTC15M-26MAY141815-15","market_id":"9b5194ce-fa5b-4fa6-a79f-003263374118","price_dollars":"0.2900","delta_fp":"-400.00","side":"no","ts":"2026-05-14T22:08:35.81495Z","ts_ms":1778796515814}}

{"type":"orderbook_delta","sid":1,"seq":322,"msg":{"market_ticker":"KXBTC15M-26MAY141815-15","market_id":"9b5194ce-fa5b-4fa6-a79f-003263374118","price_dollars":"0.3000","delta_fp":"400.00","side":"no","ts":"2026-05-14T22:08:35.81495Z","ts_ms":1778796515814}}

{"type":"orderbook_delta","sid":1,"seq":323,"msg":{"market_ticker":"KXBTC15M-26MAY141815-15","market_id":"9b5194ce-fa5b-4fa6-a79f-003263374118","price_dollars":"0.3500","delta_fp":"-10.00","side":"no","ts":"2026-05-14T22:08:35.873514Z","ts_ms":1778796515873}}

{"type":"orderbook_delta","sid":1,"seq":324,"msg":{"market_ticker":"KXBTC15M-26MAY141815-15","market_id":"9b5194ce-fa5b-4fa6-a79f-003263374118","price_dollars":"0.0900","delta_fp":"2.00","side":"no","ts":"2026-05-14T22:08:35.914352Z","ts_ms":1778796515914}}

{"type":"orderbook_delta","sid":1,"seq":325,"msg":{"market_ticker":"KXBTC15M-26MAY141815-15","market_id":"9b5194ce-fa5b-4fa6-a79f-003263374118","price_dollars":"0.6400","delta_fp":"-16.04","side":"yes","ts":"2026-05-14T22:08:35.919752Z","ts_ms":1778796515919}}

{"type":"orderbook_delta","sid":1,"seq":326,"msg":{"market_ticker":"KXBTC15M-26MAY141815-15","market_id":"9b5194ce-fa5b-4fa6-a79f-003263374118","price_dollars":"0.5800","delta_fp":"75.00","side":"yes","ts":"2026-05-14T22:08:35.919752Z","ts_ms":1778796515919}}

{"type":"orderbook_delta","sid":1,"seq":327,"msg":{"market_ticker":"KXBTC15M-26MAY141815-15","market_id":"9b5194ce-fa5b-4fa6-a79f-003263374118","price_dollars":"0.2700","delta_fp":"-75.00","side":"no","ts":"2026-05-14T22:08:35.920372Z","ts_ms":1778796515920}}

{"type":"orderbook_delta","sid":1,"seq":328,"msg":{"market_ticker":"KXBTC15M-26MAY141815-15","market_id":"9b5194ce-fa5b-4fa6-a79f-003263374118","price_dollars":"0.3400","delta_fp":"75.00","side":"no","ts":"2026-05-14T22:08:35.920372Z","ts_ms":1778796515920}}

{"type":"orderbook_delta","sid":1,"seq":329,"msg":{"market_ticker":"KXBTC15M-26MAY141815-15","market_id":"9b5194ce-fa5b-4fa6-a79f-003263374118","price_dollars":"0.5700","delta_fp":"-251.00","side":"yes","ts":"2026-05-14T22:08:35.93857Z","ts_ms":1778796515938}}

{"type":"orderbook_delta","sid":1,"seq":330,"msg":{"market_ticker":"KXBTC15M-26MAY141815-15","market_id":"9b5194ce-fa5b-4fa6-a79f-003263374118","price_dollars":"0.6400","delta_fp":"-10.00","side":"yes","ts":"2026-05-14T22:08:35.947153Z","ts_ms":1778796515947}}

{"type":"orderbook_delta","sid":1,"seq":331,"msg":{"market_ticker":"KXBTC15M-26MAY141815-15","market_id":"9b5194ce-fa5b-4fa6-a79f-003263374118","price_dollars":"0.6300","delta_fp":"10.00","side":"yes","ts":"2026-05-14T22:08:35.947153Z","ts_ms":1778796515947}}

{"type":"orderbook_delta","sid":1,"seq":332,"msg":{"market_ticker":"KXBTC15M-26MAY141815-15","market_id":"9b5194ce-fa5b-4fa6-a79f-003263374118","price_dollars":"0.5700","delta_fp":"1.00","side":"yes","ts":"2026-05-14T22:08:35.966246Z","ts_ms":1778796515966}}

{"type":"orderbook_delta","sid":1,"seq":333,"msg":{"market_ticker":"KXBTC15M-26MAY141815-15","market_id":"9b5194ce-fa5b-4fa6-a79f-003263374118","price_dollars":"0.5800","delta_fp":"251.00","side":"yes","ts":"2026-05-14T22:08:35.966702Z","ts_ms":1778796515966}}

{"type":"orderbook_delta","sid":1,"seq":334,"msg":{"market_ticker":"KXBTC15M-26MAY141815-15","market_id":"9b5194ce-fa5b-4fa6-a79f-003263374118","price_dollars":"0.5600","delta_fp":"1.00","side":"yes","ts":"2026-05-14T22:08:35.967321Z","ts_ms":1778796515967}}

{"type":"orderbook_delta","sid":1,"seq":335,"msg":{"market_ticker":"KXBTC15M-26MAY141815-15","market_id":"9b5194ce-fa5b-4fa6-a79f-003263374118","price_dollars":"0.3200","delta_fp":"1.00","side":"no","ts":"2026-05-14T22:08:35.968401Z","ts_ms":1778796515968}}

{"type":"orderbook_delta","sid":1,"seq":336,"msg":{"market_ticker":"KXBTC15M-26MAY141815-15","market_id":"9b5194ce-fa5b-4fa6-a79f-003263374118","price_dollars":"0.3000","delta_fp":"1.00","side":"no","ts":"2026-05-14T22:08:35.969403Z","ts_ms":1778796515969}}

{"type":"orderbook_delta","sid":1,"seq":337,"msg":{"market_ticker":"KXBTC15M-26MAY141815-15","market_id":"9b5194ce-fa5b-4fa6-a79f-003263374118","price_dollars":"0.3600","delta_fp":"10.00","side":"no","ts":"2026-05-14T22:08:35.970002Z","ts_ms":1778796515970}}

{"type":"orderbook_delta","sid":1,"seq":338,"msg":{"market_ticker":"KXBTC15M-26MAY141815-15","market_id":"9b5194ce-fa5b-4fa6-a79f-003263374118","price_dollars":"0.5800","delta_fp":"-2.00","side":"yes","ts":"2026-05-14T22:08:36.011254Z","ts_ms":1778796516011}}

{"type":"orderbook_delta","sid":1,"seq":339,"msg":{"market_ticker":"KXBTC15M-26MAY141815-15","market_id":"9b5194ce-fa5b-4fa6-a79f-003263374118","price_dollars":"0.6200","delta_fp":"-250.13","side":"yes","ts":"2026-05-14T22:08:36.026925Z","ts_ms":1778796516026}}

{"type":"orderbook_delta","sid":1,"seq":340,"msg":{"market_ticker":"KXBTC15M-26MAY141815-15","market_id":"9b5194ce-fa5b-4fa6-a79f-003263374118","price_dollars":"0.6300","delta_fp":"250.13","side":"yes","ts":"2026-05-14T22:08:36.026925Z","ts_ms":1778796516026}}

{"type":"orderbook_delta","sid":1,"seq":341,"msg":{"market_ticker":"KXBTC15M-26MAY141815-15","market_id":"9b5194ce-fa5b-4fa6-a79f-003263374118","price_dollars":"0.5800","delta_fp":"-75.00","side":"yes","ts":"2026-05-14T22:08:36.030909Z","ts_ms":1778796516030}}

{"type":"orderbook_delta","sid":1,"seq":342,"msg":{"market_ticker":"KXBTC15M-26MAY141815-15","market_id":"9b5194ce-fa5b-4fa6-a79f-003263374118","price_dollars":"0.6300","delta_fp":"75.00","side":"yes","ts":"2026-05-14T22:08:36.030909Z","ts_ms":1778796516030}}

{"type":"orderbook_delta","sid":1,"seq":343,"msg":{"market_ticker":"KXBTC15M-26MAY141815-15","market_id":"9b5194ce-fa5b-4fa6-a79f-003263374118","price_dollars":"0.3300","delta_fp":"-10.00","side":"no","ts":"2026-05-14T22:08:36.068894Z","ts_ms":1778796516068}}

{"type":"orderbook_delta","sid":1,"seq":344,"msg":{"market_ticker":"KXBTC15M-26MAY141815-15","market_id":"9b5194ce-fa5b-4fa6-a79f-003263374118","price_dollars":"0.3200","delta_fp":"10.00","side":"no","ts":"2026-05-14T22:08:36.068894Z","ts_ms":1778796516068}}

{"type":"orderbook_delta","sid":1,"seq":345,"msg":{"market_ticker":"KXBTC15M-26MAY141815-15","market_id":"9b5194ce-fa5b-4fa6-a79f-003263374118","price_dollars":"0.3100","delta_fp":"-2.00","side":"no","ts":"2026-05-14T22:08:36.077828Z","ts_ms":1778796516077}}

{"type":"orderbook_delta","sid":1,"seq":346,"msg":{"market_ticker":"KXBTC15M-26MAY141815-15","market_id":"9b5194ce-fa5b-4fa6-a79f-003263374118","price_dollars":"0.3000","delta_fp":"2.00","side":"no","ts":"2026-05-14T22:08:36.077828Z","ts_ms":1778796516077}}

{"type":"orderbook_delta","sid":1,"seq":347,"msg":{"market_ticker":"KXBTC15M-26MAY141815-15","market_id":"9b5194ce-fa5b-4fa6-a79f-003263374118","price_dollars":"0.3600","delta_fp":"-10.00","side":"no","ts":"2026-05-14T22:08:36.086572Z","ts_ms":1778796516086}}

{"type":"orderbook_delta","sid":1,"seq":348,"msg":{"market_ticker":"KXBTC15M-26MAY141815-15","market_id":"9b5194ce-fa5b-4fa6-a79f-003263374118","price_dollars":"0.3400","delta_fp":"-26.98","side":"no","ts":"2026-05-14T22:08:36.086572Z","ts_ms":1778796516086}}

{"type":"orderbook_delta","sid":1,"seq":349,"msg":{"market_ticker":"KXBTC15M-26MAY141815-15","market_id":"9b5194ce-fa5b-4fa6-a79f-003263374118","price_dollars":"0.3400","delta_fp":"-75.00","side":"no","ts":"2026-05-14T22:08:36.108252Z","ts_ms":1778796516108}}

{"type":"orderbook_delta","sid":1,"seq":350,"msg":{"market_ticker":"KXBTC15M-26MAY141815-15","market_id":"9b5194ce-fa5b-4fa6-a79f-003263374118","price_dollars":"0.2800","delta_fp":"75.00","side":"no","ts":"2026-05-14T22:08:36.108252Z","ts_ms":1778796516108}}

{"type":"orderbook_delta","sid":1,"seq":351,"msg":{"market_ticker":"KXBTC15M-26MAY141815-15","market_id":"9b5194ce-fa5b-4fa6-a79f-003263374118","price_dollars":"0.6400","delta_fp":"100.00","side":"yes","ts":"2026-05-14T22:08:36.13473Z","ts_ms":1778796516134}}

{"type":"orderbook_delta","sid":1,"seq":352,"msg":{"market_ticker":"KXBTC15M-26MAY141815-15","market_id":"9b5194ce-fa5b-4fa6-a79f-003263374118","price_dollars":"0.6300","delta_fp":"-75.00","side":"yes","ts":"2026-05-14T22:08:36.135329Z","ts_ms":1778796516135}}

{"type":"orderbook_delta","sid":1,"seq":353,"msg":{"market_ticker":"KXBTC15M-26MAY141815-15","market_id":"9b5194ce-fa5b-4fa6-a79f-003263374118","price_dollars":"0.6400","delta_fp":"75.00","side":"yes","ts":"2026-05-14T22:08:36.135329Z","ts_ms":1778796516135}}

{"type":"orderbook_delta","sid":1,"seq":354,"msg":{"market_ticker":"KXBTC15M-26MAY141815-15","market_id":"9b5194ce-fa5b-4fa6-a79f-003263374118","price_dollars":"0.6300","delta_fp":"-10.00","side":"yes","ts":"2026-05-14T22:08:36.142637Z","ts_ms":1778796516142}}

{"type":"orderbook_delta","sid":1,"seq":355,"msg":{"market_ticker":"KXBTC15M-26MAY141815-15","market_id":"9b5194ce-fa5b-4fa6-a79f-003263374118","price_dollars":"0.6400","delta_fp":"10.00","side":"yes","ts":"2026-05-14T22:08:36.142637Z","ts_ms":1778796516142}}

{"type":"orderbook_delta","sid":1,"seq":356,"msg":{"market_ticker":"KXBTC15M-26MAY141815-15","market_id":"9b5194ce-fa5b-4fa6-a79f-003263374118","price_dollars":"0.6000","delta_fp":"-2.00","side":"yes","ts":"2026-05-14T22:08:36.14305Z","ts_ms":1778796516143}}

{"type":"orderbook_delta","sid":1,"seq":357,"msg":{"market_ticker":"KXBTC15M-26MAY141815-15","market_id":"9b5194ce-fa5b-4fa6-a79f-003263374118","price_dollars":"0.6100","delta_fp":"2.00","side":"yes","ts":"2026-05-14T22:08:36.14305Z","ts_ms":1778796516143}}

{"type":"orderbook_delta","sid":1,"seq":358,"msg":{"market_ticker":"KXBTC15M-26MAY141815-15","market_id":"9b5194ce-fa5b-4fa6-a79f-003263374118","price_dollars":"0.3300","delta_fp":"100.00","side":"no","ts":"2026-05-14T22:08:36.144465Z","ts_ms":1778796516144}}

{"type":"orderbook_delta","sid":1,"seq":359,"msg":{"market_ticker":"KXBTC15M-26MAY141815-15","market_id":"9b5194ce-fa5b-4fa6-a79f-003263374118","price_dollars":"0.5800","delta_fp":"2.00","side":"yes","ts":"2026-05-14T22:08:36.157823Z","ts_ms":1778796516157}}

{"type":"orderbook_delta","sid":1,"seq":360,"msg":{"market_ticker":"KXBTC15M-26MAY141815-15","market_id":"9b5194ce-fa5b-4fa6-a79f-003263374118","price_dollars":"0.6300","delta_fp":"26.00","side":"yes","ts":"2026-05-14T22:08:36.188013Z","ts_ms":1778796516188}}

{"type":"orderbook_delta","sid":1,"seq":361,"msg":{"market_ticker":"KXBTC15M-26MAY141815-15","market_id":"9b5194ce-fa5b-4fa6-a79f-003263374118","price_dollars":"0.3000","delta_fp":"-1.00","side":"no","ts":"2026-05-14T22:08:36.198498Z","ts_ms":1778796516198}}

{"type":"orderbook_delta","sid":1,"seq":362,"msg":{"market_ticker":"KXBTC15M-26MAY141815-15","market_id":"9b5194ce-fa5b-4fa6-a79f-003263374118","price_dollars":"0.3200","delta_fp":"-1.00","side":"no","ts":"2026-05-14T22:08:36.199414Z","ts_ms":1778796516199}}

{"type":"orderbook_delta","sid":1,"seq":363,"msg":{"market_ticker":"KXBTC15M-26MAY141815-15","market_id":"9b5194ce-fa5b-4fa6-a79f-003263374118","price_dollars":"0.5700","delta_fp":"-1.00","side":"yes","ts":"2026-05-14T22:08:36.200431Z","ts_ms":1778796516200}}

{"type":"orderbook_delta","sid":1,"seq":364,"msg":{"market_ticker":"KXBTC15M-26MAY141815-15","market_id":"9b5194ce-fa5b-4fa6-a79f-003263374118","price_dollars":"0.5600","delta_fp":"-1.00","side":"yes","ts":"2026-05-14T22:08:36.201528Z","ts_ms":1778796516201}}

{"type":"orderbook_delta","sid":1,"seq":365,"msg":{"market_ticker":"KXBTC15M-26MAY141815-15","market_id":"9b5194ce-fa5b-4fa6-a79f-003263374118","price_dollars":"0.6300","delta_fp":"-26.00","side":"yes","ts":"2026-05-14T22:08:36.20915Z","ts_ms":1778796516209}}

{"type":"orderbook_delta","sid":1,"seq":366,"msg":{"market_ticker":"KXBTC15M-26MAY141815-15","market_id":"9b5194ce-fa5b-4fa6-a79f-003263374118","price_dollars":"0.6400","delta_fp":"12.00","side":"yes","ts":"2026-05-14T22:08:36.20915Z","ts_ms":1778796516209}}

{"type":"orderbook_delta","sid":1,"seq":367,"msg":{"market_ticker":"KXBTC15M-26MAY141815-15","market_id":"9b5194ce-fa5b-4fa6-a79f-003263374118","price_dollars":"0.5800","delta_fp":"-251.00","side":"yes","ts":"2026-05-14T22:08:36.23609Z","ts_ms":1778796516236}}

{"type":"orderbook_delta","sid":1,"seq":368,"msg":{"market_ticker":"KXBTC15M-26MAY141815-15","market_id":"9b5194ce-fa5b-4fa6-a79f-003263374118","price_dollars":"0.3000","delta_fp":"-400.00","side":"no","ts":"2026-05-14T22:08:36.250875Z","ts_ms":1778796516250}}

{"type":"orderbook_delta","sid":1,"seq":369,"msg":{"market_ticker":"KXBTC15M-26MAY141815-15","market_id":"9b5194ce-fa5b-4fa6-a79f-003263374118","price_dollars":"0.2900","delta_fp":"400.00","side":"no","ts":"2026-05-14T22:08:36.250875Z","ts_ms":1778796516250}}

{"type":"orderbook_delta","sid":1,"seq":370,"msg":{"market_ticker":"KXBTC15M-26MAY141815-15","market_id":"9b5194ce-fa5b-4fa6-a79f-003263374118","price_dollars":"0.5700","delta_fp":"251.00","side":"yes","ts":"2026-05-14T22:08:36.283062Z","ts_ms":1778796516283}}

{"type":"orderbook_delta","sid":1,"seq":371,"msg":{"market_ticker":"KXBTC15M-26MAY141815-15","market_id":"9b5194ce-fa5b-4fa6-a79f-003263374118","price_dollars":"0.1500","delta_fp":"-40.00","side":"yes","ts":"2026-05-14T22:08:36.283962Z","ts_ms":1778796516283}}

{"type":"orderbook_delta","sid":1,"seq":372,"msg":{"market_ticker":"KXBTC15M-26MAY141815-15","market_id":"9b5194ce-fa5b-4fa6-a79f-003263374118","price_dollars":"0.1400","delta_fp":"40.00","side":"yes","ts":"2026-05-14T22:08:36.283962Z","ts_ms":1778796516283}}

{"type":"orderbook_delta","sid":1,"seq":373,"msg":{"market_ticker":"KXBTC15M-26MAY141815-15","market_id":"9b5194ce-fa5b-4fa6-a79f-003263374118","price_dollars":"0.6400","delta_fp":"-0.95","side":"yes","ts":"2026-05-14T22:08:36.311077Z","ts_ms":1778796516311}}

{"type":"orderbook_delta","sid":1,"seq":374,"msg":{"market_ticker":"KXBTC15M-26MAY141815-15","market_id":"9b5194ce-fa5b-4fa6-a79f-003263374118","price_dollars":"0.6400","delta_fp":"-5.24","side":"yes","ts":"2026-05-14T22:08:36.380809Z","ts_ms":1778796516380}}

{"type":"orderbook_delta","sid":1,"seq":375,"msg":{"market_ticker":"KXBTC15M-26MAY141815-15","market_id":"9b5194ce-fa5b-4fa6-a79f-003263374118","price_dollars":"0.5700","delta_fp":"-15.00","side":"yes","ts":"2026-05-14T22:08:36.395427Z","ts_ms":1778796516395}}

{"type":"orderbook_delta","sid":1,"seq":376,"msg":{"market_ticker":"KXBTC15M-26MAY141815-15","market_id":"9b5194ce-fa5b-4fa6-a79f-003263374118","price_dollars":"0.5600","delta_fp":"15.00","side":"yes","ts":"2026-05-14T22:08:36.395427Z","ts_ms":1778796516395}}

{"type":"orderbook_delta","sid":1,"seq":377,"msg":{"market_ticker":"KXBTC15M-26MAY141815-15","market_id":"9b5194ce-fa5b-4fa6-a79f-003263374118","price_dollars":"0.2900","delta_fp":"-150.00","side":"no","ts":"2026-05-14T22:08:36.397482Z","ts_ms":1778796516397}}

{"type":"orderbook_delta","sid":1,"seq":378,"msg":{"market_ticker":"KXBTC15M-26MAY141815-15","market_id":"9b5194ce-fa5b-4fa6-a79f-003263374118","price_dollars":"0.3000","delta_fp":"150.00","side":"no","ts":"2026-05-14T22:08:36.397482Z","ts_ms":1778796516397}}

{"type":"orderbook_delta","sid":1,"seq":379,"msg":{"market_ticker":"KXBTC15M-26MAY141815-15","market_id":"9b5194ce-fa5b-4fa6-a79f-003263374118","price_dollars":"0.5800","delta_fp":"-150.00","side":"yes","ts":"2026-05-14T22:08:36.412167Z","ts_ms":1778796516412}}

{"type":"orderbook_delta","sid":1,"seq":380,"msg":{"market_ticker":"KXBTC15M-26MAY141815-15","market_id":"9b5194ce-fa5b-4fa6-a79f-003263374118","price_dollars":"0.5700","delta_fp":"150.00","side":"yes","ts":"2026-05-14T22:08:36.412167Z","ts_ms":1778796516412}}

{"type":"orderbook_delta","sid":1,"seq":381,"msg":{"market_ticker":"KXBTC15M-26MAY141815-15","market_id":"9b5194ce-fa5b-4fa6-a79f-003263374118","price_dollars":"0.3300","delta_fp":"-100.00","side":"no","ts":"2026-05-14T22:08:36.416526Z","ts_ms":1778796516416}}

{"type":"orderbook_delta","sid":1,"seq":382,"msg":{"market_ticker":"KXBTC15M-26MAY141815-15","market_id":"9b5194ce-fa5b-4fa6-a79f-003263374118","price_dollars":"0.3400","delta_fp":"100.00","side":"no","ts":"2026-05-14T22:08:36.416526Z","ts_ms":1778796516416}}

{"type":"orderbook_delta","sid":1,"seq":383,"msg":{"market_ticker":"KXBTC15M-26MAY141815-15","market_id":"9b5194ce-fa5b-4fa6-a79f-003263374118","price_dollars":"0.6300","delta_fp":"81.00","side":"yes","ts":"2026-05-14T22:08:36.419414Z","ts_ms":1778796516419}}

{"type":"orderbook_delta","sid":1,"seq":384,"msg":{"market_ticker":"KXBTC15M-26MAY141815-15","market_id":"9b5194ce-fa5b-4fa6-a79f-003263374118","price_dollars":"0.3400","delta_fp":"10.00","side":"no","ts":"2026-05-14T22:08:36.431227Z","ts_ms":1778796516431}}

{"type":"orderbook_delta","sid":1,"seq":385,"msg":{"market_ticker":"KXBTC15M-26MAY141815-15","market_id":"9b5194ce-fa5b-4fa6-a79f-003263374118","price_dollars":"0.5600","delta_fp":"-15.00","side":"yes","ts":"2026-05-14T22:08:36.437147Z","ts_ms":1778796516437}}

{"type":"orderbook_delta","sid":1,"seq":386,"msg":{"market_ticker":"KXBTC15M-26MAY141815-15","market_id":"9b5194ce-fa5b-4fa6-a79f-003263374118","price_dollars":"0.5700","delta_fp":"15.00","side":"yes","ts":"2026-05-14T22:08:36.437147Z","ts_ms":1778796516437}}

{"type":"orderbook_delta","sid":1,"seq":387,"msg":{"market_ticker":"KXBTC15M-26MAY141815-15","market_id":"9b5194ce-fa5b-4fa6-a79f-003263374118","price_dollars":"0.6200","delta_fp":"-400.00","side":"yes","ts":"2026-05-14T22:08:36.440621Z","ts_ms":1778796516440}}

{"type":"orderbook_delta","sid":1,"seq":388,"msg":{"market_ticker":"KXBTC15M-26MAY141815-15","market_id":"9b5194ce-fa5b-4fa6-a79f-003263374118","price_dollars":"0.6300","delta_fp":"400.00","side":"yes","ts":"2026-05-14T22:08:36.440621Z","ts_ms":1778796516440}}

{"type":"orderbook_delta","sid":1,"seq":389,"msg":{"market_ticker":"KXBTC15M-26MAY141815-15","market_id":"9b5194ce-fa5b-4fa6-a79f-003263374118","price_dollars":"0.6400","delta_fp":"-75.00","side":"yes","ts":"2026-05-14T22:08:36.448004Z","ts_ms":1778796516448}}

{"type":"orderbook_delta","sid":1,"seq":390,"msg":{"market_ticker":"KXBTC15M-26MAY141815-15","market_id":"9b5194ce-fa5b-4fa6-a79f-003263374118","price_dollars":"0.5700","delta_fp":"75.00","side":"yes","ts":"2026-05-14T22:08:36.448004Z","ts_ms":1778796516448}}

{"type":"orderbook_delta","sid":1,"seq":391,"msg":{"market_ticker":"KXBTC15M-26MAY141815-15","market_id":"9b5194ce-fa5b-4fa6-a79f-003263374118","price_dollars":"0.2800","delta_fp":"-75.00","side":"no","ts":"2026-05-14T22:08:36.448454Z","ts_ms":1778796516448}}

{"type":"orderbook_delta","sid":1,"seq":392,"msg":{"market_ticker":"KXBTC15M-26MAY141815-15","market_id":"9b5194ce-fa5b-4fa6-a79f-003263374118","price_dollars":"0.3500","delta_fp":"75.00","side":"no","ts":"2026-05-14T22:08:36.448454Z","ts_ms":1778796516448}}

{"type":"orderbook_delta","sid":1,"seq":393,"msg":{"market_ticker":"KXBTC15M-26MAY141815-15","market_id":"9b5194ce-fa5b-4fa6-a79f-003263374118","price_dollars":"0.5800","delta_fp":"-2.00","side":"yes","ts":"2026-05-14T22:08:36.45371Z","ts_ms":1778796516453}}

{"type":"orderbook_delta","sid":1,"seq":394,"msg":{"market_ticker":"KXBTC15M-26MAY141815-15","market_id":"9b5194ce-fa5b-4fa6-a79f-003263374118","price_dollars":"0.3400","delta_fp":"-10.00","side":"no","ts":"2026-05-14T22:08:36.463434Z","ts_ms":1778796516463}}

{"type":"orderbook_delta","sid":1,"seq":395,"msg":{"market_ticker":"KXBTC15M-26MAY141815-15","market_id":"9b5194ce-fa5b-4fa6-a79f-003263374118","price_dollars":"0.3300","delta_fp":"21.00","side":"no","ts":"2026-05-14T22:08:36.463434Z","ts_ms":1778796516463}}

{"type":"orderbook_delta","sid":1,"seq":396,"msg":{"market_ticker":"KXBTC15M-26MAY141815-15","market_id":"9b5194ce-fa5b-4fa6-a79f-003263374118","price_dollars":"0.6300","delta_fp":"-400.00","side":"yes","ts":"2026-05-14T22:08:36.481217Z","ts_ms":1778796516481}}

{"type":"orderbook_delta","sid":1,"seq":397,"msg":{"market_ticker":"KXBTC15M-26MAY141815-15","market_id":"9b5194ce-fa5b-4fa6-a79f-003263374118","price_dollars":"0.6200","delta_fp":"400.00","side":"yes","ts":"2026-05-14T22:08:36.481217Z","ts_ms":1778796516481}}

{"type":"orderbook_delta","sid":1,"seq":398,"msg":{"market_ticker":"KXBTC15M-26MAY141815-15","market_id":"9b5194ce-fa5b-4fa6-a79f-003263374118","price_dollars":"0.6200","delta_fp":"249.00","side":"yes","ts":"2026-05-14T22:08:36.483278Z","ts_ms":1778796516483}}

{"type":"orderbook_delta","sid":1,"seq":399,"msg":{"market_ticker":"KXBTC15M-26MAY141815-15","market_id":"9b5194ce-fa5b-4fa6-a79f-003263374118","price_dollars":"0.5700","delta_fp":"-15.00","side":"yes","ts":"2026-05-14T22:08:36.48447Z","ts_ms":1778796516484}}

{"type":"orderbook_delta","sid":1,"seq":400,"msg":{"market_ticker":"KXBTC15M-26MAY141815-15","market_id":"9b5194ce-fa5b-4fa6-a79f-003263374118","price_dollars":"0.5800","delta_fp":"15.00","side":"yes","ts":"2026-05-14T22:08:36.48447Z","ts_ms":1778796516484}}

{"type":"orderbook_delta","sid":1,"seq":401,"msg":{"market_ticker":"KXBTC15M-26MAY141815-15","market_id":"9b5194ce-fa5b-4fa6-a79f-003263374118","price_dollars":"0.6400","delta_fp":"-10.00","side":"yes","ts":"2026-05-14T22:08:36.496464Z","ts_ms":1778796516496}}

{"type":"orderbook_delta","sid":1,"seq":402,"msg":{"market_ticker":"KXBTC15M-26MAY141815-15","market_id":"9b5194ce-fa5b-4fa6-a79f-003263374118","price_dollars":"0.6300","delta_fp":"10.00","side":"yes","ts":"2026-05-14T22:08:36.496464Z","ts_ms":1778796516496}}

{"type":"orderbook_delta","sid":1,"seq":403,"msg":{"market_ticker":"KXBTC15M-26MAY141815-15","market_id":"9b5194ce-fa5b-4fa6-a79f-003263374118","price_dollars":"0.3200","delta_fp":"-10.00","side":"no","ts":"2026-05-14T22:08:36.496986Z","ts_ms":1778796516496}}

{"type":"orderbook_delta","sid":1,"seq":404,"msg":{"market_ticker":"KXBTC15M-26MAY141815-15","market_id":"9b5194ce-fa5b-4fa6-a79f-003263374118","price_dollars":"0.3300","delta_fp":"10.00","side":"no","ts":"2026-05-14T22:08:36.496986Z","ts_ms":1778796516496}}

{"type":"orderbook_delta","sid":1,"seq":405,"msg":{"market_ticker":"KXBTC15M-26MAY141815-15","market_id":"9b5194ce-fa5b-4fa6-a79f-003263374118","price_dollars":"0.3300","delta_fp":"-21.00","side":"no","ts":"2026-05-14T22:08:36.498321Z","ts_ms":1778796516498}}

{"type":"orderbook_delta","sid":1,"seq":406,"msg":{"market_ticker":"KXBTC15M-26MAY141815-15","market_id":"9b5194ce-fa5b-4fa6-a79f-003263374118","price_dollars":"0.3400","delta_fp":"10.00","side":"no","ts":"2026-05-14T22:08:36.498321Z","ts_ms":1778796516498}}

{"type":"orderbook_delta","sid":1,"seq":407,"msg":{"market_ticker":"KXBTC15M-26MAY141815-15","market_id":"9b5194ce-fa5b-4fa6-a79f-003263374118","price_dollars":"0.3500","delta_fp":"-75.00","side":"no","ts":"2026-05-14T22:08:36.500234Z","ts_ms":1778796516500}}

{"type":"orderbook_delta","sid":1,"seq":408,"msg":{"market_ticker":"KXBTC15M-26MAY141815-15","market_id":"9b5194ce-fa5b-4fa6-a79f-003263374118","price_dollars":"0.3400","delta_fp":"75.00","side":"no","ts":"2026-05-14T22:08:36.500234Z","ts_ms":1778796516500}}

{"type":"orderbook_delta","sid":1,"seq":409,"msg":{"market_ticker":"KXBTC15M-26MAY141815-15","market_id":"9b5194ce-fa5b-4fa6-a79f-003263374118","price_dollars":"0.3400","delta_fp":"-10.00","side":"no","ts":"2026-05-14T22:08:36.517793Z","ts_ms":1778796516517}}

{"type":"orderbook_delta","sid":1,"seq":410,"msg":{"market_ticker":"KXBTC15M-26MAY141815-15","market_id":"9b5194ce-fa5b-4fa6-a79f-003263374118","price_dollars":"0.3300","delta_fp":"20.00","side":"no","ts":"2026-05-14T22:08:36.517793Z","ts_ms":1778796516517}}

{"type":"orderbook_delta","sid":1,"seq":411,"msg":{"market_ticker":"KXBTC15M-26MAY141815-15","market_id":"9b5194ce-fa5b-4fa6-a79f-003263374118","price_dollars":"0.2600","delta_fp":"249.00","side":"no","ts":"2026-05-14T22:08:36.531025Z","ts_ms":1778796516531}}

{"type":"orderbook_delta","sid":1,"seq":412,"msg":{"market_ticker":"KXBTC15M-26MAY141815-15","market_id":"9b5194ce-fa5b-4fa6-a79f-003263374118","price_dollars":"0.5800","delta_fp":"-15.00","side":"yes","ts":"2026-05-14T22:08:36.531453Z","ts_ms":1778796516531}}

{"type":"orderbook_delta","sid":1,"seq":413,"msg":{"market_ticker":"KXBTC15M-26MAY141815-15","market_id":"9b5194ce-fa5b-4fa6-a79f-003263374118","price_dollars":"0.5700","delta_fp":"15.00","side":"yes","ts":"2026-05-14T22:08:36.531453Z","ts_ms":1778796516531}}

{"type":"orderbook_delta","sid":1,"seq":414,"msg":{"market_ticker":"KXBTC15M-26MAY141815-15","market_id":"9b5194ce-fa5b-4fa6-a79f-003263374118","price_dollars":"0.1400","delta_fp":"-40.00","side":"yes","ts":"2026-05-14T22:08:36.534445Z","ts_ms":1778796516534}}

{"type":"orderbook_delta","sid":1,"seq":415,"msg":{"market_ticker":"KXBTC15M-26MAY141815-15","market_id":"9b5194ce-fa5b-4fa6-a79f-003263374118","price_dollars":"0.1500","delta_fp":"40.00","side":"yes","ts":"2026-05-14T22:08:36.534445Z","ts_ms":1778796516534}}

{"type":"orderbook_delta","sid":1,"seq":416,"msg":{"market_ticker":"KXBTC15M-26MAY141815-15","market_id":"9b5194ce-fa5b-4fa6-a79f-003263374118","price_dollars":"0.0800","delta_fp":"2.00","side":"no","ts":"2026-05-14T22:08:36.539729Z","ts_ms":1778796516539}}

{"type":"orderbook_delta","sid":1,"seq":417,"msg":{"market_ticker":"KXBTC15M-26MAY141815-15","market_id":"9b5194ce-fa5b-4fa6-a79f-003263374118","price_dollars":"0.5700","delta_fp":"-2.00","side":"yes","ts":"2026-05-14T22:08:36.565045Z","ts_ms":1778796516565}}

{"type":"orderbook_delta","sid":1,"seq":418,"msg":{"market_ticker":"KXBTC15M-26MAY141815-15","market_id":"9b5194ce-fa5b-4fa6-a79f-003263374118","price_dollars":"0.6400","delta_fp":"-12.00","side":"yes","ts":"2026-05-14T22:08:36.570574Z","ts_ms":1778796516570}}

{"type":"orderbook_delta","sid":1,"seq":419,"msg":{"market_ticker":"KXBTC15M-26MAY141815-15","market_id":"9b5194ce-fa5b-4fa6-a79f-003263374118","price_dollars":"0.6300","delta_fp":"25.00","side":"yes","ts":"2026-05-14T22:08:36.570574Z","ts_ms":1778796516570}}

{"type":"orderbook_delta","sid":1,"seq":420,"msg":{"market_ticker":"KXBTC15M-26MAY141815-15","market_id":"9b5194ce-fa5b-4fa6-a79f-003263374118","price_dollars":"0.3300","delta_fp":"-20.00","side":"no","ts":"2026-05-14T22:08:36.582275Z","ts_ms":1778796516582}}

{"type":"orderbook_delta","sid":1,"seq":421,"msg":{"market_ticker":"KXBTC15M-26MAY141815-15","market_id":"9b5194ce-fa5b-4fa6-a79f-003263374118","price_dollars":"0.3400","delta_fp":"12.00","side":"no","ts":"2026-05-14T22:08:36.582275Z","ts_ms":1778796516582}}

{"type":"orderbook_delta","sid":1,"seq":422,"msg":{"market_ticker":"KXBTC15M-26MAY141815-15","market_id":"9b5194ce-fa5b-4fa6-a79f-003263374118","price_dollars":"0.5700","delta_fp":"-75.00","side":"yes","ts":"2026-05-14T22:08:36.596105Z","ts_ms":1778796516596}}

{"type":"orderbook_delta","sid":1,"seq":423,"msg":{"market_ticker":"KXBTC15M-26MAY141815-15","market_id":"9b5194ce-fa5b-4fa6-a79f-003263374118","price_dollars":"0.6400","delta_fp":"75.00","side":"yes","ts":"2026-05-14T22:08:36.596105Z","ts_ms":1778796516596}}

{"type":"orderbook_delta","sid":1,"seq":424,"msg":{"market_ticker":"KXBTC15M-26MAY141815-15","market_id":"9b5194ce-fa5b-4fa6-a79f-003263374118","price_dollars":"0.5700","delta_fp":"-251.00","side":"yes","ts":"2026-05-14T22:08:36.605931Z","ts_ms":1778796516605}}

{"type":"orderbook_delta","sid":1,"seq":425,"msg":{"market_ticker":"KXBTC15M-26MAY141815-15","market_id":"9b5194ce-fa5b-4fa6-a79f-003263374118","price_dollars":"0.6400","delta_fp":"-75.00","side":"yes","ts":"2026-05-14T22:08:36.607742Z","ts_ms":1778796516607}}

{"type":"orderbook_delta","sid":1,"seq":426,"msg":{"market_ticker":"KXBTC15M-26MAY141815-15","market_id":"9b5194ce-fa5b-4fa6-a79f-003263374118","price_dollars":"0.5800","delta_fp":"75.00","side":"yes","ts":"2026-05-14T22:08:36.607742Z","ts_ms":1778796516607}}

{"type":"orderbook_delta","sid":1,"seq":427,"msg":{"market_ticker":"KXBTC15M-26MAY141815-15","market_id":"9b5194ce-fa5b-4fa6-a79f-003263374118","price_dollars":"0.3400","delta_fp":"-75.00","side":"no","ts":"2026-05-14T22:08:36.608347Z","ts_ms":1778796516608}}

{"type":"orderbook_delta","sid":1,"seq":428,"msg":{"market_ticker":"KXBTC15M-26MAY141815-15","market_id":"9b5194ce-fa5b-4fa6-a79f-003263374118","price_dollars":"0.3500","delta_fp":"75.00","side":"no","ts":"2026-05-14T22:08:36.608347Z","ts_ms":1778796516608}}

{"type":"orderbook_delta","sid":1,"seq":429,"msg":{"market_ticker":"KXBTC15M-26MAY141815-15","market_id":"9b5194ce-fa5b-4fa6-a79f-003263374118","price_dollars":"0.6300","delta_fp":"-25.00","side":"yes","ts":"2026-05-14T22:08:36.608891Z","ts_ms":1778796516608}}

{"type":"orderbook_delta","sid":1,"seq":430,"msg":{"market_ticker":"KXBTC15M-26MAY141815-15","market_id":"9b5194ce-fa5b-4fa6-a79f-003263374118","price_dollars":"0.6400","delta_fp":"20.00","side":"yes","ts":"2026-05-14T22:08:36.608891Z","ts_ms":1778796516608}}

{"type":"orderbook_delta","sid":1,"seq":431,"msg":{"market_ticker":"KXBTC15M-26MAY141815-15","market_id":"9b5194ce-fa5b-4fa6-a79f-003263374118","price_dollars":"0.3400","delta_fp":"-12.00","side":"no","ts":"2026-05-14T22:08:36.615045Z","ts_ms":1778796516615}}

{"type":"orderbook_delta","sid":1,"seq":432,"msg":{"market_ticker":"KXBTC15M-26MAY141815-15","market_id":"9b5194ce-fa5b-4fa6-a79f-003263374118","price_dollars":"0.3300","delta_fp":"16.00","side":"no","ts":"2026-05-14T22:08:36.615045Z","ts_ms":1778796516615}}

{"type":"orderbook_delta","sid":1,"seq":433,"msg":{"market_ticker":"KXBTC15M-26MAY141815-15","market_id":"9b5194ce-fa5b-4fa6-a79f-003263374118","price_dollars":"0.3400","delta_fp":"-100.00","side":"no","ts":"2026-05-14T22:08:36.620453Z","ts_ms":1778796516620}}

{"type":"orderbook_delta","sid":1,"seq":434,"msg":{"market_ticker":"KXBTC15M-26MAY141815-15","market_id":"9b5194ce-fa5b-4fa6-a79f-003263374118","price_dollars":"0.5800","delta_fp":"251.00","side":"yes","ts":"2026-05-14T22:08:36.626901Z","ts_ms":1778796516626}}

{"type":"orderbook_delta","sid":1,"seq":435,"msg":{"market_ticker":"KXBTC15M-26MAY141815-15","market_id":"9b5194ce-fa5b-4fa6-a79f-003263374118","price_dollars":"0.6400","delta_fp":"-93.81","side":"yes","ts":"2026-05-14T22:08:36.670775Z","ts_ms":1778796516670}}

{"type":"orderbook_delta","sid":1,"seq":436,"msg":{"market_ticker":"KXBTC15M-26MAY141815-15","market_id":"9b5194ce-fa5b-4fa6-a79f-003263374118","price_dollars":"0.6400","delta_fp":"-20.00","side":"yes","ts":"2026-05-14T22:08:36.670775Z","ts_ms":1778796516670}}

{"type":"orderbook_delta","sid":1,"seq":437,"msg":{"market_ticker":"KXBTC15M-26MAY141815-15","market_id":"9b5194ce-fa5b-4fa6-a79f-003263374118","price_dollars":"0.3400","delta_fp":"-100.00","side":"no","ts":"2026-05-14T22:08:36.685859Z","ts_ms":1778796516685}}

{"type":"orderbook_delta","sid":1,"seq":438,"msg":{"market_ticker":"KXBTC15M-26MAY141815-15","market_id":"9b5194ce-fa5b-4fa6-a79f-003263374118","price_dollars":"0.3500","delta_fp":"-75.00","side":"no","ts":"2026-05-14T22:08:36.686078Z","ts_ms":1778796516686}}

{"type":"orderbook_delta","sid":1,"seq":439,"msg":{"market_ticker":"KXBTC15M-26MAY141815-15","market_id":"9b5194ce-fa5b-4fa6-a79f-003263374118","price_dollars":"0.3300","delta_fp":"-100.00","side":"no","ts":"2026-05-14T22:08:36.686083Z","ts_ms":1778796516686}}

{"type":"orderbook_delta","sid":1,"seq":440,"msg":{"market_ticker":"KXBTC15M-26MAY141815-15","market_id":"9b5194ce-fa5b-4fa6-a79f-003263374118","price_dollars":"0.3100","delta_fp":"-100.00","side":"no","ts":"2026-05-14T22:08:36.686482Z","ts_ms":1778796516686}}

{"type":"orderbook_delta","sid":1,"seq":441,"msg":{"market_ticker":"KXBTC15M-26MAY141815-15","market_id":"9b5194ce-fa5b-4fa6-a79f-003263374118","price_dollars":"0.3200","delta_fp":"-44.56","side":"no","ts":"2026-05-14T22:08:36.686493Z","ts_ms":1778796516686}}

{"type":"orderbook_delta","sid":1,"seq":442,"msg":{"market_ticker":"KXBTC15M-26MAY141815-15","market_id":"9b5194ce-fa5b-4fa6-a79f-003263374118","price_dollars":"0.3300","delta_fp":"-10.00","side":"no","ts":"2026-05-14T22:08:36.686691Z","ts_ms":1778796516686}}

{"type":"orderbook_delta","sid":1,"seq":443,"msg":{"market_ticker":"KXBTC15M-26MAY141815-15","market_id":"9b5194ce-fa5b-4fa6-a79f-003263374118","price_dollars":"0.6400","delta_fp":"10.00","side":"yes","ts":"2026-05-14T22:08:36.687095Z","ts_ms":1778796516687}}

{"type":"orderbook_delta","sid":1,"seq":444,"msg":{"market_ticker":"KXBTC15M-26MAY141815-15","market_id":"9b5194ce-fa5b-4fa6-a79f-003263374118","price_dollars":"0.2900","delta_fp":"-400.00","side":"no","ts":"2026-05-14T22:08:36.69063Z","ts_ms":1778796516690}}

{"type":"orderbook_delta","sid":1,"seq":445,"msg":{"market_ticker":"KXBTC15M-26MAY141815-15","market_id":"9b5194ce-fa5b-4fa6-a79f-003263374118","price_dollars":"0.2700","delta_fp":"400.00","side":"no","ts":"2026-05-14T22:08:36.69063Z","ts_ms":1778796516690}}

{"type":"orderbook_delta","sid":1,"seq":446,"msg":{"market_ticker":"KXBTC15M-26MAY141815-15","market_id":"9b5194ce-fa5b-4fa6-a79f-003263374118","price_dollars":"0.6200","delta_fp":"-818.91","side":"yes","ts":"2026-05-14T22:08:36.694803Z","ts_ms":1778796516694}}

{"type":"orderbook_delta","sid":1,"seq":447,"msg":{"market_ticker":"KXBTC15M-26MAY141815-15","market_id":"9b5194ce-fa5b-4fa6-a79f-003263374118","price_dollars":"0.6300","delta_fp":"1100.91","side":"yes","ts":"2026-05-14T22:08:36.694803Z","ts_ms":1778796516694}}

{"type":"orderbook_delta","sid":1,"seq":448,"msg":{"market_ticker":"KXBTC15M-26MAY141815-15","market_id":"9b5194ce-fa5b-4fa6-a79f-003263374118","price_dollars":"0.6200","delta_fp":"-400.00","side":"yes","ts":"2026-05-14T22:08:36.695136Z","ts_ms":1778796516695}}

{"type":"orderbook_delta","sid":1,"seq":449,"msg":{"market_ticker":"KXBTC15M-26MAY141815-15","market_id":"9b5194ce-fa5b-4fa6-a79f-003263374118","price_dollars":"0.6300","delta_fp":"400.00","side":"yes","ts":"2026-05-14T22:08:36.695136Z","ts_ms":1778796516695}}

{"type":"orderbook_delta","sid":1,"seq":450,"msg":{"market_ticker":"KXBTC15M-26MAY141815-15","market_id":"9b5194ce-fa5b-4fa6-a79f-003263374118","price_dollars":"0.6200","delta_fp":"-282.00","side":"yes","ts":"2026-05-14T22:08:36.696016Z","ts_ms":1778796516696}}

{"type":"orderbook_delta","sid":1,"seq":451,"msg":{"market_ticker":"KXBTC15M-26MAY141815-15","market_id":"9b5194ce-fa5b-4fa6-a79f-003263374118","price_dollars":"0.6300","delta_fp":"-250.13","side":"yes","ts":"2026-05-14T22:08:36.69757Z","ts_ms":1778796516697}}

{"type":"orderbook_delta","sid":1,"seq":452,"msg":{"market_ticker":"KXBTC15M-26MAY141815-15","market_id":"9b5194ce-fa5b-4fa6-a79f-003263374118","price_dollars":"0.6400","delta_fp":"250.13","side":"yes","ts":"2026-05-14T22:08:36.69757Z","ts_ms":1778796516697}}

{"type":"orderbook_delta","sid":1,"seq":453,"msg":{"market_ticker":"KXBTC15M-26MAY141815-15","market_id":"9b5194ce-fa5b-4fa6-a79f-003263374118","price_dollars":"0.3300","delta_fp":"-1000.87","side":"no","ts":"2026-05-14T22:08:36.698596Z","ts_ms":1778796516698}}

{"type":"orderbook_delta","sid":1,"seq":454,"msg":{"market_ticker":"KXBTC15M-26MAY141815-15","market_id":"9b5194ce-fa5b-4fa6-a79f-003263374118","price_dollars":"0.2900","delta_fp":"1000.87","side":"no","ts":"2026-05-14T22:08:36.698596Z","ts_ms":1778796516698}}

{"type":"orderbook_delta","sid":1,"seq":455,"msg":{"market_ticker":"KXBTC15M-26MAY141815-15","market_id":"9b5194ce-fa5b-4fa6-a79f-003263374118","price_dollars":"0.6400","delta_fp":"100.00","side":"yes","ts":"2026-05-14T22:08:36.69917Z","ts_ms":1778796516699}}

{"type":"orderbook_delta","sid":1,"seq":456,"msg":{"market_ticker":"KXBTC15M-26MAY141815-15","market_id":"9b5194ce-fa5b-4fa6-a79f-003263374118","price_dollars":"0.3400","delta_fp":"-898.54","side":"no","ts":"2026-05-14T22:08:36.699979Z","ts_ms":1778796516699}}

{"type":"orderbook_delta","sid":1,"seq":457,"msg":{"market_ticker":"KXBTC15M-26MAY141815-15","market_id":"9b5194ce-fa5b-4fa6-a79f-003263374118","price_dollars":"0.3000","delta_fp":"1100.54","side":"no","ts":"2026-05-14T22:08:36.699979Z","ts_ms":1778796516699}}

{"type":"orderbook_delta","sid":1,"seq":458,"msg":{"market_ticker":"KXBTC15M-26MAY141815-15","market_id":"9b5194ce-fa5b-4fa6-a79f-003263374118","price_dollars":"0.3200","delta_fp":"-81.00","side":"no","ts":"2026-05-14T22:08:36.702267Z","ts_ms":1778796516702}}

{"type":"orderbook_delta","sid":1,"seq":459,"msg":{"market_ticker":"KXBTC15M-26MAY141815-15","market_id":"9b5194ce-fa5b-4fa6-a79f-003263374118","price_dollars":"0.6400","delta_fp":"-250.13","side":"yes","ts":"2026-05-14T22:08:36.703035Z","ts_ms":1778796516703}}

{"type":"orderbook_delta","sid":1,"seq":460,"msg":{"market_ticker":"KXBTC15M-26MAY141815-15","market_id":"9b5194ce-fa5b-4fa6-a79f-003263374118","price_dollars":"0.2700","delta_fp":"-400.00","side":"no","ts":"2026-05-14T22:08:36.703181Z","ts_ms":1778796516703}}

{"type":"orderbook_delta","sid":1,"seq":461,"msg":{"market_ticker":"KXBTC15M-26MAY141815-15","market_id":"9b5194ce-fa5b-4fa6-a79f-003263374118","price_dollars":"0.2600","delta_fp":"400.00","side":"no","ts":"2026-05-14T22:08:36.703181Z","ts_ms":1778796516703}}

{"type":"orderbook_delta","sid":1,"seq":462,"msg":{"market_ticker":"KXBTC15M-26MAY141815-15","market_id":"9b5194ce-fa5b-4fa6-a79f-003263374118","price_dollars":"0.6300","delta_fp":"-1100.91","side":"yes","ts":"2026-05-14T22:08:36.703515Z","ts_ms":1778796516703}}

{"type":"orderbook_delta","sid":1,"seq":463,"msg":{"market_ticker":"KXBTC15M-26MAY141815-15","market_id":"9b5194ce-fa5b-4fa6-a79f-003263374118","price_dollars":"0.5700","delta_fp":"-50.00","side":"yes","ts":"2026-05-14T22:08:36.704362Z","ts_ms":1778796516704}}

{"type":"orderbook_delta","sid":1,"seq":464,"msg":{"market_ticker":"KXBTC15M-26MAY141815-15","market_id":"9b5194ce-fa5b-4fa6-a79f-003263374118","price_dollars":"0.5800","delta_fp":"50.00","side":"yes","ts":"2026-05-14T22:08:36.704944Z","ts_ms":1778796516704}}

{"type":"orderbook_delta","sid":1,"seq":465,"msg":{"market_ticker":"KXBTC15M-26MAY141815-15","market_id":"9b5194ce-fa5b-4fa6-a79f-003263374118","price_dollars":"0.2900","delta_fp":"-1000.87","side":"no","ts":"2026-05-14T22:08:36.705118Z","ts_ms":1778796516705}}

{"type":"orderbook_delta","sid":1,"seq":466,"msg":{"market_ticker":"KXBTC15M-26MAY141815-15","market_id":"9b5194ce-fa5b-4fa6-a79f-003263374118","price_dollars":"0.3000","delta_fp":"-1100.54","side":"no","ts":"2026-05-14T22:08:36.706511Z","ts_ms":1778796516706}}

{"type":"orderbook_delta","sid":1,"seq":467,"msg":{"market_ticker":"KXBTC15M-26MAY141815-15","market_id":"9b5194ce-fa5b-4fa6-a79f-003263374118","price_dollars":"0.2600","delta_fp":"-249.00","side":"no","ts":"2026-05-14T22:08:36.706977Z","ts_ms":1778796516706}}

{"type":"orderbook_delta","sid":1,"seq":468,"msg":{"market_ticker":"KXBTC15M-26MAY141815-15","market_id":"9b5194ce-fa5b-4fa6-a79f-003263374118","price_dollars":"0.5800","delta_fp":"-50.00","side":"yes","ts":"2026-05-14T22:08:36.708196Z","ts_ms":1778796516708}}

{"type":"orderbook_delta","sid":1,"seq":469,"msg":{"market_ticker":"KXBTC15M-26MAY141815-15","market_id":"9b5194ce-fa5b-4fa6-a79f-003263374118","price_dollars":"0.1600","delta_fp":"-6249.00","side":"no","ts":"2026-05-14T22:08:36.70837Z","ts_ms":1778796516708}}

{"type":"orderbook_delta","sid":1,"seq":470,"msg":{"market_ticker":"KXBTC15M-26MAY141815-15","market_id":"9b5194ce-fa5b-4fa6-a79f-003263374118","price_dollars":"0.1900","delta_fp":"-4999.00","side":"no","ts":"2026-05-14T22:08:36.70837Z","ts_ms":1778796516708}}

{"type":"orderbook_delta","sid":1,"seq":471,"msg":{"market_ticker":"KXBTC15M-26MAY141815-15","market_id":"9b5194ce-fa5b-4fa6-a79f-003263374118","price_dollars":"0.3000","delta_fp":"-100.00","side":"no","ts":"2026-05-14T22:08:36.708458Z","ts_ms":1778796516708}}

{"type":"orderbook_delta","sid":1,"seq":472,"msg":{"market_ticker":"KXBTC15M-26MAY141815-15","market_id":"9b5194ce-fa5b-4fa6-a79f-003263374118","price_dollars":"0.5800","delta_fp":"-75.00","side":"yes","ts":"2026-05-14T22:08:36.708652Z","ts_ms":1778796516708}}

{"type":"orderbook_delta","sid":1,"seq":473,"msg":{"market_ticker":"KXBTC15M-26MAY141815-15","market_id":"9b5194ce-fa5b-4fa6-a79f-003263374118","price_dollars":"0.6400","delta_fp":"75.00","side":"yes","ts":"2026-05-14T22:08:36.708652Z","ts_ms":1778796516708}}

{"type":"orderbook_delta","sid":1,"seq":474,"msg":{"market_ticker":"KXBTC15M-26MAY141815-15","market_id":"9b5194ce-fa5b-4fa6-a79f-003263374118","price_dollars":"0.6200","delta_fp":"-249.00","side":"yes","ts":"2026-05-14T22:08:36.708801Z","ts_ms":1778796516708}}

{"type":"orderbook_delta","sid":1,"seq":475,"msg":{"market_ticker":"KXBTC15M-26MAY141815-15","market_id":"9b5194ce-fa5b-4fa6-a79f-003263374118","price_dollars":"0.5300","delta_fp":"-6249.00","side":"yes","ts":"2026-05-14T22:08:36.709202Z","ts_ms":1778796516709}}

{"type":"orderbook_delta","sid":1,"seq":476,"msg":{"market_ticker":"KXBTC15M-26MAY141815-15","market_id":"9b5194ce-fa5b-4fa6-a79f-003263374118","price_dollars":"0.5600","delta_fp":"-4999.00","side":"yes","ts":"2026-05-14T22:08:36.709202Z","ts_ms":1778796516709}}

{"type":"orderbook_delta","sid":1,"seq":477,"msg":{"market_ticker":"KXBTC15M-26MAY141815-15","market_id":"9b5194ce-fa5b-4fa6-a79f-003263374118","price_dollars":"0.3300","delta_fp":"-10.00","side":"no","ts":"2026-05-14T22:08:36.711258Z","ts_ms":1778796516711}}

{"type":"orderbook_delta","sid":1,"seq":478,"msg":{"market_ticker":"KXBTC15M-26MAY141815-15","market_id":"9b5194ce-fa5b-4fa6-a79f-003263374118","price_dollars":"0.3300","delta_fp":"-16.00","side":"no","ts":"2026-05-14T22:08:36.711258Z","ts_ms":1778796516711}}

{"type":"orderbook_delta","sid":1,"seq":479,"msg":{"market_ticker":"KXBTC15M-26MAY141815-15","market_id":"9b5194ce-fa5b-4fa6-a79f-003263374118","price_dollars":"0.2600","delta_fp":"-400.00","side":"no","ts":"2026-05-14T22:08:36.713674Z","ts_ms":1778796516713}}

{"type":"orderbook_delta","sid":1,"seq":480,"msg":{"market_ticker":"KXBTC15M-26MAY141815-15","market_id":"9b5194ce-fa5b-4fa6-a79f-003263374118","price_dollars":"0.2400","delta_fp":"400.00","side":"no","ts":"2026-05-14T22:08:36.713674Z","ts_ms":1778796516713}}

{"type":"orderbook_delta","sid":1,"seq":481,"msg":{"market_ticker":"KXBTC15M-26MAY141815-15","market_id":"9b5194ce-fa5b-4fa6-a79f-003263374118","price_dollars":"0.6400","delta_fp":"1000.00","side":"yes","ts":"2026-05-14T22:08:36.716106Z","ts_ms":1778796516716}}

{"type":"orderbook_delta","sid":1,"seq":482,"msg":{"market_ticker":"KXBTC15M-26MAY141815-15","market_id":"9b5194ce-fa5b-4fa6-a79f-003263374118","price_dollars":"0.2700","delta_fp":"1100.00","side":"no","ts":"2026-05-14T22:08:36.718287Z","ts_ms":1778796516718}}

{"type":"orderbook_delta","sid":1,"seq":483,"msg":{"market_ticker":"KXBTC15M-26MAY141815-15","market_id":"9b5194ce-fa5b-4fa6-a79f-003263374118","price_dollars":"0.6300","delta_fp":"1675.48","side":"yes","ts":"2026-05-14T22:08:36.718643Z","ts_ms":1778796516718}}

{"type":"orderbook_delta","sid":1,"seq":484,"msg":{"market_ticker":"KXBTC15M-26MAY141815-15","market_id":"9b5194ce-fa5b-4fa6-a79f-003263374118","price_dollars":"0.6300","delta_fp":"-81.00","side":"yes","ts":"2026-05-14T22:08:36.722381Z","ts_ms":1778796516722}}

{"type":"orderbook_delta","sid":1,"seq":485,"msg":{"market_ticker":"KXBTC15M-26MAY141815-15","market_id":"9b5194ce-fa5b-4fa6-a79f-003263374118","price_dollars":"0.6400","delta_fp":"81.00","side":"yes","ts":"2026-05-14T22:08:36.722381Z","ts_ms":1778796516722}}

{"type":"orderbook_delta","sid":1,"seq":486,"msg":{"market_ticker":"KXBTC15M-26MAY141815-15","market_id":"9b5194ce-fa5b-4fa6-a79f-003263374118","price_dollars":"0.6300","delta_fp":"8.00","side":"yes","ts":"2026-05-14T22:08:36.722856Z","ts_ms":1778796516722}}

{"type":"orderbook_delta","sid":1,"seq":487,"msg":{"market_ticker":"KXBTC15M-26MAY141815-15","market_id":"9b5194ce-fa5b-4fa6-a79f-003263374118","price_dollars":"0.2900","delta_fp":"-10.00","side":"no","ts":"2026-05-14T22:08:36.72435Z","ts_ms":1778796516724}}

{"type":"orderbook_delta","sid":1,"seq":488,"msg":{"market_ticker":"KXBTC15M-26MAY141815-15","market_id":"9b5194ce-fa5b-4fa6-a79f-003263374118","price_dollars":"0.6500","delta_fp":"100.00","side":"yes","ts":"2026-05-14T22:08:36.724564Z","ts_ms":1778796516724}}

{"type":"orderbook_delta","sid":1,"seq":489,"msg":{"market_ticker":"KXBTC15M-26MAY141815-15","market_id":"9b5194ce-fa5b-4fa6-a79f-003263374118","price_dollars":"0.6300","delta_fp":"-36.00","side":"yes","ts":"2026-05-14T22:08:36.726466Z","ts_ms":1778796516726}}

{"type":"orderbook_delta","sid":1,"seq":490,"msg":{"market_ticker":"KXBTC15M-26MAY141815-15","market_id":"9b5194ce-fa5b-4fa6-a79f-003263374118","price_dollars":"0.2900","delta_fp":"-100.00","side":"no","ts":"2026-05-14T22:08:36.727475Z","ts_ms":1778796516727}}

{"type":"orderbook_delta","sid":1,"seq":491,"msg":{"market_ticker":"KXBTC15M-26MAY141815-15","market_id":"9b5194ce-fa5b-4fa6-a79f-003263374118","price_dollars":"0.6300","delta_fp":"-1639.48","side":"yes","ts":"2026-05-14T22:08:36.728569Z","ts_ms":1778796516728}}

{"type":"orderbook_delta","sid":1,"seq":492,"msg":{"market_ticker":"KXBTC15M-26MAY141815-15","market_id":"9b5194ce-fa5b-4fa6-a79f-003263374118","price_dollars":"0.6600","delta_fp":"100.00","side":"yes","ts":"2026-05-14T22:08:36.729737Z","ts_ms":1778796516729}}

{"type":"orderbook_delta","sid":1,"seq":493,"msg":{"market_ticker":"KXBTC15M-26MAY141815-15","market_id":"9b5194ce-fa5b-4fa6-a79f-003263374118","price_dollars":"0.6300","delta_fp":"-400.00","side":"yes","ts":"2026-05-14T22:08:36.733523Z","ts_ms":1778796516733}}

{"type":"orderbook_delta","sid":1,"seq":494,"msg":{"market_ticker":"KXBTC15M-26MAY141815-15","market_id":"9b5194ce-fa5b-4fa6-a79f-003263374118","price_dollars":"0.6400","delta_fp":"400.00","side":"yes","ts":"2026-05-14T22:08:36.733523Z","ts_ms":1778796516733}}

{"type":"orderbook_delta","sid":1,"seq":495,"msg":{"market_ticker":"KXBTC15M-26MAY141815-15","market_id":"9b5194ce-fa5b-4fa6-a79f-003263374118","price_dollars":"0.6100","delta_fp":"-2.00","side":"yes","ts":"2026-05-14T22:08:36.733728Z","ts_ms":1778796516733}}

{"type":"orderbook_delta","sid":1,"seq":496,"msg":{"market_ticker":"KXBTC15M-26MAY141815-15","market_id":"9b5194ce-fa5b-4fa6-a79f-003263374118","price_dollars":"0.6200","delta_fp":"2.00","side":"yes","ts":"2026-05-14T22:08:36.733728Z","ts_ms":1778796516733}}

{"type":"orderbook_delta","sid":1,"seq":497,"msg":{"market_ticker":"KXBTC15M-26MAY141815-15","market_id":"9b5194ce-fa5b-4fa6-a79f-003263374118","price_dollars":"0.3200","delta_fp":"-100.00","side":"no","ts":"2026-05-14T22:08:36.733951Z","ts_ms":1778796516733}}

{"type":"orderbook_delta","sid":1,"seq":498,"msg":{"market_ticker":"KXBTC15M-26MAY141815-15","market_id":"9b5194ce-fa5b-4fa6-a79f-003263374118","price_dollars":"0.3200","delta_fp":"-2.00","side":"no","ts":"2026-05-14T22:08:36.733951Z","ts_ms":1778796516733}}

{"type":"orderbook_delta","sid":1,"seq":499,"msg":{"market_ticker":"KXBTC15M-26MAY141815-15","market_id":"9b5194ce-fa5b-4fa6-a79f-003263374118","price_dollars":"0.6400","delta_fp":"1100.00","side":"yes","ts":"2026-05-14T22:08:36.734165Z","ts_ms":1778796516734}}

{"type":"orderbook_delta","sid":1,"seq":500,"msg":{"market_ticker":"KXBTC15M-26MAY141815-15","market_id":"9b5194ce-fa5b-4fa6-a79f-003263374118","price_dollars":"0.2400","delta_fp":"-400.00","side":"no","ts":"2026-05-14T22:08:36.734877Z","ts_ms":1778796516734}}

{"type":"orderbook_delta","sid":1,"seq":501,"msg":{"market_ticker":"KXBTC15M-26MAY141815-15","market_id":"9b5194ce-fa5b-4fa6-a79f-003263374118","price_dollars":"0.2500","delta_fp":"400.00","side":"no","ts":"2026-05-14T22:08:36.734877Z","ts_ms":1778796516734}}

{"type":"orderbook_delta","sid":1,"seq":502,"msg":{"market_ticker":"KXBTC15M-26MAY141815-15","market_id":"9b5194ce-fa5b-4fa6-a79f-003263374118","price_dollars":"0.6400","delta_fp":"-1000.00","side":"yes","ts":"2026-05-14T22:08:36.735235Z","ts_ms":1778796516735}}

{"type":"orderbook_delta","sid":1,"seq":503,"msg":{"market_ticker":"KXBTC15M-26MAY141815-15","market_id":"9b5194ce-fa5b-4fa6-a79f-003263374118","price_dollars":"0.6500","delta_fp":"1000.00","side":"yes","ts":"2026-05-14T22:08:36.735235Z","ts_ms":1778796516735}}

{"type":"orderbook_delta","sid":1,"seq":504,"msg":{"market_ticker":"KXBTC15M-26MAY141815-15","market_id":"9b5194ce-fa5b-4fa6-a79f-003263374118","price_dollars":"0.2600","delta_fp":"1000.00","side":"no","ts":"2026-05-14T22:08:36.735512Z","ts_ms":1778796516735}}

{"type":"orderbook_delta","sid":1,"seq":505,"msg":{"market_ticker":"KXBTC15M-26MAY141815-15","market_id":"9b5194ce-fa5b-4fa6-a79f-003263374118","price_dollars":"0.3000","delta_fp":"-2.00","side":"no","ts":"2026-05-14T22:08:36.735973Z","ts_ms":1778796516735}}

{"type":"orderbook_delta","sid":1,"seq":506,"msg":{"market_ticker":"KXBTC15M-26MAY141815-15","market_id":"9b5194ce-fa5b-4fa6-a79f-003263374118","price_dollars":"0.2900","delta_fp":"2.00","side":"no","ts":"2026-05-14T22:08:36.735973Z","ts_ms":1778796516735}}

{"type":"orderbook_delta","sid":1,"seq":507,"msg":{"market_ticker":"KXBTC15M-26MAY141815-15","market_id":"9b5194ce-fa5b-4fa6-a79f-003263374118","price_dollars":"0.6300","delta_fp":"-10.00","side":"yes","ts":"2026-05-14T22:08:36.738392Z","ts_ms":1778796516738}}

{"type":"orderbook_delta","sid":1,"seq":508,"msg":{"market_ticker":"KXBTC15M-26MAY141815-15","market_id":"9b5194ce-fa5b-4fa6-a79f-003263374118","price_dollars":"0.6400","delta_fp":"10.00","side":"yes","ts":"2026-05-14T22:08:36.738392Z","ts_ms":1778796516738}}

{"type":"orderbook_delta","sid":1,"seq":509,"msg":{"market_ticker":"KXBTC15M-26MAY141815-15","market_id":"9b5194ce-fa5b-4fa6-a79f-003263374118","price_dollars":"0.3000","delta_fp":"100.00","side":"no","ts":"2026-05-14T22:08:36.739217Z","ts_ms":1778796516739}}

{"type":"orderbook_delta","sid":1,"seq":510,"msg":{"market_ticker":"KXBTC15M-26MAY141815-15","market_id":"9b5194ce-fa5b-4fa6-a79f-003263374118","price_dollars":"0.6400","delta_fp":"-1100.00","side":"yes","ts":"2026-05-14T22:08:36.741431Z","ts_ms":1778796516741}}

{"type":"orderbook_delta","sid":1,"seq":511,"msg":{"market_ticker":"KXBTC15M-26MAY141815-15","market_id":"9b5194ce-fa5b-4fa6-a79f-003263374118","price_dollars":"0.6600","delta_fp":"1100.00","side":"yes","ts":"2026-05-14T22:08:36.741431Z","ts_ms":1778796516741}}

{"type":"orderbook_delta","sid":1,"seq":512,"msg":{"market_ticker":"KXBTC15M-26MAY141815-15","market_id":"9b5194ce-fa5b-4fa6-a79f-003263374118","price_dollars":"0.6500","delta_fp":"-1000.00","side":"yes","ts":"2026-05-14T22:08:36.742267Z","ts_ms":1778796516742}}

{"type":"orderbook_delta","sid":1,"seq":513,"msg":{"market_ticker":"KXBTC15M-26MAY141815-15","market_id":"9b5194ce-fa5b-4fa6-a79f-003263374118","price_dollars":"0.6600","delta_fp":"1000.00","side":"yes","ts":"2026-05-14T22:08:36.742267Z","ts_ms":1778796516742}}

{"type":"orderbook_delta","sid":1,"seq":514,"msg":{"market_ticker":"KXBTC15M-26MAY141815-15","market_id":"9b5194ce-fa5b-4fa6-a79f-003263374118","price_dollars":"0.6400","delta_fp":"-81.00","side":"yes","ts":"2026-05-14T22:08:36.742417Z","ts_ms":1778796516742}}

{"type":"orderbook_delta","sid":1,"seq":515,"msg":{"market_ticker":"KXBTC15M-26MAY141815-15","market_id":"9b5194ce-fa5b-4fa6-a79f-003263374118","price_dollars":"0.6500","delta_fp":"81.00","side":"yes","ts":"2026-05-14T22:08:36.742417Z","ts_ms":1778796516742}}

{"type":"orderbook_delta","sid":1,"seq":516,"msg":{"market_ticker":"KXBTC15M-26MAY141815-15","market_id":"9b5194ce-fa5b-4fa6-a79f-003263374118","price_dollars":"0.2600","delta_fp":"-1000.00","side":"no","ts":"2026-05-14T22:08:36.743661Z","ts_ms":1778796516743}}

{"type":"orderbook_delta","sid":1,"seq":517,"msg":{"market_ticker":"KXBTC15M-26MAY141815-15","market_id":"9b5194ce-fa5b-4fa6-a79f-003263374118","price_dollars":"0.2700","delta_fp":"1000.00","side":"no","ts":"2026-05-14T22:08:36.743661Z","ts_ms":1778796516743}}

{"type":"orderbook_delta","sid":1,"seq":518,"msg":{"market_ticker":"KXBTC15M-26MAY141815-15","market_id":"9b5194ce-fa5b-4fa6-a79f-003263374118","price_dollars":"0.2700","delta_fp":"-1100.00","side":"no","ts":"2026-05-14T22:08:36.744826Z","ts_ms":1778796516744}}

{"type":"orderbook_delta","sid":1,"seq":519,"msg":{"market_ticker":"KXBTC15M-26MAY141815-15","market_id":"9b5194ce-fa5b-4fa6-a79f-003263374118","price_dollars":"0.2800","delta_fp":"1100.00","side":"no","ts":"2026-05-14T22:08:36.744826Z","ts_ms":1778796516744}}

{"type":"orderbook_delta","sid":1,"seq":520,"msg":{"market_ticker":"KXBTC15M-26MAY141815-15","market_id":"9b5194ce-fa5b-4fa6-a79f-003263374118","price_dollars":"0.5400","delta_fp":"-2.00","side":"yes","ts":"2026-05-14T22:08:36.745538Z","ts_ms":1778796516745}}

{"type":"orderbook_delta","sid":1,"seq":521,"msg":{"market_ticker":"KXBTC15M-26MAY141815-15","market_id":"9b5194ce-fa5b-4fa6-a79f-003263374118","price_dollars":"0.6500","delta_fp":"2.00","side":"yes","ts":"2026-05-14T22:08:36.745999Z","ts_ms":1778796516745}}

{"type":"orderbook_delta","sid":1,"seq":522,"msg":{"market_ticker":"KXBTC15M-26MAY141815-15","market_id":"9b5194ce-fa5b-4fa6-a79f-003263374118","price_dollars":"0.6400","delta_fp":"2.00","side":"yes","ts":"2026-05-14T22:08:36.746155Z","ts_ms":1778796516746}}

{"type":"orderbook_delta","sid":1,"seq":523,"msg":{"market_ticker":"KXBTC15M-26MAY141815-15","market_id":"9b5194ce-fa5b-4fa6-a79f-003263374118","price_dollars":"0.3000","delta_fp":"2.00","side":"no","ts":"2026-05-14T22:08:36.747508Z","ts_ms":1778796516747}}

{"type":"orderbook_delta","sid":1,"seq":524,"msg":{"market_ticker":"KXBTC15M-26MAY141815-15","market_id":"9b5194ce-fa5b-4fa6-a79f-003263374118","price_dollars":"0.2500","delta_fp":"-400.00","side":"no","ts":"2026-05-14T22:08:36.749542Z","ts_ms":1778796516749}}

{"type":"orderbook_delta","sid":1,"seq":525,"msg":{"market_ticker":"KXBTC15M-26MAY141815-15","market_id":"9b5194ce-fa5b-4fa6-a79f-003263374118","price_dollars":"0.2400","delta_fp":"400.00","side":"no","ts":"2026-05-14T22:08:36.749542Z","ts_ms":1778796516749}}

{"type":"orderbook_delta","sid":1,"seq":526,"msg":{"market_ticker":"KXBTC15M-26MAY141815-15","market_id":"9b5194ce-fa5b-4fa6-a79f-003263374118","price_dollars":"0.2700","delta_fp":"-1000.00","side":"no","ts":"2026-05-14T22:08:36.749871Z","ts_ms":1778796516749}}

{"type":"orderbook_delta","sid":1,"seq":527,"msg":{"market_ticker":"KXBTC15M-26MAY141815-15","market_id":"9b5194ce-fa5b-4fa6-a79f-003263374118","price_dollars":"0.2800","delta_fp":"1000.00","side":"no","ts":"2026-05-14T22:08:36.749871Z","ts_ms":1778796516749}}

{"type":"orderbook_delta","sid":1,"seq":528,"msg":{"market_ticker":"KXBTC15M-26MAY141815-15","market_id":"9b5194ce-fa5b-4fa6-a79f-003263374118","price_dollars":"0.5700","delta_fp":"-15.00","side":"yes","ts":"2026-05-14T22:08:36.753043Z","ts_ms":1778796516753}}

{"type":"orderbook_delta","sid":1,"seq":529,"msg":{"market_ticker":"KXBTC15M-26MAY141815-15","market_id":"9b5194ce-fa5b-4fa6-a79f-003263374118","price_dollars":"0.5800","delta_fp":"15.00","side":"yes","ts":"2026-05-14T22:08:36.753043Z","ts_ms":1778796516753}}

{"type":"orderbook_delta","sid":1,"seq":530,"msg":{"market_ticker":"KXBTC15M-26MAY141815-15","market_id":"9b5194ce-fa5b-4fa6-a79f-003263374118","price_dollars":"0.6000","delta_fp":"50.00","side":"yes","ts":"2026-05-14T22:08:36.754896Z","ts_ms":1778796516754}}

{"type":"orderbook_delta","sid":1,"seq":531,"msg":{"market_ticker":"KXBTC15M-26MAY141815-15","market_id":"9b5194ce-fa5b-4fa6-a79f-003263374118","price_dollars":"0.6000","delta_fp":"-50.00","side":"yes","ts":"2026-05-14T22:08:36.758787Z","ts_ms":1778796516758}}

{"type":"orderbook_delta","sid":1,"seq":532,"msg":{"market_ticker":"KXBTC15M-26MAY141815-15","market_id":"9b5194ce-fa5b-4fa6-a79f-003263374118","price_dollars":"0.2800","delta_fp":"-1100.00","side":"no","ts":"2026-05-14T22:08:36.759538Z","ts_ms":1778796516759}}

{"type":"orderbook_delta","sid":1,"seq":533,"msg":{"market_ticker":"KXBTC15M-26MAY141815-15","market_id":"9b5194ce-fa5b-4fa6-a79f-003263374118","price_dollars":"0.2900","delta_fp":"1100.00","side":"no","ts":"2026-05-14T22:08:36.759538Z","ts_ms":1778796516759}}

{"type":"orderbook_delta","sid":1,"seq":534,"msg":{"market_ticker":"KXBTC15M-26MAY141815-15","market_id":"9b5194ce-fa5b-4fa6-a79f-003263374118","price_dollars":"0.3300","delta_fp":"31.00","side":"no","ts":"2026-05-14T22:08:36.760938Z","ts_ms":1778796516760}}

{"type":"orderbook_delta","sid":1,"seq":535,"msg":{"market_ticker":"KXBTC15M-26MAY141815-15","market_id":"9b5194ce-fa5b-4fa6-a79f-003263374118","price_dollars":"0.2400","delta_fp":"-400.00","side":"no","ts":"2026-05-14T22:08:36.763468Z","ts_ms":1778796516763}}

{"type":"orderbook_delta","sid":1,"seq":536,"msg":{"market_ticker":"KXBTC15M-26MAY141815-15","market_id":"9b5194ce-fa5b-4fa6-a79f-003263374118","price_dollars":"0.2700","delta_fp":"400.00","side":"no","ts":"2026-05-14T22:08:36.763468Z","ts_ms":1778796516763}}

{"type":"orderbook_delta","sid":1,"seq":537,"msg":{"market_ticker":"KXBTC15M-26MAY141815-15","market_id":"9b5194ce-fa5b-4fa6-a79f-003263374118","price_dollars":"0.6500","delta_fp":"-81.00","side":"yes","ts":"2026-05-14T22:08:36.763884Z","ts_ms":1778796516763}}

{"type":"orderbook_delta","sid":1,"seq":538,"msg":{"market_ticker":"KXBTC15M-26MAY141815-15","market_id":"9b5194ce-fa5b-4fa6-a79f-003263374118","price_dollars":"0.3300","delta_fp":"-31.00","side":"no","ts":"2026-05-14T22:08:36.767293Z","ts_ms":1778796516767}}

{"type":"orderbook_delta","sid":1,"seq":539,"msg":{"market_ticker":"KXBTC15M-26MAY141815-15","market_id":"9b5194ce-fa5b-4fa6-a79f-003263374118","price_dollars":"0.6700","delta_fp":"1639.48","side":"yes","ts":"2026-05-14T22:08:36.767296Z","ts_ms":1778796516767}}

{"type":"orderbook_delta","sid":1,"seq":540,"msg":{"market_ticker":"KXBTC15M-26MAY141815-15","market_id":"9b5194ce-fa5b-4fa6-a79f-003263374118","price_dollars":"0.6700","delta_fp":"-1639.48","side":"yes","ts":"2026-05-14T22:08:36.767924Z","ts_ms":1778796516767}}

{"type":"orderbook_delta","sid":1,"seq":541,"msg":{"market_ticker":"KXBTC15M-26MAY141815-15","market_id":"9b5194ce-fa5b-4fa6-a79f-003263374118","price_dollars":"0.6600","delta_fp":"1639.48","side":"yes","ts":"2026-05-14T22:08:36.767924Z","ts_ms":1778796516767}}

{"type":"orderbook_delta","sid":1,"seq":542,"msg":{"market_ticker":"KXBTC15M-26MAY141815-15","market_id":"9b5194ce-fa5b-4fa6-a79f-003263374118","price_dollars":"0.6700","delta_fp":"100.00","side":"yes","ts":"2026-05-14T22:08:36.768113Z","ts_ms":1778796516768}}

{"type":"orderbook_delta","sid":1,"seq":543,"msg":{"market_ticker":"KXBTC15M-26MAY141815-15","market_id":"9b5194ce-fa5b-4fa6-a79f-003263374118","price_dollars":"0.3000","delta_fp":"-100.00","side":"no","ts":"2026-05-14T22:08:36.770434Z","ts_ms":1778796516770}}

{"type":"orderbook_delta","sid":1,"seq":544,"msg":{"market_ticker":"KXBTC15M-26MAY141815-15","market_id":"9b5194ce-fa5b-4fa6-a79f-003263374118","price_dollars":"0.5800","delta_fp":"-251.00","side":"yes","ts":"2026-05-14T22:08:36.774642Z","ts_ms":1778796516774}}

{"type":"orderbook_delta","sid":1,"seq":545,"msg":{"market_ticker":"KXBTC15M-26MAY141815-15","market_id":"9b5194ce-fa5b-4fa6-a79f-003263374118","price_dollars":"0.2900","delta_fp":"100.00","side":"no","ts":"2026-05-14T22:08:36.774657Z","ts_ms":1778796516774}}

{"type":"orderbook_delta","sid":1,"seq":546,"msg":{"market_ticker":"KXBTC15M-26MAY141815-15","market_id":"9b5194ce-fa5b-4fa6-a79f-003263374118","price_dollars":"0.6700","delta_fp":"81.00","side":"yes","ts":"2026-05-14T22:08:36.775985Z","ts_ms":1778796516775}}

{"type":"orderbook_delta","sid":1,"seq":547,"msg":{"market_ticker":"KXBTC15M-26MAY141815-15","market_id":"9b5194ce-fa5b-4fa6-a79f-003263374118","price_dollars":"0.6600","delta_fp":"-1639.48","side":"yes","ts":"2026-05-14T22:08:36.780394Z","ts_ms":1778796516780}}

{"type":"orderbook_delta","sid":1,"seq":548,"msg":{"market_ticker":"KXBTC15M-26MAY141815-15","market_id":"9b5194ce-fa5b-4fa6-a79f-003263374118","price_dollars":"0.6300","delta_fp":"-8.00","side":"yes","ts":"2026-05-14T22:08:36.785328Z","ts_ms":1778796516785}}

{"type":"orderbook_delta","sid":1,"seq":549,"msg":{"market_ticker":"KXBTC15M-26MAY141815-15","market_id":"9b5194ce-fa5b-4fa6-a79f-003263374118","price_dollars":"0.6400","delta_fp":"-400.00","side":"yes","ts":"2026-05-14T22:08:36.791363Z","ts_ms":1778796516791}}

{"type":"orderbook_delta","sid":1,"seq":550,"msg":{"market_ticker":"KXBTC15M-26MAY141815-15","market_id":"9b5194ce-fa5b-4fa6-a79f-003263374118","price_dollars":"0.6500","delta_fp":"400.00","side":"yes","ts":"2026-05-14T22:08:36.791363Z","ts_ms":1778796516791}}

{"type":"orderbook_delta","sid":1,"seq":551,"msg":{"market_ticker":"KXBTC15M-26MAY141815-15","market_id":"9b5194ce-fa5b-4fa6-a79f-003263374118","price_dollars":"0.6800","delta_fp":"100.00","side":"yes","ts":"2026-05-14T22:08:36.791409Z","ts_ms":1778796516791}}

{"type":"orderbook_delta","sid":1,"seq":552,"msg":{"market_ticker":"KXBTC15M-26MAY141815-15","market_id":"9b5194ce-fa5b-4fa6-a79f-003263374118","price_dollars":"0.6800","delta_fp":"10.00","side":"yes","ts":"2026-05-14T22:08:36.791592Z","ts_ms":1778796516791}}

{"type":"orderbook_delta","sid":1,"seq":553,"msg":{"market_ticker":"KXBTC15M-26MAY141815-15","market_id":"9b5194ce-fa5b-4fa6-a79f-003263374118","price_dollars":"0.6700","delta_fp":"-81.00","side":"yes","ts":"2026-05-14T22:08:36.792848Z","ts_ms":1778796516792}}

{"type":"orderbook_delta","sid":1,"seq":554,"msg":{"market_ticker":"KXBTC15M-26MAY141815-15","market_id":"9b5194ce-fa5b-4fa6-a79f-003263374118","price_dollars":"0.5500","delta_fp":"-2.00","side":"yes","ts":"2026-05-14T22:08:36.795156Z","ts_ms":1778796516795}}

{"type":"orderbook_delta","sid":1,"seq":555,"msg":{"market_ticker":"KXBTC15M-26MAY141815-15","market_id":"9b5194ce-fa5b-4fa6-a79f-003263374118","price_dollars":"0.6400","delta_fp":"-10.00","side":"yes","ts":"2026-05-14T22:08:36.797051Z","ts_ms":1778796516797}}

{"type":"orderbook_delta","sid":1,"seq":556,"msg":{"market_ticker":"KXBTC15M-26MAY141815-15","market_id":"9b5194ce-fa5b-4fa6-a79f-003263374118","price_dollars":"0.6800","delta_fp":"10.00","side":"yes","ts":"2026-05-14T22:08:36.797051Z","ts_ms":1778796516797}}

{"type":"orderbook_delta","sid":1,"seq":557,"msg":{"market_ticker":"KXBTC15M-26MAY141815-15","market_id":"9b5194ce-fa5b-4fa6-a79f-003263374118","price_dollars":"0.2900","delta_fp":"10.00","side":"no","ts":"2026-05-14T22:08:36.800512Z","ts_ms":1778796516800}}

{"type":"orderbook_delta","sid":1,"seq":558,"msg":{"market_ticker":"KXBTC15M-26MAY141815-15","market_id":"9b5194ce-fa5b-4fa6-a79f-003263374118","price_dollars":"0.2900","delta_fp":"100.00","side":"no","ts":"2026-05-14T22:08:36.801428Z","ts_ms":1778796516801}}

{"type":"orderbook_delta","sid":1,"seq":559,"msg":{"market_ticker":"KXBTC15M-26MAY141815-15","market_id":"9b5194ce-fa5b-4fa6-a79f-003263374118","price_dollars":"0.5900","delta_fp":"50.00","side":"yes","ts":"2026-05-14T22:08:36.806892Z","ts_ms":1778796516806}}

{"type":"orderbook_delta","sid":1,"seq":560,"msg":{"market_ticker":"KXBTC15M-26MAY141815-15","market_id":"9b5194ce-fa5b-4fa6-a79f-003263374118","price_dollars":"0.5800","delta_fp":"-15.00","side":"yes","ts":"2026-05-14T22:08:36.807852Z","ts_ms":1778796516807}}

{"type":"orderbook_delta","sid":1,"seq":561,"msg":{"market_ticker":"KXBTC15M-26MAY141815-15","market_id":"9b5194ce-fa5b-4fa6-a79f-003263374118","price_dollars":"0.5900","delta_fp":"15.00","side":"yes","ts":"2026-05-14T22:08:36.807852Z","ts_ms":1778796516807}}

{"type":"orderbook_delta","sid":1,"seq":562,"msg":{"market_ticker":"KXBTC15M-26MAY141815-15","market_id":"9b5194ce-fa5b-4fa6-a79f-003263374118","price_dollars":"0.2900","delta_fp":"-2.00","side":"no","ts":"2026-05-14T22:08:36.809824Z","ts_ms":1778796516809}}

{"type":"orderbook_delta","sid":1,"seq":563,"msg":{"market_ticker":"KXBTC15M-26MAY141815-15","market_id":"9b5194ce-fa5b-4fa6-a79f-003263374118","price_dollars":"0.2800","delta_fp":"2.00","side":"no","ts":"2026-05-14T22:08:36.809824Z","ts_ms":1778796516809}}

{"type":"orderbook_delta","sid":1,"seq":564,"msg":{"market_ticker":"KXBTC15M-26MAY141815-15","market_id":"9b5194ce-fa5b-4fa6-a79f-003263374118","price_dollars":"0.6400","delta_fp":"-75.00","side":"yes","ts":"2026-05-14T22:08:36.812581Z","ts_ms":1778796516812}}

{"type":"orderbook_delta","sid":1,"seq":565,"msg":{"market_ticker":"KXBTC15M-26MAY141815-15","market_id":"9b5194ce-fa5b-4fa6-a79f-003263374118","price_dollars":"0.6600","delta_fp":"75.00","side":"yes","ts":"2026-05-14T22:08:36.812581Z","ts_ms":1778796516812}}

{"type":"orderbook_delta","sid":1,"seq":566,"msg":{"market_ticker":"KXBTC15M-26MAY141815-15","market_id":"9b5194ce-fa5b-4fa6-a79f-003263374118","price_dollars":"0.6600","delta_fp":"1639.48","side":"yes","ts":"2026-05-14T22:08:36.813325Z","ts_ms":1778796516813}}

{"type":"orderbook_delta","sid":1,"seq":567,"msg":{"market_ticker":"KXBTC15M-26MAY141815-15","market_id":"9b5194ce-fa5b-4fa6-a79f-003263374118","price_dollars":"0.6500","delta_fp":"-400.00","side":"yes","ts":"2026-05-14T22:08:36.813432Z","ts_ms":1778796516813}}

{"type":"orderbook_delta","sid":1,"seq":568,"msg":{"market_ticker":"KXBTC15M-26MAY141815-15","market_id":"9b5194ce-fa5b-4fa6-a79f-003263374118","price_dollars":"0.6400","delta_fp":"400.00","side":"yes","ts":"2026-05-14T22:08:36.813432Z","ts_ms":1778796516813}}

{"type":"orderbook_delta","sid":1,"seq":569,"msg":{"market_ticker":"KXBTC15M-26MAY141815-15","market_id":"9b5194ce-fa5b-4fa6-a79f-003263374118","price_dollars":"0.5900","delta_fp":"-1.00","side":"yes","ts":"2026-05-14T22:08:36.817523Z","ts_ms":1778796516817}}

{"type":"orderbook_delta","sid":1,"seq":570,"msg":{"market_ticker":"KXBTC15M-26MAY141815-15","market_id":"9b5194ce-fa5b-4fa6-a79f-003263374118","price_dollars":"0.2300","delta_fp":"75.00","side":"no","ts":"2026-05-14T22:08:36.819003Z","ts_ms":1778796516819}}

{"type":"orderbook_delta","sid":1,"seq":571,"msg":{"market_ticker":"KXBTC15M-26MAY141815-15","market_id":"9b5194ce-fa5b-4fa6-a79f-003263374118","price_dollars":"0.6600","delta_fp":"-1639.48","side":"yes","ts":"2026-05-14T22:08:36.819927Z","ts_ms":1778796516819}}

{"type":"orderbook_delta","sid":1,"seq":572,"msg":{"market_ticker":"KXBTC15M-26MAY141815-15","market_id":"9b5194ce-fa5b-4fa6-a79f-003263374118","price_dollars":"0.6700","delta_fp":"1639.48","side":"yes","ts":"2026-05-14T22:08:36.819927Z","ts_ms":1778796516819}}

{"type":"orderbook_delta","sid":1,"seq":573,"msg":{"market_ticker":"KXBTC15M-26MAY141815-15","market_id":"9b5194ce-fa5b-4fa6-a79f-003263374118","price_dollars":"0.6800","delta_fp":"81.00","side":"yes","ts":"2026-05-14T22:08:36.823182Z","ts_ms":1778796516823}}

{"type":"orderbook_delta","sid":1,"seq":574,"msg":{"market_ticker":"KXBTC15M-26MAY141815-15","market_id":"9b5194ce-fa5b-4fa6-a79f-003263374118","price_dollars":"0.2900","delta_fp":"-100.00","side":"no","ts":"2026-05-14T22:08:36.826185Z","ts_ms":1778796516826}}

{"type":"orderbook_delta","sid":1,"seq":575,"msg":{"market_ticker":"KXBTC15M-26MAY141815-15","market_id":"9b5194ce-fa5b-4fa6-a79f-003263374118","price_dollars":"0.3000","delta_fp":"18.00","side":"no","ts":"2026-05-14T22:08:36.82876Z","ts_ms":1778796516828}}

{"type":"orderbook_delta","sid":1,"seq":576,"msg":{"market_ticker":"KXBTC15M-26MAY141815-15","market_id":"9b5194ce-fa5b-4fa6-a79f-003263374118","price_dollars":"0.6700","delta_fp":"-1639.48","side":"yes","ts":"2026-05-14T22:08:36.829051Z","ts_ms":1778796516829}}

{"type":"orderbook_delta","sid":1,"seq":577,"msg":{"market_ticker":"KXBTC15M-26MAY141815-15","market_id":"9b5194ce-fa5b-4fa6-a79f-003263374118","price_dollars":"0.6200","delta_fp":"-2.00","side":"yes","ts":"2026-05-14T22:08:36.83518Z","ts_ms":1778796516835}}

{"type":"orderbook_delta","sid":1,"seq":578,"msg":{"market_ticker":"KXBTC15M-26MAY141815-15","market_id":"9b5194ce-fa5b-4fa6-a79f-003263374118","price_dollars":"0.6300","delta_fp":"2.00","side":"yes","ts":"2026-05-14T22:08:36.83518Z","ts_ms":1778796516835}}

{"type":"orderbook_delta","sid":1,"seq":579,"msg":{"market_ticker":"KXBTC15M-26MAY141815-15","market_id":"9b5194ce-fa5b-4fa6-a79f-003263374118","price_dollars":"0.2900","delta_fp":"100.00","side":"no","ts":"2026-05-14T22:08:36.838154Z","ts_ms":1778796516838}}

{"type":"orderbook_delta","sid":1,"seq":580,"msg":{"market_ticker":"KXBTC15M-26MAY141815-15","market_id":"9b5194ce-fa5b-4fa6-a79f-003263374118","price_dollars":"0.2900","delta_fp":"-100.00","side":"no","ts":"2026-05-14T22:08:36.850372Z","ts_ms":1778796516850}}

{"type":"orderbook_delta","sid":1,"seq":581,"msg":{"market_ticker":"KXBTC15M-26MAY141815-15","market_id":"9b5194ce-fa5b-4fa6-a79f-003263374118","price_dollars":"0.2200","delta_fp":"-14.00","side":"no","ts":"2026-05-14T22:08:36.85142Z","ts_ms":1778796516851}}

{"type":"orderbook_delta","sid":1,"seq":582,"msg":{"market_ticker":"KXBTC15M-26MAY141815-15","market_id":"9b5194ce-fa5b-4fa6-a79f-003263374118","price_dollars":"0.0910","delta_fp":"14.00","side":"no","ts":"2026-05-14T22:08:36.85142Z","ts_ms":1778796516851}}

{"type":"orderbook_delta","sid":1,"seq":583,"msg":{"market_ticker":"KXBTC15M-26MAY141815-15","market_id":"9b5194ce-fa5b-4fa6-a79f-003263374118","price_dollars":"0.5600","delta_fp":"-2.00","side":"yes","ts":"2026-05-14T22:08:36.854037Z","ts_ms":1778796516854}}

{"type":"orderbook_delta","sid":1,"seq":584,"msg":{"market_ticker":"KXBTC15M-26MAY141815-15","market_id":"9b5194ce-fa5b-4fa6-a79f-003263374118","price_dollars":"0.6600","delta_fp":"-1000.00","side":"yes","ts":"2026-05-14T22:08:36.856971Z","ts_ms":1778796516856}}

{"type":"orderbook_delta","sid":1,"seq":585,"msg":{"market_ticker":"KXBTC15M-26MAY141815-15","market_id":"9b5194ce-fa5b-4fa6-a79f-003263374118","price_dollars":"0.6700","delta_fp":"1000.00","side":"yes","ts":"2026-05-14T22:08:36.856971Z","ts_ms":1778796516856}}

{"type":"orderbook_delta","sid":1,"seq":586,"msg":{"market_ticker":"KXBTC15M-26MAY141815-15","market_id":"9b5194ce-fa5b-4fa6-a79f-003263374118","price_dollars":"0.2800","delta_fp":"-1000.00","side":"no","ts":"2026-05-14T22:08:36.857201Z","ts_ms":1778796516857}}

{"type":"orderbook_delta","sid":1,"seq":587,"msg":{"market_ticker":"KXBTC15M-26MAY141815-15","market_id":"9b5194ce-fa5b-4fa6-a79f-003263374118","price_dollars":"0.2900","delta_fp":"1000.00","side":"no","ts":"2026-05-14T22:08:36.857201Z","ts_ms":1778796516857}}

{"type":"orderbook_delta","sid":1,"seq":588,"msg":{"market_ticker":"KXBTC15M-26MAY141815-15","market_id":"9b5194ce-fa5b-4fa6-a79f-003263374118","price_dollars":"0.2800","delta_fp":"-2.00","side":"no","ts":"2026-05-14T22:08:36.878174Z","ts_ms":1778796516878}}

{"type":"orderbook_delta","sid":1,"seq":589,"msg":{"market_ticker":"KXBTC15M-26MAY141815-15","market_id":"9b5194ce-fa5b-4fa6-a79f-003263374118","price_dollars":"0.2900","delta_fp":"2.00","side":"no","ts":"2026-05-14T22:08:36.878174Z","ts_ms":1778796516878}}

{"type":"orderbook_delta","sid":1,"seq":590,"msg":{"market_ticker":"KXBTC15M-26MAY141815-15","market_id":"9b5194ce-fa5b-4fa6-a79f-003263374118","price_dollars":"0.2700","delta_fp":"-400.00","side":"no","ts":"2026-05-14T22:08:36.884841Z","ts_ms":1778796516884}}

{"type":"orderbook_delta","sid":1,"seq":591,"msg":{"market_ticker":"KXBTC15M-26MAY141815-15","market_id":"9b5194ce-fa5b-4fa6-a79f-003263374118","price_dollars":"0.2800","delta_fp":"400.00","side":"no","ts":"2026-05-14T22:08:36.884841Z","ts_ms":1778796516884}}

{"type":"orderbook_delta","sid":1,"seq":592,"msg":{"market_ticker":"KXBTC15M-26MAY141815-15","market_id":"9b5194ce-fa5b-4fa6-a79f-003263374118","price_dollars":"0.3000","delta_fp":"-18.00","side":"no","ts":"2026-05-14T22:08:36.891193Z","ts_ms":1778796516891}}

{"type":"orderbook_delta","sid":1,"seq":593,"msg":{"market_ticker":"KXBTC15M-26MAY141815-15","market_id":"9b5194ce-fa5b-4fa6-a79f-003263374118","price_dollars":"0.2800","delta_fp":"11.00","side":"no","ts":"2026-05-14T22:08:36.891193Z","ts_ms":1778796516891}}

{"type":"orderbook_delta","sid":1,"seq":594,"msg":{"market_ticker":"KXBTC15M-26MAY141815-15","market_id":"9b5194ce-fa5b-4fa6-a79f-003263374118","price_dollars":"0.2500","delta_fp":"10.00","side":"no","ts":"2026-05-14T22:08:36.902073Z","ts_ms":1778796516902}}

{"type":"orderbook_delta","sid":1,"seq":595,"msg":{"market_ticker":"KXBTC15M-26MAY141815-15","market_id":"9b5194ce-fa5b-4fa6-a79f-003263374118","price_dollars":"0.6000","delta_fp":"2.00","side":"yes","ts":"2026-05-14T22:08:36.906163Z","ts_ms":1778796516906}}

{"type":"orderbook_delta","sid":1,"seq":596,"msg":{"market_ticker":"KXBTC15M-26MAY141815-15","market_id":"9b5194ce-fa5b-4fa6-a79f-003263374118","price_dollars":"0.2900","delta_fp":"100.00","side":"no","ts":"2026-05-14T22:08:36.913Z","ts_ms":1778796516913}}

{"type":"orderbook_delta","sid":1,"seq":597,"msg":{"market_ticker":"KXBTC15M-26MAY141815-15","market_id":"9b5194ce-fa5b-4fa6-a79f-003263374118","price_dollars":"0.6600","delta_fp":"-75.00","side":"yes","ts":"2026-05-14T22:08:36.915153Z","ts_ms":1778796516915}}

{"type":"orderbook_delta","sid":1,"seq":598,"msg":{"market_ticker":"KXBTC15M-26MAY141815-15","market_id":"9b5194ce-fa5b-4fa6-a79f-003263374118","price_dollars":"0.6800","delta_fp":"75.00","side":"yes","ts":"2026-05-14T22:08:36.915153Z","ts_ms":1778796516915}}

{"type":"orderbook_delta","sid":1,"seq":599,"msg":{"market_ticker":"KXBTC15M-26MAY141815-15","market_id":"9b5194ce-fa5b-4fa6-a79f-003263374118","price_dollars":"0.6200","delta_fp":"1.00","side":"yes","ts":"2026-05-14T22:08:36.917154Z","ts_ms":1778796516917}}

{"type":"orderbook_delta","sid":1,"seq":600,"msg":{"market_ticker":"KXBTC15M-26MAY141815-15","market_id":"9b5194ce-fa5b-4fa6-a79f-003263374118","price_dollars":"0.5700","delta_fp":"1.00","side":"yes","ts":"2026-05-14T22:08:36.926369Z","ts_ms":1778796516926}}

{"type":"orderbook_delta","sid":1,"seq":601,"msg":{"market_ticker":"KXBTC15M-26MAY141815-15","market_id":"9b5194ce-fa5b-4fa6-a79f-003263374118","price_dollars":"0.5600","delta_fp":"1.00","side":"yes","ts":"2026-05-14T22:08:36.92744Z","ts_ms":1778796516927}}

{"type":"orderbook_delta","sid":1,"seq":602,"msg":{"market_ticker":"KXBTC15M-26MAY141815-15","market_id":"9b5194ce-fa5b-4fa6-a79f-003263374118","price_dollars":"0.3000","delta_fp":"1.00","side":"no","ts":"2026-05-14T22:08:36.929539Z","ts_ms":1778796516929}}

{"type":"orderbook_delta","sid":1,"seq":603,"msg":{"market_ticker":"KXBTC15M-26MAY141815-15","market_id":"9b5194ce-fa5b-4fa6-a79f-003263374118","price_dollars":"0.2900","delta_fp":"-100.00","side":"no","ts":"2026-05-14T22:08:36.929694Z","ts_ms":1778796516929}}

{"type":"orderbook_delta","sid":1,"seq":604,"msg":{"market_ticker":"KXBTC15M-26MAY141815-15","market_id":"9b5194ce-fa5b-4fa6-a79f-003263374118","price_dollars":"0.6000","delta_fp":"-2.00","side":"yes","ts":"2026-05-14T22:08:36.949475Z","ts_ms":1778796516949}}

{"type":"orderbook_delta","sid":1,"seq":605,"msg":{"market_ticker":"KXBTC15M-26MAY141815-15","market_id":"9b5194ce-fa5b-4fa6-a79f-003263374118","price_dollars":"0.2500","delta_fp":"-10.00","side":"no","ts":"2026-05-14T22:08:36.952785Z","ts_ms":1778796516952}}

{"type":"orderbook_delta","sid":1,"seq":606,"msg":{"market_ticker":"KXBTC15M-26MAY141815-15","market_id":"9b5194ce-fa5b-4fa6-a79f-003263374118","price_dollars":"0.2600","delta_fp":"10.00","side":"no","ts":"2026-05-14T22:08:36.952785Z","ts_ms":1778796516952}}

{"type":"orderbook_delta","sid":1,"seq":607,"msg":{"market_ticker":"KXBTC15M-26MAY141815-15","market_id":"9b5194ce-fa5b-4fa6-a79f-003263374118","price_dollars":"0.6500","delta_fp":"2.00","side":"yes","ts":"2026-05-14T22:08:36.95325Z","ts_ms":1778796516953}}

{"type":"orderbook_delta","sid":1,"seq":608,"msg":{"market_ticker":"KXBTC15M-26MAY141815-15","market_id":"9b5194ce-fa5b-4fa6-a79f-003263374118","price_dollars":"0.1500","delta_fp":"-40.00","side":"yes","ts":"2026-05-14T22:08:36.956658Z","ts_ms":1778796516956}}

{"type":"orderbook_delta","sid":1,"seq":609,"msg":{"market_ticker":"KXBTC15M-26MAY141815-15","market_id":"9b5194ce-fa5b-4fa6-a79f-003263374118","price_dollars":"0.1400","delta_fp":"40.00","side":"yes","ts":"2026-05-14T22:08:36.956658Z","ts_ms":1778796516956}}

{"type":"orderbook_delta","sid":1,"seq":610,"msg":{"market_ticker":"KXBTC15M-26MAY141815-15","market_id":"9b5194ce-fa5b-4fa6-a79f-003263374118","price_dollars":"0.6800","delta_fp":"-75.00","side":"yes","ts":"2026-05-14T22:08:36.963781Z","ts_ms":1778796516963}}

{"type":"orderbook_delta","sid":1,"seq":611,"msg":{"market_ticker":"KXBTC15M-26MAY141815-15","market_id":"9b5194ce-fa5b-4fa6-a79f-003263374118","price_dollars":"0.6200","delta_fp":"75.00","side":"yes","ts":"2026-05-14T22:08:36.963781Z","ts_ms":1778796516963}}

{"type":"orderbook_delta","sid":1,"seq":612,"msg":{"market_ticker":"KXBTC15M-26MAY141815-15","market_id":"9b5194ce-fa5b-4fa6-a79f-003263374118","price_dollars":"0.2800","delta_fp":"-11.00","side":"no","ts":"2026-05-14T22:08:36.968149Z","ts_ms":1778796516968}}

{"type":"orderbook_delta","sid":1,"seq":613,"msg":{"market_ticker":"KXBTC15M-26MAY141815-15","market_id":"9b5194ce-fa5b-4fa6-a79f-003263374118","price_dollars":"0.2700","delta_fp":"20.00","side":"no","ts":"2026-05-14T22:08:36.968149Z","ts_ms":1778796516968}}

{"type":"orderbook_delta","sid":1,"seq":614,"msg":{"market_ticker":"KXBTC15M-26MAY141815-15","market_id":"9b5194ce-fa5b-4fa6-a79f-003263374118","price_dollars":"0.6000","delta_fp":"251.00","side":"yes","ts":"2026-05-14T22:08:36.975498Z","ts_ms":1778796516975}}

{"type":"orderbook_delta","sid":1,"seq":615,"msg":{"market_ticker":"KXBTC15M-26MAY141815-15","market_id":"9b5194ce-fa5b-4fa6-a79f-003263374118","price_dollars":"0.5900","delta_fp":"-50.00","side":"yes","ts":"2026-05-14T22:08:36.9791Z","ts_ms":1778796516979}}

{"type":"orderbook_delta","sid":1,"seq":616,"msg":{"market_ticker":"KXBTC15M-26MAY141815-15","market_id":"9b5194ce-fa5b-4fa6-a79f-003263374118","price_dollars":"0.5600","delta_fp":"50.00","side":"yes","ts":"2026-05-14T22:08:36.979752Z","ts_ms":1778796516979}}

{"type":"orderbook_delta","sid":1,"seq":617,"msg":{"market_ticker":"KXBTC15M-26MAY141815-15","market_id":"9b5194ce-fa5b-4fa6-a79f-003263374118","price_dollars":"0.2900","delta_fp":"100.00","side":"no","ts":"2026-05-14T22:08:36.98033Z","ts_ms":1778796516980}}

{"type":"orderbook_delta","sid":1,"seq":618,"msg":{"market_ticker":"KXBTC15M-26MAY141815-15","market_id":"9b5194ce-fa5b-4fa6-a79f-003263374118","price_dollars":"0.2700","delta_fp":"-20.00","side":"no","ts":"2026-05-14T22:08:36.9841Z","ts_ms":1778796516984}}

{"type":"orderbook_delta","sid":1,"seq":619,"msg":{"market_ticker":"KXBTC15M-26MAY141815-15","market_id":"9b5194ce-fa5b-4fa6-a79f-003263374118","price_dollars":"0.2900","delta_fp":"12.00","side":"no","ts":"2026-05-14T22:08:36.9841Z","ts_ms":1778796516984}}

{"type":"orderbook_delta","sid":1,"seq":620,"msg":{"market_ticker":"KXBTC15M-26MAY141815-15","market_id":"9b5194ce-fa5b-4fa6-a79f-003263374118","price_dollars":"0.2900","delta_fp":"-12.00","side":"no","ts":"2026-05-14T22:08:37.002906Z","ts_ms":1778796517002}}

{"type":"orderbook_delta","sid":1,"seq":621,"msg":{"market_ticker":"KXBTC15M-26MAY141815-15","market_id":"9b5194ce-fa5b-4fa6-a79f-003263374118","price_dollars":"0.2800","delta_fp":"20.00","side":"no","ts":"2026-05-14T22:08:37.002906Z","ts_ms":1778796517002}}

{"type":"orderbook_delta","sid":1,"seq":622,"msg":{"market_ticker":"KXBTC15M-26MAY141815-15","market_id":"9b5194ce-fa5b-4fa6-a79f-003263374118","price_dollars":"0.2800","delta_fp":"-20.00","side":"no","ts":"2026-05-14T22:08:37.020745Z","ts_ms":1778796517020}}

{"type":"orderbook_delta","sid":1,"seq":623,"msg":{"market_ticker":"KXBTC15M-26MAY141815-15","market_id":"9b5194ce-fa5b-4fa6-a79f-003263374118","price_dollars":"0.2900","delta_fp":"10.00","side":"no","ts":"2026-05-14T22:08:37.020745Z","ts_ms":1778796517020}}

{"type":"orderbook_delta","sid":1,"seq":624,"msg":{"market_ticker":"KXBTC15M-26MAY141815-15","market_id":"9b5194ce-fa5b-4fa6-a79f-003263374118","price_dollars":"0.6300","delta_fp":"2.00","side":"yes","ts":"2026-05-14T22:08:37.033051Z","ts_ms":1778796517033}}

{"type":"orderbook_delta","sid":1,"seq":625,"msg":{"market_ticker":"KXBTC15M-26MAY141815-15","market_id":"9b5194ce-fa5b-4fa6-a79f-003263374118","price_dollars":"0.2900","delta_fp":"-10.00","side":"no","ts":"2026-05-14T22:08:37.034741Z","ts_ms":1778796517034}}

{"type":"orderbook_delta","sid":1,"seq":626,"msg":{"market_ticker":"KXBTC15M-26MAY141815-15","market_id":"9b5194ce-fa5b-4fa6-a79f-003263374118","price_dollars":"0.2800","delta_fp":"12.00","side":"no","ts":"2026-05-14T22:08:37.034741Z","ts_ms":1778796517034}}

{"type":"orderbook_delta","sid":1,"seq":627,"msg":{"market_ticker":"KXBTC15M-26MAY141815-15","market_id":"9b5194ce-fa5b-4fa6-a79f-003263374118","price_dollars":"0.2300","delta_fp":"-75.00","side":"no","ts":"2026-05-14T22:08:37.042933Z","ts_ms":1778796517042}}

{"type":"orderbook_delta","sid":1,"seq":628,"msg":{"market_ticker":"KXBTC15M-26MAY141815-15","market_id":"9b5194ce-fa5b-4fa6-a79f-003263374118","price_dollars":"0.3100","delta_fp":"75.00","side":"no","ts":"2026-05-14T22:08:37.042933Z","ts_ms":1778796517042}}

{"type":"orderbook_delta","sid":1,"seq":629,"msg":{"market_ticker":"KXBTC15M-26MAY141815-15","market_id":"9b5194ce-fa5b-4fa6-a79f-003263374118","price_dollars":"0.1400","delta_fp":"-40.00","side":"yes","ts":"2026-05-14T22:08:37.048276Z","ts_ms":1778796517048}}

{"type":"orderbook_delta","sid":1,"seq":630,"msg":{"market_ticker":"KXBTC15M-26MAY141815-15","market_id":"9b5194ce-fa5b-4fa6-a79f-003263374118","price_dollars":"0.1900","delta_fp":"40.00","side":"yes","ts":"2026-05-14T22:08:37.048276Z","ts_ms":1778796517048}}

{"type":"orderbook_delta","sid":1,"seq":631,"msg":{"market_ticker":"KXBTC15M-26MAY141815-15","market_id":"9b5194ce-fa5b-4fa6-a79f-003263374118","price_dollars":"0.2800","delta_fp":"-12.00","side":"no","ts":"2026-05-14T22:08:37.060207Z","ts_ms":1778796517060}}

{"type":"orderbook_delta","sid":1,"seq":632,"msg":{"market_ticker":"KXBTC15M-26MAY141815-15","market_id":"9b5194ce-fa5b-4fa6-a79f-003263374118","price_dollars":"0.2700","delta_fp":"15.00","side":"no","ts":"2026-05-14T22:08:37.060207Z","ts_ms":1778796517060}}

{"type":"orderbook_delta","sid":1,"seq":633,"msg":{"market_ticker":"KXBTC15M-26MAY141815-15","market_id":"9b5194ce-fa5b-4fa6-a79f-003263374118","price_dollars":"0.6400","delta_fp":"-400.00","side":"yes","ts":"2026-05-14T22:08:37.07437Z","ts_ms":1778796517074}}

{"type":"orderbook_delta","sid":1,"seq":634,"msg":{"market_ticker":"KXBTC15M-26MAY141815-15","market_id":"9b5194ce-fa5b-4fa6-a79f-003263374118","price_dollars":"0.6500","delta_fp":"400.00","side":"yes","ts":"2026-05-14T22:08:37.07437Z","ts_ms":1778796517074}}

{"type":"orderbook_delta","sid":1,"seq":635,"msg":{"market_ticker":"KXBTC15M-26MAY141815-15","market_id":"9b5194ce-fa5b-4fa6-a79f-003263374118","price_dollars":"0.2800","delta_fp":"-400.00","side":"no","ts":"2026-05-14T22:08:37.074962Z","ts_ms":1778796517074}}

{"type":"orderbook_delta","sid":1,"seq":636,"msg":{"market_ticker":"KXBTC15M-26MAY141815-15","market_id":"9b5194ce-fa5b-4fa6-a79f-003263374118","price_dollars":"0.2700","delta_fp":"400.00","side":"no","ts":"2026-05-14T22:08:37.074962Z","ts_ms":1778796517074}}

{"type":"orderbook_delta","sid":1,"seq":637,"msg":{"market_ticker":"KXBTC15M-26MAY141815-15","market_id":"9b5194ce-fa5b-4fa6-a79f-003263374118","price_dollars":"0.5600","delta_fp":"-50.00","side":"yes","ts":"2026-05-14T22:08:37.080143Z","ts_ms":1778796517080}}

{"type":"orderbook_delta","sid":1,"seq":638,"msg":{"market_ticker":"KXBTC15M-26MAY141815-15","market_id":"9b5194ce-fa5b-4fa6-a79f-003263374118","price_dollars":"0.5900","delta_fp":"50.00","side":"yes","ts":"2026-05-14T22:08:37.08072Z","ts_ms":1778796517080}}

{"type":"orderbook_delta","sid":1,"seq":639,"msg":{"market_ticker":"KXBTC15M-26MAY141815-15","market_id":"9b5194ce-fa5b-4fa6-a79f-003263374118","price_dollars":"0.2900","delta_fp":"-100.00","side":"no","ts":"2026-05-14T22:08:37.081743Z","ts_ms":1778796517081}}

{"type":"orderbook_delta","sid":1,"seq":640,"msg":{"market_ticker":"KXBTC15M-26MAY141815-15","market_id":"9b5194ce-fa5b-4fa6-a79f-003263374118","price_dollars":"0.3000","delta_fp":"100.00","side":"no","ts":"2026-05-14T22:08:37.081743Z","ts_ms":1778796517081}}

{"type":"orderbook_delta","sid":1,"seq":641,"msg":{"market_ticker":"KXBTC15M-26MAY141815-15","market_id":"9b5194ce-fa5b-4fa6-a79f-003263374118","price_dollars":"0.5500","delta_fp":"6249.00","side":"yes","ts":"2026-05-14T22:08:37.091903Z","ts_ms":1778796517091}}

{"type":"orderbook_delta","sid":1,"seq":642,"msg":{"market_ticker":"KXBTC15M-26MAY141815-15","market_id":"9b5194ce-fa5b-4fa6-a79f-003263374118","price_dollars":"0.5900","delta_fp":"-15.00","side":"yes","ts":"2026-05-14T22:08:37.097539Z","ts_ms":1778796517097}}

{"type":"orderbook_delta","sid":1,"seq":643,"msg":{"market_ticker":"KXBTC15M-26MAY141815-15","market_id":"9b5194ce-fa5b-4fa6-a79f-003263374118","price_dollars":"0.5800","delta_fp":"15.00","side":"yes","ts":"2026-05-14T22:08:37.097539Z","ts_ms":1778796517097}}

{"type":"orderbook_delta","sid":1,"seq":644,"msg":{"market_ticker":"KXBTC15M-26MAY141815-15","market_id":"9b5194ce-fa5b-4fa6-a79f-003263374118","price_dollars":"0.0910","delta_fp":"-14.00","side":"no","ts":"2026-05-14T22:08:37.101922Z","ts_ms":1778796517101}}

{"type":"orderbook_delta","sid":1,"seq":645,"msg":{"market_ticker":"KXBTC15M-26MAY141815-15","market_id":"9b5194ce-fa5b-4fa6-a79f-003263374118","price_dollars":"0.2100","delta_fp":"14.00","side":"no","ts":"2026-05-14T22:08:37.101922Z","ts_ms":1778796517101}}

{"type":"orderbook_delta","sid":1,"seq":646,"msg":{"market_ticker":"KXBTC15M-26MAY141815-15","market_id":"9b5194ce-fa5b-4fa6-a79f-003263374118","price_dollars":"0.2700","delta_fp":"-15.00","side":"no","ts":"2026-05-14T22:08:37.105165Z","ts_ms":1778796517105}}

{"type":"orderbook_delta","sid":1,"seq":647,"msg":{"market_ticker":"KXBTC15M-26MAY141815-15","market_id":"9b5194ce-fa5b-4fa6-a79f-003263374118","price_dollars":"0.2800","delta_fp":"13.00","side":"no","ts":"2026-05-14T22:08:37.105165Z","ts_ms":1778796517105}}

{"type":"orderbook_delta","sid":1,"seq":648,"msg":{"market_ticker":"KXBTC15M-26MAY141815-15","market_id":"9b5194ce-fa5b-4fa6-a79f-003263374118","price_dollars":"0.6500","delta_fp":"-400.00","side":"yes","ts":"2026-05-14T22:08:37.113581Z","ts_ms":1778796517113}}

{"type":"orderbook_delta","sid":1,"seq":649,"msg":{"market_ticker":"KXBTC15M-26MAY141815-15","market_id":"9b5194ce-fa5b-4fa6-a79f-003263374118","price_dollars":"0.6400","delta_fp":"400.00","side":"yes","ts":"2026-05-14T22:08:37.113581Z","ts_ms":1778796517113}}

{"type":"orderbook_delta","sid":1,"seq":650,"msg":{"market_ticker":"KXBTC15M-26MAY141815-15","market_id":"9b5194ce-fa5b-4fa6-a79f-003263374118","price_dollars":"0.2800","delta_fp":"-13.00","side":"no","ts":"2026-05-14T22:08:37.123068Z","ts_ms":1778796517123}}

{"type":"orderbook_delta","sid":1,"seq":651,"msg":{"market_ticker":"KXBTC15M-26MAY141815-15","market_id":"9b5194ce-fa5b-4fa6-a79f-003263374118","price_dollars":"0.2700","delta_fp":"19.00","side":"no","ts":"2026-05-14T22:08:37.123068Z","ts_ms":1778796517123}}

{"type":"orderbook_delta","sid":1,"seq":652,"msg":{"market_ticker":"KXBTC15M-26MAY141815-15","market_id":"9b5194ce-fa5b-4fa6-a79f-003263374118","price_dollars":"0.6800","delta_fp":"1.00","side":"yes","ts":"2026-05-14T22:08:37.138362Z","ts_ms":1778796517138}}

{"type":"orderbook_delta","sid":1,"seq":653,"msg":{"market_ticker":"KXBTC15M-26MAY141815-15","market_id":"9b5194ce-fa5b-4fa6-a79f-003263374118","price_dollars":"0.2700","delta_fp":"-19.00","side":"no","ts":"2026-05-14T22:08:37.141771Z","ts_ms":1778796517141}}

{"type":"orderbook_delta","sid":1,"seq":654,"msg":{"market_ticker":"KXBTC15M-26MAY141815-15","market_id":"9b5194ce-fa5b-4fa6-a79f-003263374118","price_dollars":"0.2800","delta_fp":"20.00","side":"no","ts":"2026-05-14T22:08:37.141771Z","ts_ms":1778796517141}}

{"type":"orderbook_delta","sid":1,"seq":655,"msg":{"market_ticker":"KXBTC15M-26MAY141815-15","market_id":"9b5194ce-fa5b-4fa6-a79f-003263374118","price_dollars":"0.3000","delta_fp":"-1.00","side":"no","ts":"2026-05-14T22:08:37.152702Z","ts_ms":1778796517152}}

{"type":"orderbook_delta","sid":1,"seq":656,"msg":{"market_ticker":"KXBTC15M-26MAY141815-15","market_id":"9b5194ce-fa5b-4fa6-a79f-003263374118","price_dollars":"0.5700","delta_fp":"-1.00","side":"yes","ts":"2026-05-14T22:08:37.153717Z","ts_ms":1778796517153}}

{"type":"orderbook_delta","sid":1,"seq":657,"msg":{"market_ticker":"KXBTC15M-26MAY141815-15","market_id":"9b5194ce-fa5b-4fa6-a79f-003263374118","price_dollars":"0.5600","delta_fp":"-1.00","side":"yes","ts":"2026-05-14T22:08:37.154686Z","ts_ms":1778796517154}}

{"type":"orderbook_delta","sid":1,"seq":658,"msg":{"market_ticker":"KXBTC15M-26MAY141815-15","market_id":"9b5194ce-fa5b-4fa6-a79f-003263374118","price_dollars":"0.6300","delta_fp":"-2.00","side":"yes","ts":"2026-05-14T22:08:37.15534Z","ts_ms":1778796517155}}

{"type":"orderbook_delta","sid":1,"seq":659,"msg":{"market_ticker":"KXBTC15M-26MAY141815-15","market_id":"9b5194ce-fa5b-4fa6-a79f-003263374118","price_dollars":"0.2800","delta_fp":"-20.00","side":"no","ts":"2026-05-14T22:08:37.156135Z","ts_ms":1778796517156}}

{"type":"orderbook_delta","sid":1,"seq":660,"msg":{"market_ticker":"KXBTC15M-26MAY141815-15","market_id":"9b5194ce-fa5b-4fa6-a79f-003263374118","price_dollars":"0.2700","delta_fp":"20.00","side":"no","ts":"2026-05-14T22:08:37.156135Z","ts_ms":1778796517156}}

{"type":"orderbook_delta","sid":1,"seq":661,"msg":{"market_ticker":"KXBTC15M-26MAY141815-15","market_id":"9b5194ce-fa5b-4fa6-a79f-003263374118","price_dollars":"0.3000","delta_fp":"-100.00","side":"no","ts":"2026-05-14T22:08:37.160334Z","ts_ms":1778796517160}}

{"type":"orderbook_delta","sid":1,"seq":662,"msg":{"market_ticker":"KXBTC15M-26MAY141815-15","market_id":"9b5194ce-fa5b-4fa6-a79f-003263374118","price_dollars":"0.3100","delta_fp":"100.00","side":"no","ts":"2026-05-14T22:08:37.160334Z","ts_ms":1778796517160}}

{"type":"orderbook_delta","sid":1,"seq":663,"msg":{"market_ticker":"KXBTC15M-26MAY141815-15","market_id":"9b5194ce-fa5b-4fa6-a79f-003263374118","price_dollars":"0.0700","delta_fp":"2.00","side":"no","ts":"2026-05-14T22:08:37.163529Z","ts_ms":1778796517163}}

{"type":"orderbook_delta","sid":1,"seq":664,"msg":{"market_ticker":"KXBTC15M-26MAY141815-15","market_id":"9b5194ce-fa5b-4fa6-a79f-003263374118","price_dollars":"0.6100","delta_fp":"2.00","side":"yes","ts":"2026-05-14T22:08:37.176822Z","ts_ms":1778796517176}}

{"type":"orderbook_delta","sid":1,"seq":665,"msg":{"market_ticker":"KXBTC15M-26MAY141815-15","market_id":"9b5194ce-fa5b-4fa6-a79f-003263374118","price_dollars":"0.6500","delta_fp":"-2.00","side":"yes","ts":"2026-05-14T22:08:37.185511Z","ts_ms":1778796517185}}

{"type":"orderbook_delta","sid":1,"seq":666,"msg":{"market_ticker":"KXBTC15M-26MAY141815-15","market_id":"9b5194ce-fa5b-4fa6-a79f-003263374118","price_dollars":"0.2700","delta_fp":"-20.00","side":"no","ts":"2026-05-14T22:08:37.196239Z","ts_ms":1778796517196}}

{"type":"orderbook_delta","sid":1,"seq":667,"msg":{"market_ticker":"KXBTC15M-26MAY141815-15","market_id":"9b5194ce-fa5b-4fa6-a79f-003263374118","price_dollars":"0.2800","delta_fp":"14.00","side":"no","ts":"2026-05-14T22:08:37.196239Z","ts_ms":1778796517196}}

{"type":"orderbook_delta","sid":1,"seq":668,"msg":{"market_ticker":"KXBTC15M-26MAY141815-15","market_id":"9b5194ce-fa5b-4fa6-a79f-003263374118","price_dollars":"0.6400","delta_fp":"-400.00","side":"yes","ts":"2026-05-14T22:08:37.214986Z","ts_ms":1778796517214}}

{"type":"orderbook_delta","sid":1,"seq":669,"msg":{"market_ticker":"KXBTC15M-26MAY141815-15","market_id":"9b5194ce-fa5b-4fa6-a79f-003263374118","price_dollars":"0.6500","delta_fp":"400.00","side":"yes","ts":"2026-05-14T22:08:37.214986Z","ts_ms":1778796517214}}

{"type":"orderbook_delta","sid":1,"seq":670,"msg":{"market_ticker":"KXBTC15M-26MAY141815-15","market_id":"9b5194ce-fa5b-4fa6-a79f-003263374118","price_dollars":"0.6800","delta_fp":"36.00","side":"yes","ts":"2026-05-14T22:08:37.233818Z","ts_ms":1778796517233}}

{"type":"orderbook_delta","sid":1,"seq":671,"msg":{"market_ticker":"KXBTC15M-26MAY141815-15","market_id":"9b5194ce-fa5b-4fa6-a79f-003263374118","price_dollars":"0.0100","delta_fp":"2.13","side":"yes","ts":"2026-05-14T22:08:37.248939Z","ts_ms":1778796517248}}

{"type":"orderbook_delta","sid":1,"seq":672,"msg":{"market_ticker":"KXBTC15M-26MAY141815-15","market_id":"9b5194ce-fa5b-4fa6-a79f-003263374118","price_dollars":"0.3000","delta_fp":"-150.00","side":"no","ts":"2026-05-14T22:08:37.337955Z","ts_ms":1778796517337}}

{"type":"orderbook_delta","sid":1,"seq":673,"msg":{"market_ticker":"KXBTC15M-26MAY141815-15","market_id":"9b5194ce-fa5b-4fa6-a79f-003263374118","price_dollars":"0.2600","delta_fp":"150.00","side":"no","ts":"2026-05-14T22:08:37.337955Z","ts_ms":1778796517337}}

{"type":"orderbook_delta","sid":1,"seq":674,"msg":{"market_ticker":"KXBTC15M-26MAY141815-15","market_id":"9b5194ce-fa5b-4fa6-a79f-003263374118","price_dollars":"0.6000","delta_fp":"-251.00","side":"yes","ts":"2026-05-14T22:08:37.346156Z","ts_ms":1778796517346}}

{"type":"orderbook_delta","sid":1,"seq":675,"msg":{"market_ticker":"KXBTC15M-26MAY141815-15","market_id":"9b5194ce-fa5b-4fa6-a79f-003263374118","price_dollars":"0.5700","delta_fp":"-150.00","side":"yes","ts":"2026-05-14T22:08:37.359998Z","ts_ms":1778796517359}}

{"type":"orderbook_delta","sid":1,"seq":676,"msg":{"market_ticker":"KXBTC15M-26MAY141815-15","market_id":"9b5194ce-fa5b-4fa6-a79f-003263374118","price_dollars":"0.6100","delta_fp":"150.00","side":"yes","ts":"2026-05-14T22:08:37.359998Z","ts_ms":1778796517359}}

{"type":"orderbook_delta","sid":1,"seq":677,"msg":{"market_ticker":"KXBTC15M-26MAY141815-15","market_id":"9b5194ce-fa5b-4fa6-a79f-003263374118","price_dollars":"0.6100","delta_fp":"-2.00","side":"yes","ts":"2026-05-14T22:08:37.463904Z","ts_ms":1778796517463}}

{"type":"orderbook_delta","sid":1,"seq":678,"msg":{"market_ticker":"KXBTC15M-26MAY141815-15","market_id":"9b5194ce-fa5b-4fa6-a79f-003263374118","price_dollars":"0.1400","delta_fp":"-2.00","side":"no","ts":"2026-05-14T22:08:37.473159Z","ts_ms":1778796517473}}

{"type":"orderbook_delta","sid":1,"seq":679,"msg":{"market_ticker":"KXBTC15M-26MAY141815-15","market_id":"9b5194ce-fa5b-4fa6-a79f-003263374118","price_dollars":"0.6000","delta_fp":"2.00","side":"yes","ts":"2026-05-14T22:08:37.511411Z","ts_ms":1778796517511}}

{"type":"orderbook_delta","sid":1,"seq":680,"msg":{"market_ticker":"KXBTC15M-26MAY141815-15","market_id":"9b5194ce-fa5b-4fa6-a79f-003263374118","price_dollars":"0.6100","delta_fp":"251.00","side":"yes","ts":"2026-05-14T22:08:37.51613Z","ts_ms":1778796517516}}

{"type":"orderbook_delta","sid":1,"seq":681,"msg":{"market_ticker":"KXBTC15M-26MAY141815-15","market_id":"9b5194ce-fa5b-4fa6-a79f-003263374118","price_dollars":"0.6800","delta_fp":"-5.31","side":"yes","ts":"2026-05-14T22:08:37.518806Z","ts_ms":1778796517518}}

{"type":"orderbook_delta","sid":1,"seq":682,"msg":{"market_ticker":"KXBTC15M-26MAY141815-15","market_id":"9b5194ce-fa5b-4fa6-a79f-003263374118","price_dollars":"0.6300","delta_fp":"-2.00","side":"yes","ts":"2026-05-14T22:08:37.532776Z","ts_ms":1778796517532}}

{"type":"orderbook_delta","sid":1,"seq":683,"msg":{"market_ticker":"KXBTC15M-26MAY141815-15","market_id":"9b5194ce-fa5b-4fa6-a79f-003263374118","price_dollars":"0.6400","delta_fp":"2.00","side":"yes","ts":"2026-05-14T22:08:37.532776Z","ts_ms":1778796517532}}

{"type":"orderbook_delta","sid":1,"seq":684,"msg":{"market_ticker":"KXBTC15M-26MAY141815-15","market_id":"9b5194ce-fa5b-4fa6-a79f-003263374118","price_dollars":"0.2900","delta_fp":"-2.00","side":"no","ts":"2026-05-14T22:08:37.561415Z","ts_ms":1778796517561}}

{"type":"orderbook_delta","sid":1,"seq":685,"msg":{"market_ticker":"KXBTC15M-26MAY141815-15","market_id":"9b5194ce-fa5b-4fa6-a79f-003263374118","price_dollars":"0.2700","delta_fp":"2.00","side":"no","ts":"2026-05-14T22:08:37.561415Z","ts_ms":1778796517561}}

{"type":"orderbook_delta","sid":1,"seq":686,"msg":{"market_ticker":"KXBTC15M-26MAY141815-15","market_id":"9b5194ce-fa5b-4fa6-a79f-003263374118","price_dollars":"0.0700","delta_fp":"-811.00","side":"yes","ts":"2026-05-14T22:08:37.648581Z","ts_ms":1778796517648}}

{"type":"orderbook_delta","sid":1,"seq":687,"msg":{"market_ticker":"KXBTC15M-26MAY141815-15","market_id":"9b5194ce-fa5b-4fa6-a79f-003263374118","price_dollars":"0.0600","delta_fp":"860.00","side":"yes","ts":"2026-05-14T22:08:37.648581Z","ts_ms":1778796517648}}

{"type":"orderbook_delta","sid":1,"seq":688,"msg":{"market_ticker":"KXBTC15M-26MAY141815-15","market_id":"9b5194ce-fa5b-4fa6-a79f-003263374118","price_dollars":"0.6200","delta_fp":"-75.00","side":"yes","ts":"2026-05-14T22:08:37.663249Z","ts_ms":1778796517663}}

{"type":"orderbook_delta","sid":1,"seq":689,"msg":{"market_ticker":"KXBTC15M-26MAY141815-15","market_id":"9b5194ce-fa5b-4fa6-a79f-003263374118","price_dollars":"0.6800","delta_fp":"75.00","side":"yes","ts":"2026-05-14T22:08:37.663249Z","ts_ms":1778796517663}}

{"type":"orderbook_delta","sid":1,"seq":690,"msg":{"market_ticker":"KXBTC15M-26MAY141815-15","market_id":"9b5194ce-fa5b-4fa6-a79f-003263374118","price_dollars":"0.3100","delta_fp":"-75.00","side":"no","ts":"2026-05-14T22:08:37.663683Z","ts_ms":1778796517663}}

{"type":"orderbook_delta","sid":1,"seq":691,"msg":{"market_ticker":"KXBTC15M-26MAY141815-15","market_id":"9b5194ce-fa5b-4fa6-a79f-003263374118","price_dollars":"0.2400","delta_fp":"75.00","side":"no","ts":"2026-05-14T22:08:37.663683Z","ts_ms":1778796517663}}

{"type":"orderbook_delta","sid":1,"seq":692,"msg":{"market_ticker":"KXBTC15M-26MAY141815-15","market_id":"9b5194ce-fa5b-4fa6-a79f-003263374118","price_dollars":"0.3100","delta_fp":"-2.00","side":"no","ts":"2026-05-14T22:08:37.679894Z","ts_ms":1778796517679}}

{"type":"orderbook_delta","sid":1,"seq":693,"msg":{"market_ticker":"KXBTC15M-26MAY141815-15","market_id":"9b5194ce-fa5b-4fa6-a79f-003263374118","price_dollars":"0.3100","delta_fp":"-40.79","side":"no","ts":"2026-05-14T22:08:37.679894Z","ts_ms":1778796517679}}

{"type":"orderbook_delta","sid":1,"seq":694,"msg":{"market_ticker":"KXBTC15M-26MAY141815-15","market_id":"9b5194ce-fa5b-4fa6-a79f-003263374118","price_dollars":"0.0900","delta_fp":"-849.00","side":"yes","ts":"2026-05-14T22:08:37.684082Z","ts_ms":1778796517684}}

{"type":"orderbook_delta","sid":1,"seq":695,"msg":{"market_ticker":"KXBTC15M-26MAY141815-15","market_id":"9b5194ce-fa5b-4fa6-a79f-003263374118","price_dollars":"0.0800","delta_fp":"847.00","side":"yes","ts":"2026-05-14T22:08:37.684082Z","ts_ms":1778796517684}}

{"type":"orderbook_delta","sid":1,"seq":696,"msg":{"market_ticker":"KXBTC15M-26MAY141815-15","market_id":"9b5194ce-fa5b-4fa6-a79f-003263374118","price_dollars":"0.0500","delta_fp":"-855.00","side":"yes","ts":"2026-05-14T22:08:37.692117Z","ts_ms":1778796517692}}

{"type":"orderbook_delta","sid":1,"seq":697,"msg":{"market_ticker":"KXBTC15M-26MAY141815-15","market_id":"9b5194ce-fa5b-4fa6-a79f-003263374118","price_dollars":"0.0400","delta_fp":"774.00","side":"yes","ts":"2026-05-14T22:08:37.692117Z","ts_ms":1778796517692}}

{"type":"orderbook_delta","sid":1,"seq":698,"msg":{"market_ticker":"KXBTC15M-26MAY141815-15","market_id":"9b5194ce-fa5b-4fa6-a79f-003263374118","price_dollars":"0.3100","delta_fp":"40.00","side":"no","ts":"2026-05-14T22:08:37.729009Z","ts_ms":1778796517729}}

{"type":"orderbook_delta","sid":1,"seq":699,"msg":{"market_ticker":"KXBTC15M-26MAY141815-15","market_id":"9b5194ce-fa5b-4fa6-a79f-003263374118","price_dollars":"0.0200","delta_fp":"-772.00","side":"no","ts":"2026-05-14T22:08:37.730921Z","ts_ms":1778796517730}}

{"type":"orderbook_delta","sid":1,"seq":700,"msg":{"market_ticker":"KXBTC15M-26MAY141815-15","market_id":"9b5194ce-fa5b-4fa6-a79f-003263374118","price_dollars":"0.0100","delta_fp":"-26843.00","side":"no","ts":"2026-05-14T22:08:37.731924Z","ts_ms":1778796517731}}

{"type":"orderbook_delta","sid":1,"seq":701,"msg":{"market_ticker":"KXBTC15M-26MAY141815-15","market_id":"9b5194ce-fa5b-4fa6-a79f-003263374118","price_dollars":"0.6100","delta_fp":"-251.00","side":"yes","ts":"2026-05-14T22:08:37.784502Z","ts_ms":1778796517784}}

{"type":"orderbook_delta","sid":1,"seq":702,"msg":{"market_ticker":"KXBTC15M-26MAY141815-15","market_id":"9b5194ce-fa5b-4fa6-a79f-003263374118","price_dollars":"0.1300","delta_fp":"-2.00","side":"no","ts":"2026-05-14T22:08:37.786191Z","ts_ms":1778796517786}}

{"type":"orderbook_delta","sid":1,"seq":703,"msg":{"market_ticker":"KXBTC15M-26MAY141815-15","market_id":"9b5194ce-fa5b-4fa6-a79f-003263374118","price_dollars":"0.0600","delta_fp":"2.00","side":"no","ts":"2026-05-14T22:08:37.799483Z","ts_ms":1778796517799}}

{"type":"orderbook_delta","sid":1,"seq":704,"msg":{"market_ticker":"KXBTC15M-26MAY141815-15","market_id":"9b5194ce-fa5b-4fa6-a79f-003263374118","price_dollars":"0.2900","delta_fp":"2.00","side":"no","ts":"2026-05-14T22:08:37.806361Z","ts_ms":1778796517806}}

{"type":"orderbook_delta","sid":1,"seq":705,"msg":{"market_ticker":"KXBTC15M-26MAY141815-15","market_id":"9b5194ce-fa5b-4fa6-a79f-003263374118","price_dollars":"0.6100","delta_fp":"2.00","side":"yes","ts":"2026-05-14T22:08:37.812955Z","ts_ms":1778796517812}}

{"type":"orderbook_delta","sid":1,"seq":706,"msg":{"market_ticker":"KXBTC15M-26MAY141815-15","market_id":"9b5194ce-fa5b-4fa6-a79f-003263374118","price_dollars":"0.5600","delta_fp":"7.00","side":"yes","ts":"2026-05-14T22:08:37.826226Z","ts_ms":1778796517826}}

{"type":"orderbook_delta","sid":1,"seq":707,"msg":{"market_ticker":"KXBTC15M-26MAY141815-15","market_id":"9b5194ce-fa5b-4fa6-a79f-003263374118","price_dollars":"0.5800","delta_fp":"1.00","side":"yes","ts":"2026-05-14T22:08:37.849198Z","ts_ms":1778796517849}}

{"type":"orderbook_delta","sid":1,"seq":708,"msg":{"market_ticker":"KXBTC15M-26MAY141815-15","market_id":"9b5194ce-fa5b-4fa6-a79f-003263374118","price_dollars":"0.5600","delta_fp":"1.00","side":"yes","ts":"2026-05-14T22:08:37.850215Z","ts_ms":1778796517850}}

{"type":"orderbook_delta","sid":1,"seq":709,"msg":{"market_ticker":"KXBTC15M-26MAY141815-15","market_id":"9b5194ce-fa5b-4fa6-a79f-003263374118","price_dollars":"0.3100","delta_fp":"1.00","side":"no","ts":"2026-05-14T22:08:37.851303Z","ts_ms":1778796517851}}

{"type":"orderbook_delta","sid":1,"seq":710,"msg":{"market_ticker":"KXBTC15M-26MAY141815-15","market_id":"9b5194ce-fa5b-4fa6-a79f-003263374118","price_dollars":"0.3000","delta_fp":"1.00","side":"no","ts":"2026-05-14T22:08:37.852462Z","ts_ms":1778796517852}}

{"type":"orderbook_delta","sid":1,"seq":711,"msg":{"market_ticker":"KXBTC15M-26MAY141815-15","market_id":"9b5194ce-fa5b-4fa6-a79f-003263374118","price_dollars":"0.3000","delta_fp":"-2.00","side":"no","ts":"2026-05-14T22:08:37.989364Z","ts_ms":1778796517989}}

{"type":"orderbook_delta","sid":1,"seq":712,"msg":{"market_ticker":"KXBTC15M-26MAY141815-15","market_id":"9b5194ce-fa5b-4fa6-a79f-003263374118","price_dollars":"0.6600","delta_fp":"2.00","side":"yes","ts":"2026-05-14T22:08:37.989583Z","ts_ms":1778796517989}}

{"type":"orderbook_delta","sid":1,"seq":713,"msg":{"market_ticker":"KXBTC15M-26MAY141815-15","market_id":"9b5194ce-fa5b-4fa6-a79f-003263374118","price_dollars":"0.2800","delta_fp":"2.00","side":"no","ts":"2026-05-14T22:08:37.991004Z","ts_ms":1778796517991}}

{"type":"orderbook_delta","sid":1,"seq":714,"msg":{"market_ticker":"KXBTC15M-26MAY141815-15","market_id":"9b5194ce-fa5b-4fa6-a79f-003263374118","price_dollars":"0.6100","delta_fp":"-2.00","side":"yes","ts":"2026-05-14T22:08:37.991751Z","ts_ms":1778796517991}}

{"type":"orderbook_delta","sid":1,"seq":715,"msg":{"market_ticker":"KXBTC15M-26MAY141815-15","market_id":"9b5194ce-fa5b-4fa6-a79f-003263374118","price_dollars":"0.6200","delta_fp":"251.00","side":"yes","ts":"2026-05-14T22:08:38.003594Z","ts_ms":1778796518003}}

{"type":"orderbook_delta","sid":1,"seq":716,"msg":{"market_ticker":"KXBTC15M-26MAY141815-15","market_id":"9b5194ce-fa5b-4fa6-a79f-003263374118","price_dollars":"0.3000","delta_fp":"-1.00","side":"no","ts":"2026-05-14T22:08:38.012167Z","ts_ms":1778796518012}}

{"type":"orderbook_delta","sid":1,"seq":717,"msg":{"market_ticker":"KXBTC15M-26MAY141815-15","market_id":"9b5194ce-fa5b-4fa6-a79f-003263374118","price_dollars":"0.3100","delta_fp":"-1.00","side":"no","ts":"2026-05-14T22:08:38.01258Z","ts_ms":1778796518012}}

{"type":"orderbook_delta","sid":1,"seq":718,"msg":{"market_ticker":"KXBTC15M-26MAY141815-15","market_id":"9b5194ce-fa5b-4fa6-a79f-003263374118","price_dollars":"0.5800","delta_fp":"-1.00","side":"yes","ts":"2026-05-14T22:08:38.012986Z","ts_ms":1778796518012}}

{"type":"orderbook_delta","sid":1,"seq":719,"msg":{"market_ticker":"KXBTC15M-26MAY141815-15","market_id":"9b5194ce-fa5b-4fa6-a79f-003263374118","price_dollars":"0.5600","delta_fp":"-1.00","side":"yes","ts":"2026-05-14T22:08:38.013409Z","ts_ms":1778796518013}}

{"type":"orderbook_delta","sid":1,"seq":720,"msg":{"market_ticker":"KXBTC15M-26MAY141815-15","market_id":"9b5194ce-fa5b-4fa6-a79f-003263374118","price_dollars":"0.2700","delta_fp":"-2.00","side":"no","ts":"2026-05-14T22:08:38.060265Z","ts_ms":1778796518060}}

{"type":"orderbook_delta","sid":1,"seq":721,"msg":{"market_ticker":"KXBTC15M-26MAY141815-15","market_id":"9b5194ce-fa5b-4fa6-a79f-003263374118","price_dollars":"0.2800","delta_fp":"2.00","side":"no","ts":"2026-05-14T22:08:38.060265Z","ts_ms":1778796518060}}

{"type":"orderbook_delta","sid":1,"seq":722,"msg":{"market_ticker":"KXBTC15M-26MAY141815-15","market_id":"9b5194ce-fa5b-4fa6-a79f-003263374118","price_dollars":"0.6400","delta_fp":"-2.00","side":"yes","ts":"2026-05-14T22:08:38.062709Z","ts_ms":1778796518062}}

{"type":"orderbook_delta","sid":1,"seq":723,"msg":{"market_ticker":"KXBTC15M-26MAY141815-15","market_id":"9b5194ce-fa5b-4fa6-a79f-003263374118","price_dollars":"0.6300","delta_fp":"2.00","side":"yes","ts":"2026-05-14T22:08:38.062709Z","ts_ms":1778796518062}}

{"type":"orderbook_delta","sid":1,"seq":724,"msg":{"market_ticker":"KXBTC15M-26MAY141815-15","market_id":"9b5194ce-fa5b-4fa6-a79f-003263374118","price_dollars":"0.1400","delta_fp":"6249.00","side":"no","ts":"2026-05-14T22:08:38.09132Z","ts_ms":1778796518091}}

{"type":"orderbook_delta","sid":1,"seq":725,"msg":{"market_ticker":"KXBTC15M-26MAY141815-15","market_id":"9b5194ce-fa5b-4fa6-a79f-003263374118","price_dollars":"0.3100","delta_fp":"-30.77","side":"no","ts":"2026-05-14T22:08:38.092147Z","ts_ms":1778796518092}}

{"type":"orderbook_delta","sid":1,"seq":726,"msg":{"market_ticker":"KXBTC15M-26MAY141815-15","market_id":"9b5194ce-fa5b-4fa6-a79f-003263374118","price_dollars":"0.6800","delta_fp":"-81.00","side":"yes","ts":"2026-05-14T22:08:38.094004Z","ts_ms":1778796518094}}

{"type":"orderbook_delta","sid":1,"seq":727,"msg":{"market_ticker":"KXBTC15M-26MAY141815-15","market_id":"9b5194ce-fa5b-4fa6-a79f-003263374118","price_dollars":"0.6500","delta_fp":"81.00","side":"yes","ts":"2026-05-14T22:08:38.107366Z","ts_ms":1778796518107}}

{"type":"orderbook_delta","sid":1,"seq":728,"msg":{"market_ticker":"KXBTC15M-26MAY141815-15","market_id":"9b5194ce-fa5b-4fa6-a79f-003263374118","price_dollars":"0.5800","delta_fp":"4999.00","side":"yes","ts":"2026-05-14T22:08:38.120499Z","ts_ms":1778796518120}}

{"type":"orderbook_delta","sid":1,"seq":729,"msg":{"market_ticker":"KXBTC15M-26MAY141815-15","market_id":"9b5194ce-fa5b-4fa6-a79f-003263374118","price_dollars":"0.3100","delta_fp":"31.00","side":"no","ts":"2026-05-14T22:08:38.136664Z","ts_ms":1778796518136}}

{"type":"orderbook_delta","sid":1,"seq":730,"msg":{"market_ticker":"KXBTC15M-26MAY141815-15","market_id":"9b5194ce-fa5b-4fa6-a79f-003263374118","price_dollars":"0.3100","delta_fp":"-39.56","side":"no","ts":"2026-05-14T22:08:38.139124Z","ts_ms":1778796518139}}

{"type":"orderbook_delta","sid":1,"seq":731,"msg":{"market_ticker":"KXBTC15M-26MAY141815-15","market_id":"9b5194ce-fa5b-4fa6-a79f-003263374118","price_dollars":"0.1700","delta_fp":"4999.00","side":"no","ts":"2026-05-14T22:08:38.147035Z","ts_ms":1778796518147}}

{"type":"orderbook_delta","sid":1,"seq":732,"msg":{"market_ticker":"KXBTC15M-26MAY141815-15","market_id":"9b5194ce-fa5b-4fa6-a79f-003263374118","price_dollars":"0.2800","delta_fp":"-2.00","side":"no","ts":"2026-05-14T22:08:38.151053Z","ts_ms":1778796518151}}

{"type":"orderbook_delta","sid":1,"seq":733,"msg":{"market_ticker":"KXBTC15M-26MAY141815-15","market_id":"9b5194ce-fa5b-4fa6-a79f-003263374118","price_dollars":"0.2700","delta_fp":"2.00","side":"no","ts":"2026-05-14T22:08:38.151053Z","ts_ms":1778796518151}}

{"type":"orderbook_delta","sid":1,"seq":734,"msg":{"market_ticker":"KXBTC15M-26MAY141815-15","market_id":"9b5194ce-fa5b-4fa6-a79f-003263374118","price_dollars":"0.6500","delta_fp":"249.00","side":"yes","ts":"2026-05-14T22:08:38.16237Z","ts_ms":1778796518162}}

{"type":"orderbook_delta","sid":1,"seq":735,"msg":{"market_ticker":"KXBTC15M-26MAY141815-15","market_id":"9b5194ce-fa5b-4fa6-a79f-003263374118","price_dollars":"0.3100","delta_fp":"40.00","side":"no","ts":"2026-05-14T22:08:38.175889Z","ts_ms":1778796518175}}

{"type":"orderbook_delta","sid":1,"seq":736,"msg":{"market_ticker":"KXBTC15M-26MAY141815-15","market_id":"9b5194ce-fa5b-4fa6-a79f-003263374118","price_dollars":"0.2200","delta_fp":"249.00","side":"no","ts":"2026-05-14T22:08:38.177542Z","ts_ms":1778796518177}}

{"type":"orderbook_delta","sid":1,"seq":737,"msg":{"market_ticker":"KXBTC15M-26MAY141815-15","market_id":"9b5194ce-fa5b-4fa6-a79f-003263374118","price_dollars":"0.5600","delta_fp":"-7.00","side":"yes","ts":"2026-05-14T22:08:38.193667Z","ts_ms":1778796518193}}

{"type":"orderbook_delta","sid":1,"seq":738,"msg":{"market_ticker":"KXBTC15M-26MAY141815-15","market_id":"9b5194ce-fa5b-4fa6-a79f-003263374118","price_dollars":"0.6100","delta_fp":"2.00","side":"yes","ts":"2026-05-14T22:08:38.215032Z","ts_ms":1778796518215}}

{"type":"orderbook_delta","sid":1,"seq":739,"msg":{"market_ticker":"KXBTC15M-26MAY141815-15","market_id":"9b5194ce-fa5b-4fa6-a79f-003263374118","price_dollars":"0.6800","delta_fp":"-15.00","side":"yes","ts":"2026-05-14T22:08:38.218937Z","ts_ms":1778796518218}}

{"type":"orderbook_delta","sid":1,"seq":740,"msg":{"market_ticker":"KXBTC15M-26MAY141815-15","market_id":"9b5194ce-fa5b-4fa6-a79f-003263374118","price_dollars":"0.6800","delta_fp":"-75.00","side":"yes","ts":"2026-05-14T22:08:38.222152Z","ts_ms":1778796518222}}

{"type":"orderbook_delta","sid":1,"seq":741,"msg":{"market_ticker":"KXBTC15M-26MAY141815-15","market_id":"9b5194ce-fa5b-4fa6-a79f-003263374118","price_dollars":"0.6200","delta_fp":"75.00","side":"yes","ts":"2026-05-14T22:08:38.222152Z","ts_ms":1778796518222}}

{"type":"orderbook_delta","sid":1,"seq":742,"msg":{"market_ticker":"KXBTC15M-26MAY141815-15","market_id":"9b5194ce-fa5b-4fa6-a79f-003263374118","price_dollars":"0.3100","delta_fp":"-99.88","side":"no","ts":"2026-05-14T22:08:38.246473Z","ts_ms":1778796518246}}

{"type":"orderbook_delta","sid":1,"seq":743,"msg":{"market_ticker":"KXBTC15M-26MAY141815-15","market_id":"9b5194ce-fa5b-4fa6-a79f-003263374118","price_dollars":"0.3000","delta_fp":"-2.00","side":"no","ts":"2026-05-14T22:08:38.246473Z","ts_ms":1778796518246}}

{"type":"orderbook_delta","sid":1,"seq":744,"msg":{"market_ticker":"KXBTC15M-26MAY141815-15","market_id":"9b5194ce-fa5b-4fa6-a79f-003263374118","price_dollars":"0.3000","delta_fp":"-5.87","side":"no","ts":"2026-05-14T22:08:38.246473Z","ts_ms":1778796518246}}

{"type":"orderbook_delta","sid":1,"seq":745,"msg":{"market_ticker":"KXBTC15M-26MAY141815-15","market_id":"9b5194ce-fa5b-4fa6-a79f-003263374118","price_dollars":"0.2600","delta_fp":"-10.00","side":"no","ts":"2026-05-14T22:08:38.259434Z","ts_ms":1778796518259}}

{"type":"orderbook_delta","sid":1,"seq":746,"msg":{"market_ticker":"KXBTC15M-26MAY141815-15","market_id":"9b5194ce-fa5b-4fa6-a79f-003263374118","price_dollars":"0.2700","delta_fp":"10.00","side":"no","ts":"2026-05-14T22:08:38.259434Z","ts_ms":1778796518259}}

{"type":"orderbook_delta","sid":1,"seq":747,"msg":{"market_ticker":"KXBTC15M-26MAY141815-15","market_id":"9b5194ce-fa5b-4fa6-a79f-003263374118","price_dollars":"0.6200","delta_fp":"-251.00","side":"yes","ts":"2026-05-14T22:08:38.261489Z","ts_ms":1778796518261}}

{"type":"orderbook_delta","sid":1,"seq":748,"msg":{"market_ticker":"KXBTC15M-26MAY141815-15","market_id":"9b5194ce-fa5b-4fa6-a79f-003263374118","price_dollars":"0.6100","delta_fp":"-2.00","side":"yes","ts":"2026-05-14T22:08:38.274886Z","ts_ms":1778796518274}}

{"type":"orderbook_delta","sid":1,"seq":749,"msg":{"market_ticker":"KXBTC15M-26MAY141815-15","market_id":"9b5194ce-fa5b-4fa6-a79f-003263374118","price_dollars":"0.2400","delta_fp":"-75.00","side":"no","ts":"2026-05-14T22:08:38.295864Z","ts_ms":1778796518295}}

{"type":"orderbook_delta","sid":1,"seq":750,"msg":{"market_ticker":"KXBTC15M-26MAY141815-15","market_id":"9b5194ce-fa5b-4fa6-a79f-003263374118","price_dollars":"0.3000","delta_fp":"75.00","side":"no","ts":"2026-05-14T22:08:38.295864Z","ts_ms":1778796518295}}

