{"market":"0x2a903c589141bce4a1e50fb98b73397af6820942542793ab10b1df477e912b6e", "asset_id":"68919878716222388542639225642064847629616106443780159680232863841946753372582", "bids":[{"price":"0.01", "size":"11345.74"}, {"price":"0.02", "size":"1437.32"}, {"price":"0.03", "size":"1105.78"}, {"price":"0.04", "size":"637.82"}, {"price":"0.05", "size":"755.72"}, {"price":"0.06", "size":"378.24"}, {"price":"0.07", "size":"357.1"}, {"price":"0.08", "size":"674.73"}, {"price":"0.09", "size":"286.11"}, {"price":"0.1", "size":"830.33"}, {"price":"0.11", "size":"13.23"}], "asks":[{"price":"0.99", "size":"12076.51"}, {"price":"0.98", "size":"1219.45"}, {"price":"0.97", "size":"1111.98"}, {"price":"0.96", "size":"670.05"}, {"price":"0.95", "size":"549.45"}, {"price":"0.94", "size":"346.2"}, {"price":"0.93", "size":"902.05"}, {"price":"0.92", "size":"170.79"}, {"price":"0.91", "size":"234.6"}, {"price":"0.9", "size":"128"}, {"price":"0.89", "size":"142.6"}, {"price":"0.88", "size":"141.8"}, {"price":"0.87", "size":"144.81"}, {"price":"0.86", "size":"204.9"}, {"price":"0.85", "size":"113.5"}, {"price":"0.84", "size":"102.3"}, {"price":"0.83", "size":"101.3"}, {"price":"0.82", "size":"105.3"}, {"price":"0.81", "size":"199.5"}, {"price":"0.8", "size":"103.8"}, {"price":"0.79", "size":"98.1"}, {"price":"0.78", "size":"97.5"}, {"price":"0.77", "size":"96.89"}, {"price":"0.76", "size":"201.39"}, {"price":"0.75", "size":"116"}, {"price":"0.74", "size":"100.6"}, {"price":"0.73", "size":"95.2"}, {"price":"0.72", "size":"94.9"}, {"price":"0.71", "size":"199.6"}, {"price":"0.7", "size":"94.3"}, {"price":"0.69", "size":"108.28"}, {"price":"0.68", "size":"98.8"}, {"price":"0.67", "size":"718.6"}, {"price":"0.66", "size":"798.4"}, {"price":"0.65", "size":"107.3"}, {"price":"0.64", "size":"293"}, {"price":"0.63", "size":"292.9"}, {"price":"0.62", "size":"897.7"}, {"price":"0.61", "size":"397.6"}, {"price":"0.6", "size":"356.93"}, {"price":"0.59", "size":"297.4"}, {"price":"0.58", "size":"109.6"}, {"price":"0.57", "size":"131.48"}, {"price":"0.56", "size":"413.97"}, {"price":"0.55", "size":"934.2"}, {"price":"0.54", "size":"375.6"}, {"price":"0.53", "size":"292"}, {"price":"0.52", "size":"297.12"}, {"price":"0.51", "size":"402"}, {"price":"0.5", "size":"340.91"}, {"price":"0.49", "size":"362"}, {"price":"0.48", "size":"317"}, {"price":"0.47", "size":"337"}, {"price":"0.46", "size":"607.1"}, {"price":"0.45", "size":"346.64"}, {"price":"0.44", "size":"332.45"}, {"price":"0.43", "size":"434.89"}, {"price":"0.42", "size":"324.36"}, {"price":"0.41", "size":"412.4"}, {"price":"0.4", "size":"328.83"}, {"price":"0.39", "size":"297.6"}, {"price":"0.38", "size":"626.5"}, {"price":"0.37", "size":"297.9"}, {"price":"0.36", "size":"208"}, {"price":"0.35", "size":"345.14"}, {"price":"0.34", "size":"360.9"}, {"price":"0.33", "size":"343.6"}, {"price":"0.32", "size":"2055.88"}, {"price":"0.31", "size":"439"}, {"price":"0.3", "size":"134.3"}, {"price":"0.29", "size":"316.38"}, {"price":"0.28", "size":"154.9"}, {"price":"0.27", "size":"180.2"}, {"price":"0.26", "size":"230.6"}, {"price":"0.25", "size":"331"}, {"price":"0.24", "size":"126.39"}, {"price":"0.23", "size":"121.89"}, {"price":"0.22", "size":"117.5"}, {"price":"0.21", "size":"175.44"}, {"price":"0.2", "size":"90"}, {"price":"0.19", "size":"72.35"}, {"price":"0.18", "size":"437.54"}], "hash":"50555f6e1ea24e89513e50b79efaabaa96106be6", "timestamp":"1778784199660", "event_type":"book"}
{"market":"0x2a903c589141bce4a1e50fb98b73397af6820942542793ab10b1df477e912b6e", "price_changes":[{"asset_id":"68919878716222388542639225642064847629616106443780159680232863841946753372582", "price":"0.1", "size":"837.33", "side":"BUY", "hash":"9b49f0e98f7ff168c5d22d9cdcf7fac306e01994", "best_bid":"0.11", "best_ask":"0.18"}, {"asset_id":"20436996072316278452977393149218961565084965483366669504673105646378938504388", "price":"0.9", "size":"837.33", "side":"SELL", "hash":"dbee3f313f2b878f80fbbbd03fdb38be2c89799a", "best_bid":"0.82", "best_ask":"0.89"}], "timestamp":"1778784199670", "event_type":"price_change"}
{"market":"0x2a903c589141bce4a1e50fb98b73397af6820942542793ab10b1df477e912b6e", "price_changes":[{"asset_id":"68919878716222388542639225642064847629616106443780159680232863841946753372582", "price":"0.13", "size":"8", "side":"BUY", "hash":"cd35ab88beb93d15d970882f89b3fda60feede75", "best_bid":"0.13", "best_ask":"0.18"}, {"asset_id":"20436996072316278452977393149218961565084965483366669504673105646378938504388", "price":"0.87", "size":"8", "side":"SELL", "hash":"5c49c0c20a00944f61d62859c9316ac95f3edf4c", "best_bid":"0.82", "best_ask":"0.87"}], "timestamp":"1778784199678", "event_type":"price_change"}
{"market":"0x2a903c589141bce4a1e50fb98b73397af6820942542793ab10b1df477e912b6e", "price_changes":[{"asset_id":"68919878716222388542639225642064847629616106443780159680232863841946753372582", "price":"0.13", "size":"4.55", "side":"BUY", "hash":"2df7005c93ad114d7fd9187912ee7b2a13d9087c", "best_bid":"0.13", "best_ask":"0.18"}, {"asset_id":"20436996072316278452977393149218961565084965483366669504673105646378938504388", "price":"0.87", "size":"4.55", "side":"SELL", "hash":"b570c98c2be70df633f2fe18f63b1a44de33136c", "best_bid":"0.82", "best_ask":"0.87"}], "timestamp":"1778784199686", "event_type":"price_change"}
{"market":"0x2a903c589141bce4a1e50fb98b73397af6820942542793ab10b1df477e912b6e", "asset_id":"68919878716222388542639225642064847629616106443780159680232863841946753372582", "bids":[{"price":"0.01", "size":"11345.74"}, {"price":"0.02", "size":"1437.32"}, {"price":"0.03", "size":"1105.78"}, {"price":"0.04", "size":"637.82"}, {"price":"0.05", "size":"755.72"}, {"price":"0.06", "size":"378.24"}, {"price":"0.07", "size":"357.1"}, {"price":"0.08", "size":"674.73"}, {"price":"0.09", "size":"286.11"}, {"price":"0.1", "size":"837.33"}, {"price":"0.11", "size":"13.23"}, {"price":"0.13", "size":"4.55"}], "asks":[{"price":"0.99", "size":"12076.51"}, {"price":"0.98", "size":"1219.45"}, {"price":"0.97", "size":"1111.98"}, {"price":"0.96", "size":"670.05"}, {"price":"0.95", "size":"549.45"}, {"price":"0.94", "size":"346.2"}, {"price":"0.93", "size":"902.05"}, {"price":"0.92", "size":"170.79"}, {"price":"0.91", "size":"234.6"}, {"price":"0.9", "size":"128"}, {"price":"0.89", "size":"142.6"}, {"price":"0.88", "size":"141.8"}, {"price":"0.87", "size":"144.81"}, {"price":"0.86", "size":"204.9"}, {"price":"0.85", "size":"113.5"}, {"price":"0.84", "size":"102.3"}, {"price":"0.83", "size":"101.3"}, {"price":"0.82", "size":"105.3"}, {"price":"0.81", "size":"199.5"}, {"price":"0.8", "size":"103.8"}, {"price":"0.79", "size":"98.1"}, {"price":"0.78", "size":"97.5"}, {"price":"0.77", "size":"96.89"}, {"price":"0.76", "size":"201.39"}, {"price":"0.75", "size":"116"}, {"price":"0.74", "size":"100.6"}, {"price":"0.73", "size":"95.2"}, {"price":"0.72", "size":"94.9"}, {"price":"0.71", "size":"199.6"}, {"price":"0.7", "size":"94.3"}, {"price":"0.69", "size":"108.28"}, {"price":"0.68", "size":"98.8"}, {"price":"0.67", "size":"718.6"}, {"price":"0.66", "size":"798.4"}, {"price":"0.65", "size":"107.3"}, {"price":"0.64", "size":"293"}, {"price":"0.63", "size":"292.9"}, {"price":"0.62", "size":"897.7"}, {"price":"0.61", "size":"397.6"}, {"price":"0.6", "size":"356.93"}, {"price":"0.59", "size":"297.4"}, {"price":"0.58", "size":"109.6"}, {"price":"0.57", "size":"131.48"}, {"price":"0.56", "size":"413.97"}, {"price":"0.55", "size":"934.2"}, {"price":"0.54", "size":"375.6"}, {"price":"0.53", "size":"292"}, {"price":"0.52", "size":"297.12"}, {"price":"0.51", "size":"402"}, {"price":"0.5", "size":"340.91"}, {"price":"0.49", "size":"362"}, {"price":"0.48", "size":"317"}, {"price":"0.47", "size":"337"}, {"price":"0.46", "size":"607.1"}, {"price":"0.45", "size":"346.64"}, {"price":"0.44", "size":"332.45"}, {"price":"0.43", "size":"434.89"}, {"price":"0.42", "size":"324.36"}, {"price":"0.41", "size":"412.4"}, {"price":"0.4", "size":"328.83"}, {"price":"0.39", "size":"297.6"}, {"price":"0.38", "size":"626.5"}, {"price":"0.37", "size":"297.9"}, {"price":"0.36", "size":"208"}, {"price":"0.35", "size":"345.14"}, {"price":"0.34", "size":"360.9"}, {"price":"0.33", "size":"343.6"}, {"price":"0.32", "size":"2055.88"}, {"price":"0.31", "size":"439"}, {"price":"0.3", "size":"134.3"}, {"price":"0.29", "size":"316.38"}, {"price":"0.28", "size":"154.9"}, {"price":"0.27", "size":"180.2"}, {"price":"0.26", "size":"230.6"}, {"price":"0.25", "size":"331"}, {"price":"0.24", "size":"126.39"}, {"price":"0.23", "size":"121.89"}, {"price":"0.22", "size":"117.5"}, {"price":"0.21", "size":"175.44"}, {"price":"0.2", "size":"90"}, {"price":"0.19", "size":"72.35"}, {"price":"0.18", "size":"437.54"}], "hash":"2df7005c93ad114d7fd9187912ee7b2a13d9087c", "timestamp":"1778784199686", "event_type":"book"}
{"market":"0x2a903c589141bce4a1e50fb98b73397af6820942542793ab10b1df477e912b6e", "price_changes":[{"asset_id":"20436996072316278452977393149218961565084965483366669504673105646378938504388", "price":"0.8", "size":"120", "side":"BUY", "hash":"9b69d57b790b7d4878cb97ddb0f083dc102ae2f8", "best_bid":"0.82", "best_ask":"0.87"}, {"asset_id":"68919878716222388542639225642064847629616106443780159680232863841946753372582", "price":"0.2", "size":"120", "side":"SELL", "hash":"8fb50b60d56a54f70b97576aa3a17718697da4ea", "best_bid":"0.13", "best_ask":"0.18"}], "timestamp":"1778784199701", "event_type":"price_change"}
{"market":"0x2a903c589141bce4a1e50fb98b73397af6820942542793ab10b1df477e912b6e", "price_changes":[{"asset_id":"68919878716222388542639225642064847629616106443780159680232863841946753372582", "price":"0.08", "size":"749.73", "side":"BUY", "hash":"d6b623a1efdf6db468528fdb80cad5bf474b723d", "best_bid":"0.13", "best_ask":"0.18"}, {"asset_id":"20436996072316278452977393149218961565084965483366669504673105646378938504388", "price":"0.92", "size":"749.73", "side":"SELL", "hash":"76a2f01348762362aca53d5521a50e8a3804a2f1", "best_bid":"0.82", "best_ask":"0.87"}], "timestamp":"1778784199703", "event_type":"price_change"}
{"market":"0x2a903c589141bce4a1e50fb98b73397af6820942542793ab10b1df477e912b6e", "price_changes":[{"asset_id":"68919878716222388542639225642064847629616106443780159680232863841946753372582", "price":"0.11", "size":"18.23", "side":"BUY", "hash":"ad4d7707f2e2de0e7de39b8b503af2a0cce40278", "best_bid":"0.13", "best_ask":"0.18"}, {"asset_id":"20436996072316278452977393149218961565084965483366669504673105646378938504388", "price":"0.89", "size":"18.23", "side":"SELL", "hash":"44c0d9313560ca8141b192541c6010eaeac836fe", "best_bid":"0.82", "best_ask":"0.87"}], "timestamp":"1778784199704", "event_type":"price_change"}
{"market":"0x2a903c589141bce4a1e50fb98b73397af6820942542793ab10b1df477e912b6e", "price_changes":[{"asset_id":"20436996072316278452977393149218961565084965483366669504673105646378938504388", "price":"0.72", "size":"159.9", "side":"BUY", "hash":"bc3b14f4e501740d55a64e0d7ebc707049594f6e", "best_bid":"0.82", "best_ask":"0.87"}, {"asset_id":"68919878716222388542639225642064847629616106443780159680232863841946753372582", "price":"0.28", "size":"159.9", "side":"SELL", "hash":"94f00c497909d213f6a05fefa80bfa57ba9583c8", "best_bid":"0.13", "best_ask":"0.18"}], "timestamp":"1778784199705", "event_type":"price_change"}
{"market":"0x2a903c589141bce4a1e50fb98b73397af6820942542793ab10b1df477e912b6e", "price_changes":[{"asset_id":"20436996072316278452977393149218961565084965483366669504673105646378938504388", "price":"0.58", "size":"724.36", "side":"BUY", "hash":"ce1da77d25dbf33d0bffbe9af774e99f4dd2d47b", "best_bid":"0.82", "best_ask":"0.87"}, {"asset_id":"68919878716222388542639225642064847629616106443780159680232863841946753372582", "price":"0.42", "size":"724.36", "side":"SELL", "hash":"59a268cc77a3d58626cc1076bbfc91dec71935a0", "best_bid":"0.13", "best_ask":"0.18"}], "timestamp":"1778784199706", "event_type":"price_change"}
{"market":"0x2a903c589141bce4a1e50fb98b73397af6820942542793ab10b1df477e912b6e", "price_changes":[{"asset_id":"68919878716222388542639225642064847629616106443780159680232863841946753372582", "price":"0.16", "size":"69.16", "side":"SELL", "hash":"ed499cb5419214213569eb423acafaa6e7e7fb75", "best_bid":"0.13", "best_ask":"0.16"}, {"asset_id":"20436996072316278452977393149218961565084965483366669504673105646378938504388", "price":"0.84", "size":"69.16", "side":"BUY", "hash":"bbfec5ce6ba7bdc204bba63b2998549164bcf7a3", "best_bid":"0.84", "best_ask":"0.87"}], "timestamp":"1778784199708", "event_type":"price_change"}
{"market":"0x2a903c589141bce4a1e50fb98b73397af6820942542793ab10b1df477e912b6e", "price_changes":[{"asset_id":"20436996072316278452977393149218961565084965483366669504673105646378938504388", "price":"0.82", "size":"432.54", "side":"BUY", "hash":"e927c7ad55d4e9cce3d45d9e5d20b3df1bb38ac4", "best_bid":"0.84", "best_ask":"0.87"}, {"asset_id":"68919878716222388542639225642064847629616106443780159680232863841946753372582", "price":"0.18", "size":"432.54", "side":"SELL", "hash":"6cc2cccdb11df373c89bcf806b22d257dc430ed3", "best_bid":"0.13", "best_ask":"0.16"}], "timestamp":"1778784199709", "event_type":"price_change"}
{"market":"0x2a903c589141bce4a1e50fb98b73397af6820942542793ab10b1df477e912b6e", "price_changes":[{"asset_id":"68919878716222388542639225642064847629616106443780159680232863841946753372582", "price":"0.11", "size":"17.78", "side":"BUY", "hash":"af6c8b1a306db8e3a72d996f3abc71d7af31cdcc", "best_bid":"0.11", "best_ask":"0.16"}, {"asset_id":"20436996072316278452977393149218961565084965483366669504673105646378938504388", "price":"0.89", "size":"17.78", "side":"SELL", "hash":"d2f2047c345e6bc9c12a00671e801ad5cccfdfe0", "best_bid":"0.84", "best_ask":"0.89"}], "timestamp":"1778784199713", "event_type":"price_change"}
{"market":"0x2a903c589141bce4a1e50fb98b73397af6820942542793ab10b1df477e912b6e", "price_changes":[{"asset_id":"68919878716222388542639225642064847629616106443780159680232863841946753372582", "price":"0.13", "size":"0", "side":"BUY", "hash":"af6c8b1a306db8e3a72d996f3abc71d7af31cdcc", "best_bid":"0.11", "best_ask":"0.16"}, {"asset_id":"20436996072316278452977393149218961565084965483366669504673105646378938504388", "price":"0.87", "size":"0", "side":"SELL", "hash":"d2f2047c345e6bc9c12a00671e801ad5cccfdfe0", "best_bid":"0.84", "best_ask":"0.89"}], "timestamp":"1778784199713", "event_type":"price_change"}
{"market":"0x2a903c589141bce4a1e50fb98b73397af6820942542793ab10b1df477e912b6e", "asset_id":"68919878716222388542639225642064847629616106443780159680232863841946753372582", "bids":[{"price":"0.01", "size":"11345.74"}, {"price":"0.02", "size":"1437.32"}, {"price":"0.03", "size":"1105.78"}, {"price":"0.04", "size":"637.82"}, {"price":"0.05", "size":"755.72"}, {"price":"0.06", "size":"378.24"}, {"price":"0.07", "size":"357.1"}, {"price":"0.08", "size":"749.73"}, {"price":"0.09", "size":"286.11"}, {"price":"0.1", "size":"837.33"}, {"price":"0.11", "size":"17.78"}], "asks":[{"price":"0.99", "size":"12076.51"}, {"price":"0.98", "size":"1219.45"}, {"price":"0.97", "size":"1111.98"}, {"price":"0.96", "size":"670.05"}, {"price":"0.95", "size":"549.45"}, {"price":"0.94", "size":"346.2"}, {"price":"0.93", "size":"902.05"}, {"price":"0.92", "size":"170.79"}, {"price":"0.91", "size":"234.6"}, {"price":"0.9", "size":"128"}, {"price":"0.89", "size":"142.6"}, {"price":"0.88", "size":"141.8"}, {"price":"0.87", "size":"144.81"}, {"price":"0.86", "size":"204.9"}, {"price":"0.85", "size":"113.5"}, {"price":"0.84", "size":"102.3"}, {"price":"0.83", "size":"101.3"}, {"price":"0.82", "size":"105.3"}, {"price":"0.81", "size":"199.5"}, {"price":"0.8", "size":"103.8"}, {"price":"0.79", "size":"98.1"}, {"price":"0.78", "size":"97.5"}, {"price":"0.77", "size":"96.89"}, {"price":"0.76", "size":"201.39"}, {"price":"0.75", "size":"116"}, {"price":"0.74", "size":"100.6"}, {"price":"0.73", "size":"95.2"}, {"price":"0.72", "size":"94.9"}, {"price":"0.71", "size":"199.6"}, {"price":"0.7", "size":"94.3"}, {"price":"0.69", "size":"108.28"}, {"price":"0.68", "size":"98.8"}, {"price":"0.67", "size":"718.6"}, {"price":"0.66", "size":"798.4"}, {"price":"0.65", "size":"107.3"}, {"price":"0.64", "size":"293"}, {"price":"0.63", "size":"292.9"}, {"price":"0.62", "size":"897.7"}, {"price":"0.61", "size":"397.6"}, {"price":"0.6", "size":"356.93"}, {"price":"0.59", "size":"297.4"}, {"price":"0.58", "size":"109.6"}, {"price":"0.57", "size":"131.48"}, {"price":"0.56", "size":"413.97"}, {"price":"0.55", "size":"934.2"}, {"price":"0.54", "size":"375.6"}, {"price":"0.53", "size":"292"}, {"price":"0.52", "size":"297.12"}, {"price":"0.51", "size":"402"}, {"price":"0.5", "size":"340.91"}, {"price":"0.49", "size":"362"}, {"price":"0.48", "size":"317"}, {"price":"0.47", "size":"337"}, {"price":"0.46", "size":"607.1"}, {"price":"0.45", "size":"346.64"}, {"price":"0.44", "size":"332.45"}, {"price":"0.43", "size":"434.89"}, {"price":"0.42", "size":"724.36"}, {"price":"0.41", "size":"412.4"}, {"price":"0.4", "size":"328.83"}, {"price":"0.39", "size":"297.6"}, {"price":"0.38", "size":"626.5"}, {"price":"0.37", "size":"297.9"}, {"price":"0.36", "size":"208"}, {"price":"0.35", "size":"345.14"}, {"price":"0.34", "size":"360.9"}, {"price":"0.33", "size":"343.6"}, {"price":"0.32", "size":"2055.88"}, {"price":"0.31", "size":"439"}, {"price":"0.3", "size":"134.3"}, {"price":"0.29", "size":"316.38"}, {"price":"0.28", "size":"159.9"}, {"price":"0.27", "size":"180.2"}, {"price":"0.26", "size":"230.6"}, {"price":"0.25", "size":"331"}, {"price":"0.24", "size":"126.39"}, {"price":"0.23", "size":"121.89"}, {"price":"0.22", "size":"117.5"}, {"price":"0.21", "size":"175.44"}, {"price":"0.2", "size":"120"}, {"price":"0.19", "size":"72.35"}, {"price":"0.18", "size":"432.54"}, {"price":"0.16", "size":"69.16"}], "hash":"af6c8b1a306db8e3a72d996f3abc71d7af31cdcc", "timestamp":"1778784199713", "event_type":"book"}
{"market":"0x2a903c589141bce4a1e50fb98b73397af6820942542793ab10b1df477e912b6e", "price_changes":[{"asset_id":"68919878716222388542639225642064847629616106443780159680232863841946753372582", "price":"0.12", "size":"8.8", "side":"BUY", "hash":"f6a3ddef98888da472ef45fc6d3c855a68451ea4", "best_bid":"0.12", "best_ask":"0.16"}, {"asset_id":"20436996072316278452977393149218961565084965483366669504673105646378938504388", "price":"0.88", "size":"8.8", "side":"SELL", "hash":"8d7101f6bbdd61fe2aca7210ed9cae84824e3e44", "best_bid":"0.84", "best_ask":"0.88"}], "timestamp":"1778784199721", "event_type":"price_change"}
{"market":"0x2a903c589141bce4a1e50fb98b73397af6820942542793ab10b1df477e912b6e", "price_changes":[{"asset_id":"68919878716222388542639225642064847629616106443780159680232863841946753372582", "price":"0.01", "size":"11340.74", "side":"BUY", "hash":"c9e9640ede03b20d618c4ad1418cfde9f83b2868", "best_bid":"0.12", "best_ask":"0.16"}, {"asset_id":"20436996072316278452977393149218961565084965483366669504673105646378938504388", "price":"0.99", "size":"11340.74", "side":"SELL", "hash":"5b084535554065c54a0c134d7246ba74f3f823fa", "best_bid":"0.84", "best_ask":"0.88"}], "timestamp":"1778784199725", "event_type":"price_change"}
{"market":"0x2a903c589141bce4a1e50fb98b73397af6820942542793ab10b1df477e912b6e", "price_changes":[{"asset_id":"20436996072316278452977393149218961565084965483366669504673105646378938504388", "price":"0.34", "size":"898.4", "side":"BUY", "hash":"d638c20ce577b7ecebc45cc2dd4812be42e7b246", "best_bid":"0.84", "best_ask":"0.88"}, {"asset_id":"68919878716222388542639225642064847629616106443780159680232863841946753372582", "price":"0.66", "size":"898.4", "side":"SELL", "hash":"5858622e251a11a3df36c70ae2ff3bc9a3481dc4", "best_bid":"0.12", "best_ask":"0.16"}], "timestamp":"1778784199725", "event_type":"price_change"}
{"market":"0x2a903c589141bce4a1e50fb98b73397af6820942542793ab10b1df477e912b6e", "price_changes":[{"asset_id":"20436996072316278452977393149218961565084965483366669504673105646378938504388", "price":"0.89", "size":"37.78", "side":"SELL", "hash":"736697061171de0bf01852955160342bade7fe1d", "best_bid":"0.84", "best_ask":"0.88"}, {"asset_id":"68919878716222388542639225642064847629616106443780159680232863841946753372582", "price":"0.11", "size":"37.78", "side":"BUY", "hash":"55123a4a0ec1ced6e05bfece5b028c2900ac0726", "best_bid":"0.12", "best_ask":"0.16"}], "timestamp":"1778784199726", "event_type":"price_change"}
{"market":"0x2a903c589141bce4a1e50fb98b73397af6820942542793ab10b1df477e912b6e", "price_changes":[{"asset_id":"20436996072316278452977393149218961565084965483366669504673105646378938504388", "price":"0.73", "size":"160.2", "side":"BUY", "hash":"691986374d3d48e185652246da28adbabaec4255", "best_bid":"0.84", "best_ask":"0.88"}, {"asset_id":"68919878716222388542639225642064847629616106443780159680232863841946753372582", "price":"0.27", "size":"160.2", "side":"SELL", "hash":"4cdd7c1a09e6a6eb3162e871a69ee2aca703d378", "best_bid":"0.12", "best_ask":"0.16"}], "timestamp":"1778784199727", "event_type":"price_change"}
{"market":"0x2a903c589141bce4a1e50fb98b73397af6820942542793ab10b1df477e912b6e", "price_changes":[{"asset_id":"68919878716222388542639225642064847629616106443780159680232863841946753372582", "price":"0.11", "size":"174.78", "side":"BUY", "hash":"b216b6c6a9a5d4641b4da035095cd1f67effb991", "best_bid":"0.12", "best_ask":"0.16"}, {"asset_id":"20436996072316278452977393149218961565084965483366669504673105646378938504388", "price":"0.89", "size":"174.78", "side":"SELL", "hash":"472b0f5ee65f48d04d959eebae443573a73d79ee", "best_bid":"0.84", "best_ask":"0.88"}], "timestamp":"1778784199728", "event_type":"price_change"}
{"market":"0x2a903c589141bce4a1e50fb98b73397af6820942542793ab10b1df477e912b6e", "price_changes":[{"asset_id":"68919878716222388542639225642064847629616106443780159680232863841946753372582", "price":"0.01", "size":"11345.74", "side":"BUY", "hash":"2a61fd096cef3b865a3d894b003d547a7b6f401d", "best_bid":"0.12", "best_ask":"0.16"}, {"asset_id":"20436996072316278452977393149218961565084965483366669504673105646378938504388", "price":"0.99", "size":"11345.74", "side":"SELL", "hash":"40d4d39d9644271054e0cf8efea0c8c5b6cb2700", "best_bid":"0.84", "best_ask":"0.88"}], "timestamp":"1778784199730", "event_type":"price_change"}
{"market":"0x2a903c589141bce4a1e50fb98b73397af6820942542793ab10b1df477e912b6e", "price_changes":[{"asset_id":"68919878716222388542639225642064847629616106443780159680232863841946753372582", "price":"0.09", "size":"298.11", "side":"BUY", "hash":"70105b6162a9520f41263acdae3e62836718bdca", "best_bid":"0.12", "best_ask":"0.16"}, {"asset_id":"20436996072316278452977393149218961565084965483366669504673105646378938504388", "price":"0.91", "size":"298.11", "side":"SELL", "hash":"39361ebc673c3124cd620f1280870fdcdc1407ec", "best_bid":"0.84", "best_ask":"0.88"}], "timestamp":"1778784199731", "event_type":"price_change"}
{"market":"0x2a903c589141bce4a1e50fb98b73397af6820942542793ab10b1df477e912b6e", "price_changes":[{"asset_id":"68919878716222388542639225642064847629616106443780159680232863841946753372582", "price":"0.11", "size":"179.78", "side":"BUY", "hash":"3293dc69bf454aa92cb6eeba16008c50b0b443c7", "best_bid":"0.12", "best_ask":"0.16"}, {"asset_id":"20436996072316278452977393149218961565084965483366669504673105646378938504388", "price":"0.89", "size":"179.78", "side":"SELL", "hash":"bfa143b947fb0c37e98e1f6cfac52474214deca0", "best_bid":"0.84", "best_ask":"0.88"}], "timestamp":"1778784199732", "event_type":"price_change"}
{"market":"0x2a903c589141bce4a1e50fb98b73397af6820942542793ab10b1df477e912b6e", "price_changes":[{"asset_id":"68919878716222388542639225642064847629616106443780159680232863841946753372582", "price":"0.11", "size":"148.03", "side":"BUY", "hash":"c2415d0d53665cfa12a0c4aadd7fda520cd03b17", "best_bid":"0.11", "best_ask":"0.16"}, {"asset_id":"20436996072316278452977393149218961565084965483366669504673105646378938504388", "price":"0.89", "size":"148.03", "side":"SELL", "hash":"63250195f7002b67dcbe7c7786f579890349234c", "best_bid":"0.84", "best_ask":"0.89"}], "timestamp":"1778784199739", "event_type":"price_change"}
{"market":"0x2a903c589141bce4a1e50fb98b73397af6820942542793ab10b1df477e912b6e", "price_changes":[{"asset_id":"68919878716222388542639225642064847629616106443780159680232863841946753372582", "price":"0.12", "size":"0", "side":"BUY", "hash":"c2415d0d53665cfa12a0c4aadd7fda520cd03b17", "best_bid":"0.11", "best_ask":"0.16"}, {"asset_id":"20436996072316278452977393149218961565084965483366669504673105646378938504388", "price":"0.88", "size":"0", "side":"SELL", "hash":"63250195f7002b67dcbe7c7786f579890349234c", "best_bid":"0.84", "best_ask":"0.89"}], "timestamp":"1778784199739", "event_type":"price_change"}
{"market":"0x2a903c589141bce4a1e50fb98b73397af6820942542793ab10b1df477e912b6e", "asset_id":"68919878716222388542639225642064847629616106443780159680232863841946753372582", "bids":[{"price":"0.01", "size":"11345.74"}, {"price":"0.02", "size":"1437.32"}, {"price":"0.03", "size":"1105.78"}, {"price":"0.04", "size":"637.82"}, {"price":"0.05", "size":"755.72"}, {"price":"0.06", "size":"378.24"}, {"price":"0.07", "size":"357.1"}, {"price":"0.08", "size":"749.73"}, {"price":"0.09", "size":"298.11"}, {"price":"0.1", "size":"837.33"}, {"price":"0.11", "size":"148.03"}], "asks":[{"price":"0.99", "size":"12076.51"}, {"price":"0.98", "size":"1219.45"}, {"price":"0.97", "size":"1111.98"}, {"price":"0.96", "size":"670.05"}, {"price":"0.95", "size":"549.45"}, {"price":"0.94", "size":"346.2"}, {"price":"0.93", "size":"902.05"}, {"price":"0.92", "size":"170.79"}, {"price":"0.91", "size":"234.6"}, {"price":"0.9", "size":"128"}, {"price":"0.89", "size":"142.6"}, {"price":"0.88", "size":"141.8"}, {"price":"0.87", "size":"144.81"}, {"price":"0.86", "size":"204.9"}, {"price":"0.85", "size":"113.5"}, {"price":"0.84", "size":"102.3"}, {"price":"0.83", "size":"101.3"}, {"price":"0.82", "size":"105.3"}, {"price":"0.81", "size":"199.5"}, {"price":"0.8", "size":"103.8"}, {"price":"0.79", "size":"98.1"}, {"price":"0.78", "size":"97.5"}, {"price":"0.77", "size":"96.89"}, {"price":"0.76", "size":"201.39"}, {"price":"0.75", "size":"116"}, {"price":"0.74", "size":"100.6"}, {"price":"0.73", "size":"95.2"}, {"price":"0.72", "size":"94.9"}, {"price":"0.71", "size":"199.6"}, {"price":"0.7", "size":"94.3"}, {"price":"0.69", "size":"108.28"}, {"price":"0.68", "size":"98.8"}, {"price":"0.67", "size":"718.6"}, {"price":"0.66", "size":"898.4"}, {"price":"0.65", "size":"107.3"}, {"price":"0.64", "size":"293"}, {"price":"0.63", "size":"292.9"}, {"price":"0.62", "size":"897.7"}, {"price":"0.61", "size":"397.6"}, {"price":"0.6", "size":"356.93"}, {"price":"0.59", "size":"297.4"}, {"price":"0.58", "size":"109.6"}, {"price":"0.57", "size":"131.48"}, {"price":"0.56", "size":"413.97"}, {"price":"0.55", "size":"934.2"}, {"price":"0.54", "size":"375.6"}, {"price":"0.53", "size":"292"}, {"price":"0.52", "size":"297.12"}, {"price":"0.51", "size":"402"}, {"price":"0.5", "size":"340.91"}, {"price":"0.49", "size":"362"}, {"price":"0.48", "size":"317"}, {"price":"0.47", "size":"337"}, {"price":"0.46", "size":"607.1"}, {"price":"0.45", "size":"346.64"}, {"price":"0.44", "size":"332.45"}, {"price":"0.43", "size":"434.89"}, {"price":"0.42", "size":"724.36"}, {"price":"0.41", "size":"412.4"}, {"price":"0.4", "size":"328.83"}, {"price":"0.39", "size":"297.6"}, {"price":"0.38", "size":"626.5"}, {"price":"0.37", "size":"297.9"}, {"price":"0.36", "size":"208"}, {"price":"0.35", "size":"345.14"}, {"price":"0.34", "size":"360.9"}, {"price":"0.33", "size":"343.6"}, {"price":"0.32", "size":"2055.88"}, {"price":"0.31", "size":"439"}, {"price":"0.3", "size":"134.3"}, {"price":"0.29", "size":"316.38"}, {"price":"0.28", "size":"159.9"}, {"price":"0.27", "size":"160.2"}, {"price":"0.26", "size":"230.6"}, {"price":"0.25", "size":"331"}, {"price":"0.24", "size":"126.39"}, {"price":"0.23", "size":"121.89"}, {"price":"0.22", "size":"117.5"}, {"price":"0.21", "size":"175.44"}, {"price":"0.2", "size":"120"}, {"price":"0.19", "size":"72.35"}, {"price":"0.18", "size":"432.54"}, {"price":"0.16", "size":"69.16"}], "hash":"c2415d0d53665cfa12a0c4aadd7fda520cd03b17", "timestamp":"1778784199739", "event_type":"book"}
{"market":"0x2a903c589141bce4a1e50fb98b73397af6820942542793ab10b1df477e912b6e", "price_changes":[{"asset_id":"68919878716222388542639225642064847629616106443780159680232863841946753372582", "price":"0.11", "size":"142.41", "side":"BUY", "hash":"4faf179726cf689b41a37b3cb6a63f68599f62fc", "best_bid":"0.11", "best_ask":"0.16"}, {"asset_id":"20436996072316278452977393149218961565084965483366669504673105646378938504388", "price":"0.89", "size":"142.41", "side":"SELL", "hash":"b81b5d47a7d53e1ff3e706d398a3fc349ed22999", "best_bid":"0.84", "best_ask":"0.89"}], "timestamp":"1778784199749", "event_type":"price_change"}
{"market":"0x2a903c589141bce4a1e50fb98b73397af6820942542793ab10b1df477e912b6e", "asset_id":"68919878716222388542639225642064847629616106443780159680232863841946753372582", "bids":[{"price":"0.01", "size":"11345.74"}, {"price":"0.02", "size":"1437.32"}, {"price":"0.03", "size":"1105.78"}, {"price":"0.04", "size":"637.82"}, {"price":"0.05", "size":"755.72"}, {"price":"0.06", "size":"378.24"}, {"price":"0.07", "size":"357.1"}, {"price":"0.08", "size":"749.73"}, {"price":"0.09", "size":"298.11"}, {"price":"0.1", "size":"837.33"}, {"price":"0.11", "size":"142.41"}], "asks":[{"price":"0.99", "size":"12076.51"}, {"price":"0.98", "size":"1219.45"}, {"price":"0.97", "size":"1111.98"}, {"price":"0.96", "size":"670.05"}, {"price":"0.95", "size":"549.45"}, {"price":"0.94", "size":"346.2"}, {"price":"0.93", "size":"902.05"}, {"price":"0.92", "size":"170.79"}, {"price":"0.91", "size":"234.6"}, {"price":"0.9", "size":"128"}, {"price":"0.89", "size":"142.6"}, {"price":"0.88", "size":"141.8"}, {"price":"0.87", "size":"144.81"}, {"price":"0.86", "size":"204.9"}, {"price":"0.85", "size":"113.5"}, {"price":"0.84", "size":"102.3"}, {"price":"0.83", "size":"101.3"}, {"price":"0.82", "size":"105.3"}, {"price":"0.81", "size":"199.5"}, {"price":"0.8", "size":"103.8"}, {"price":"0.79", "size":"98.1"}, {"price":"0.78", "size":"97.5"}, {"price":"0.77", "size":"96.89"}, {"price":"0.76", "size":"201.39"}, {"price":"0.75", "size":"116"}, {"price":"0.74", "size":"100.6"}, {"price":"0.73", "size":"95.2"}, {"price":"0.72", "size":"94.9"}, {"price":"0.71", "size":"199.6"}, {"price":"0.7", "size":"94.3"}, {"price":"0.69", "size":"108.28"}, {"price":"0.68", "size":"98.8"}, {"price":"0.67", "size":"718.6"}, {"price":"0.66", "size":"898.4"}, {"price":"0.65", "size":"107.3"}, {"price":"0.64", "size":"293"}, {"price":"0.63", "size":"292.9"}, {"price":"0.62", "size":"897.7"}, {"price":"0.61", "size":"397.6"}, {"price":"0.6", "size":"356.93"}, {"price":"0.59", "size":"297.4"}, {"price":"0.58", "size":"109.6"}, {"price":"0.57", "size":"131.48"}, {"price":"0.56", "size":"413.97"}, {"price":"0.55", "size":"934.2"}, {"price":"0.54", "size":"375.6"}, {"price":"0.53", "size":"292"}, {"price":"0.52", "size":"297.12"}, {"price":"0.51", "size":"402"}, {"price":"0.5", "size":"340.91"}, {"price":"0.49", "size":"362"}, {"price":"0.48", "size":"317"}, {"price":"0.47", "size":"337"}, {"price":"0.46", "size":"607.1"}, {"price":"0.45", "size":"346.64"}, {"price":"0.44", "size":"332.45"}, {"price":"0.43", "size":"434.89"}, {"price":"0.42", "size":"724.36"}, {"price":"0.41", "size":"412.4"}, {"price":"0.4", "size":"328.83"}, {"price":"0.39", "size":"297.6"}, {"price":"0.38", "size":"626.5"}, {"price":"0.37", "size":"297.9"}, {"price":"0.36", "size":"208"}, {"price":"0.35", "size":"345.14"}, {"price":"0.34", "size":"360.9"}, {"price":"0.33", "size":"343.6"}, {"price":"0.32", "size":"2055.88"}, {"price":"0.31", "size":"439"}, {"price":"0.3", "size":"134.3"}, {"price":"0.29", "size":"316.38"}, {"price":"0.28", "size":"159.9"}, {"price":"0.27", "size":"160.2"}, {"price":"0.26", "size":"230.6"}, {"price":"0.25", "size":"331"}, {"price":"0.24", "size":"126.39"}, {"price":"0.23", "size":"121.89"}, {"price":"0.22", "size":"117.5"}, {"price":"0.21", "size":"175.44"}, {"price":"0.2", "size":"120"}, {"price":"0.19", "size":"72.35"}, {"price":"0.18", "size":"432.54"}, {"price":"0.16", "size":"69.16"}], "hash":"4faf179726cf689b41a37b3cb6a63f68599f62fc", "timestamp":"1778784199749", "event_type":"book"}
{"market":"0x2a903c589141bce4a1e50fb98b73397af6820942542793ab10b1df477e912b6e", "price_changes":[{"asset_id":"68919878716222388542639225642064847629616106443780159680232863841946753372582", "price":"0.08", "size":"765.73", "side":"BUY", "hash":"28425649a513d4e782ae5e428292f95451cb0f92", "best_bid":"0.11", "best_ask":"0.16"}, {"asset_id":"20436996072316278452977393149218961565084965483366669504673105646378938504388", "price":"0.92", "size":"765.73", "side":"SELL", "hash":"fd08e1304b6604db7a8d01739b9f3051ca357c61", "best_bid":"0.84", "best_ask":"0.89"}], "timestamp":"1778784199752", "event_type":"price_change"}
{"market":"0x2a903c589141bce4a1e50fb98b73397af6820942542793ab10b1df477e912b6e", "price_changes":[{"asset_id":"20436996072316278452977393149218961565084965483366669504673105646378938504388", "price":"0.69", "size":"559", "side":"BUY", "hash":"6f6ef9daefab6a2f1f1a65309c2ae5213ef45433", "best_bid":"0.84", "best_ask":"0.89"}, {"asset_id":"68919878716222388542639225642064847629616106443780159680232863841946753372582", "price":"0.31", "size":"559", "side":"SELL", "hash":"1bea288cde64808b08f750725c0a6f3ab991d06a", "best_bid":"0.11", "best_ask":"0.16"}], "timestamp":"1778784199753", "event_type":"price_change"}
{"market":"0x2a903c589141bce4a1e50fb98b73397af6820942542793ab10b1df477e912b6e", "price_changes":[{"asset_id":"20436996072316278452977393149218961565084965483366669504673105646378938504388", "price":"0.88", "size":"25", "side":"BUY", "hash":"fae69d62e3de1af9780fabe8ec88fa51dae53a72", "best_bid":"0.88", "best_ask":"0.89"}, {"asset_id":"68919878716222388542639225642064847629616106443780159680232863841946753372582", "price":"0.12", "size":"25", "side":"SELL", "hash":"636e22213bff069b90be5f9bc91dea78dd950730", "best_bid":"0.11", "best_ask":"0.12"}], "timestamp":"1778784199754", "event_type":"price_change"}
{"market":"0x2a903c589141bce4a1e50fb98b73397af6820942542793ab10b1df477e912b6e", "price_changes":[{"asset_id":"20436996072316278452977393149218961565084965483366669504673105646378938504388", "price":"0.88", "size":"30", "side":"BUY", "hash":"bac3776df96a6516e0da6b903a87cc455d0a8f7f", "best_bid":"0.88", "best_ask":"0.89"}, {"asset_id":"68919878716222388542639225642064847629616106443780159680232863841946753372582", "price":"0.12", "size":"30", "side":"SELL", "hash":"1d93176ab1decd33006aa4224eb33635d638f087", "best_bid":"0.11", "best_ask":"0.12"}], "timestamp":"1778784199756", "event_type":"price_change"}
{"market":"0x2a903c589141bce4a1e50fb98b73397af6820942542793ab10b1df477e912b6e", "price_changes":[{"asset_id":"68919878716222388542639225642064847629616106443780159680232863841946753372582", "price":"0.13", "size":"8.1", "side":"SELL", "hash":"21177d737f6eaa4e94510eacea1706c7be17bf89", "best_bid":"0.11", "best_ask":"0.12"}, {"asset_id":"20436996072316278452977393149218961565084965483366669504673105646378938504388", "price":"0.87", "size":"8.1", "side":"BUY", "hash":"8e7e2a10a2ffefdf3927c94a5838deb22bedd329", "best_bid":"0.88", "best_ask":"0.89"}], "timestamp":"1778784199758", "event_type":"price_change"}
{"market":"0x2a903c589141bce4a1e50fb98b73397af6820942542793ab10b1df477e912b6e", "price_changes":[{"asset_id":"20436996072316278452977393149218961565084965483366669504673105646378938504388", "price":"0.88", "size":"35", "side":"BUY", "hash":"9eac43b2d9c45a9ea770df78279140c320eb4cc9", "best_bid":"0.88", "best_ask":"0.89"}, {"asset_id":"68919878716222388542639225642064847629616106443780159680232863841946753372582", "price":"0.12", "size":"35", "side":"SELL", "hash":"f3de8e597524cc59136c0046ddce3b627e950062", "best_bid":"0.11", "best_ask":"0.12"}], "timestamp":"1778784199759", "event_type":"price_change"}
{"market":"0x2a903c589141bce4a1e50fb98b73397af6820942542793ab10b1df477e912b6e", "price_changes":[{"asset_id":"20436996072316278452977393149218961565084965483366669504673105646378938504388", "price":"0.88", "size":"18.33", "side":"BUY", "hash":"9a3b3b35dea8f80384762bf278e01383c4858804", "best_bid":"0.88", "best_ask":"0.89"}, {"asset_id":"68919878716222388542639225642064847629616106443780159680232863841946753372582", "price":"0.12", "size":"18.33", "side":"SELL", "hash":"90d848dfd55632318fa2d679c5f625cef28e4484", "best_bid":"0.11", "best_ask":"0.12"}], "timestamp":"1778784199762", "event_type":"price_change"}
{"market":"0x2a903c589141bce4a1e50fb98b73397af6820942542793ab10b1df477e912b6e", "asset_id":"68919878716222388542639225642064847629616106443780159680232863841946753372582", "bids":[{"price":"0.01", "size":"11345.74"}, {"price":"0.02", "size":"1437.32"}, {"price":"0.03", "size":"1105.78"}, {"price":"0.04", "size":"637.82"}, {"price":"0.05", "size":"755.72"}, {"price":"0.06", "size":"378.24"}, {"price":"0.07", "size":"357.1"}, {"price":"0.08", "size":"765.73"}, {"price":"0.09", "size":"298.11"}, {"price":"0.1", "size":"837.33"}, {"price":"0.11", "size":"142.41"}], "asks":[{"price":"0.99", "size":"12076.51"}, {"price":"0.98", "size":"1219.45"}, {"price":"0.97", "size":"1111.98"}, {"price":"0.96", "size":"670.05"}, {"price":"0.95", "size":"549.45"}, {"price":"0.94", "size":"346.2"}, {"price":"0.93", "size":"902.05"}, {"price":"0.92", "size":"170.79"}, {"price":"0.91", "size":"234.6"}, {"price":"0.9", "size":"128"}, {"price":"0.89", "size":"142.6"}, {"price":"0.88", "size":"141.8"}, {"price":"0.87", "size":"144.81"}, {"price":"0.86", "size":"204.9"}, {"price":"0.85", "size":"113.5"}, {"price":"0.84", "size":"102.3"}, {"price":"0.83", "size":"101.3"}, {"price":"0.82", "size":"105.3"}, {"price":"0.81", "size":"199.5"}, {"price":"0.8", "size":"103.8"}, {"price":"0.79", "size":"98.1"}, {"price":"0.78", "size":"97.5"}, {"price":"0.77", "size":"96.89"}, {"price":"0.76", "size":"201.39"}, {"price":"0.75", "size":"116"}, {"price":"0.74", "size":"100.6"}, {"price":"0.73", "size":"95.2"}, {"price":"0.72", "size":"94.9"}, {"price":"0.71", "size":"199.6"}, {"price":"0.7", "size":"94.3"}, {"price":"0.69", "size":"108.28"}, {"price":"0.68", "size":"98.8"}, {"price":"0.67", "size":"718.6"}, {"price":"0.66", "size":"898.4"}, {"price":"0.65", "size":"107.3"}, {"price":"0.64", "size":"293"}, {"price":"0.63", "size":"292.9"}, {"price":"0.62", "size":"897.7"}, {"price":"0.61", "size":"397.6"}, {"price":"0.6", "size":"356.93"}, {"price":"0.59", "size":"297.4"}, {"price":"0.58", "size":"109.6"}, {"price":"0.57", "size":"131.48"}, {"price":"0.56", "size":"413.97"}, {"price":"0.55", "size":"934.2"}, {"price":"0.54", "size":"375.6"}, {"price":"0.53", "size":"292"}, {"price":"0.52", "size":"297.12"}, {"price":"0.51", "size":"402"}, {"price":"0.5", "size":"340.91"}, {"price":"0.49", "size":"362"}, {"price":"0.48", "size":"317"}, {"price":"0.47", "size":"337"}, {"price":"0.46", "size":"607.1"}, {"price":"0.45", "size":"346.64"}, {"price":"0.44", "size":"332.45"}, {"price":"0.43", "size":"434.89"}, {"price":"0.42", "size":"724.36"}, {"price":"0.41", "size":"412.4"}, {"price":"0.4", "size":"328.83"}, {"price":"0.39", "size":"297.6"}, {"price":"0.38", "size":"626.5"}, {"price":"0.37", "size":"297.9"}, {"price":"0.36", "size":"208"}, {"price":"0.35", "size":"345.14"}, {"price":"0.34", "size":"360.9"}, {"price":"0.33", "size":"343.6"}, {"price":"0.32", "size":"2055.88"}, {"price":"0.31", "size":"559"}, {"price":"0.3", "size":"134.3"}, {"price":"0.29", "size":"316.38"}, {"price":"0.28", "size":"159.9"}, {"price":"0.27", "size":"160.2"}, {"price":"0.26", "size":"230.6"}, {"price":"0.25", "size":"331"}, {"price":"0.24", "size":"126.39"}, {"price":"0.23", "size":"121.89"}, {"price":"0.22", "size":"117.5"}, {"price":"0.21", "size":"175.44"}, {"price":"0.2", "size":"120"}, {"price":"0.19", "size":"72.35"}, {"price":"0.18", "size":"432.54"}, {"price":"0.16", "size":"69.16"}, {"price":"0.13", "size":"8.1"}, {"price":"0.12", "size":"18.33"}], "hash":"90d848dfd55632318fa2d679c5f625cef28e4484", "timestamp":"1778784199762", "event_type":"book"}
{"market":"0x2a903c589141bce4a1e50fb98b73397af6820942542793ab10b1df477e912b6e", "price_changes":[{"asset_id":"68919878716222388542639225642064847629616106443780159680232863841946753372582", "price":"0.07", "size":"337.1", "side":"BUY", "hash":"f5c487f2aa6f309f42be2459c58da609cc60f78f", "best_bid":"0.11", "best_ask":"0.12"}, {"asset_id":"20436996072316278452977393149218961565084965483366669504673105646378938504388", "price":"0.93", "size":"337.1", "side":"SELL", "hash":"e26dfee909413e9142d8dec45d8a3f638d0f1968", "best_bid":"0.88", "best_ask":"0.89"}], "timestamp":"1778784199764", "event_type":"price_change"}
{"market":"0x2a903c589141bce4a1e50fb98b73397af6820942542793ab10b1df477e912b6e", "price_changes":[{"asset_id":"20436996072316278452977393149218961565084965483366669504673105646378938504388", "price":"0.56", "size":"337.45", "side":"BUY", "hash":"f54b0be965d4c39c41c7f2521556d88faf59ad53", "best_bid":"0.88", "best_ask":"0.89"}, {"asset_id":"68919878716222388542639225642064847629616106443780159680232863841946753372582", "price":"0.44", "size":"337.45", "side":"SELL", "hash":"f10a35f0825675ae58ca8845c13fb0527e2642e7", "best_bid":"0.11", "best_ask":"0.12"}], "timestamp":"1778784199765", "event_type":"price_change"}
{"market":"0x2a903c589141bce4a1e50fb98b73397af6820942542793ab10b1df477e912b6e", "price_changes":[{"asset_id":"20436996072316278452977393149218961565084965483366669504673105646378938504388", "price":"0.88", "size":"23.33", "side":"BUY", "hash":"24c5fc84fe3df840cb7622c1f8636c328f860f2b", "best_bid":"0.88", "best_ask":"0.89"}, {"asset_id":"68919878716222388542639225642064847629616106443780159680232863841946753372582", "price":"0.12", "size":"23.33", "side":"SELL", "hash":"6cb9c9f8edc79ed8de589cbcbb224da8ab5fcf25", "best_bid":"0.11", "best_ask":"0.12"}], "timestamp":"1778784199766", "event_type":"price_change"}
{"market":"0x2a903c589141bce4a1e50fb98b73397af6820942542793ab10b1df477e912b6e", "price_changes":[{"asset_id":"68919878716222388542639225642064847629616106443780159680232863841946753372582", "price":"0.08", "size":"690.73", "side":"BUY", "hash":"3e7fc1fed7a00948eeaffbea472baf45215bb412", "best_bid":"0.11", "best_ask":"0.12"}, {"asset_id":"20436996072316278452977393149218961565084965483366669504673105646378938504388", "price":"0.92", "size":"690.73", "side":"SELL", "hash":"a5b6234d0f91abfa98735d200ee829f2598c3573", "best_bid":"0.88", "best_ask":"0.89"}], "timestamp":"1778784199767", "event_type":"price_change"}
{"market":"0x2a903c589141bce4a1e50fb98b73397af6820942542793ab10b1df477e912b6e", "price_changes":[{"asset_id":"20436996072316278452977393149218961565084965483366669504673105646378938504388", "price":"0.88", "size":"14.33", "side":"BUY", "hash":"40460f66a3587ba5a2bd184f88659f7d49e1de8e", "best_bid":"0.88", "best_ask":"0.89"}, {"asset_id":"68919878716222388542639225642064847629616106443780159680232863841946753372582", "price":"0.12", "size":"14.33", "side":"SELL", "hash":"a812bdb6b3256a3a032d4a78377ee59df6ca89e4", "best_bid":"0.11", "best_ask":"0.12"}], "timestamp":"1778784199770", "event_type":"price_change"}
{"market":"0x2a903c589141bce4a1e50fb98b73397af6820942542793ab10b1df477e912b6e", "price_changes":[{"asset_id":"68919878716222388542639225642064847629616106443780159680232863841946753372582", "price":"0.05", "size":"1055.72", "side":"BUY", "hash":"6c1901294d1c9bd268e96709025bce606173c9b5", "best_bid":"0.11", "best_ask":"0.12"}, {"asset_id":"20436996072316278452977393149218961565084965483366669504673105646378938504388", "price":"0.95", "size":"1055.72", "side":"SELL", "hash":"71540d9062b9383626953df84a42cbb1a59395a0", "best_bid":"0.88", "best_ask":"0.89"}], "timestamp":"1778784199773", "event_type":"price_change"}
{"market":"0x2a903c589141bce4a1e50fb98b73397af6820942542793ab10b1df477e912b6e", "asset_id":"68919878716222388542639225642064847629616106443780159680232863841946753372582", "bids":[{"price":"0.01", "size":"11345.74"}, {"price":"0.02", "size":"1437.32"}, {"price":"0.03", "size":"1105.78"}, {"price":"0.04", "size":"637.82"}, {"price":"0.05", "size":"755.72"}, {"price":"0.06", "size":"378.24"}, {"price":"0.07", "size":"337.1"}, {"price":"0.08", "size":"690.73"}, {"price":"0.09", "size":"298.11"}, {"price":"0.1", "size":"837.33"}, {"price":"0.11", "size":"142.41"}], "asks":[{"price":"0.99", "size":"12076.51"}, {"price":"0.98", "size":"1219.45"}, {"price":"0.97", "size":"1111.98"}, {"price":"0.96", "size":"670.05"}, {"price":"0.95", "size":"549.45"}, {"price":"0.94", "size":"346.2"}, {"price":"0.93", "size":"902.05"}, {"price":"0.92", "size":"170.79"}, {"price":"0.91", "size":"234.6"}, {"price":"0.9", "size":"128"}, {"price":"0.89", "size":"142.6"}, {"price":"0.88", "size":"141.8"}, {"price":"0.87", "size":"144.81"}, {"price":"0.86", "size":"204.9"}, {"price":"0.85", "size":"113.5"}, {"price":"0.84", "size":"102.3"}, {"price":"0.83", "size":"101.3"}, {"price":"0.82", "size":"105.3"}, {"price":"0.81", "size":"199.5"}, {"price":"0.8", "size":"103.8"}, {"price":"0.79", "size":"98.1"}, {"price":"0.78", "size":"97.5"}, {"price":"0.77", "size":"96.89"}, {"price":"0.76", "size":"201.39"}, {"price":"0.75", "size":"116"}, {"price":"0.74", "size":"100.6"}, {"price":"0.73", "size":"95.2"}, {"price":"0.72", "size":"94.9"}, {"price":"0.71", "size":"199.6"}, {"price":"0.7", "size":"94.3"}, {"price":"0.69", "size":"108.28"}, {"price":"0.68", "size":"98.8"}, {"price":"0.67", "size":"718.6"}, {"price":"0.66", "size":"898.4"}, {"price":"0.65", "size":"107.3"}, {"price":"0.64", "size":"293"}, {"price":"0.63", "size":"292.9"}, {"price":"0.62", "size":"897.7"}, {"price":"0.61", "size":"397.6"}, {"price":"0.6", "size":"356.93"}, {"price":"0.59", "size":"297.4"}, {"price":"0.58", "size":"109.6"}, {"price":"0.57", "size":"131.48"}, {"price":"0.56", "size":"413.97"}, {"price":"0.55", "size":"934.2"}, {"price":"0.54", "size":"375.6"}, {"price":"0.53", "size":"292"}, {"price":"0.52", "size":"297.12"}, {"price":"0.51", "size":"402"}, {"price":"0.5", "size":"340.91"}, {"price":"0.49", "size":"362"}, {"price":"0.48", "size":"317"}, {"price":"0.47", "size":"337"}, {"price":"0.46", "size":"607.1"}, {"price":"0.45", "size":"346.64"}, {"price":"0.44", "size":"337.45"}, {"price":"0.43", "size":"434.89"}, {"price":"0.42", "size":"724.36"}, {"price":"0.41", "size":"412.4"}, {"price":"0.4", "size":"328.83"}, {"price":"0.39", "size":"297.6"}, {"price":"0.38", "size":"626.5"}, {"price":"0.37", "size":"297.9"}, {"price":"0.36", "size":"208"}, {"price":"0.35", "size":"345.14"}, {"price":"0.34", "size":"360.9"}, {"price":"0.33", "size":"343.6"}, {"price":"0.32", "size":"2055.88"}, {"price":"0.31", "size":"559"}, {"price":"0.3", "size":"134.3"}, {"price":"0.29", "size":"316.38"}, {"price":"0.28", "size":"159.9"}, {"price":"0.27", "size":"160.2"}, {"price":"0.26", "size":"230.6"}, {"price":"0.25", "size":"331"}, {"price":"0.24", "size":"126.39"}, {"price":"0.23", "size":"121.89"}, {"price":"0.22", "size":"117.5"}, {"price":"0.21", "size":"175.44"}, {"price":"0.2", "size":"120"}, {"price":"0.19", "size":"72.35"}, {"price":"0.18", "size":"432.54"}, {"price":"0.16", "size":"69.16"}, {"price":"0.13", "size":"8.1"}, {"price":"0.12", "size":"14.33"}], "hash":"a812bdb6b3256a3a032d4a78377ee59df6ca89e4", "timestamp":"1778784199770", "event_type":"book"}
{"market":"0x2a903c589141bce4a1e50fb98b73397af6820942542793ab10b1df477e912b6e", "asset_id":"68919878716222388542639225642064847629616106443780159680232863841946753372582", "price":"0.12", "size":"9", "fee_rate_bps":"0", "side":"BUY", "timestamp":"1778784199800", "event_type":"last_trade_price", "transaction_hash":"0x47d1da429b42b0769b0e5b99fff0a6ee94fc12db0a3b9288590622ec3ef2e4cb"}
{"market":"0x2a903c589141bce4a1e50fb98b73397af6820942542793ab10b1df477e912b6e", "asset_id":"68919878716222388542639225642064847629616106443780159680232863841946753372582", "price":"0.12", "size":"16.67", "fee_rate_bps":"0", "side":"BUY", "timestamp":"1778784199802", "event_type":"last_trade_price", "transaction_hash":"0xd107ef4bae99e09a5c121a683438ae54efaac4ca662d4bfe8c5ae2aa685954be"}
{"market":"0x2a903c589141bce4a1e50fb98b73397af6820942542793ab10b1df477e912b6e", "price_changes":[{"asset_id":"20436996072316278452977393149218961565084965483366669504673105646378938504388", "price":"0.5", "size":"345.91", "side":"BUY", "hash":"1c73ab30ed34ac5c2174db0cdffb8d2f988a12d8", "best_bid":"0.88", "best_ask":"0.89"}, {"asset_id":"68919878716222388542639225642064847629616106443780159680232863841946753372582", "price":"0.5", "size":"345.91", "side":"SELL", "hash":"a6ba91fe68db63ec2ac614ece676c49889334d6d", "best_bid":"0.11", "best_ask":"0.12"}], "timestamp":"1778784199774", "event_type":"price_change"}
{"market":"0x2a903c589141bce4a1e50fb98b73397af6820942542793ab10b1df477e912b6e", "price_changes":[{"asset_id":"20436996072316278452977393149218961565084965483366669504673105646378938504388", "price":"0.35", "size":"207.3", "side":"BUY", "hash":"9358cdb42030f18b0cf997e08137d50a12aedd86", "best_bid":"0.88", "best_ask":"0.89"}, {"asset_id":"68919878716222388542639225642064847629616106443780159680232863841946753372582", "price":"0.65", "size":"207.3", "side":"SELL", "hash":"eb6a52cd136a3e71c53ce8ff364de54198fe9968", "best_bid":"0.11", "best_ask":"0.12"}], "timestamp":"1778784199859", "event_type":"price_change"}
{"market":"0x2a903c589141bce4a1e50fb98b73397af6820942542793ab10b1df477e912b6e", "price_changes":[{"asset_id":"20436996072316278452977393149218961565084965483366669504673105646378938504388", "price":"0.88", "size":"19.33", "side":"BUY", "hash":"e0987beb68f3b9dadad941597d2540c6c23a6ede", "best_bid":"0.88", "best_ask":"0.89"}, {"asset_id":"68919878716222388542639225642064847629616106443780159680232863841946753372582", "price":"0.12", "size":"19.33", "side":"SELL", "hash":"6f2820e4238a2a7d9a99e9e2e987c9b7f36b9d79", "best_bid":"0.11", "best_ask":"0.12"}], "timestamp":"1778784199867", "event_type":"price_change"}
{"market":"0x2a903c589141bce4a1e50fb98b73397af6820942542793ab10b1df477e912b6e", "price_changes":[{"asset_id":"20436996072316278452977393149218961565084965483366669504673105646378938504388", "price":"0.66", "size":"365.9", "side":"BUY", "hash":"d0323447e6f65639dabdde2cef3e3dafdcb502f5", "best_bid":"0.88", "best_ask":"0.89"}, {"asset_id":"68919878716222388542639225642064847629616106443780159680232863841946753372582", "price":"0.34", "size":"365.9", "side":"SELL", "hash":"84be0053229f3a4c93591b7e5be2d34ba14a82d3", "best_bid":"0.11", "best_ask":"0.12"}], "timestamp":"1778784199871", "event_type":"price_change"}
{"market":"0x2a903c589141bce4a1e50fb98b73397af6820942542793ab10b1df477e912b6e", "price_changes":[{"asset_id":"20436996072316278452977393149218961565084965483366669504673105646378938504388", "price":"0.81", "size":"91.85", "side":"BUY", "hash":"08483467c9cbc6169229a6aa98ccef74c620fbca", "best_bid":"0.88", "best_ask":"0.89"}, {"asset_id":"68919878716222388542639225642064847629616106443780159680232863841946753372582", "price":"0.19", "size":"91.85", "side":"SELL", "hash":"e3eb611890d363fafa1b6d24d4078c36fea586c5", "best_bid":"0.11", "best_ask":"0.12"}], "timestamp":"1778784199876", "event_type":"price_change"}
{"market":"0x2a903c589141bce4a1e50fb98b73397af6820942542793ab10b1df477e912b6e", "price_changes":[{"asset_id":"20436996072316278452977393149218961565084965483366669504673105646378938504388", "price":"0.88", "size":"6.37", "side":"BUY", "hash":"279d2807eb40f9b846800449994b2672e1b00298", "best_bid":"0.88", "best_ask":"0.89"}, {"asset_id":"68919878716222388542639225642064847629616106443780159680232863841946753372582", "price":"0.12", "size":"6.37", "side":"SELL", "hash":"5cea451fc5b7ca9528af57327658a81fbf849546", "best_bid":"0.11", "best_ask":"0.12"}], "timestamp":"1778784199882", "event_type":"price_change"}
{"market":"0x2a903c589141bce4a1e50fb98b73397af6820942542793ab10b1df477e912b6e", "asset_id":"68919878716222388542639225642064847629616106443780159680232863841946753372582", "bids":[{"price":"0.01", "size":"11345.74"}, {"price":"0.02", "size":"1437.32"}, {"price":"0.03", "size":"1105.78"}, {"price":"0.04", "size":"637.82"}, {"price":"0.05", "size":"1055.72"}, {"price":"0.06", "size":"378.24"}, {"price":"0.07", "size":"337.1"}, {"price":"0.08", "size":"690.73"}, {"price":"0.09", "size":"298.11"}, {"price":"0.1", "size":"837.33"}, {"price":"0.11", "size":"142.41"}], "asks":[{"price":"0.99", "size":"12076.51"}, {"price":"0.98", "size":"1219.45"}, {"price":"0.97", "size":"1111.98"}, {"price":"0.96", "size":"670.05"}, {"price":"0.95", "size":"549.45"}, {"price":"0.94", "size":"346.2"}, {"price":"0.93", "size":"902.05"}, {"price":"0.92", "size":"170.79"}, {"price":"0.91", "size":"234.6"}, {"price":"0.9", "size":"128"}, {"price":"0.89", "size":"142.6"}, {"price":"0.88", "size":"141.8"}, {"price":"0.87", "size":"144.81"}, {"price":"0.86", "size":"204.9"}, {"price":"0.85", "size":"113.5"}, {"price":"0.84", "size":"102.3"}, {"price":"0.83", "size":"101.3"}, {"price":"0.82", "size":"105.3"}, {"price":"0.81", "size":"199.5"}, {"price":"0.8", "size":"103.8"}, {"price":"0.79", "size":"98.1"}, {"price":"0.78", "size":"97.5"}, {"price":"0.77", "size":"96.89"}, {"price":"0.76", "size":"201.39"}, {"price":"0.75", "size":"116"}, {"price":"0.74", "size":"100.6"}, {"price":"0.73", "size":"95.2"}, {"price":"0.72", "size":"94.9"}, {"price":"0.71", "size":"199.6"}, {"price":"0.7", "size":"94.3"}, {"price":"0.69", "size":"108.28"}, {"price":"0.68", "size":"98.8"}, {"price":"0.67", "size":"718.6"}, {"price":"0.66", "size":"898.4"}, {"price":"0.65", "size":"207.3"}, {"price":"0.64", "size":"293"}, {"price":"0.63", "size":"292.9"}, {"price":"0.62", "size":"897.7"}, {"price":"0.61", "size":"397.6"}, {"price":"0.6", "size":"356.93"}, {"price":"0.59", "size":"297.4"}, {"price":"0.58", "size":"109.6"}, {"price":"0.57", "size":"131.48"}, {"price":"0.56", "size":"413.97"}, {"price":"0.55", "size":"934.2"}, {"price":"0.54", "size":"375.6"}, {"price":"0.53", "size":"292"}, {"price":"0.52", "size":"297.12"}, {"price":"0.51", "size":"402"}, {"price":"0.5", "size":"345.91"}, {"price":"0.49", "size":"362"}, {"price":"0.48", "size":"317"}, {"price":"0.47", "size":"337"}, {"price":"0.46", "size":"607.1"}, {"price":"0.45", "size":"346.64"}, {"price":"0.44", "size":"337.45"}, {"price":"0.43", "size":"434.89"}, {"price":"0.42", "size":"724.36"}, {"price":"0.41", "size":"412.4"}, {"price":"0.4", "size":"328.83"}, {"price":"0.39", "size":"297.6"}, {"price":"0.38", "size":"626.5"}, {"price":"0.37", "size":"297.9"}, {"price":"0.36", "size":"208"}, {"price":"0.35", "size":"345.14"}, {"price":"0.34", "size":"365.9"}, {"price":"0.33", "size":"343.6"}, {"price":"0.32", "size":"2055.88"}, {"price":"0.31", "size":"559"}, {"price":"0.3", "size":"134.3"}, {"price":"0.29", "size":"316.38"}, {"price":"0.28", "size":"159.9"}, {"price":"0.27", "size":"160.2"}, {"price":"0.26", "size":"230.6"}, {"price":"0.25", "size":"331"}, {"price":"0.24", "size":"126.39"}, {"price":"0.23", "size":"121.89"}, {"price":"0.22", "size":"117.5"}, {"price":"0.21", "size":"175.44"}, {"price":"0.2", "size":"120"}, {"price":"0.19", "size":"91.85"}, {"price":"0.18", "size":"432.54"}, {"price":"0.16", "size":"69.16"}, {"price":"0.13", "size":"8.1"}, {"price":"0.12", "size":"6.37"}], "hash":"5cea451fc5b7ca9528af57327658a81fbf849546", "timestamp":"1778784199882", "event_type":"book"}
{"market":"0x2a903c589141bce4a1e50fb98b73397af6820942542793ab10b1df477e912b6e", "price_changes":[{"asset_id":"68919878716222388542639225642064847629616106443780159680232863841946753372582", "price":"0.11", "size":"162.41", "side":"BUY", "hash":"f473d042cb99344efe0bd2fbca78ae4dda975d01", "best_bid":"0.11", "best_ask":"0.12"}, {"asset_id":"20436996072316278452977393149218961565084965483366669504673105646378938504388", "price":"0.89", "size":"162.41", "side":"SELL", "hash":"f090c72bf8e5e1a746404a45ce5b60cb6631c377", "best_bid":"0.88", "best_ask":"0.89"}], "timestamp":"1778784199887", "event_type":"price_change"}
{"market":"0x2a903c589141bce4a1e50fb98b73397af6820942542793ab10b1df477e912b6e", "price_changes":[{"asset_id":"68919878716222388542639225642064847629616106443780159680232863841946753372582", "price":"0.11", "size":"157.41", "side":"BUY", "hash":"2d67cd851bb31988bb18edc035e598d0b4eca26d", "best_bid":"0.11", "best_ask":"0.12"}, {"asset_id":"20436996072316278452977393149218961565084965483366669504673105646378938504388", "price":"0.89", "size":"157.41", "side":"SELL", "hash":"9bce7f0f5f27eabca53ab9618642dd359c0db68c", "best_bid":"0.88", "best_ask":"0.89"}], "timestamp":"1778784199891", "event_type":"price_change"}
{"market":"0x2a903c589141bce4a1e50fb98b73397af6820942542793ab10b1df477e912b6e", "asset_id":"68919878716222388542639225642064847629616106443780159680232863841946753372582", "bids":[{"price":"0.01", "size":"11345.74"}, {"price":"0.02", "size":"1437.32"}, {"price":"0.03", "size":"1105.78"}, {"price":"0.04", "size":"637.82"}, {"price":"0.05", "size":"1055.72"}, {"price":"0.06", "size":"378.24"}, {"price":"0.07", "size":"337.1"}, {"price":"0.08", "size":"690.73"}, {"price":"0.09", "size":"298.11"}, {"price":"0.1", "size":"837.33"}, {"price":"0.11", "size":"157.41"}], "asks":[{"price":"0.99", "size":"12076.51"}, {"price":"0.98", "size":"1219.45"}, {"price":"0.97", "size":"1111.98"}, {"price":"0.96", "size":"670.05"}, {"price":"0.95", "size":"549.45"}, {"price":"0.94", "size":"346.2"}, {"price":"0.93", "size":"902.05"}, {"price":"0.92", "size":"170.79"}, {"price":"0.91", "size":"234.6"}, {"price":"0.9", "size":"128"}, {"price":"0.89", "size":"142.6"}, {"price":"0.88", "size":"141.8"}, {"price":"0.87", "size":"144.81"}, {"price":"0.86", "size":"204.9"}, {"price":"0.85", "size":"113.5"}, {"price":"0.84", "size":"102.3"}, {"price":"0.83", "size":"101.3"}, {"price":"0.82", "size":"105.3"}, {"price":"0.81", "size":"199.5"}, {"price":"0.8", "size":"103.8"}, {"price":"0.79", "size":"98.1"}, {"price":"0.78", "size":"97.5"}, {"price":"0.77", "size":"96.89"}, {"price":"0.76", "size":"201.39"}, {"price":"0.75", "size":"116"}, {"price":"0.74", "size":"100.6"}, {"price":"0.73", "size":"95.2"}, {"price":"0.72", "size":"94.9"}, {"price":"0.71", "size":"199.6"}, {"price":"0.7", "size":"94.3"}, {"price":"0.69", "size":"108.28"}, {"price":"0.68", "size":"98.8"}, {"price":"0.67", "size":"718.6"}, {"price":"0.66", "size":"898.4"}, {"price":"0.65", "size":"207.3"}, {"price":"0.64", "size":"293"}, {"price":"0.63", "size":"292.9"}, {"price":"0.62", "size":"897.7"}, {"price":"0.61", "size":"397.6"}, {"price":"0.6", "size":"356.93"}, {"price":"0.59", "size":"297.4"}, {"price":"0.58", "size":"109.6"}, {"price":"0.57", "size":"131.48"}, {"price":"0.56", "size":"413.97"}, {"price":"0.55", "size":"934.2"}, {"price":"0.54", "size":"375.6"}, {"price":"0.53", "size":"292"}, {"price":"0.52", "size":"297.12"}, {"price":"0.51", "size":"402"}, {"price":"0.5", "size":"345.91"}, {"price":"0.49", "size":"362"}, {"price":"0.48", "size":"317"}, {"price":"0.47", "size":"337"}, {"price":"0.46", "size":"607.1"}, {"price":"0.45", "size":"346.64"}, {"price":"0.44", "size":"337.45"}, {"price":"0.43", "size":"434.89"}, {"price":"0.42", "size":"724.36"}, {"price":"0.41", "size":"412.4"}, {"price":"0.4", "size":"328.83"}, {"price":"0.39", "size":"297.6"}, {"price":"0.38", "size":"626.5"}, {"price":"0.37", "size":"297.9"}, {"price":"0.36", "size":"208"}, {"price":"0.35", "size":"345.14"}, {"price":"0.34", "size":"365.9"}, {"price":"0.33", "size":"343.6"}, {"price":"0.32", "size":"2055.88"}, {"price":"0.31", "size":"559"}, {"price":"0.3", "size":"134.3"}, {"price":"0.29", "size":"316.38"}, {"price":"0.28", "size":"159.9"}, {"price":"0.27", "size":"160.2"}, {"price":"0.26", "size":"230.6"}, {"price":"0.25", "size":"331"}, {"price":"0.24", "size":"126.39"}, {"price":"0.23", "size":"121.89"}, {"price":"0.22", "size":"117.5"}, {"price":"0.21", "size":"175.44"}, {"price":"0.2", "size":"120"}, {"price":"0.19", "size":"91.85"}, {"price":"0.18", "size":"432.54"}, {"price":"0.16", "size":"69.16"}, {"price":"0.13", "size":"8.1"}, {"price":"0.12", "size":"6.37"}], "hash":"2d67cd851bb31988bb18edc035e598d0b4eca26d", "timestamp":"1778784199891", "event_type":"book"}
{"market":"0x2a903c589141bce4a1e50fb98b73397af6820942542793ab10b1df477e912b6e", "price_changes":[{"asset_id":"20436996072316278452977393149218961565084965483366669504673105646378938504388", "price":"0.48", "size":"292.12", "side":"BUY", "hash":"4a290a2479495397d1fb1507e1fbc3009d3a389b", "best_bid":"0.88", "best_ask":"0.89"}, {"asset_id":"68919878716222388542639225642064847629616106443780159680232863841946753372582", "price":"0.52", "size":"292.12", "side":"SELL", "hash":"4aa39f3ec2974edaf4b7c791d4936957bc096317", "best_bid":"0.11", "best_ask":"0.12"}], "timestamp":"1778784199894", "event_type":"price_change"}
{"market":"0x2a903c589141bce4a1e50fb98b73397af6820942542793ab10b1df477e912b6e", "price_changes":[{"asset_id":"68919878716222388542639225642064847629616106443780159680232863841946753372582", "price":"0.13", "size":"52.69", "side":"BUY", "hash":"8d6f0cb9893950dbb5460ef6d69041c2d764443f", "best_bid":"0.13", "best_ask":"0.16"}, {"asset_id":"20436996072316278452977393149218961565084965483366669504673105646378938504388", "price":"0.87", "size":"52.69", "side":"SELL", "hash":"8e7cd57b2066639ecbc279244d0a588dbe9101a2", "best_bid":"0.84", "best_ask":"0.87"}], "timestamp":"1778784199903", "event_type":"price_change"}
{"market":"0x2a903c589141bce4a1e50fb98b73397af6820942542793ab10b1df477e912b6e", "price_changes":[{"asset_id":"20436996072316278452977393149218961565084965483366669504673105646378938504388", "price":"0.88", "size":"0", "side":"BUY", "hash":"8e7cd57b2066639ecbc279244d0a588dbe9101a2", "best_bid":"0.84", "best_ask":"0.87"}, {"asset_id":"68919878716222388542639225642064847629616106443780159680232863841946753372582", "price":"0.12", "size":"0", "side":"SELL", "hash":"8d6f0cb9893950dbb5460ef6d69041c2d764443f", "best_bid":"0.13", "best_ask":"0.16"}], "timestamp":"1778784199903", "event_type":"price_change"}
{"market":"0x2a903c589141bce4a1e50fb98b73397af6820942542793ab10b1df477e912b6e", "asset_id":"68919878716222388542639225642064847629616106443780159680232863841946753372582", "bids":[{"price":"0.01", "size":"11345.74"}, {"price":"0.02", "size":"1437.32"}, {"price":"0.03", "size":"1105.78"}, {"price":"0.04", "size":"637.82"}, {"price":"0.05", "size":"1055.72"}, {"price":"0.06", "size":"378.24"}, {"price":"0.07", "size":"337.1"}, {"price":"0.08", "size":"690.73"}, {"price":"0.09", "size":"298.11"}, {"price":"0.1", "size":"837.33"}, {"price":"0.11", "size":"157.41"}, {"price":"0.13", "size":"52.69"}], "asks":[{"price":"0.99", "size":"12076.51"}, {"price":"0.98", "size":"1219.45"}, {"price":"0.97", "size":"1111.98"}, {"price":"0.96", "size":"670.05"}, {"price":"0.95", "size":"549.45"}, {"price":"0.94", "size":"346.2"}, {"price":"0.93", "size":"902.05"}, {"price":"0.92", "size":"170.79"}, {"price":"0.91", "size":"234.6"}, {"price":"0.9", "size":"128"}, {"price":"0.89", "size":"142.6"}, {"price":"0.88", "size":"141.8"}, {"price":"0.87", "size":"144.81"}, {"price":"0.86", "size":"204.9"}, {"price":"0.85", "size":"113.5"}, {"price":"0.84", "size":"102.3"}, {"price":"0.83", "size":"101.3"}, {"price":"0.82", "size":"105.3"}, {"price":"0.81", "size":"199.5"}, {"price":"0.8", "size":"103.8"}, {"price":"0.79", "size":"98.1"}, {"price":"0.78", "size":"97.5"}, {"price":"0.77", "size":"96.89"}, {"price":"0.76", "size":"201.39"}, {"price":"0.75", "size":"116"}, {"price":"0.74", "size":"100.6"}, {"price":"0.73", "size":"95.2"}, {"price":"0.72", "size":"94.9"}, {"price":"0.71", "size":"199.6"}, {"price":"0.7", "size":"94.3"}, {"price":"0.69", "size":"108.28"}, {"price":"0.68", "size":"98.8"}, {"price":"0.67", "size":"718.6"}, {"price":"0.66", "size":"898.4"}, {"price":"0.65", "size":"207.3"}, {"price":"0.64", "size":"293"}, {"price":"0.63", "size":"292.9"}, {"price":"0.62", "size":"897.7"}, {"price":"0.61", "size":"397.6"}, {"price":"0.6", "size":"356.93"}, {"price":"0.59", "size":"297.4"}, {"price":"0.58", "size":"109.6"}, {"price":"0.57", "size":"131.48"}, {"price":"0.56", "size":"413.97"}, {"price":"0.55", "size":"934.2"}, {"price":"0.54", "size":"375.6"}, {"price":"0.53", "size":"292"}, {"price":"0.52", "size":"292.12"}, {"price":"0.51", "size":"402"}, {"price":"0.5", "size":"345.91"}, {"price":"0.49", "size":"362"}, {"price":"0.48", "size":"317"}, {"price":"0.47", "size":"337"}, {"price":"0.46", "size":"607.1"}, {"price":"0.45", "size":"346.64"}, {"price":"0.44", "size":"337.45"}, {"price":"0.43", "size":"434.89"}, {"price":"0.42", "size":"724.36"}, {"price":"0.41", "size":"412.4"}, {"price":"0.4", "size":"328.83"}, {"price":"0.39", "size":"297.6"}, {"price":"0.38", "size":"626.5"}, {"price":"0.37", "size":"297.9"}, {"price":"0.36", "size":"208"}, {"price":"0.35", "size":"345.14"}, {"price":"0.34", "size":"365.9"}, {"price":"0.33", "size":"343.6"}, {"price":"0.32", "size":"2055.88"}, {"price":"0.31", "size":"559"}, {"price":"0.3", "size":"134.3"}, {"price":"0.29", "size":"316.38"}, {"price":"0.28", "size":"159.9"}, {"price":"0.27", "size":"160.2"}, {"price":"0.26", "size":"230.6"}, {"price":"0.25", "size":"331"}, {"price":"0.24", "size":"126.39"}, {"price":"0.23", "size":"121.89"}, {"price":"0.22", "size":"117.5"}, {"price":"0.21", "size":"175.44"}, {"price":"0.2", "size":"120"}, {"price":"0.19", "size":"91.85"}, {"price":"0.18", "size":"432.54"}, {"price":"0.16", "size":"69.16"}], "hash":"8d6f0cb9893950dbb5460ef6d69041c2d764443f", "timestamp":"1778784199903", "event_type":"book"}
{"market":"0x2a903c589141bce4a1e50fb98b73397af6820942542793ab10b1df477e912b6e", "asset_id":"68919878716222388542639225642064847629616106443780159680232863841946753372582", "price":"0.12", "size":"12.96", "fee_rate_bps":"0", "side":"BUY", "timestamp":"1778784199906", "event_type":"last_trade_price", "transaction_hash":"0xfec3000352d0af0104d5370372ff7e0be493d90f9f95837d6c9e53fbbe5e6c2d"}
{"market":"0x2a903c589141bce4a1e50fb98b73397af6820942542793ab10b1df477e912b6e", "price_changes":[{"asset_id":"68919878716222388542639225642064847629616106443780159680232863841946753372582", "price":"0.13", "size":"152.69", "side":"BUY", "hash":"7009ef85128ecfd36d40684e989d7a3b632a1330", "best_bid":"0.13", "best_ask":"0.16"}, {"asset_id":"20436996072316278452977393149218961565084965483366669504673105646378938504388", "price":"0.87", "size":"152.69", "side":"SELL", "hash":"d5879b155b266f8f32d1bccd1c035cc2277b4313", "best_bid":"0.84", "best_ask":"0.87"}], "timestamp":"1778784199908", "event_type":"price_change"}
{"market":"0x2a903c589141bce4a1e50fb98b73397af6820942542793ab10b1df477e912b6e", "price_changes":[{"asset_id":"68919878716222388542639225642064847629616106443780159680232863841946753372582", "price":"0.13", "size":"302.69", "side":"BUY", "hash":"da94eb562d1ff360aa1936212628fa053ba2ab81", "best_bid":"0.13", "best_ask":"0.16"}, {"asset_id":"20436996072316278452977393149218961565084965483366669504673105646378938504388", "price":"0.87", "size":"302.69", "side":"SELL", "hash":"ef3685958279c598b977fb02fffc51a1752446e2", "best_bid":"0.84", "best_ask":"0.87"}], "timestamp":"1778784199910", "event_type":"price_change"}
{"market":"0x2a903c589141bce4a1e50fb98b73397af6820942542793ab10b1df477e912b6e", "price_changes":[{"asset_id":"20436996072316278452977393149218961565084965483366669504673105646378938504388", "price":"0.01", "size":"12081.51", "side":"BUY", "hash":"320f08eb8a085cf7e282f68cdd09b6c4e42828eb", "best_bid":"0.84", "best_ask":"0.87"}, {"asset_id":"68919878716222388542639225642064847629616106443780159680232863841946753372582", "price":"0.99", "size":"12081.51", "side":"SELL", "hash":"cd48a65245241691e4de4707481030573006501c", "best_bid":"0.13", "best_ask":"0.16"}], "timestamp":"1778784199912", "event_type":"price_change"}
{"market":"0x2a903c589141bce4a1e50fb98b73397af6820942542793ab10b1df477e912b6e", "price_changes":[{"asset_id":"20436996072316278452977393149218961565084965483366669504673105646378938504388", "price":"0.01", "size":"12086.51", "side":"BUY", "hash":"437dd9135453d942280f4633bf3a2747283a75db", "best_bid":"0.84", "best_ask":"0.87"}, {"asset_id":"68919878716222388542639225642064847629616106443780159680232863841946753372582", "price":"0.99", "size":"12086.51", "side":"SELL", "hash":"dfb07c731d544a4465bd0617bf56f16eeb48f65b", "best_bid":"0.13", "best_ask":"0.16"}], "timestamp":"1778784199915", "event_type":"price_change"}
{"market":"0x2a903c589141bce4a1e50fb98b73397af6820942542793ab10b1df477e912b6e", "price_changes":[{"asset_id":"68919878716222388542639225642064847629616106443780159680232863841946753372582", "price":"0.06", "size":"337.72", "side":"BUY", "hash":"0d3c40a1e671b9df6c8c4c8e69d9cd96107a3866", "best_bid":"0.13", "best_ask":"0.16"}, {"asset_id":"20436996072316278452977393149218961565084965483366669504673105646378938504388", "price":"0.94", "size":"337.72", "side":"SELL", "hash":"2cee2d03926d31075fabbc96f452d639951f4eab", "best_bid":"0.84", "best_ask":"0.87"}], "timestamp":"1778784199917", "event_type":"price_change"}
{"market":"0x2a903c589141bce4a1e50fb98b73397af6820942542793ab10b1df477e912b6e", "price_changes":[{"asset_id":"20436996072316278452977393149218961565084965483366669504673105646378938504388", "price":"0.01", "size":"12091.51", "side":"BUY", "hash":"8be2b3642d8097f29465074c0e31f2691930d3bc", "best_bid":"0.84", "best_ask":"0.87"}, {"asset_id":"68919878716222388542639225642064847629616106443780159680232863841946753372582", "price":"0.99", "size":"12091.51", "side":"SELL", "hash":"8231f09ce8500fa828bac17c40a0fa1ceb135e3e", "best_bid":"0.13", "best_ask":"0.16"}], "timestamp":"1778784199918", "event_type":"price_change"}
{"market":"0x2a903c589141bce4a1e50fb98b73397af6820942542793ab10b1df477e912b6e", "price_changes":[{"asset_id":"20436996072316278452977393149218961565084965483366669504673105646378938504388", "price":"0.01", "size":"12096.51", "side":"BUY", "hash":"2d230cf5bf010455a315195efe1fa42fe40f5583", "best_bid":"0.84", "best_ask":"0.87"}, {"asset_id":"68919878716222388542639225642064847629616106443780159680232863841946753372582", "price":"0.99", "size":"12096.51", "side":"SELL", "hash":"03961df78bb7c236e260aebc72a5a1f26eb948a2", "best_bid":"0.13", "best_ask":"0.16"}], "timestamp":"1778784199920", "event_type":"price_change"}
{"market":"0x2a903c589141bce4a1e50fb98b73397af6820942542793ab10b1df477e912b6e", "price_changes":[{"asset_id":"68919878716222388542639225642064847629616106443780159680232863841946753372582", "price":"0.1", "size":"826.83", "side":"BUY", "hash":"ed9cae3c5548eeae7a0a6fcdcd16e12dd97ac81d", "best_bid":"0.13", "best_ask":"0.16"}, {"asset_id":"20436996072316278452977393149218961565084965483366669504673105646378938504388", "price":"0.9", "size":"826.83", "side":"SELL", "hash":"d82aef729a2a5875a56de8d31e31d7bff6b66369", "best_bid":"0.84", "best_ask":"0.87"}], "timestamp":"1778784199922", "event_type":"price_change"}
{"market":"0x2a903c589141bce4a1e50fb98b73397af6820942542793ab10b1df477e912b6e", "price_changes":[{"asset_id":"68919878716222388542639225642064847629616106443780159680232863841946753372582", "price":"0.1", "size":"836.83", "side":"BUY", "hash":"2b0e738bf9b89805045510dfd452014e993deecb", "best_bid":"0.13", "best_ask":"0.16"}, {"asset_id":"20436996072316278452977393149218961565084965483366669504673105646378938504388", "price":"0.9", "size":"836.83", "side":"SELL", "hash":"32144573c38ea37ed850af24bf32ba53b57bca2b", "best_bid":"0.84", "best_ask":"0.87"}], "timestamp":"1778784199924", "event_type":"price_change"}
{"market":"0x2a903c589141bce4a1e50fb98b73397af6820942542793ab10b1df477e912b6e", "price_changes":[{"asset_id":"20436996072316278452977393149218961565084965483366669504673105646378938504388", "price":"0.75", "size":"356", "side":"BUY", "hash":"e54892b07b611424b94d4c964ead230bf96ba9ae", "best_bid":"0.84", "best_ask":"0.87"}, {"asset_id":"68919878716222388542639225642064847629616106443780159680232863841946753372582", "price":"0.25", "size":"356", "side":"SELL", "hash":"d82811cade34f3c8a6ec72bda7485fd27a300a59", "best_bid":"0.13", "best_ask":"0.16"}], "timestamp":"1778784199928", "event_type":"price_change"}
{"market":"0x2a903c589141bce4a1e50fb98b73397af6820942542793ab10b1df477e912b6e", "asset_id":"68919878716222388542639225642064847629616106443780159680232863841946753372582", "price":"0.13", "size":"14.47", "fee_rate_bps":"0", "side":"BUY", "timestamp":"1778784199930", "event_type":"last_trade_price", "transaction_hash":"0xab3118baf8e2b66a55eb80b1318a9fad3dae3dcd2c52c53c022ae2fc202782b4"}
{"market":"0x2a903c589141bce4a1e50fb98b73397af6820942542793ab10b1df477e912b6e", "price_changes":[{"asset_id":"20436996072316278452977393149218961565084965483366669504673105646378938504388", "price":"0.01", "size":"12101.51", "side":"BUY", "hash":"2c4f1265eb01648d1536f6619ccb84838b4bc80b", "best_bid":"0.84", "best_ask":"0.87"}, {"asset_id":"68919878716222388542639225642064847629616106443780159680232863841946753372582", "price":"0.99", "size":"12101.51", "side":"SELL", "hash":"3e9294c7eae773e550d8048d13574fe390a19677", "best_bid":"0.13", "best_ask":"0.16"}], "timestamp":"1778784199930", "event_type":"price_change"}
{"market":"0x2a903c589141bce4a1e50fb98b73397af6820942542793ab10b1df477e912b6e", "price_changes":[{"asset_id":"68919878716222388542639225642064847629616106443780159680232863841946753372582", "price":"0.13", "size":"301.54", "side":"BUY", "hash":"32516b555da4f206526e3e77605d289c3886dc22", "best_bid":"0.13", "best_ask":"0.16"}, {"asset_id":"20436996072316278452977393149218961565084965483366669504673105646378938504388", "price":"0.87", "size":"301.54", "side":"SELL", "hash":"1e656a38072bb961a4cce7c113c73a3c9b640dec", "best_bid":"0.84", "best_ask":"0.87"}], "timestamp":"1778784199947", "event_type":"price_change"}
{"market":"0x2a903c589141bce4a1e50fb98b73397af6820942542793ab10b1df477e912b6e", "asset_id":"68919878716222388542639225642064847629616106443780159680232863841946753372582", "bids":[{"price":"0.01", "size":"11345.74"}, {"price":"0.02", "size":"1437.32"}, {"price":"0.03", "size":"1105.78"}, {"price":"0.04", "size":"637.82"}, {"price":"0.05", "size":"1055.72"}, {"price":"0.06", "size":"337.72"}, {"price":"0.07", "size":"337.1"}, {"price":"0.08", "size":"690.73"}, {"price":"0.09", "size":"298.11"}, {"price":"0.1", "size":"836.83"}, {"price":"0.11", "size":"157.41"}, {"price":"0.13", "size":"301.54"}], "asks":[{"price":"0.99", "size":"12101.51"}, {"price":"0.98", "size":"1219.45"}, {"price":"0.97", "size":"1111.98"}, {"price":"0.96", "size":"670.05"}, {"price":"0.95", "size":"549.45"}, {"price":"0.94", "size":"346.2"}, {"price":"0.93", "size":"902.05"}, {"price":"0.92", "size":"170.79"}, {"price":"0.91", "size":"234.6"}, {"price":"0.9", "size":"128"}, {"price":"0.89", "size":"142.6"}, {"price":"0.88", "size":"141.8"}, {"price":"0.87", "size":"144.81"}, {"price":"0.86", "size":"204.9"}, {"price":"0.85", "size":"113.5"}, {"price":"0.84", "size":"102.3"}, {"price":"0.83", "size":"101.3"}, {"price":"0.82", "size":"105.3"}, {"price":"0.81", "size":"199.5"}, {"price":"0.8", "size":"103.8"}, {"price":"0.79", "size":"98.1"}, {"price":"0.78", "size":"97.5"}, {"price":"0.77", "size":"96.89"}, {"price":"0.76", "size":"201.39"}, {"price":"0.75", "size":"116"}, {"price":"0.74", "size":"100.6"}, {"price":"0.73", "size":"95.2"}, {"price":"0.72", "size":"94.9"}, {"price":"0.71", "size":"199.6"}, {"price":"0.7", "size":"94.3"}, {"price":"0.69", "size":"108.28"}, {"price":"0.68", "size":"98.8"}, {"price":"0.67", "size":"718.6"}, {"price":"0.66", "size":"898.4"}, {"price":"0.65", "size":"207.3"}, {"price":"0.64", "size":"293"}, {"price":"0.63", "size":"292.9"}, {"price":"0.62", "size":"897.7"}, {"price":"0.61", "size":"397.6"}, {"price":"0.6", "size":"356.93"}, {"price":"0.59", "size":"297.4"}, {"price":"0.58", "size":"109.6"}, {"price":"0.57", "size":"131.48"}, {"price":"0.56", "size":"413.97"}, {"price":"0.55", "size":"934.2"}, {"price":"0.54", "size":"375.6"}, {"price":"0.53", "size":"292"}, {"price":"0.52", "size":"292.12"}, {"price":"0.51", "size":"402"}, {"price":"0.5", "size":"345.91"}, {"price":"0.49", "size":"362"}, {"price":"0.48", "size":"317"}, {"price":"0.47", "size":"337"}, {"price":"0.46", "size":"607.1"}, {"price":"0.45", "size":"346.64"}, {"price":"0.44", "size":"337.45"}, {"price":"0.43", "size":"434.89"}, {"price":"0.42", "size":"724.36"}, {"price":"0.41", "size":"412.4"}, {"price":"0.4", "size":"328.83"}, {"price":"0.39", "size":"297.6"}, {"price":"0.38", "size":"626.5"}, {"price":"0.37", "size":"297.9"}, {"price":"0.36", "size":"208"}, {"price":"0.35", "size":"345.14"}, {"price":"0.34", "size":"365.9"}, {"price":"0.33", "size":"343.6"}, {"price":"0.32", "size":"2055.88"}, {"price":"0.31", "size":"559"}, {"price":"0.3", "size":"134.3"}, {"price":"0.29", "size":"316.38"}, {"price":"0.28", "size":"159.9"}, {"price":"0.27", "size":"160.2"}, {"price":"0.26", "size":"230.6"}, {"price":"0.25", "size":"356"}, {"price":"0.24", "size":"126.39"}, {"price":"0.23", "size":"121.89"}, {"price":"0.22", "size":"117.5"}, {"price":"0.21", "size":"175.44"}, {"price":"0.2", "size":"120"}, {"price":"0.19", "size":"91.85"}, {"price":"0.18", "size":"432.54"}, {"price":"0.16", "size":"69.16"}], "hash":"32516b555da4f206526e3e77605d289c3886dc22", "timestamp":"1778784199947", "event_type":"book"}
{"market":"0x2a903c589141bce4a1e50fb98b73397af6820942542793ab10b1df477e912b6e", "price_changes":[{"asset_id":"68919878716222388542639225642064847629616106443780159680232863841946753372582", "price":"0.5", "size":"355.91", "side":"SELL", "hash":"5d7333241a0d379e908e0d7e797e3d6aefd7a57a", "best_bid":"0.13", "best_ask":"0.16"}, {"asset_id":"20436996072316278452977393149218961565084965483366669504673105646378938504388", "price":"0.5", "size":"355.91", "side":"BUY", "hash":"c8fdc5fdbfa1616df097fb96f006373f5e550ae5", "best_bid":"0.84", "best_ask":"0.87"}], "timestamp":"1778784199950", "event_type":"price_change"}
{"market":"0x2a903c589141bce4a1e50fb98b73397af6820942542793ab10b1df477e912b6e", "price_changes":[{"asset_id":"20436996072316278452977393149218961565084965483366669504673105646378938504388", "price":"0.01", "size":"12096.51", "side":"BUY", "hash":"881cbde8a37b912df118081935bd8817232dc1fa", "best_bid":"0.84", "best_ask":"0.87"}, {"asset_id":"68919878716222388542639225642064847629616106443780159680232863841946753372582", "price":"0.99", "size":"12096.51", "side":"SELL", "hash":"dc71ea2307b2b4cd29b4bfd52acc579100b66afb", "best_bid":"0.13", "best_ask":"0.16"}], "timestamp":"1778784199982", "event_type":"price_change"}
{"market":"0x2a903c589141bce4a1e50fb98b73397af6820942542793ab10b1df477e912b6e", "price_changes":[{"asset_id":"20436996072316278452977393149218961565084965483366669504673105646378938504388", "price":"0.01", "size":"12101.51", "side":"BUY", "hash":"f1e1df9af42d82a857f272c099ad638ac4a02556", "best_bid":"0.84", "best_ask":"0.87"}, {"asset_id":"68919878716222388542639225642064847629616106443780159680232863841946753372582", "price":"0.99", "size":"12101.51", "side":"SELL", "hash":"b942fd96b7d3da867dcbefcddd70d2aa45ed84f1", "best_bid":"0.13", "best_ask":"0.16"}], "timestamp":"1778784199986", "event_type":"price_change"}
{"market":"0x2a903c589141bce4a1e50fb98b73397af6820942542793ab10b1df477e912b6e", "price_changes":[{"asset_id":"68919878716222388542639225642064847629616106443780159680232863841946753372582", "price":"0.04", "size":"837.82", "side":"BUY", "hash":"04d7e7289a9a01861d99b8485b1f283113d664e8", "best_bid":"0.13", "best_ask":"0.16"}, {"asset_id":"20436996072316278452977393149218961565084965483366669504673105646378938504388", "price":"0.96", "size":"837.82", "side":"SELL", "hash":"4f0621df279fe4ea51759cbc856ec64a0f63f98e", "best_bid":"0.84", "best_ask":"0.87"}], "timestamp":"1778784199991", "event_type":"price_change"}
{"market":"0x2a903c589141bce4a1e50fb98b73397af6820942542793ab10b1df477e912b6e", "price_changes":[{"asset_id":"68919878716222388542639225642064847629616106443780159680232863841946753372582", "price":"0.13", "size":"71.65", "side":"BUY", "hash":"a2b4a8003be54b14c5ad3d26bc3cdf01bac5b7f2", "best_bid":"0.13", "best_ask":"0.16"}, {"asset_id":"20436996072316278452977393149218961565084965483366669504673105646378938504388", "price":"0.87", "size":"71.65", "side":"SELL", "hash":"8d3a84d2a8a20ea087beea0129a15ef4bd71c1ba", "best_bid":"0.84", "best_ask":"0.87"}], "timestamp":"1778784199998", "event_type":"price_change"}
{"market":"0x2a903c589141bce4a1e50fb98b73397af6820942542793ab10b1df477e912b6e", "asset_id":"68919878716222388542639225642064847629616106443780159680232863841946753372582", "bids":[{"price":"0.01", "size":"11345.74"}, {"price":"0.02", "size":"1437.32"}, {"price":"0.03", "size":"1105.78"}, {"price":"0.04", "size":"837.82"}, {"price":"0.05", "size":"1055.72"}, {"price":"0.06", "size":"337.72"}, {"price":"0.07", "size":"337.1"}, {"price":"0.08", "size":"690.73"}, {"price":"0.09", "size":"298.11"}, {"price":"0.1", "size":"836.83"}, {"price":"0.11", "size":"157.41"}, {"price":"0.13", "size":"71.65"}], "asks":[{"price":"0.99", "size":"12101.51"}, {"price":"0.98", "size":"1219.45"}, {"price":"0.97", "size":"1111.98"}, {"price":"0.96", "size":"670.05"}, {"price":"0.95", "size":"549.45"}, {"price":"0.94", "size":"346.2"}, {"price":"0.93", "size":"902.05"}, {"price":"0.92", "size":"170.79"}, {"price":"0.91", "size":"234.6"}, {"price":"0.9", "size":"128"}, {"price":"0.89", "size":"142.6"}, {"price":"0.88", "size":"141.8"}, {"price":"0.87", "size":"144.81"}, {"price":"0.86", "size":"204.9"}, {"price":"0.85", "size":"113.5"}, {"price":"0.84", "size":"102.3"}, {"price":"0.83", "size":"101.3"}, {"price":"0.82", "size":"105.3"}, {"price":"0.81", "size":"199.5"}, {"price":"0.8", "size":"103.8"}, {"price":"0.79", "size":"98.1"}, {"price":"0.78", "size":"97.5"}, {"price":"0.77", "size":"96.89"}, {"price":"0.76", "size":"201.39"}, {"price":"0.75", "size":"116"}, {"price":"0.74", "size":"100.6"}, {"price":"0.73", "size":"95.2"}, {"price":"0.72", "size":"94.9"}, {"price":"0.71", "size":"199.6"}, {"price":"0.7", "size":"94.3"}, {"price":"0.69", "size":"108.28"}, {"price":"0.68", "size":"98.8"}, {"price":"0.67", "size":"718.6"}, {"price":"0.66", "size":"898.4"}, {"price":"0.65", "size":"207.3"}, {"price":"0.64", "size":"293"}, {"price":"0.63", "size":"292.9"}, {"price":"0.62", "size":"897.7"}, {"price":"0.61", "size":"397.6"}, {"price":"0.6", "size":"356.93"}, {"price":"0.59", "size":"297.4"}, {"price":"0.58", "size":"109.6"}, {"price":"0.57", "size":"131.48"}, {"price":"0.56", "size":"413.97"}, {"price":"0.55", "size":"934.2"}, {"price":"0.54", "size":"375.6"}, {"price":"0.53", "size":"292"}, {"price":"0.52", "size":"292.12"}, {"price":"0.51", "size":"402"}, {"price":"0.5", "size":"355.91"}, {"price":"0.49", "size":"362"}, {"price":"0.48", "size":"317"}, {"price":"0.47", "size":"337"}, {"price":"0.46", "size":"607.1"}, {"price":"0.45", "size":"346.64"}, {"price":"0.44", "size":"337.45"}, {"price":"0.43", "size":"434.89"}, {"price":"0.42", "size":"724.36"}, {"price":"0.41", "size":"412.4"}, {"price":"0.4", "size":"328.83"}, {"price":"0.39", "size":"297.6"}, {"price":"0.38", "size":"626.5"}, {"price":"0.37", "size":"297.9"}, {"price":"0.36", "size":"208"}, {"price":"0.35", "size":"345.14"}, {"price":"0.34", "size":"365.9"}, {"price":"0.33", "size":"343.6"}, {"price":"0.32", "size":"2055.88"}, {"price":"0.31", "size":"559"}, {"price":"0.3", "size":"134.3"}, {"price":"0.29", "size":"316.38"}, {"price":"0.28", "size":"159.9"}, {"price":"0.27", "size":"160.2"}, {"price":"0.26", "size":"230.6"}, {"price":"0.25", "size":"356"}, {"price":"0.24", "size":"126.39"}, {"price":"0.23", "size":"121.89"}, {"price":"0.22", "size":"117.5"}, {"price":"0.21", "size":"175.44"}, {"price":"0.2", "size":"120"}, {"price":"0.19", "size":"91.85"}, {"price":"0.18", "size":"432.54"}, {"price":"0.16", "size":"69.16"}], "hash":"a2b4a8003be54b14c5ad3d26bc3cdf01bac5b7f2", "timestamp":"1778784199998", "event_type":"book"}
{"market":"0x2a903c589141bce4a1e50fb98b73397af6820942542793ab10b1df477e912b6e", "price_changes":[{"asset_id":"20436996072316278452977393149218961565084965483366669504673105646378938504388", "price":"0.82", "size":"379.93", "side":"BUY", "hash":"9ea533cc975a9afe09e1eb4482140fa5ed628f9b", "best_bid":"0.82", "best_ask":"0.87"}, {"asset_id":"68919878716222388542639225642064847629616106443780159680232863841946753372582", "price":"0.18", "size":"379.93", "side":"SELL", "hash":"a3a01dd83d19a2195faf78be82022fd772c007b3", "best_bid":"0.13", "best_ask":"0.18"}], "timestamp":"1778784200012", "event_type":"price_change"}
{"market":"0x2a903c589141bce4a1e50fb98b73397af6820942542793ab10b1df477e912b6e", "price_changes":[{"asset_id":"68919878716222388542639225642064847629616106443780159680232863841946753372582", "price":"0.16", "size":"0", "side":"SELL", "hash":"a3a01dd83d19a2195faf78be82022fd772c007b3", "best_bid":"0.13", "best_ask":"0.18"}, {"asset_id":"20436996072316278452977393149218961565084965483366669504673105646378938504388", "price":"0.84", "size":"0", "side":"BUY", "hash":"9ea533cc975a9afe09e1eb4482140fa5ed628f9b", "best_bid":"0.82", "best_ask":"0.87"}], "timestamp":"1778784200012", "event_type":"price_change"}
{"market":"0x2a903c589141bce4a1e50fb98b73397af6820942542793ab10b1df477e912b6e", "asset_id":"68919878716222388542639225642064847629616106443780159680232863841946753372582", "bids":[{"price":"0.01", "size":"11345.74"}, {"price":"0.02", "size":"1437.32"}, {"price":"0.03", "size":"1105.78"}, {"price":"0.04", "size":"837.82"}, {"price":"0.05", "size":"1055.72"}, {"price":"0.06", "size":"337.72"}, {"price":"0.07", "size":"337.1"}, {"price":"0.08", "size":"690.73"}, {"price":"0.09", "size":"298.11"}, {"price":"0.1", "size":"836.83"}, {"price":"0.11", "size":"157.41"}, {"price":"0.13", "size":"71.65"}], "asks":[{"price":"0.99", "size":"12101.51"}, {"price":"0.98", "size":"1219.45"}, {"price":"0.97", "size":"1111.98"}, {"price":"0.96", "size":"670.05"}, {"price":"0.95", "size":"549.45"}, {"price":"0.94", "size":"346.2"}, {"price":"0.93", "size":"902.05"}, {"price":"0.92", "size":"170.79"}, {"price":"0.91", "size":"234.6"}, {"price":"0.9", "size":"128"}, {"price":"0.89", "size":"142.6"}, {"price":"0.88", "size":"141.8"}, {"price":"0.87", "size":"144.81"}, {"price":"0.86", "size":"204.9"}, {"price":"0.85", "size":"113.5"}, {"price":"0.84", "size":"102.3"}, {"price":"0.83", "size":"101.3"}, {"price":"0.82", "size":"105.3"}, {"price":"0.81", "size":"199.5"}, {"price":"0.8", "size":"103.8"}, {"price":"0.79", "size":"98.1"}, {"price":"0.78", "size":"97.5"}, {"price":"0.77", "size":"96.89"}, {"price":"0.76", "size":"201.39"}, {"price":"0.75", "size":"116"}, {"price":"0.74", "size":"100.6"}, {"price":"0.73", "size":"95.2"}, {"price":"0.72", "size":"94.9"}, {"price":"0.71", "size":"199.6"}, {"price":"0.7", "size":"94.3"}, {"price":"0.69", "size":"108.28"}, {"price":"0.68", "size":"98.8"}, {"price":"0.67", "size":"718.6"}, {"price":"0.66", "size":"898.4"}, {"price":"0.65", "size":"207.3"}, {"price":"0.64", "size":"293"}, {"price":"0.63", "size":"292.9"}, {"price":"0.62", "size":"897.7"}, {"price":"0.61", "size":"397.6"}, {"price":"0.6", "size":"356.93"}, {"price":"0.59", "size":"297.4"}, {"price":"0.58", "size":"109.6"}, {"price":"0.57", "size":"131.48"}, {"price":"0.56", "size":"413.97"}, {"price":"0.55", "size":"934.2"}, {"price":"0.54", "size":"375.6"}, {"price":"0.53", "size":"292"}, {"price":"0.52", "size":"292.12"}, {"price":"0.51", "size":"402"}, {"price":"0.5", "size":"355.91"}, {"price":"0.49", "size":"362"}, {"price":"0.48", "size":"317"}, {"price":"0.47", "size":"337"}, {"price":"0.46", "size":"607.1"}, {"price":"0.45", "size":"346.64"}, {"price":"0.44", "size":"337.45"}, {"price":"0.43", "size":"434.89"}, {"price":"0.42", "size":"724.36"}, {"price":"0.41", "size":"412.4"}, {"price":"0.4", "size":"328.83"}, {"price":"0.39", "size":"297.6"}, {"price":"0.38", "size":"626.5"}, {"price":"0.37", "size":"297.9"}, {"price":"0.36", "size":"208"}, {"price":"0.35", "size":"345.14"}, {"price":"0.34", "size":"365.9"}, {"price":"0.33", "size":"343.6"}, {"price":"0.32", "size":"2055.88"}, {"price":"0.31", "size":"559"}, {"price":"0.3", "size":"134.3"}, {"price":"0.29", "size":"316.38"}, {"price":"0.28", "size":"159.9"}, {"price":"0.27", "size":"160.2"}, {"price":"0.26", "size":"230.6"}, {"price":"0.25", "size":"356"}, {"price":"0.24", "size":"126.39"}, {"price":"0.23", "size":"121.89"}, {"price":"0.22", "size":"117.5"}, {"price":"0.21", "size":"175.44"}, {"price":"0.2", "size":"120"}, {"price":"0.19", "size":"91.85"}, {"price":"0.18", "size":"379.93"}], "hash":"a3a01dd83d19a2195faf78be82022fd772c007b3", "timestamp":"1778784200012", "event_type":"book"}
{"market":"0x2a903c589141bce4a1e50fb98b73397af6820942542793ab10b1df477e912b6e", "price_changes":[{"asset_id":"20436996072316278452977393149218961565084965483366669504673105646378938504388", "price":"0.76", "size":"151.39", "side":"BUY", "hash":"9e3dcd78050b1ddc40687d04c0bbcbc5053d62a6", "best_bid":"0.82", "best_ask":"0.87"}, {"asset_id":"68919878716222388542639225642064847629616106443780159680232863841946753372582", "price":"0.24", "size":"151.39", "side":"SELL", "hash":"157cda16570a05155d983c9a059803428196dc86", "best_bid":"0.13", "best_ask":"0.18"}], "timestamp":"1778784200016", "event_type":"price_change"}
{"market":"0x2a903c589141bce4a1e50fb98b73397af6820942542793ab10b1df477e912b6e", "price_changes":[{"asset_id":"20436996072316278452977393149218961565084965483366669504673105646378938504388", "price":"0.77", "size":"146.89", "side":"BUY", "hash":"b232ec9f14ea1abcb8699ac8afc269a3c27260fa", "best_bid":"0.82", "best_ask":"0.87"}, {"asset_id":"68919878716222388542639225642064847629616106443780159680232863841946753372582", "price":"0.23", "size":"146.89", "side":"SELL", "hash":"ab8618433ceca20bcbb094032ea08bf72b5fe14c", "best_bid":"0.13", "best_ask":"0.18"}], "timestamp":"1778784200021", "event_type":"price_change"}
{"market":"0x2a903c589141bce4a1e50fb98b73397af6820942542793ab10b1df477e912b6e", "price_changes":[{"asset_id":"20436996072316278452977393149218961565084965483366669504673105646378938504388", "price":"0.82", "size":"374.82", "side":"BUY", "hash":"61620bdeb48e142561a5828449f9e5e8f7c99190", "best_bid":"0.82", "best_ask":"0.87"}, {"asset_id":"68919878716222388542639225642064847629616106443780159680232863841946753372582", "price":"0.18", "size":"374.82", "side":"SELL", "hash":"1e8939d6ba0c5ee73209b0ee610c5ca536736be5", "best_bid":"0.13", "best_ask":"0.18"}], "timestamp":"1778784200030", "event_type":"price_change"}
{"market":"0x2a903c589141bce4a1e50fb98b73397af6820942542793ab10b1df477e912b6e", "asset_id":"68919878716222388542639225642064847629616106443780159680232863841946753372582", "bids":[{"price":"0.01", "size":"11345.74"}, {"price":"0.02", "size":"1437.32"}, {"price":"0.03", "size":"1105.78"}, {"price":"0.04", "size":"837.82"}, {"price":"0.05", "size":"1055.72"}, {"price":"0.06", "size":"337.72"}, {"price":"0.07", "size":"337.1"}, {"price":"0.08", "size":"690.73"}, {"price":"0.09", "size":"298.11"}, {"price":"0.1", "size":"836.83"}, {"price":"0.11", "size":"157.41"}, {"price":"0.13", "size":"71.65"}], "asks":[{"price":"0.99", "size":"12101.51"}, {"price":"0.98", "size":"1219.45"}, {"price":"0.97", "size":"1111.98"}, {"price":"0.96", "size":"670.05"}, {"price":"0.95", "size":"549.45"}, {"price":"0.94", "size":"346.2"}, {"price":"0.93", "size":"902.05"}, {"price":"0.92", "size":"170.79"}, {"price":"0.91", "size":"234.6"}, {"price":"0.9", "size":"128"}, {"price":"0.89", "size":"142.6"}, {"price":"0.88", "size":"141.8"}, {"price":"0.87", "size":"144.81"}, {"price":"0.86", "size":"204.9"}, {"price":"0.85", "size":"113.5"}, {"price":"0.84", "size":"102.3"}, {"price":"0.83", "size":"101.3"}, {"price":"0.82", "size":"105.3"}, {"price":"0.81", "size":"199.5"}, {"price":"0.8", "size":"103.8"}, {"price":"0.79", "size":"98.1"}, {"price":"0.78", "size":"97.5"}, {"price":"0.77", "size":"96.89"}, {"price":"0.76", "size":"201.39"}, {"price":"0.75", "size":"116"}, {"price":"0.74", "size":"100.6"}, {"price":"0.73", "size":"95.2"}, {"price":"0.72", "size":"94.9"}, {"price":"0.71", "size":"199.6"}, {"price":"0.7", "size":"94.3"}, {"price":"0.69", "size":"108.28"}, {"price":"0.68", "size":"98.8"}, {"price":"0.67", "size":"718.6"}, {"price":"0.66", "size":"898.4"}, {"price":"0.65", "size":"207.3"}, {"price":"0.64", "size":"293"}, {"price":"0.63", "size":"292.9"}, {"price":"0.62", "size":"897.7"}, {"price":"0.61", "size":"397.6"}, {"price":"0.6", "size":"356.93"}, {"price":"0.59", "size":"297.4"}, {"price":"0.58", "size":"109.6"}, {"price":"0.57", "size":"131.48"}, {"price":"0.56", "size":"413.97"}, {"price":"0.55", "size":"934.2"}, {"price":"0.54", "size":"375.6"}, {"price":"0.53", "size":"292"}, {"price":"0.52", "size":"292.12"}, {"price":"0.51", "size":"402"}, {"price":"0.5", "size":"355.91"}, {"price":"0.49", "size":"362"}, {"price":"0.48", "size":"317"}, {"price":"0.47", "size":"337"}, {"price":"0.46", "size":"607.1"}, {"price":"0.45", "size":"346.64"}, {"price":"0.44", "size":"337.45"}, {"price":"0.43", "size":"434.89"}, {"price":"0.42", "size":"724.36"}, {"price":"0.41", "size":"412.4"}, {"price":"0.4", "size":"328.83"}, {"price":"0.39", "size":"297.6"}, {"price":"0.38", "size":"626.5"}, {"price":"0.37", "size":"297.9"}, {"price":"0.36", "size":"208"}, {"price":"0.35", "size":"345.14"}, {"price":"0.34", "size":"365.9"}, {"price":"0.33", "size":"343.6"}, {"price":"0.32", "size":"2055.88"}, {"price":"0.31", "size":"559"}, {"price":"0.3", "size":"134.3"}, {"price":"0.29", "size":"316.38"}, {"price":"0.28", "size":"159.9"}, {"price":"0.27", "size":"160.2"}, {"price":"0.26", "size":"230.6"}, {"price":"0.25", "size":"356"}, {"price":"0.24", "size":"151.39"}, {"price":"0.23", "size":"146.89"}, {"price":"0.22", "size":"117.5"}, {"price":"0.21", "size":"175.44"}, {"price":"0.2", "size":"120"}, {"price":"0.19", "size":"91.85"}, {"price":"0.18", "size":"374.82"}], "hash":"1e8939d6ba0c5ee73209b0ee610c5ca536736be5", "timestamp":"1778784200030", "event_type":"book"}
{"market":"0x2a903c589141bce4a1e50fb98b73397af6820942542793ab10b1df477e912b6e", "price_changes":[{"asset_id":"20436996072316278452977393149218961565084965483366669504673105646378938504388", "price":"0.77", "size":"151.89", "side":"BUY", "hash":"ac28451058337bb20d9045d425b9b57f25c8f2da", "best_bid":"0.82", "best_ask":"0.87"}, {"asset_id":"68919878716222388542639225642064847629616106443780159680232863841946753372582", "price":"0.23", "size":"151.89", "side":"SELL", "hash":"63ef32879f1fa74726ab6184746914d004b72924", "best_bid":"0.13", "best_ask":"0.18"}], "timestamp":"1778784200033", "event_type":"price_change"}
{"market":"0x2a903c589141bce4a1e50fb98b73397af6820942542793ab10b1df477e912b6e", "price_changes":[{"asset_id":"20436996072316278452977393149218961565084965483366669504673105646378938504388", "price":"0.66", "size":"355.9", "side":"BUY", "hash":"71f058a2da084c09c5c711062a446a8e0b0a1a34", "best_bid":"0.82", "best_ask":"0.87"}, {"asset_id":"68919878716222388542639225642064847629616106443780159680232863841946753372582", "price":"0.34", "size":"355.9", "side":"SELL", "hash":"b93fbf9566e6876adceee03ddbf3dc8592107f0b", "best_bid":"0.13", "best_ask":"0.18"}], "timestamp":"1778784200037", "event_type":"price_change"}
{"market":"0x2a903c589141bce4a1e50fb98b73397af6820942542793ab10b1df477e912b6e", "asset_id":"68919878716222388542639225642064847629616106443780159680232863841946753372582", "price":"0.18", "size":"5.11", "fee_rate_bps":"0", "side":"BUY", "timestamp":"1778784200069", "event_type":"last_trade_price", "transaction_hash":"0x324baa5c97b473fcf22918019f0553a6ed9001e3f28a37e6be82b2e5992b8257"}
{"market":"0x2a903c589141bce4a1e50fb98b73397af6820942542793ab10b1df477e912b6e", "price_changes":[{"asset_id":"20436996072316278452977393149218961565084965483366669504673105646378938504388", "price":"0.82", "size":"274.82", "side":"BUY", "hash":"60720e44c1dcda0b70670c31a5a548ed03f774e9", "best_bid":"0.82", "best_ask":"0.87"}, {"asset_id":"68919878716222388542639225642064847629616106443780159680232863841946753372582", "price":"0.18", "size":"274.82", "side":"SELL", "hash":"134da8c62aeb2dd02b4261f2fecf64660ca28c0a", "best_bid":"0.13", "best_ask":"0.18"}], "timestamp":"1778784200045", "event_type":"price_change"}
{"market":"0x2a903c589141bce4a1e50fb98b73397af6820942542793ab10b1df477e912b6e", "price_changes":[{"asset_id":"20436996072316278452977393149218961565084965483366669504673105646378938504388", "price":"0.81", "size":"72.35", "side":"BUY", "hash":"60720e44c1dcda0b70670c31a5a548ed03f774e9", "best_bid":"0.82", "best_ask":"0.87"}, {"asset_id":"68919878716222388542639225642064847629616106443780159680232863841946753372582", "price":"0.19", "size":"72.35", "side":"SELL", "hash":"134da8c62aeb2dd02b4261f2fecf64660ca28c0a", "best_bid":"0.13", "best_ask":"0.18"}], "timestamp":"1778784200045", "event_type":"price_change"}
{"market":"0x2a903c589141bce4a1e50fb98b73397af6820942542793ab10b1df477e912b6e", "price_changes":[{"asset_id":"20436996072316278452977393149218961565084965483366669504673105646378938504388", "price":"0.8", "size":"90", "side":"BUY", "hash":"60720e44c1dcda0b70670c31a5a548ed03f774e9", "best_bid":"0.82", "best_ask":"0.87"}, {"asset_id":"68919878716222388542639225642064847629616106443780159680232863841946753372582", "price":"0.2", "size":"90", "side":"SELL", "hash":"134da8c62aeb2dd02b4261f2fecf64660ca28c0a", "best_bid":"0.13", "best_ask":"0.18"}], "timestamp":"1778784200045", "event_type":"price_change"}
{"market":"0x2a903c589141bce4a1e50fb98b73397af6820942542793ab10b1df477e912b6e", "price_changes":[{"asset_id":"68919878716222388542639225642064847629616106443780159680232863841946753372582", "price":"0.13", "size":"70.5", "side":"BUY", "hash":"6faac2358170644cd4997b05bd2b8459fff0aa1f", "best_bid":"0.13", "best_ask":"0.18"}, {"asset_id":"20436996072316278452977393149218961565084965483366669504673105646378938504388", "price":"0.87", "size":"70.5", "side":"SELL", "hash":"478c73d4e4d41c65e113b9c1e4a99e5deebecd77", "best_bid":"0.82", "best_ask":"0.87"}], "timestamp":"1778784200182", "event_type":"price_change"}
{"market":"0x2a903c589141bce4a1e50fb98b73397af6820942542793ab10b1df477e912b6e", "asset_id":"68919878716222388542639225642064847629616106443780159680232863841946753372582", "bids":[{"price":"0.01", "size":"11345.74"}, {"price":"0.02", "size":"1437.32"}, {"price":"0.03", "size":"1105.78"}, {"price":"0.04", "size":"837.82"}, {"price":"0.05", "size":"1055.72"}, {"price":"0.06", "size":"337.72"}, {"price":"0.07", "size":"337.1"}, {"price":"0.08", "size":"690.73"}, {"price":"0.09", "size":"298.11"}, {"price":"0.1", "size":"836.83"}, {"price":"0.11", "size":"157.41"}, {"price":"0.13", "size":"70.5"}], "asks":[{"price":"0.99", "size":"12101.51"}, {"price":"0.98", "size":"1219.45"}, {"price":"0.97", "size":"1111.98"}, {"price":"0.96", "size":"670.05"}, {"price":"0.95", "size":"549.45"}, {"price":"0.94", "size":"346.2"}, {"price":"0.93", "size":"902.05"}, {"price":"0.92", "size":"170.79"}, {"price":"0.91", "size":"234.6"}, {"price":"0.9", "size":"128"}, {"price":"0.89", "size":"142.6"}, {"price":"0.88", "size":"141.8"}, {"price":"0.87", "size":"144.81"}, {"price":"0.86", "size":"204.9"}, {"price":"0.85", "size":"113.5"}, {"price":"0.84", "size":"102.3"}, {"price":"0.83", "size":"101.3"}, {"price":"0.82", "size":"105.3"}, {"price":"0.81", "size":"199.5"}, {"price":"0.8", "size":"103.8"}, {"price":"0.79", "size":"98.1"}, {"price":"0.78", "size":"97.5"}, {"price":"0.77", "size":"96.89"}, {"price":"0.76", "size":"201.39"}, {"price":"0.75", "size":"116"}, {"price":"0.74", "size":"100.6"}, {"price":"0.73", "size":"95.2"}, {"price":"0.72", "size":"94.9"}, {"price":"0.71", "size":"199.6"}, {"price":"0.7", "size":"94.3"}, {"price":"0.69", "size":"108.28"}, {"price":"0.68", "size":"98.8"}, {"price":"0.67", "size":"718.6"}, {"price":"0.66", "size":"898.4"}, {"price":"0.65", "size":"207.3"}, {"price":"0.64", "size":"293"}, {"price":"0.63", "size":"292.9"}, {"price":"0.62", "size":"897.7"}, {"price":"0.61", "size":"397.6"}, {"price":"0.6", "size":"356.93"}, {"price":"0.59", "size":"297.4"}, {"price":"0.58", "size":"109.6"}, {"price":"0.57", "size":"131.48"}, {"price":"0.56", "size":"413.97"}, {"price":"0.55", "size":"934.2"}, {"price":"0.54", "size":"375.6"}, {"price":"0.53", "size":"292"}, {"price":"0.52", "size":"292.12"}, {"price":"0.51", "size":"402"}, {"price":"0.5", "size":"355.91"}, {"price":"0.49", "size":"362"}, {"price":"0.48", "size":"317"}, {"price":"0.47", "size":"337"}, {"price":"0.46", "size":"607.1"}, {"price":"0.45", "size":"346.64"}, {"price":"0.44", "size":"337.45"}, {"price":"0.43", "size":"434.89"}, {"price":"0.42", "size":"724.36"}, {"price":"0.41", "size":"412.4"}, {"price":"0.4", "size":"328.83"}, {"price":"0.39", "size":"297.6"}, {"price":"0.38", "size":"626.5"}, {"price":"0.37", "size":"297.9"}, {"price":"0.36", "size":"208"}, {"price":"0.35", "size":"345.14"}, {"price":"0.34", "size":"355.9"}, {"price":"0.33", "size":"343.6"}, {"price":"0.32", "size":"2055.88"}, {"price":"0.31", "size":"559"}, {"price":"0.3", "size":"134.3"}, {"price":"0.29", "size":"316.38"}, {"price":"0.28", "size":"159.9"}, {"price":"0.27", "size":"160.2"}, {"price":"0.26", "size":"230.6"}, {"price":"0.25", "size":"356"}, {"price":"0.24", "size":"151.39"}, {"price":"0.23", "size":"151.89"}, {"price":"0.22", "size":"117.5"}, {"price":"0.21", "size":"175.44"}, {"price":"0.2", "size":"90"}, {"price":"0.19", "size":"72.35"}, {"price":"0.18", "size":"274.82"}], "hash":"6faac2358170644cd4997b05bd2b8459fff0aa1f", "timestamp":"1778784200182", "event_type":"book"}
{"market":"0x2a903c589141bce4a1e50fb98b73397af6820942542793ab10b1df477e912b6e", "price_changes":[{"asset_id":"20436996072316278452977393149218961565084965483366669504673105646378938504388", "price":"0.62", "size":"618.44", "side":"BUY", "hash":"9890e7622ceb13a6cacb32b21742077b527cc63f", "best_bid":"0.82", "best_ask":"0.87"}, {"asset_id":"68919878716222388542639225642064847629616106443780159680232863841946753372582", "price":"0.38", "size":"618.44", "side":"SELL", "hash":"41b9c330e64f798f1a7031c024e7bbfa97eddccf", "best_bid":"0.13", "best_ask":"0.18"}], "timestamp":"1778784200242", "event_type":"price_change"}
{"market":"0x2a903c589141bce4a1e50fb98b73397af6820942542793ab10b1df477e912b6e", "price_changes":[{"asset_id":"20436996072316278452977393149218961565084965483366669504673105646378938504388", "price":"0.82", "size":"274.82", "side":"BUY", "hash":"9890e7622ceb13a6cacb32b21742077b527cc63f", "best_bid":"0.82", "best_ask":"0.87"}, {"asset_id":"68919878716222388542639225642064847629616106443780159680232863841946753372582", "price":"0.18", "size":"274.82", "side":"SELL", "hash":"f0ab5c90b7959731d0b7d0e4efd46c0bedfa1195", "best_bid":"0.13", "best_ask":"0.18"}], "timestamp":"1778784200245", "event_type":"price_change"}
{"market":"0x2a903c589141bce4a1e50fb98b73397af6820942542793ab10b1df477e912b6e", "price_changes":[{"asset_id":"20436996072316278452977393149218961565084965483366669504673105646378938504388", "price":"0.81", "size":"72.35", "side":"BUY", "hash":"9890e7622ceb13a6cacb32b21742077b527cc63f", "best_bid":"0.82", "best_ask":"0.87"}, {"asset_id":"68919878716222388542639225642064847629616106443780159680232863841946753372582", "price":"0.19", "size":"72.35", "side":"SELL", "hash":"f0ab5c90b7959731d0b7d0e4efd46c0bedfa1195", "best_bid":"0.13", "best_ask":"0.18"}], "timestamp":"1778784200245", "event_type":"price_change"}
{"market":"0x2a903c589141bce4a1e50fb98b73397af6820942542793ab10b1df477e912b6e", "price_changes":[{"asset_id":"20436996072316278452977393149218961565084965483366669504673105646378938504388", "price":"0.8", "size":"90", "side":"BUY", "hash":"9890e7622ceb13a6cacb32b21742077b527cc63f", "best_bid":"0.82", "best_ask":"0.87"}, {"asset_id":"68919878716222388542639225642064847629616106443780159680232863841946753372582", "price":"0.2", "size":"90", "side":"SELL", "hash":"f0ab5c90b7959731d0b7d0e4efd46c0bedfa1195", "best_bid":"0.13", "best_ask":"0.18"}], "timestamp":"1778784200245", "event_type":"price_change"}
{"market":"0x2a903c589141bce4a1e50fb98b73397af6820942542793ab10b1df477e912b6e", "price_changes":[{"asset_id":"20436996072316278452977393149218961565084965483366669504673105646378938504388", "price":"0.77", "size":"126.89", "side":"BUY", "hash":"9890e7622ceb13a6cacb32b21742077b527cc63f", "best_bid":"0.82", "best_ask":"0.87"}, {"asset_id":"68919878716222388542639225642064847629616106443780159680232863841946753372582", "price":"0.23", "size":"126.89", "side":"SELL", "hash":"f0ab5c90b7959731d0b7d0e4efd46c0bedfa1195", "best_bid":"0.13", "best_ask":"0.18"}], "timestamp":"1778784200245", "event_type":"price_change"}
{"market":"0x2a903c589141bce4a1e50fb98b73397af6820942542793ab10b1df477e912b6e", "price_changes":[{"asset_id":"68919878716222388542639225642064847629616106443780159680232863841946753372582", "price":"0.11", "size":"119.58", "side":"BUY", "hash":"f8b7ffdc2b3f38041f65136f6f98e3f14ee40f59", "best_bid":"0.11", "best_ask":"0.18"}, {"asset_id":"20436996072316278452977393149218961565084965483366669504673105646378938504388", "price":"0.89", "size":"119.58", "side":"SELL", "hash":"2d7027833f0b5e80c64cd8ab8ddcf0a5d70a515d", "best_bid":"0.82", "best_ask":"0.89"}], "timestamp":"1778784200257", "event_type":"price_change"}
{"market":"0x2a903c589141bce4a1e50fb98b73397af6820942542793ab10b1df477e912b6e", "price_changes":[{"asset_id":"68919878716222388542639225642064847629616106443780159680232863841946753372582", "price":"0.13", "size":"0", "side":"BUY", "hash":"f8b7ffdc2b3f38041f65136f6f98e3f14ee40f59", "best_bid":"0.11", "best_ask":"0.18"}, {"asset_id":"20436996072316278452977393149218961565084965483366669504673105646378938504388", "price":"0.87", "size":"0", "side":"SELL", "hash":"2d7027833f0b5e80c64cd8ab8ddcf0a5d70a515d", "best_bid":"0.82", "best_ask":"0.89"}], "timestamp":"1778784200257", "event_type":"price_change"}
{"market":"0x2a903c589141bce4a1e50fb98b73397af6820942542793ab10b1df477e912b6e", "asset_id":"68919878716222388542639225642064847629616106443780159680232863841946753372582", "bids":[{"price":"0.01", "size":"11345.74"}, {"price":"0.02", "size":"1437.32"}, {"price":"0.03", "size":"1105.78"}, {"price":"0.04", "size":"837.82"}, {"price":"0.05", "size":"1055.72"}, {"price":"0.06", "size":"337.72"}, {"price":"0.07", "size":"337.1"}, {"price":"0.08", "size":"690.73"}, {"price":"0.09", "size":"298.11"}, {"price":"0.1", "size":"836.83"}, {"price":"0.11", "size":"119.58"}], "asks":[{"price":"0.99", "size":"12101.51"}, {"price":"0.98", "size":"1219.45"}, {"price":"0.97", "size":"1111.98"}, {"price":"0.96", "size":"670.05"}, {"price":"0.95", "size":"549.45"}, {"price":"0.94", "size":"346.2"}, {"price":"0.93", "size":"902.05"}, {"price":"0.92", "size":"170.79"}, {"price":"0.91", "size":"234.6"}, {"price":"0.9", "size":"128"}, {"price":"0.89", "size":"142.6"}, {"price":"0.88", "size":"141.8"}, {"price":"0.87", "size":"144.81"}, {"price":"0.86", "size":"204.9"}, {"price":"0.85", "size":"113.5"}, {"price":"0.84", "size":"102.3"}, {"price":"0.83", "size":"101.3"}, {"price":"0.82", "size":"105.3"}, {"price":"0.81", "size":"199.5"}, {"price":"0.8", "size":"103.8"}, {"price":"0.79", "size":"98.1"}, {"price":"0.78", "size":"97.5"}, {"price":"0.77", "size":"96.89"}, {"price":"0.76", "size":"201.39"}, {"price":"0.75", "size":"116"}, {"price":"0.74", "size":"100.6"}, {"price":"0.73", "size":"95.2"}, {"price":"0.72", "size":"94.9"}, {"price":"0.71", "size":"199.6"}, {"price":"0.7", "size":"94.3"}, {"price":"0.69", "size":"108.28"}, {"price":"0.68", "size":"98.8"}, {"price":"0.67", "size":"718.6"}, {"price":"0.66", "size":"898.4"}, {"price":"0.65", "size":"207.3"}, {"price":"0.64", "size":"293"}, {"price":"0.63", "size":"292.9"}, {"price":"0.62", "size":"897.7"}, {"price":"0.61", "size":"397.6"}, {"price":"0.6", "size":"356.93"}, {"price":"0.59", "size":"297.4"}, {"price":"0.58", "size":"109.6"}, {"price":"0.57", "size":"131.48"}, {"price":"0.56", "size":"413.97"}, {"price":"0.55", "size":"934.2"}, {"price":"0.54", "size":"375.6"}, {"price":"0.53", "size":"292"}, {"price":"0.52", "size":"292.12"}, {"price":"0.51", "size":"402"}, {"price":"0.5", "size":"355.91"}, {"price":"0.49", "size":"362"}, {"price":"0.48", "size":"317"}, {"price":"0.47", "size":"337"}, {"price":"0.46", "size":"607.1"}, {"price":"0.45", "size":"346.64"}, {"price":"0.44", "size":"337.45"}, {"price":"0.43", "size":"434.89"}, {"price":"0.42", "size":"724.36"}, {"price":"0.41", "size":"412.4"}, {"price":"0.4", "size":"328.83"}, {"price":"0.39", "size":"297.6"}, {"price":"0.38", "size":"618.44"}, {"price":"0.37", "size":"297.9"}, {"price":"0.36", "size":"208"}, {"price":"0.35", "size":"345.14"}, {"price":"0.34", "size":"355.9"}, {"price":"0.33", "size":"343.6"}, {"price":"0.32", "size":"2055.88"}, {"price":"0.31", "size":"559"}, {"price":"0.3", "size":"134.3"}, {"price":"0.29", "size":"316.38"}, {"price":"0.28", "size":"159.9"}, {"price":"0.27", "size":"160.2"}, {"price":"0.26", "size":"230.6"}, {"price":"0.25", "size":"356"}, {"price":"0.24", "size":"151.39"}, {"price":"0.23", "size":"126.89"}, {"price":"0.22", "size":"117.5"}, {"price":"0.21", "size":"175.44"}, {"price":"0.2", "size":"90"}, {"price":"0.19", "size":"72.35"}, {"price":"0.18", "size":"274.82"}], "hash":"f8b7ffdc2b3f38041f65136f6f98e3f14ee40f59", "timestamp":"1778784200257", "event_type":"book"}
{"market":"0x2a903c589141bce4a1e50fb98b73397af6820942542793ab10b1df477e912b6e", "price_changes":[{"asset_id":"68919878716222388542639225642064847629616106443780159680232863841946753372582", "price":"0.12", "size":"5", "side":"SELL", "hash":"949bbbc06629417dbb15ab36ffaa2fc987df880a", "best_bid":"0.11", "best_ask":"0.12"}, {"asset_id":"20436996072316278452977393149218961565084965483366669504673105646378938504388", "price":"0.88", "size":"5", "side":"BUY", "hash":"632ff7ae3af8526658d6a18f6a3f4a83ab985f31", "best_bid":"0.88", "best_ask":"0.89"}], "timestamp":"1778784200270", "event_type":"price_change"}
{"market":"0x2a903c589141bce4a1e50fb98b73397af6820942542793ab10b1df477e912b6e", "price_changes":[{"asset_id":"68919878716222388542639225642064847629616106443780159680232863841946753372582", "price":"0.11", "size":"63.4", "side":"BUY", "hash":"dc22d821216e9d2c47fe79f8d1bb928bf3f8e5ef", "best_bid":"0.11", "best_ask":"0.12"}, {"asset_id":"20436996072316278452977393149218961565084965483366669504673105646378938504388", "price":"0.89", "size":"63.4", "side":"SELL", "hash":"1e0568b4dcc17c2d93a3e91424fa45b1f5672e0c", "best_bid":"0.88", "best_ask":"0.89"}], "timestamp":"1778784200279", "event_type":"price_change"}
{"market":"0x2a903c589141bce4a1e50fb98b73397af6820942542793ab10b1df477e912b6e", "asset_id":"68919878716222388542639225642064847629616106443780159680232863841946753372582", "bids":[{"price":"0.01", "size":"11345.74"}, {"price":"0.02", "size":"1437.32"}, {"price":"0.03", "size":"1105.78"}, {"price":"0.04", "size":"837.82"}, {"price":"0.05", "size":"1055.72"}, {"price":"0.06", "size":"337.72"}, {"price":"0.07", "size":"337.1"}, {"price":"0.08", "size":"690.73"}, {"price":"0.09", "size":"298.11"}, {"price":"0.1", "size":"836.83"}, {"price":"0.11", "size":"63.4"}], "asks":[{"price":"0.99", "size":"12101.51"}, {"price":"0.98", "size":"1219.45"}, {"price":"0.97", "size":"1111.98"}, {"price":"0.96", "size":"670.05"}, {"price":"0.95", "size":"549.45"}, {"price":"0.94", "size":"346.2"}, {"price":"0.93", "size":"902.05"}, {"price":"0.92", "size":"170.79"}, {"price":"0.91", "size":"234.6"}, {"price":"0.9", "size":"128"}, {"price":"0.89", "size":"142.6"}, {"price":"0.88", "size":"141.8"}, {"price":"0.87", "size":"144.81"}, {"price":"0.86", "size":"204.9"}, {"price":"0.85", "size":"113.5"}, {"price":"0.84", "size":"102.3"}, {"price":"0.83", "size":"101.3"}, {"price":"0.82", "size":"105.3"}, {"price":"0.81", "size":"199.5"}, {"price":"0.8", "size":"103.8"}, {"price":"0.79", "size":"98.1"}, {"price":"0.78", "size":"97.5"}, {"price":"0.77", "size":"96.89"}, {"price":"0.76", "size":"201.39"}, {"price":"0.75", "size":"116"}, {"price":"0.74", "size":"100.6"}, {"price":"0.73", "size":"95.2"}, {"price":"0.72", "size":"94.9"}, {"price":"0.71", "size":"199.6"}, {"price":"0.7", "size":"94.3"}, {"price":"0.69", "size":"108.28"}, {"price":"0.68", "size":"98.8"}, {"price":"0.67", "size":"718.6"}, {"price":"0.66", "size":"898.4"}, {"price":"0.65", "size":"207.3"}, {"price":"0.64", "size":"293"}, {"price":"0.63", "size":"292.9"}, {"price":"0.62", "size":"897.7"}, {"price":"0.61", "size":"397.6"}, {"price":"0.6", "size":"356.93"}, {"price":"0.59", "size":"297.4"}, {"price":"0.58", "size":"109.6"}, {"price":"0.57", "size":"131.48"}, {"price":"0.56", "size":"413.97"}, {"price":"0.55", "size":"934.2"}, {"price":"0.54", "size":"375.6"}, {"price":"0.53", "size":"292"}, {"price":"0.52", "size":"292.12"}, {"price":"0.51", "size":"402"}, {"price":"0.5", "size":"355.91"}, {"price":"0.49", "size":"362"}, {"price":"0.48", "size":"317"}, {"price":"0.47", "size":"337"}, {"price":"0.46", "size":"607.1"}, {"price":"0.45", "size":"346.64"}, {"price":"0.44", "size":"337.45"}, {"price":"0.43", "size":"434.89"}, {"price":"0.42", "size":"724.36"}, {"price":"0.41", "size":"412.4"}, {"price":"0.4", "size":"328.83"}, {"price":"0.39", "size":"297.6"}, {"price":"0.38", "size":"618.44"}, {"price":"0.37", "size":"297.9"}, {"price":"0.36", "size":"208"}, {"price":"0.35", "size":"345.14"}, {"price":"0.34", "size":"355.9"}, {"price":"0.33", "size":"343.6"}, {"price":"0.32", "size":"2055.88"}, {"price":"0.31", "size":"559"}, {"price":"0.3", "size":"134.3"}, {"price":"0.29", "size":"316.38"}, {"price":"0.28", "size":"159.9"}, {"price":"0.27", "size":"160.2"}, {"price":"0.26", "size":"230.6"}, {"price":"0.25", "size":"356"}, {"price":"0.24", "size":"151.39"}, {"price":"0.23", "size":"126.89"}, {"price":"0.22", "size":"117.5"}, {"price":"0.21", "size":"175.44"}, {"price":"0.2", "size":"90"}, {"price":"0.19", "size":"72.35"}, {"price":"0.18", "size":"274.82"}, {"price":"0.12", "size":"5"}], "hash":"dc22d821216e9d2c47fe79f8d1bb928bf3f8e5ef", "timestamp":"1778784200279", "event_type":"book"}
{"market":"0x2a903c589141bce4a1e50fb98b73397af6820942542793ab10b1df477e912b6e", "price_changes":[{"asset_id":"20436996072316278452977393149218961565084965483366669504673105646378938504388", "price":"0.99", "size":"11373.83", "side":"SELL", "hash":"9ad65ac52671220fa8a204c38e42a547b34dcebf", "best_bid":"0.88", "best_ask":"0.89"}, {"asset_id":"68919878716222388542639225642064847629616106443780159680232863841946753372582", "price":"0.01", "size":"11373.83", "side":"BUY", "hash":"7c43a1e9f0e93c9a9ecaa7b96a13b23a64271403", "best_bid":"0.11", "best_ask":"0.12"}], "timestamp":"1778784200289", "event_type":"price_change"}
{"market":"0x2a903c589141bce4a1e50fb98b73397af6820942542793ab10b1df477e912b6e", "price_changes":[{"asset_id":"68919878716222388542639225642064847629616106443780159680232863841946753372582", "price":"0.49", "size":"312", "side":"SELL", "hash":"aca0e0daac0ffcec251ec293db7647097b929c1f", "best_bid":"0.11", "best_ask":"0.12"}, {"asset_id":"20436996072316278452977393149218961565084965483366669504673105646378938504388", "price":"0.51", "size":"312", "side":"BUY", "hash":"d4c8e29857b663df1f289e455e6e2d9830469493", "best_bid":"0.88", "best_ask":"0.89"}], "timestamp":"1778784200290", "event_type":"price_change"}
{"market":"0x2a903c589141bce4a1e50fb98b73397af6820942542793ab10b1df477e912b6e", "price_changes":[{"asset_id":"20436996072316278452977393149218961565084965483366669504673105646378938504388", "price":"0.45", "size":"334.2", "side":"BUY", "hash":"29605cebb6422b93053407893553b9801f81928c", "best_bid":"0.88", "best_ask":"0.89"}, {"asset_id":"68919878716222388542639225642064847629616106443780159680232863841946753372582", "price":"0.55", "size":"334.2", "side":"SELL", "hash":"0d81c572365f3c80277e2da3679f79e27b8d9bd7", "best_bid":"0.11", "best_ask":"0.12"}], "timestamp":"1778784200292", "event_type":"price_change"}
{"market":"0x2a903c589141bce4a1e50fb98b73397af6820942542793ab10b1df477e912b6e", "price_changes":[{"asset_id":"68919878716222388542639225642064847629616106443780159680232863841946753372582", "price":"0.1", "size":"846.83", "side":"BUY", "hash":"6bb118a244a4817e2ea903e90accc9f5740a54c0", "best_bid":"0.11", "best_ask":"0.12"}, {"asset_id":"20436996072316278452977393149218961565084965483366669504673105646378938504388", "price":"0.9", "size":"846.83", "side":"SELL", "hash":"4f74dbe5f891e00c872821ace2049a34a2c6e061", "best_bid":"0.88", "best_ask":"0.89"}], "timestamp":"1778784200294", "event_type":"price_change"}
{"market":"0x2a903c589141bce4a1e50fb98b73397af6820942542793ab10b1df477e912b6e", "price_changes":[{"asset_id":"20436996072316278452977393149218961565084965483366669504673105646378938504388", "price":"0.88", "size":"28.97", "side":"BUY", "hash":"cb43b6dfc57d748552f0b3daac783968103efd30", "best_bid":"0.88", "best_ask":"0.89"}, {"asset_id":"68919878716222388542639225642064847629616106443780159680232863841946753372582", "price":"0.12", "size":"28.97", "side":"SELL", "hash":"bfdc5638892d30be35432e6d896617a8e43b9e02", "best_bid":"0.11", "best_ask":"0.12"}], "timestamp":"1778784200296", "event_type":"price_change"}
{"market":"0x2a903c589141bce4a1e50fb98b73397af6820942542793ab10b1df477e912b6e", "price_changes":[{"asset_id":"68919878716222388542639225642064847629616106443780159680232863841946753372582", "price":"0.11", "size":"163.4", "side":"BUY", "hash":"358f4a14eeb7f950808d5d08fbc52023988c62a8", "best_bid":"0.11", "best_ask":"0.12"}, {"asset_id":"20436996072316278452977393149218961565084965483366669504673105646378938504388", "price":"0.89", "size":"163.4", "side":"SELL", "hash":"9e3d2f7132b3fc025c0a9bc858b83a81e2ada426", "best_bid":"0.88", "best_ask":"0.89"}], "timestamp":"1778784200302", "event_type":"price_change"}
{"market":"0x2a903c589141bce4a1e50fb98b73397af6820942542793ab10b1df477e912b6e", "price_changes":[{"asset_id":"68919878716222388542639225642064847629616106443780159680232863841946753372582", "price":"0.08", "size":"680.73", "side":"BUY", "hash":"ef32e2900a25bb87002c3480b0dc6386dce93df2", "best_bid":"0.11", "best_ask":"0.12"}, {"asset_id":"20436996072316278452977393149218961565084965483366669504673105646378938504388", "price":"0.92", "size":"680.73", "side":"SELL", "hash":"4c9f6e6bd4320fc83ff75dde4a6d8cd44d761dd8", "best_bid":"0.88", "best_ask":"0.89"}], "timestamp":"1778784200303", "event_type":"price_change"}
{"market":"0x2a903c589141bce4a1e50fb98b73397af6820942542793ab10b1df477e912b6e", "price_changes":[{"asset_id":"68919878716222388542639225642064847629616106443780159680232863841946753372582", "price":"0.15", "size":"6.67", "side":"SELL", "hash":"46812f96e5c34d44878cb6e3966aab56deb557b2", "best_bid":"0.11", "best_ask":"0.12"}, {"asset_id":"20436996072316278452977393149218961565084965483366669504673105646378938504388", "price":"0.85", "size":"6.67", "side":"BUY", "hash":"701a31073451f427fbf0b868cbff284002e3e13b", "best_bid":"0.88", "best_ask":"0.89"}], "timestamp":"1778784200305", "event_type":"price_change"}
{"market":"0x2a903c589141bce4a1e50fb98b73397af6820942542793ab10b1df477e912b6e", "price_changes":[{"asset_id":"20436996072316278452977393149218961565084965483366669504673105646378938504388", "price":"0.73", "size":"165.2", "side":"BUY", "hash":"dc54a29c588c503f28624ceddb30dca91db9d720", "best_bid":"0.88", "best_ask":"0.89"}, {"asset_id":"68919878716222388542639225642064847629616106443780159680232863841946753372582", "price":"0.27", "size":"165.2", "side":"SELL", "hash":"d2e8cbf520c5006cadc41a400c6744b878410599", "best_bid":"0.11", "best_ask":"0.12"}], "timestamp":"1778784200308", "event_type":"price_change"}
{"market":"0x2a903c589141bce4a1e50fb98b73397af6820942542793ab10b1df477e912b6e", "price_changes":[{"asset_id":"20436996072316278452977393149218961565084965483366669504673105646378938504388", "price":"0.98", "size":"1427.82", "side":"SELL", "hash":"b1518ff32a1245aab1bd669969ef4b24a7e0a7d0", "best_bid":"0.88", "best_ask":"0.89"}, {"asset_id":"68919878716222388542639225642064847629616106443780159680232863841946753372582", "price":"0.02", "size":"1427.82", "side":"BUY", "hash":"54cb77c384e218c8295428ba694f86f5f4a98a03", "best_bid":"0.11", "best_ask":"0.12"}], "timestamp":"1778784200309", "event_type":"price_change"}
{"market":"0x2a903c589141bce4a1e50fb98b73397af6820942542793ab10b1df477e912b6e", "price_changes":[{"asset_id":"68919878716222388542639225642064847629616106443780159680232863841946753372582", "price":"0.47", "size":"802", "side":"SELL", "hash":"04162d6472576274fafd9366627a56f421453c4e", "best_bid":"0.11", "best_ask":"0.12"}, {"asset_id":"20436996072316278452977393149218961565084965483366669504673105646378938504388", "price":"0.53", "size":"802", "side":"BUY", "hash":"78b4b22b8572c48d5cefcdedfcf2eb28a72f7fca", "best_bid":"0.88", "best_ask":"0.89"}], "timestamp":"1778784200310", "event_type":"price_change"}
{"market":"0x2a903c589141bce4a1e50fb98b73397af6820942542793ab10b1df477e912b6e", "price_changes":[{"asset_id":"68919878716222388542639225642064847629616106443780159680232863841946753372582", "price":"0.11", "size":"158.9", "side":"BUY", "hash":"9efdc33bfe22ab122f9a1888542c123769a58bb7", "best_bid":"0.11", "best_ask":"0.12"}, {"asset_id":"20436996072316278452977393149218961565084965483366669504673105646378938504388", "price":"0.89", "size":"158.9", "side":"SELL", "hash":"8b854d5975ff13ce98b9c55faa611ad43bcc3dac", "best_bid":"0.88", "best_ask":"0.89"}], "timestamp":"1778784200314", "event_type":"price_change"}
{"market":"0x2a903c589141bce4a1e50fb98b73397af6820942542793ab10b1df477e912b6e", "asset_id":"68919878716222388542639225642064847629616106443780159680232863841946753372582", "bids":[{"price":"0.01", "size":"11373.83"}, {"price":"0.02", "size":"1427.82"}, {"price":"0.03", "size":"1105.78"}, {"price":"0.04", "size":"837.82"}, {"price":"0.05", "size":"1055.72"}, {"price":"0.06", "size":"337.72"}, {"price":"0.07", "size":"337.1"}, {"price":"0.08", "size":"680.73"}, {"price":"0.09", "size":"298.11"}, {"price":"0.1", "size":"846.83"}, {"price":"0.11", "size":"158.9"}], "asks":[{"price":"0.99", "size":"12101.51"}, {"price":"0.98", "size":"1219.45"}, {"price":"0.97", "size":"1111.98"}, {"price":"0.96", "size":"670.05"}, {"price":"0.95", "size":"549.45"}, {"price":"0.94", "size":"346.2"}, {"price":"0.93", "size":"902.05"}, {"price":"0.92", "size":"170.79"}, {"price":"0.91", "size":"234.6"}, {"price":"0.9", "size":"128"}, {"price":"0.89", "size":"142.6"}, {"price":"0.88", "size":"141.8"}, {"price":"0.87", "size":"144.81"}, {"price":"0.86", "size":"204.9"}, {"price":"0.85", "size":"113.5"}, {"price":"0.84", "size":"102.3"}, {"price":"0.83", "size":"101.3"}, {"price":"0.82", "size":"105.3"}, {"price":"0.81", "size":"199.5"}, {"price":"0.8", "size":"103.8"}, {"price":"0.79", "size":"98.1"}, {"price":"0.78", "size":"97.5"}, {"price":"0.77", "size":"96.89"}, {"price":"0.76", "size":"201.39"}, {"price":"0.75", "size":"116"}, {"price":"0.74", "size":"100.6"}, {"price":"0.73", "size":"95.2"}, {"price":"0.72", "size":"94.9"}, {"price":"0.71", "size":"199.6"}, {"price":"0.7", "size":"94.3"}, {"price":"0.69", "size":"108.28"}, {"price":"0.68", "size":"98.8"}, {"price":"0.67", "size":"718.6"}, {"price":"0.66", "size":"898.4"}, {"price":"0.65", "size":"207.3"}, {"price":"0.64", "size":"293"}, {"price":"0.63", "size":"292.9"}, {"price":"0.62", "size":"897.7"}, {"price":"0.61", "size":"397.6"}, {"price":"0.6", "size":"356.93"}, {"price":"0.59", "size":"297.4"}, {"price":"0.58", "size":"109.6"}, {"price":"0.57", "size":"131.48"}, {"price":"0.56", "size":"413.97"}, {"price":"0.55", "size":"334.2"}, {"price":"0.54", "size":"375.6"}, {"price":"0.53", "size":"292"}, {"price":"0.52", "size":"292.12"}, {"price":"0.51", "size":"402"}, {"price":"0.5", "size":"355.91"}, {"price":"0.49", "size":"312"}, {"price":"0.48", "size":"317"}, {"price":"0.47", "size":"802"}, {"price":"0.46", "size":"607.1"}, {"price":"0.45", "size":"346.64"}, {"price":"0.44", "size":"337.45"}, {"price":"0.43", "size":"434.89"}, {"price":"0.42", "size":"724.36"}, {"price":"0.41", "size":"412.4"}, {"price":"0.4", "size":"328.83"}, {"price":"0.39", "size":"297.6"}, {"price":"0.38", "size":"618.44"}, {"price":"0.37", "size":"297.9"}, {"price":"0.36", "size":"208"}, {"price":"0.35", "size":"345.14"}, {"price":"0.34", "size":"355.9"}, {"price":"0.33", "size":"343.6"}, {"price":"0.32", "size":"2055.88"}, {"price":"0.31", "size":"559"}, {"price":"0.3", "size":"134.3"}, {"price":"0.29", "size":"316.38"}, {"price":"0.28", "size":"159.9"}, {"price":"0.27", "size":"165.2"}, {"price":"0.26", "size":"230.6"}, {"price":"0.25", "size":"356"}, {"price":"0.24", "size":"151.39"}, {"price":"0.23", "size":"126.89"}, {"price":"0.22", "size":"117.5"}, {"price":"0.21", "size":"175.44"}, {"price":"0.2", "size":"90"}, {"price":"0.19", "size":"72.35"}, {"price":"0.18", "size":"274.82"}, {"price":"0.15", "size":"6.67"}, {"price":"0.12", "size":"28.97"}], "hash":"9efdc33bfe22ab122f9a1888542c123769a58bb7", "timestamp":"1778784200314", "event_type":"book"}
{"market":"0x2a903c589141bce4a1e50fb98b73397af6820942542793ab10b1df477e912b6e", "price_changes":[{"asset_id":"20436996072316278452977393149218961565084965483366669504673105646378938504388", "price":"0.76", "size":"146.39", "side":"BUY", "hash":"8f17580e9d2a0f814d5435d964c6f26844874433", "best_bid":"0.88", "best_ask":"0.89"}, {"asset_id":"68919878716222388542639225642064847629616106443780159680232863841946753372582", "price":"0.24", "size":"146.39", "side":"SELL", "hash":"713b8cd9ad6b05578c19496d1741ff4a4db4fea9", "best_bid":"0.11", "best_ask":"0.12"}], "timestamp":"1778784200316", "event_type":"price_change"}
{"market":"0x2a903c589141bce4a1e50fb98b73397af6820942542793ab10b1df477e912b6e", "price_changes":[{"asset_id":"20436996072316278452977393149218961565084965483366669504673105646378938504388", "price":"0.91", "size":"307.7", "side":"SELL", "hash":"b6ad55ee2f5afcafb0e4262a30c0bffec82351b8", "best_bid":"0.88", "best_ask":"0.89"}, {"asset_id":"68919878716222388542639225642064847629616106443780159680232863841946753372582", "price":"0.09", "size":"307.7", "side":"BUY", "hash":"7ce2009586a205defe4b1106283af07c96a715d1", "best_bid":"0.11", "best_ask":"0.12"}], "timestamp":"1778784200318", "event_type":"price_change"}
{"market":"0x2a903c589141bce4a1e50fb98b73397af6820942542793ab10b1df477e912b6e", "price_changes":[{"asset_id":"68919878716222388542639225642064847629616106443780159680232863841946753372582", "price":"0.11", "size":"163.9", "side":"BUY", "hash":"8d336c607274c9cf8d934f0f0c9364a497c818f5", "best_bid":"0.11", "best_ask":"0.12"}, {"asset_id":"20436996072316278452977393149218961565084965483366669504673105646378938504388", "price":"0.89", "size":"163.9", "side":"SELL", "hash":"63caa59dccd76d4168d042153564305fe8de0009", "best_bid":"0.88", "best_ask":"0.89"}], "timestamp":"1778784200319", "event_type":"price_change"}
{"market":"0x2a903c589141bce4a1e50fb98b73397af6820942542793ab10b1df477e912b6e", "price_changes":[{"asset_id":"20436996072316278452977393149218961565084965483366669504673105646378938504388", "price":"0.75", "size":"656", "side":"BUY", "hash":"5adc9608fa89a7abccfd573e7586a54dfdceb8c4", "best_bid":"0.88", "best_ask":"0.89"}, {"asset_id":"68919878716222388542639225642064847629616106443780159680232863841946753372582", "price":"0.25", "size":"656", "side":"SELL", "hash":"afdeb28e93c58b37d2e8effde91ddae854a9381a", "best_bid":"0.11", "best_ask":"0.12"}], "timestamp":"1778784200320", "event_type":"price_change"}
{"market":"0x2a903c589141bce4a1e50fb98b73397af6820942542793ab10b1df477e912b6e", "price_changes":[{"asset_id":"68919878716222388542639225642064847629616106443780159680232863841946753372582", "price":"0.11", "size":"162.77", "side":"BUY", "hash":"96eda6c64c390834f354e9ac1e6929e76c9a7d5f", "best_bid":"0.11", "best_ask":"0.12"}, {"asset_id":"20436996072316278452977393149218961565084965483366669504673105646378938504388", "price":"0.89", "size":"162.77", "side":"SELL", "hash":"16f5e3479d5f201aa6d988e28a7f8c44914636bd", "best_bid":"0.88", "best_ask":"0.89"}], "timestamp":"1778784200323", "event_type":"price_change"}
{"market":"0x2a903c589141bce4a1e50fb98b73397af6820942542793ab10b1df477e912b6e", "asset_id":"68919878716222388542639225642064847629616106443780159680232863841946753372582", "bids":[{"price":"0.01", "size":"11373.83"}, {"price":"0.02", "size":"1427.82"}, {"price":"0.03", "size":"1105.78"}, {"price":"0.04", "size":"837.82"}, {"price":"0.05", "size":"1055.72"}, {"price":"0.06", "size":"337.72"}, {"price":"0.07", "size":"337.1"}, {"price":"0.08", "size":"680.73"}, {"price":"0.09", "size":"307.7"}, {"price":"0.1", "size":"846.83"}, {"price":"0.11", "size":"162.77"}], "asks":[{"price":"0.99", "size":"12101.51"}, {"price":"0.98", "size":"1219.45"}, {"price":"0.97", "size":"1111.98"}, {"price":"0.96", "size":"670.05"}, {"price":"0.95", "size":"549.45"}, {"price":"0.94", "size":"346.2"}, {"price":"0.93", "size":"902.05"}, {"price":"0.92", "size":"170.79"}, {"price":"0.91", "size":"234.6"}, {"price":"0.9", "size":"128"}, {"price":"0.89", "size":"142.6"}, {"price":"0.88", "size":"141.8"}, {"price":"0.87", "size":"144.81"}, {"price":"0.86", "size":"204.9"}, {"price":"0.85", "size":"113.5"}, {"price":"0.84", "size":"102.3"}, {"price":"0.83", "size":"101.3"}, {"price":"0.82", "size":"105.3"}, {"price":"0.81", "size":"199.5"}, {"price":"0.8", "size":"103.8"}, {"price":"0.79", "size":"98.1"}, {"price":"0.78", "size":"97.5"}, {"price":"0.77", "size":"96.89"}, {"price":"0.76", "size":"201.39"}, {"price":"0.75", "size":"116"}, {"price":"0.74", "size":"100.6"}, {"price":"0.73", "size":"95.2"}, {"price":"0.72", "size":"94.9"}, {"price":"0.71", "size":"199.6"}, {"price":"0.7", "size":"94.3"}, {"price":"0.69", "size":"108.28"}, {"price":"0.68", "size":"98.8"}, {"price":"0.67", "size":"718.6"}, {"price":"0.66", "size":"898.4"}, {"price":"0.65", "size":"207.3"}, {"price":"0.64", "size":"293"}, {"price":"0.63", "size":"292.9"}, {"price":"0.62", "size":"897.7"}, {"price":"0.61", "size":"397.6"}, {"price":"0.6", "size":"356.93"}, {"price":"0.59", "size":"297.4"}, {"price":"0.58", "size":"109.6"}, {"price":"0.57", "size":"131.48"}, {"price":"0.56", "size":"413.97"}, {"price":"0.55", "size":"334.2"}, {"price":"0.54", "size":"375.6"}, {"price":"0.53", "size":"292"}, {"price":"0.52", "size":"292.12"}, {"price":"0.51", "size":"402"}, {"price":"0.5", "size":"355.91"}, {"price":"0.49", "size":"312"}, {"price":"0.48", "size":"317"}, {"price":"0.47", "size":"802"}, {"price":"0.46", "size":"607.1"}, {"price":"0.45", "size":"346.64"}, {"price":"0.44", "size":"337.45"}, {"price":"0.43", "size":"434.89"}, {"price":"0.42", "size":"724.36"}, {"price":"0.41", "size":"412.4"}, {"price":"0.4", "size":"328.83"}, {"price":"0.39", "size":"297.6"}, {"price":"0.38", "size":"618.44"}, {"price":"0.37", "size":"297.9"}, {"price":"0.36", "size":"208"}, {"price":"0.35", "size":"345.14"}, {"price":"0.34", "size":"355.9"}, {"price":"0.33", "size":"343.6"}, {"price":"0.32", "size":"2055.88"}, {"price":"0.31", "size":"559"}, {"price":"0.3", "size":"134.3"}, {"price":"0.29", "size":"316.38"}, {"price":"0.28", "size":"159.9"}, {"price":"0.27", "size":"165.2"}, {"price":"0.26", "size":"230.6"}, {"price":"0.25", "size":"656"}, {"price":"0.24", "size":"146.39"}, {"price":"0.23", "size":"126.89"}, {"price":"0.22", "size":"117.5"}, {"price":"0.21", "size":"175.44"}, {"price":"0.2", "size":"90"}, {"price":"0.19", "size":"72.35"}, {"price":"0.18", "size":"274.82"}, {"price":"0.15", "size":"6.67"}, {"price":"0.12", "size":"28.97"}], "hash":"96eda6c64c390834f354e9ac1e6929e76c9a7d5f", "timestamp":"1778784200323", "event_type":"book"}
{"market":"0x2a903c589141bce4a1e50fb98b73397af6820942542793ab10b1df477e912b6e", "price_changes":[{"asset_id":"68919878716222388542639225642064847629616106443780159680232863841946753372582", "price":"0.11", "size":"157.77", "side":"BUY", "hash":"5c7fa03d3f9c0ccffb6c4db055869ae56e609099", "best_bid":"0.11", "best_ask":"0.12"}, {"asset_id":"20436996072316278452977393149218961565084965483366669504673105646378938504388", "price":"0.89", "size":"157.77", "side":"SELL", "hash":"ce496e44f0cf3c3d192ad23f960023d2fa496df4", "best_bid":"0.88", "best_ask":"0.89"}], "timestamp":"1778784200327", "event_type":"price_change"}
{"market":"0x2a903c589141bce4a1e50fb98b73397af6820942542793ab10b1df477e912b6e", "asset_id":"68919878716222388542639225642064847629616106443780159680232863841946753372582", "bids":[{"price":"0.01", "size":"11373.83"}, {"price":"0.02", "size":"1427.82"}, {"price":"0.03", "size":"1105.78"}, {"price":"0.04", "size":"837.82"}, {"price":"0.05", "size":"1055.72"}, {"price":"0.06", "size":"337.72"}, {"price":"0.07", "size":"337.1"}, {"price":"0.08", "size":"680.73"}, {"price":"0.09", "size":"307.7"}, {"price":"0.1", "size":"846.83"}, {"price":"0.11", "size":"157.77"}], "asks":[{"price":"0.99", "size":"12101.51"}, {"price":"0.98", "size":"1219.45"}, {"price":"0.97", "size":"1111.98"}, {"price":"0.96", "size":"670.05"}, {"price":"0.95", "size":"549.45"}, {"price":"0.94", "size":"346.2"}, {"price":"0.93", "size":"902.05"}, {"price":"0.92", "size":"170.79"}, {"price":"0.91", "size":"234.6"}, {"price":"0.9", "size":"128"}, {"price":"0.89", "size":"142.6"}, {"price":"0.88", "size":"141.8"}, {"price":"0.87", "size":"144.81"}, {"price":"0.86", "size":"204.9"}, {"price":"0.85", "size":"113.5"}, {"price":"0.84", "size":"102.3"}, {"price":"0.83", "size":"101.3"}, {"price":"0.82", "size":"105.3"}, {"price":"0.81", "size":"199.5"}, {"price":"0.8", "size":"103.8"}, {"price":"0.79", "size":"98.1"}, {"price":"0.78", "size":"97.5"}, {"price":"0.77", "size":"96.89"}, {"price":"0.76", "size":"201.39"}, {"price":"0.75", "size":"116"}, {"price":"0.74", "size":"100.6"}, {"price":"0.73", "size":"95.2"}, {"price":"0.72", "size":"94.9"}, {"price":"0.71", "size":"199.6"}, {"price":"0.7", "size":"94.3"}, {"price":"0.69", "size":"108.28"}, {"price":"0.68", "size":"98.8"}, {"price":"0.67", "size":"718.6"}, {"price":"0.66", "size":"898.4"}, {"price":"0.65", "size":"207.3"}, {"price":"0.64", "size":"293"}, {"price":"0.63", "size":"292.9"}, {"price":"0.62", "size":"897.7"}, {"price":"0.61", "size":"397.6"}, {"price":"0.6", "size":"356.93"}, {"price":"0.59", "size":"297.4"}, {"price":"0.58", "size":"109.6"}, {"price":"0.57", "size":"131.48"}, {"price":"0.56", "size":"413.97"}, {"price":"0.55", "size":"334.2"}, {"price":"0.54", "size":"375.6"}, {"price":"0.53", "size":"292"}, {"price":"0.52", "size":"292.12"}, {"price":"0.51", "size":"402"}, {"price":"0.5", "size":"355.91"}, {"price":"0.49", "size":"312"}, {"price":"0.48", "size":"317"}, {"price":"0.47", "size":"802"}, {"price":"0.46", "size":"607.1"}, {"price":"0.45", "size":"346.64"}, {"price":"0.44", "size":"337.45"}, {"price":"0.43", "size":"434.89"}, {"price":"0.42", "size":"724.36"}, {"price":"0.41", "size":"412.4"}, {"price":"0.4", "size":"328.83"}, {"price":"0.39", "size":"297.6"}, {"price":"0.38", "size":"618.44"}, {"price":"0.37", "size":"297.9"}, {"price":"0.36", "size":"208"}, {"price":"0.35", "size":"345.14"}, {"price":"0.34", "size":"355.9"}, {"price":"0.33", "size":"343.6"}, {"price":"0.32", "size":"2055.88"}, {"price":"0.31", "size":"559"}, {"price":"0.3", "size":"134.3"}, {"price":"0.29", "size":"316.38"}, {"price":"0.28", "size":"159.9"}, {"price":"0.27", "size":"165.2"}, {"price":"0.26", "size":"230.6"}, {"price":"0.25", "size":"656"}, {"price":"0.24", "size":"146.39"}, {"price":"0.23", "size":"126.89"}, {"price":"0.22", "size":"117.5"}, {"price":"0.21", "size":"175.44"}, {"price":"0.2", "size":"90"}, {"price":"0.19", "size":"72.35"}, {"price":"0.18", "size":"274.82"}, {"price":"0.15", "size":"6.67"}, {"price":"0.12", "size":"28.97"}], "hash":"5c7fa03d3f9c0ccffb6c4db055869ae56e609099", "timestamp":"1778784200327", "event_type":"book"}
{"market":"0x2a903c589141bce4a1e50fb98b73397af6820942542793ab10b1df477e912b6e", "price_changes":[{"asset_id":"68919878716222388542639225642064847629616106443780159680232863841946753372582", "price":"0.11", "size":"148.25", "side":"BUY", "hash":"b28bc47f909c7936a9b55a5310f6d2be88acd442", "best_bid":"0.11", "best_ask":"0.12"}, {"asset_id":"20436996072316278452977393149218961565084965483366669504673105646378938504388", "price":"0.89", "size":"148.25", "side":"SELL", "hash":"62badeb57acc972777f1ae5c02241969a413ccde", "best_bid":"0.88", "best_ask":"0.89"}], "timestamp":"1778784200332", "event_type":"price_change"}
{"market":"0x2a903c589141bce4a1e50fb98b73397af6820942542793ab10b1df477e912b6e", "asset_id":"68919878716222388542639225642064847629616106443780159680232863841946753372582", "bids":[{"price":"0.01", "size":"11373.83"}, {"price":"0.02", "size":"1427.82"}, {"price":"0.03", "size":"1105.78"}, {"price":"0.04", "size":"837.82"}, {"price":"0.05", "size":"1055.72"}, {"price":"0.06", "size":"337.72"}, {"price":"0.07", "size":"337.1"}, {"price":"0.08", "size":"680.73"}, {"price":"0.09", "size":"307.7"}, {"price":"0.1", "size":"846.83"}, {"price":"0.11", "size":"148.25"}], "asks":[{"price":"0.99", "size":"12101.51"}, {"price":"0.98", "size":"1219.45"}, {"price":"0.97", "size":"1111.98"}, {"price":"0.96", "size":"670.05"}, {"price":"0.95", "size":"549.45"}, {"price":"0.94", "size":"346.2"}, {"price":"0.93", "size":"902.05"}, {"price":"0.92", "size":"170.79"}, {"price":"0.91", "size":"234.6"}, {"price":"0.9", "size":"128"}, {"price":"0.89", "size":"142.6"}, {"price":"0.88", "size":"141.8"}, {"price":"0.87", "size":"144.81"}, {"price":"0.86", "size":"204.9"}, {"price":"0.85", "size":"113.5"}, {"price":"0.84", "size":"102.3"}, {"price":"0.83", "size":"101.3"}, {"price":"0.82", "size":"105.3"}, {"price":"0.81", "size":"199.5"}, {"price":"0.8", "size":"103.8"}, {"price":"0.79", "size":"98.1"}, {"price":"0.78", "size":"97.5"}, {"price":"0.77", "size":"96.89"}, {"price":"0.76", "size":"201.39"}, {"price":"0.75", "size":"116"}, {"price":"0.74", "size":"100.6"}, {"price":"0.73", "size":"95.2"}, {"price":"0.72", "size":"94.9"}, {"price":"0.71", "size":"199.6"}, {"price":"0.7", "size":"94.3"}, {"price":"0.69", "size":"108.28"}, {"price":"0.68", "size":"98.8"}, {"price":"0.67", "size":"718.6"}, {"price":"0.66", "size":"898.4"}, {"price":"0.65", "size":"207.3"}, {"price":"0.64", "size":"293"}, {"price":"0.63", "size":"292.9"}, {"price":"0.62", "size":"897.7"}, {"price":"0.61", "size":"397.6"}, {"price":"0.6", "size":"356.93"}, {"price":"0.59", "size":"297.4"}, {"price":"0.58", "size":"109.6"}, {"price":"0.57", "size":"131.48"}, {"price":"0.56", "size":"413.97"}, {"price":"0.55", "size":"334.2"}, {"price":"0.54", "size":"375.6"}, {"price":"0.53", "size":"292"}, {"price":"0.52", "size":"292.12"}, {"price":"0.51", "size":"402"}, {"price":"0.5", "size":"355.91"}, {"price":"0.49", "size":"312"}, {"price":"0.48", "size":"317"}, {"price":"0.47", "size":"802"}, {"price":"0.46", "size":"607.1"}, {"price":"0.45", "size":"346.64"}, {"price":"0.44", "size":"337.45"}, {"price":"0.43", "size":"434.89"}, {"price":"0.42", "size":"724.36"}, {"price":"0.41", "size":"412.4"}, {"price":"0.4", "size":"328.83"}, {"price":"0.39", "size":"297.6"}, {"price":"0.38", "size":"618.44"}, {"price":"0.37", "size":"297.9"}, {"price":"0.36", "size":"208"}, {"price":"0.35", "size":"345.14"}, {"price":"0.34", "size":"355.9"}, {"price":"0.33", "size":"343.6"}, {"price":"0.32", "size":"2055.88"}, {"price":"0.31", "size":"559"}, {"price":"0.3", "size":"134.3"}, {"price":"0.29", "size":"316.38"}, {"price":"0.28", "size":"159.9"}, {"price":"0.27", "size":"165.2"}, {"price":"0.26", "size":"230.6"}, {"price":"0.25", "size":"656"}, {"price":"0.24", "size":"146.39"}, {"price":"0.23", "size":"126.89"}, {"price":"0.22", "size":"117.5"}, {"price":"0.21", "size":"175.44"}, {"price":"0.2", "size":"90"}, {"price":"0.19", "size":"72.35"}, {"price":"0.18", "size":"274.82"}, {"price":"0.15", "size":"6.67"}, {"price":"0.12", "size":"28.97"}], "hash":"b28bc47f909c7936a9b55a5310f6d2be88acd442", "timestamp":"1778784200332", "event_type":"book"}
{"market":"0x2a903c589141bce4a1e50fb98b73397af6820942542793ab10b1df477e912b6e", "price_changes":[{"asset_id":"68919878716222388542639225642064847629616106443780159680232863841946753372582", "price":"0.11", "size":"146.77", "side":"BUY", "hash":"fb9f879416f872fb1186a7dfe4e9b6d21393ccc9", "best_bid":"0.11", "best_ask":"0.12"}, {"asset_id":"20436996072316278452977393149218961565084965483366669504673105646378938504388", "price":"0.89", "size":"146.77", "side":"SELL", "hash":"b324c5a4c6fc28776a943bcbc7380ac09f39d483", "best_bid":"0.88", "best_ask":"0.89"}], "timestamp":"1778784200334", "event_type":"price_change"}
{"market":"0x2a903c589141bce4a1e50fb98b73397af6820942542793ab10b1df477e912b6e", "asset_id":"68919878716222388542639225642064847629616106443780159680232863841946753372582", "bids":[{"price":"0.01", "size":"11373.83"}, {"price":"0.02", "size":"1427.82"}, {"price":"0.03", "size":"1105.78"}, {"price":"0.04", "size":"837.82"}, {"price":"0.05", "size":"1055.72"}, {"price":"0.06", "size":"337.72"}, {"price":"0.07", "size":"337.1"}, {"price":"0.08", "size":"680.73"}, {"price":"0.09", "size":"307.7"}, {"price":"0.1", "size":"846.83"}, {"price":"0.11", "size":"146.77"}], "asks":[{"price":"0.99", "size":"12101.51"}, {"price":"0.98", "size":"1219.45"}, {"price":"0.97", "size":"1111.98"}, {"price":"0.96", "size":"670.05"}, {"price":"0.95", "size":"549.45"}, {"price":"0.94", "size":"346.2"}, {"price":"0.93", "size":"902.05"}, {"price":"0.92", "size":"170.79"}, {"price":"0.91", "size":"234.6"}, {"price":"0.9", "size":"128"}, {"price":"0.89", "size":"142.6"}, {"price":"0.88", "size":"141.8"}, {"price":"0.87", "size":"144.81"}, {"price":"0.86", "size":"204.9"}, {"price":"0.85", "size":"113.5"}, {"price":"0.84", "size":"102.3"}, {"price":"0.83", "size":"101.3"}, {"price":"0.82", "size":"105.3"}, {"price":"0.81", "size":"199.5"}, {"price":"0.8", "size":"103.8"}, {"price":"0.79", "size":"98.1"}, {"price":"0.78", "size":"97.5"}, {"price":"0.77", "size":"96.89"}, {"price":"0.76", "size":"201.39"}, {"price":"0.75", "size":"116"}, {"price":"0.74", "size":"100.6"}, {"price":"0.73", "size":"95.2"}, {"price":"0.72", "size":"94.9"}, {"price":"0.71", "size":"199.6"}, {"price":"0.7", "size":"94.3"}, {"price":"0.69", "size":"108.28"}, {"price":"0.68", "size":"98.8"}, {"price":"0.67", "size":"718.6"}, {"price":"0.66", "size":"898.4"}, {"price":"0.65", "size":"207.3"}, {"price":"0.64", "size":"293"}, {"price":"0.63", "size":"292.9"}, {"price":"0.62", "size":"897.7"}, {"price":"0.61", "size":"397.6"}, {"price":"0.6", "size":"356.93"}, {"price":"0.59", "size":"297.4"}, {"price":"0.58", "size":"109.6"}, {"price":"0.57", "size":"131.48"}, {"price":"0.56", "size":"413.97"}, {"price":"0.55", "size":"334.2"}, {"price":"0.54", "size":"375.6"}, {"price":"0.53", "size":"292"}, {"price":"0.52", "size":"292.12"}, {"price":"0.51", "size":"402"}, {"price":"0.5", "size":"355.91"}, {"price":"0.49", "size":"312"}, {"price":"0.48", "size":"317"}, {"price":"0.47", "size":"802"}, {"price":"0.46", "size":"607.1"}, {"price":"0.45", "size":"346.64"}, {"price":"0.44", "size":"337.45"}, {"price":"0.43", "size":"434.89"}, {"price":"0.42", "size":"724.36"}, {"price":"0.41", "size":"412.4"}, {"price":"0.4", "size":"328.83"}, {"price":"0.39", "size":"297.6"}, {"price":"0.38", "size":"618.44"}, {"price":"0.37", "size":"297.9"}, {"price":"0.36", "size":"208"}, {"price":"0.35", "size":"345.14"}, {"price":"0.34", "size":"355.9"}, {"price":"0.33", "size":"343.6"}, {"price":"0.32", "size":"2055.88"}, {"price":"0.31", "size":"559"}, {"price":"0.3", "size":"134.3"}, {"price":"0.29", "size":"316.38"}, {"price":"0.28", "size":"159.9"}, {"price":"0.27", "size":"165.2"}, {"price":"0.26", "size":"230.6"}, {"price":"0.25", "size":"656"}, {"price":"0.24", "size":"146.39"}, {"price":"0.23", "size":"126.89"}, {"price":"0.22", "size":"117.5"}, {"price":"0.21", "size":"175.44"}, {"price":"0.2", "size":"90"}, {"price":"0.19", "size":"72.35"}, {"price":"0.18", "size":"274.82"}, {"price":"0.15", "size":"6.67"}, {"price":"0.12", "size":"28.97"}], "hash":"fb9f879416f872fb1186a7dfe4e9b6d21393ccc9", "timestamp":"1778784200334", "event_type":"book"}
{"market":"0x2a903c589141bce4a1e50fb98b73397af6820942542793ab10b1df477e912b6e", "price_changes":[{"asset_id":"20436996072316278452977393149218961565084965483366669504673105646378938504388", "price":"0.35", "size":"307.3", "side":"BUY", "hash":"7c1a1071067bc4e78a26be3150705a6b7cb85458", "best_bid":"0.88", "best_ask":"0.89"}, {"asset_id":"68919878716222388542639225642064847629616106443780159680232863841946753372582", "price":"0.65", "size":"307.3", "side":"SELL", "hash":"ff74ecd1700adf121e87265e948199bcd9d78c80", "best_bid":"0.11", "best_ask":"0.12"}], "timestamp":"1778784200336", "event_type":"price_change"}
{"market":"0x2a903c589141bce4a1e50fb98b73397af6820942542793ab10b1df477e912b6e", "price_changes":[{"asset_id":"20436996072316278452977393149218961565084965483366669504673105646378938504388", "price":"0.83", "size":"30", "side":"BUY", "hash":"e6d099810be9e5801e4d7e5a40483146465c7d44", "best_bid":"0.88", "best_ask":"0.89"}, {"asset_id":"68919878716222388542639225642064847629616106443780159680232863841946753372582", "price":"0.17", "size":"30", "side":"SELL", "hash":"bebd547c8e2d5128b840c36bf74462690f42bfd8", "best_bid":"0.11", "best_ask":"0.12"}], "timestamp":"1778784200338", "event_type":"price_change"}
{"market":"0x2a903c589141bce4a1e50fb98b73397af6820942542793ab10b1df477e912b6e", "price_changes":[{"asset_id":"68919878716222388542639225642064847629616106443780159680232863841946753372582", "price":"0.11", "size":"140.02", "side":"BUY", "hash":"0261a9e81b336ba41600c05b20f4fe4c906a21c4", "best_bid":"0.11", "best_ask":"0.12"}, {"asset_id":"20436996072316278452977393149218961565084965483366669504673105646378938504388", "price":"0.89", "size":"140.02", "side":"SELL", "hash":"1de2bf3d4dc7d8fdb6ae2940322f932361fc4ccc", "best_bid":"0.88", "best_ask":"0.89"}], "timestamp":"1778784200341", "event_type":"price_change"}
{"market":"0x2a903c589141bce4a1e50fb98b73397af6820942542793ab10b1df477e912b6e", "asset_id":"68919878716222388542639225642064847629616106443780159680232863841946753372582", "bids":[{"price":"0.01", "size":"11373.83"}, {"price":"0.02", "size":"1427.82"}, {"price":"0.03", "size":"1105.78"}, {"price":"0.04", "size":"837.82"}, {"price":"0.05", "size":"1055.72"}, {"price":"0.06", "size":"337.72"}, {"price":"0.07", "size":"337.1"}, {"price":"0.08", "size":"680.73"}, {"price":"0.09", "size":"307.7"}, {"price":"0.1", "size":"846.83"}, {"price":"0.11", "size":"140.02"}], "asks":[{"price":"0.99", "size":"12101.51"}, {"price":"0.98", "size":"1219.45"}, {"price":"0.97", "size":"1111.98"}, {"price":"0.96", "size":"670.05"}, {"price":"0.95", "size":"549.45"}, {"price":"0.94", "size":"346.2"}, {"price":"0.93", "size":"902.05"}, {"price":"0.92", "size":"170.79"}, {"price":"0.91", "size":"234.6"}, {"price":"0.9", "size":"128"}, {"price":"0.89", "size":"142.6"}, {"price":"0.88", "size":"141.8"}, {"price":"0.87", "size":"144.81"}, {"price":"0.86", "size":"204.9"}, {"price":"0.85", "size":"113.5"}, {"price":"0.84", "size":"102.3"}, {"price":"0.83", "size":"101.3"}, {"price":"0.82", "size":"105.3"}, {"price":"0.81", "size":"199.5"}, {"price":"0.8", "size":"103.8"}, {"price":"0.79", "size":"98.1"}, {"price":"0.78", "size":"97.5"}, {"price":"0.77", "size":"96.89"}, {"price":"0.76", "size":"201.39"}, {"price":"0.75", "size":"116"}, {"price":"0.74", "size":"100.6"}, {"price":"0.73", "size":"95.2"}, {"price":"0.72", "size":"94.9"}, {"price":"0.71", "size":"199.6"}, {"price":"0.7", "size":"94.3"}, {"price":"0.69", "size":"108.28"}, {"price":"0.68", "size":"98.8"}, {"price":"0.67", "size":"718.6"}, {"price":"0.66", "size":"898.4"}, {"price":"0.65", "size":"307.3"}, {"price":"0.64", "size":"293"}, {"price":"0.63", "size":"292.9"}, {"price":"0.62", "size":"897.7"}, {"price":"0.61", "size":"397.6"}, {"price":"0.6", "size":"356.93"}, {"price":"0.59", "size":"297.4"}, {"price":"0.58", "size":"109.6"}, {"price":"0.57", "size":"131.48"}, {"price":"0.56", "size":"413.97"}, {"price":"0.55", "size":"334.2"}, {"price":"0.54", "size":"375.6"}, {"price":"0.53", "size":"292"}, {"price":"0.52", "size":"292.12"}, {"price":"0.51", "size":"402"}, {"price":"0.5", "size":"355.91"}, {"price":"0.49", "size":"312"}, {"price":"0.48", "size":"317"}, {"price":"0.47", "size":"802"}, {"price":"0.46", "size":"607.1"}, {"price":"0.45", "size":"346.64"}, {"price":"0.44", "size":"337.45"}, {"price":"0.43", "size":"434.89"}, {"price":"0.42", "size":"724.36"}, {"price":"0.41", "size":"412.4"}, {"price":"0.4", "size":"328.83"}, {"price":"0.39", "size":"297.6"}, {"price":"0.38", "size":"618.44"}, {"price":"0.37", "size":"297.9"}, {"price":"0.36", "size":"208"}, {"price":"0.35", "size":"345.14"}, {"price":"0.34", "size":"355.9"}, {"price":"0.33", "size":"343.6"}, {"price":"0.32", "size":"2055.88"}, {"price":"0.31", "size":"559"}, {"price":"0.3", "size":"134.3"}, {"price":"0.29", "size":"316.38"}, {"price":"0.28", "size":"159.9"}, {"price":"0.27", "size":"165.2"}, {"price":"0.26", "size":"230.6"}, {"price":"0.25", "size":"656"}, {"price":"0.24", "size":"146.39"}, {"price":"0.23", "size":"126.89"}, {"price":"0.22", "size":"117.5"}, {"price":"0.21", "size":"175.44"}, {"price":"0.2", "size":"90"}, {"price":"0.19", "size":"72.35"}, {"price":"0.18", "size":"274.82"}, {"price":"0.17", "size":"30"}, {"price":"0.15", "size":"6.67"}, {"price":"0.12", "size":"28.97"}], "hash":"0261a9e81b336ba41600c05b20f4fe4c906a21c4", "timestamp":"1778784200341", "event_type":"book"}
{"market":"0x2a903c589141bce4a1e50fb98b73397af6820942542793ab10b1df477e912b6e", "price_changes":[{"asset_id":"20436996072316278452977393149218961565084965483366669504673105646378938504388", "price":"0.34", "size":"998.4", "side":"BUY", "hash":"f533aec692879922756a373e803d777d35f8491b", "best_bid":"0.88", "best_ask":"0.89"}, {"asset_id":"68919878716222388542639225642064847629616106443780159680232863841946753372582", "price":"0.66", "size":"998.4", "side":"SELL", "hash":"a242c350e15e661eb5426b6ca6781b9d75f219ee", "best_bid":"0.11", "best_ask":"0.12"}], "timestamp":"1778784200343", "event_type":"price_change"}
{"market":"0x2a903c589141bce4a1e50fb98b73397af6820942542793ab10b1df477e912b6e", "price_changes":[{"asset_id":"20436996072316278452977393149218961565084965483366669504673105646378938504388", "price":"0.84", "size":"100", "side":"BUY", "hash":"a936d1ef7c0c2bd891055f2acb58f6b5ea26199d", "best_bid":"0.88", "best_ask":"0.89"}, {"asset_id":"68919878716222388542639225642064847629616106443780159680232863841946753372582", "price":"0.16", "size":"100", "side":"SELL", "hash":"cca1dd190050adf42d6d73d0867feed17b588aae", "best_bid":"0.11", "best_ask":"0.12"}], "timestamp":"1778784200344", "event_type":"price_change"}
{"market":"0x2a903c589141bce4a1e50fb98b73397af6820942542793ab10b1df477e912b6e", "price_changes":[{"asset_id":"68919878716222388542639225642064847629616106443780159680232863841946753372582", "price":"0.09", "size":"312.7", "side":"BUY", "hash":"36af705249f58c482a0bae9062691587e83cf75c", "best_bid":"0.11", "best_ask":"0.12"}, {"asset_id":"20436996072316278452977393149218961565084965483366669504673105646378938504388", "price":"0.91", "size":"312.7", "side":"SELL", "hash":"669b1db0b49c3005a3255c0690d8a39d635da0af", "best_bid":"0.88", "best_ask":"0.89"}], "timestamp":"1778784200346", "event_type":"price_change"}
{"market":"0x2a903c589141bce4a1e50fb98b73397af6820942542793ab10b1df477e912b6e", "price_changes":[{"asset_id":"20436996072316278452977393149218961565084965483366669504673105646378938504388", "price":"0.89", "size":"165.02", "side":"SELL", "hash":"5e2cce557ae0a31b627753da5af946605a8efb20", "best_bid":"0.88", "best_ask":"0.89"}, {"asset_id":"68919878716222388542639225642064847629616106443780159680232863841946753372582", "price":"0.11", "size":"165.02", "side":"BUY", "hash":"f2e89d51d6cb70078168162ea74b8f33c4518ba2", "best_bid":"0.11", "best_ask":"0.12"}], "timestamp":"1778784200347", "event_type":"price_change"}
{"market":"0x2a903c589141bce4a1e50fb98b73397af6820942542793ab10b1df477e912b6e", "price_changes":[{"asset_id":"20436996072316278452977393149218961565084965483366669504673105646378938504388", "price":"0.35", "size":"407.3", "side":"BUY", "hash":"af58750d382d3b5d7518809d7aaa66d11bb64482", "best_bid":"0.88", "best_ask":"0.89"}, {"asset_id":"68919878716222388542639225642064847629616106443780159680232863841946753372582", "price":"0.65", "size":"407.3", "side":"SELL", "hash":"534a1538fa3cc5783815e0d3f320a072bb8511a6", "best_bid":"0.11", "best_ask":"0.12"}], "timestamp":"1778784200348", "event_type":"price_change"}
{"market":"0x2a903c589141bce4a1e50fb98b73397af6820942542793ab10b1df477e912b6e", "price_changes":[{"asset_id":"68919878716222388542639225642064847629616106443780159680232863841946753372582", "price":"0.23", "size":"151.89", "side":"SELL", "hash":"6b9e8d0a272be35899398a6b432b2477828b5ac8", "best_bid":"0.11", "best_ask":"0.12"}, {"asset_id":"20436996072316278452977393149218961565084965483366669504673105646378938504388", "price":"0.77", "size":"151.89", "side":"BUY", "hash":"066f063abdc7faeaf1ff96d08e1f8373bf736cbf", "best_bid":"0.88", "best_ask":"0.89"}], "timestamp":"1778784200350", "event_type":"price_change"}
{"market":"0x2a903c589141bce4a1e50fb98b73397af6820942542793ab10b1df477e912b6e", "price_changes":[{"asset_id":"20436996072316278452977393149218961565084965483366669504673105646378938504388", "price":"0.35", "size":"507.3", "side":"BUY", "hash":"55f68c60b2950ac08dde102f519bd40508dd33ca", "best_bid":"0.88", "best_ask":"0.89"}, {"asset_id":"68919878716222388542639225642064847629616106443780159680232863841946753372582", "price":"0.65", "size":"507.3", "side":"SELL", "hash":"cf18424dc76a1d9107f52b9e0b5d51d5a324f5cf", "best_bid":"0.11", "best_ask":"0.12"}], "timestamp":"1778784200351", "event_type":"price_change"}
{"market":"0x2a903c589141bce4a1e50fb98b73397af6820942542793ab10b1df477e912b6e", "asset_id":"68919878716222388542639225642064847629616106443780159680232863841946753372582", "price":"0.11", "size":"9.52", "fee_rate_bps":"0", "side":"SELL", "timestamp":"1778784200352", "event_type":"last_trade_price", "transaction_hash":"0x056715cff9c8c77225f10f2db29db6babb4c10773314e37fcef97b42e59e5413"}
{"market":"0x2a903c589141bce4a1e50fb98b73397af6820942542793ab10b1df477e912b6e", "price_changes":[{"asset_id":"20436996072316278452977393149218961565084965483366669504673105646378938504388", "price":"0.87", "size":"5", "side":"BUY", "hash":"7909d873da419772d4e3aab81135978a058cbc07", "best_bid":"0.88", "best_ask":"0.89"}, {"asset_id":"68919878716222388542639225642064847629616106443780159680232863841946753372582", "price":"0.13", "size":"5", "side":"SELL", "hash":"9d7a2c8f633f6d1f2db88a8628650e3c7096ed17", "best_bid":"0.11", "best_ask":"0.12"}], "timestamp":"1778784200353", "event_type":"price_change"}
{"market":"0x2a903c589141bce4a1e50fb98b73397af6820942542793ab10b1df477e912b6e", "price_changes":[{"asset_id":"20436996072316278452977393149218961565084965483366669504673105646378938504388", "price":"0.54", "size":"651.54", "side":"BUY", "hash":"cb0c4fbaff953a74966938fe37146949d2c24281", "best_bid":"0.88", "best_ask":"0.89"}, {"asset_id":"68919878716222388542639225642064847629616106443780159680232863841946753372582", "price":"0.46", "size":"651.54", "side":"SELL", "hash":"253531626c19d9e92ca6c73eec7468f2a70cca2d", "best_bid":"0.11", "best_ask":"0.12"}], "timestamp":"1778784200356", "event_type":"price_change"}
{"market":"0x2a903c589141bce4a1e50fb98b73397af6820942542793ab10b1df477e912b6e", "price_changes":[{"asset_id":"20436996072316278452977393149218961565084965483366669504673105646378938504388", "price":"0.9", "size":"694.26", "side":"SELL", "hash":"8248073aa38783cef022ed7d1462dc6f8de0640e", "best_bid":"0.88", "best_ask":"0.89"}, {"asset_id":"68919878716222388542639225642064847629616106443780159680232863841946753372582", "price":"0.1", "size":"694.26", "side":"BUY", "hash":"5b1f2a61d2613056caddd947df669774eccc1d90", "best_bid":"0.11", "best_ask":"0.12"}], "timestamp":"1778784200361", "event_type":"price_change"}
{"market":"0x2a903c589141bce4a1e50fb98b73397af6820942542793ab10b1df477e912b6e", "price_changes":[{"asset_id":"68919878716222388542639225642064847629616106443780159680232863841946753372582", "price":"0.11", "size":"295.41", "side":"BUY", "hash":"1dcd579c408d94a1f12c6a3d315b096ef1f1d75e", "best_bid":"0.11", "best_ask":"0.12"}, {"asset_id":"20436996072316278452977393149218961565084965483366669504673105646378938504388", "price":"0.89", "size":"295.41", "side":"SELL", "hash":"d50ada5d450f29e03ed95aabeb1aac47dd64b3d3", "best_bid":"0.88", "best_ask":"0.89"}], "timestamp":"1778784200362", "event_type":"price_change"}
{"market":"0x2a903c589141bce4a1e50fb98b73397af6820942542793ab10b1df477e912b6e", "price_changes":[{"asset_id":"20436996072316278452977393149218961565084965483366669504673105646378938504388", "price":"0.85", "size":"31.67", "side":"BUY", "hash":"ea9a8e336922400a9a8ba03bc619db3afb30a19d", "best_bid":"0.88", "best_ask":"0.89"}, {"asset_id":"68919878716222388542639225642064847629616106443780159680232863841946753372582", "price":"0.15", "size":"31.67", "side":"SELL", "hash":"aa982f30cc8b5dbb586b840d78845804e331b9ce", "best_bid":"0.11", "best_ask":"0.12"}], "timestamp":"1778784200363", "event_type":"price_change"}
{"market":"0x2a903c589141bce4a1e50fb98b73397af6820942542793ab10b1df477e912b6e", "price_changes":[{"asset_id":"68919878716222388542639225642064847629616106443780159680232863841946753372582", "price":"0.1", "size":"631.26", "side":"BUY", "hash":"b9a6fa770a9a7b2950dc95addf5624eee47877ae", "best_bid":"0.11", "best_ask":"0.12"}, {"asset_id":"20436996072316278452977393149218961565084965483366669504673105646378938504388", "price":"0.9", "size":"631.26", "side":"SELL", "hash":"c212bdc879f716ac845424f6daadccec37c2f519", "best_bid":"0.88", "best_ask":"0.89"}], "timestamp":"1778784200364", "event_type":"price_change"}
{"market":"0x2a903c589141bce4a1e50fb98b73397af6820942542793ab10b1df477e912b6e", "price_changes":[{"asset_id":"68919878716222388542639225642064847629616106443780159680232863841946753372582", "price":"0.01", "size":"11378.83", "side":"BUY", "hash":"7b22f02464ff9cda85b37050c9fdff348a7ee1f5", "best_bid":"0.11", "best_ask":"0.12"}, {"asset_id":"20436996072316278452977393149218961565084965483366669504673105646378938504388", "price":"0.99", "size":"11378.83", "side":"SELL", "hash":"457668839da0ea992cf49f0dfd5e25cd3b7a7d64", "best_bid":"0.88", "best_ask":"0.89"}], "timestamp":"1778784200365", "event_type":"price_change"}
{"market":"0x2a903c589141bce4a1e50fb98b73397af6820942542793ab10b1df477e912b6e", "price_changes":[{"asset_id":"68919878716222388542639225642064847629616106443780159680232863841946753372582", "price":"0.11", "size":"300.41", "side":"BUY", "hash":"e1840cf8d2d0b93af374afe2c49bd51e792cf902", "best_bid":"0.11", "best_ask":"0.12"}, {"asset_id":"20436996072316278452977393149218961565084965483366669504673105646378938504388", "price":"0.89", "size":"300.41", "side":"SELL", "hash":"84bdd5279917cd512bc1c44fb4b7b81c00d886a7", "best_bid":"0.88", "best_ask":"0.89"}], "timestamp":"1778784200366", "event_type":"price_change"}
{"market":"0x2a903c589141bce4a1e50fb98b73397af6820942542793ab10b1df477e912b6e", "price_changes":[{"asset_id":"20436996072316278452977393149218961565084965483366669504673105646378938504388", "price":"0.79", "size":"215.44", "side":"BUY", "hash":"4cad3b8e23287745a3073490bd13854daaa9cbb9", "best_bid":"0.88", "best_ask":"0.89"}, {"asset_id":"68919878716222388542639225642064847629616106443780159680232863841946753372582", "price":"0.21", "size":"215.44", "side":"SELL", "hash":"0aad20621a51af07abf4e038b950a2d503441063", "best_bid":"0.11", "best_ask":"0.12"}], "timestamp":"1778784200367", "event_type":"price_change"}
{"market":"0x2a903c589141bce4a1e50fb98b73397af6820942542793ab10b1df477e912b6e", "price_changes":[{"asset_id":"20436996072316278452977393149218961565084965483366669504673105646378938504388", "price":"0.8", "size":"110", "side":"BUY", "hash":"7329b880cc34b845ba670f8b17ed4063205cb463", "best_bid":"0.88", "best_ask":"0.89"}, {"asset_id":"68919878716222388542639225642064847629616106443780159680232863841946753372582", "price":"0.2", "size":"110", "side":"SELL", "hash":"c317c9671ed58fcff5b9e400984987d72838dc00", "best_bid":"0.11", "best_ask":"0.12"}], "timestamp":"1778784200369", "event_type":"price_change"}
{"market":"0x2a903c589141bce4a1e50fb98b73397af6820942542793ab10b1df477e912b6e", "price_changes":[{"asset_id":"20436996072316278452977393149218961565084965483366669504673105646378938504388", "price":"0.77", "size":"191.89", "side":"BUY", "hash":"9dfdbf2039fcd3a91a42931438634432a1904b7c", "best_bid":"0.88", "best_ask":"0.89"}, {"asset_id":"68919878716222388542639225642064847629616106443780159680232863841946753372582", "price":"0.23", "size":"191.89", "side":"SELL", "hash":"4d33c098c71613089a3392a31bd619b37f9dbee3", "best_bid":"0.11", "best_ask":"0.12"}], "timestamp":"1778784200371", "event_type":"price_change"}
{"market":"0x2a903c589141bce4a1e50fb98b73397af6820942542793ab10b1df477e912b6e", "price_changes":[{"asset_id":"20436996072316278452977393149218961565084965483366669504673105646378938504388", "price":"0.88", "size":"18.13", "side":"BUY", "hash":"27eeab74cfd78b04f224fde162451738794163b1", "best_bid":"0.88", "best_ask":"0.89"}, {"asset_id":"68919878716222388542639225642064847629616106443780159680232863841946753372582", "price":"0.12", "size":"18.13", "side":"SELL", "hash":"10d2823c6e261296c58ae16f6cf1381cfff98c2f", "best_bid":"0.11", "best_ask":"0.12"}], "timestamp":"1778784200376", "event_type":"price_change"}
{"market":"0x2a903c589141bce4a1e50fb98b73397af6820942542793ab10b1df477e912b6e", "price_changes":[{"asset_id":"68919878716222388542639225642064847629616106443780159680232863841946753372582", "price":"0.12", "size":"18.13", "side":"SELL", "hash":"10d2823c6e261296c58ae16f6cf1381cfff98c2f", "best_bid":"0.11", "best_ask":"0.12"}, {"asset_id":"20436996072316278452977393149218961565084965483366669504673105646378938504388", "price":"0.88", "size":"18.13", "side":"BUY", "hash":"27eeab74cfd78b04f224fde162451738794163b1", "best_bid":"0.88", "best_ask":"0.89"}], "timestamp":"1778784200376", "event_type":"price_change"}
{"market":"0x2a903c589141bce4a1e50fb98b73397af6820942542793ab10b1df477e912b6e", "asset_id":"68919878716222388542639225642064847629616106443780159680232863841946753372582", "bids":[{"price":"0.01", "size":"11378.83"}, {"price":"0.02", "size":"1427.82"}, {"price":"0.03", "size":"1105.78"}, {"price":"0.04", "size":"837.82"}, {"price":"0.05", "size":"1055.72"}, {"price":"0.06", "size":"337.72"}, {"price":"0.07", "size":"337.1"}, {"price":"0.08", "size":"680.73"}, {"price":"0.09", "size":"312.7"}, {"price":"0.1", "size":"631.26"}, {"price":"0.11", "size":"300.41"}], "asks":[{"price":"0.99", "size":"12101.51"}, {"price":"0.98", "size":"1219.45"}, {"price":"0.97", "size":"1111.98"}, {"price":"0.96", "size":"670.05"}, {"price":"0.95", "size":"549.45"}, {"price":"0.94", "size":"346.2"}, {"price":"0.93", "size":"902.05"}, {"price":"0.92", "size":"170.79"}, {"price":"0.91", "size":"234.6"}, {"price":"0.9", "size":"128"}, {"price":"0.89", "size":"142.6"}, {"price":"0.88", "size":"141.8"}, {"price":"0.87", "size":"144.81"}, {"price":"0.86", "size":"204.9"}, {"price":"0.85", "size":"113.5"}, {"price":"0.84", "size":"102.3"}, {"price":"0.83", "size":"101.3"}, {"price":"0.82", "size":"105.3"}, {"price":"0.81", "size":"199.5"}, {"price":"0.8", "size":"103.8"}, {"price":"0.79", "size":"98.1"}, {"price":"0.78", "size":"97.5"}, {"price":"0.77", "size":"96.89"}, {"price":"0.76", "size":"201.39"}, {"price":"0.75", "size":"116"}, {"price":"0.74", "size":"100.6"}, {"price":"0.73", "size":"95.2"}, {"price":"0.72", "size":"94.9"}, {"price":"0.71", "size":"199.6"}, {"price":"0.7", "size":"94.3"}, {"price":"0.69", "size":"108.28"}, {"price":"0.68", "size":"98.8"}, {"price":"0.67", "size":"718.6"}, {"price":"0.66", "size":"998.4"}, {"price":"0.65", "size":"507.3"}, {"price":"0.64", "size":"293"}, {"price":"0.63", "size":"292.9"}, {"price":"0.62", "size":"897.7"}, {"price":"0.61", "size":"397.6"}, {"price":"0.6", "size":"356.93"}, {"price":"0.59", "size":"297.4"}, {"price":"0.58", "size":"109.6"}, {"price":"0.57", "size":"131.48"}, {"price":"0.56", "size":"413.97"}, {"price":"0.55", "size":"334.2"}, {"price":"0.54", "size":"375.6"}, {"price":"0.53", "size":"292"}, {"price":"0.52", "size":"292.12"}, {"price":"0.51", "size":"402"}, {"price":"0.5", "size":"355.91"}, {"price":"0.49", "size":"312"}, {"price":"0.48", "size":"317"}, {"price":"0.47", "size":"802"}, {"price":"0.46", "size":"651.54"}, {"price":"0.45", "size":"346.64"}, {"price":"0.44", "size":"337.45"}, {"price":"0.43", "size":"434.89"}, {"price":"0.42", "size":"724.36"}, {"price":"0.41", "size":"412.4"}, {"price":"0.4", "size":"328.83"}, {"price":"0.39", "size":"297.6"}, {"price":"0.38", "size":"618.44"}, {"price":"0.37", "size":"297.9"}, {"price":"0.36", "size":"208"}, {"price":"0.35", "size":"345.14"}, {"price":"0.34", "size":"355.9"}, {"price":"0.33", "size":"343.6"}, {"price":"0.32", "size":"2055.88"}, {"price":"0.31", "size":"559"}, {"price":"0.3", "size":"134.3"}, {"price":"0.29", "size":"316.38"}, {"price":"0.28", "size":"159.9"}, {"price":"0.27", "size":"165.2"}, {"price":"0.26", "size":"230.6"}, {"price":"0.25", "size":"656"}, {"price":"0.24", "size":"146.39"}, {"price":"0.23", "size":"191.89"}, {"price":"0.22", "size":"117.5"}, {"price":"0.21", "size":"215.44"}, {"price":"0.2", "size":"110"}, {"price":"0.19", "size":"72.35"}, {"price":"0.18", "size":"274.82"}, {"price":"0.17", "size":"30"}, {"price":"0.16", "size":"100"}, {"price":"0.15", "size":"31.67"}, {"price":"0.13", "size":"5"}, {"price":"0.12", "size":"18.13"}], "hash":"10d2823c6e261296c58ae16f6cf1381cfff98c2f", "timestamp":"1778784200376", "event_type":"book"}
{"market":"0x2a903c589141bce4a1e50fb98b73397af6820942542793ab10b1df477e912b6e", "price_changes":[{"asset_id":"20436996072316278452977393149218961565084965483366669504673105646378938504388", "price":"0.78", "size":"157.5", "side":"BUY", "hash":"84c63bba51ac375a37521f10a90b12d99e82f3df", "best_bid":"0.88", "best_ask":"0.89"}, {"asset_id":"68919878716222388542639225642064847629616106443780159680232863841946753372582", "price":"0.22", "size":"157.5", "side":"SELL", "hash":"756a5aa4ac8767605fbe6704865f0035b1808e2f", "best_bid":"0.11", "best_ask":"0.12"}], "timestamp":"1778784200380", "event_type":"price_change"}
{"market":"0x2a903c589141bce4a1e50fb98b73397af6820942542793ab10b1df477e912b6e", "price_changes":[{"asset_id":"68919878716222388542639225642064847629616106443780159680232863841946753372582", "price":"0.06", "size":"237.72", "side":"BUY", "hash":"1a85f7b14a9698eec3ba6bd698d5ba101978b60a", "best_bid":"0.11", "best_ask":"0.12"}, {"asset_id":"20436996072316278452977393149218961565084965483366669504673105646378938504388", "price":"0.94", "size":"237.72", "side":"SELL", "hash":"b5fa26be16cfad76a7c4180f7851f6f53763953e", "best_bid":"0.88", "best_ask":"0.89"}], "timestamp":"1778784200383", "event_type":"price_change"}
{"market":"0x2a903c589141bce4a1e50fb98b73397af6820942542793ab10b1df477e912b6e", "price_changes":[{"asset_id":"68919878716222388542639225642064847629616106443780159680232863841946753372582", "price":"0.01", "size":"11373.83", "side":"BUY", "hash":"c023411d8048ec039f7ab724ec8d1e0d4541dfe7", "best_bid":"0.11", "best_ask":"0.12"}, {"asset_id":"20436996072316278452977393149218961565084965483366669504673105646378938504388", "price":"0.99", "size":"11373.83", "side":"SELL", "hash":"1a9e7e84a696519f18049e89b30a5ae2e9064391", "best_bid":"0.88", "best_ask":"0.89"}], "timestamp":"1778784200384", "event_type":"price_change"}
{"market":"0x2a903c589141bce4a1e50fb98b73397af6820942542793ab10b1df477e912b6e", "price_changes":[{"asset_id":"20436996072316278452977393149218961565084965483366669504673105646378938504388", "price":"0.75", "size":"696", "side":"BUY", "hash":"5b9046865bef4b26cd474c713f1847c2cef98567", "best_bid":"0.88", "best_ask":"0.89"}, {"asset_id":"68919878716222388542639225642064847629616106443780159680232863841946753372582", "price":"0.25", "size":"696", "side":"SELL", "hash":"953ce64daf5a04b4077cf5cb92b0e815a0c672e7", "best_bid":"0.11", "best_ask":"0.12"}], "timestamp":"1778784200386", "event_type":"price_change"}
{"market":"0x2a903c589141bce4a1e50fb98b73397af6820942542793ab10b1df477e912b6e", "price_changes":[{"asset_id":"68919878716222388542639225642064847629616106443780159680232863841946753372582", "price":"0.11", "size":"296.97", "side":"BUY", "hash":"26fe3aad96b607952a3a3ab8d8a8303407e47fcf", "best_bid":"0.11", "best_ask":"0.12"}, {"asset_id":"20436996072316278452977393149218961565084965483366669504673105646378938504388", "price":"0.89", "size":"296.97", "side":"SELL", "hash":"86a51076c3130838f15b7d9ff703c8c4abad5f49", "best_bid":"0.88", "best_ask":"0.89"}], "timestamp":"1778784200395", "event_type":"price_change"}
{"market":"0x2a903c589141bce4a1e50fb98b73397af6820942542793ab10b1df477e912b6e", "asset_id":"68919878716222388542639225642064847629616106443780159680232863841946753372582", "bids":[{"price":"0.01", "size":"11373.83"}, {"price":"0.02", "size":"1427.82"}, {"price":"0.03", "size":"1105.78"}, {"price":"0.04", "size":"837.82"}, {"price":"0.05", "size":"1055.72"}, {"price":"0.06", "size":"237.72"}, {"price":"0.07", "size":"337.1"}, {"price":"0.08", "size":"680.73"}, {"price":"0.09", "size":"312.7"}, {"price":"0.1", "size":"631.26"}, {"price":"0.11", "size":"296.97"}], "asks":[{"price":"0.99", "size":"12101.51"}, {"price":"0.98", "size":"1219.45"}, {"price":"0.97", "size":"1111.98"}, {"price":"0.96", "size":"670.05"}, {"price":"0.95", "size":"549.45"}, {"price":"0.94", "size":"346.2"}, {"price":"0.93", "size":"902.05"}, {"price":"0.92", "size":"170.79"}, {"price":"0.91", "size":"234.6"}, {"price":"0.9", "size":"128"}, {"price":"0.89", "size":"142.6"}, {"price":"0.88", "size":"141.8"}, {"price":"0.87", "size":"144.81"}, {"price":"0.86", "size":"204.9"}, {"price":"0.85", "size":"113.5"}, {"price":"0.84", "size":"102.3"}, {"price":"0.83", "size":"101.3"}, {"price":"0.82", "size":"105.3"}, {"price":"0.81", "size":"199.5"}, {"price":"0.8", "size":"103.8"}, {"price":"0.79", "size":"98.1"}, {"price":"0.78", "size":"97.5"}, {"price":"0.77", "size":"96.89"}, {"price":"0.76", "size":"201.39"}, {"price":"0.75", "size":"116"}, {"price":"0.74", "size":"100.6"}, {"price":"0.73", "size":"95.2"}, {"price":"0.72", "size":"94.9"}, {"price":"0.71", "size":"199.6"}, {"price":"0.7", "size":"94.3"}, {"price":"0.69", "size":"108.28"}, {"price":"0.68", "size":"98.8"}, {"price":"0.67", "size":"718.6"}, {"price":"0.66", "size":"998.4"}, {"price":"0.65", "size":"507.3"}, {"price":"0.64", "size":"293"}, {"price":"0.63", "size":"292.9"}, {"price":"0.62", "size":"897.7"}, {"price":"0.61", "size":"397.6"}, {"price":"0.6", "size":"356.93"}, {"price":"0.59", "size":"297.4"}, {"price":"0.58", "size":"109.6"}, {"price":"0.57", "size":"131.48"}, {"price":"0.56", "size":"413.97"}, {"price":"0.55", "size":"334.2"}, {"price":"0.54", "size":"375.6"}, {"price":"0.53", "size":"292"}, {"price":"0.52", "size":"292.12"}, {"price":"0.51", "size":"402"}, {"price":"0.5", "size":"355.91"}, {"price":"0.49", "size":"312"}, {"price":"0.48", "size":"317"}, {"price":"0.47", "size":"802"}, {"price":"0.46", "size":"651.54"}, {"price":"0.45", "size":"346.64"}, {"price":"0.44", "size":"337.45"}, {"price":"0.43", "size":"434.89"}, {"price":"0.42", "size":"724.36"}, {"price":"0.41", "size":"412.4"}, {"price":"0.4", "size":"328.83"}, {"price":"0.39", "size":"297.6"}, {"price":"0.38", "size":"618.44"}, {"price":"0.37", "size":"297.9"}, {"price":"0.36", "size":"208"}, {"price":"0.35", "size":"345.14"}, {"price":"0.34", "size":"355.9"}, {"price":"0.33", "size":"343.6"}, {"price":"0.32", "size":"2055.88"}, {"price":"0.31", "size":"559"}, {"price":"0.3", "size":"134.3"}, {"price":"0.29", "size":"316.38"}, {"price":"0.28", "size":"159.9"}, {"price":"0.27", "size":"165.2"}, {"price":"0.26", "size":"230.6"}, {"price":"0.25", "size":"696"}, {"price":"0.24", "size":"146.39"}, {"price":"0.23", "size":"191.89"}, {"price":"0.22", "size":"157.5"}, {"price":"0.21", "size":"215.44"}, {"price":"0.2", "size":"110"}, {"price":"0.19", "size":"72.35"}, {"price":"0.18", "size":"274.82"}, {"price":"0.17", "size":"30"}, {"price":"0.16", "size":"100"}, {"price":"0.15", "size":"31.67"}, {"price":"0.13", "size":"5"}, {"price":"0.12", "size":"18.13"}], "hash":"26fe3aad96b607952a3a3ab8d8a8303407e47fcf", "timestamp":"1778784200395", "event_type":"book"}
{"market":"0x2a903c589141bce4a1e50fb98b73397af6820942542793ab10b1df477e912b6e", "price_changes":[{"asset_id":"20436996072316278452977393149218961565084965483366669504673105646378938504388", "price":"0.78", "size":"177.5", "side":"BUY", "hash":"03a5339eb8bd19d3e4feb5295ad7091bc34a4afe", "best_bid":"0.88", "best_ask":"0.89"}, {"asset_id":"68919878716222388542639225642064847629616106443780159680232863841946753372582", "price":"0.22", "size":"177.5", "side":"SELL", "hash":"9832f3b50a0ac28ab79a5d172f1c502d1866ad74", "best_bid":"0.11", "best_ask":"0.12"}], "timestamp":"1778784200398", "event_type":"price_change"}
{"market":"0x2a903c589141bce4a1e50fb98b73397af6820942542793ab10b1df477e912b6e", "asset_id":"68919878716222388542639225642064847629616106443780159680232863841946753372582", "price":"0.12", "size":"10.833332", "fee_rate_bps":"0", "side":"BUY", "timestamp":"1778784200396", "event_type":"last_trade_price", "transaction_hash":"0xe54d36ae05791c03b4dc663abe01ecb97704b2bc222ee1f750a31575e184e2ad"}
{"market":"0x2a903c589141bce4a1e50fb98b73397af6820942542793ab10b1df477e912b6e", "price_changes":[{"asset_id":"20436996072316278452977393149218961565084965483366669504673105646378938504388", "price":"0.88", "size":"13.13", "side":"BUY", "hash":"99d71cd6afad37767678c9029cbe56d569d22a84", "best_bid":"0.88", "best_ask":"0.89"}, {"asset_id":"68919878716222388542639225642064847629616106443780159680232863841946753372582", "price":"0.12", "size":"13.13", "side":"SELL", "hash":"986a418e7f3442fb26064b93cd192331360447c3", "best_bid":"0.11", "best_ask":"0.12"}], "timestamp":"1778784200407", "event_type":"price_change"}
{"market":"0x2a903c589141bce4a1e50fb98b73397af6820942542793ab10b1df477e912b6e", "asset_id":"68919878716222388542639225642064847629616106443780159680232863841946753372582", "bids":[{"price":"0.01", "size":"11373.83"}, {"price":"0.02", "size":"1427.82"}, {"price":"0.03", "size":"1105.78"}, {"price":"0.04", "size":"837.82"}, {"price":"0.05", "size":"1055.72"}, {"price":"0.06", "size":"237.72"}, {"price":"0.07", "size":"337.1"}, {"price":"0.08", "size":"680.73"}, {"price":"0.09", "size":"312.7"}, {"price":"0.1", "size":"631.26"}, {"price":"0.11", "size":"296.97"}], "asks":[{"price":"0.99", "size":"12101.51"}, {"price":"0.98", "size":"1219.45"}, {"price":"0.97", "size":"1111.98"}, {"price":"0.96", "size":"670.05"}, {"price":"0.95", "size":"549.45"}, {"price":"0.94", "size":"346.2"}, {"price":"0.93", "size":"902.05"}, {"price":"0.92", "size":"170.79"}, {"price":"0.91", "size":"234.6"}, {"price":"0.9", "size":"128"}, {"price":"0.89", "size":"142.6"}, {"price":"0.88", "size":"141.8"}, {"price":"0.87", "size":"144.81"}, {"price":"0.86", "size":"204.9"}, {"price":"0.85", "size":"113.5"}, {"price":"0.84", "size":"102.3"}, {"price":"0.83", "size":"101.3"}, {"price":"0.82", "size":"105.3"}, {"price":"0.81", "size":"199.5"}, {"price":"0.8", "size":"103.8"}, {"price":"0.79", "size":"98.1"}, {"price":"0.78", "size":"97.5"}, {"price":"0.77", "size":"96.89"}, {"price":"0.76", "size":"201.39"}, {"price":"0.75", "size":"116"}, {"price":"0.74", "size":"100.6"}, {"price":"0.73", "size":"95.2"}, {"price":"0.72", "size":"94.9"}, {"price":"0.71", "size":"199.6"}, {"price":"0.7", "size":"94.3"}, {"price":"0.69", "size":"108.28"}, {"price":"0.68", "size":"98.8"}, {"price":"0.67", "size":"718.6"}, {"price":"0.66", "size":"998.4"}, {"price":"0.65", "size":"507.3"}, {"price":"0.64", "size":"293"}, {"price":"0.63", "size":"292.9"}, {"price":"0.62", "size":"897.7"}, {"price":"0.61", "size":"397.6"}, {"price":"0.6", "size":"356.93"}, {"price":"0.59", "size":"297.4"}, {"price":"0.58", "size":"109.6"}, {"price":"0.57", "size":"131.48"}, {"price":"0.56", "size":"413.97"}, {"price":"0.55", "size":"334.2"}, {"price":"0.54", "size":"375.6"}, {"price":"0.53", "size":"292"}, {"price":"0.52", "size":"292.12"}, {"price":"0.51", "size":"402"}, {"price":"0.5", "size":"355.91"}, {"price":"0.49", "size":"312"}, {"price":"0.48", "size":"317"}, {"price":"0.47", "size":"802"}, {"price":"0.46", "size":"651.54"}, {"price":"0.45", "size":"346.64"}, {"price":"0.44", "size":"337.45"}, {"price":"0.43", "size":"434.89"}, {"price":"0.42", "size":"724.36"}, {"price":"0.41", "size":"412.4"}, {"price":"0.4", "size":"328.83"}, {"price":"0.39", "size":"297.6"}, {"price":"0.38", "size":"618.44"}, {"price":"0.37", "size":"297.9"}, {"price":"0.36", "size":"208"}, {"price":"0.35", "size":"345.14"}, {"price":"0.34", "size":"355.9"}, {"price":"0.33", "size":"343.6"}, {"price":"0.32", "size":"2055.88"}, {"price":"0.31", "size":"559"}, {"price":"0.3", "size":"134.3"}, {"price":"0.29", "size":"316.38"}, {"price":"0.28", "size":"159.9"}, {"price":"0.27", "size":"165.2"}, {"price":"0.26", "size":"230.6"}, {"price":"0.25", "size":"696"}, {"price":"0.24", "size":"146.39"}, {"price":"0.23", "size":"191.89"}, {"price":"0.22", "size":"177.5"}, {"price":"0.21", "size":"215.44"}, {"price":"0.2", "size":"110"}, {"price":"0.19", "size":"72.35"}, {"price":"0.18", "size":"274.82"}, {"price":"0.17", "size":"30"}, {"price":"0.16", "size":"100"}, {"price":"0.15", "size":"31.67"}, {"price":"0.13", "size":"5"}, {"price":"0.12", "size":"13.13"}], "hash":"986a418e7f3442fb26064b93cd192331360447c3", "timestamp":"1778784200407", "event_type":"book"}
{"market":"0x2a903c589141bce4a1e50fb98b73397af6820942542793ab10b1df477e912b6e", "price_changes":[{"asset_id":"20436996072316278452977393149218961565084965483366669504673105646378938504388", "price":"0.79", "size":"235.44", "side":"BUY", "hash":"1637204ee39336d22807c104acfe3a4a5f52ea30", "best_bid":"0.88", "best_ask":"0.89"}, {"asset_id":"68919878716222388542639225642064847629616106443780159680232863841946753372582", "price":"0.21", "size":"235.44", "side":"SELL", "hash":"37eebe92a55b92b1ddf9f6acc55c121ccb1be170", "best_bid":"0.11", "best_ask":"0.12"}], "timestamp":"1778784200409", "event_type":"price_change"}
{"market":"0x2a903c589141bce4a1e50fb98b73397af6820942542793ab10b1df477e912b6e", "price_changes":[{"asset_id":"20436996072316278452977393149218961565084965483366669504673105646378938504388", "price":"0.01", "size":"12010.61", "side":"BUY", "hash":"12756418b25de85cf96ceb69c5c7da1c0fcf6eff", "best_bid":"0.88", "best_ask":"0.89"}, {"asset_id":"68919878716222388542639225642064847629616106443780159680232863841946753372582", "price":"0.99", "size":"12010.61", "side":"SELL", "hash":"9318aa96f7cd27667d5e3681c53c774845e0a7e3", "best_bid":"0.11", "best_ask":"0.12"}], "timestamp":"1778784200410", "event_type":"price_change"}
{"market":"0x2a903c589141bce4a1e50fb98b73397af6820942542793ab10b1df477e912b6e", "price_changes":[{"asset_id":"20436996072316278452977393149218961565084965483366669504673105646378938504388", "price":"0.88", "size":"8.13", "side":"BUY", "hash":"8fa0a1b47ab4d40ec3cef4970a44d23004901b8c", "best_bid":"0.88", "best_ask":"0.89"}, {"asset_id":"68919878716222388542639225642064847629616106443780159680232863841946753372582", "price":"0.12", "size":"8.13", "side":"SELL", "hash":"f5bf2f5dc65e8c5f5b2781fba42613ac628b85bb", "best_bid":"0.11", "best_ask":"0.12"}], "timestamp":"1778784200413", "event_type":"price_change"}
{"market":"0x2a903c589141bce4a1e50fb98b73397af6820942542793ab10b1df477e912b6e", "asset_id":"68919878716222388542639225642064847629616106443780159680232863841946753372582", "bids":[{"price":"0.01", "size":"11373.83"}, {"price":"0.02", "size":"1427.82"}, {"price":"0.03", "size":"1105.78"}, {"price":"0.04", "size":"837.82"}, {"price":"0.05", "size":"1055.72"}, {"price":"0.06", "size":"237.72"}, {"price":"0.07", "size":"337.1"}, {"price":"0.08", "size":"680.73"}, {"price":"0.09", "size":"312.7"}, {"price":"0.1", "size":"631.26"}, {"price":"0.11", "size":"296.97"}], "asks":[{"price":"0.99", "size":"12010.61"}, {"price":"0.98", "size":"1219.45"}, {"price":"0.97", "size":"1111.98"}, {"price":"0.96", "size":"670.05"}, {"price":"0.95", "size":"549.45"}, {"price":"0.94", "size":"346.2"}, {"price":"0.93", "size":"902.05"}, {"price":"0.92", "size":"170.79"}, {"price":"0.91", "size":"234.6"}, {"price":"0.9", "size":"128"}, {"price":"0.89", "size":"142.6"}, {"price":"0.88", "size":"141.8"}, {"price":"0.87", "size":"144.81"}, {"price":"0.86", "size":"204.9"}, {"price":"0.85", "size":"113.5"}, {"price":"0.84", "size":"102.3"}, {"price":"0.83", "size":"101.3"}, {"price":"0.82", "size":"105.3"}, {"price":"0.81", "size":"199.5"}, {"price":"0.8", "size":"103.8"}, {"price":"0.79", "size":"98.1"}, {"price":"0.78", "size":"97.5"}, {"price":"0.77", "size":"96.89"}, {"price":"0.76", "size":"201.39"}, {"price":"0.75", "size":"116"}, {"price":"0.74", "size":"100.6"}, {"price":"0.73", "size":"95.2"}, {"price":"0.72", "size":"94.9"}, {"price":"0.71", "size":"199.6"}, {"price":"0.7", "size":"94.3"}, {"price":"0.69", "size":"108.28"}, {"price":"0.68", "size":"98.8"}, {"price":"0.67", "size":"718.6"}, {"price":"0.66", "size":"998.4"}, {"price":"0.65", "size":"507.3"}, {"price":"0.64", "size":"293"}, {"price":"0.63", "size":"292.9"}, {"price":"0.62", "size":"897.7"}, {"price":"0.61", "size":"397.6"}, {"price":"0.6", "size":"356.93"}, {"price":"0.59", "size":"297.4"}, {"price":"0.58", "size":"109.6"}, {"price":"0.57", "size":"131.48"}, {"price":"0.56", "size":"413.97"}, {"price":"0.55", "size":"334.2"}, {"price":"0.54", "size":"375.6"}, {"price":"0.53", "size":"292"}, {"price":"0.52", "size":"292.12"}, {"price":"0.51", "size":"402"}, {"price":"0.5", "size":"355.91"}, {"price":"0.49", "size":"312"}, {"price":"0.48", "size":"317"}, {"price":"0.47", "size":"802"}, {"price":"0.46", "size":"651.54"}, {"price":"0.45", "size":"346.64"}, {"price":"0.44", "size":"337.45"}, {"price":"0.43", "size":"434.89"}, {"price":"0.42", "size":"724.36"}, {"price":"0.41", "size":"412.4"}, {"price":"0.4", "size":"328.83"}, {"price":"0.39", "size":"297.6"}, {"price":"0.38", "size":"618.44"}, {"price":"0.37", "size":"297.9"}, {"price":"0.36", "size":"208"}, {"price":"0.35", "size":"345.14"}, {"price":"0.34", "size":"355.9"}, {"price":"0.33", "size":"343.6"}, {"price":"0.32", "size":"2055.88"}, {"price":"0.31", "size":"559"}, {"price":"0.3", "size":"134.3"}, {"price":"0.29", "size":"316.38"}, {"price":"0.28", "size":"159.9"}, {"price":"0.27", "size":"165.2"}, {"price":"0.26", "size":"230.6"}, {"price":"0.25", "size":"696"}, {"price":"0.24", "size":"146.39"}, {"price":"0.23", "size":"191.89"}, {"price":"0.22", "size":"177.5"}, {"price":"0.21", "size":"235.44"}, {"price":"0.2", "size":"110"}, {"price":"0.19", "size":"72.35"}, {"price":"0.18", "size":"274.82"}, {"price":"0.17", "size":"30"}, {"price":"0.16", "size":"100"}, {"price":"0.15", "size":"31.67"}, {"price":"0.13", "size":"5"}, {"price":"0.12", "size":"8.13"}], "hash":"f5bf2f5dc65e8c5f5b2781fba42613ac628b85bb", "timestamp":"1778784200413", "event_type":"book"}
{"market":"0x2a903c589141bce4a1e50fb98b73397af6820942542793ab10b1df477e912b6e", "price_changes":[{"asset_id":"20436996072316278452977393149218961565084965483366669504673105646378938504388", "price":"0.89", "size":"271.97", "side":"SELL", "hash":"d7824203e92d16d5679e63ca54a21137500d04aa", "best_bid":"0.88", "best_ask":"0.89"}, {"asset_id":"68919878716222388542639225642064847629616106443780159680232863841946753372582", "price":"0.11", "size":"271.97", "side":"BUY", "hash":"4f9aed12bf82cd054a787c020a962589c1d43b87", "best_bid":"0.11", "best_ask":"0.12"}], "timestamp":"1778784200415", "event_type":"price_change"}
{"market":"0x2a903c589141bce4a1e50fb98b73397af6820942542793ab10b1df477e912b6e", "price_changes":[{"asset_id":"20436996072316278452977393149218961565084965483366669504673105646378938504388", "price":"0.79", "size":"275.44", "side":"BUY", "hash":"85c24b0c64b16143b73b48448d2350334a513c3e", "best_bid":"0.88", "best_ask":"0.89"}, {"asset_id":"68919878716222388542639225642064847629616106443780159680232863841946753372582", "price":"0.21", "size":"275.44", "side":"SELL", "hash":"9587700d83012f2e41feb76e5c849b4fe1a0e00f", "best_bid":"0.11", "best_ask":"0.12"}], "timestamp":"1778784200416", "event_type":"price_change"}
{"market":"0x2a903c589141bce4a1e50fb98b73397af6820942542793ab10b1df477e912b6e", "asset_id":"68919878716222388542639225642064847629616106443780159680232863841946753372582", "price":"0.11", "size":"3.44", "fee_rate_bps":"0", "side":"SELL", "timestamp":"1778784200417", "event_type":"last_trade_price", "transaction_hash":"0xb55f4595a6b954b81684cec673f62d612ced255f997b8e4c8ce6945d8ee18986"}
{"market":"0x2a903c589141bce4a1e50fb98b73397af6820942542793ab10b1df477e912b6e", "price_changes":[{"asset_id":"68919878716222388542639225642064847629616106443780159680232863841946753372582", "price":"0.13", "size":"86.87", "side":"BUY", "hash":"28e7ad03c5ff5ba65e1d5aeb0e65e849820bf60c", "best_bid":"0.13", "best_ask":"0.15"}, {"asset_id":"20436996072316278452977393149218961565084965483366669504673105646378938504388", "price":"0.87", "size":"86.87", "side":"SELL", "hash":"b69970fdea201a57a0b7d8306f4cead5c4400a05", "best_bid":"0.85", "best_ask":"0.87"}], "timestamp":"1778784200418", "event_type":"price_change"}
{"market":"0x2a903c589141bce4a1e50fb98b73397af6820942542793ab10b1df477e912b6e", "price_changes":[{"asset_id":"20436996072316278452977393149218961565084965483366669504673105646378938504388", "price":"0.88", "size":"0", "side":"BUY", "hash":"b69970fdea201a57a0b7d8306f4cead5c4400a05", "best_bid":"0.85", "best_ask":"0.87"}, {"asset_id":"68919878716222388542639225642064847629616106443780159680232863841946753372582", "price":"0.12", "size":"0", "side":"SELL", "hash":"28e7ad03c5ff5ba65e1d5aeb0e65e849820bf60c", "best_bid":"0.13", "best_ask":"0.15"}], "timestamp":"1778784200418", "event_type":"price_change"}
{"market":"0x2a903c589141bce4a1e50fb98b73397af6820942542793ab10b1df477e912b6e", "price_changes":[{"asset_id":"20436996072316278452977393149218961565084965483366669504673105646378938504388", "price":"0.87", "size":"0", "side":"BUY", "hash":"b69970fdea201a57a0b7d8306f4cead5c4400a05", "best_bid":"0.85", "best_ask":"0.87"}, {"asset_id":"68919878716222388542639225642064847629616106443780159680232863841946753372582", "price":"0.13", "size":"0", "side":"SELL", "hash":"28e7ad03c5ff5ba65e1d5aeb0e65e849820bf60c", "best_bid":"0.13", "best_ask":"0.15"}], "timestamp":"1778784200418", "event_type":"price_change"}
{"market":"0x2a903c589141bce4a1e50fb98b73397af6820942542793ab10b1df477e912b6e", "asset_id":"68919878716222388542639225642064847629616106443780159680232863841946753372582", "bids":[{"price":"0.01", "size":"11373.83"}, {"price":"0.02", "size":"1427.82"}, {"price":"0.03", "size":"1105.78"}, {"price":"0.04", "size":"837.82"}, {"price":"0.05", "size":"1055.72"}, {"price":"0.06", "size":"237.72"}, {"price":"0.07", "size":"337.1"}, {"price":"0.08", "size":"680.73"}, {"price":"0.09", "size":"312.7"}, {"price":"0.1", "size":"631.26"}, {"price":"0.11", "size":"271.97"}, {"price":"0.13", "size":"86.87"}], "asks":[{"price":"0.99", "size":"12010.61"}, {"price":"0.98", "size":"1219.45"}, {"price":"0.97", "size":"1111.98"}, {"price":"0.96", "size":"670.05"}, {"price":"0.95", "size":"549.45"}, {"price":"0.94", "size":"346.2"}, {"price":"0.93", "size":"902.05"}, {"price":"0.92", "size":"170.79"}, {"price":"0.91", "size":"234.6"}, {"price":"0.9", "size":"128"}, {"price":"0.89", "size":"142.6"}, {"price":"0.88", "size":"141.8"}, {"price":"0.87", "size":"144.81"}, {"price":"0.86", "size":"204.9"}, {"price":"0.85", "size":"113.5"}, {"price":"0.84", "size":"102.3"}, {"price":"0.83", "size":"101.3"}, {"price":"0.82", "size":"105.3"}, {"price":"0.81", "size":"199.5"}, {"price":"0.8", "size":"103.8"}, {"price":"0.79", "size":"98.1"}, {"price":"0.78", "size":"97.5"}, {"price":"0.77", "size":"96.89"}, {"price":"0.76", "size":"201.39"}, {"price":"0.75", "size":"116"}, {"price":"0.74", "size":"100.6"}, {"price":"0.73", "size":"95.2"}, {"price":"0.72", "size":"94.9"}, {"price":"0.71", "size":"199.6"}, {"price":"0.7", "size":"94.3"}, {"price":"0.69", "size":"108.28"}, {"price":"0.68", "size":"98.8"}, {"price":"0.67", "size":"718.6"}, {"price":"0.66", "size":"998.4"}, {"price":"0.65", "size":"507.3"}, {"price":"0.64", "size":"293"}, {"price":"0.63", "size":"292.9"}, {"price":"0.62", "size":"897.7"}, {"price":"0.61", "size":"397.6"}, {"price":"0.6", "size":"356.93"}, {"price":"0.59", "size":"297.4"}, {"price":"0.58", "size":"109.6"}, {"price":"0.57", "size":"131.48"}, {"price":"0.56", "size":"413.97"}, {"price":"0.55", "size":"334.2"}, {"price":"0.54", "size":"375.6"}, {"price":"0.53", "size":"292"}, {"price":"0.52", "size":"292.12"}, {"price":"0.51", "size":"402"}, {"price":"0.5", "size":"355.91"}, {"price":"0.49", "size":"312"}, {"price":"0.48", "size":"317"}, {"price":"0.47", "size":"802"}, {"price":"0.46", "size":"651.54"}, {"price":"0.45", "size":"346.64"}, {"price":"0.44", "size":"337.45"}, {"price":"0.43", "size":"434.89"}, {"price":"0.42", "size":"724.36"}, {"price":"0.41", "size":"412.4"}, {"price":"0.4", "size":"328.83"}, {"price":"0.39", "size":"297.6"}, {"price":"0.38", "size":"618.44"}, {"price":"0.37", "size":"297.9"}, {"price":"0.36", "size":"208"}, {"price":"0.35", "size":"345.14"}, {"price":"0.34", "size":"355.9"}, {"price":"0.33", "size":"343.6"}, {"price":"0.32", "size":"2055.88"}, {"price":"0.31", "size":"559"}, {"price":"0.3", "size":"134.3"}, {"price":"0.29", "size":"316.38"}, {"price":"0.28", "size":"159.9"}, {"price":"0.27", "size":"165.2"}, {"price":"0.26", "size":"230.6"}, {"price":"0.25", "size":"696"}, {"price":"0.24", "size":"146.39"}, {"price":"0.23", "size":"191.89"}, {"price":"0.22", "size":"177.5"}, {"price":"0.21", "size":"275.44"}, {"price":"0.2", "size":"110"}, {"price":"0.19", "size":"72.35"}, {"price":"0.18", "size":"274.82"}, {"price":"0.17", "size":"30"}, {"price":"0.16", "size":"100"}, {"price":"0.15", "size":"31.67"}], "hash":"28e7ad03c5ff5ba65e1d5aeb0e65e849820bf60c", "timestamp":"1778784200418", "event_type":"book"}
{"market":"0x2a903c589141bce4a1e50fb98b73397af6820942542793ab10b1df477e912b6e", "price_changes":[{"asset_id":"20436996072316278452977393149218961565084965483366669504673105646378938504388", "price":"0.78", "size":"217.5", "side":"BUY", "hash":"bd91437e891b5c05593fa50a9700571f7cf779c7", "best_bid":"0.85", "best_ask":"0.87"}, {"asset_id":"68919878716222388542639225642064847629616106443780159680232863841946753372582", "price":"0.22", "size":"217.5", "side":"SELL", "hash":"012968ac125e7784d1f86d02a9dc92734794a2a5", "best_bid":"0.13", "best_ask":"0.15"}], "timestamp":"1778784200421", "event_type":"price_change"}
{"market":"0x2a903c589141bce4a1e50fb98b73397af6820942542793ab10b1df477e912b6e", "price_changes":[{"asset_id":"20436996072316278452977393149218961565084965483366669504673105646378938504388", "price":"0.82", "size":"269.82", "side":"BUY", "hash":"1019f0defcb9fe3126aae81ce9fa55f696610665", "best_bid":"0.85", "best_ask":"0.87"}, {"asset_id":"68919878716222388542639225642064847629616106443780159680232863841946753372582", "price":"0.18", "size":"269.82", "side":"SELL", "hash":"ccddd887c5d046c31fc4438fe650a03874377ede", "best_bid":"0.13", "best_ask":"0.15"}], "timestamp":"1778784200422", "event_type":"price_change"}
{"market":"0x2a903c589141bce4a1e50fb98b73397af6820942542793ab10b1df477e912b6e", "price_changes":[{"asset_id":"68919878716222388542639225642064847629616106443780159680232863841946753372582", "price":"0.23", "size":"166.89", "side":"SELL", "hash":"05ef9d548f3c8f6049f9fd693729617e2e2694a2", "best_bid":"0.13", "best_ask":"0.15"}, {"asset_id":"20436996072316278452977393149218961565084965483366669504673105646378938504388", "price":"0.77", "size":"166.89", "side":"BUY", "hash":"5d7234226ed2fc62586d443a58ea26128ebfb2e1", "best_bid":"0.85", "best_ask":"0.87"}], "timestamp":"1778784200423", "event_type":"price_change"}
{"market":"0x2a903c589141bce4a1e50fb98b73397af6820942542793ab10b1df477e912b6e", "price_changes":[{"asset_id":"68919878716222388542639225642064847629616106443780159680232863841946753372582", "price":"0.14", "size":"30", "side":"BUY", "hash":"0ee5fba4d1e9183d8517d6aebb3d5f4de5f42fba", "best_bid":"0.14", "best_ask":"0.15"}, {"asset_id":"20436996072316278452977393149218961565084965483366669504673105646378938504388", "price":"0.86", "size":"30", "side":"SELL", "hash":"66ea0c0a37947f0e524a79428c2b07c47707b82b", "best_bid":"0.85", "best_ask":"0.86"}], "timestamp":"1778784200425", "event_type":"price_change"}
{"market":"0x2a903c589141bce4a1e50fb98b73397af6820942542793ab10b1df477e912b6e", "asset_id":"68919878716222388542639225642064847629616106443780159680232863841946753372582", "price":"0.12", "size":"5", "fee_rate_bps":"0", "side":"BUY", "timestamp":"1778784200426", "event_type":"last_trade_price", "transaction_hash":"0xc9d027ba5d18e731acd1177f879900d43745128c0560a7af9881b6484ce08c1e"}
{"market":"0x2a903c589141bce4a1e50fb98b73397af6820942542793ab10b1df477e912b6e", "price_changes":[{"asset_id":"68919878716222388542639225642064847629616106443780159680232863841946753372582", "price":"0.14", "size":"27.67", "side":"BUY", "hash":"3b29fd954580df90937fddb98b2aaa2d8e2c68cf", "best_bid":"0.14", "best_ask":"0.15"}, {"asset_id":"20436996072316278452977393149218961565084965483366669504673105646378938504388", "price":"0.86", "size":"27.67", "side":"SELL", "hash":"9ed45cbad18dc2be7baf329d4d86d635c55ff96d", "best_bid":"0.85", "best_ask":"0.86"}], "timestamp":"1778784200428", "event_type":"price_change"}
