{"market":"0x2a903c589141bce4a1e50fb98b73397af6820942542793ab10b1df477e912b6e", "asset_id":"68919878716222388542639225642064847629616106443780159680232863841946753372582", "bids":[{"price":"0.01", "size":"11343.83"}, {"price":"0.02", "size":"1397.82"}, {"price":"0.03", "size":"1100.78"}, {"price":"0.04", "size":"1237.82"}, {"price":"0.05", "size":"796.72"}, {"price":"0.06", "size":"347.21"}, {"price":"0.07", "size":"647.1"}, {"price":"0.08", "size":"694.53"}, {"price":"0.09", "size":"357.1"}, {"price":"0.1", "size":"507"}, {"price":"0.11", "size":"442.62"}, {"price":"0.12", "size":"511.23"}, {"price":"0.13", "size":"125"}, {"price":"0.14", "size":"232.57"}, {"price":"0.15", "size":"262.96"}], "asks":[{"price":"0.99", "size":"11995.61"}, {"price":"0.98", "size":"1219.45"}, {"price":"0.97", "size":"1096.98"}, {"price":"0.96", "size":"670.05"}, {"price":"0.95", "size":"549.45"}, {"price":"0.94", "size":"346.2"}, {"price":"0.93", "size":"902.05"}, {"price":"0.92", "size":"170.79"}, {"price":"0.91", "size":"234.6"}, {"price":"0.9", "size":"128"}, {"price":"0.89", "size":"142.6"}, {"price":"0.88", "size":"141.8"}, {"price":"0.87", "size":"144.81"}, {"price":"0.86", "size":"204.9"}, {"price":"0.85", "size":"113.5"}, {"price":"0.84", "size":"102.3"}, {"price":"0.83", "size":"101.3"}, {"price":"0.82", "size":"105.3"}, {"price":"0.81", "size":"199.5"}, {"price":"0.8", "size":"103.8"}, {"price":"0.79", "size":"98.1"}, {"price":"0.78", "size":"97.5"}, {"price":"0.77", "size":"96.89"}, {"price":"0.76", "size":"201.39"}, {"price":"0.75", "size":"116"}, {"price":"0.74", "size":"100.6"}, {"price":"0.73", "size":"95.2"}, {"price":"0.72", "size":"94.9"}, {"price":"0.71", "size":"199.6"}, {"price":"0.7", "size":"94.3"}, {"price":"0.69", "size":"108.28"}, {"price":"0.68", "size":"98.8"}, {"price":"0.67", "size":"118.6"}, {"price":"0.66", "size":"398.4"}, {"price":"0.65", "size":"507.3"}, {"price":"0.64", "size":"893"}, {"price":"0.63", "size":"892.9"}, {"price":"0.62", "size":"297.7"}, {"price":"0.61", "size":"397.6"}, {"price":"0.6", "size":"356.93"}, {"price":"0.59", "size":"297.4"}, {"price":"0.58", "size":"109.6"}, {"price":"0.57", "size":"131.48"}, {"price":"0.56", "size":"413.97"}, {"price":"0.55", "size":"334.2"}, {"price":"0.54", "size":"375.6"}, {"price":"0.53", "size":"292"}, {"price":"0.52", "size":"297.12"}, {"price":"0.51", "size":"402"}, {"price":"0.5", "size":"340.91"}, {"price":"0.49", "size":"798"}, {"price":"0.48", "size":"317"}, {"price":"0.47", "size":"337"}, {"price":"0.46", "size":"451.54"}, {"price":"0.45", "size":"346.64"}, {"price":"0.44", "size":"341.45"}, {"price":"0.43", "size":"434.89"}, {"price":"0.42", "size":"724.36"}, {"price":"0.41", "size":"412.4"}, {"price":"0.4", "size":"328.83"}, {"price":"0.39", "size":"297.6"}, {"price":"0.38", "size":"318.44"}, {"price":"0.37", "size":"576.9"}, {"price":"0.36", "size":"203"}, {"price":"0.35", "size":"330.14"}, {"price":"0.34", "size":"350.9"}, {"price":"0.33", "size":"363.6"}, {"price":"0.32", "size":"2065.88"}, {"price":"0.31", "size":"559"}, {"price":"0.3", "size":"234.3"}, {"price":"0.29", "size":"626.38"}, {"price":"0.28", "size":"134.9"}, {"price":"0.27", "size":"460.2"}, {"price":"0.26", "size":"250.6"}, {"price":"0.25", "size":"496"}, {"price":"0.24", "size":"511.39"}, {"price":"0.23", "size":"246.89"}, {"price":"0.22", "size":"355.5"}, {"price":"0.21", "size":"305.44"}, {"price":"0.2", "size":"123.8"}, {"price":"0.19", "size":"72.35"}, {"price":"0.18", "size":"289.82"}, {"price":"0.17", "size":"28.97"}, {"price":"0.16", "size":"161.21"}], "hash":"f2c4ba7b106761e03c3c2000f626b820c784d05d", "timestamp":"1778784200988", "event_type":"book"}
{"market":"0x2a903c589141bce4a1e50fb98b73397af6820942542793ab10b1df477e912b6e", "price_changes":[{"asset_id":"20436996072316278452977393149218961565084965483366669504673105646378938504388", "price":"0.7", "size":"244.3", "side":"BUY", "hash":"e63c9235f922d1a997b9f2e0f78880be52d8fda7", "best_bid":"0.84", "best_ask":"0.85"}, {"asset_id":"68919878716222388542639225642064847629616106443780159680232863841946753372582", "price":"0.3", "size":"244.3", "side":"SELL", "hash":"5ad1f452d03ba7a6fac22e2f8d69919da097fadc", "best_bid":"0.15", "best_ask":"0.16"}], "timestamp":"1778784200989", "event_type":"price_change"}
{"market":"0x2a903c589141bce4a1e50fb98b73397af6820942542793ab10b1df477e912b6e", "price_changes":[{"asset_id":"68919878716222388542639225642064847629616106443780159680232863841946753372582", "price":"0.15", "size":"275.96", "side":"BUY", "hash":"f33cc6dd146d630b23f9ceb76c9d7124680c0fe3", "best_bid":"0.15", "best_ask":"0.16"}, {"asset_id":"20436996072316278452977393149218961565084965483366669504673105646378938504388", "price":"0.85", "size":"275.96", "side":"SELL", "hash":"407d75995fa750b87d674dcb3430a5da11cd9e8b", "best_bid":"0.84", "best_ask":"0.85"}], "timestamp":"1778784200991", "event_type":"price_change"}
{"market":"0x2a903c589141bce4a1e50fb98b73397af6820942542793ab10b1df477e912b6e", "price_changes":[{"asset_id":"20436996072316278452977393149218961565084965483366669504673105646378938504388", "price":"0.88", "size":"471.23", "side":"SELL", "hash":"66c8d7fc164c33984f8035b93bb9419f30662464", "best_bid":"0.84", "best_ask":"0.85"}, {"asset_id":"68919878716222388542639225642064847629616106443780159680232863841946753372582", "price":"0.12", "size":"471.23", "side":"BUY", "hash":"b8ebe04079ae325383580f941e47dbb5175cefd0", "best_bid":"0.15", "best_ask":"0.16"}], "timestamp":"1778784200992", "event_type":"price_change"}
{"market":"0x2a903c589141bce4a1e50fb98b73397af6820942542793ab10b1df477e912b6e", "price_changes":[{"asset_id":"20436996072316278452977393149218961565084965483366669504673105646378938504388", "price":"0.84", "size":"166.21", "side":"BUY", "hash":"929401d398e5e80d4b25c00b457d704309d5b9f1", "best_bid":"0.84", "best_ask":"0.85"}, {"asset_id":"68919878716222388542639225642064847629616106443780159680232863841946753372582", "price":"0.16", "size":"166.21", "side":"SELL", "hash":"c29da565069aff396e5d8737399c2b614a56bc58", "best_bid":"0.15", "best_ask":"0.16"}], "timestamp":"1778784200992", "event_type":"price_change"}
{"market":"0x2a903c589141bce4a1e50fb98b73397af6820942542793ab10b1df477e912b6e", "price_changes":[{"asset_id":"68919878716222388542639225642064847629616106443780159680232863841946753372582", "price":"0.15", "size":"264.96", "side":"BUY", "hash":"6e83bd2e4c4d880578a5e2b6be796e326582cef1", "best_bid":"0.15", "best_ask":"0.16"}, {"asset_id":"20436996072316278452977393149218961565084965483366669504673105646378938504388", "price":"0.85", "size":"264.96", "side":"SELL", "hash":"b55701dd9a46908afb37c4934c84ba8b9f9a300c", "best_bid":"0.84", "best_ask":"0.85"}], "timestamp":"1778784200994", "event_type":"price_change"}
{"market":"0x2a903c589141bce4a1e50fb98b73397af6820942542793ab10b1df477e912b6e", "price_changes":[{"asset_id":"68919878716222388542639225642064847629616106443780159680232863841946753372582", "price":"0.15", "size":"254.96", "side":"BUY", "hash":"98d28dc279bdd14f5828e6ca60c3202535c0be7b", "best_bid":"0.15", "best_ask":"0.16"}, {"asset_id":"20436996072316278452977393149218961565084965483366669504673105646378938504388", "price":"0.85", "size":"254.96", "side":"SELL", "hash":"e71f0d6605a75d8e8687bf9edea333e32a7e1a05", "best_bid":"0.84", "best_ask":"0.85"}], "timestamp":"1778784200994", "event_type":"price_change"}
{"market":"0x2a903c589141bce4a1e50fb98b73397af6820942542793ab10b1df477e912b6e", "price_changes":[{"asset_id":"68919878716222388542639225642064847629616106443780159680232863841946753372582", "price":"0.15", "size":"244.96", "side":"BUY", "hash":"c49ea2b2d459be1a68973c2938800d8d53da740c", "best_bid":"0.15", "best_ask":"0.16"}, {"asset_id":"20436996072316278452977393149218961565084965483366669504673105646378938504388", "price":"0.85", "size":"244.96", "side":"SELL", "hash":"8745a2935450dbdc8e6658517a252d0076b9f249", "best_bid":"0.84", "best_ask":"0.85"}], "timestamp":"1778784200995", "event_type":"price_change"}
{"market":"0x2a903c589141bce4a1e50fb98b73397af6820942542793ab10b1df477e912b6e", "price_changes":[{"asset_id":"20436996072316278452977393149218961565084965483366669504673105646378938504388", "price":"0.93", "size":"656.69", "side":"SELL", "hash":"62aef9aa5f0066add4ed2c039c5161022f73de8e", "best_bid":"0.84", "best_ask":"0.85"}, {"asset_id":"68919878716222388542639225642064847629616106443780159680232863841946753372582", "price":"0.07", "size":"656.69", "side":"BUY", "hash":"5740cde0b2507eb1a9d3bb9ecb0f8f6dca888102", "best_bid":"0.15", "best_ask":"0.16"}], "timestamp":"1778784200995", "event_type":"price_change"}
{"market":"0x2a903c589141bce4a1e50fb98b73397af6820942542793ab10b1df477e912b6e", "price_changes":[{"asset_id":"68919878716222388542639225642064847629616106443780159680232863841946753372582", "price":"0.15", "size":"271.52", "side":"BUY", "hash":"3ac7df232b45a6f00e1e4efaca0daeeac48ae4bc", "best_bid":"0.15", "best_ask":"0.16"}, {"asset_id":"20436996072316278452977393149218961565084965483366669504673105646378938504388", "price":"0.85", "size":"271.52", "side":"SELL", "hash":"fe9efdef55f814e7f7a5142ec784c0d47710830c", "best_bid":"0.84", "best_ask":"0.85"}], "timestamp":"1778784200996", "event_type":"price_change"}
{"market":"0x2a903c589141bce4a1e50fb98b73397af6820942542793ab10b1df477e912b6e", "price_changes":[{"asset_id":"68919878716222388542639225642064847629616106443780159680232863841946753372582", "price":"0.15", "size":"278.19", "side":"BUY", "hash":"08f1328a0e32c0ad7fe01cbb92135fb6a237cfaf", "best_bid":"0.15", "best_ask":"0.16"}, {"asset_id":"20436996072316278452977393149218961565084965483366669504673105646378938504388", "price":"0.85", "size":"278.19", "side":"SELL", "hash":"e30a7088077b7d2512d4e4d97bafd9b2b4afe897", "best_bid":"0.84", "best_ask":"0.85"}], "timestamp":"1778784200997", "event_type":"price_change"}
{"market":"0x2a903c589141bce4a1e50fb98b73397af6820942542793ab10b1df477e912b6e", "price_changes":[{"asset_id":"20436996072316278452977393149218961565084965483366669504673105646378938504388", "price":"0.84", "size":"158.21", "side":"BUY", "hash":"dc9148b42b2d30d0740a51783d60f6e6735ca8bb", "best_bid":"0.84", "best_ask":"0.85"}, {"asset_id":"68919878716222388542639225642064847629616106443780159680232863841946753372582", "price":"0.16", "size":"158.21", "side":"SELL", "hash":"630258e5953c7e67505c7580c4b6ea97e62687ef", "best_bid":"0.15", "best_ask":"0.16"}], "timestamp":"1778784200998", "event_type":"price_change"}
{"market":"0x2a903c589141bce4a1e50fb98b73397af6820942542793ab10b1df477e912b6e", "price_changes":[{"asset_id":"68919878716222388542639225642064847629616106443780159680232863841946753372582", "price":"0.14", "size":"227.57", "side":"BUY", "hash":"658bc450f9060f9788097e5071d4c92c0d8d4bd0", "best_bid":"0.15", "best_ask":"0.16"}, {"asset_id":"20436996072316278452977393149218961565084965483366669504673105646378938504388", "price":"0.86", "size":"227.57", "side":"SELL", "hash":"13deddef56e2cfdd1d0131565ca495607e7ea907", "best_bid":"0.84", "best_ask":"0.85"}], "timestamp":"1778784200999", "event_type":"price_change"}
{"market":"0x2a903c589141bce4a1e50fb98b73397af6820942542793ab10b1df477e912b6e", "price_changes":[{"asset_id":"68919878716222388542639225642064847629616106443780159680232863841946753372582", "price":"0.15", "size":"235.19", "side":"BUY", "hash":"e2b59452d36b27ea7b2edf7c2b2ac32be422b922", "best_bid":"0.15", "best_ask":"0.16"}, {"asset_id":"20436996072316278452977393149218961565084965483366669504673105646378938504388", "price":"0.85", "size":"235.19", "side":"SELL", "hash":"d965fac3e6547e19f07fc88088799a47f81887d9", "best_bid":"0.84", "best_ask":"0.85"}], "timestamp":"1778784201000", "event_type":"price_change"}
{"market":"0x2a903c589141bce4a1e50fb98b73397af6820942542793ab10b1df477e912b6e", "price_changes":[{"asset_id":"68919878716222388542639225642064847629616106443780159680232863841946753372582", "price":"0.15", "size":"225.19", "side":"BUY", "hash":"5a1418202a6ef43a4f0db254d9de4c3b88b25f34", "best_bid":"0.15", "best_ask":"0.16"}, {"asset_id":"20436996072316278452977393149218961565084965483366669504673105646378938504388", "price":"0.85", "size":"225.19", "side":"SELL", "hash":"320a194c8904e46df1de73c841770c4c8e823c71", "best_bid":"0.84", "best_ask":"0.85"}], "timestamp":"1778784201001", "event_type":"price_change"}
{"market":"0x2a903c589141bce4a1e50fb98b73397af6820942542793ab10b1df477e912b6e", "price_changes":[{"asset_id":"20436996072316278452977393149218961565084965483366669504673105646378938504388", "price":"0.91", "size":"303.11", "side":"SELL", "hash":"85b1eb13c82964edd76abc170a28147df87c7696", "best_bid":"0.84", "best_ask":"0.85"}, {"asset_id":"68919878716222388542639225642064847629616106443780159680232863841946753372582", "price":"0.09", "size":"303.11", "side":"BUY", "hash":"4184d86ecc9a84d1af29d5180d14291d0c698cdd", "best_bid":"0.15", "best_ask":"0.16"}], "timestamp":"1778784201002", "event_type":"price_change"}
{"market":"0x2a903c589141bce4a1e50fb98b73397af6820942542793ab10b1df477e912b6e", "price_changes":[{"asset_id":"68919878716222388542639225642064847629616106443780159680232863841946753372582", "price":"0.13", "size":"133", "side":"BUY", "hash":"2f51f9241923fb568b8266a5023c38ed903caf7c", "best_bid":"0.15", "best_ask":"0.16"}, {"asset_id":"20436996072316278452977393149218961565084965483366669504673105646378938504388", "price":"0.87", "size":"133", "side":"SELL", "hash":"32a0c4308954753f1692f9c3fafb47470e0659ea", "best_bid":"0.84", "best_ask":"0.85"}], "timestamp":"1778784201004", "event_type":"price_change"}
{"market":"0x2a903c589141bce4a1e50fb98b73397af6820942542793ab10b1df477e912b6e", "price_changes":[{"asset_id":"20436996072316278452977393149218961565084965483366669504673105646378938504388", "price":"0.78", "size":"349.5", "side":"BUY", "hash":"279a00a96795b1a6b27d0badc6150a3d6198babb", "best_bid":"0.84", "best_ask":"0.85"}, {"asset_id":"68919878716222388542639225642064847629616106443780159680232863841946753372582", "price":"0.22", "size":"349.5", "side":"SELL", "hash":"b55cf2f45964da832af1c0c1f02434315b970642", "best_bid":"0.15", "best_ask":"0.16"}], "timestamp":"1778784201005", "event_type":"price_change"}
{"market":"0x2a903c589141bce4a1e50fb98b73397af6820942542793ab10b1df477e912b6e", "price_changes":[{"asset_id":"20436996072316278452977393149218961565084965483366669504673105646378938504388", "price":"0.64", "size":"213", "side":"BUY", "hash":"02d236622dd6587998527029b71000d5d629768d", "best_bid":"0.84", "best_ask":"0.85"}, {"asset_id":"68919878716222388542639225642064847629616106443780159680232863841946753372582", "price":"0.36", "size":"213", "side":"SELL", "hash":"4ce8c1f45112ae85b8deb0f0e76c6d82a8b27233", "best_bid":"0.15", "best_ask":"0.16"}], "timestamp":"1778784201006", "event_type":"price_change"}
{"market":"0x2a903c589141bce4a1e50fb98b73397af6820942542793ab10b1df477e912b6e", "price_changes":[{"asset_id":"68919878716222388542639225642064847629616106443780159680232863841946753372582", "price":"0.12", "size":"438.41", "side":"BUY", "hash":"2195bce0e05ac1d077a44948819c487ab6a67b34", "best_bid":"0.15", "best_ask":"0.16"}, {"asset_id":"20436996072316278452977393149218961565084965483366669504673105646378938504388", "price":"0.88", "size":"438.41", "side":"SELL", "hash":"f4b9acb41fc36e842e5763208826bf7ae4d5cb17", "best_bid":"0.84", "best_ask":"0.85"}], "timestamp":"1778784201007", "event_type":"price_change"}
{"market":"0x2a903c589141bce4a1e50fb98b73397af6820942542793ab10b1df477e912b6e", "price_changes":[{"asset_id":"68919878716222388542639225642064847629616106443780159680232863841946753372582", "price":"0.11", "size":"472.62", "side":"BUY", "hash":"856540ff77d6d0cded8f2f95bf8f896197b75920", "best_bid":"0.15", "best_ask":"0.16"}, {"asset_id":"20436996072316278452977393149218961565084965483366669504673105646378938504388", "price":"0.89", "size":"472.62", "side":"SELL", "hash":"ff8e27b8f8e018b03499ee412a30ec6ccd327e70", "best_bid":"0.84", "best_ask":"0.85"}], "timestamp":"1778784201008", "event_type":"price_change"}
{"market":"0x2a903c589141bce4a1e50fb98b73397af6820942542793ab10b1df477e912b6e", "price_changes":[{"asset_id":"68919878716222388542639225642064847629616106443780159680232863841946753372582", "price":"0.14", "size":"257.57", "side":"BUY", "hash":"73b3146d9ec5a8a0c17d757fb6ff0488cebef45b", "best_bid":"0.15", "best_ask":"0.16"}, {"asset_id":"20436996072316278452977393149218961565084965483366669504673105646378938504388", "price":"0.86", "size":"257.57", "side":"SELL", "hash":"12da7a36fe41640812f989fc4ee2e838ad4104d1", "best_bid":"0.84", "best_ask":"0.85"}], "timestamp":"1778784201008", "event_type":"price_change"}
{"market":"0x2a903c589141bce4a1e50fb98b73397af6820942542793ab10b1df477e912b6e", "asset_id":"68919878716222388542639225642064847629616106443780159680232863841946753372582", "price":"0.16", "size":"5", "fee_rate_bps":"0", "side":"BUY", "timestamp":"1778784201007", "event_type":"last_trade_price", "transaction_hash":"0xbfd75ac3bd55992326e8771f6e79ddaa674537639890953d9f299c633ce3b223"}
{"market":"0x2a903c589141bce4a1e50fb98b73397af6820942542793ab10b1df477e912b6e", "price_changes":[{"asset_id":"20436996072316278452977393149218961565084965483366669504673105646378938504388", "price":"0.84", "size":"149.21", "side":"BUY", "hash":"3133314e1bdf9c948bb27c4672919b12cf5b8fe1", "best_bid":"0.84", "best_ask":"0.85"}, {"asset_id":"68919878716222388542639225642064847629616106443780159680232863841946753372582", "price":"0.16", "size":"149.21", "side":"SELL", "hash":"ee3f2b076ee2a934ab6042960d548feeb5bb12e7", "best_bid":"0.15", "best_ask":"0.16"}], "timestamp":"1778784201009", "event_type":"price_change"}
{"market":"0x2a903c589141bce4a1e50fb98b73397af6820942542793ab10b1df477e912b6e", "price_changes":[{"asset_id":"68919878716222388542639225642064847629616106443780159680232863841946753372582", "price":"0.13", "size":"233", "side":"BUY", "hash":"269f2e18dd89d31ade73d74ea2731fc6e289e002", "best_bid":"0.15", "best_ask":"0.16"}, {"asset_id":"20436996072316278452977393149218961565084965483366669504673105646378938504388", "price":"0.87", "size":"233", "side":"SELL", "hash":"a66722c6815b3d259d8b397e6e42bd0135cad125", "best_bid":"0.84", "best_ask":"0.85"}], "timestamp":"1778784201011", "event_type":"price_change"}
{"market":"0x2a903c589141bce4a1e50fb98b73397af6820942542793ab10b1df477e912b6e", "price_changes":[{"asset_id":"20436996072316278452977393149218961565084965483366669504673105646378938504388", "price":"0.84", "size":"199.21", "side":"BUY", "hash":"bee38d4391696ca704662fcbed8a72d4c3d0d881", "best_bid":"0.84", "best_ask":"0.85"}, {"asset_id":"68919878716222388542639225642064847629616106443780159680232863841946753372582", "price":"0.16", "size":"199.21", "side":"SELL", "hash":"391c773179cf74e53a58350cb8c8b2b50455282d", "best_bid":"0.15", "best_ask":"0.16"}], "timestamp":"1778784201011", "event_type":"price_change"}
{"market":"0x2a903c589141bce4a1e50fb98b73397af6820942542793ab10b1df477e912b6e", "price_changes":[{"asset_id":"20436996072316278452977393149218961565084965483366669504673105646378938504388", "price":"0.84", "size":"216.21", "side":"BUY", "hash":"751b6eb44c975a2f9d110225f18b663bce860468", "best_bid":"0.84", "best_ask":"0.85"}, {"asset_id":"68919878716222388542639225642064847629616106443780159680232863841946753372582", "price":"0.16", "size":"216.21", "side":"SELL", "hash":"d82f56f5a44c12d2922bf8293bef1171b7d0922f", "best_bid":"0.15", "best_ask":"0.16"}], "timestamp":"1778784201013", "event_type":"price_change"}
{"market":"0x2a903c589141bce4a1e50fb98b73397af6820942542793ab10b1df477e912b6e", "price_changes":[{"asset_id":"68919878716222388542639225642064847629616106443780159680232863841946753372582", "price":"0.15", "size":"245.19", "side":"BUY", "hash":"a79fac7d989bab1ffb690c93742f460588f1a19e", "best_bid":"0.15", "best_ask":"0.16"}, {"asset_id":"20436996072316278452977393149218961565084965483366669504673105646378938504388", "price":"0.85", "size":"245.19", "side":"SELL", "hash":"ddad408cfa20281501a6bea4fb66c85c98fb76cc", "best_bid":"0.84", "best_ask":"0.85"}], "timestamp":"1778784201014", "event_type":"price_change"}
{"market":"0x2a903c589141bce4a1e50fb98b73397af6820942542793ab10b1df477e912b6e", "price_changes":[{"asset_id":"20436996072316278452977393149218961565084965483366669504673105646378938504388", "price":"0.79", "size":"330.44", "side":"BUY", "hash":"1f920a74d0efae2a484b8f4755c9a20f595488bb", "best_bid":"0.84", "best_ask":"0.85"}, {"asset_id":"68919878716222388542639225642064847629616106443780159680232863841946753372582", "price":"0.21", "size":"330.44", "side":"SELL", "hash":"7d63dfc63cad8b5f563d179f2aa2164485396d98", "best_bid":"0.15", "best_ask":"0.16"}], "timestamp":"1778784201015", "event_type":"price_change"}
{"market":"0x2a903c589141bce4a1e50fb98b73397af6820942542793ab10b1df477e912b6e", "price_changes":[{"asset_id":"68919878716222388542639225642064847629616106443780159680232863841946753372582", "price":"0.15", "size":"265.19", "side":"BUY", "hash":"be76fd4e900c53c6129c753059d0ab9fd2678e7c", "best_bid":"0.15", "best_ask":"0.16"}, {"asset_id":"20436996072316278452977393149218961565084965483366669504673105646378938504388", "price":"0.85", "size":"265.19", "side":"SELL", "hash":"3a841bfa2789f9d93caf5d178365fb984e71752f", "best_bid":"0.84", "best_ask":"0.85"}], "timestamp":"1778784201016", "event_type":"price_change"}
{"market":"0x2a903c589141bce4a1e50fb98b73397af6820942542793ab10b1df477e912b6e", "price_changes":[{"asset_id":"68919878716222388542639225642064847629616106443780159680232863841946753372582", "price":"0.04", "size":"1312.84", "side":"BUY", "hash":"663a18fe12a968bad5e3af8fb07c35aab3e4b025", "best_bid":"0.15", "best_ask":"0.16"}, {"asset_id":"20436996072316278452977393149218961565084965483366669504673105646378938504388", "price":"0.96", "size":"1312.84", "side":"SELL", "hash":"5f1131bef81e888fdf78148793d5728e13564799", "best_bid":"0.84", "best_ask":"0.85"}], "timestamp":"1778784201018", "event_type":"price_change"}
{"market":"0x2a903c589141bce4a1e50fb98b73397af6820942542793ab10b1df477e912b6e", "price_changes":[{"asset_id":"20436996072316278452977393149218961565084965483366669504673105646378938504388", "price":"0.84", "size":"207.21", "side":"BUY", "hash":"5309ad229c5a83ddfc55126c80ff5dadb3bc5d01", "best_bid":"0.84", "best_ask":"0.85"}, {"asset_id":"68919878716222388542639225642064847629616106443780159680232863841946753372582", "price":"0.16", "size":"207.21", "side":"SELL", "hash":"c667227db3fff15c199371c62c92a23f678d3179", "best_bid":"0.15", "best_ask":"0.16"}], "timestamp":"1778784201018", "event_type":"price_change"}
{"market":"0x2a903c589141bce4a1e50fb98b73397af6820942542793ab10b1df477e912b6e", "price_changes":[{"asset_id":"20436996072316278452977393149218961565084965483366669504673105646378938504388", "price":"0.84", "size":"192.21", "side":"BUY", "hash":"6122c9f4ff173fa505df06e72a5f8393a5dc57ed", "best_bid":"0.84", "best_ask":"0.85"}, {"asset_id":"68919878716222388542639225642064847629616106443780159680232863841946753372582", "price":"0.16", "size":"192.21", "side":"SELL", "hash":"46a4039daf74deaf589b80d4c64015a06d52bafa", "best_bid":"0.15", "best_ask":"0.16"}], "timestamp":"1778784201019", "event_type":"price_change"}
{"market":"0x2a903c589141bce4a1e50fb98b73397af6820942542793ab10b1df477e912b6e", "price_changes":[{"asset_id":"68919878716222388542639225642064847629616106443780159680232863841946753372582", "price":"0.15", "size":"270.19", "side":"BUY", "hash":"e86c830380d02ae7ba72c77e67f08ee77e7fcff6", "best_bid":"0.15", "best_ask":"0.16"}, {"asset_id":"20436996072316278452977393149218961565084965483366669504673105646378938504388", "price":"0.85", "size":"270.19", "side":"SELL", "hash":"6e0565e45f4e093b60af8fac26c1f02499ce7316", "best_bid":"0.84", "best_ask":"0.85"}], "timestamp":"1778784201021", "event_type":"price_change"}
{"market":"0x2a903c589141bce4a1e50fb98b73397af6820942542793ab10b1df477e912b6e", "price_changes":[{"asset_id":"68919878716222388542639225642064847629616106443780159680232863841946753372582", "price":"0.12", "size":"468.41", "side":"BUY", "hash":"356ca8adac11e8507e69b6d2b227d91d8cbb93ec", "best_bid":"0.15", "best_ask":"0.16"}, {"asset_id":"20436996072316278452977393149218961565084965483366669504673105646378938504388", "price":"0.88", "size":"468.41", "side":"SELL", "hash":"7bafd8493080ceb9d3312e1490c180624f0e3113", "best_bid":"0.84", "best_ask":"0.85"}], "timestamp":"1778784201021", "event_type":"price_change"}
{"market":"0x2a903c589141bce4a1e50fb98b73397af6820942542793ab10b1df477e912b6e", "price_changes":[{"asset_id":"68919878716222388542639225642064847629616106443780159680232863841946753372582", "price":"0.05", "size":"775.72", "side":"BUY", "hash":"c49b71a7186ce8d6dd64f7fda22835efd6401366", "best_bid":"0.15", "best_ask":"0.16"}, {"asset_id":"20436996072316278452977393149218961565084965483366669504673105646378938504388", "price":"0.95", "size":"775.72", "side":"SELL", "hash":"543832b4325b06bd18a21816461f6eaa51ecca20", "best_bid":"0.84", "best_ask":"0.85"}], "timestamp":"1778784201022", "event_type":"price_change"}
{"market":"0x2a903c589141bce4a1e50fb98b73397af6820942542793ab10b1df477e912b6e", "price_changes":[{"asset_id":"68919878716222388542639225642064847629616106443780159680232863841946753372582", "price":"0.12", "size":"459.41", "side":"BUY", "hash":"c49b71a7186ce8d6dd64f7fda22835efd6401366", "best_bid":"0.15", "best_ask":"0.16"}, {"asset_id":"20436996072316278452977393149218961565084965483366669504673105646378938504388", "price":"0.88", "size":"459.41", "side":"SELL", "hash":"543832b4325b06bd18a21816461f6eaa51ecca20", "best_bid":"0.84", "best_ask":"0.85"}], "timestamp":"1778784201022", "event_type":"price_change"}
{"market":"0x2a903c589141bce4a1e50fb98b73397af6820942542793ab10b1df477e912b6e", "price_changes":[{"asset_id":"20436996072316278452977393149218961565084965483366669504673105646378938504388", "price":"0.84", "size":"177.21", "side":"BUY", "hash":"d9e3e849b547e92d0b42b0b985d6388921de53fa", "best_bid":"0.84", "best_ask":"0.85"}, {"asset_id":"68919878716222388542639225642064847629616106443780159680232863841946753372582", "price":"0.16", "size":"177.21", "side":"SELL", "hash":"49e2f46a7b8bc5e41145922e71c3a0401ae1dfc5", "best_bid":"0.15", "best_ask":"0.16"}], "timestamp":"1778784201023", "event_type":"price_change"}
{"market":"0x2a903c589141bce4a1e50fb98b73397af6820942542793ab10b1df477e912b6e", "price_changes":[{"asset_id":"68919878716222388542639225642064847629616106443780159680232863841946753372582", "price":"0.11", "size":"463.52", "side":"BUY", "hash":"774576497a83a36c4cc7e33205a6f8ce74e7523c", "best_bid":"0.15", "best_ask":"0.16"}, {"asset_id":"20436996072316278452977393149218961565084965483366669504673105646378938504388", "price":"0.89", "size":"463.52", "side":"SELL", "hash":"3549ce950efc10f680284a37dae722070851f658", "best_bid":"0.84", "best_ask":"0.85"}], "timestamp":"1778784201024", "event_type":"price_change"}
{"market":"0x2a903c589141bce4a1e50fb98b73397af6820942542793ab10b1df477e912b6e", "price_changes":[{"asset_id":"68919878716222388542639225642064847629616106443780159680232863841946753372582", "price":"0.12", "size":"451", "side":"BUY", "hash":"26ef92e961aa7022beadb882ccc8d8918e54494c", "best_bid":"0.15", "best_ask":"0.16"}, {"asset_id":"20436996072316278452977393149218961565084965483366669504673105646378938504388", "price":"0.88", "size":"451", "side":"SELL", "hash":"96118ec9680e62d6496f884d33a066e7339d9948", "best_bid":"0.84", "best_ask":"0.85"}], "timestamp":"1778784201025", "event_type":"price_change"}
{"market":"0x2a903c589141bce4a1e50fb98b73397af6820942542793ab10b1df477e912b6e", "price_changes":[{"asset_id":"20436996072316278452977393149218961565084965483366669504673105646378938504388", "price":"0.84", "size":"168.5", "side":"BUY", "hash":"fd00f14e5118ead7954df1df3a374aa6e701a83e", "best_bid":"0.84", "best_ask":"0.85"}, {"asset_id":"68919878716222388542639225642064847629616106443780159680232863841946753372582", "price":"0.16", "size":"168.5", "side":"SELL", "hash":"7068e9f0f3caec8e04ff5e2f244920343896ab53", "best_bid":"0.15", "best_ask":"0.16"}], "timestamp":"1778784201025", "event_type":"price_change"}
{"market":"0x2a903c589141bce4a1e50fb98b73397af6820942542793ab10b1df477e912b6e", "price_changes":[{"asset_id":"68919878716222388542639225642064847629616106443780159680232863841946753372582", "price":"0.15", "size":"280.19", "side":"BUY", "hash":"c9b12456d6709e3d1ff0c359a815bf79f864ca06", "best_bid":"0.15", "best_ask":"0.16"}, {"asset_id":"20436996072316278452977393149218961565084965483366669504673105646378938504388", "price":"0.85", "size":"280.19", "side":"SELL", "hash":"4db8a5d0e5283f3dd5f3631f3779209bb0e9fa3c", "best_bid":"0.84", "best_ask":"0.85"}], "timestamp":"1778784201027", "event_type":"price_change"}
{"market":"0x2a903c589141bce4a1e50fb98b73397af6820942542793ab10b1df477e912b6e", "price_changes":[{"asset_id":"68919878716222388542639225642064847629616106443780159680232863841946753372582", "price":"0.11", "size":"437.52", "side":"BUY", "hash":"2c4efb4b7e0332e4134cadcde65fa9dbaaf18f18", "best_bid":"0.15", "best_ask":"0.16"}, {"asset_id":"20436996072316278452977393149218961565084965483366669504673105646378938504388", "price":"0.89", "size":"437.52", "side":"SELL", "hash":"86b4871e06624d78e604ab483ba0b2921b9049ae", "best_bid":"0.84", "best_ask":"0.85"}], "timestamp":"1778784201027", "event_type":"price_change"}
{"market":"0x2a903c589141bce4a1e50fb98b73397af6820942542793ab10b1df477e912b6e", "price_changes":[{"asset_id":"68919878716222388542639225642064847629616106443780159680232863841946753372582", "price":"0.12", "size":"456", "side":"BUY", "hash":"b2a847fb8f6d8083669e4860c557c6e4d3c68e27", "best_bid":"0.15", "best_ask":"0.16"}, {"asset_id":"20436996072316278452977393149218961565084965483366669504673105646378938504388", "price":"0.88", "size":"456", "side":"SELL", "hash":"aa255b886fa6209ba3be749f268f164590f8f64b", "best_bid":"0.84", "best_ask":"0.85"}], "timestamp":"1778784201028", "event_type":"price_change"}
{"market":"0x2a903c589141bce4a1e50fb98b73397af6820942542793ab10b1df477e912b6e", "price_changes":[{"asset_id":"68919878716222388542639225642064847629616106443780159680232863841946753372582", "price":"0.12", "size":"456", "side":"BUY", "hash":"1ca15eaceacaab2eacd3ba443865fa33e2a34a18", "best_bid":"0.15", "best_ask":"0.16"}, {"asset_id":"20436996072316278452977393149218961565084965483366669504673105646378938504388", "price":"0.88", "size":"456", "side":"SELL", "hash":"26ca5d86470102f623d7c4003f06c55378cddd69", "best_bid":"0.84", "best_ask":"0.85"}], "timestamp":"1778784201029", "event_type":"price_change"}
{"market":"0x2a903c589141bce4a1e50fb98b73397af6820942542793ab10b1df477e912b6e", "price_changes":[{"asset_id":"68919878716222388542639225642064847629616106443780159680232863841946753372582", "price":"0.15", "size":"280.19", "side":"BUY", "hash":"01cf5e0f011e67403f435906184dbf62dc1fb455", "best_bid":"0.15", "best_ask":"0.16"}, {"asset_id":"20436996072316278452977393149218961565084965483366669504673105646378938504388", "price":"0.85", "size":"280.19", "side":"SELL", "hash":"6b7838714fc5ba90cbfe92f54abb9ad35943fdbf", "best_bid":"0.84", "best_ask":"0.85"}], "timestamp":"1778784201030", "event_type":"price_change"}
{"market":"0x2a903c589141bce4a1e50fb98b73397af6820942542793ab10b1df477e912b6e", "price_changes":[{"asset_id":"68919878716222388542639225642064847629616106443780159680232863841946753372582", "price":"0.12", "size":"466", "side":"BUY", "hash":"c1a8ac1eac2a8d9df9e91e2cc12275aa61cc7609", "best_bid":"0.15", "best_ask":"0.16"}, {"asset_id":"20436996072316278452977393149218961565084965483366669504673105646378938504388", "price":"0.88", "size":"466", "side":"SELL", "hash":"35a4a095413a424d70d6d35ca361fafad9f03639", "best_bid":"0.84", "best_ask":"0.85"}], "timestamp":"1778784201030", "event_type":"price_change"}
{"market":"0x2a903c589141bce4a1e50fb98b73397af6820942542793ab10b1df477e912b6e", "price_changes":[{"asset_id":"68919878716222388542639225642064847629616106443780159680232863841946753372582", "price":"0.15", "size":"273.97", "side":"BUY", "hash":"a56f09ffd7591312f1b01a07285f62434cf7acec", "best_bid":"0.15", "best_ask":"0.16"}, {"asset_id":"20436996072316278452977393149218961565084965483366669504673105646378938504388", "price":"0.85", "size":"273.97", "side":"SELL", "hash":"43231a4468648339b62b706369c89ebee91cd6a8", "best_bid":"0.84", "best_ask":"0.85"}], "timestamp":"1778784201033", "event_type":"price_change"}
{"market":"0x2a903c589141bce4a1e50fb98b73397af6820942542793ab10b1df477e912b6e", "asset_id":"68919878716222388542639225642064847629616106443780159680232863841946753372582", "bids":[{"price":"0.01", "size":"11343.83"}, {"price":"0.02", "size":"1397.82"}, {"price":"0.03", "size":"1100.78"}, {"price":"0.04", "size":"1312.84"}, {"price":"0.05", "size":"775.72"}, {"price":"0.06", "size":"347.21"}, {"price":"0.07", "size":"656.69"}, {"price":"0.08", "size":"694.53"}, {"price":"0.09", "size":"303.11"}, {"price":"0.1", "size":"507"}, {"price":"0.11", "size":"437.52"}, {"price":"0.12", "size":"466"}, {"price":"0.13", "size":"233"}, {"price":"0.14", "size":"257.57"}, {"price":"0.15", "size":"273.97"}], "asks":[{"price":"0.99", "size":"11995.61"}, {"price":"0.98", "size":"1219.45"}, {"price":"0.97", "size":"1096.98"}, {"price":"0.96", "size":"670.05"}, {"price":"0.95", "size":"549.45"}, {"price":"0.94", "size":"346.2"}, {"price":"0.93", "size":"902.05"}, {"price":"0.92", "size":"170.79"}, {"price":"0.91", "size":"234.6"}, {"price":"0.9", "size":"128"}, {"price":"0.89", "size":"142.6"}, {"price":"0.88", "size":"141.8"}, {"price":"0.87", "size":"144.81"}, {"price":"0.86", "size":"204.9"}, {"price":"0.85", "size":"113.5"}, {"price":"0.84", "size":"102.3"}, {"price":"0.83", "size":"101.3"}, {"price":"0.82", "size":"105.3"}, {"price":"0.81", "size":"199.5"}, {"price":"0.8", "size":"103.8"}, {"price":"0.79", "size":"98.1"}, {"price":"0.78", "size":"97.5"}, {"price":"0.77", "size":"96.89"}, {"price":"0.76", "size":"201.39"}, {"price":"0.75", "size":"116"}, {"price":"0.74", "size":"100.6"}, {"price":"0.73", "size":"95.2"}, {"price":"0.72", "size":"94.9"}, {"price":"0.71", "size":"199.6"}, {"price":"0.7", "size":"94.3"}, {"price":"0.69", "size":"108.28"}, {"price":"0.68", "size":"98.8"}, {"price":"0.67", "size":"118.6"}, {"price":"0.66", "size":"398.4"}, {"price":"0.65", "size":"507.3"}, {"price":"0.64", "size":"893"}, {"price":"0.63", "size":"892.9"}, {"price":"0.62", "size":"297.7"}, {"price":"0.61", "size":"397.6"}, {"price":"0.6", "size":"356.93"}, {"price":"0.59", "size":"297.4"}, {"price":"0.58", "size":"109.6"}, {"price":"0.57", "size":"131.48"}, {"price":"0.56", "size":"413.97"}, {"price":"0.55", "size":"334.2"}, {"price":"0.54", "size":"375.6"}, {"price":"0.53", "size":"292"}, {"price":"0.52", "size":"297.12"}, {"price":"0.51", "size":"402"}, {"price":"0.5", "size":"340.91"}, {"price":"0.49", "size":"798"}, {"price":"0.48", "size":"317"}, {"price":"0.47", "size":"337"}, {"price":"0.46", "size":"451.54"}, {"price":"0.45", "size":"346.64"}, {"price":"0.44", "size":"341.45"}, {"price":"0.43", "size":"434.89"}, {"price":"0.42", "size":"724.36"}, {"price":"0.41", "size":"412.4"}, {"price":"0.4", "size":"328.83"}, {"price":"0.39", "size":"297.6"}, {"price":"0.38", "size":"318.44"}, {"price":"0.37", "size":"576.9"}, {"price":"0.36", "size":"213"}, {"price":"0.35", "size":"330.14"}, {"price":"0.34", "size":"350.9"}, {"price":"0.33", "size":"363.6"}, {"price":"0.32", "size":"2065.88"}, {"price":"0.31", "size":"559"}, {"price":"0.3", "size":"244.3"}, {"price":"0.29", "size":"626.38"}, {"price":"0.28", "size":"134.9"}, {"price":"0.27", "size":"460.2"}, {"price":"0.26", "size":"250.6"}, {"price":"0.25", "size":"496"}, {"price":"0.24", "size":"511.39"}, {"price":"0.23", "size":"246.89"}, {"price":"0.22", "size":"349.5"}, {"price":"0.21", "size":"330.44"}, {"price":"0.2", "size":"123.8"}, {"price":"0.19", "size":"72.35"}, {"price":"0.18", "size":"289.82"}, {"price":"0.17", "size":"28.97"}, {"price":"0.16", "size":"168.5"}], "hash":"a56f09ffd7591312f1b01a07285f62434cf7acec", "timestamp":"1778784201033", "event_type":"book"}
{"market":"0x2a903c589141bce4a1e50fb98b73397af6820942542793ab10b1df477e912b6e", "price_changes":[{"asset_id":"68919878716222388542639225642064847629616106443780159680232863841946753372582", "price":"0.15", "size":"280.97", "side":"BUY", "hash":"023268231c7be9e469f64eca77bcc9611611e027", "best_bid":"0.15", "best_ask":"0.16"}, {"asset_id":"20436996072316278452977393149218961565084965483366669504673105646378938504388", "price":"0.85", "size":"280.97", "side":"SELL", "hash":"aaa944390a0c61d68548d271301083ba4baa5b60", "best_bid":"0.84", "best_ask":"0.85"}], "timestamp":"1778784201035", "event_type":"price_change"}
{"market":"0x2a903c589141bce4a1e50fb98b73397af6820942542793ab10b1df477e912b6e", "price_changes":[{"asset_id":"68919878716222388542639225642064847629616106443780159680232863841946753372582", "price":"0.11", "size":"537.52", "side":"BUY", "hash":"17e12c441067cef96030fcb9e9c7a7b7fa388f50", "best_bid":"0.15", "best_ask":"0.16"}, {"asset_id":"20436996072316278452977393149218961565084965483366669504673105646378938504388", "price":"0.89", "size":"537.52", "side":"SELL", "hash":"a7812308077c0a31abf1231a3f9d7bf675010815", "best_bid":"0.84", "best_ask":"0.85"}], "timestamp":"1778784201036", "event_type":"price_change"}
{"market":"0x2a903c589141bce4a1e50fb98b73397af6820942542793ab10b1df477e912b6e", "price_changes":[{"asset_id":"68919878716222388542639225642064847629616106443780159680232863841946753372582", "price":"0.01", "size":"11373.83", "side":"BUY", "hash":"86ee2598509563c13db58e678bc90e4b15b02a16", "best_bid":"0.15", "best_ask":"0.16"}, {"asset_id":"20436996072316278452977393149218961565084965483366669504673105646378938504388", "price":"0.99", "size":"11373.83", "side":"SELL", "hash":"15c435d5f318077e11dc868ca67035f9769abfe1", "best_bid":"0.84", "best_ask":"0.85"}], "timestamp":"1778784201037", "event_type":"price_change"}
{"market":"0x2a903c589141bce4a1e50fb98b73397af6820942542793ab10b1df477e912b6e", "price_changes":[{"asset_id":"68919878716222388542639225642064847629616106443780159680232863841946753372582", "price":"0.15", "size":"330.97", "side":"BUY", "hash":"bcb0dc015952bcad59ed3e048010edf189ff16be", "best_bid":"0.15", "best_ask":"0.16"}, {"asset_id":"20436996072316278452977393149218961565084965483366669504673105646378938504388", "price":"0.85", "size":"330.97", "side":"SELL", "hash":"0e47dbae92e589900733785f04df284b9a75b14c", "best_bid":"0.84", "best_ask":"0.85"}], "timestamp":"1778784201038", "event_type":"price_change"}
{"market":"0x2a903c589141bce4a1e50fb98b73397af6820942542793ab10b1df477e912b6e", "price_changes":[{"asset_id":"20436996072316278452977393149218961565084965483366669504673105646378938504388", "price":"0.01", "size":"11990.61", "side":"BUY", "hash":"88ca14979e935527e587377db558ac80647bae60", "best_bid":"0.84", "best_ask":"0.85"}, {"asset_id":"68919878716222388542639225642064847629616106443780159680232863841946753372582", "price":"0.99", "size":"11990.61", "side":"SELL", "hash":"8e928e3def09b9e09fbfc130125ae0e332fb1b8d", "best_bid":"0.15", "best_ask":"0.16"}], "timestamp":"1778784201039", "event_type":"price_change"}
{"market":"0x2a903c589141bce4a1e50fb98b73397af6820942542793ab10b1df477e912b6e", "price_changes":[{"asset_id":"20436996072316278452977393149218961565084965483366669504673105646378938504388", "price":"0.63", "size":"297.9", "side":"BUY", "hash":"40e8cef023bca1e36e8ff76d4972298025608984", "best_bid":"0.84", "best_ask":"0.85"}, {"asset_id":"68919878716222388542639225642064847629616106443780159680232863841946753372582", "price":"0.37", "size":"297.9", "side":"SELL", "hash":"4f543bf8cc013e40e8bb6f17597f10f2cb87aa30", "best_bid":"0.15", "best_ask":"0.16"}], "timestamp":"1778784201040", "event_type":"price_change"}
{"market":"0x2a903c589141bce4a1e50fb98b73397af6820942542793ab10b1df477e912b6e", "price_changes":[{"asset_id":"68919878716222388542639225642064847629616106443780159680232863841946753372582", "price":"0.08", "size":"732.27", "side":"BUY", "hash":"595ec22f0a4aab326aa575e05407058e0de7c11d", "best_bid":"0.15", "best_ask":"0.16"}, {"asset_id":"20436996072316278452977393149218961565084965483366669504673105646378938504388", "price":"0.92", "size":"732.27", "side":"SELL", "hash":"446347f8043bd5ead1317d017ff5c7c3a2e9ab3b", "best_bid":"0.84", "best_ask":"0.85"}], "timestamp":"1778784201041", "event_type":"price_change"}
{"market":"0x2a903c589141bce4a1e50fb98b73397af6820942542793ab10b1df477e912b6e", "price_changes":[{"asset_id":"20436996072316278452977393149218961565084965483366669504673105646378938504388", "price":"0.76", "size":"541.39", "side":"BUY", "hash":"245546c6bbf0adf79cb3e21da88a2f43b2938588", "best_bid":"0.84", "best_ask":"0.85"}, {"asset_id":"68919878716222388542639225642064847629616106443780159680232863841946753372582", "price":"0.24", "size":"541.39", "side":"SELL", "hash":"b61c38623c03ac0fb0a1a40f98ae7ba13ab9fba1", "best_bid":"0.15", "best_ask":"0.16"}], "timestamp":"1778784201042", "event_type":"price_change"}
{"market":"0x2a903c589141bce4a1e50fb98b73397af6820942542793ab10b1df477e912b6e", "price_changes":[{"asset_id":"20436996072316278452977393149218961565084965483366669504673105646378938504388", "price":"0.01", "size":"11995.61", "side":"BUY", "hash":"d2e7977b7baa7c19ddcf65dbd98a400b45b87d8d", "best_bid":"0.84", "best_ask":"0.85"}, {"asset_id":"68919878716222388542639225642064847629616106443780159680232863841946753372582", "price":"0.99", "size":"11995.61", "side":"SELL", "hash":"e84316eca564711d8ac98c6e0647b79241b5a2b0", "best_bid":"0.15", "best_ask":"0.16"}], "timestamp":"1778784201044", "event_type":"price_change"}
{"market":"0x2a903c589141bce4a1e50fb98b73397af6820942542793ab10b1df477e912b6e", "price_changes":[{"asset_id":"68919878716222388542639225642064847629616106443780159680232863841946753372582", "price":"0.15", "size":"340.97", "side":"BUY", "hash":"1344526eca8685e1d6796e666e3225f8e8270152", "best_bid":"0.15", "best_ask":"0.16"}, {"asset_id":"20436996072316278452977393149218961565084965483366669504673105646378938504388", "price":"0.85", "size":"340.97", "side":"SELL", "hash":"011d18a10b4c79aa520f41f61439eb5b51cd032a", "best_bid":"0.84", "best_ask":"0.85"}], "timestamp":"1778784201045", "event_type":"price_change"}
{"market":"0x2a903c589141bce4a1e50fb98b73397af6820942542793ab10b1df477e912b6e", "price_changes":[{"asset_id":"20436996072316278452977393149218961565084965483366669504673105646378938504388", "price":"0.84", "size":"163.5", "side":"BUY", "hash":"9ce08d5a867e7c13d54a1f5b283cda4bdceda0f6", "best_bid":"0.84", "best_ask":"0.85"}, {"asset_id":"68919878716222388542639225642064847629616106443780159680232863841946753372582", "price":"0.16", "size":"163.5", "side":"SELL", "hash":"44e5996ed9c1ec0224a40a54f7f14bd0dbf9e661", "best_bid":"0.15", "best_ask":"0.16"}], "timestamp":"1778784201046", "event_type":"price_change"}
{"market":"0x2a903c589141bce4a1e50fb98b73397af6820942542793ab10b1df477e912b6e", "price_changes":[{"asset_id":"68919878716222388542639225642064847629616106443780159680232863841946753372582", "price":"0.15", "size":"350.97", "side":"BUY", "hash":"50598a90377142b99fad2243e90a8976d376e430", "best_bid":"0.15", "best_ask":"0.16"}, {"asset_id":"20436996072316278452977393149218961565084965483366669504673105646378938504388", "price":"0.85", "size":"350.97", "side":"SELL", "hash":"eae6622ddfa86d392f0bf38e3bd3ad16eb6f15b9", "best_bid":"0.84", "best_ask":"0.85"}], "timestamp":"1778784201047", "event_type":"price_change"}
{"market":"0x2a903c589141bce4a1e50fb98b73397af6820942542793ab10b1df477e912b6e", "price_changes":[{"asset_id":"68919878716222388542639225642064847629616106443780159680232863841946753372582", "price":"0.15", "size":"360.97", "side":"BUY", "hash":"4fb6aa3cf501f81c8c51bcf27737394b3d62ee33", "best_bid":"0.15", "best_ask":"0.16"}, {"asset_id":"20436996072316278452977393149218961565084965483366669504673105646378938504388", "price":"0.85", "size":"360.97", "side":"SELL", "hash":"35cd6ef87295bf7138b4ef22747d8755f1a04b02", "best_bid":"0.84", "best_ask":"0.85"}], "timestamp":"1778784201049", "event_type":"price_change"}
{"market":"0x2a903c589141bce4a1e50fb98b73397af6820942542793ab10b1df477e912b6e", "price_changes":[{"asset_id":"68919878716222388542639225642064847629616106443780159680232863841946753372582", "price":"0.15", "size":"370.97", "side":"BUY", "hash":"e0f6bbcee17715f0341dda092e61ff8e40fc35b8", "best_bid":"0.15", "best_ask":"0.16"}, {"asset_id":"20436996072316278452977393149218961565084965483366669504673105646378938504388", "price":"0.85", "size":"370.97", "side":"SELL", "hash":"268e921e80b5819f97d595598c626f31172e9955", "best_bid":"0.84", "best_ask":"0.85"}], "timestamp":"1778784201050", "event_type":"price_change"}
{"market":"0x2a903c589141bce4a1e50fb98b73397af6820942542793ab10b1df477e912b6e", "price_changes":[{"asset_id":"68919878716222388542639225642064847629616106443780159680232863841946753372582", "price":"0.14", "size":"265.57", "side":"BUY", "hash":"02136af35f00b6b5477447cc4b52fdae896653a0", "best_bid":"0.15", "best_ask":"0.16"}, {"asset_id":"20436996072316278452977393149218961565084965483366669504673105646378938504388", "price":"0.86", "size":"265.57", "side":"SELL", "hash":"13c344ebc186f5500a6b292a874f4bce9664850c", "best_bid":"0.84", "best_ask":"0.85"}], "timestamp":"1778784201051", "event_type":"price_change"}
{"market":"0x2a903c589141bce4a1e50fb98b73397af6820942542793ab10b1df477e912b6e", "price_changes":[{"asset_id":"20436996072316278452977393149218961565084965483366669504673105646378938504388", "price":"0.84", "size":"177.5", "side":"BUY", "hash":"3910832114d56ed90a25068338934f8e76b117ea", "best_bid":"0.84", "best_ask":"0.85"}, {"asset_id":"68919878716222388542639225642064847629616106443780159680232863841946753372582", "price":"0.16", "size":"177.5", "side":"SELL", "hash":"c4d1a12bebe54efd33abc182e15bd92f23f69952", "best_bid":"0.15", "best_ask":"0.16"}], "timestamp":"1778784201052", "event_type":"price_change"}
{"market":"0x2a903c589141bce4a1e50fb98b73397af6820942542793ab10b1df477e912b6e", "price_changes":[{"asset_id":"68919878716222388542639225642064847629616106443780159680232863841946753372582", "price":"0.15", "size":"340.97", "side":"BUY", "hash":"f6c7d5d5c656f5bda9bc8c22ace41ccc9f16acd5", "best_bid":"0.15", "best_ask":"0.16"}, {"asset_id":"20436996072316278452977393149218961565084965483366669504673105646378938504388", "price":"0.85", "size":"340.97", "side":"SELL", "hash":"182316974adc6a7f11406553e595c23100de3591", "best_bid":"0.84", "best_ask":"0.85"}], "timestamp":"1778784201053", "event_type":"price_change"}
{"market":"0x2a903c589141bce4a1e50fb98b73397af6820942542793ab10b1df477e912b6e", "price_changes":[{"asset_id":"68919878716222388542639225642064847629616106443780159680232863841946753372582", "price":"0.14", "size":"235.57", "side":"BUY", "hash":"f6c7d5d5c656f5bda9bc8c22ace41ccc9f16acd5", "best_bid":"0.15", "best_ask":"0.16"}, {"asset_id":"20436996072316278452977393149218961565084965483366669504673105646378938504388", "price":"0.86", "size":"235.57", "side":"SELL", "hash":"182316974adc6a7f11406553e595c23100de3591", "best_bid":"0.84", "best_ask":"0.85"}], "timestamp":"1778784201053", "event_type":"price_change"}
{"market":"0x2a903c589141bce4a1e50fb98b73397af6820942542793ab10b1df477e912b6e", "price_changes":[{"asset_id":"68919878716222388542639225642064847629616106443780159680232863841946753372582", "price":"0.13", "size":"113", "side":"BUY", "hash":"f6c7d5d5c656f5bda9bc8c22ace41ccc9f16acd5", "best_bid":"0.15", "best_ask":"0.16"}, {"asset_id":"20436996072316278452977393149218961565084965483366669504673105646378938504388", "price":"0.87", "size":"113", "side":"SELL", "hash":"182316974adc6a7f11406553e595c23100de3591", "best_bid":"0.84", "best_ask":"0.85"}], "timestamp":"1778784201053", "event_type":"price_change"}
{"market":"0x2a903c589141bce4a1e50fb98b73397af6820942542793ab10b1df477e912b6e", "price_changes":[{"asset_id":"68919878716222388542639225642064847629616106443780159680232863841946753372582", "price":"0.12", "size":"286", "side":"BUY", "hash":"f6c7d5d5c656f5bda9bc8c22ace41ccc9f16acd5", "best_bid":"0.15", "best_ask":"0.16"}, {"asset_id":"20436996072316278452977393149218961565084965483366669504673105646378938504388", "price":"0.88", "size":"286", "side":"SELL", "hash":"182316974adc6a7f11406553e595c23100de3591", "best_bid":"0.84", "best_ask":"0.85"}], "timestamp":"1778784201053", "event_type":"price_change"}
{"market":"0x2a903c589141bce4a1e50fb98b73397af6820942542793ab10b1df477e912b6e", "price_changes":[{"asset_id":"68919878716222388542639225642064847629616106443780159680232863841946753372582", "price":"0.1", "size":"607", "side":"BUY", "hash":"12bfa79034ea9dbe792ce78db1066988616bdda6", "best_bid":"0.15", "best_ask":"0.16"}, {"asset_id":"20436996072316278452977393149218961565084965483366669504673105646378938504388", "price":"0.9", "size":"607", "side":"SELL", "hash":"bb15a7a77ca9a79879409cfe1597cdbf1e89c7c1", "best_bid":"0.84", "best_ask":"0.85"}], "timestamp":"1778784201054", "event_type":"price_change"}
{"market":"0x2a903c589141bce4a1e50fb98b73397af6820942542793ab10b1df477e912b6e", "price_changes":[{"asset_id":"20436996072316278452977393149218961565084965483366669504673105646378938504388", "price":"0.83", "size":"78.97", "side":"BUY", "hash":"e458095c15a7aef8d899cfb81fbbba774332eaee", "best_bid":"0.84", "best_ask":"0.85"}, {"asset_id":"68919878716222388542639225642064847629616106443780159680232863841946753372582", "price":"0.17", "size":"78.97", "side":"SELL", "hash":"34a03d0acab24a52d1fd9aab29b2e2ced8b7d0d9", "best_bid":"0.15", "best_ask":"0.16"}], "timestamp":"1778784201055", "event_type":"price_change"}
{"market":"0x2a903c589141bce4a1e50fb98b73397af6820942542793ab10b1df477e912b6e", "price_changes":[{"asset_id":"20436996072316278452977393149218961565084965483366669504673105646378938504388", "price":"0.82", "size":"319.82", "side":"BUY", "hash":"f0698e488252b822b78c23eef3c1ab8534bba425", "best_bid":"0.84", "best_ask":"0.85"}, {"asset_id":"68919878716222388542639225642064847629616106443780159680232863841946753372582", "price":"0.18", "size":"319.82", "side":"SELL", "hash":"21474155f94a7b6c1f86882d1a75baf74de41bfb", "best_bid":"0.15", "best_ask":"0.16"}], "timestamp":"1778784201057", "event_type":"price_change"}
{"market":"0x2a903c589141bce4a1e50fb98b73397af6820942542793ab10b1df477e912b6e", "price_changes":[{"asset_id":"68919878716222388542639225642064847629616106443780159680232863841946753372582", "price":"0.14", "size":"240.57", "side":"BUY", "hash":"79fb68a55fa5380994605879cbd974ae02d23b58", "best_bid":"0.15", "best_ask":"0.16"}, {"asset_id":"20436996072316278452977393149218961565084965483366669504673105646378938504388", "price":"0.86", "size":"240.57", "side":"SELL", "hash":"268034328f387f35d32220d7c2b3d933aa24c63f", "best_bid":"0.84", "best_ask":"0.85"}], "timestamp":"1778784201059", "event_type":"price_change"}
{"market":"0x2a903c589141bce4a1e50fb98b73397af6820942542793ab10b1df477e912b6e", "price_changes":[{"asset_id":"68919878716222388542639225642064847629616106443780159680232863841946753372582", "price":"0.15", "size":"351.97", "side":"BUY", "hash":"ad950552efd7295026396110d847db1c9875a662", "best_bid":"0.15", "best_ask":"0.16"}, {"asset_id":"20436996072316278452977393149218961565084965483366669504673105646378938504388", "price":"0.85", "size":"351.97", "side":"SELL", "hash":"a5855294eb01d04b7af0ef5bfb0252cf94f985c4", "best_bid":"0.84", "best_ask":"0.85"}], "timestamp":"1778784201060", "event_type":"price_change"}
{"market":"0x2a903c589141bce4a1e50fb98b73397af6820942542793ab10b1df477e912b6e", "price_changes":[{"asset_id":"68919878716222388542639225642064847629616106443780159680232863841946753372582", "price":"0.07", "size":"699.82", "side":"BUY", "hash":"4d72bb03999dbb11c0a8077d3b530ece3aa55b0f", "best_bid":"0.15", "best_ask":"0.16"}, {"asset_id":"20436996072316278452977393149218961565084965483366669504673105646378938504388", "price":"0.93", "size":"699.82", "side":"SELL", "hash":"6f95ed2f29e28ac10d474faaa6755e8e7e93b939", "best_bid":"0.84", "best_ask":"0.85"}], "timestamp":"1778784201060", "event_type":"price_change"}
{"market":"0x2a903c589141bce4a1e50fb98b73397af6820942542793ab10b1df477e912b6e", "price_changes":[{"asset_id":"68919878716222388542639225642064847629616106443780159680232863841946753372582", "price":"0.13", "size":"105", "side":"BUY", "hash":"a55d5155d32a3faf7ae746a264880b3c67537d6d", "best_bid":"0.15", "best_ask":"0.16"}, {"asset_id":"20436996072316278452977393149218961565084965483366669504673105646378938504388", "price":"0.87", "size":"105", "side":"SELL", "hash":"181ae3bc34467a912f6a308db57738e76e81d904", "best_bid":"0.84", "best_ask":"0.85"}], "timestamp":"1778784201061", "event_type":"price_change"}
{"market":"0x2a903c589141bce4a1e50fb98b73397af6820942542793ab10b1df477e912b6e", "price_changes":[{"asset_id":"68919878716222388542639225642064847629616106443780159680232863841946753372582", "price":"0.06", "size":"297.2", "side":"BUY", "hash":"e00ce2db4f2121d4af778dd471de126d7353f770", "best_bid":"0.15", "best_ask":"0.16"}, {"asset_id":"20436996072316278452977393149218961565084965483366669504673105646378938504388", "price":"0.94", "size":"297.2", "side":"SELL", "hash":"42bce1ab40a6e822672c625915dec2388f9a37b3", "best_bid":"0.84", "best_ask":"0.85"}], "timestamp":"1778784201062", "event_type":"price_change"}
{"market":"0x2a903c589141bce4a1e50fb98b73397af6820942542793ab10b1df477e912b6e", "price_changes":[{"asset_id":"68919878716222388542639225642064847629616106443780159680232863841946753372582", "price":"0.04", "size":"1237.82", "side":"BUY", "hash":"e00ce2db4f2121d4af778dd471de126d7353f770", "best_bid":"0.15", "best_ask":"0.16"}, {"asset_id":"20436996072316278452977393149218961565084965483366669504673105646378938504388", "price":"0.96", "size":"1237.82", "side":"SELL", "hash":"42bce1ab40a6e822672c625915dec2388f9a37b3", "best_bid":"0.84", "best_ask":"0.85"}], "timestamp":"1778784201062", "event_type":"price_change"}
{"market":"0x2a903c589141bce4a1e50fb98b73397af6820942542793ab10b1df477e912b6e", "price_changes":[{"asset_id":"68919878716222388542639225642064847629616106443780159680232863841946753372582", "price":"0.09", "size":"333.11", "side":"BUY", "hash":"aebb1ff575a90f059bb496e9a255eec58da4bab9", "best_bid":"0.15", "best_ask":"0.16"}, {"asset_id":"20436996072316278452977393149218961565084965483366669504673105646378938504388", "price":"0.91", "size":"333.11", "side":"SELL", "hash":"8b8f2fa667f9d9145845fd9db17d313802c8a853", "best_bid":"0.84", "best_ask":"0.85"}], "timestamp":"1778784201063", "event_type":"price_change"}
{"market":"0x2a903c589141bce4a1e50fb98b73397af6820942542793ab10b1df477e912b6e", "price_changes":[{"asset_id":"68919878716222388542639225642064847629616106443780159680232863841946753372582", "price":"0.15", "size":"341.97", "side":"BUY", "hash":"4d5feed685a29553c64b0cd77846462b4c842ed0", "best_bid":"0.15", "best_ask":"0.16"}, {"asset_id":"20436996072316278452977393149218961565084965483366669504673105646378938504388", "price":"0.85", "size":"341.97", "side":"SELL", "hash":"2412e11a0efb8dd8a0ea67d600d44aab93addd66", "best_bid":"0.84", "best_ask":"0.85"}], "timestamp":"1778784201064", "event_type":"price_change"}
{"market":"0x2a903c589141bce4a1e50fb98b73397af6820942542793ab10b1df477e912b6e", "price_changes":[{"asset_id":"68919878716222388542639225642064847629616106443780159680232863841946753372582", "price":"0.15", "size":"331.97", "side":"BUY", "hash":"631c07f57a19cb4f34405997403dc926b7b7e7eb", "best_bid":"0.15", "best_ask":"0.16"}, {"asset_id":"20436996072316278452977393149218961565084965483366669504673105646378938504388", "price":"0.85", "size":"331.97", "side":"SELL", "hash":"4595621aa4c11744cd90855115a4e65be5de8c5e", "best_bid":"0.84", "best_ask":"0.85"}], "timestamp":"1778784201064", "event_type":"price_change"}
{"market":"0x2a903c589141bce4a1e50fb98b73397af6820942542793ab10b1df477e912b6e", "price_changes":[{"asset_id":"68919878716222388542639225642064847629616106443780159680232863841946753372582", "price":"0.15", "size":"336.97", "side":"BUY", "hash":"d4711726a460b587415460ee8c5e9d5ecb961d4a", "best_bid":"0.15", "best_ask":"0.16"}, {"asset_id":"20436996072316278452977393149218961565084965483366669504673105646378938504388", "price":"0.85", "size":"336.97", "side":"SELL", "hash":"4c245539f0eaddc1f6687ff6722ef078f708fbb8", "best_bid":"0.84", "best_ask":"0.85"}], "timestamp":"1778784201065", "event_type":"price_change"}
{"market":"0x2a903c589141bce4a1e50fb98b73397af6820942542793ab10b1df477e912b6e", "price_changes":[{"asset_id":"68919878716222388542639225642064847629616106443780159680232863841946753372582", "price":"0.14", "size":"213.88", "side":"BUY", "hash":"3bfce7ec0d185ff65952059596d654e24cfc0fde", "best_bid":"0.15", "best_ask":"0.16"}, {"asset_id":"20436996072316278452977393149218961565084965483366669504673105646378938504388", "price":"0.86", "size":"213.88", "side":"SELL", "hash":"655a85ffe1764ba2f2b2dd61fef166bf9cc8c1d5", "best_bid":"0.84", "best_ask":"0.85"}], "timestamp":"1778784201066", "event_type":"price_change"}
{"market":"0x2a903c589141bce4a1e50fb98b73397af6820942542793ab10b1df477e912b6e", "price_changes":[{"asset_id":"20436996072316278452977393149218961565084965483366669504673105646378938504388", "price":"0.84", "size":"162.5", "side":"BUY", "hash":"320170dde8ea156eaf7f64499d49c915a7a7d714", "best_bid":"0.84", "best_ask":"0.85"}, {"asset_id":"68919878716222388542639225642064847629616106443780159680232863841946753372582", "price":"0.16", "size":"162.5", "side":"SELL", "hash":"cc76468f4a51b96c0426174c62c1f8621d5fdeb1", "best_bid":"0.15", "best_ask":"0.16"}], "timestamp":"1778784201066", "event_type":"price_change"}
{"market":"0x2a903c589141bce4a1e50fb98b73397af6820942542793ab10b1df477e912b6e", "price_changes":[{"asset_id":"20436996072316278452977393149218961565084965483366669504673105646378938504388", "price":"0.85", "size":"341.97", "side":"SELL", "hash":"de3aa25cfe1312c354781f4ff8eb7ffe8af727c0", "best_bid":"0.84", "best_ask":"0.85"}, {"asset_id":"68919878716222388542639225642064847629616106443780159680232863841946753372582", "price":"0.15", "size":"341.97", "side":"BUY", "hash":"d4119be8aba75f6069ef7a812543573a2256c4a0", "best_bid":"0.15", "best_ask":"0.16"}], "timestamp":"1778784201068", "event_type":"price_change"}
{"market":"0x2a903c589141bce4a1e50fb98b73397af6820942542793ab10b1df477e912b6e", "price_changes":[{"asset_id":"68919878716222388542639225642064847629616106443780159680232863841946753372582", "price":"0.15", "size":"331.97", "side":"BUY", "hash":"ce968aab0018a2b86ec6687e3a4372944b95ee5d", "best_bid":"0.15", "best_ask":"0.16"}, {"asset_id":"20436996072316278452977393149218961565084965483366669504673105646378938504388", "price":"0.85", "size":"331.97", "side":"SELL", "hash":"fcb3e9dc09d322b792385427dfac14b691a765e5", "best_bid":"0.84", "best_ask":"0.85"}], "timestamp":"1778784201069", "event_type":"price_change"}
{"market":"0x2a903c589141bce4a1e50fb98b73397af6820942542793ab10b1df477e912b6e", "price_changes":[{"asset_id":"20436996072316278452977393149218961565084965483366669504673105646378938504388", "price":"0.84", "size":"173.5", "side":"BUY", "hash":"6d0b5b429f85dd1d9fa70f996bb1400418863336", "best_bid":"0.84", "best_ask":"0.85"}, {"asset_id":"68919878716222388542639225642064847629616106443780159680232863841946753372582", "price":"0.16", "size":"173.5", "side":"SELL", "hash":"684e453580a7f7e66b12331e5a23b41a90adc365", "best_bid":"0.15", "best_ask":"0.16"}], "timestamp":"1778784201069", "event_type":"price_change"}
{"market":"0x2a903c589141bce4a1e50fb98b73397af6820942542793ab10b1df477e912b6e", "price_changes":[{"asset_id":"68919878716222388542639225642064847629616106443780159680232863841946753372582", "price":"0.15", "size":"321.97", "side":"BUY", "hash":"b58c59da7881d5b8094d2620e2eab3e0f9fb2a3b", "best_bid":"0.15", "best_ask":"0.16"}, {"asset_id":"20436996072316278452977393149218961565084965483366669504673105646378938504388", "price":"0.85", "size":"321.97", "side":"SELL", "hash":"cf7af7f5a3946500c6f53200c4a387b171b6c895", "best_bid":"0.84", "best_ask":"0.85"}], "timestamp":"1778784201071", "event_type":"price_change"}
{"market":"0x2a903c589141bce4a1e50fb98b73397af6820942542793ab10b1df477e912b6e", "price_changes":[{"asset_id":"20436996072316278452977393149218961565084965483366669504673105646378938504388", "price":"0.79", "size":"335.44", "side":"BUY", "hash":"0994e46c5901d496bb80596f902c38d427af6822", "best_bid":"0.84", "best_ask":"0.85"}, {"asset_id":"68919878716222388542639225642064847629616106443780159680232863841946753372582", "price":"0.21", "size":"335.44", "side":"SELL", "hash":"f6b0aeb3a878d96d8996aabfeea43d76452c66c8", "best_bid":"0.15", "best_ask":"0.16"}], "timestamp":"1778784201072", "event_type":"price_change"}
{"market":"0x2a903c589141bce4a1e50fb98b73397af6820942542793ab10b1df477e912b6e", "price_changes":[{"asset_id":"68919878716222388542639225642064847629616106443780159680232863841946753372582", "price":"0.12", "size":"386", "side":"BUY", "hash":"175db9d5ffa1c36700c1c4469d84cd6f91afb5e1", "best_bid":"0.15", "best_ask":"0.16"}, {"asset_id":"20436996072316278452977393149218961565084965483366669504673105646378938504388", "price":"0.88", "size":"386", "side":"SELL", "hash":"2204f7605629f237085a36956d4e5aa136df7bbb", "best_bid":"0.84", "best_ask":"0.85"}], "timestamp":"1778784201076", "event_type":"price_change"}
{"market":"0x2a903c589141bce4a1e50fb98b73397af6820942542793ab10b1df477e912b6e", "price_changes":[{"asset_id":"20436996072316278452977393149218961565084965483366669504673105646378938504388", "price":"0.84", "size":"163.5", "side":"BUY", "hash":"ec19f753840fecc3a9cb29cb6d14618182b02fe1", "best_bid":"0.84", "best_ask":"0.85"}, {"asset_id":"68919878716222388542639225642064847629616106443780159680232863841946753372582", "price":"0.16", "size":"163.5", "side":"SELL", "hash":"5b2366e632956e25eb9769c1b3ecc9eee54cfdf8", "best_bid":"0.15", "best_ask":"0.16"}], "timestamp":"1778784201079", "event_type":"price_change"}
{"market":"0x2a903c589141bce4a1e50fb98b73397af6820942542793ab10b1df477e912b6e", "price_changes":[{"asset_id":"20436996072316278452977393149218961565084965483366669504673105646378938504388", "price":"0.84", "size":"153.5", "side":"BUY", "hash":"8d59258efabbf66bec06b2a9118fb3ecd635945f", "best_bid":"0.84", "best_ask":"0.85"}, {"asset_id":"68919878716222388542639225642064847629616106443780159680232863841946753372582", "price":"0.16", "size":"153.5", "side":"SELL", "hash":"d425e3af45856d6715844347b5c286578b5b4b1e", "best_bid":"0.15", "best_ask":"0.16"}], "timestamp":"1778784201081", "event_type":"price_change"}
{"market":"0x2a903c589141bce4a1e50fb98b73397af6820942542793ab10b1df477e912b6e", "price_changes":[{"asset_id":"68919878716222388542639225642064847629616106443780159680232863841946753372582", "price":"0.15", "size":"331.97", "side":"BUY", "hash":"9bcd5e37cf8a6d7c0be2c57daad15fafff32ec37", "best_bid":"0.15", "best_ask":"0.16"}, {"asset_id":"20436996072316278452977393149218961565084965483366669504673105646378938504388", "price":"0.85", "size":"331.97", "side":"SELL", "hash":"8274261f93d14c43a871ea0206c13d7bda525d93", "best_bid":"0.84", "best_ask":"0.85"}], "timestamp":"1778784201082", "event_type":"price_change"}
{"market":"0x2a903c589141bce4a1e50fb98b73397af6820942542793ab10b1df477e912b6e", "price_changes":[{"asset_id":"68919878716222388542639225642064847629616106443780159680232863841946753372582", "price":"0.15", "size":"340.97", "side":"BUY", "hash":"965e09f3ff6c11fd5ea19dabf5a92bc465c7b726", "best_bid":"0.15", "best_ask":"0.16"}, {"asset_id":"20436996072316278452977393149218961565084965483366669504673105646378938504388", "price":"0.85", "size":"340.97", "side":"SELL", "hash":"b19d12f2717226ac2fde5c035816b559bb0db37a", "best_bid":"0.84", "best_ask":"0.85"}], "timestamp":"1778784201083", "event_type":"price_change"}
{"market":"0x2a903c589141bce4a1e50fb98b73397af6820942542793ab10b1df477e912b6e", "price_changes":[{"asset_id":"68919878716222388542639225642064847629616106443780159680232863841946753372582", "price":"0.15", "size":"330.97", "side":"BUY", "hash":"abdb9f8370b93bacadcbdac4ff54681d411336ed", "best_bid":"0.15", "best_ask":"0.16"}, {"asset_id":"20436996072316278452977393149218961565084965483366669504673105646378938504388", "price":"0.85", "size":"330.97", "side":"SELL", "hash":"cfa92d2b7ac6baa1f25712a3d50cdcf522ec271d", "best_bid":"0.84", "best_ask":"0.85"}], "timestamp":"1778784201084", "event_type":"price_change"}
{"market":"0x2a903c589141bce4a1e50fb98b73397af6820942542793ab10b1df477e912b6e", "price_changes":[{"asset_id":"68919878716222388542639225642064847629616106443780159680232863841946753372582", "price":"0.02", "size":"1427.82", "side":"BUY", "hash":"2bd8a1c8ddc440a98519d1be7531ade7ca1fcca8", "best_bid":"0.15", "best_ask":"0.16"}, {"asset_id":"20436996072316278452977393149218961565084965483366669504673105646378938504388", "price":"0.98", "size":"1427.82", "side":"SELL", "hash":"5fea9f79290a4f18a676c93b4388b8e807f976de", "best_bid":"0.84", "best_ask":"0.85"}], "timestamp":"1778784201085", "event_type":"price_change"}
{"market":"0x2a903c589141bce4a1e50fb98b73397af6820942542793ab10b1df477e912b6e", "price_changes":[{"asset_id":"68919878716222388542639225642064847629616106443780159680232863841946753372582", "price":"0.03", "size":"1090.78", "side":"BUY", "hash":"104d6e1590fb8520488f3b8edda837ec12960964", "best_bid":"0.15", "best_ask":"0.16"}, {"asset_id":"20436996072316278452977393149218961565084965483366669504673105646378938504388", "price":"0.97", "size":"1090.78", "side":"SELL", "hash":"656c3366111f7b8c32366d1e6bdb287382fdd57e", "best_bid":"0.84", "best_ask":"0.85"}], "timestamp":"1778784201086", "event_type":"price_change"}
{"market":"0x2a903c589141bce4a1e50fb98b73397af6820942542793ab10b1df477e912b6e", "price_changes":[{"asset_id":"20436996072316278452977393149218961565084965483366669504673105646378938504388", "price":"0.01", "size":"12000.67", "side":"BUY", "hash":"7cd993ad6340eeb2357a994bde99f0d611aa7005", "best_bid":"0.84", "best_ask":"0.85"}, {"asset_id":"68919878716222388542639225642064847629616106443780159680232863841946753372582", "price":"0.99", "size":"12000.67", "side":"SELL", "hash":"0fdea959b346c56e3945324c423f2440820dc638", "best_bid":"0.15", "best_ask":"0.16"}], "timestamp":"1778784201086", "event_type":"price_change"}
{"market":"0x2a903c589141bce4a1e50fb98b73397af6820942542793ab10b1df477e912b6e", "price_changes":[{"asset_id":"68919878716222388542639225642064847629616106443780159680232863841946753372582", "price":"0.15", "size":"320.97", "side":"BUY", "hash":"0ef8d6213de2348633633a1ba5685bb024558f29", "best_bid":"0.15", "best_ask":"0.16"}, {"asset_id":"20436996072316278452977393149218961565084965483366669504673105646378938504388", "price":"0.85", "size":"320.97", "side":"SELL", "hash":"afbaa5b96a5f8e89487828c0fb834e651f960dc6", "best_bid":"0.84", "best_ask":"0.85"}], "timestamp":"1778784201087", "event_type":"price_change"}
{"market":"0x2a903c589141bce4a1e50fb98b73397af6820942542793ab10b1df477e912b6e", "price_changes":[{"asset_id":"68919878716222388542639225642064847629616106443780159680232863841946753372582", "price":"0.09", "size":"366.66", "side":"BUY", "hash":"60ebf7ffe267bd00bc313ebc8b40009130c5242c", "best_bid":"0.15", "best_ask":"0.16"}, {"asset_id":"20436996072316278452977393149218961565084965483366669504673105646378938504388", "price":"0.91", "size":"366.66", "side":"SELL", "hash":"f4ad042e16b964704476ff61e25bd12b6551098f", "best_bid":"0.84", "best_ask":"0.85"}], "timestamp":"1778784201088", "event_type":"price_change"}
{"market":"0x2a903c589141bce4a1e50fb98b73397af6820942542793ab10b1df477e912b6e", "price_changes":[{"asset_id":"68919878716222388542639225642064847629616106443780159680232863841946753372582", "price":"0.15", "size":"335.97", "side":"BUY", "hash":"7636ca5cb6a40f10774ac912f7e94f17cc7c323c", "best_bid":"0.15", "best_ask":"0.16"}, {"asset_id":"20436996072316278452977393149218961565084965483366669504673105646378938504388", "price":"0.85", "size":"335.97", "side":"SELL", "hash":"a67b540868de0a949b13b8cf433d4b967eb8791f", "best_bid":"0.84", "best_ask":"0.85"}], "timestamp":"1778784201089", "event_type":"price_change"}
{"market":"0x2a903c589141bce4a1e50fb98b73397af6820942542793ab10b1df477e912b6e", "price_changes":[{"asset_id":"20436996072316278452977393149218961565084965483366669504673105646378938504388", "price":"0.84", "size":"147.5", "side":"BUY", "hash":"b6ccc922cfde39c1109a505022dd2abade16d039", "best_bid":"0.84", "best_ask":"0.85"}, {"asset_id":"68919878716222388542639225642064847629616106443780159680232863841946753372582", "price":"0.16", "size":"147.5", "side":"SELL", "hash":"c8916b200fa5964ecb5c23c936c6b5ddaa478c6c", "best_bid":"0.15", "best_ask":"0.16"}], "timestamp":"1778784201090", "event_type":"price_change"}
{"market":"0x2a903c589141bce4a1e50fb98b73397af6820942542793ab10b1df477e912b6e", "price_changes":[{"asset_id":"20436996072316278452977393149218961565084965483366669504673105646378938504388", "price":"0.84", "size":"137.5", "side":"BUY", "hash":"3d4cfe08705bb841c4909ab9c50a10457c611234", "best_bid":"0.84", "best_ask":"0.85"}, {"asset_id":"68919878716222388542639225642064847629616106443780159680232863841946753372582", "price":"0.16", "size":"137.5", "side":"SELL", "hash":"5190cc34dad3f6f22918c40027a693ddfbae4c18", "best_bid":"0.15", "best_ask":"0.16"}], "timestamp":"1778784201091", "event_type":"price_change"}
{"market":"0x2a903c589141bce4a1e50fb98b73397af6820942542793ab10b1df477e912b6e", "price_changes":[{"asset_id":"68919878716222388542639225642064847629616106443780159680232863841946753372582", "price":"0.15", "size":"345.97", "side":"BUY", "hash":"8aa1c405d9f87cf719255afe10724288990565b6", "best_bid":"0.15", "best_ask":"0.16"}, {"asset_id":"20436996072316278452977393149218961565084965483366669504673105646378938504388", "price":"0.85", "size":"345.97", "side":"SELL", "hash":"f902b789e8a91c39d6ac60d50aa7a16bb340c4bb", "best_bid":"0.84", "best_ask":"0.85"}], "timestamp":"1778784201092", "event_type":"price_change"}
{"market":"0x2a903c589141bce4a1e50fb98b73397af6820942542793ab10b1df477e912b6e", "price_changes":[{"asset_id":"68919878716222388542639225642064847629616106443780159680232863841946753372582", "price":"0.15", "size":"332.97", "side":"BUY", "hash":"d8fd7e5861222f395ee539254669c8a1a9308dbd", "best_bid":"0.15", "best_ask":"0.16"}, {"asset_id":"20436996072316278452977393149218961565084965483366669504673105646378938504388", "price":"0.85", "size":"332.97", "side":"SELL", "hash":"0d8ba8e868d5f7e6125e1eaef7b6cfc229ff5c0d", "best_bid":"0.84", "best_ask":"0.85"}], "timestamp":"1778784201093", "event_type":"price_change"}
{"market":"0x2a903c589141bce4a1e50fb98b73397af6820942542793ab10b1df477e912b6e", "price_changes":[{"asset_id":"68919878716222388542639225642064847629616106443780159680232863841946753372582", "price":"0.15", "size":"326.24", "side":"BUY", "hash":"6cc5085714b7c583b2aca32e8ae2e8cab6c41818", "best_bid":"0.15", "best_ask":"0.16"}, {"asset_id":"20436996072316278452977393149218961565084965483366669504673105646378938504388", "price":"0.85", "size":"326.24", "side":"SELL", "hash":"d21d0f58525023c27522db3962502789d86c5550", "best_bid":"0.84", "best_ask":"0.85"}], "timestamp":"1778784201094", "event_type":"price_change"}
{"market":"0x2a903c589141bce4a1e50fb98b73397af6820942542793ab10b1df477e912b6e", "price_changes":[{"asset_id":"20436996072316278452977393149218961565084965483366669504673105646378938504388", "price":"0.8", "size":"128.8", "side":"BUY", "hash":"8e2ec353242b2e1ae36a438a45a5fd1ec6697c71", "best_bid":"0.84", "best_ask":"0.85"}, {"asset_id":"68919878716222388542639225642064847629616106443780159680232863841946753372582", "price":"0.2", "size":"128.8", "side":"SELL", "hash":"e5c4a5f8a71b808ac24595b8aec83f2b8ef3ce4b", "best_bid":"0.15", "best_ask":"0.16"}], "timestamp":"1778784201095", "event_type":"price_change"}
{"market":"0x2a903c589141bce4a1e50fb98b73397af6820942542793ab10b1df477e912b6e", "price_changes":[{"asset_id":"20436996072316278452977393149218961565084965483366669504673105646378938504388", "price":"0.64", "size":"492", "side":"BUY", "hash":"805d0199d5a2c7cb6222fa2b491584e63c101b2a", "best_bid":"0.84", "best_ask":"0.85"}, {"asset_id":"68919878716222388542639225642064847629616106443780159680232863841946753372582", "price":"0.36", "size":"492", "side":"SELL", "hash":"6906d438b669379032f0624c8c8d7bcc56a4e536", "best_bid":"0.15", "best_ask":"0.16"}], "timestamp":"1778784201096", "event_type":"price_change"}
{"market":"0x2a903c589141bce4a1e50fb98b73397af6820942542793ab10b1df477e912b6e", "price_changes":[{"asset_id":"68919878716222388542639225642064847629616106443780159680232863841946753372582", "price":"0.13", "size":"205", "side":"BUY", "hash":"9fbdad5cda33a2db6067358fe29c64e5334bc3e8", "best_bid":"0.15", "best_ask":"0.16"}, {"asset_id":"20436996072316278452977393149218961565084965483366669504673105646378938504388", "price":"0.87", "size":"205", "side":"SELL", "hash":"c15ea00838251d7b03be5ea748ad3fb4e4bedc66", "best_bid":"0.84", "best_ask":"0.85"}], "timestamp":"1778784201098", "event_type":"price_change"}
{"market":"0x2a903c589141bce4a1e50fb98b73397af6820942542793ab10b1df477e912b6e", "price_changes":[{"asset_id":"20436996072316278452977393149218961565084965483366669504673105646378938504388", "price":"0.83", "size":"83.97", "side":"BUY", "hash":"a9945555dd7c393c6327236c1506d6f89242b85d", "best_bid":"0.84", "best_ask":"0.85"}, {"asset_id":"68919878716222388542639225642064847629616106443780159680232863841946753372582", "price":"0.17", "size":"83.97", "side":"SELL", "hash":"ee7b2d47f7f0929ae8540e6804342728ae637b35", "best_bid":"0.15", "best_ask":"0.16"}], "timestamp":"1778784201098", "event_type":"price_change"}
{"market":"0x2a903c589141bce4a1e50fb98b73397af6820942542793ab10b1df477e912b6e", "price_changes":[{"asset_id":"68919878716222388542639225642064847629616106443780159680232863841946753372582", "price":"0.07", "size":"656.69", "side":"BUY", "hash":"a3b370fa55e06f205513e332c6b95b04c3116e07", "best_bid":"0.15", "best_ask":"0.16"}, {"asset_id":"20436996072316278452977393149218961565084965483366669504673105646378938504388", "price":"0.93", "size":"656.69", "side":"SELL", "hash":"083f3c34d9e2f25abe44995bbdd7fa34d026127a", "best_bid":"0.84", "best_ask":"0.85"}], "timestamp":"1778784201100", "event_type":"price_change"}
{"market":"0x2a903c589141bce4a1e50fb98b73397af6820942542793ab10b1df477e912b6e", "price_changes":[{"asset_id":"20436996072316278452977393149218961565084965483366669504673105646378938504388", "price":"0.79", "size":"365.44", "side":"BUY", "hash":"b8a784f51f578fe8194320ba8ed44caabd1a5797", "best_bid":"0.84", "best_ask":"0.85"}, {"asset_id":"68919878716222388542639225642064847629616106443780159680232863841946753372582", "price":"0.21", "size":"365.44", "side":"SELL", "hash":"de12123b3f756b10156037c9116eb5b4d00965ae", "best_bid":"0.15", "best_ask":"0.16"}], "timestamp":"1778784201100", "event_type":"price_change"}
{"market":"0x2a903c589141bce4a1e50fb98b73397af6820942542793ab10b1df477e912b6e", "price_changes":[{"asset_id":"68919878716222388542639225642064847629616106443780159680232863841946753372582", "price":"0.12", "size":"416", "side":"BUY", "hash":"8ed1ec1294d5f98af5e831146c996215c333b8d0", "best_bid":"0.15", "best_ask":"0.16"}, {"asset_id":"20436996072316278452977393149218961565084965483366669504673105646378938504388", "price":"0.88", "size":"416", "side":"SELL", "hash":"5e86ad7f53000f600a9d30cb480108dc274d73ef", "best_bid":"0.84", "best_ask":"0.85"}], "timestamp":"1778784201102", "event_type":"price_change"}
{"market":"0x2a903c589141bce4a1e50fb98b73397af6820942542793ab10b1df477e912b6e", "price_changes":[{"asset_id":"20436996072316278452977393149218961565084965483366669504673105646378938504388", "price":"0.84", "size":"120.5", "side":"BUY", "hash":"4fd26174031f01a97ec732f0b4737f56734318f4", "best_bid":"0.84", "best_ask":"0.85"}, {"asset_id":"68919878716222388542639225642064847629616106443780159680232863841946753372582", "price":"0.16", "size":"120.5", "side":"SELL", "hash":"f7feed940777942b958baaee432ba79be4817232", "best_bid":"0.15", "best_ask":"0.16"}], "timestamp":"1778784201102", "event_type":"price_change"}
{"market":"0x2a903c589141bce4a1e50fb98b73397af6820942542793ab10b1df477e912b6e", "price_changes":[{"asset_id":"20436996072316278452977393149218961565084965483366669504673105646378938504388", "price":"0.82", "size":"289.82", "side":"BUY", "hash":"16a58f12787c9d95978d271ec4be04a2c394683c", "best_bid":"0.84", "best_ask":"0.85"}, {"asset_id":"68919878716222388542639225642064847629616106443780159680232863841946753372582", "price":"0.18", "size":"289.82", "side":"SELL", "hash":"5a4a5071b3fa766dcd273b78326a12c17c67fb96", "best_bid":"0.15", "best_ask":"0.16"}], "timestamp":"1778784201113", "event_type":"price_change"}
{"market":"0x2a903c589141bce4a1e50fb98b73397af6820942542793ab10b1df477e912b6e", "price_changes":[{"asset_id":"68919878716222388542639225642064847629616106443780159680232863841946753372582", "price":"0.08", "size":"694.53", "side":"BUY", "hash":"054fbfd0beb72c5f5b709176037ab2bd4f4ba00d", "best_bid":"0.15", "best_ask":"0.16"}, {"asset_id":"20436996072316278452977393149218961565084965483366669504673105646378938504388", "price":"0.92", "size":"694.53", "side":"SELL", "hash":"2ac6df240ed21b0aef4d5854b53d1ccf268705c4", "best_bid":"0.84", "best_ask":"0.85"}], "timestamp":"1778784201114", "event_type":"price_change"}
{"market":"0x2a903c589141bce4a1e50fb98b73397af6820942542793ab10b1df477e912b6e", "price_changes":[{"asset_id":"68919878716222388542639225642064847629616106443780159680232863841946753372582", "price":"0.15", "size":"334.24", "side":"BUY", "hash":"6a854a7966f20404da1cb55c0da15f9412775fc7", "best_bid":"0.15", "best_ask":"0.16"}, {"asset_id":"20436996072316278452977393149218961565084965483366669504673105646378938504388", "price":"0.85", "size":"334.24", "side":"SELL", "hash":"ad191f6c9e6bdc3531d494e9da38ad9b7be166b6", "best_bid":"0.84", "best_ask":"0.85"}], "timestamp":"1778784201115", "event_type":"price_change"}
{"market":"0x2a903c589141bce4a1e50fb98b73397af6820942542793ab10b1df477e912b6e", "price_changes":[{"asset_id":"68919878716222388542639225642064847629616106443780159680232863841946753372582", "price":"0.15", "size":"344.24", "side":"BUY", "hash":"b708ee5c2e4f7c0304751f31f3740f988e966081", "best_bid":"0.15", "best_ask":"0.16"}, {"asset_id":"20436996072316278452977393149218961565084965483366669504673105646378938504388", "price":"0.85", "size":"344.24", "side":"SELL", "hash":"43debfb6a3e3edb410f4248ba5a2ca4e4f855cb6", "best_bid":"0.84", "best_ask":"0.85"}], "timestamp":"1778784201116", "event_type":"price_change"}
{"market":"0x2a903c589141bce4a1e50fb98b73397af6820942542793ab10b1df477e912b6e", "price_changes":[{"asset_id":"68919878716222388542639225642064847629616106443780159680232863841946753372582", "price":"0.11", "size":"637.52", "side":"BUY", "hash":"7184ce534a437e9e15908c1bab5341321324de1c", "best_bid":"0.15", "best_ask":"0.16"}, {"asset_id":"20436996072316278452977393149218961565084965483366669504673105646378938504388", "price":"0.89", "size":"637.52", "side":"SELL", "hash":"637af725b0b21c2815428c53158cdeeea2d327a5", "best_bid":"0.84", "best_ask":"0.85"}], "timestamp":"1778784201117", "event_type":"price_change"}
{"market":"0x2a903c589141bce4a1e50fb98b73397af6820942542793ab10b1df477e912b6e", "price_changes":[{"asset_id":"68919878716222388542639225642064847629616106443780159680232863841946753372582", "price":"0.14", "size":"205.88", "side":"BUY", "hash":"a3f134f7755dbe70e174cd72fe11394587e7b71e", "best_bid":"0.15", "best_ask":"0.16"}, {"asset_id":"20436996072316278452977393149218961565084965483366669504673105646378938504388", "price":"0.86", "size":"205.88", "side":"SELL", "hash":"d935ecefa61e38948c5efda148a2a4bd7a3f2154", "best_bid":"0.84", "best_ask":"0.85"}], "timestamp":"1778784201117", "event_type":"price_change"}
{"market":"0x2a903c589141bce4a1e50fb98b73397af6820942542793ab10b1df477e912b6e", "price_changes":[{"asset_id":"68919878716222388542639225642064847629616106443780159680232863841946753372582", "price":"0.15", "size":"337.24", "side":"BUY", "hash":"a3f134f7755dbe70e174cd72fe11394587e7b71e", "best_bid":"0.15", "best_ask":"0.16"}, {"asset_id":"20436996072316278452977393149218961565084965483366669504673105646378938504388", "price":"0.85", "size":"337.24", "side":"SELL", "hash":"d935ecefa61e38948c5efda148a2a4bd7a3f2154", "best_bid":"0.84", "best_ask":"0.85"}], "timestamp":"1778784201117", "event_type":"price_change"}
{"market":"0x2a903c589141bce4a1e50fb98b73397af6820942542793ab10b1df477e912b6e", "price_changes":[{"asset_id":"68919878716222388542639225642064847629616106443780159680232863841946753372582", "price":"0.15", "size":"346.24", "side":"BUY", "hash":"3c5cb7ba78cfd958eccc024c12f5a01add3aa6f9", "best_bid":"0.15", "best_ask":"0.16"}, {"asset_id":"20436996072316278452977393149218961565084965483366669504673105646378938504388", "price":"0.85", "size":"346.24", "side":"SELL", "hash":"2bbe6e7020273a781f3602e84f0d5fe1401e43d4", "best_bid":"0.84", "best_ask":"0.85"}], "timestamp":"1778784201119", "event_type":"price_change"}
{"market":"0x2a903c589141bce4a1e50fb98b73397af6820942542793ab10b1df477e912b6e", "price_changes":[{"asset_id":"68919878716222388542639225642064847629616106443780159680232863841946753372582", "price":"0.15", "size":"376.24", "side":"BUY", "hash":"db76a598011d1d2ea5c122f09aa6df93c7f78b2d", "best_bid":"0.15", "best_ask":"0.16"}, {"asset_id":"20436996072316278452977393149218961565084965483366669504673105646378938504388", "price":"0.85", "size":"376.24", "side":"SELL", "hash":"5ef2b510790ca604f51baaf72a393fe9bb4ce529", "best_bid":"0.84", "best_ask":"0.85"}], "timestamp":"1778784201119", "event_type":"price_change"}
{"market":"0x2a903c589141bce4a1e50fb98b73397af6820942542793ab10b1df477e912b6e", "price_changes":[{"asset_id":"68919878716222388542639225642064847629616106443780159680232863841946753372582", "price":"0.15", "size":"381.24", "side":"BUY", "hash":"cc49e3c906305b4d20f1ad643301ba2dea08aba2", "best_bid":"0.15", "best_ask":"0.16"}, {"asset_id":"20436996072316278452977393149218961565084965483366669504673105646378938504388", "price":"0.85", "size":"381.24", "side":"SELL", "hash":"b1e48b0471f8560d9ee538dc56e52a702f42de53", "best_bid":"0.84", "best_ask":"0.85"}], "timestamp":"1778784201120", "event_type":"price_change"}
{"market":"0x2a903c589141bce4a1e50fb98b73397af6820942542793ab10b1df477e912b6e", "price_changes":[{"asset_id":"68919878716222388542639225642064847629616106443780159680232863841946753372582", "price":"0.15", "size":"371.24", "side":"BUY", "hash":"06ea303c4389da4a0e7bd9a3452015000228df61", "best_bid":"0.15", "best_ask":"0.16"}, {"asset_id":"20436996072316278452977393149218961565084965483366669504673105646378938504388", "price":"0.85", "size":"371.24", "side":"SELL", "hash":"4e9cf63b2bf64e1cdabbaef8716b82de9c19830c", "best_bid":"0.84", "best_ask":"0.85"}], "timestamp":"1778784201121", "event_type":"price_change"}
{"market":"0x2a903c589141bce4a1e50fb98b73397af6820942542793ab10b1df477e912b6e", "price_changes":[{"asset_id":"68919878716222388542639225642064847629616106443780159680232863841946753372582", "price":"0.11", "size":"667.52", "side":"BUY", "hash":"55e82715a7a87fb14a219a6ff6defd928ce1b286", "best_bid":"0.15", "best_ask":"0.16"}, {"asset_id":"20436996072316278452977393149218961565084965483366669504673105646378938504388", "price":"0.89", "size":"667.52", "side":"SELL", "hash":"d0a1832f9204acd3c68aef37c007e43da1fc13a4", "best_bid":"0.84", "best_ask":"0.85"}], "timestamp":"1778784201122", "event_type":"price_change"}
{"market":"0x2a903c589141bce4a1e50fb98b73397af6820942542793ab10b1df477e912b6e", "price_changes":[{"asset_id":"68919878716222388542639225642064847629616106443780159680232863841946753372582", "price":"0.15", "size":"380.24", "side":"BUY", "hash":"fcd4d28892e08b5d9a0322439f2810296e2a365e", "best_bid":"0.15", "best_ask":"0.16"}, {"asset_id":"20436996072316278452977393149218961565084965483366669504673105646378938504388", "price":"0.85", "size":"380.24", "side":"SELL", "hash":"50a4929cbd0d231e153b5c37bdf879200987fcd4", "best_bid":"0.84", "best_ask":"0.85"}], "timestamp":"1778784201123", "event_type":"price_change"}
{"market":"0x2a903c589141bce4a1e50fb98b73397af6820942542793ab10b1df477e912b6e", "price_changes":[{"asset_id":"68919878716222388542639225642064847629616106443780159680232863841946753372582", "price":"0.15", "size":"390.24", "side":"BUY", "hash":"55d81dc27b469e50ac25b6fedf6420f528ca1c5b", "best_bid":"0.15", "best_ask":"0.16"}, {"asset_id":"20436996072316278452977393149218961565084965483366669504673105646378938504388", "price":"0.85", "size":"390.24", "side":"SELL", "hash":"c4392f64246064fcfac98574f44c8a54bc183a77", "best_bid":"0.84", "best_ask":"0.85"}], "timestamp":"1778784201124", "event_type":"price_change"}
{"market":"0x2a903c589141bce4a1e50fb98b73397af6820942542793ab10b1df477e912b6e", "price_changes":[{"asset_id":"20436996072316278452977393149218961565084965483366669504673105646378938504388", "price":"0.79", "size":"360.44", "side":"BUY", "hash":"0b38b843629eafe3c069449c9c7c6d96206ca241", "best_bid":"0.84", "best_ask":"0.85"}, {"asset_id":"68919878716222388542639225642064847629616106443780159680232863841946753372582", "price":"0.21", "size":"360.44", "side":"SELL", "hash":"1c9ab767ef29eb57e7e706dacdab6469fc9de06c", "best_bid":"0.15", "best_ask":"0.16"}], "timestamp":"1778784201124", "event_type":"price_change"}
{"market":"0x2a903c589141bce4a1e50fb98b73397af6820942542793ab10b1df477e912b6e", "price_changes":[{"asset_id":"68919878716222388542639225642064847629616106443780159680232863841946753372582", "price":"0.15", "size":"400.24", "side":"BUY", "hash":"23899ec27438000b3ffee0584b9c15d3187c9401", "best_bid":"0.15", "best_ask":"0.16"}, {"asset_id":"20436996072316278452977393149218961565084965483366669504673105646378938504388", "price":"0.85", "size":"400.24", "side":"SELL", "hash":"26dae19400759e2122c8458ff07f8f6213b14950", "best_bid":"0.84", "best_ask":"0.85"}], "timestamp":"1778784201125", "event_type":"price_change"}
{"market":"0x2a903c589141bce4a1e50fb98b73397af6820942542793ab10b1df477e912b6e", "price_changes":[{"asset_id":"68919878716222388542639225642064847629616106443780159680232863841946753372582", "price":"0.12", "size":"424.41", "side":"BUY", "hash":"21a0b6c81c610a4ae9c75729912a1c3fc8c7e731", "best_bid":"0.15", "best_ask":"0.16"}, {"asset_id":"20436996072316278452977393149218961565084965483366669504673105646378938504388", "price":"0.88", "size":"424.41", "side":"SELL", "hash":"60a31d1af669f26692c5d22e22c16fc05a6ff76b", "best_bid":"0.84", "best_ask":"0.85"}], "timestamp":"1778784201126", "event_type":"price_change"}
{"market":"0x2a903c589141bce4a1e50fb98b73397af6820942542793ab10b1df477e912b6e", "price_changes":[{"asset_id":"68919878716222388542639225642064847629616106443780159680232863841946753372582", "price":"0.15", "size":"410.24", "side":"BUY", "hash":"6a1433bbac430660ec6f5113cbb6879657efa74f", "best_bid":"0.15", "best_ask":"0.16"}, {"asset_id":"20436996072316278452977393149218961565084965483366669504673105646378938504388", "price":"0.85", "size":"410.24", "side":"SELL", "hash":"d9ec032ad3a85956e33e80df82e3a9989dfd8ccd", "best_bid":"0.84", "best_ask":"0.85"}], "timestamp":"1778784201127", "event_type":"price_change"}
{"market":"0x2a903c589141bce4a1e50fb98b73397af6820942542793ab10b1df477e912b6e", "price_changes":[{"asset_id":"68919878716222388542639225642064847629616106443780159680232863841946753372582", "price":"0.09", "size":"333.11", "side":"BUY", "hash":"ef67a591bcbd1d9f3a61e25c14ca291fa726c0a4", "best_bid":"0.15", "best_ask":"0.16"}, {"asset_id":"20436996072316278452977393149218961565084965483366669504673105646378938504388", "price":"0.91", "size":"333.11", "side":"SELL", "hash":"66e6c99f2390ce0fb8dd928860e798a254c4b8ad", "best_bid":"0.84", "best_ask":"0.85"}], "timestamp":"1778784201127", "event_type":"price_change"}
{"market":"0x2a903c589141bce4a1e50fb98b73397af6820942542793ab10b1df477e912b6e", "price_changes":[{"asset_id":"68919878716222388542639225642064847629616106443780159680232863841946753372582", "price":"0.1", "size":"707", "side":"BUY", "hash":"022b5d5ab9050e8307431d241d8aeecc6b1ff189", "best_bid":"0.15", "best_ask":"0.16"}, {"asset_id":"20436996072316278452977393149218961565084965483366669504673105646378938504388", "price":"0.9", "size":"707", "side":"SELL", "hash":"33e40b01da55eeb9d5095eb158faa94931892a78", "best_bid":"0.84", "best_ask":"0.85"}], "timestamp":"1778784201128", "event_type":"price_change"}
{"market":"0x2a903c589141bce4a1e50fb98b73397af6820942542793ab10b1df477e912b6e", "price_changes":[{"asset_id":"68919878716222388542639225642064847629616106443780159680232863841946753372582", "price":"0.15", "size":"420.24", "side":"BUY", "hash":"726fd2a484ed6756d99a140ae86dbc52172a7096", "best_bid":"0.15", "best_ask":"0.16"}, {"asset_id":"20436996072316278452977393149218961565084965483366669504673105646378938504388", "price":"0.85", "size":"420.24", "side":"SELL", "hash":"9eb1f71f9de2a95f9b3a55b765a425f13a2a9399", "best_bid":"0.84", "best_ask":"0.85"}], "timestamp":"1778784201129", "event_type":"price_change"}
{"market":"0x2a903c589141bce4a1e50fb98b73397af6820942542793ab10b1df477e912b6e", "price_changes":[{"asset_id":"68919878716222388542639225642064847629616106443780159680232863841946753372582", "price":"0.14", "size":"235.88", "side":"BUY", "hash":"87a1edf642df768e64157614ee675e8180c18e60", "best_bid":"0.15", "best_ask":"0.16"}, {"asset_id":"20436996072316278452977393149218961565084965483366669504673105646378938504388", "price":"0.86", "size":"235.88", "side":"SELL", "hash":"6103166e5b35d50190399e4d10c81428ea77d37a", "best_bid":"0.84", "best_ask":"0.85"}], "timestamp":"1778784201129", "event_type":"price_change"}
{"market":"0x2a903c589141bce4a1e50fb98b73397af6820942542793ab10b1df477e912b6e", "price_changes":[{"asset_id":"68919878716222388542639225642064847629616106443780159680232863841946753372582", "price":"0.15", "size":"430.24", "side":"BUY", "hash":"f00a2bdc8c6dc25db7e6853b92102b2c1ff0e358", "best_bid":"0.15", "best_ask":"0.16"}, {"asset_id":"20436996072316278452977393149218961565084965483366669504673105646378938504388", "price":"0.85", "size":"430.24", "side":"SELL", "hash":"fb7721ecf6bede76ad3b9c56b70000a35c6f36bf", "best_bid":"0.84", "best_ask":"0.85"}], "timestamp":"1778784201130", "event_type":"price_change"}
{"market":"0x2a903c589141bce4a1e50fb98b73397af6820942542793ab10b1df477e912b6e", "price_changes":[{"asset_id":"68919878716222388542639225642064847629616106443780159680232863841946753372582", "price":"0.15", "size":"420.24", "side":"BUY", "hash":"ef59f4d82b5f28b8b7e2282e55ab06d760f75c40", "best_bid":"0.15", "best_ask":"0.16"}, {"asset_id":"20436996072316278452977393149218961565084965483366669504673105646378938504388", "price":"0.85", "size":"420.24", "side":"SELL", "hash":"4aab71569e4f5eec58162c5a25bb50bdfd11f0f7", "best_bid":"0.84", "best_ask":"0.85"}], "timestamp":"1778784201131", "event_type":"price_change"}
{"market":"0x2a903c589141bce4a1e50fb98b73397af6820942542793ab10b1df477e912b6e", "price_changes":[{"asset_id":"20436996072316278452977393149218961565084965483366669504673105646378938504388", "price":"0.83", "size":"60", "side":"BUY", "hash":"03cc0fc27c96b31c94700497f7f3fd879b8ff3d8", "best_bid":"0.84", "best_ask":"0.85"}, {"asset_id":"68919878716222388542639225642064847629616106443780159680232863841946753372582", "price":"0.17", "size":"60", "side":"SELL", "hash":"73aa4a7ab963fe0de55e8ee1dc242f871ea89aaa", "best_bid":"0.15", "best_ask":"0.16"}], "timestamp":"1778784201131", "event_type":"price_change"}
{"market":"0x2a903c589141bce4a1e50fb98b73397af6820942542793ab10b1df477e912b6e", "price_changes":[{"asset_id":"20436996072316278452977393149218961565084965483366669504673105646378938504388", "price":"0.51", "size":"803", "side":"BUY", "hash":"82e6f3c2bc2393d87d3e60853ad1129f39148edb", "best_bid":"0.84", "best_ask":"0.85"}, {"asset_id":"68919878716222388542639225642064847629616106443780159680232863841946753372582", "price":"0.49", "size":"803", "side":"SELL", "hash":"34ad1f8ac3e768ae91f5f01c98f84922084b2116", "best_bid":"0.15", "best_ask":"0.16"}], "timestamp":"1778784201132", "event_type":"price_change"}
{"market":"0x2a903c589141bce4a1e50fb98b73397af6820942542793ab10b1df477e912b6e", "price_changes":[{"asset_id":"68919878716222388542639225642064847629616106443780159680232863841946753372582", "price":"0.15", "size":"430.24", "side":"BUY", "hash":"9d69b37c8dbfa5212f85920b25a9609e5e107581", "best_bid":"0.15", "best_ask":"0.16"}, {"asset_id":"20436996072316278452977393149218961565084965483366669504673105646378938504388", "price":"0.85", "size":"430.24", "side":"SELL", "hash":"ba24f20e4932aaa09ef5173cbf780fd7bd1684d4", "best_bid":"0.84", "best_ask":"0.85"}], "timestamp":"1778784201134", "event_type":"price_change"}
{"market":"0x2a903c589141bce4a1e50fb98b73397af6820942542793ab10b1df477e912b6e", "price_changes":[{"asset_id":"68919878716222388542639225642064847629616106443780159680232863841946753372582", "price":"0.15", "size":"420.24", "side":"BUY", "hash":"39b873ce53127238622f2f0b06266e95d251397d", "best_bid":"0.15", "best_ask":"0.16"}, {"asset_id":"20436996072316278452977393149218961565084965483366669504673105646378938504388", "price":"0.85", "size":"420.24", "side":"SELL", "hash":"2da69ec372e28c4285a0c6edc122f2638b065d39", "best_bid":"0.84", "best_ask":"0.85"}], "timestamp":"1778784201135", "event_type":"price_change"}
{"market":"0x2a903c589141bce4a1e50fb98b73397af6820942542793ab10b1df477e912b6e", "price_changes":[{"asset_id":"20436996072316278452977393149218961565084965483366669504673105646378938504388", "price":"0.84", "size":"133.17", "side":"BUY", "hash":"90a3dd5f0088d634b791189b736927f0c25a7c4d", "best_bid":"0.84", "best_ask":"0.85"}, {"asset_id":"68919878716222388542639225642064847629616106443780159680232863841946753372582", "price":"0.16", "size":"133.17", "side":"SELL", "hash":"a828ccb1f3e26f44c092802a34088811f6d8de4f", "best_bid":"0.15", "best_ask":"0.16"}], "timestamp":"1778784201135", "event_type":"price_change"}
{"market":"0x2a903c589141bce4a1e50fb98b73397af6820942542793ab10b1df477e912b6e", "price_changes":[{"asset_id":"20436996072316278452977393149218961565084965483366669504673105646378938504388", "price":"0.73", "size":"470.2", "side":"BUY", "hash":"f56e732a6306016c32c816109768e6a52ebee3ba", "best_bid":"0.84", "best_ask":"0.85"}, {"asset_id":"68919878716222388542639225642064847629616106443780159680232863841946753372582", "price":"0.27", "size":"470.2", "side":"SELL", "hash":"e3041518455095d731a0babefb2d80e5e5463883", "best_bid":"0.15", "best_ask":"0.16"}], "timestamp":"1778784201136", "event_type":"price_change"}
{"market":"0x2a903c589141bce4a1e50fb98b73397af6820942542793ab10b1df477e912b6e", "price_changes":[{"asset_id":"20436996072316278452977393149218961565084965483366669504673105646378938504388", "price":"0.84", "size":"119.17", "side":"BUY", "hash":"0792ef4933e54cb33a840fd75af02872bd43b21b", "best_bid":"0.84", "best_ask":"0.85"}, {"asset_id":"68919878716222388542639225642064847629616106443780159680232863841946753372582", "price":"0.16", "size":"119.17", "side":"SELL", "hash":"188843a992e81831b80b121c640620e85f84b239", "best_bid":"0.15", "best_ask":"0.16"}], "timestamp":"1778784201137", "event_type":"price_change"}
{"market":"0x2a903c589141bce4a1e50fb98b73397af6820942542793ab10b1df477e912b6e", "price_changes":[{"asset_id":"68919878716222388542639225642064847629616106443780159680232863841946753372582", "price":"0.12", "size":"424.41", "side":"BUY", "hash":"94c3c530cb8f07c0cb2c5ab74c22c4ebc02d1577", "best_bid":"0.15", "best_ask":"0.16"}, {"asset_id":"20436996072316278452977393149218961565084965483366669504673105646378938504388", "price":"0.88", "size":"424.41", "side":"SELL", "hash":"6960d2f33f02f808919c780d507094c4e8c42cba", "best_bid":"0.84", "best_ask":"0.85"}], "timestamp":"1778784201139", "event_type":"price_change"}
{"market":"0x2a903c589141bce4a1e50fb98b73397af6820942542793ab10b1df477e912b6e", "price_changes":[{"asset_id":"68919878716222388542639225642064847629616106443780159680232863841946753372582", "price":"0.14", "size":"230.88", "side":"BUY", "hash":"f8c7b627ae9730a848907965c127d62402f4c9a3", "best_bid":"0.15", "best_ask":"0.16"}, {"asset_id":"20436996072316278452977393149218961565084965483366669504673105646378938504388", "price":"0.86", "size":"230.88", "side":"SELL", "hash":"815ea681c74c72852eadfca60bdde56ede160820", "best_bid":"0.84", "best_ask":"0.85"}], "timestamp":"1778784201140", "event_type":"price_change"}
{"market":"0x2a903c589141bce4a1e50fb98b73397af6820942542793ab10b1df477e912b6e", "price_changes":[{"asset_id":"68919878716222388542639225642064847629616106443780159680232863841946753372582", "price":"0.12", "size":"454.41", "side":"BUY", "hash":"2f37a26c9caa5fc5542f82a72349656b08362016", "best_bid":"0.15", "best_ask":"0.16"}, {"asset_id":"20436996072316278452977393149218961565084965483366669504673105646378938504388", "price":"0.88", "size":"454.41", "side":"SELL", "hash":"72b2ec7cebc9439521fad0d67f4cd93aee7808e8", "best_bid":"0.84", "best_ask":"0.85"}], "timestamp":"1778784201140", "event_type":"price_change"}
{"market":"0x2a903c589141bce4a1e50fb98b73397af6820942542793ab10b1df477e912b6e", "price_changes":[{"asset_id":"20436996072316278452977393149218961565084965483366669504673105646378938504388", "price":"0.01", "size":"11995.61", "side":"BUY", "hash":"869b76994fb39dc3c802967dfb65bad958da7096", "best_bid":"0.84", "best_ask":"0.85"}, {"asset_id":"68919878716222388542639225642064847629616106443780159680232863841946753372582", "price":"0.99", "size":"11995.61", "side":"SELL", "hash":"e2e8c9c079a9912238a997f23f992263db1f471d", "best_bid":"0.15", "best_ask":"0.16"}], "timestamp":"1778784201141", "event_type":"price_change"}
{"market":"0x2a903c589141bce4a1e50fb98b73397af6820942542793ab10b1df477e912b6e", "price_changes":[{"asset_id":"68919878716222388542639225642064847629616106443780159680232863841946753372582", "price":"0.12", "size":"554.41", "side":"BUY", "hash":"c51132259aaa2556c52c06c42a31b7845db163cd", "best_bid":"0.15", "best_ask":"0.16"}, {"asset_id":"20436996072316278452977393149218961565084965483366669504673105646378938504388", "price":"0.88", "size":"554.41", "side":"SELL", "hash":"accea573d18788234ade8d41fb445d374a369fd3", "best_bid":"0.84", "best_ask":"0.85"}], "timestamp":"1778784201143", "event_type":"price_change"}
{"market":"0x2a903c589141bce4a1e50fb98b73397af6820942542793ab10b1df477e912b6e", "price_changes":[{"asset_id":"68919878716222388542639225642064847629616106443780159680232863841946753372582", "price":"0.15", "size":"410.24", "side":"BUY", "hash":"20c0d808b230e00113af531c8e9f6c855aef65df", "best_bid":"0.15", "best_ask":"0.16"}, {"asset_id":"20436996072316278452977393149218961565084965483366669504673105646378938504388", "price":"0.85", "size":"410.24", "side":"SELL", "hash":"d00db6ec854326fff57c023811157ecbf9199515", "best_bid":"0.84", "best_ask":"0.85"}], "timestamp":"1778784201143", "event_type":"price_change"}
{"market":"0x2a903c589141bce4a1e50fb98b73397af6820942542793ab10b1df477e912b6e", "price_changes":[{"asset_id":"68919878716222388542639225642064847629616106443780159680232863841946753372582", "price":"0.15", "size":"400.24", "side":"BUY", "hash":"99868815e428ae5459d820d35d1508952a21eb0c", "best_bid":"0.15", "best_ask":"0.16"}, {"asset_id":"20436996072316278452977393149218961565084965483366669504673105646378938504388", "price":"0.85", "size":"400.24", "side":"SELL", "hash":"7dd869362059dd03ab4fcb9978691100c8caf59d", "best_bid":"0.84", "best_ask":"0.85"}], "timestamp":"1778784201144", "event_type":"price_change"}
{"market":"0x2a903c589141bce4a1e50fb98b73397af6820942542793ab10b1df477e912b6e", "price_changes":[{"asset_id":"68919878716222388542639225642064847629616106443780159680232863841946753372582", "price":"0.12", "size":"554.41", "side":"BUY", "hash":"99868815e428ae5459d820d35d1508952a21eb0c", "best_bid":"0.15", "best_ask":"0.16"}, {"asset_id":"20436996072316278452977393149218961565084965483366669504673105646378938504388", "price":"0.88", "size":"554.41", "side":"SELL", "hash":"7dd869362059dd03ab4fcb9978691100c8caf59d", "best_bid":"0.84", "best_ask":"0.85"}], "timestamp":"1778784201144", "event_type":"price_change"}
{"market":"0x2a903c589141bce4a1e50fb98b73397af6820942542793ab10b1df477e912b6e", "price_changes":[{"asset_id":"68919878716222388542639225642064847629616106443780159680232863841946753372582", "price":"0.15", "size":"389.24", "side":"BUY", "hash":"b2d51ea7cb0c5bdff49fd6fccb19c0178085812f", "best_bid":"0.15", "best_ask":"0.16"}, {"asset_id":"20436996072316278452977393149218961565084965483366669504673105646378938504388", "price":"0.85", "size":"389.24", "side":"SELL", "hash":"6e406a51977d507110c115c1c6dcbcf4cfb594a0", "best_bid":"0.84", "best_ask":"0.85"}], "timestamp":"1778784201145", "event_type":"price_change"}
{"market":"0x2a903c589141bce4a1e50fb98b73397af6820942542793ab10b1df477e912b6e", "price_changes":[{"asset_id":"68919878716222388542639225642064847629616106443780159680232863841946753372582", "price":"0.15", "size":"401.24", "side":"BUY", "hash":"e8c8890ec2c173d853d36b9ea6453cf53e6bf35f", "best_bid":"0.15", "best_ask":"0.16"}, {"asset_id":"20436996072316278452977393149218961565084965483366669504673105646378938504388", "price":"0.85", "size":"401.24", "side":"SELL", "hash":"f1ad2d25b4597262075364691f46502095629aae", "best_bid":"0.84", "best_ask":"0.85"}], "timestamp":"1778784201146", "event_type":"price_change"}
{"market":"0x2a903c589141bce4a1e50fb98b73397af6820942542793ab10b1df477e912b6e", "price_changes":[{"asset_id":"68919878716222388542639225642064847629616106443780159680232863841946753372582", "price":"0.15", "size":"416.24", "side":"BUY", "hash":"cb8a9538165171d23743ead544020c49a9223552", "best_bid":"0.15", "best_ask":"0.16"}, {"asset_id":"20436996072316278452977393149218961565084965483366669504673105646378938504388", "price":"0.85", "size":"416.24", "side":"SELL", "hash":"bc446f0a1b085d49aed80b63690db9ff5669f38c", "best_bid":"0.84", "best_ask":"0.85"}], "timestamp":"1778784201147", "event_type":"price_change"}
{"market":"0x2a903c589141bce4a1e50fb98b73397af6820942542793ab10b1df477e912b6e", "price_changes":[{"asset_id":"20436996072316278452977393149218961565084965483366669504673105646378938504388", "price":"0.78", "size":"379.5", "side":"BUY", "hash":"d8a1cb30ef2564e8aff254c3d71178d96d7c142d", "best_bid":"0.84", "best_ask":"0.85"}, {"asset_id":"68919878716222388542639225642064847629616106443780159680232863841946753372582", "price":"0.22", "size":"379.5", "side":"SELL", "hash":"9b697387ecc38ee63dd298229abbea32344e5ed6", "best_bid":"0.15", "best_ask":"0.16"}], "timestamp":"1778784201147", "event_type":"price_change"}
{"market":"0x2a903c589141bce4a1e50fb98b73397af6820942542793ab10b1df477e912b6e", "price_changes":[{"asset_id":"20436996072316278452977393149218961565084965483366669504673105646378938504388", "price":"0.84", "size":"108.17", "side":"BUY", "hash":"80b810fbcf33d7c5f08ad225cea6ca353f413cea", "best_bid":"0.84", "best_ask":"0.85"}, {"asset_id":"68919878716222388542639225642064847629616106443780159680232863841946753372582", "price":"0.16", "size":"108.17", "side":"SELL", "hash":"bb149cca601a8fbf97890cd46e02e89c1f4d1d0f", "best_bid":"0.15", "best_ask":"0.16"}], "timestamp":"1778784201148", "event_type":"price_change"}
{"market":"0x2a903c589141bce4a1e50fb98b73397af6820942542793ab10b1df477e912b6e", "price_changes":[{"asset_id":"68919878716222388542639225642064847629616106443780159680232863841946753372582", "price":"0.11", "size":"637.52", "side":"BUY", "hash":"f42eddaa744e85ab5fcb48d9ca807090c9f6ca01", "best_bid":"0.15", "best_ask":"0.16"}, {"asset_id":"20436996072316278452977393149218961565084965483366669504673105646378938504388", "price":"0.89", "size":"637.52", "side":"SELL", "hash":"b2467070168d8e9894543fd6f83c2af4a09b638b", "best_bid":"0.84", "best_ask":"0.85"}], "timestamp":"1778784201149", "event_type":"price_change"}
{"market":"0x2a903c589141bce4a1e50fb98b73397af6820942542793ab10b1df477e912b6e", "price_changes":[{"asset_id":"68919878716222388542639225642064847629616106443780159680232863841946753372582", "price":"0.12", "size":"554.41", "side":"BUY", "hash":"1d7be747034771243fe74d22d2e4a379f4d84db8", "best_bid":"0.15", "best_ask":"0.16"}, {"asset_id":"20436996072316278452977393149218961565084965483366669504673105646378938504388", "price":"0.88", "size":"554.41", "side":"SELL", "hash":"8ba61029a3d11590df604b6848bfa2c2c037d693", "best_bid":"0.84", "best_ask":"0.85"}], "timestamp":"1778784201150", "event_type":"price_change"}
{"market":"0x2a903c589141bce4a1e50fb98b73397af6820942542793ab10b1df477e912b6e", "price_changes":[{"asset_id":"68919878716222388542639225642064847629616106443780159680232863841946753372582", "price":"0.15", "size":"347.73", "side":"BUY", "hash":"47ccb0fadab46c340969e37c834811f19330f7f6", "best_bid":"0.15", "best_ask":"0.16"}, {"asset_id":"20436996072316278452977393149218961565084965483366669504673105646378938504388", "price":"0.85", "size":"347.73", "side":"SELL", "hash":"8eb1e7ceb39cd8f3e435359e7e5f3b9f51e00622", "best_bid":"0.84", "best_ask":"0.85"}], "timestamp":"1778784201154", "event_type":"price_change"}
{"market":"0x2a903c589141bce4a1e50fb98b73397af6820942542793ab10b1df477e912b6e", "asset_id":"68919878716222388542639225642064847629616106443780159680232863841946753372582", "bids":[{"price":"0.01", "size":"11373.83"}, {"price":"0.02", "size":"1427.82"}, {"price":"0.03", "size":"1090.78"}, {"price":"0.04", "size":"1237.82"}, {"price":"0.05", "size":"775.72"}, {"price":"0.06", "size":"297.2"}, {"price":"0.07", "size":"656.69"}, {"price":"0.08", "size":"694.53"}, {"price":"0.09", "size":"333.11"}, {"price":"0.1", "size":"707"}, {"price":"0.11", "size":"637.52"}, {"price":"0.12", "size":"554.41"}, {"price":"0.13", "size":"205"}, {"price":"0.14", "size":"230.88"}, {"price":"0.15", "size":"347.73"}], "asks":[{"price":"0.99", "size":"11995.61"}, {"price":"0.98", "size":"1219.45"}, {"price":"0.97", "size":"1096.98"}, {"price":"0.96", "size":"670.05"}, {"price":"0.95", "size":"549.45"}, {"price":"0.94", "size":"346.2"}, {"price":"0.93", "size":"902.05"}, {"price":"0.92", "size":"170.79"}, {"price":"0.91", "size":"234.6"}, {"price":"0.9", "size":"128"}, {"price":"0.89", "size":"142.6"}, {"price":"0.88", "size":"141.8"}, {"price":"0.87", "size":"144.81"}, {"price":"0.86", "size":"204.9"}, {"price":"0.85", "size":"113.5"}, {"price":"0.84", "size":"102.3"}, {"price":"0.83", "size":"101.3"}, {"price":"0.82", "size":"105.3"}, {"price":"0.81", "size":"199.5"}, {"price":"0.8", "size":"103.8"}, {"price":"0.79", "size":"98.1"}, {"price":"0.78", "size":"97.5"}, {"price":"0.77", "size":"96.89"}, {"price":"0.76", "size":"201.39"}, {"price":"0.75", "size":"116"}, {"price":"0.74", "size":"100.6"}, {"price":"0.73", "size":"95.2"}, {"price":"0.72", "size":"94.9"}, {"price":"0.71", "size":"199.6"}, {"price":"0.7", "size":"94.3"}, {"price":"0.69", "size":"108.28"}, {"price":"0.68", "size":"98.8"}, {"price":"0.67", "size":"118.6"}, {"price":"0.66", "size":"398.4"}, {"price":"0.65", "size":"507.3"}, {"price":"0.64", "size":"893"}, {"price":"0.63", "size":"892.9"}, {"price":"0.62", "size":"297.7"}, {"price":"0.61", "size":"397.6"}, {"price":"0.6", "size":"356.93"}, {"price":"0.59", "size":"297.4"}, {"price":"0.58", "size":"109.6"}, {"price":"0.57", "size":"131.48"}, {"price":"0.56", "size":"413.97"}, {"price":"0.55", "size":"334.2"}, {"price":"0.54", "size":"375.6"}, {"price":"0.53", "size":"292"}, {"price":"0.52", "size":"297.12"}, {"price":"0.51", "size":"402"}, {"price":"0.5", "size":"340.91"}, {"price":"0.49", "size":"803"}, {"price":"0.48", "size":"317"}, {"price":"0.47", "size":"337"}, {"price":"0.46", "size":"451.54"}, {"price":"0.45", "size":"346.64"}, {"price":"0.44", "size":"341.45"}, {"price":"0.43", "size":"434.89"}, {"price":"0.42", "size":"724.36"}, {"price":"0.41", "size":"412.4"}, {"price":"0.4", "size":"328.83"}, {"price":"0.39", "size":"297.6"}, {"price":"0.38", "size":"318.44"}, {"price":"0.37", "size":"297.9"}, {"price":"0.36", "size":"492"}, {"price":"0.35", "size":"330.14"}, {"price":"0.34", "size":"350.9"}, {"price":"0.33", "size":"363.6"}, {"price":"0.32", "size":"2065.88"}, {"price":"0.31", "size":"559"}, {"price":"0.3", "size":"244.3"}, {"price":"0.29", "size":"626.38"}, {"price":"0.28", "size":"134.9"}, {"price":"0.27", "size":"470.2"}, {"price":"0.26", "size":"250.6"}, {"price":"0.25", "size":"496"}, {"price":"0.24", "size":"541.39"}, {"price":"0.23", "size":"246.89"}, {"price":"0.22", "size":"379.5"}, {"price":"0.21", "size":"360.44"}, {"price":"0.2", "size":"128.8"}, {"price":"0.19", "size":"72.35"}, {"price":"0.18", "size":"289.82"}, {"price":"0.17", "size":"60"}, {"price":"0.16", "size":"108.17"}], "hash":"47ccb0fadab46c340969e37c834811f19330f7f6", "timestamp":"1778784201154", "event_type":"book"}
{"market":"0x2a903c589141bce4a1e50fb98b73397af6820942542793ab10b1df477e912b6e", "price_changes":[{"asset_id":"68919878716222388542639225642064847629616106443780159680232863841946753372582", "price":"0.12", "size":"554.41", "side":"BUY", "hash":"673c291826d437e615e486c5f3fcdf4f06b86018", "best_bid":"0.15", "best_ask":"0.16"}, {"asset_id":"20436996072316278452977393149218961565084965483366669504673105646378938504388", "price":"0.88", "size":"554.41", "side":"SELL", "hash":"00b97d49d10db586e8d13d634e5c085922ab4b83", "best_bid":"0.84", "best_ask":"0.85"}], "timestamp":"1778784201156", "event_type":"price_change"}
{"market":"0x2a903c589141bce4a1e50fb98b73397af6820942542793ab10b1df477e912b6e", "price_changes":[{"asset_id":"68919878716222388542639225642064847629616106443780159680232863841946753372582", "price":"0.15", "size":"357.73", "side":"BUY", "hash":"c71d6ae4ab078a066eb8435ca5b258979dc97b87", "best_bid":"0.15", "best_ask":"0.16"}, {"asset_id":"20436996072316278452977393149218961565084965483366669504673105646378938504388", "price":"0.85", "size":"357.73", "side":"SELL", "hash":"f4ab3ff370a91e90c01b1677f53b5f1cda51efa0", "best_bid":"0.84", "best_ask":"0.85"}], "timestamp":"1778784201157", "event_type":"price_change"}
{"market":"0x2a903c589141bce4a1e50fb98b73397af6820942542793ab10b1df477e912b6e", "price_changes":[{"asset_id":"68919878716222388542639225642064847629616106443780159680232863841946753372582", "price":"0.12", "size":"554.41", "side":"BUY", "hash":"d7aef891910168325a8aef695b6b6da47f7e3ef4", "best_bid":"0.15", "best_ask":"0.16"}, {"asset_id":"20436996072316278452977393149218961565084965483366669504673105646378938504388", "price":"0.88", "size":"554.41", "side":"SELL", "hash":"cf810682ec4be159b19f1299a57f923a22b0655a", "best_bid":"0.84", "best_ask":"0.85"}], "timestamp":"1778784201158", "event_type":"price_change"}
{"market":"0x2a903c589141bce4a1e50fb98b73397af6820942542793ab10b1df477e912b6e", "price_changes":[{"asset_id":"68919878716222388542639225642064847629616106443780159680232863841946753372582", "price":"0.12", "size":"554.41", "side":"BUY", "hash":"243270f6a7d0244c2ef7665e6579bb86dd43494a", "best_bid":"0.15", "best_ask":"0.16"}, {"asset_id":"20436996072316278452977393149218961565084965483366669504673105646378938504388", "price":"0.88", "size":"554.41", "side":"SELL", "hash":"f443cfd1d43a6ee2d836b97da8d0a4bf0e7c55a0", "best_bid":"0.84", "best_ask":"0.85"}], "timestamp":"1778784201160", "event_type":"price_change"}
{"market":"0x2a903c589141bce4a1e50fb98b73397af6820942542793ab10b1df477e912b6e", "price_changes":[{"asset_id":"20436996072316278452977393149218961565084965483366669504673105646378938504388", "price":"0.78", "size":"384.5", "side":"BUY", "hash":"52c21c7853862cb763dff3331420223406521545", "best_bid":"0.84", "best_ask":"0.85"}, {"asset_id":"68919878716222388542639225642064847629616106443780159680232863841946753372582", "price":"0.22", "size":"384.5", "side":"SELL", "hash":"6aa2f446f1db36a96440b8a189c9f6fd35365917", "best_bid":"0.15", "best_ask":"0.16"}], "timestamp":"1778784201161", "event_type":"price_change"}
