{"market":"0x2a903c589141bce4a1e50fb98b73397af6820942542793ab10b1df477e912b6e", "asset_id":"68919878716222388542639225642064847629616106443780159680232863841946753372582", "bids":[{"price":"0.01", "size":"11338.83"}, {"price":"0.02", "size":"1397.82"}, {"price":"0.03", "size":"1090.78"}, {"price":"0.04", "size":"1237.82"}, {"price":"0.05", "size":"755.72"}, {"price":"0.06", "size":"297.2"}, {"price":"0.07", "size":"362.1"}, {"price":"0.08", "size":"348.74"}, {"price":"0.09", "size":"357.1"}, {"price":"0.1", "size":"570.99"}, {"price":"0.11", "size":"467.18"}, {"price":"0.12", "size":"233.41"}, {"price":"0.13", "size":"55"}, {"price":"0.14", "size":"170.88"}, {"price":"0.15", "size":"12.85"}], "asks":[{"price":"0.99", "size":"11995.61"}, {"price":"0.98", "size":"1219.45"}, {"price":"0.97", "size":"1111.98"}, {"price":"0.96", "size":"670.05"}, {"price":"0.95", "size":"549.45"}, {"price":"0.94", "size":"346.2"}, {"price":"0.93", "size":"902.05"}, {"price":"0.92", "size":"170.79"}, {"price":"0.91", "size":"234.6"}, {"price":"0.9", "size":"128"}, {"price":"0.89", "size":"142.6"}, {"price":"0.88", "size":"141.8"}, {"price":"0.87", "size":"144.81"}, {"price":"0.86", "size":"204.9"}, {"price":"0.85", "size":"113.5"}, {"price":"0.84", "size":"102.3"}, {"price":"0.83", "size":"101.3"}, {"price":"0.82", "size":"105.3"}, {"price":"0.81", "size":"199.5"}, {"price":"0.8", "size":"103.8"}, {"price":"0.79", "size":"98.1"}, {"price":"0.78", "size":"97.5"}, {"price":"0.77", "size":"96.89"}, {"price":"0.76", "size":"201.39"}, {"price":"0.75", "size":"116"}, {"price":"0.74", "size":"100.6"}, {"price":"0.73", "size":"95.2"}, {"price":"0.72", "size":"94.9"}, {"price":"0.71", "size":"199.6"}, {"price":"0.7", "size":"94.3"}, {"price":"0.69", "size":"108.28"}, {"price":"0.68", "size":"98.8"}, {"price":"0.67", "size":"118.6"}, {"price":"0.66", "size":"398.4"}, {"price":"0.65", "size":"507.3"}, {"price":"0.64", "size":"293"}, {"price":"0.63", "size":"892.9"}, {"price":"0.62", "size":"297.7"}, {"price":"0.61", "size":"397.6"}, {"price":"0.6", "size":"356.93"}, {"price":"0.59", "size":"297.4"}, {"price":"0.58", "size":"109.6"}, {"price":"0.57", "size":"131.48"}, {"price":"0.56", "size":"413.97"}, {"price":"0.55", "size":"334.2"}, {"price":"0.54", "size":"375.6"}, {"price":"0.53", "size":"292"}, {"price":"0.52", "size":"297.12"}, {"price":"0.51", "size":"402"}, {"price":"0.5", "size":"345.91"}, {"price":"0.49", "size":"312"}, {"price":"0.48", "size":"317"}, {"price":"0.47", "size":"337"}, {"price":"0.46", "size":"451.54"}, {"price":"0.45", "size":"346.64"}, {"price":"0.44", "size":"346.45"}, {"price":"0.43", "size":"434.89"}, {"price":"0.42", "size":"724.36"}, {"price":"0.41", "size":"412.4"}, {"price":"0.4", "size":"328.83"}, {"price":"0.39", "size":"297.6"}, {"price":"0.38", "size":"318.44"}, {"price":"0.37", "size":"576.9"}, {"price":"0.36", "size":"203"}, {"price":"0.35", "size":"340.14"}, {"price":"0.34", "size":"320.9"}, {"price":"0.33", "size":"323.6"}, {"price":"0.32", "size":"2065.88"}, {"price":"0.31", "size":"559"}, {"price":"0.3", "size":"134.3"}, {"price":"0.29", "size":"616.38"}, {"price":"0.28", "size":"139.9"}, {"price":"0.27", "size":"165.2"}, {"price":"0.26", "size":"230.6"}, {"price":"0.25", "size":"406"}, {"price":"0.24", "size":"206.39"}, {"price":"0.23", "size":"246.89"}, {"price":"0.22", "size":"249.5"}, {"price":"0.21", "size":"275.44"}, {"price":"0.2", "size":"110"}, {"price":"0.19", "size":"197.35"}, {"price":"0.18", "size":"364.82"}, {"price":"0.17", "size":"31"}, {"price":"0.16", "size":"18.75"}], "hash":"84d99464727b77d1cbbd7121e5973746f955a4f9", "timestamp":"1778784200684", "event_type":"book"}
{"market":"0x2a903c589141bce4a1e50fb98b73397af6820942542793ab10b1df477e912b6e", "price_changes":[{"asset_id":"68919878716222388542639225642064847629616106443780159680232863841946753372582", "price":"0.1", "size":"560.99", "side":"BUY", "hash":"3eecdc069c9816257346ee57608c218064297401", "best_bid":"0.15", "best_ask":"0.16"}, {"asset_id":"20436996072316278452977393149218961565084965483366669504673105646378938504388", "price":"0.9", "size":"560.99", "side":"SELL", "hash":"33d77733cb0fc2e11e9957e836cf24af6f2935ff", "best_bid":"0.84", "best_ask":"0.85"}], "timestamp":"1778784200686", "event_type":"price_change"}
{"market":"0x2a903c589141bce4a1e50fb98b73397af6820942542793ab10b1df477e912b6e", "price_changes":[{"asset_id":"68919878716222388542639225642064847629616106443780159680232863841946753372582", "price":"0.11", "size":"487.18", "side":"BUY", "hash":"5133d239e36b6a47c337feeae375426f5ec64603", "best_bid":"0.15", "best_ask":"0.16"}, {"asset_id":"20436996072316278452977393149218961565084965483366669504673105646378938504388", "price":"0.89", "size":"487.18", "side":"SELL", "hash":"51ff7ce26c6f368ac5f7139747bdbaa3beb6a552", "best_bid":"0.84", "best_ask":"0.85"}], "timestamp":"1778784200687", "event_type":"price_change"}
{"market":"0x2a903c589141bce4a1e50fb98b73397af6820942542793ab10b1df477e912b6e", "price_changes":[{"asset_id":"20436996072316278452977393149218961565084965483366669504673105646378938504388", "price":"0.7", "size":"144.3", "side":"BUY", "hash":"c9b0b206f36cd8791413b6cf1b7c0091e90189c6", "best_bid":"0.84", "best_ask":"0.85"}, {"asset_id":"68919878716222388542639225642064847629616106443780159680232863841946753372582", "price":"0.3", "size":"144.3", "side":"SELL", "hash":"759e586c0a19dcf0aa71f70291c3905b935afa05", "best_bid":"0.15", "best_ask":"0.16"}], "timestamp":"1778784200687", "event_type":"price_change"}
{"market":"0x2a903c589141bce4a1e50fb98b73397af6820942542793ab10b1df477e912b6e", "price_changes":[{"asset_id":"20436996072316278452977393149218961565084965483366669504673105646378938504388", "price":"0.84", "size":"38.75", "side":"BUY", "hash":"c7ffe446f713e7c9b17d36e3d49ae04c00d65eb8", "best_bid":"0.84", "best_ask":"0.85"}, {"asset_id":"68919878716222388542639225642064847629616106443780159680232863841946753372582", "price":"0.16", "size":"38.75", "side":"SELL", "hash":"95017e4a6192e3e24292d2617aec39e2612d2319", "best_bid":"0.15", "best_ask":"0.16"}], "timestamp":"1778784200689", "event_type":"price_change"}
{"market":"0x2a903c589141bce4a1e50fb98b73397af6820942542793ab10b1df477e912b6e", "price_changes":[{"asset_id":"68919878716222388542639225642064847629616106443780159680232863841946753372582", "price":"0.15", "size":"17.85", "side":"BUY", "hash":"e3fae0957cef8e0e5320cf156992d42cd5005812", "best_bid":"0.15", "best_ask":"0.16"}, {"asset_id":"20436996072316278452977393149218961565084965483366669504673105646378938504388", "price":"0.85", "size":"17.85", "side":"SELL", "hash":"b499bab3ebb4c49d5610f048f6384543b9a592f2", "best_bid":"0.84", "best_ask":"0.85"}], "timestamp":"1778784200690", "event_type":"price_change"}
{"market":"0x2a903c589141bce4a1e50fb98b73397af6820942542793ab10b1df477e912b6e", "price_changes":[{"asset_id":"68919878716222388542639225642064847629616106443780159680232863841946753372582", "price":"0.11", "size":"517.18", "side":"BUY", "hash":"d01ab9b75fed78a2324f55dcb997e147c582a2ee", "best_bid":"0.15", "best_ask":"0.16"}, {"asset_id":"20436996072316278452977393149218961565084965483366669504673105646378938504388", "price":"0.89", "size":"517.18", "side":"SELL", "hash":"534b25b9a317bdd5a91f6e4d8d8550ba684c0ad0", "best_bid":"0.84", "best_ask":"0.85"}], "timestamp":"1778784200691", "event_type":"price_change"}
{"market":"0x2a903c589141bce4a1e50fb98b73397af6820942542793ab10b1df477e912b6e", "price_changes":[{"asset_id":"20436996072316278452977393149218961565084965483366669504673105646378938504388", "price":"0.83", "size":"11", "side":"BUY", "hash":"86179b9ac0b0a3f67ce0fa698bb3f6e5299240e8", "best_bid":"0.84", "best_ask":"0.85"}, {"asset_id":"68919878716222388542639225642064847629616106443780159680232863841946753372582", "price":"0.17", "size":"11", "side":"SELL", "hash":"0da0df4c2c4c5b8d9d21372e395aaf0b1441512b", "best_bid":"0.15", "best_ask":"0.16"}], "timestamp":"1778784200692", "event_type":"price_change"}
{"market":"0x2a903c589141bce4a1e50fb98b73397af6820942542793ab10b1df477e912b6e", "price_changes":[{"asset_id":"20436996072316278452977393149218961565084965483366669504673105646378938504388", "price":"0.83", "size":"83.35", "side":"BUY", "hash":"9c9baaa9db42c064dd4701bd3dc71c6031eeee03", "best_bid":"0.84", "best_ask":"0.85"}, {"asset_id":"68919878716222388542639225642064847629616106443780159680232863841946753372582", "price":"0.17", "size":"83.35", "side":"SELL", "hash":"83f0ce529c6a529219b2ed8a8013cb803a34da23", "best_bid":"0.15", "best_ask":"0.16"}], "timestamp":"1778784200693", "event_type":"price_change"}
{"market":"0x2a903c589141bce4a1e50fb98b73397af6820942542793ab10b1df477e912b6e", "price_changes":[{"asset_id":"68919878716222388542639225642064847629616106443780159680232863841946753372582", "price":"0.11", "size":"530.18", "side":"BUY", "hash":"da05fd421d3aa004ad7855e0d1b51c744bbe9529", "best_bid":"0.15", "best_ask":"0.16"}, {"asset_id":"20436996072316278452977393149218961565084965483366669504673105646378938504388", "price":"0.89", "size":"530.18", "side":"SELL", "hash":"842b403ea1648cde12b44bad5749ba8e8cab58d4", "best_bid":"0.84", "best_ask":"0.85"}], "timestamp":"1778784200694", "event_type":"price_change"}
{"market":"0x2a903c589141bce4a1e50fb98b73397af6820942542793ab10b1df477e912b6e", "price_changes":[{"asset_id":"20436996072316278452977393149218961565084965483366669504673105646378938504388", "price":"0.35", "size":"407.3", "side":"BUY", "hash":"1b733efa6d7d289b1991fe2e34720ee24aa2ffe2", "best_bid":"0.84", "best_ask":"0.85"}, {"asset_id":"68919878716222388542639225642064847629616106443780159680232863841946753372582", "price":"0.65", "size":"407.3", "side":"SELL", "hash":"18ce5234e0bdca813e09f6e2e39d4430063acf00", "best_bid":"0.15", "best_ask":"0.16"}], "timestamp":"1778784200695", "event_type":"price_change"}
{"market":"0x2a903c589141bce4a1e50fb98b73397af6820942542793ab10b1df477e912b6e", "price_changes":[{"asset_id":"20436996072316278452977393149218961565084965483366669504673105646378938504388", "price":"0.87", "size":"95", "side":"SELL", "hash":"94d618908e8a0d532384bfad85e8a41addc45704", "best_bid":"0.84", "best_ask":"0.85"}, {"asset_id":"68919878716222388542639225642064847629616106443780159680232863841946753372582", "price":"0.13", "size":"95", "side":"BUY", "hash":"c9af356da74bd4539a584689febb5a3d0188cfc3", "best_bid":"0.15", "best_ask":"0.16"}], "timestamp":"1778784200696", "event_type":"price_change"}
{"market":"0x2a903c589141bce4a1e50fb98b73397af6820942542793ab10b1df477e912b6e", "asset_id":"68919878716222388542639225642064847629616106443780159680232863841946753372582", "price":"0.16", "size":"10", "fee_rate_bps":"0", "side":"BUY", "timestamp":"1778784200694", "event_type":"last_trade_price", "transaction_hash":"0xca3fc256a30ef2c0958bba75db503728eab52bf69bd938f4cb22aa84ea54a67b"}
{"market":"0x2a903c589141bce4a1e50fb98b73397af6820942542793ab10b1df477e912b6e", "price_changes":[{"asset_id":"68919878716222388542639225642064847629616106443780159680232863841946753372582", "price":"0.12", "size":"213.41", "side":"BUY", "hash":"56e9d2bdd4677a2f7b39a3f8af961417add31772", "best_bid":"0.15", "best_ask":"0.16"}, {"asset_id":"20436996072316278452977393149218961565084965483366669504673105646378938504388", "price":"0.88", "size":"213.41", "side":"SELL", "hash":"b17d7c42c9e6f44cae820345ce6197d6d455c4fe", "best_bid":"0.84", "best_ask":"0.85"}], "timestamp":"1778784200703", "event_type":"price_change"}
{"market":"0x2a903c589141bce4a1e50fb98b73397af6820942542793ab10b1df477e912b6e", "price_changes":[{"asset_id":"20436996072316278452977393149218961565084965483366669504673105646378938504388", "price":"0.84", "size":"18.75", "side":"BUY", "hash":"5723f593c8d8a6d58ba86d8f0e9e10652e50a21d", "best_bid":"0.84", "best_ask":"0.85"}, {"asset_id":"68919878716222388542639225642064847629616106443780159680232863841946753372582", "price":"0.16", "size":"18.75", "side":"SELL", "hash":"a47bd8b9d142a23ba0d2ff2e8627ecc05b1f18e5", "best_bid":"0.15", "best_ask":"0.16"}], "timestamp":"1778784200704", "event_type":"price_change"}
{"market":"0x2a903c589141bce4a1e50fb98b73397af6820942542793ab10b1df477e912b6e", "price_changes":[{"asset_id":"20436996072316278452977393149218961565084965483366669504673105646378938504388", "price":"0.81", "size":"97.35", "side":"BUY", "hash":"5723f593c8d8a6d58ba86d8f0e9e10652e50a21d", "best_bid":"0.84", "best_ask":"0.85"}, {"asset_id":"68919878716222388542639225642064847629616106443780159680232863841946753372582", "price":"0.19", "size":"97.35", "side":"SELL", "hash":"a47bd8b9d142a23ba0d2ff2e8627ecc05b1f18e5", "best_bid":"0.15", "best_ask":"0.16"}], "timestamp":"1778784200704", "event_type":"price_change"}
{"market":"0x2a903c589141bce4a1e50fb98b73397af6820942542793ab10b1df477e912b6e", "price_changes":[{"asset_id":"68919878716222388542639225642064847629616106443780159680232863841946753372582", "price":"0.11", "size":"542.18", "side":"BUY", "hash":"a9afbf50c7d3cfee242cd0db949252e25a6f2603", "best_bid":"0.15", "best_ask":"0.16"}, {"asset_id":"20436996072316278452977393149218961565084965483366669504673105646378938504388", "price":"0.89", "size":"542.18", "side":"SELL", "hash":"dced69de3174647dd1f2c7585f33804306f3decc", "best_bid":"0.84", "best_ask":"0.85"}], "timestamp":"1778784200706", "event_type":"price_change"}
{"market":"0x2a903c589141bce4a1e50fb98b73397af6820942542793ab10b1df477e912b6e", "price_changes":[{"asset_id":"68919878716222388542639225642064847629616106443780159680232863841946753372582", "price":"0.12", "size":"237.41", "side":"BUY", "hash":"49311cf7f829cae783eeeff754cf5acdf30d9f92", "best_bid":"0.15", "best_ask":"0.16"}, {"asset_id":"20436996072316278452977393149218961565084965483366669504673105646378938504388", "price":"0.88", "size":"237.41", "side":"SELL", "hash":"06a6dd7e5588fffbb9f7dad517ed256f4db4411e", "best_bid":"0.84", "best_ask":"0.85"}], "timestamp":"1778784200707", "event_type":"price_change"}
{"market":"0x2a903c589141bce4a1e50fb98b73397af6820942542793ab10b1df477e912b6e", "price_changes":[{"asset_id":"20436996072316278452977393149218961565084965483366669504673105646378938504388", "price":"0.69", "size":"564", "side":"BUY", "hash":"0bbd782501ffe6a2d766220e6c55eca6e7dac739", "best_bid":"0.84", "best_ask":"0.85"}, {"asset_id":"68919878716222388542639225642064847629616106443780159680232863841946753372582", "price":"0.31", "size":"564", "side":"SELL", "hash":"95e448014ac916b3e67ae498e333e42c9c156e80", "best_bid":"0.15", "best_ask":"0.16"}], "timestamp":"1778784200708", "event_type":"price_change"}
{"market":"0x2a903c589141bce4a1e50fb98b73397af6820942542793ab10b1df477e912b6e", "price_changes":[{"asset_id":"68919878716222388542639225642064847629616106443780159680232863841946753372582", "price":"0.1", "size":"576.99", "side":"BUY", "hash":"03a2672bdfb36b32bc3c3adf28650f2fb02bec54", "best_bid":"0.15", "best_ask":"0.16"}, {"asset_id":"20436996072316278452977393149218961565084965483366669504673105646378938504388", "price":"0.9", "size":"576.99", "side":"SELL", "hash":"0efadc512e4ba6187ff3ba4311243e44cee055f9", "best_bid":"0.84", "best_ask":"0.85"}], "timestamp":"1778784200709", "event_type":"price_change"}
{"market":"0x2a903c589141bce4a1e50fb98b73397af6820942542793ab10b1df477e912b6e", "price_changes":[{"asset_id":"20436996072316278452977393149218961565084965483366669504673105646378938504388", "price":"0.79", "size":"175.44", "side":"BUY", "hash":"4f651032dcee96d3db3b67fced01ea117d6fb3c2", "best_bid":"0.84", "best_ask":"0.85"}, {"asset_id":"68919878716222388542639225642064847629616106443780159680232863841946753372582", "price":"0.21", "size":"175.44", "side":"SELL", "hash":"ac801f4d6ee5ade1268971a74b25cf84dcd84aba", "best_bid":"0.15", "best_ask":"0.16"}], "timestamp":"1778784200710", "event_type":"price_change"}
{"market":"0x2a903c589141bce4a1e50fb98b73397af6820942542793ab10b1df477e912b6e", "price_changes":[{"asset_id":"20436996072316278452977393149218961565084965483366669504673105646378938504388", "price":"0.82", "size":"339.82", "side":"BUY", "hash":"9b2c2f42fe986016acd1bce5350ac823d030afec", "best_bid":"0.84", "best_ask":"0.85"}, {"asset_id":"68919878716222388542639225642064847629616106443780159680232863841946753372582", "price":"0.18", "size":"339.82", "side":"SELL", "hash":"5d081bf874b4f1ada32b7d277e322197ded5d740", "best_bid":"0.15", "best_ask":"0.16"}], "timestamp":"1778784200711", "event_type":"price_change"}
{"market":"0x2a903c589141bce4a1e50fb98b73397af6820942542793ab10b1df477e912b6e", "price_changes":[{"asset_id":"20436996072316278452977393149218961565084965483366669504673105646378938504388", "price":"0.84", "size":"32.75", "side":"BUY", "hash":"4c65001d3e01e0be36aad5f75fab4aca96299908", "best_bid":"0.84", "best_ask":"0.85"}, {"asset_id":"68919878716222388542639225642064847629616106443780159680232863841946753372582", "price":"0.16", "size":"32.75", "side":"SELL", "hash":"078821a0941da64251c908ad95759b3be17cefa9", "best_bid":"0.15", "best_ask":"0.16"}], "timestamp":"1778784200712", "event_type":"price_change"}
{"market":"0x2a903c589141bce4a1e50fb98b73397af6820942542793ab10b1df477e912b6e", "price_changes":[{"asset_id":"68919878716222388542639225642064847629616106443780159680232863841946753372582", "price":"0.11", "size":"557.18", "side":"BUY", "hash":"ef5123bf9c09f63d1a1aa7364a4fad68a90e963a", "best_bid":"0.15", "best_ask":"0.16"}, {"asset_id":"20436996072316278452977393149218961565084965483366669504673105646378938504388", "price":"0.89", "size":"557.18", "side":"SELL", "hash":"85a8f0dd1538140f4f87e2addfcb3adf683d839e", "best_bid":"0.84", "best_ask":"0.85"}], "timestamp":"1778784200713", "event_type":"price_change"}
{"market":"0x2a903c589141bce4a1e50fb98b73397af6820942542793ab10b1df477e912b6e", "price_changes":[{"asset_id":"68919878716222388542639225642064847629616106443780159680232863841946753372582", "price":"0.11", "size":"574.18", "side":"BUY", "hash":"1a2d672fdf3a972ef3ce72e4387294e96e5f70e1", "best_bid":"0.15", "best_ask":"0.16"}, {"asset_id":"20436996072316278452977393149218961565084965483366669504673105646378938504388", "price":"0.89", "size":"574.18", "side":"SELL", "hash":"1e6d112642f2395753c8d0f9f575c020aec9dcea", "best_bid":"0.84", "best_ask":"0.85"}], "timestamp":"1778784200714", "event_type":"price_change"}
{"market":"0x2a903c589141bce4a1e50fb98b73397af6820942542793ab10b1df477e912b6e", "price_changes":[{"asset_id":"20436996072316278452977393149218961565084965483366669504673105646378938504388", "price":"0.75", "size":"396", "side":"BUY", "hash":"2268922126fe0cef2e1f746baa7332c24936a8c2", "best_bid":"0.84", "best_ask":"0.85"}, {"asset_id":"68919878716222388542639225642064847629616106443780159680232863841946753372582", "price":"0.25", "size":"396", "side":"SELL", "hash":"19459d312151fa3340a3f31c0e8f46476643b2bd", "best_bid":"0.15", "best_ask":"0.16"}], "timestamp":"1778784200714", "event_type":"price_change"}
{"market":"0x2a903c589141bce4a1e50fb98b73397af6820942542793ab10b1df477e912b6e", "price_changes":[{"asset_id":"20436996072316278452977393149218961565084965483366669504673105646378938504388", "price":"0.82", "size":"319.82", "side":"BUY", "hash":"7b0462a506933eb036598b03dbd1915ad6793795", "best_bid":"0.84", "best_ask":"0.85"}, {"asset_id":"68919878716222388542639225642064847629616106443780159680232863841946753372582", "price":"0.18", "size":"319.82", "side":"SELL", "hash":"5b81e2c8dfa0c4361614b4ce834f7a098dd7d1f3", "best_bid":"0.15", "best_ask":"0.16"}], "timestamp":"1778784200715", "event_type":"price_change"}
{"market":"0x2a903c589141bce4a1e50fb98b73397af6820942542793ab10b1df477e912b6e", "price_changes":[{"asset_id":"68919878716222388542639225642064847629616106443780159680232863841946753372582", "price":"0.11", "size":"591.18", "side":"BUY", "hash":"ea44dc91fb813a99b96113a65d25b3ab072c34e0", "best_bid":"0.15", "best_ask":"0.16"}, {"asset_id":"20436996072316278452977393149218961565084965483366669504673105646378938504388", "price":"0.89", "size":"591.18", "side":"SELL", "hash":"069300ab1476bd73812f173f36d129cdafcc3f3d", "best_bid":"0.84", "best_ask":"0.85"}], "timestamp":"1778784200717", "event_type":"price_change"}
{"market":"0x2a903c589141bce4a1e50fb98b73397af6820942542793ab10b1df477e912b6e", "price_changes":[{"asset_id":"68919878716222388542639225642064847629616106443780159680232863841946753372582", "price":"0.11", "size":"586.18", "side":"BUY", "hash":"ca98cbf4b0ff99b16fd973ef379ed0abe9845ff5", "best_bid":"0.15", "best_ask":"0.16"}, {"asset_id":"20436996072316278452977393149218961565084965483366669504673105646378938504388", "price":"0.89", "size":"586.18", "side":"SELL", "hash":"c87a92d5cf114a59e670e9a17f08667792ae51d9", "best_bid":"0.84", "best_ask":"0.85"}], "timestamp":"1778784200717", "event_type":"price_change"}
{"market":"0x2a903c589141bce4a1e50fb98b73397af6820942542793ab10b1df477e912b6e", "price_changes":[{"asset_id":"68919878716222388542639225642064847629616106443780159680232863841946753372582", "price":"0.07", "size":"352.1", "side":"BUY", "hash":"74f63d56de72ae70ae356390ea60a92ac77895df", "best_bid":"0.15", "best_ask":"0.16"}, {"asset_id":"20436996072316278452977393149218961565084965483366669504673105646378938504388", "price":"0.93", "size":"352.1", "side":"SELL", "hash":"de0096a2fae9fccc579485422b1b375400d070c6", "best_bid":"0.84", "best_ask":"0.85"}], "timestamp":"1778784200718", "event_type":"price_change"}
{"market":"0x2a903c589141bce4a1e50fb98b73397af6820942542793ab10b1df477e912b6e", "price_changes":[{"asset_id":"68919878716222388542639225642064847629616106443780159680232863841946753372582", "price":"0.11", "size":"566.18", "side":"BUY", "hash":"4c449c24166b270310347eeebfb707bb0b394b71", "best_bid":"0.15", "best_ask":"0.16"}, {"asset_id":"20436996072316278452977393149218961565084965483366669504673105646378938504388", "price":"0.89", "size":"566.18", "side":"SELL", "hash":"b3f91822d0788000f3985ad9b1db9781ab8f74cb", "best_bid":"0.84", "best_ask":"0.85"}], "timestamp":"1778784200719", "event_type":"price_change"}
{"market":"0x2a903c589141bce4a1e50fb98b73397af6820942542793ab10b1df477e912b6e", "price_changes":[{"asset_id":"68919878716222388542639225642064847629616106443780159680232863841946753372582", "price":"0.15", "size":"10.75", "side":"BUY", "hash":"653588e9ca63e20ecda1593f86f2d43e236e6eb7", "best_bid":"0.15", "best_ask":"0.16"}, {"asset_id":"20436996072316278452977393149218961565084965483366669504673105646378938504388", "price":"0.85", "size":"10.75", "side":"SELL", "hash":"693e0f73d48314a74d8e9e796917f3e505023ede", "best_bid":"0.84", "best_ask":"0.85"}], "timestamp":"1778784200721", "event_type":"price_change"}
{"market":"0x2a903c589141bce4a1e50fb98b73397af6820942542793ab10b1df477e912b6e", "asset_id":"68919878716222388542639225642064847629616106443780159680232863841946753372582", "bids":[{"price":"0.01", "size":"11338.83"}, {"price":"0.02", "size":"1397.82"}, {"price":"0.03", "size":"1090.78"}, {"price":"0.04", "size":"1237.82"}, {"price":"0.05", "size":"755.72"}, {"price":"0.06", "size":"297.2"}, {"price":"0.07", "size":"352.1"}, {"price":"0.08", "size":"348.74"}, {"price":"0.09", "size":"357.1"}, {"price":"0.1", "size":"576.99"}, {"price":"0.11", "size":"566.18"}, {"price":"0.12", "size":"237.41"}, {"price":"0.13", "size":"95"}, {"price":"0.14", "size":"170.88"}, {"price":"0.15", "size":"10.75"}], "asks":[{"price":"0.99", "size":"11995.61"}, {"price":"0.98", "size":"1219.45"}, {"price":"0.97", "size":"1111.98"}, {"price":"0.96", "size":"670.05"}, {"price":"0.95", "size":"549.45"}, {"price":"0.94", "size":"346.2"}, {"price":"0.93", "size":"902.05"}, {"price":"0.92", "size":"170.79"}, {"price":"0.91", "size":"234.6"}, {"price":"0.9", "size":"128"}, {"price":"0.89", "size":"142.6"}, {"price":"0.88", "size":"141.8"}, {"price":"0.87", "size":"144.81"}, {"price":"0.86", "size":"204.9"}, {"price":"0.85", "size":"113.5"}, {"price":"0.84", "size":"102.3"}, {"price":"0.83", "size":"101.3"}, {"price":"0.82", "size":"105.3"}, {"price":"0.81", "size":"199.5"}, {"price":"0.8", "size":"103.8"}, {"price":"0.79", "size":"98.1"}, {"price":"0.78", "size":"97.5"}, {"price":"0.77", "size":"96.89"}, {"price":"0.76", "size":"201.39"}, {"price":"0.75", "size":"116"}, {"price":"0.74", "size":"100.6"}, {"price":"0.73", "size":"95.2"}, {"price":"0.72", "size":"94.9"}, {"price":"0.71", "size":"199.6"}, {"price":"0.7", "size":"94.3"}, {"price":"0.69", "size":"108.28"}, {"price":"0.68", "size":"98.8"}, {"price":"0.67", "size":"118.6"}, {"price":"0.66", "size":"398.4"}, {"price":"0.65", "size":"407.3"}, {"price":"0.64", "size":"293"}, {"price":"0.63", "size":"892.9"}, {"price":"0.62", "size":"297.7"}, {"price":"0.61", "size":"397.6"}, {"price":"0.6", "size":"356.93"}, {"price":"0.59", "size":"297.4"}, {"price":"0.58", "size":"109.6"}, {"price":"0.57", "size":"131.48"}, {"price":"0.56", "size":"413.97"}, {"price":"0.55", "size":"334.2"}, {"price":"0.54", "size":"375.6"}, {"price":"0.53", "size":"292"}, {"price":"0.52", "size":"297.12"}, {"price":"0.51", "size":"402"}, {"price":"0.5", "size":"345.91"}, {"price":"0.49", "size":"312"}, {"price":"0.48", "size":"317"}, {"price":"0.47", "size":"337"}, {"price":"0.46", "size":"451.54"}, {"price":"0.45", "size":"346.64"}, {"price":"0.44", "size":"346.45"}, {"price":"0.43", "size":"434.89"}, {"price":"0.42", "size":"724.36"}, {"price":"0.41", "size":"412.4"}, {"price":"0.4", "size":"328.83"}, {"price":"0.39", "size":"297.6"}, {"price":"0.38", "size":"318.44"}, {"price":"0.37", "size":"576.9"}, {"price":"0.36", "size":"203"}, {"price":"0.35", "size":"340.14"}, {"price":"0.34", "size":"320.9"}, {"price":"0.33", "size":"323.6"}, {"price":"0.32", "size":"2065.88"}, {"price":"0.31", "size":"564"}, {"price":"0.3", "size":"144.3"}, {"price":"0.29", "size":"616.38"}, {"price":"0.28", "size":"139.9"}, {"price":"0.27", "size":"165.2"}, {"price":"0.26", "size":"230.6"}, {"price":"0.25", "size":"396"}, {"price":"0.24", "size":"206.39"}, {"price":"0.23", "size":"246.89"}, {"price":"0.22", "size":"249.5"}, {"price":"0.21", "size":"175.44"}, {"price":"0.2", "size":"110"}, {"price":"0.19", "size":"97.35"}, {"price":"0.18", "size":"319.82"}, {"price":"0.17", "size":"83.35"}, {"price":"0.16", "size":"32.75"}], "hash":"653588e9ca63e20ecda1593f86f2d43e236e6eb7", "timestamp":"1778784200721", "event_type":"book"}
{"market":"0x2a903c589141bce4a1e50fb98b73397af6820942542793ab10b1df477e912b6e", "price_changes":[{"asset_id":"20436996072316278452977393149218961565084965483366669504673105646378938504388", "price":"0.36", "size":"893", "side":"BUY", "hash":"464cb349e21410108260d20140721d6833d94e73", "best_bid":"0.84", "best_ask":"0.85"}, {"asset_id":"68919878716222388542639225642064847629616106443780159680232863841946753372582", "price":"0.64", "size":"893", "side":"SELL", "hash":"c85c4729d2405728e65b5f8f1bb1d4e9961bdcd8", "best_bid":"0.15", "best_ask":"0.16"}], "timestamp":"1778784200723", "event_type":"price_change"}
{"market":"0x2a903c589141bce4a1e50fb98b73397af6820942542793ab10b1df477e912b6e", "price_changes":[{"asset_id":"68919878716222388542639225642064847629616106443780159680232863841946753372582", "price":"0.14", "size":"210.88", "side":"BUY", "hash":"0575710192b165edc324c167fef32d8e6d6dfbf2", "best_bid":"0.15", "best_ask":"0.16"}, {"asset_id":"20436996072316278452977393149218961565084965483366669504673105646378938504388", "price":"0.86", "size":"210.88", "side":"SELL", "hash":"85a5dc8300ad0f859319fa408fe35193c7813261", "best_bid":"0.84", "best_ask":"0.85"}], "timestamp":"1778784200725", "event_type":"price_change"}
{"market":"0x2a903c589141bce4a1e50fb98b73397af6820942542793ab10b1df477e912b6e", "price_changes":[{"asset_id":"68919878716222388542639225642064847629616106443780159680232863841946753372582", "price":"0.11", "size":"582.18", "side":"BUY", "hash":"8cfff2d34a316dbcf6244b6f92c7ee0f6db5c86f", "best_bid":"0.15", "best_ask":"0.16"}, {"asset_id":"20436996072316278452977393149218961565084965483366669504673105646378938504388", "price":"0.89", "size":"582.18", "side":"SELL", "hash":"c9cb2d6856af778be5acc165721c77f6fa3e5a55", "best_bid":"0.84", "best_ask":"0.85"}], "timestamp":"1778784200726", "event_type":"price_change"}
{"market":"0x2a903c589141bce4a1e50fb98b73397af6820942542793ab10b1df477e912b6e", "price_changes":[{"asset_id":"20436996072316278452977393149218961565084965483366669504673105646378938504388", "price":"0.35", "size":"507.3", "side":"BUY", "hash":"eaee7ddb7784ab16052e0987688ff48331afa5b1", "best_bid":"0.84", "best_ask":"0.85"}, {"asset_id":"68919878716222388542639225642064847629616106443780159680232863841946753372582", "price":"0.65", "size":"507.3", "side":"SELL", "hash":"c6e7ffb2a6c7918ee6ae15c59fbf7087ad40013d", "best_bid":"0.15", "best_ask":"0.16"}], "timestamp":"1778784200726", "event_type":"price_change"}
{"market":"0x2a903c589141bce4a1e50fb98b73397af6820942542793ab10b1df477e912b6e", "price_changes":[{"asset_id":"20436996072316278452977393149218961565084965483366669504673105646378938504388", "price":"0.84", "size":"28", "side":"BUY", "hash":"05e93fe96d17b09b4d51c94913e98437d8d3d96f", "best_bid":"0.84", "best_ask":"0.85"}, {"asset_id":"68919878716222388542639225642064847629616106443780159680232863841946753372582", "price":"0.16", "size":"28", "side":"SELL", "hash":"01a6b9ec6d8be0488c56ec9c010ff325543a58b2", "best_bid":"0.15", "best_ask":"0.16"}], "timestamp":"1778784200727", "event_type":"price_change"}
{"market":"0x2a903c589141bce4a1e50fb98b73397af6820942542793ab10b1df477e912b6e", "price_changes":[{"asset_id":"20436996072316278452977393149218961565084965483366669504673105646378938504388", "price":"0.8", "size":"128.8", "side":"BUY", "hash":"fa9df30ef63165a610e88e0abaea45658590505d", "best_bid":"0.84", "best_ask":"0.85"}, {"asset_id":"68919878716222388542639225642064847629616106443780159680232863841946753372582", "price":"0.2", "size":"128.8", "side":"SELL", "hash":"642d0445556d0d0b452b92f255d256fcdbaf86f2", "best_bid":"0.15", "best_ask":"0.16"}], "timestamp":"1778784200729", "event_type":"price_change"}
{"market":"0x2a903c589141bce4a1e50fb98b73397af6820942542793ab10b1df477e912b6e", "price_changes":[{"asset_id":"68919878716222388542639225642064847629616106443780159680232863841946753372582", "price":"0.11", "size":"577.18", "side":"BUY", "hash":"807b17d2cb28b1fecaae333a514cefa7b67de972", "best_bid":"0.15", "best_ask":"0.16"}, {"asset_id":"20436996072316278452977393149218961565084965483366669504673105646378938504388", "price":"0.89", "size":"577.18", "side":"SELL", "hash":"018a01fb1b998ba77d77438413ea7144dc24a582", "best_bid":"0.84", "best_ask":"0.85"}], "timestamp":"1778784200730", "event_type":"price_change"}
{"market":"0x2a903c589141bce4a1e50fb98b73397af6820942542793ab10b1df477e912b6e", "price_changes":[{"asset_id":"68919878716222388542639225642064847629616106443780159680232863841946753372582", "price":"0.11", "size":"572.18", "side":"BUY", "hash":"b4b71e8ef83f03b369a4a5db084fd638a756a131", "best_bid":"0.15", "best_ask":"0.16"}, {"asset_id":"20436996072316278452977393149218961565084965483366669504673105646378938504388", "price":"0.89", "size":"572.18", "side":"SELL", "hash":"089fd2065584ff62bca44d6105abd221888c96e3", "best_bid":"0.84", "best_ask":"0.85"}], "timestamp":"1778784200731", "event_type":"price_change"}
{"market":"0x2a903c589141bce4a1e50fb98b73397af6820942542793ab10b1df477e912b6e", "price_changes":[{"asset_id":"20436996072316278452977393149218961565084965483366669504673105646378938504388", "price":"0.84", "size":"14", "side":"BUY", "hash":"2c3870766b8e64e8e95395226088b505fc9ca18f", "best_bid":"0.84", "best_ask":"0.85"}, {"asset_id":"68919878716222388542639225642064847629616106443780159680232863841946753372582", "price":"0.16", "size":"14", "side":"SELL", "hash":"00922318e5637f5088dbbdf36a7158e20c6ed6dd", "best_bid":"0.15", "best_ask":"0.16"}], "timestamp":"1778784200731", "event_type":"price_change"}
{"market":"0x2a903c589141bce4a1e50fb98b73397af6820942542793ab10b1df477e912b6e", "price_changes":[{"asset_id":"68919878716222388542639225642064847629616106443780159680232863841946753372582", "price":"0.15", "size":"35.75", "side":"BUY", "hash":"1b98a741a0bdc1250c0dce02eba1ffd150d78027", "best_bid":"0.15", "best_ask":"0.16"}, {"asset_id":"20436996072316278452977393149218961565084965483366669504673105646378938504388", "price":"0.85", "size":"35.75", "side":"SELL", "hash":"c8e0cf660070dcbd0649d0cdbf8e4fb3d9f4e408", "best_bid":"0.84", "best_ask":"0.85"}], "timestamp":"1778784200733", "event_type":"price_change"}
{"market":"0x2a903c589141bce4a1e50fb98b73397af6820942542793ab10b1df477e912b6e", "price_changes":[{"asset_id":"20436996072316278452977393149218961565084965483366669504673105646378938504388", "price":"0.89", "size":"532.18", "side":"SELL", "hash":"e275abf6da006151c92a3832cae7edad27b1cabe", "best_bid":"0.84", "best_ask":"0.85"}, {"asset_id":"68919878716222388542639225642064847629616106443780159680232863841946753372582", "price":"0.11", "size":"532.18", "side":"BUY", "hash":"3ee400cae159cebd28dfa4f15d139c4c404e34be", "best_bid":"0.15", "best_ask":"0.16"}], "timestamp":"1778784200733", "event_type":"price_change"}
{"market":"0x2a903c589141bce4a1e50fb98b73397af6820942542793ab10b1df477e912b6e", "price_changes":[{"asset_id":"68919878716222388542639225642064847629616106443780159680232863841946753372582", "price":"0.11", "size":"517.18", "side":"BUY", "hash":"7ec323bca086bd243ac925086b0956a648fbdb5a", "best_bid":"0.15", "best_ask":"0.16"}, {"asset_id":"20436996072316278452977393149218961565084965483366669504673105646378938504388", "price":"0.89", "size":"517.18", "side":"SELL", "hash":"639e62a6db345157556c6b081bc1ffe86e7e4e0a", "best_bid":"0.84", "best_ask":"0.85"}], "timestamp":"1778784200734", "event_type":"price_change"}
{"market":"0x2a903c589141bce4a1e50fb98b73397af6820942542793ab10b1df477e912b6e", "price_changes":[{"asset_id":"68919878716222388542639225642064847629616106443780159680232863841946753372582", "price":"0.11", "size":"512.18", "side":"BUY", "hash":"8d74194f36e3bf01ca0cf50c20a5e5305fe61b85", "best_bid":"0.15", "best_ask":"0.16"}, {"asset_id":"20436996072316278452977393149218961565084965483366669504673105646378938504388", "price":"0.89", "size":"512.18", "side":"SELL", "hash":"6e0fae979e9136707ec8c0d6af002f7740768bc7", "best_bid":"0.84", "best_ask":"0.85"}], "timestamp":"1778784200734", "event_type":"price_change"}
{"market":"0x2a903c589141bce4a1e50fb98b73397af6820942542793ab10b1df477e912b6e", "price_changes":[{"asset_id":"20436996072316278452977393149218961565084965483366669504673105646378938504388", "price":"0.82", "size":"335.82", "side":"BUY", "hash":"d28c7997f6dc5bc39c35e1e74d8e0cbeefdc9a80", "best_bid":"0.84", "best_ask":"0.85"}, {"asset_id":"68919878716222388542639225642064847629616106443780159680232863841946753372582", "price":"0.18", "size":"335.82", "side":"SELL", "hash":"13f7efa71c2564fe6385ffc66cfa5cd6682ee3cb", "best_bid":"0.15", "best_ask":"0.16"}], "timestamp":"1778784200735", "event_type":"price_change"}
{"market":"0x2a903c589141bce4a1e50fb98b73397af6820942542793ab10b1df477e912b6e", "price_changes":[{"asset_id":"68919878716222388542639225642064847629616106443780159680232863841946753372582", "price":"0.05", "size":"775.72", "side":"BUY", "hash":"008a534de8c0af8a9a6dfce846d25e68788904ba", "best_bid":"0.15", "best_ask":"0.16"}, {"asset_id":"20436996072316278452977393149218961565084965483366669504673105646378938504388", "price":"0.95", "size":"775.72", "side":"SELL", "hash":"59bd6be5d7f504d70013896a7fef69156b46b429", "best_bid":"0.84", "best_ask":"0.85"}], "timestamp":"1778784200737", "event_type":"price_change"}
{"market":"0x2a903c589141bce4a1e50fb98b73397af6820942542793ab10b1df477e912b6e", "price_changes":[{"asset_id":"20436996072316278452977393149218961565084965483366669504673105646378938504388", "price":"0.84", "size":"4.5", "side":"BUY", "hash":"24910c405cbdad033b9151b86ecb5e2ee474c193", "best_bid":"0.84", "best_ask":"0.85"}, {"asset_id":"68919878716222388542639225642064847629616106443780159680232863841946753372582", "price":"0.16", "size":"4.5", "side":"SELL", "hash":"8573dd0d1d4c4c5a4d77571ce00d88f0b239cfc6", "best_bid":"0.15", "best_ask":"0.16"}], "timestamp":"1778784200742", "event_type":"price_change"}
{"market":"0x2a903c589141bce4a1e50fb98b73397af6820942542793ab10b1df477e912b6e", "asset_id":"68919878716222388542639225642064847629616106443780159680232863841946753372582", "bids":[{"price":"0.01", "size":"11338.83"}, {"price":"0.02", "size":"1397.82"}, {"price":"0.03", "size":"1090.78"}, {"price":"0.04", "size":"1237.82"}, {"price":"0.05", "size":"775.72"}, {"price":"0.06", "size":"297.2"}, {"price":"0.07", "size":"352.1"}, {"price":"0.08", "size":"348.74"}, {"price":"0.09", "size":"357.1"}, {"price":"0.1", "size":"576.99"}, {"price":"0.11", "size":"512.18"}, {"price":"0.12", "size":"237.41"}, {"price":"0.13", "size":"95"}, {"price":"0.14", "size":"210.88"}, {"price":"0.15", "size":"35.75"}], "asks":[{"price":"0.99", "size":"11995.61"}, {"price":"0.98", "size":"1219.45"}, {"price":"0.97", "size":"1111.98"}, {"price":"0.96", "size":"670.05"}, {"price":"0.95", "size":"549.45"}, {"price":"0.94", "size":"346.2"}, {"price":"0.93", "size":"902.05"}, {"price":"0.92", "size":"170.79"}, {"price":"0.91", "size":"234.6"}, {"price":"0.9", "size":"128"}, {"price":"0.89", "size":"142.6"}, {"price":"0.88", "size":"141.8"}, {"price":"0.87", "size":"144.81"}, {"price":"0.86", "size":"204.9"}, {"price":"0.85", "size":"113.5"}, {"price":"0.84", "size":"102.3"}, {"price":"0.83", "size":"101.3"}, {"price":"0.82", "size":"105.3"}, {"price":"0.81", "size":"199.5"}, {"price":"0.8", "size":"103.8"}, {"price":"0.79", "size":"98.1"}, {"price":"0.78", "size":"97.5"}, {"price":"0.77", "size":"96.89"}, {"price":"0.76", "size":"201.39"}, {"price":"0.75", "size":"116"}, {"price":"0.74", "size":"100.6"}, {"price":"0.73", "size":"95.2"}, {"price":"0.72", "size":"94.9"}, {"price":"0.71", "size":"199.6"}, {"price":"0.7", "size":"94.3"}, {"price":"0.69", "size":"108.28"}, {"price":"0.68", "size":"98.8"}, {"price":"0.67", "size":"118.6"}, {"price":"0.66", "size":"398.4"}, {"price":"0.65", "size":"507.3"}, {"price":"0.64", "size":"893"}, {"price":"0.63", "size":"892.9"}, {"price":"0.62", "size":"297.7"}, {"price":"0.61", "size":"397.6"}, {"price":"0.6", "size":"356.93"}, {"price":"0.59", "size":"297.4"}, {"price":"0.58", "size":"109.6"}, {"price":"0.57", "size":"131.48"}, {"price":"0.56", "size":"413.97"}, {"price":"0.55", "size":"334.2"}, {"price":"0.54", "size":"375.6"}, {"price":"0.53", "size":"292"}, {"price":"0.52", "size":"297.12"}, {"price":"0.51", "size":"402"}, {"price":"0.5", "size":"345.91"}, {"price":"0.49", "size":"312"}, {"price":"0.48", "size":"317"}, {"price":"0.47", "size":"337"}, {"price":"0.46", "size":"451.54"}, {"price":"0.45", "size":"346.64"}, {"price":"0.44", "size":"346.45"}, {"price":"0.43", "size":"434.89"}, {"price":"0.42", "size":"724.36"}, {"price":"0.41", "size":"412.4"}, {"price":"0.4", "size":"328.83"}, {"price":"0.39", "size":"297.6"}, {"price":"0.38", "size":"318.44"}, {"price":"0.37", "size":"576.9"}, {"price":"0.36", "size":"203"}, {"price":"0.35", "size":"340.14"}, {"price":"0.34", "size":"320.9"}, {"price":"0.33", "size":"323.6"}, {"price":"0.32", "size":"2065.88"}, {"price":"0.31", "size":"564"}, {"price":"0.3", "size":"144.3"}, {"price":"0.29", "size":"616.38"}, {"price":"0.28", "size":"139.9"}, {"price":"0.27", "size":"165.2"}, {"price":"0.26", "size":"230.6"}, {"price":"0.25", "size":"396"}, {"price":"0.24", "size":"206.39"}, {"price":"0.23", "size":"246.89"}, {"price":"0.22", "size":"249.5"}, {"price":"0.21", "size":"175.44"}, {"price":"0.2", "size":"128.8"}, {"price":"0.19", "size":"97.35"}, {"price":"0.18", "size":"335.82"}, {"price":"0.17", "size":"83.35"}, {"price":"0.16", "size":"4.5"}], "hash":"8573dd0d1d4c4c5a4d77571ce00d88f0b239cfc6", "timestamp":"1778784200742", "event_type":"book"}
{"market":"0x2a903c589141bce4a1e50fb98b73397af6820942542793ab10b1df477e912b6e", "price_changes":[{"asset_id":"68919878716222388542639225642064847629616106443780159680232863841946753372582", "price":"0.11", "size":"507.18", "side":"BUY", "hash":"668080d282a8195132bc1ecaada3f936c826905c", "best_bid":"0.15", "best_ask":"0.16"}, {"asset_id":"20436996072316278452977393149218961565084965483366669504673105646378938504388", "price":"0.89", "size":"507.18", "side":"SELL", "hash":"5a0e9fd0b30c82bb0a732b6a2b593bd72886cdde", "best_bid":"0.84", "best_ask":"0.85"}], "timestamp":"1778784200745", "event_type":"price_change"}
{"market":"0x2a903c589141bce4a1e50fb98b73397af6820942542793ab10b1df477e912b6e", "price_changes":[{"asset_id":"68919878716222388542639225642064847629616106443780159680232863841946753372582", "price":"0.11", "size":"489.18", "side":"BUY", "hash":"6d83bef6a7ec0a144da4bfbce1dce1435f53d309", "best_bid":"0.15", "best_ask":"0.16"}, {"asset_id":"20436996072316278452977393149218961565084965483366669504673105646378938504388", "price":"0.89", "size":"489.18", "side":"SELL", "hash":"4c0b75c8852130240fd8841cdcce61d1bdd04527", "best_bid":"0.84", "best_ask":"0.85"}], "timestamp":"1778784200745", "event_type":"price_change"}
{"market":"0x2a903c589141bce4a1e50fb98b73397af6820942542793ab10b1df477e912b6e", "price_changes":[{"asset_id":"20436996072316278452977393149218961565084965483366669504673105646378938504388", "price":"0.81", "size":"102.35", "side":"BUY", "hash":"81340982b6a8cc16a1fde84a389a516e49296498", "best_bid":"0.84", "best_ask":"0.85"}, {"asset_id":"68919878716222388542639225642064847629616106443780159680232863841946753372582", "price":"0.19", "size":"102.35", "side":"SELL", "hash":"593818ffaae291c17e6e06535251edac49af2c4e", "best_bid":"0.15", "best_ask":"0.16"}], "timestamp":"1778784200746", "event_type":"price_change"}
{"market":"0x2a903c589141bce4a1e50fb98b73397af6820942542793ab10b1df477e912b6e", "price_changes":[{"asset_id":"68919878716222388542639225642064847629616106443780159680232863841946753372582", "price":"0.11", "size":"502.18", "side":"BUY", "hash":"901ec7f418b3c04d2be10d368dee20ea0d6b67c1", "best_bid":"0.15", "best_ask":"0.16"}, {"asset_id":"20436996072316278452977393149218961565084965483366669504673105646378938504388", "price":"0.89", "size":"502.18", "side":"SELL", "hash":"abddd1210af1bcb2243fb72839e0b1fe97afec4b", "best_bid":"0.84", "best_ask":"0.85"}], "timestamp":"1778784200747", "event_type":"price_change"}
{"market":"0x2a903c589141bce4a1e50fb98b73397af6820942542793ab10b1df477e912b6e", "asset_id":"68919878716222388542639225642064847629616106443780159680232863841946753372582", "price":"0.15", "size":"7.1", "fee_rate_bps":"0", "side":"SELL", "timestamp":"1778784200747", "event_type":"last_trade_price", "transaction_hash":"0x91b107ea6c957e1a239c13940426b42a0e884dd4f6c2b47556565a21a850a272"}
{"market":"0x2a903c589141bce4a1e50fb98b73397af6820942542793ab10b1df477e912b6e", "price_changes":[{"asset_id":"20436996072316278452977393149218961565084965483366669504673105646378938504388", "price":"0.75", "size":"496", "side":"BUY", "hash":"8138e63067d598418c09c1b6f2d5dd1f0bea93e9", "best_bid":"0.84", "best_ask":"0.85"}, {"asset_id":"68919878716222388542639225642064847629616106443780159680232863841946753372582", "price":"0.25", "size":"496", "side":"SELL", "hash":"99c4e82914fa4b7a91bf8930a203f1ab53e16bd6", "best_bid":"0.15", "best_ask":"0.16"}], "timestamp":"1778784200748", "event_type":"price_change"}
{"market":"0x2a903c589141bce4a1e50fb98b73397af6820942542793ab10b1df477e912b6e", "price_changes":[{"asset_id":"20436996072316278452977393149218961565084965483366669504673105646378938504388", "price":"0.01", "size":"11990.61", "side":"BUY", "hash":"db43dce9705d71ab551f098203bcd780bba63bf1", "best_bid":"0.84", "best_ask":"0.85"}, {"asset_id":"68919878716222388542639225642064847629616106443780159680232863841946753372582", "price":"0.99", "size":"11990.61", "side":"SELL", "hash":"d27d5271c56b122e05d410a663b8440cc948d5ad", "best_bid":"0.15", "best_ask":"0.16"}], "timestamp":"1778784200749", "event_type":"price_change"}
{"market":"0x2a903c589141bce4a1e50fb98b73397af6820942542793ab10b1df477e912b6e", "price_changes":[{"asset_id":"20436996072316278452977393149218961565084965483366669504673105646378938504388", "price":"0.01", "size":"11995.61", "side":"BUY", "hash":"abfa2345d3f6cfde9bb5e34040601b81506193eb", "best_bid":"0.84", "best_ask":"0.85"}, {"asset_id":"68919878716222388542639225642064847629616106443780159680232863841946753372582", "price":"0.99", "size":"11995.61", "side":"SELL", "hash":"153cb27e2712dcd552dd5674e1a7e9288e065f6d", "best_bid":"0.15", "best_ask":"0.16"}], "timestamp":"1778784200751", "event_type":"price_change"}
{"market":"0x2a903c589141bce4a1e50fb98b73397af6820942542793ab10b1df477e912b6e", "price_changes":[{"asset_id":"68919878716222388542639225642064847629616106443780159680232863841946753372582", "price":"0.12", "size":"246.23", "side":"BUY", "hash":"0a45fa9b228914c0a54dfaaa958959e61638c523", "best_bid":"0.15", "best_ask":"0.16"}, {"asset_id":"20436996072316278452977393149218961565084965483366669504673105646378938504388", "price":"0.88", "size":"246.23", "side":"SELL", "hash":"5a62f85b64412a96f2db39d8486d240d9720a853", "best_bid":"0.84", "best_ask":"0.85"}], "timestamp":"1778784200752", "event_type":"price_change"}
{"market":"0x2a903c589141bce4a1e50fb98b73397af6820942542793ab10b1df477e912b6e", "price_changes":[{"asset_id":"20436996072316278452977393149218961565084965483366669504673105646378938504388", "price":"0.72", "size":"144.9", "side":"BUY", "hash":"b573e454513808e788304e029fffd33732ffbd6c", "best_bid":"0.84", "best_ask":"0.85"}, {"asset_id":"68919878716222388542639225642064847629616106443780159680232863841946753372582", "price":"0.28", "size":"144.9", "side":"SELL", "hash":"53b9644bd873cdab9e942642e434bcf46434effd", "best_bid":"0.15", "best_ask":"0.16"}], "timestamp":"1778784200753", "event_type":"price_change"}
{"market":"0x2a903c589141bce4a1e50fb98b73397af6820942542793ab10b1df477e912b6e", "price_changes":[{"asset_id":"20436996072316278452977393149218961565084965483366669504673105646378938504388", "price":"0.73", "size":"170.2", "side":"BUY", "hash":"9009e2f79f8ca515f87523f4fb4bc2f2251bdbf9", "best_bid":"0.84", "best_ask":"0.85"}, {"asset_id":"68919878716222388542639225642064847629616106443780159680232863841946753372582", "price":"0.27", "size":"170.2", "side":"SELL", "hash":"5199392486dc525bef357ff7f56d461d775a3d31", "best_bid":"0.15", "best_ask":"0.16"}], "timestamp":"1778784200754", "event_type":"price_change"}
{"market":"0x2a903c589141bce4a1e50fb98b73397af6820942542793ab10b1df477e912b6e", "price_changes":[{"asset_id":"68919878716222388542639225642064847629616106443780159680232863841946753372582", "price":"0.08", "size":"648.74", "side":"BUY", "hash":"e5bccc91c6a7476d19323a555066a380777dce1d", "best_bid":"0.15", "best_ask":"0.16"}, {"asset_id":"20436996072316278452977393149218961565084965483366669504673105646378938504388", "price":"0.92", "size":"648.74", "side":"SELL", "hash":"02b6e5674f5385f2c923843ac2b49f49cabac2c5", "best_bid":"0.84", "best_ask":"0.85"}], "timestamp":"1778784200756", "event_type":"price_change"}
{"market":"0x2a903c589141bce4a1e50fb98b73397af6820942542793ab10b1df477e912b6e", "price_changes":[{"asset_id":"68919878716222388542639225642064847629616106443780159680232863841946753372582", "price":"0.11", "size":"602.18", "side":"BUY", "hash":"86740f74ef5ab4c61565492e1da751d24cc05f29", "best_bid":"0.15", "best_ask":"0.16"}, {"asset_id":"20436996072316278452977393149218961565084965483366669504673105646378938504388", "price":"0.89", "size":"602.18", "side":"SELL", "hash":"b96d346f14d458fc489d8fdbb333e4f5cc01c622", "best_bid":"0.84", "best_ask":"0.85"}], "timestamp":"1778784200757", "event_type":"price_change"}
{"market":"0x2a903c589141bce4a1e50fb98b73397af6820942542793ab10b1df477e912b6e", "price_changes":[{"asset_id":"20436996072316278452977393149218961565084965483366669504673105646378938504388", "price":"0.83", "size":"88.35", "side":"BUY", "hash":"603606491988b2f4234a34c3596310fc95231a64", "best_bid":"0.84", "best_ask":"0.85"}, {"asset_id":"68919878716222388542639225642064847629616106443780159680232863841946753372582", "price":"0.17", "size":"88.35", "side":"SELL", "hash":"90df54abd53f89db04ae6e21a93d2bfed9364ea1", "best_bid":"0.15", "best_ask":"0.16"}], "timestamp":"1778784200758", "event_type":"price_change"}
{"market":"0x2a903c589141bce4a1e50fb98b73397af6820942542793ab10b1df477e912b6e", "price_changes":[{"asset_id":"68919878716222388542639225642064847629616106443780159680232863841946753372582", "price":"0.17", "size":"82.35", "side":"SELL", "hash":"0bcd631023c03d55e66263f5dfd6b6626d862c8e", "best_bid":"0.15", "best_ask":"0.16"}, {"asset_id":"20436996072316278452977393149218961565084965483366669504673105646378938504388", "price":"0.83", "size":"82.35", "side":"BUY", "hash":"c7c32d29409d2f1eef51bc35f9e403c59c909e46", "best_bid":"0.84", "best_ask":"0.85"}], "timestamp":"1778784200759", "event_type":"price_change"}
{"market":"0x2a903c589141bce4a1e50fb98b73397af6820942542793ab10b1df477e912b6e", "price_changes":[{"asset_id":"20436996072316278452977393149218961565084965483366669504673105646378938504388", "price":"0.84", "size":"30.5", "side":"BUY", "hash":"b7ffce7783eea03df70da3c3c32f88d2489f3099", "best_bid":"0.84", "best_ask":"0.85"}, {"asset_id":"68919878716222388542639225642064847629616106443780159680232863841946753372582", "price":"0.16", "size":"30.5", "side":"SELL", "hash":"35d591c02736725bfac43e3336b1ab2f16432e6d", "best_bid":"0.15", "best_ask":"0.16"}], "timestamp":"1778784200761", "event_type":"price_change"}
{"market":"0x2a903c589141bce4a1e50fb98b73397af6820942542793ab10b1df477e912b6e", "price_changes":[{"asset_id":"20436996072316278452977393149218961565084965483366669504673105646378938504388", "price":"0.8", "size":"123.8", "side":"BUY", "hash":"3aca21e52393070dd44457dba056cc82d4d2f620", "best_bid":"0.84", "best_ask":"0.85"}, {"asset_id":"68919878716222388542639225642064847629616106443780159680232863841946753372582", "price":"0.2", "size":"123.8", "side":"SELL", "hash":"6a827c1f91b9e81e5242335101cf19b4b1bbd3a1", "best_bid":"0.15", "best_ask":"0.16"}], "timestamp":"1778784200762", "event_type":"price_change"}
{"market":"0x2a903c589141bce4a1e50fb98b73397af6820942542793ab10b1df477e912b6e", "price_changes":[{"asset_id":"68919878716222388542639225642064847629616106443780159680232863841946753372582", "price":"0.12", "size":"246.23", "side":"BUY", "hash":"c7fd063058eb1ed882629d834308a12b1f175074", "best_bid":"0.15", "best_ask":"0.16"}, {"asset_id":"20436996072316278452977393149218961565084965483366669504673105646378938504388", "price":"0.88", "size":"246.23", "side":"SELL", "hash":"59f6399864b7d9bab9cec5c0d6a7941fd8e154b4", "best_bid":"0.84", "best_ask":"0.85"}], "timestamp":"1778784200763", "event_type":"price_change"}
{"market":"0x2a903c589141bce4a1e50fb98b73397af6820942542793ab10b1df477e912b6e", "price_changes":[{"asset_id":"68919878716222388542639225642064847629616106443780159680232863841946753372582", "price":"0.07", "size":"347.1", "side":"BUY", "hash":"844cfedb64a076bad9baf5e772d6166e261686ad", "best_bid":"0.15", "best_ask":"0.16"}, {"asset_id":"20436996072316278452977393149218961565084965483366669504673105646378938504388", "price":"0.93", "size":"347.1", "side":"SELL", "hash":"438a5d4948d028d46a0f168d6becb07fcfe0af06", "best_bid":"0.84", "best_ask":"0.85"}], "timestamp":"1778784200764", "event_type":"price_change"}
{"market":"0x2a903c589141bce4a1e50fb98b73397af6820942542793ab10b1df477e912b6e", "price_changes":[{"asset_id":"68919878716222388542639225642064847629616106443780159680232863841946753372582", "price":"0.11", "size":"597.18", "side":"BUY", "hash":"ac01474de10cffe6a2346d66ea4ba84b21786761", "best_bid":"0.15", "best_ask":"0.16"}, {"asset_id":"20436996072316278452977393149218961565084965483366669504673105646378938504388", "price":"0.89", "size":"597.18", "side":"SELL", "hash":"cdd1ce813f8dd21b5ebd763036a43d1b0adb0acb", "best_bid":"0.84", "best_ask":"0.85"}], "timestamp":"1778784200764", "event_type":"price_change"}
{"market":"0x2a903c589141bce4a1e50fb98b73397af6820942542793ab10b1df477e912b6e", "price_changes":[{"asset_id":"20436996072316278452977393149218961565084965483366669504673105646378938504388", "price":"0.67", "size":"328.6", "side":"BUY", "hash":"19e3a502d91f7d10b7beacc9b0a9feb5c2c3ca87", "best_bid":"0.84", "best_ask":"0.85"}, {"asset_id":"68919878716222388542639225642064847629616106443780159680232863841946753372582", "price":"0.33", "size":"328.6", "side":"SELL", "hash":"4acce3d1e983f73c2744a5ad7b9cb1ceb7a63ffa", "best_bid":"0.15", "best_ask":"0.16"}], "timestamp":"1778784200766", "event_type":"price_change"}
{"market":"0x2a903c589141bce4a1e50fb98b73397af6820942542793ab10b1df477e912b6e", "price_changes":[{"asset_id":"68919878716222388542639225642064847629616106443780159680232863841946753372582", "price":"0.33", "size":"333.6", "side":"SELL", "hash":"c38625803e44f7aba14fc4570b768758118ab7c6", "best_bid":"0.15", "best_ask":"0.16"}, {"asset_id":"20436996072316278452977393149218961565084965483366669504673105646378938504388", "price":"0.67", "size":"333.6", "side":"BUY", "hash":"49cd23b18b0401b8965640c8b401aa88616d972d", "best_bid":"0.84", "best_ask":"0.85"}], "timestamp":"1778784200767", "event_type":"price_change"}
{"market":"0x2a903c589141bce4a1e50fb98b73397af6820942542793ab10b1df477e912b6e", "price_changes":[{"asset_id":"68919878716222388542639225642064847629616106443780159680232863841946753372582", "price":"0.12", "size":"254.64", "side":"BUY", "hash":"b892b8f78c542f5ed500812f2a50da364e7c2e14", "best_bid":"0.15", "best_ask":"0.16"}, {"asset_id":"20436996072316278452977393149218961565084965483366669504673105646378938504388", "price":"0.88", "size":"254.64", "side":"SELL", "hash":"1af5413409a53273912c1cee72081a8f416b930f", "best_bid":"0.84", "best_ask":"0.85"}], "timestamp":"1778784200768", "event_type":"price_change"}
{"market":"0x2a903c589141bce4a1e50fb98b73397af6820942542793ab10b1df477e912b6e", "price_changes":[{"asset_id":"68919878716222388542639225642064847629616106443780159680232863841946753372582", "price":"0.13", "size":"115", "side":"BUY", "hash":"ed7402447f7c44f7914fd9b98633c2db32c0b03a", "best_bid":"0.15", "best_ask":"0.16"}, {"asset_id":"20436996072316278452977393149218961565084965483366669504673105646378938504388", "price":"0.87", "size":"115", "side":"SELL", "hash":"4506d869a3fc04dce8eef676e09491e547f4a14e", "best_bid":"0.84", "best_ask":"0.85"}], "timestamp":"1778784200769", "event_type":"price_change"}
{"market":"0x2a903c589141bce4a1e50fb98b73397af6820942542793ab10b1df477e912b6e", "price_changes":[{"asset_id":"68919878716222388542639225642064847629616106443780159680232863841946753372582", "price":"0.11", "size":"592.18", "side":"BUY", "hash":"9c0b9591280a243d28463706779de21958aad72b", "best_bid":"0.15", "best_ask":"0.16"}, {"asset_id":"20436996072316278452977393149218961565084965483366669504673105646378938504388", "price":"0.89", "size":"592.18", "side":"SELL", "hash":"7d0a21aebabf48cc4c84ff5eea98a3eff5859b37", "best_bid":"0.84", "best_ask":"0.85"}], "timestamp":"1778784200770", "event_type":"price_change"}
{"market":"0x2a903c589141bce4a1e50fb98b73397af6820942542793ab10b1df477e912b6e", "price_changes":[{"asset_id":"68919878716222388542639225642064847629616106443780159680232863841946753372582", "price":"0.14", "size":"223.88", "side":"BUY", "hash":"7a2bdb6a0e9a818d9f33e0ed332c7da8f01f8a67", "best_bid":"0.15", "best_ask":"0.16"}, {"asset_id":"20436996072316278452977393149218961565084965483366669504673105646378938504388", "price":"0.86", "size":"223.88", "side":"SELL", "hash":"6d4229ecc7999c8866846d3eb983992d9664974e", "best_bid":"0.84", "best_ask":"0.85"}], "timestamp":"1778784200770", "event_type":"price_change"}
{"market":"0x2a903c589141bce4a1e50fb98b73397af6820942542793ab10b1df477e912b6e", "price_changes":[{"asset_id":"20436996072316278452977393149218961565084965483366669504673105646378938504388", "price":"0.76", "size":"211.39", "side":"BUY", "hash":"c5326d9aeff0df8c26e3b99e0e5155897fc1d603", "best_bid":"0.84", "best_ask":"0.85"}, {"asset_id":"68919878716222388542639225642064847629616106443780159680232863841946753372582", "price":"0.24", "size":"211.39", "side":"SELL", "hash":"bc6c1c4cd8ffd7cf24265f9f81944421f5c5f5f8", "best_bid":"0.15", "best_ask":"0.16"}], "timestamp":"1778784200771", "event_type":"price_change"}
{"market":"0x2a903c589141bce4a1e50fb98b73397af6820942542793ab10b1df477e912b6e", "price_changes":[{"asset_id":"20436996072316278452977393149218961565084965483366669504673105646378938504388", "price":"0.92", "size":"658.33", "side":"SELL", "hash":"7ffdacf241ad9c373e88bec8d58819a3dda57c43", "best_bid":"0.84", "best_ask":"0.85"}, {"asset_id":"68919878716222388542639225642064847629616106443780159680232863841946753372582", "price":"0.08", "size":"658.33", "side":"BUY", "hash":"a5a2d22c79308f0e0aade962f4b403b4301374df", "best_bid":"0.15", "best_ask":"0.16"}], "timestamp":"1778784200772", "event_type":"price_change"}
{"market":"0x2a903c589141bce4a1e50fb98b73397af6820942542793ab10b1df477e912b6e", "price_changes":[{"asset_id":"68919878716222388542639225642064847629616106443780159680232863841946753372582", "price":"0.11", "size":"569.18", "side":"BUY", "hash":"1e8eef293a51e9be876027d17c31a0327ec553bd", "best_bid":"0.15", "best_ask":"0.16"}, {"asset_id":"20436996072316278452977393149218961565084965483366669504673105646378938504388", "price":"0.89", "size":"569.18", "side":"SELL", "hash":"17edf84f55a6c08bfe0c2bcc8cc8675cf900d740", "best_bid":"0.84", "best_ask":"0.85"}], "timestamp":"1778784200773", "event_type":"price_change"}
{"market":"0x2a903c589141bce4a1e50fb98b73397af6820942542793ab10b1df477e912b6e", "price_changes":[{"asset_id":"20436996072316278452977393149218961565084965483366669504673105646378938504388", "price":"0.5", "size":"340.91", "side":"BUY", "hash":"1e43a60c9b9e1b598db26bf5a6762fc8ae3e8547", "best_bid":"0.84", "best_ask":"0.85"}, {"asset_id":"68919878716222388542639225642064847629616106443780159680232863841946753372582", "price":"0.5", "size":"340.91", "side":"SELL", "hash":"c3fb309e49d4c9ee1c7b6d30c304194108a9efd9", "best_bid":"0.15", "best_ask":"0.16"}], "timestamp":"1778784200773", "event_type":"price_change"}
{"market":"0x2a903c589141bce4a1e50fb98b73397af6820942542793ab10b1df477e912b6e", "price_changes":[{"asset_id":"68919878716222388542639225642064847629616106443780159680232863841946753372582", "price":"0.11", "size":"564.18", "side":"BUY", "hash":"2ee0c604509cfcf9dc1b4bd283b14da9181fde0a", "best_bid":"0.15", "best_ask":"0.16"}, {"asset_id":"20436996072316278452977393149218961565084965483366669504673105646378938504388", "price":"0.89", "size":"564.18", "side":"SELL", "hash":"2472e417f61f50cc6571b15bcf7f018de0da044c", "best_bid":"0.84", "best_ask":"0.85"}], "timestamp":"1778784200775", "event_type":"price_change"}
{"market":"0x2a903c589141bce4a1e50fb98b73397af6820942542793ab10b1df477e912b6e", "price_changes":[{"asset_id":"68919878716222388542639225642064847629616106443780159680232863841946753372582", "price":"0.14", "size":"239.88", "side":"BUY", "hash":"c777d2ba982afe33a0cb9a715b7158e002a71808", "best_bid":"0.15", "best_ask":"0.16"}, {"asset_id":"20436996072316278452977393149218961565084965483366669504673105646378938504388", "price":"0.86", "size":"239.88", "side":"SELL", "hash":"b9d579927ed88e544de11437b273a1783018fa00", "best_bid":"0.84", "best_ask":"0.85"}], "timestamp":"1778784200775", "event_type":"price_change"}
{"market":"0x2a903c589141bce4a1e50fb98b73397af6820942542793ab10b1df477e912b6e", "price_changes":[{"asset_id":"20436996072316278452977393149218961565084965483366669504673105646378938504388", "price":"0.84", "size":"50.5", "side":"BUY", "hash":"ffbf390dfbef02e1d07fe1bc3590f752c61b21ac", "best_bid":"0.84", "best_ask":"0.85"}, {"asset_id":"68919878716222388542639225642064847629616106443780159680232863841946753372582", "price":"0.16", "size":"50.5", "side":"SELL", "hash":"c3d737257ef357a89b567999694d5799c3d02de5", "best_bid":"0.15", "best_ask":"0.16"}], "timestamp":"1778784200776", "event_type":"price_change"}
{"market":"0x2a903c589141bce4a1e50fb98b73397af6820942542793ab10b1df477e912b6e", "price_changes":[{"asset_id":"20436996072316278452977393149218961565084965483366669504673105646378938504388", "price":"0.78", "size":"349.5", "side":"BUY", "hash":"4f3e22d934dedf228222f1b42aa79957e366cad9", "best_bid":"0.84", "best_ask":"0.85"}, {"asset_id":"68919878716222388542639225642064847629616106443780159680232863841946753372582", "price":"0.22", "size":"349.5", "side":"SELL", "hash":"d4dde0b8a495ca4495f8e1f10ac8c5450274f134", "best_bid":"0.15", "best_ask":"0.16"}], "timestamp":"1778784200777", "event_type":"price_change"}
{"market":"0x2a903c589141bce4a1e50fb98b73397af6820942542793ab10b1df477e912b6e", "price_changes":[{"asset_id":"20436996072316278452977393149218961565084965483366669504673105646378938504388", "price":"0.84", "size":"80.5", "side":"BUY", "hash":"6363768e0c8d1e12b274e4947ad12ba9187aa467", "best_bid":"0.84", "best_ask":"0.85"}, {"asset_id":"68919878716222388542639225642064847629616106443780159680232863841946753372582", "price":"0.16", "size":"80.5", "side":"SELL", "hash":"4ec513a52f0ec1f026dd02b1ddc3d97850c9b428", "best_bid":"0.15", "best_ask":"0.16"}], "timestamp":"1778784200779", "event_type":"price_change"}
{"market":"0x2a903c589141bce4a1e50fb98b73397af6820942542793ab10b1df477e912b6e", "price_changes":[{"asset_id":"20436996072316278452977393149218961565084965483366669504673105646378938504388", "price":"0.8", "size":"148.8", "side":"BUY", "hash":"7c5d5137bab533cc88913f6b79e4e1349f081c1c", "best_bid":"0.84", "best_ask":"0.85"}, {"asset_id":"68919878716222388542639225642064847629616106443780159680232863841946753372582", "price":"0.2", "size":"148.8", "side":"SELL", "hash":"71b8d53d4c8ff393b7c084da145a4030790b2c9f", "best_bid":"0.15", "best_ask":"0.16"}], "timestamp":"1778784200780", "event_type":"price_change"}
{"market":"0x2a903c589141bce4a1e50fb98b73397af6820942542793ab10b1df477e912b6e", "price_changes":[{"asset_id":"20436996072316278452977393149218961565084965483366669504673105646378938504388", "price":"0.84", "size":"70.5", "side":"BUY", "hash":"cc48d3e57a05d8173a889b71df7050cc297d48a7", "best_bid":"0.84", "best_ask":"0.85"}, {"asset_id":"68919878716222388542639225642064847629616106443780159680232863841946753372582", "price":"0.16", "size":"70.5", "side":"SELL", "hash":"ae9ad66f595d5b7c3a447317611a8bf1c024dbaa", "best_bid":"0.15", "best_ask":"0.16"}], "timestamp":"1778784200786", "event_type":"price_change"}
{"market":"0x2a903c589141bce4a1e50fb98b73397af6820942542793ab10b1df477e912b6e", "asset_id":"68919878716222388542639225642064847629616106443780159680232863841946753372582", "bids":[{"price":"0.01", "size":"11338.83"}, {"price":"0.02", "size":"1397.82"}, {"price":"0.03", "size":"1090.78"}, {"price":"0.04", "size":"1237.82"}, {"price":"0.05", "size":"775.72"}, {"price":"0.06", "size":"297.2"}, {"price":"0.07", "size":"347.1"}, {"price":"0.08", "size":"658.33"}, {"price":"0.09", "size":"357.1"}, {"price":"0.1", "size":"576.99"}, {"price":"0.11", "size":"564.18"}, {"price":"0.12", "size":"254.64"}, {"price":"0.13", "size":"115"}, {"price":"0.14", "size":"239.88"}, {"price":"0.15", "size":"35.75"}], "asks":[{"price":"0.99", "size":"11995.61"}, {"price":"0.98", "size":"1219.45"}, {"price":"0.97", "size":"1111.98"}, {"price":"0.96", "size":"670.05"}, {"price":"0.95", "size":"549.45"}, {"price":"0.94", "size":"346.2"}, {"price":"0.93", "size":"902.05"}, {"price":"0.92", "size":"170.79"}, {"price":"0.91", "size":"234.6"}, {"price":"0.9", "size":"128"}, {"price":"0.89", "size":"142.6"}, {"price":"0.88", "size":"141.8"}, {"price":"0.87", "size":"144.81"}, {"price":"0.86", "size":"204.9"}, {"price":"0.85", "size":"113.5"}, {"price":"0.84", "size":"102.3"}, {"price":"0.83", "size":"101.3"}, {"price":"0.82", "size":"105.3"}, {"price":"0.81", "size":"199.5"}, {"price":"0.8", "size":"103.8"}, {"price":"0.79", "size":"98.1"}, {"price":"0.78", "size":"97.5"}, {"price":"0.77", "size":"96.89"}, {"price":"0.76", "size":"201.39"}, {"price":"0.75", "size":"116"}, {"price":"0.74", "size":"100.6"}, {"price":"0.73", "size":"95.2"}, {"price":"0.72", "size":"94.9"}, {"price":"0.71", "size":"199.6"}, {"price":"0.7", "size":"94.3"}, {"price":"0.69", "size":"108.28"}, {"price":"0.68", "size":"98.8"}, {"price":"0.67", "size":"118.6"}, {"price":"0.66", "size":"398.4"}, {"price":"0.65", "size":"507.3"}, {"price":"0.64", "size":"893"}, {"price":"0.63", "size":"892.9"}, {"price":"0.62", "size":"297.7"}, {"price":"0.61", "size":"397.6"}, {"price":"0.6", "size":"356.93"}, {"price":"0.59", "size":"297.4"}, {"price":"0.58", "size":"109.6"}, {"price":"0.57", "size":"131.48"}, {"price":"0.56", "size":"413.97"}, {"price":"0.55", "size":"334.2"}, {"price":"0.54", "size":"375.6"}, {"price":"0.53", "size":"292"}, {"price":"0.52", "size":"297.12"}, {"price":"0.51", "size":"402"}, {"price":"0.5", "size":"340.91"}, {"price":"0.49", "size":"312"}, {"price":"0.48", "size":"317"}, {"price":"0.47", "size":"337"}, {"price":"0.46", "size":"451.54"}, {"price":"0.45", "size":"346.64"}, {"price":"0.44", "size":"346.45"}, {"price":"0.43", "size":"434.89"}, {"price":"0.42", "size":"724.36"}, {"price":"0.41", "size":"412.4"}, {"price":"0.4", "size":"328.83"}, {"price":"0.39", "size":"297.6"}, {"price":"0.38", "size":"318.44"}, {"price":"0.37", "size":"576.9"}, {"price":"0.36", "size":"203"}, {"price":"0.35", "size":"340.14"}, {"price":"0.34", "size":"320.9"}, {"price":"0.33", "size":"333.6"}, {"price":"0.32", "size":"2065.88"}, {"price":"0.31", "size":"564"}, {"price":"0.3", "size":"144.3"}, {"price":"0.29", "size":"616.38"}, {"price":"0.28", "size":"144.9"}, {"price":"0.27", "size":"170.2"}, {"price":"0.26", "size":"230.6"}, {"price":"0.25", "size":"496"}, {"price":"0.24", "size":"211.39"}, {"price":"0.23", "size":"246.89"}, {"price":"0.22", "size":"349.5"}, {"price":"0.21", "size":"175.44"}, {"price":"0.2", "size":"148.8"}, {"price":"0.19", "size":"102.35"}, {"price":"0.18", "size":"335.82"}, {"price":"0.17", "size":"82.35"}, {"price":"0.16", "size":"70.5"}], "hash":"ae9ad66f595d5b7c3a447317611a8bf1c024dbaa", "timestamp":"1778784200786", "event_type":"book"}
{"market":"0x2a903c589141bce4a1e50fb98b73397af6820942542793ab10b1df477e912b6e", "price_changes":[{"asset_id":"20436996072316278452977393149218961565084965483366669504673105646378938504388", "price":"0.9", "size":"523", "side":"SELL", "hash":"9cc5671cee8a22fd7a49df1fa5a870ae93a39cb1", "best_bid":"0.84", "best_ask":"0.85"}, {"asset_id":"68919878716222388542639225642064847629616106443780159680232863841946753372582", "price":"0.1", "size":"523", "side":"BUY", "hash":"53b5430c07e3f9f1d2ae51e9bfecee4bac79a5de", "best_bid":"0.15", "best_ask":"0.16"}], "timestamp":"1778784200787", "event_type":"price_change"}
{"market":"0x2a903c589141bce4a1e50fb98b73397af6820942542793ab10b1df477e912b6e", "price_changes":[{"asset_id":"68919878716222388542639225642064847629616106443780159680232863841946753372582", "price":"0.11", "size":"537.18", "side":"BUY", "hash":"692c4c10227b10f8d43489ad001dd23e9b34a341", "best_bid":"0.15", "best_ask":"0.16"}, {"asset_id":"20436996072316278452977393149218961565084965483366669504673105646378938504388", "price":"0.89", "size":"537.18", "side":"SELL", "hash":"ad09466dcb848f0b5446d6b0962c48939b6db9d0", "best_bid":"0.84", "best_ask":"0.85"}], "timestamp":"1778784200787", "event_type":"price_change"}
{"market":"0x2a903c589141bce4a1e50fb98b73397af6820942542793ab10b1df477e912b6e", "price_changes":[{"asset_id":"68919878716222388542639225642064847629616106443780159680232863841946753372582", "price":"0.14", "size":"219.88", "side":"BUY", "hash":"e33326e334d9aaafc5505422e77890acf98f1107", "best_bid":"0.15", "best_ask":"0.16"}, {"asset_id":"20436996072316278452977393149218961565084965483366669504673105646378938504388", "price":"0.86", "size":"219.88", "side":"SELL", "hash":"9b8f10bb4e848e0efe27e8acf704656224089822", "best_bid":"0.84", "best_ask":"0.85"}], "timestamp":"1778784200788", "event_type":"price_change"}
{"market":"0x2a903c589141bce4a1e50fb98b73397af6820942542793ab10b1df477e912b6e", "price_changes":[{"asset_id":"68919878716222388542639225642064847629616106443780159680232863841946753372582", "price":"0.12", "size":"304.64", "side":"BUY", "hash":"0a722e5a79349e90c3a25bdf97f30a2303fafc12", "best_bid":"0.15", "best_ask":"0.16"}, {"asset_id":"20436996072316278452977393149218961565084965483366669504673105646378938504388", "price":"0.88", "size":"304.64", "side":"SELL", "hash":"635b729c348e2adbe2bec59b2b2faa77d371df9e", "best_bid":"0.84", "best_ask":"0.85"}], "timestamp":"1778784200789", "event_type":"price_change"}
{"market":"0x2a903c589141bce4a1e50fb98b73397af6820942542793ab10b1df477e912b6e", "price_changes":[{"asset_id":"20436996072316278452977393149218961565084965483366669504673105646378938504388", "price":"0.03", "size":"1096.98", "side":"BUY", "hash":"6297b0176be16b62f994efecf9f434492cc820f8", "best_bid":"0.84", "best_ask":"0.85"}, {"asset_id":"68919878716222388542639225642064847629616106443780159680232863841946753372582", "price":"0.97", "size":"1096.98", "side":"SELL", "hash":"2f46a1b7d4d7edce4b6b98453143b13eaae64cee", "best_bid":"0.15", "best_ask":"0.16"}], "timestamp":"1778784200789", "event_type":"price_change"}
{"market":"0x2a903c589141bce4a1e50fb98b73397af6820942542793ab10b1df477e912b6e", "price_changes":[{"asset_id":"68919878716222388542639225642064847629616106443780159680232863841946753372582", "price":"0.11", "size":"517.18", "side":"BUY", "hash":"29a19fa9c6a3293ee8d138ec02081406bc08756b", "best_bid":"0.15", "best_ask":"0.16"}, {"asset_id":"20436996072316278452977393149218961565084965483366669504673105646378938504388", "price":"0.89", "size":"517.18", "side":"SELL", "hash":"d6e11be7e6410a25dcaff129814033db903ce92f", "best_bid":"0.84", "best_ask":"0.85"}], "timestamp":"1778784200791", "event_type":"price_change"}
{"market":"0x2a903c589141bce4a1e50fb98b73397af6820942542793ab10b1df477e912b6e", "price_changes":[{"asset_id":"20436996072316278452977393149218961565084965483366669504673105646378938504388", "price":"0.57", "size":"444.89", "side":"BUY", "hash":"b60c26b75cb317f49c2ec16f7c2effec5656b3d8", "best_bid":"0.84", "best_ask":"0.85"}, {"asset_id":"68919878716222388542639225642064847629616106443780159680232863841946753372582", "price":"0.43", "size":"444.89", "side":"SELL", "hash":"6ede0644f8812cfc558017ef0e67136397e7db0f", "best_bid":"0.15", "best_ask":"0.16"}], "timestamp":"1778784200791", "event_type":"price_change"}
{"market":"0x2a903c589141bce4a1e50fb98b73397af6820942542793ab10b1df477e912b6e", "price_changes":[{"asset_id":"68919878716222388542639225642064847629616106443780159680232863841946753372582", "price":"0.14", "size":"224.88", "side":"BUY", "hash":"564aac7e944db7b929334afd6d3e83f0acf3cceb", "best_bid":"0.15", "best_ask":"0.16"}, {"asset_id":"20436996072316278452977393149218961565084965483366669504673105646378938504388", "price":"0.86", "size":"224.88", "side":"SELL", "hash":"c67e281fea2daf6e4395447735343d005dc1ed83", "best_bid":"0.84", "best_ask":"0.85"}], "timestamp":"1778784200792", "event_type":"price_change"}
{"market":"0x2a903c589141bce4a1e50fb98b73397af6820942542793ab10b1df477e912b6e", "price_changes":[{"asset_id":"20436996072316278452977393149218961565084965483366669504673105646378938504388", "price":"0.66", "size":"350.9", "side":"BUY", "hash":"ee6ce4b8668bd1b564c60b636649de139117d1d0", "best_bid":"0.84", "best_ask":"0.85"}, {"asset_id":"68919878716222388542639225642064847629616106443780159680232863841946753372582", "price":"0.34", "size":"350.9", "side":"SELL", "hash":"7826b7107e92c0469d55bd647031c3d2d9ebb100", "best_bid":"0.15", "best_ask":"0.16"}], "timestamp":"1778784200793", "event_type":"price_change"}
{"market":"0x2a903c589141bce4a1e50fb98b73397af6820942542793ab10b1df477e912b6e", "price_changes":[{"asset_id":"20436996072316278452977393149218961565084965483366669504673105646378938504388", "price":"0.82", "size":"409.05", "side":"BUY", "hash":"fc1aeb719b7a81f69b0e3f60b88debdfacb5264d", "best_bid":"0.84", "best_ask":"0.85"}, {"asset_id":"68919878716222388542639225642064847629616106443780159680232863841946753372582", "price":"0.18", "size":"409.05", "side":"SELL", "hash":"1e0eab9bb49dd8bc107c44f3b5643002e93e5da2", "best_bid":"0.15", "best_ask":"0.16"}], "timestamp":"1778784200795", "event_type":"price_change"}
{"market":"0x2a903c589141bce4a1e50fb98b73397af6820942542793ab10b1df477e912b6e", "price_changes":[{"asset_id":"68919878716222388542639225642064847629616106443780159680232863841946753372582", "price":"0.49", "size":"798", "side":"SELL", "hash":"8afa1174dc0f1f70e1639a2e706fcca096ece530", "best_bid":"0.15", "best_ask":"0.16"}, {"asset_id":"20436996072316278452977393149218961565084965483366669504673105646378938504388", "price":"0.51", "size":"798", "side":"BUY", "hash":"4a5ec44f98ca451062c673835a2c694b45150631", "best_bid":"0.84", "best_ask":"0.85"}], "timestamp":"1778784200796", "event_type":"price_change"}
{"market":"0x2a903c589141bce4a1e50fb98b73397af6820942542793ab10b1df477e912b6e", "price_changes":[{"asset_id":"68919878716222388542639225642064847629616106443780159680232863841946753372582", "price":"0.11", "size":"508", "side":"BUY", "hash":"8c4dd5c1f55f767186b18bb354935c43bd8ea23b", "best_bid":"0.15", "best_ask":"0.16"}, {"asset_id":"20436996072316278452977393149218961565084965483366669504673105646378938504388", "price":"0.89", "size":"508", "side":"SELL", "hash":"cefadea578f18e07a433b3a33c947530f00375af", "best_bid":"0.84", "best_ask":"0.85"}], "timestamp":"1778784200799", "event_type":"price_change"}
{"market":"0x2a903c589141bce4a1e50fb98b73397af6820942542793ab10b1df477e912b6e", "price_changes":[{"asset_id":"68919878716222388542639225642064847629616106443780159680232863841946753372582", "price":"0.14", "size":"247.88", "side":"BUY", "hash":"e45e3801db4b5a3c341e0026ceaa40d8d9d48869", "best_bid":"0.15", "best_ask":"0.16"}, {"asset_id":"20436996072316278452977393149218961565084965483366669504673105646378938504388", "price":"0.86", "size":"247.88", "side":"SELL", "hash":"c1dc426bd9d8eccc7aa6ddf8777dd73203d19115", "best_bid":"0.84", "best_ask":"0.85"}], "timestamp":"1778784200799", "event_type":"price_change"}
{"market":"0x2a903c589141bce4a1e50fb98b73397af6820942542793ab10b1df477e912b6e", "price_changes":[{"asset_id":"20436996072316278452977393149218961565084965483366669504673105646378938504388", "price":"0.88", "size":"344.64", "side":"SELL", "hash":"1b459aa8d68779cc82fdd692fec1b1d8d366c977", "best_bid":"0.84", "best_ask":"0.85"}, {"asset_id":"68919878716222388542639225642064847629616106443780159680232863841946753372582", "price":"0.12", "size":"344.64", "side":"BUY", "hash":"849b75a9aea516d59edf8513206b44cac6569340", "best_bid":"0.15", "best_ask":"0.16"}], "timestamp":"1778784200800", "event_type":"price_change"}
{"market":"0x2a903c589141bce4a1e50fb98b73397af6820942542793ab10b1df477e912b6e", "price_changes":[{"asset_id":"20436996072316278452977393149218961565084965483366669504673105646378938504388", "price":"0.82", "size":"379.05", "side":"BUY", "hash":"8d145dbbd958f06cf20ce9696ca62ecb9b31ab48", "best_bid":"0.84", "best_ask":"0.85"}, {"asset_id":"68919878716222388542639225642064847629616106443780159680232863841946753372582", "price":"0.18", "size":"379.05", "side":"SELL", "hash":"de023a45e4ecc51bb71c0d4dba43c826d23950f2", "best_bid":"0.15", "best_ask":"0.16"}], "timestamp":"1778784200801", "event_type":"price_change"}
{"market":"0x2a903c589141bce4a1e50fb98b73397af6820942542793ab10b1df477e912b6e", "price_changes":[{"asset_id":"20436996072316278452977393149218961565084965483366669504673105646378938504388", "price":"0.67", "size":"363.6", "side":"BUY", "hash":"2d33d632d4923d5ff2cd95444ae1b336c437dd28", "best_bid":"0.84", "best_ask":"0.85"}, {"asset_id":"68919878716222388542639225642064847629616106443780159680232863841946753372582", "price":"0.33", "size":"363.6", "side":"SELL", "hash":"fa5c22a017c878f29b408f6c352d4d338c2caf76", "best_bid":"0.15", "best_ask":"0.16"}], "timestamp":"1778784200802", "event_type":"price_change"}
{"market":"0x2a903c589141bce4a1e50fb98b73397af6820942542793ab10b1df477e912b6e", "price_changes":[{"asset_id":"68919878716222388542639225642064847629616106443780159680232863841946753372582", "price":"0.16", "size":"75.5", "side":"SELL", "hash":"c2443c98a2472bc9529668eddea9e808c9d04bcc", "best_bid":"0.15", "best_ask":"0.16"}, {"asset_id":"20436996072316278452977393149218961565084965483366669504673105646378938504388", "price":"0.84", "size":"75.5", "side":"BUY", "hash":"6a600ff48cbd283ef66400fa03f35cb84fcf63dd", "best_bid":"0.84", "best_ask":"0.85"}], "timestamp":"1778784200803", "event_type":"price_change"}
{"market":"0x2a903c589141bce4a1e50fb98b73397af6820942542793ab10b1df477e912b6e", "price_changes":[{"asset_id":"20436996072316278452977393149218961565084965483366669504673105646378938504388", "price":"0.84", "size":"25.5", "side":"BUY", "hash":"db38849da3f161004ba7c2c88f531cb5deb8702d", "best_bid":"0.84", "best_ask":"0.85"}, {"asset_id":"68919878716222388542639225642064847629616106443780159680232863841946753372582", "price":"0.16", "size":"25.5", "side":"SELL", "hash":"2af1c2f6e71f04e7d3efbe174a4b377de5927e9a", "best_bid":"0.15", "best_ask":"0.16"}], "timestamp":"1778784200805", "event_type":"price_change"}
{"market":"0x2a903c589141bce4a1e50fb98b73397af6820942542793ab10b1df477e912b6e", "price_changes":[{"asset_id":"68919878716222388542639225642064847629616106443780159680232863841946753372582", "price":"0.15", "size":"6.33", "side":"BUY", "hash":"51291105011931332f70022688e16771e9fa558f", "best_bid":"0.15", "best_ask":"0.16"}, {"asset_id":"20436996072316278452977393149218961565084965483366669504673105646378938504388", "price":"0.85", "size":"6.33", "side":"SELL", "hash":"8e67c96de1824a0a2a95c6a949c3287d7265bd0f", "best_bid":"0.84", "best_ask":"0.85"}], "timestamp":"1778784200806", "event_type":"price_change"}
{"market":"0x2a903c589141bce4a1e50fb98b73397af6820942542793ab10b1df477e912b6e", "asset_id":"68919878716222388542639225642064847629616106443780159680232863841946753372582", "bids":[{"price":"0.01", "size":"11338.83"}, {"price":"0.02", "size":"1397.82"}, {"price":"0.03", "size":"1090.78"}, {"price":"0.04", "size":"1237.82"}, {"price":"0.05", "size":"775.72"}, {"price":"0.06", "size":"297.2"}, {"price":"0.07", "size":"347.1"}, {"price":"0.08", "size":"658.33"}, {"price":"0.09", "size":"357.1"}, {"price":"0.1", "size":"523"}, {"price":"0.11", "size":"508"}, {"price":"0.12", "size":"344.64"}, {"price":"0.13", "size":"115"}, {"price":"0.14", "size":"247.88"}, {"price":"0.15", "size":"6.33"}], "asks":[{"price":"0.99", "size":"11995.61"}, {"price":"0.98", "size":"1219.45"}, {"price":"0.97", "size":"1096.98"}, {"price":"0.96", "size":"670.05"}, {"price":"0.95", "size":"549.45"}, {"price":"0.94", "size":"346.2"}, {"price":"0.93", "size":"902.05"}, {"price":"0.92", "size":"170.79"}, {"price":"0.91", "size":"234.6"}, {"price":"0.9", "size":"128"}, {"price":"0.89", "size":"142.6"}, {"price":"0.88", "size":"141.8"}, {"price":"0.87", "size":"144.81"}, {"price":"0.86", "size":"204.9"}, {"price":"0.85", "size":"113.5"}, {"price":"0.84", "size":"102.3"}, {"price":"0.83", "size":"101.3"}, {"price":"0.82", "size":"105.3"}, {"price":"0.81", "size":"199.5"}, {"price":"0.8", "size":"103.8"}, {"price":"0.79", "size":"98.1"}, {"price":"0.78", "size":"97.5"}, {"price":"0.77", "size":"96.89"}, {"price":"0.76", "size":"201.39"}, {"price":"0.75", "size":"116"}, {"price":"0.74", "size":"100.6"}, {"price":"0.73", "size":"95.2"}, {"price":"0.72", "size":"94.9"}, {"price":"0.71", "size":"199.6"}, {"price":"0.7", "size":"94.3"}, {"price":"0.69", "size":"108.28"}, {"price":"0.68", "size":"98.8"}, {"price":"0.67", "size":"118.6"}, {"price":"0.66", "size":"398.4"}, {"price":"0.65", "size":"507.3"}, {"price":"0.64", "size":"893"}, {"price":"0.63", "size":"892.9"}, {"price":"0.62", "size":"297.7"}, {"price":"0.61", "size":"397.6"}, {"price":"0.6", "size":"356.93"}, {"price":"0.59", "size":"297.4"}, {"price":"0.58", "size":"109.6"}, {"price":"0.57", "size":"131.48"}, {"price":"0.56", "size":"413.97"}, {"price":"0.55", "size":"334.2"}, {"price":"0.54", "size":"375.6"}, {"price":"0.53", "size":"292"}, {"price":"0.52", "size":"297.12"}, {"price":"0.51", "size":"402"}, {"price":"0.5", "size":"340.91"}, {"price":"0.49", "size":"798"}, {"price":"0.48", "size":"317"}, {"price":"0.47", "size":"337"}, {"price":"0.46", "size":"451.54"}, {"price":"0.45", "size":"346.64"}, {"price":"0.44", "size":"346.45"}, {"price":"0.43", "size":"444.89"}, {"price":"0.42", "size":"724.36"}, {"price":"0.41", "size":"412.4"}, {"price":"0.4", "size":"328.83"}, {"price":"0.39", "size":"297.6"}, {"price":"0.38", "size":"318.44"}, {"price":"0.37", "size":"576.9"}, {"price":"0.36", "size":"203"}, {"price":"0.35", "size":"340.14"}, {"price":"0.34", "size":"350.9"}, {"price":"0.33", "size":"363.6"}, {"price":"0.32", "size":"2065.88"}, {"price":"0.31", "size":"564"}, {"price":"0.3", "size":"144.3"}, {"price":"0.29", "size":"616.38"}, {"price":"0.28", "size":"144.9"}, {"price":"0.27", "size":"170.2"}, {"price":"0.26", "size":"230.6"}, {"price":"0.25", "size":"496"}, {"price":"0.24", "size":"211.39"}, {"price":"0.23", "size":"246.89"}, {"price":"0.22", "size":"349.5"}, {"price":"0.21", "size":"175.44"}, {"price":"0.2", "size":"148.8"}, {"price":"0.19", "size":"102.35"}, {"price":"0.18", "size":"379.05"}, {"price":"0.17", "size":"82.35"}, {"price":"0.16", "size":"25.5"}], "hash":"51291105011931332f70022688e16771e9fa558f", "timestamp":"1778784200806", "event_type":"book"}
{"market":"0x2a903c589141bce4a1e50fb98b73397af6820942542793ab10b1df477e912b6e", "asset_id":"68919878716222388542639225642064847629616106443780159680232863841946753372582", "price":"0.16", "size":"10", "fee_rate_bps":"0", "side":"BUY", "timestamp":"1778784200807", "event_type":"last_trade_price", "transaction_hash":"0x98c0901926a61218cf7fe31c7bbce88d5bddb16e6ea1eec014cfc6611085bfa4"}
{"market":"0x2a903c589141bce4a1e50fb98b73397af6820942542793ab10b1df477e912b6e", "price_changes":[{"asset_id":"20436996072316278452977393149218961565084965483366669504673105646378938504388", "price":"0.81", "size":"77.35", "side":"BUY", "hash":"a783334e3130783ca9d1f920a03d3290875df24f", "best_bid":"0.84", "best_ask":"0.85"}, {"asset_id":"68919878716222388542639225642064847629616106443780159680232863841946753372582", "price":"0.19", "size":"77.35", "side":"SELL", "hash":"7b798bc49dc089395f8492cd12968738151747f3", "best_bid":"0.15", "best_ask":"0.16"}], "timestamp":"1778784200808", "event_type":"price_change"}
{"market":"0x2a903c589141bce4a1e50fb98b73397af6820942542793ab10b1df477e912b6e", "price_changes":[{"asset_id":"20436996072316278452977393149218961565084965483366669504673105646378938504388", "price":"0.73", "size":"470.2", "side":"BUY", "hash":"9fd709a0900cada336c7de276af10385a5512429", "best_bid":"0.84", "best_ask":"0.85"}, {"asset_id":"68919878716222388542639225642064847629616106443780159680232863841946753372582", "price":"0.27", "size":"470.2", "side":"SELL", "hash":"ca8ef5ebd84163258d9db5ef4c721c3d346be4ca", "best_bid":"0.15", "best_ask":"0.16"}], "timestamp":"1778784200809", "event_type":"price_change"}
{"market":"0x2a903c589141bce4a1e50fb98b73397af6820942542793ab10b1df477e912b6e", "price_changes":[{"asset_id":"20436996072316278452977393149218961565084965483366669504673105646378938504388", "price":"0.78", "size":"379.5", "side":"BUY", "hash":"7ce731806bcffb913c8d814e1fea0c0946e5cedd", "best_bid":"0.84", "best_ask":"0.85"}, {"asset_id":"68919878716222388542639225642064847629616106443780159680232863841946753372582", "price":"0.22", "size":"379.5", "side":"SELL", "hash":"856a85f613e2c47c4af82fe940206b805296fb8e", "best_bid":"0.15", "best_ask":"0.16"}], "timestamp":"1778784200811", "event_type":"price_change"}
{"market":"0x2a903c589141bce4a1e50fb98b73397af6820942542793ab10b1df477e912b6e", "price_changes":[{"asset_id":"20436996072316278452977393149218961565084965483366669504673105646378938504388", "price":"0.77", "size":"261.89", "side":"BUY", "hash":"4e574ea0b1853ef4782287122e9da06baa3b21fe", "best_bid":"0.84", "best_ask":"0.85"}, {"asset_id":"68919878716222388542639225642064847629616106443780159680232863841946753372582", "price":"0.23", "size":"261.89", "side":"SELL", "hash":"dc838bb1716314761b9477ee2e84d649440a2629", "best_bid":"0.15", "best_ask":"0.16"}], "timestamp":"1778784200812", "event_type":"price_change"}
{"market":"0x2a903c589141bce4a1e50fb98b73397af6820942542793ab10b1df477e912b6e", "price_changes":[{"asset_id":"20436996072316278452977393149218961565084965483366669504673105646378938504388", "price":"0.56", "size":"341.45", "side":"BUY", "hash":"dd64f7e5db4dee598d8753745ad596f752d71a1a", "best_bid":"0.84", "best_ask":"0.85"}, {"asset_id":"68919878716222388542639225642064847629616106443780159680232863841946753372582", "price":"0.44", "size":"341.45", "side":"SELL", "hash":"5200e9b78e339b3c832a537a8dd2ca59a8733956", "best_bid":"0.15", "best_ask":"0.16"}], "timestamp":"1778784200813", "event_type":"price_change"}
{"market":"0x2a903c589141bce4a1e50fb98b73397af6820942542793ab10b1df477e912b6e", "price_changes":[{"asset_id":"68919878716222388542639225642064847629616106443780159680232863841946753372582", "price":"0.15", "size":"16.33", "side":"BUY", "hash":"8ac51d4cd7c2d5311dd7d42e6be879a51cf5fa6f", "best_bid":"0.15", "best_ask":"0.16"}, {"asset_id":"20436996072316278452977393149218961565084965483366669504673105646378938504388", "price":"0.85", "size":"16.33", "side":"SELL", "hash":"d42c8bec019ccf9479ebd02cd543072149d35ed6", "best_bid":"0.84", "best_ask":"0.85"}], "timestamp":"1778784200814", "event_type":"price_change"}
{"market":"0x2a903c589141bce4a1e50fb98b73397af6820942542793ab10b1df477e912b6e", "price_changes":[{"asset_id":"20436996072316278452977393149218961565084965483366669504673105646378938504388", "price":"0.7", "size":"134.3", "side":"BUY", "hash":"9400b99de3b65ead5502716c537cd41d3aa13574", "best_bid":"0.84", "best_ask":"0.85"}, {"asset_id":"68919878716222388542639225642064847629616106443780159680232863841946753372582", "price":"0.3", "size":"134.3", "side":"SELL", "hash":"ad06928cb395b5d7d2a7f41b6c250daee6f0375a", "best_bid":"0.15", "best_ask":"0.16"}], "timestamp":"1778784200815", "event_type":"price_change"}
{"market":"0x2a903c589141bce4a1e50fb98b73397af6820942542793ab10b1df477e912b6e", "price_changes":[{"asset_id":"68919878716222388542639225642064847629616106443780159680232863841946753372582", "price":"0.03", "size":"1100.78", "side":"BUY", "hash":"68fb92e03199b641c11ed63de343c9b839465a89", "best_bid":"0.15", "best_ask":"0.16"}, {"asset_id":"20436996072316278452977393149218961565084965483366669504673105646378938504388", "price":"0.97", "size":"1100.78", "side":"SELL", "hash":"6e3ea9fe59ee6228b8b83bd31b250be2f6387ca4", "best_bid":"0.84", "best_ask":"0.85"}], "timestamp":"1778784200816", "event_type":"price_change"}
{"market":"0x2a903c589141bce4a1e50fb98b73397af6820942542793ab10b1df477e912b6e", "price_changes":[{"asset_id":"68919878716222388542639225642064847629616106443780159680232863841946753372582", "price":"0.11", "size":"495", "side":"BUY", "hash":"b2a82c7b30379b74dec2cbb9d6e7ef540343bb03", "best_bid":"0.15", "best_ask":"0.16"}, {"asset_id":"20436996072316278452977393149218961565084965483366669504673105646378938504388", "price":"0.89", "size":"495", "side":"SELL", "hash":"1c912b95e51cfd1bce5c947b9fb5660c3dc1cd0c", "best_bid":"0.84", "best_ask":"0.85"}], "timestamp":"1778784200817", "event_type":"price_change"}
{"market":"0x2a903c589141bce4a1e50fb98b73397af6820942542793ab10b1df477e912b6e", "price_changes":[{"asset_id":"68919878716222388542639225642064847629616106443780159680232863841946753372582", "price":"0.11", "size":"465", "side":"BUY", "hash":"a21ab71dd330ee13b964c65fdc81382906868056", "best_bid":"0.15", "best_ask":"0.16"}, {"asset_id":"20436996072316278452977393149218961565084965483366669504673105646378938504388", "price":"0.89", "size":"465", "side":"SELL", "hash":"6ba962ca5c08c1eb33f61957489c9d3962e25b75", "best_bid":"0.84", "best_ask":"0.85"}], "timestamp":"1778784200817", "event_type":"price_change"}
{"market":"0x2a903c589141bce4a1e50fb98b73397af6820942542793ab10b1df477e912b6e", "price_changes":[{"asset_id":"68919878716222388542639225642064847629616106443780159680232863841946753372582", "price":"0.11", "size":"474.1", "side":"BUY", "hash":"011b5c9c956927a543d18dcc1d5843f70c2456d4", "best_bid":"0.15", "best_ask":"0.16"}, {"asset_id":"20436996072316278452977393149218961565084965483366669504673105646378938504388", "price":"0.89", "size":"474.1", "side":"SELL", "hash":"ed33f1a39ac6d45c8ef079a01a8ee4f4757121a2", "best_bid":"0.84", "best_ask":"0.85"}], "timestamp":"1778784200818", "event_type":"price_change"}
{"market":"0x2a903c589141bce4a1e50fb98b73397af6820942542793ab10b1df477e912b6e", "price_changes":[{"asset_id":"20436996072316278452977393149218961565084965483366669504673105646378938504388", "price":"0.83", "size":"10", "side":"BUY", "hash":"2c68f340be10a99d28c82289c34da1f6feaba875", "best_bid":"0.84", "best_ask":"0.85"}, {"asset_id":"68919878716222388542639225642064847629616106443780159680232863841946753372582", "price":"0.17", "size":"10", "side":"SELL", "hash":"3ad1ea5d39afcc328a2156f26e09ec1ef4a1219f", "best_bid":"0.15", "best_ask":"0.16"}], "timestamp":"1778784200819", "event_type":"price_change"}
{"market":"0x2a903c589141bce4a1e50fb98b73397af6820942542793ab10b1df477e912b6e", "price_changes":[{"asset_id":"68919878716222388542639225642064847629616106443780159680232863841946753372582", "price":"0.13", "size":"95", "side":"BUY", "hash":"bde170071db5131163a3f36a379b887ebdc489d4", "best_bid":"0.15", "best_ask":"0.16"}, {"asset_id":"20436996072316278452977393149218961565084965483366669504673105646378938504388", "price":"0.87", "size":"95", "side":"SELL", "hash":"5d95518c196f77167ef36d4589653131fc5af1ac", "best_bid":"0.84", "best_ask":"0.85"}], "timestamp":"1778784200825", "event_type":"price_change"}
{"market":"0x2a903c589141bce4a1e50fb98b73397af6820942542793ab10b1df477e912b6e", "price_changes":[{"asset_id":"68919878716222388542639225642064847629616106443780159680232863841946753372582", "price":"0.11", "size":"474.1", "side":"BUY", "hash":"bde170071db5131163a3f36a379b887ebdc489d4", "best_bid":"0.15", "best_ask":"0.16"}, {"asset_id":"20436996072316278452977393149218961565084965483366669504673105646378938504388", "price":"0.89", "size":"474.1", "side":"SELL", "hash":"5d95518c196f77167ef36d4589653131fc5af1ac", "best_bid":"0.84", "best_ask":"0.85"}], "timestamp":"1778784200825", "event_type":"price_change"}
{"market":"0x2a903c589141bce4a1e50fb98b73397af6820942542793ab10b1df477e912b6e", "price_changes":[{"asset_id":"20436996072316278452977393149218961565084965483366669504673105646378938504388", "price":"0.78", "size":"349.5", "side":"BUY", "hash":"54577efb0dbd96b199f02ab1da760895971e3719", "best_bid":"0.84", "best_ask":"0.85"}, {"asset_id":"68919878716222388542639225642064847629616106443780159680232863841946753372582", "price":"0.22", "size":"349.5", "side":"SELL", "hash":"3d4a10c1d1cc39141df5a38a7cacfae3817ebcfd", "best_bid":"0.15", "best_ask":"0.16"}], "timestamp":"1778784200825", "event_type":"price_change"}
{"market":"0x2a903c589141bce4a1e50fb98b73397af6820942542793ab10b1df477e912b6e", "price_changes":[{"asset_id":"20436996072316278452977393149218961565084965483366669504673105646378938504388", "price":"0.77", "size":"246.89", "side":"BUY", "hash":"54577efb0dbd96b199f02ab1da760895971e3719", "best_bid":"0.84", "best_ask":"0.85"}, {"asset_id":"68919878716222388542639225642064847629616106443780159680232863841946753372582", "price":"0.23", "size":"246.89", "side":"SELL", "hash":"3d4a10c1d1cc39141df5a38a7cacfae3817ebcfd", "best_bid":"0.15", "best_ask":"0.16"}], "timestamp":"1778784200825", "event_type":"price_change"}
{"market":"0x2a903c589141bce4a1e50fb98b73397af6820942542793ab10b1df477e912b6e", "price_changes":[{"asset_id":"68919878716222388542639225642064847629616106443780159680232863841946753372582", "price":"0.11", "size":"454.1", "side":"BUY", "hash":"3d5a342452b880df3d0dc7d235637bfc1953ded1", "best_bid":"0.15", "best_ask":"0.16"}, {"asset_id":"20436996072316278452977393149218961565084965483366669504673105646378938504388", "price":"0.89", "size":"454.1", "side":"SELL", "hash":"95723e9652cae9e98956e5df145fcd3b1d620c95", "best_bid":"0.84", "best_ask":"0.85"}], "timestamp":"1778784200827", "event_type":"price_change"}
{"market":"0x2a903c589141bce4a1e50fb98b73397af6820942542793ab10b1df477e912b6e", "price_changes":[{"asset_id":"20436996072316278452977393149218961565084965483366669504673105646378938504388", "price":"0.84", "size":"30.5", "side":"BUY", "hash":"75d0d780f8f6e04979241c4372e46e13aeed836f", "best_bid":"0.84", "best_ask":"0.85"}, {"asset_id":"68919878716222388542639225642064847629616106443780159680232863841946753372582", "price":"0.16", "size":"30.5", "side":"SELL", "hash":"64b33203f1027c8528ca7e2d16901f84a178fc68", "best_bid":"0.15", "best_ask":"0.16"}], "timestamp":"1778784200828", "event_type":"price_change"}
{"market":"0x2a903c589141bce4a1e50fb98b73397af6820942542793ab10b1df477e912b6e", "price_changes":[{"asset_id":"68919878716222388542639225642064847629616106443780159680232863841946753372582", "price":"0.11", "size":"439.1", "side":"BUY", "hash":"a0f90bb7568adf087dcd5faa691b2eb8db3656d9", "best_bid":"0.15", "best_ask":"0.16"}, {"asset_id":"20436996072316278452977393149218961565084965483366669504673105646378938504388", "price":"0.89", "size":"439.1", "side":"SELL", "hash":"34edef938c44af0d6fc900a4d43a403af7a7dd1c", "best_bid":"0.84", "best_ask":"0.85"}], "timestamp":"1778784200829", "event_type":"price_change"}
{"market":"0x2a903c589141bce4a1e50fb98b73397af6820942542793ab10b1df477e912b6e", "price_changes":[{"asset_id":"68919878716222388542639225642064847629616106443780159680232863841946753372582", "price":"0.11", "size":"422.1", "side":"BUY", "hash":"11e9823528f48ae90d2a1727b16e0410b92a9e2c", "best_bid":"0.15", "best_ask":"0.16"}, {"asset_id":"20436996072316278452977393149218961565084965483366669504673105646378938504388", "price":"0.89", "size":"422.1", "side":"SELL", "hash":"39f44c05009552c9a7ffd5176ed8042583d07d92", "best_bid":"0.84", "best_ask":"0.85"}], "timestamp":"1778784200830", "event_type":"price_change"}
{"market":"0x2a903c589141bce4a1e50fb98b73397af6820942542793ab10b1df477e912b6e", "price_changes":[{"asset_id":"68919878716222388542639225642064847629616106443780159680232863841946753372582", "price":"0.1", "size":"507", "side":"BUY", "hash":"6809034048538f55fcd96de7993323bca043bee9", "best_bid":"0.15", "best_ask":"0.16"}, {"asset_id":"20436996072316278452977393149218961565084965483366669504673105646378938504388", "price":"0.9", "size":"507", "side":"SELL", "hash":"ea6bdc37e3ee175250ec6f07629595379a43790b", "best_bid":"0.84", "best_ask":"0.85"}], "timestamp":"1778784200830", "event_type":"price_change"}
{"market":"0x2a903c589141bce4a1e50fb98b73397af6820942542793ab10b1df477e912b6e", "price_changes":[{"asset_id":"68919878716222388542639225642064847629616106443780159680232863841946753372582", "price":"0.01", "size":"11333.83", "side":"BUY", "hash":"2580ec6a32df8b93d3f83122a47b8ce05df795aa", "best_bid":"0.15", "best_ask":"0.16"}, {"asset_id":"20436996072316278452977393149218961565084965483366669504673105646378938504388", "price":"0.99", "size":"11333.83", "side":"SELL", "hash":"4b6d2471331ad4ecd8d6996edc069b747d6810f3", "best_bid":"0.84", "best_ask":"0.85"}], "timestamp":"1778784200831", "event_type":"price_change"}
{"market":"0x2a903c589141bce4a1e50fb98b73397af6820942542793ab10b1df477e912b6e", "price_changes":[{"asset_id":"20436996072316278452977393149218961565084965483366669504673105646378938504388", "price":"0.69", "size":"559", "side":"BUY", "hash":"bdfa093348218e3d5d500753829b30e80f09bd05", "best_bid":"0.84", "best_ask":"0.85"}, {"asset_id":"68919878716222388542639225642064847629616106443780159680232863841946753372582", "price":"0.31", "size":"559", "side":"SELL", "hash":"96192dce2254b4b5cd14c2700c6c282662863599", "best_bid":"0.15", "best_ask":"0.16"}], "timestamp":"1778784200832", "event_type":"price_change"}
{"market":"0x2a903c589141bce4a1e50fb98b73397af6820942542793ab10b1df477e912b6e", "price_changes":[{"asset_id":"20436996072316278452977393149218961565084965483366669504673105646378938504388", "price":"0.72", "size":"139.9", "side":"BUY", "hash":"bdfa093348218e3d5d500753829b30e80f09bd05", "best_bid":"0.84", "best_ask":"0.85"}, {"asset_id":"68919878716222388542639225642064847629616106443780159680232863841946753372582", "price":"0.28", "size":"139.9", "side":"SELL", "hash":"96192dce2254b4b5cd14c2700c6c282662863599", "best_bid":"0.15", "best_ask":"0.16"}], "timestamp":"1778784200832", "event_type":"price_change"}
{"market":"0x2a903c589141bce4a1e50fb98b73397af6820942542793ab10b1df477e912b6e", "price_changes":[{"asset_id":"68919878716222388542639225642064847629616106443780159680232863841946753372582", "price":"0.08", "size":"699.12", "side":"BUY", "hash":"883cebfdf21799844ee08d1dd64e70fc507a9cca", "best_bid":"0.15", "best_ask":"0.16"}, {"asset_id":"20436996072316278452977393149218961565084965483366669504673105646378938504388", "price":"0.92", "size":"699.12", "side":"SELL", "hash":"1d5336ada2610144201b1bbb5906f8497f525bc1", "best_bid":"0.84", "best_ask":"0.85"}], "timestamp":"1778784200833", "event_type":"price_change"}
{"market":"0x2a903c589141bce4a1e50fb98b73397af6820942542793ab10b1df477e912b6e", "price_changes":[{"asset_id":"68919878716222388542639225642064847629616106443780159680232863841946753372582", "price":"0.12", "size":"360.64", "side":"BUY", "hash":"049c068d9560b1256f62fad55979ff013564647f", "best_bid":"0.15", "best_ask":"0.16"}, {"asset_id":"20436996072316278452977393149218961565084965483366669504673105646378938504388", "price":"0.88", "size":"360.64", "side":"SELL", "hash":"846ef70b55a5ab83f81b7590055344a898b6bdda", "best_bid":"0.84", "best_ask":"0.85"}], "timestamp":"1778784200834", "event_type":"price_change"}
{"market":"0x2a903c589141bce4a1e50fb98b73397af6820942542793ab10b1df477e912b6e", "price_changes":[{"asset_id":"20436996072316278452977393149218961565084965483366669504673105646378938504388", "price":"0.82", "size":"409.05", "side":"BUY", "hash":"84434fe7f8a4d5ebc9dba557ee87d9a672800a1f", "best_bid":"0.84", "best_ask":"0.85"}, {"asset_id":"68919878716222388542639225642064847629616106443780159680232863841946753372582", "price":"0.18", "size":"409.05", "side":"SELL", "hash":"3f8044e91bbc2f6299c3c037990ca9072587c8d0", "best_bid":"0.15", "best_ask":"0.16"}], "timestamp":"1778784200835", "event_type":"price_change"}
{"market":"0x2a903c589141bce4a1e50fb98b73397af6820942542793ab10b1df477e912b6e", "price_changes":[{"asset_id":"20436996072316278452977393149218961565084965483366669504673105646378938504388", "price":"0.7", "size":"234.3", "side":"BUY", "hash":"1489fc6f59f50a8b586bc15340efb66b78e4446a", "best_bid":"0.84", "best_ask":"0.85"}, {"asset_id":"68919878716222388542639225642064847629616106443780159680232863841946753372582", "price":"0.3", "size":"234.3", "side":"SELL", "hash":"e1c64a830927268f13503a5dcd2bce436188d755", "best_bid":"0.15", "best_ask":"0.16"}], "timestamp":"1778784200837", "event_type":"price_change"}
{"market":"0x2a903c589141bce4a1e50fb98b73397af6820942542793ab10b1df477e912b6e", "price_changes":[{"asset_id":"68919878716222388542639225642064847629616106443780159680232863841946753372582", "price":"0.11", "size":"405.1", "side":"BUY", "hash":"fce8c5deafaf22002011c59d35e6fc34cfd1aa8c", "best_bid":"0.15", "best_ask":"0.16"}, {"asset_id":"20436996072316278452977393149218961565084965483366669504673105646378938504388", "price":"0.89", "size":"405.1", "side":"SELL", "hash":"00a5ba1e5ca78f4962216621b6842ea0ce7196bc", "best_bid":"0.84", "best_ask":"0.85"}], "timestamp":"1778784200838", "event_type":"price_change"}
{"market":"0x2a903c589141bce4a1e50fb98b73397af6820942542793ab10b1df477e912b6e", "price_changes":[{"asset_id":"68919878716222388542639225642064847629616106443780159680232863841946753372582", "price":"0.11", "size":"389.1", "side":"BUY", "hash":"0c8246552d18c9cbb9e9b0cde94ec1524cb9aa20", "best_bid":"0.15", "best_ask":"0.16"}, {"asset_id":"20436996072316278452977393149218961565084965483366669504673105646378938504388", "price":"0.89", "size":"389.1", "side":"SELL", "hash":"f353681368394397c35e50d79ff2a0c106a9a8b0", "best_bid":"0.84", "best_ask":"0.85"}], "timestamp":"1778784200840", "event_type":"price_change"}
{"market":"0x2a903c589141bce4a1e50fb98b73397af6820942542793ab10b1df477e912b6e", "price_changes":[{"asset_id":"20436996072316278452977393149218961565084965483366669504673105646378938504388", "price":"0.83", "size":"33.97", "side":"BUY", "hash":"42fd2524a1dc992afc39f682b1026ef92ad45350", "best_bid":"0.84", "best_ask":"0.85"}, {"asset_id":"68919878716222388542639225642064847629616106443780159680232863841946753372582", "price":"0.17", "size":"33.97", "side":"SELL", "hash":"da62ba0a87a62d10540fe728101b6dca24dce3c9", "best_bid":"0.15", "best_ask":"0.16"}], "timestamp":"1778784200841", "event_type":"price_change"}
{"market":"0x2a903c589141bce4a1e50fb98b73397af6820942542793ab10b1df477e912b6e", "price_changes":[{"asset_id":"68919878716222388542639225642064847629616106443780159680232863841946753372582", "price":"0.08", "size":"704.12", "side":"BUY", "hash":"0c1e2ac04e2ad0e102e14d824c2330a5b1bae4dd", "best_bid":"0.15", "best_ask":"0.16"}, {"asset_id":"20436996072316278452977393149218961565084965483366669504673105646378938504388", "price":"0.92", "size":"704.12", "side":"SELL", "hash":"41f826963aacde0a059ee6261fc10178644cef9c", "best_bid":"0.84", "best_ask":"0.85"}], "timestamp":"1778784200842", "event_type":"price_change"}
{"market":"0x2a903c589141bce4a1e50fb98b73397af6820942542793ab10b1df477e912b6e", "price_changes":[{"asset_id":"68919878716222388542639225642064847629616106443780159680232863841946753372582", "price":"0.11", "size":"399.1", "side":"BUY", "hash":"297ac6dcdefab9665deb6d06558b8687ace3934a", "best_bid":"0.15", "best_ask":"0.16"}, {"asset_id":"20436996072316278452977393149218961565084965483366669504673105646378938504388", "price":"0.89", "size":"399.1", "side":"SELL", "hash":"67c26c1e5f8ecddb97cb8b0b264b647bfb7b8311", "best_bid":"0.84", "best_ask":"0.85"}], "timestamp":"1778784200843", "event_type":"price_change"}
{"market":"0x2a903c589141bce4a1e50fb98b73397af6820942542793ab10b1df477e912b6e", "price_changes":[{"asset_id":"20436996072316278452977393149218961565084965483366669504673105646378938504388", "price":"0.82", "size":"393.05", "side":"BUY", "hash":"f5cb19654f6c37d055c9eb451bf13407de856f27", "best_bid":"0.84", "best_ask":"0.85"}, {"asset_id":"68919878716222388542639225642064847629616106443780159680232863841946753372582", "price":"0.18", "size":"393.05", "side":"SELL", "hash":"c4be4723297baf9b0de96bce3c420d47dc4c1ee2", "best_bid":"0.15", "best_ask":"0.16"}], "timestamp":"1778784200844", "event_type":"price_change"}
{"market":"0x2a903c589141bce4a1e50fb98b73397af6820942542793ab10b1df477e912b6e", "price_changes":[{"asset_id":"68919878716222388542639225642064847629616106443780159680232863841946753372582", "price":"0.15", "size":"27.33", "side":"BUY", "hash":"7e0ed8f48ecb0d4ea87508ba1f36e436a2ace4b1", "best_bid":"0.15", "best_ask":"0.16"}, {"asset_id":"20436996072316278452977393149218961565084965483366669504673105646378938504388", "price":"0.85", "size":"27.33", "side":"SELL", "hash":"cc13d670d19fab48f7cdc67ece1000ef11f7fcb9", "best_bid":"0.84", "best_ask":"0.85"}], "timestamp":"1778784200845", "event_type":"price_change"}
{"market":"0x2a903c589141bce4a1e50fb98b73397af6820942542793ab10b1df477e912b6e", "price_changes":[{"asset_id":"68919878716222388542639225642064847629616106443780159680232863841946753372582", "price":"0.15", "size":"37.33", "side":"BUY", "hash":"bd80e6f50725d07446897a7ebcf972e2a8085487", "best_bid":"0.15", "best_ask":"0.16"}, {"asset_id":"20436996072316278452977393149218961565084965483366669504673105646378938504388", "price":"0.85", "size":"37.33", "side":"SELL", "hash":"811e46dd0cf2d1671448070c72e7b021f593e6d6", "best_bid":"0.84", "best_ask":"0.85"}], "timestamp":"1778784200846", "event_type":"price_change"}
{"market":"0x2a903c589141bce4a1e50fb98b73397af6820942542793ab10b1df477e912b6e", "price_changes":[{"asset_id":"68919878716222388542639225642064847629616106443780159680232863841946753372582", "price":"0.15", "size":"48.33", "side":"BUY", "hash":"252ea17fd17aa8b24e7cc8d122c7bc9f845ee16c", "best_bid":"0.15", "best_ask":"0.16"}, {"asset_id":"20436996072316278452977393149218961565084965483366669504673105646378938504388", "price":"0.85", "size":"48.33", "side":"SELL", "hash":"92bafba110223214f3d0365fc6ecd505ed80bce1", "best_bid":"0.84", "best_ask":"0.85"}], "timestamp":"1778784200847", "event_type":"price_change"}
{"market":"0x2a903c589141bce4a1e50fb98b73397af6820942542793ab10b1df477e912b6e", "price_changes":[{"asset_id":"68919878716222388542639225642064847629616106443780159680232863841946753372582", "price":"0.12", "size":"360.64", "side":"BUY", "hash":"53bda33e420ce1c59f6d3ed37ee1aa9ee7710d99", "best_bid":"0.15", "best_ask":"0.16"}, {"asset_id":"20436996072316278452977393149218961565084965483366669504673105646378938504388", "price":"0.88", "size":"360.64", "side":"SELL", "hash":"7c1b2309b85299be2812e13847bbc323617e689d", "best_bid":"0.84", "best_ask":"0.85"}], "timestamp":"1778784200848", "event_type":"price_change"}
{"market":"0x2a903c589141bce4a1e50fb98b73397af6820942542793ab10b1df477e912b6e", "price_changes":[{"asset_id":"68919878716222388542639225642064847629616106443780159680232863841946753372582", "price":"0.12", "size":"422.64", "side":"BUY", "hash":"d9637a5494e6411be968a9f242aa75230e964a07", "best_bid":"0.15", "best_ask":"0.16"}, {"asset_id":"20436996072316278452977393149218961565084965483366669504673105646378938504388", "price":"0.88", "size":"422.64", "side":"SELL", "hash":"4592f571283ed8ba2add0af2cb9c6fe43fc89347", "best_bid":"0.84", "best_ask":"0.85"}], "timestamp":"1778784200849", "event_type":"price_change"}
{"market":"0x2a903c589141bce4a1e50fb98b73397af6820942542793ab10b1df477e912b6e", "price_changes":[{"asset_id":"68919878716222388542639225642064847629616106443780159680232863841946753372582", "price":"0.15", "size":"58.33", "side":"BUY", "hash":"7ecdad91ce0e6f9b33be935397567c5c93401176", "best_bid":"0.15", "best_ask":"0.16"}, {"asset_id":"20436996072316278452977393149218961565084965483366669504673105646378938504388", "price":"0.85", "size":"58.33", "side":"SELL", "hash":"db0b46826ba3d6d7a96afab9fc0f84db0279c44a", "best_bid":"0.84", "best_ask":"0.85"}], "timestamp":"1778784200850", "event_type":"price_change"}
{"market":"0x2a903c589141bce4a1e50fb98b73397af6820942542793ab10b1df477e912b6e", "price_changes":[{"asset_id":"68919878716222388542639225642064847629616106443780159680232863841946753372582", "price":"0.12", "size":"431.64", "side":"BUY", "hash":"b8379934e9ffd5fa7af824d0d2fcb8be4c399132", "best_bid":"0.15", "best_ask":"0.16"}, {"asset_id":"20436996072316278452977393149218961565084965483366669504673105646378938504388", "price":"0.88", "size":"431.64", "side":"SELL", "hash":"4bc379e61e245137b827fca7e081949575485864", "best_bid":"0.84", "best_ask":"0.85"}], "timestamp":"1778784200851", "event_type":"price_change"}
{"market":"0x2a903c589141bce4a1e50fb98b73397af6820942542793ab10b1df477e912b6e", "price_changes":[{"asset_id":"20436996072316278452977393149218961565084965483366669504673105646378938504388", "price":"0.84", "size":"43.5", "side":"BUY", "hash":"d4b3cc64778693f63fe5f93473f5e5bad5bce5bc", "best_bid":"0.84", "best_ask":"0.85"}, {"asset_id":"68919878716222388542639225642064847629616106443780159680232863841946753372582", "price":"0.16", "size":"43.5", "side":"SELL", "hash":"823f4d8a8334c0275ddc54a5f3536ebac87072a3", "best_bid":"0.15", "best_ask":"0.16"}], "timestamp":"1778784200852", "event_type":"price_change"}
{"market":"0x2a903c589141bce4a1e50fb98b73397af6820942542793ab10b1df477e912b6e", "price_changes":[{"asset_id":"20436996072316278452977393149218961565084965483366669504673105646378938504388", "price":"0.81", "size":"107.35", "side":"BUY", "hash":"ff7c832d1d503658d6e443127fd83a8975e22279", "best_bid":"0.84", "best_ask":"0.85"}, {"asset_id":"68919878716222388542639225642064847629616106443780159680232863841946753372582", "price":"0.19", "size":"107.35", "side":"SELL", "hash":"6206676816c16fe562745553567603f8029a7bc6", "best_bid":"0.15", "best_ask":"0.16"}], "timestamp":"1778784200855", "event_type":"price_change"}
{"market":"0x2a903c589141bce4a1e50fb98b73397af6820942542793ab10b1df477e912b6e", "price_changes":[{"asset_id":"68919878716222388542639225642064847629616106443780159680232863841946753372582", "price":"0.15", "size":"65.06", "side":"BUY", "hash":"6dd4ad82216905b17bb242ce154b88756e420c2e", "best_bid":"0.15", "best_ask":"0.16"}, {"asset_id":"20436996072316278452977393149218961565084965483366669504673105646378938504388", "price":"0.85", "size":"65.06", "side":"SELL", "hash":"66ae55e805359eeae0d9b72593f43c973f1af668", "best_bid":"0.84", "best_ask":"0.85"}], "timestamp":"1778784200858", "event_type":"price_change"}
{"market":"0x2a903c589141bce4a1e50fb98b73397af6820942542793ab10b1df477e912b6e", "price_changes":[{"asset_id":"68919878716222388542639225642064847629616106443780159680232863841946753372582", "price":"0.15", "size":"75.06", "side":"BUY", "hash":"155f4a032a0750dbe7dcb195945d84f76eb7f12f", "best_bid":"0.15", "best_ask":"0.16"}, {"asset_id":"20436996072316278452977393149218961565084965483366669504673105646378938504388", "price":"0.85", "size":"75.06", "side":"SELL", "hash":"cea1bab60f771cd75e671160728b8f84ede00b9c", "best_bid":"0.84", "best_ask":"0.85"}], "timestamp":"1778784200859", "event_type":"price_change"}
{"market":"0x2a903c589141bce4a1e50fb98b73397af6820942542793ab10b1df477e912b6e", "price_changes":[{"asset_id":"68919878716222388542639225642064847629616106443780159680232863841946753372582", "price":"0.15", "size":"94.06", "side":"BUY", "hash":"c059b95f217b40229e18465baf22b3c389ee99b0", "best_bid":"0.15", "best_ask":"0.16"}, {"asset_id":"20436996072316278452977393149218961565084965483366669504673105646378938504388", "price":"0.85", "size":"94.06", "side":"SELL", "hash":"e1dd233ab8b27a910de36073e5f042da1feee7ae", "best_bid":"0.84", "best_ask":"0.85"}], "timestamp":"1778784200861", "event_type":"price_change"}
{"market":"0x2a903c589141bce4a1e50fb98b73397af6820942542793ab10b1df477e912b6e", "price_changes":[{"asset_id":"68919878716222388542639225642064847629616106443780159680232863841946753372582", "price":"0.12", "size":"461.64", "side":"BUY", "hash":"b0f29d58a7b3638454f19ce03f8f92a8b03d4a85", "best_bid":"0.15", "best_ask":"0.16"}, {"asset_id":"20436996072316278452977393149218961565084965483366669504673105646378938504388", "price":"0.88", "size":"461.64", "side":"SELL", "hash":"e2a24d9ae5af9c2ca4f613dd0266778bf3d4096f", "best_bid":"0.84", "best_ask":"0.85"}], "timestamp":"1778784200862", "event_type":"price_change"}
{"market":"0x2a903c589141bce4a1e50fb98b73397af6820942542793ab10b1df477e912b6e", "price_changes":[{"asset_id":"20436996072316278452977393149218961565084965483366669504673105646378938504388", "price":"0.79", "size":"275.44", "side":"BUY", "hash":"9a26a8b9098e36fef0621e382f04801fde406e10", "best_bid":"0.84", "best_ask":"0.85"}, {"asset_id":"68919878716222388542639225642064847629616106443780159680232863841946753372582", "price":"0.21", "size":"275.44", "side":"SELL", "hash":"d2f38459707823a801fca6954059f2b4aed410cb", "best_bid":"0.15", "best_ask":"0.16"}], "timestamp":"1778784200862", "event_type":"price_change"}
{"market":"0x2a903c589141bce4a1e50fb98b73397af6820942542793ab10b1df477e912b6e", "price_changes":[{"asset_id":"68919878716222388542639225642064847629616106443780159680232863841946753372582", "price":"0.11", "size":"439.62", "side":"BUY", "hash":"a91bc0b21343546c53c2d8689545dfa01abdb3db", "best_bid":"0.15", "best_ask":"0.16"}, {"asset_id":"20436996072316278452977393149218961565084965483366669504673105646378938504388", "price":"0.89", "size":"439.62", "side":"SELL", "hash":"3cff98d4e51712a339e3cb017bf79180c73e7633", "best_bid":"0.84", "best_ask":"0.85"}], "timestamp":"1778784200864", "event_type":"price_change"}
{"market":"0x2a903c589141bce4a1e50fb98b73397af6820942542793ab10b1df477e912b6e", "price_changes":[{"asset_id":"68919878716222388542639225642064847629616106443780159680232863841946753372582", "price":"0.11", "size":"426.62", "side":"BUY", "hash":"24199c589778c65658e618bc410b32e311f6f046", "best_bid":"0.15", "best_ask":"0.16"}, {"asset_id":"20436996072316278452977393149218961565084965483366669504673105646378938504388", "price":"0.89", "size":"426.62", "side":"SELL", "hash":"bc078c6e32c6ad11700057775f3db719c0269f35", "best_bid":"0.84", "best_ask":"0.85"}], "timestamp":"1778784200865", "event_type":"price_change"}
{"market":"0x2a903c589141bce4a1e50fb98b73397af6820942542793ab10b1df477e912b6e", "price_changes":[{"asset_id":"68919878716222388542639225642064847629616106443780159680232863841946753372582", "price":"0.12", "size":"481.64", "side":"BUY", "hash":"0f690789e055c5ee67d7a214755c83723ed924aa", "best_bid":"0.15", "best_ask":"0.16"}, {"asset_id":"20436996072316278452977393149218961565084965483366669504673105646378938504388", "price":"0.88", "size":"481.64", "side":"SELL", "hash":"f0a0ce383b5fbd6422d2926c5d93c3e995002e69", "best_bid":"0.84", "best_ask":"0.85"}], "timestamp":"1778784200866", "event_type":"price_change"}
{"market":"0x2a903c589141bce4a1e50fb98b73397af6820942542793ab10b1df477e912b6e", "price_changes":[{"asset_id":"20436996072316278452977393149218961565084965483366669504673105646378938504388", "price":"0.81", "size":"102.35", "side":"BUY", "hash":"7da689dae24c2aa2d102aa58cc47316f261801e5", "best_bid":"0.84", "best_ask":"0.85"}, {"asset_id":"68919878716222388542639225642064847629616106443780159680232863841946753372582", "price":"0.19", "size":"102.35", "side":"SELL", "hash":"a892f54ae44323ecd059ffaf0fb4c212c1672315", "best_bid":"0.15", "best_ask":"0.16"}], "timestamp":"1778784200867", "event_type":"price_change"}
{"market":"0x2a903c589141bce4a1e50fb98b73397af6820942542793ab10b1df477e912b6e", "price_changes":[{"asset_id":"20436996072316278452977393149218961565084965483366669504673105646378938504388", "price":"0.73", "size":"465.2", "side":"BUY", "hash":"90f13f6d75163bf490d3b03602f47eadd370d31b", "best_bid":"0.84", "best_ask":"0.85"}, {"asset_id":"68919878716222388542639225642064847629616106443780159680232863841946753372582", "price":"0.27", "size":"465.2", "side":"SELL", "hash":"54bf855ff3aeb7c0551208549e0261a3e410e71b", "best_bid":"0.15", "best_ask":"0.16"}], "timestamp":"1778784200868", "event_type":"price_change"}
{"market":"0x2a903c589141bce4a1e50fb98b73397af6820942542793ab10b1df477e912b6e", "price_changes":[{"asset_id":"20436996072316278452977393149218961565084965483366669504673105646378938504388", "price":"0.72", "size":"134.9", "side":"BUY", "hash":"90f13f6d75163bf490d3b03602f47eadd370d31b", "best_bid":"0.84", "best_ask":"0.85"}, {"asset_id":"68919878716222388542639225642064847629616106443780159680232863841946753372582", "price":"0.28", "size":"134.9", "side":"SELL", "hash":"54bf855ff3aeb7c0551208549e0261a3e410e71b", "best_bid":"0.15", "best_ask":"0.16"}], "timestamp":"1778784200868", "event_type":"price_change"}
{"market":"0x2a903c589141bce4a1e50fb98b73397af6820942542793ab10b1df477e912b6e", "price_changes":[{"asset_id":"68919878716222388542639225642064847629616106443780159680232863841946753372582", "price":"0.12", "size":"486.64", "side":"BUY", "hash":"21da6999ec145f7f572c0e12183714f56d34d2c6", "best_bid":"0.15", "best_ask":"0.16"}, {"asset_id":"20436996072316278452977393149218961565084965483366669504673105646378938504388", "price":"0.88", "size":"486.64", "side":"SELL", "hash":"03ad3ed8c3d66086d03420481385c306a150a1f7", "best_bid":"0.84", "best_ask":"0.85"}], "timestamp":"1778784200870", "event_type":"price_change"}
{"market":"0x2a903c589141bce4a1e50fb98b73397af6820942542793ab10b1df477e912b6e", "price_changes":[{"asset_id":"68919878716222388542639225642064847629616106443780159680232863841946753372582", "price":"0.13", "size":"145", "side":"BUY", "hash":"4487393660690f846a8c2bdca8ba58deed09cf59", "best_bid":"0.15", "best_ask":"0.16"}, {"asset_id":"20436996072316278452977393149218961565084965483366669504673105646378938504388", "price":"0.87", "size":"145", "side":"SELL", "hash":"6c1b8f60ea19ed91eb1ee1329d162eb8ee3ecaef", "best_bid":"0.84", "best_ask":"0.85"}], "timestamp":"1778784200871", "event_type":"price_change"}
{"market":"0x2a903c589141bce4a1e50fb98b73397af6820942542793ab10b1df477e912b6e", "price_changes":[{"asset_id":"20436996072316278452977393149218961565084965483366669504673105646378938504388", "price":"0.74", "size":"250.6", "side":"BUY", "hash":"e2024545d59bc59c86cf97059457df1ee96253a8", "best_bid":"0.84", "best_ask":"0.85"}, {"asset_id":"68919878716222388542639225642064847629616106443780159680232863841946753372582", "price":"0.26", "size":"250.6", "side":"SELL", "hash":"61ba988710d2c6623dcaf8561dea1b700a323de1", "best_bid":"0.15", "best_ask":"0.16"}], "timestamp":"1778784200872", "event_type":"price_change"}
{"market":"0x2a903c589141bce4a1e50fb98b73397af6820942542793ab10b1df477e912b6e", "price_changes":[{"asset_id":"68919878716222388542639225642064847629616106443780159680232863841946753372582", "price":"0.14", "size":"234.88", "side":"BUY", "hash":"f59199b6d36f331ee548da619da65c343e98d463", "best_bid":"0.15", "best_ask":"0.16"}, {"asset_id":"20436996072316278452977393149218961565084965483366669504673105646378938504388", "price":"0.86", "size":"234.88", "side":"SELL", "hash":"3a861c20982ee8cdb4d1edde850822c40684c080", "best_bid":"0.84", "best_ask":"0.85"}], "timestamp":"1778784200874", "event_type":"price_change"}
{"market":"0x2a903c589141bce4a1e50fb98b73397af6820942542793ab10b1df477e912b6e", "price_changes":[{"asset_id":"68919878716222388542639225642064847629616106443780159680232863841946753372582", "price":"0.05", "size":"835.73", "side":"BUY", "hash":"c209ea1962497fbc5f0bf3bb2582a2ac5de69743", "best_bid":"0.15", "best_ask":"0.16"}, {"asset_id":"20436996072316278452977393149218961565084965483366669504673105646378938504388", "price":"0.95", "size":"835.73", "side":"SELL", "hash":"63b2f8a3a54a173520abb35c094e8e84384d46e8", "best_bid":"0.84", "best_ask":"0.85"}], "timestamp":"1778784200875", "event_type":"price_change"}
{"market":"0x2a903c589141bce4a1e50fb98b73397af6820942542793ab10b1df477e912b6e", "price_changes":[{"asset_id":"20436996072316278452977393149218961565084965483366669504673105646378938504388", "price":"0.84", "size":"52.5", "side":"BUY", "hash":"81337618e915a3d389db0bcb56ab166ad7843734", "best_bid":"0.84", "best_ask":"0.85"}, {"asset_id":"68919878716222388542639225642064847629616106443780159680232863841946753372582", "price":"0.16", "size":"52.5", "side":"SELL", "hash":"ca09fcbf555f60e71222b19fb32cc390faafe025", "best_bid":"0.15", "best_ask":"0.16"}], "timestamp":"1778784200878", "event_type":"price_change"}
{"market":"0x2a903c589141bce4a1e50fb98b73397af6820942542793ab10b1df477e912b6e", "price_changes":[{"asset_id":"68919878716222388542639225642064847629616106443780159680232863841946753372582", "price":"0.14", "size":"218.88", "side":"BUY", "hash":"5683c4bce50a933ccdbbe866a9deb95e0acdac75", "best_bid":"0.15", "best_ask":"0.16"}, {"asset_id":"20436996072316278452977393149218961565084965483366669504673105646378938504388", "price":"0.86", "size":"218.88", "side":"SELL", "hash":"f4d09dfb18816cdcc3a28db2496f6ec023b6698b", "best_bid":"0.84", "best_ask":"0.85"}], "timestamp":"1778784200880", "event_type":"price_change"}
{"market":"0x2a903c589141bce4a1e50fb98b73397af6820942542793ab10b1df477e912b6e", "price_changes":[{"asset_id":"20436996072316278452977393149218961565084965483366669504673105646378938504388", "price":"0.73", "size":"460.2", "side":"BUY", "hash":"6c35cff5ad94311d768edbb59c6a7cd129136fb7", "best_bid":"0.84", "best_ask":"0.85"}, {"asset_id":"68919878716222388542639225642064847629616106443780159680232863841946753372582", "price":"0.27", "size":"460.2", "side":"SELL", "hash":"d7edab755b058b6c5a6b0ee4770e0f631634f805", "best_bid":"0.15", "best_ask":"0.16"}], "timestamp":"1778784200881", "event_type":"price_change"}
{"market":"0x2a903c589141bce4a1e50fb98b73397af6820942542793ab10b1df477e912b6e", "price_changes":[{"asset_id":"20436996072316278452977393149218961565084965483366669504673105646378938504388", "price":"0.85", "size":"134.06", "side":"SELL", "hash":"d0ed9d33c4bcc4a3cb88aba57f308066583affbf", "best_bid":"0.84", "best_ask":"0.85"}, {"asset_id":"68919878716222388542639225642064847629616106443780159680232863841946753372582", "price":"0.15", "size":"134.06", "side":"BUY", "hash":"409eee697713a7f10c7f57addaa357bc9866d039", "best_bid":"0.15", "best_ask":"0.16"}], "timestamp":"1778784200883", "event_type":"price_change"}
{"market":"0x2a903c589141bce4a1e50fb98b73397af6820942542793ab10b1df477e912b6e", "price_changes":[{"asset_id":"20436996072316278452977393149218961565084965483366669504673105646378938504388", "price":"0.84", "size":"61.5", "side":"BUY", "hash":"25a3fd0ac4c54ca46c3fb407ecf67cf989f77220", "best_bid":"0.84", "best_ask":"0.85"}, {"asset_id":"68919878716222388542639225642064847629616106443780159680232863841946753372582", "price":"0.16", "size":"61.5", "side":"SELL", "hash":"b265f8252a17de93a28b8d9fd4dd15583585c2da", "best_bid":"0.15", "best_ask":"0.16"}], "timestamp":"1778784200884", "event_type":"price_change"}
{"market":"0x2a903c589141bce4a1e50fb98b73397af6820942542793ab10b1df477e912b6e", "price_changes":[{"asset_id":"20436996072316278452977393149218961565084965483366669504673105646378938504388", "price":"0.84", "size":"51.5", "side":"BUY", "hash":"420f0ede3a8b7aa6c940241799692de2a8ccb95f", "best_bid":"0.84", "best_ask":"0.85"}, {"asset_id":"68919878716222388542639225642064847629616106443780159680232863841946753372582", "price":"0.16", "size":"51.5", "side":"SELL", "hash":"80bbd1cb31b026745118a5579e41153d0647f69a", "best_bid":"0.15", "best_ask":"0.16"}], "timestamp":"1778784200893", "event_type":"price_change"}
{"market":"0x2a903c589141bce4a1e50fb98b73397af6820942542793ab10b1df477e912b6e", "price_changes":[{"asset_id":"68919878716222388542639225642064847629616106443780159680232863841946753372582", "price":"0.16", "size":"51.5", "side":"SELL", "hash":"80bbd1cb31b026745118a5579e41153d0647f69a", "best_bid":"0.15", "best_ask":"0.16"}, {"asset_id":"20436996072316278452977393149218961565084965483366669504673105646378938504388", "price":"0.84", "size":"51.5", "side":"BUY", "hash":"420f0ede3a8b7aa6c940241799692de2a8ccb95f", "best_bid":"0.84", "best_ask":"0.85"}], "timestamp":"1778784200893", "event_type":"price_change"}
{"market":"0x2a903c589141bce4a1e50fb98b73397af6820942542793ab10b1df477e912b6e", "asset_id":"68919878716222388542639225642064847629616106443780159680232863841946753372582", "bids":[{"price":"0.01", "size":"11333.83"}, {"price":"0.02", "size":"1397.82"}, {"price":"0.03", "size":"1100.78"}, {"price":"0.04", "size":"1237.82"}, {"price":"0.05", "size":"835.73"}, {"price":"0.06", "size":"297.2"}, {"price":"0.07", "size":"347.1"}, {"price":"0.08", "size":"704.12"}, {"price":"0.09", "size":"357.1"}, {"price":"0.1", "size":"507"}, {"price":"0.11", "size":"426.62"}, {"price":"0.12", "size":"486.64"}, {"price":"0.13", "size":"145"}, {"price":"0.14", "size":"218.88"}, {"price":"0.15", "size":"134.06"}], "asks":[{"price":"0.99", "size":"11995.61"}, {"price":"0.98", "size":"1219.45"}, {"price":"0.97", "size":"1096.98"}, {"price":"0.96", "size":"670.05"}, {"price":"0.95", "size":"549.45"}, {"price":"0.94", "size":"346.2"}, {"price":"0.93", "size":"902.05"}, {"price":"0.92", "size":"170.79"}, {"price":"0.91", "size":"234.6"}, {"price":"0.9", "size":"128"}, {"price":"0.89", "size":"142.6"}, {"price":"0.88", "size":"141.8"}, {"price":"0.87", "size":"144.81"}, {"price":"0.86", "size":"204.9"}, {"price":"0.85", "size":"113.5"}, {"price":"0.84", "size":"102.3"}, {"price":"0.83", "size":"101.3"}, {"price":"0.82", "size":"105.3"}, {"price":"0.81", "size":"199.5"}, {"price":"0.8", "size":"103.8"}, {"price":"0.79", "size":"98.1"}, {"price":"0.78", "size":"97.5"}, {"price":"0.77", "size":"96.89"}, {"price":"0.76", "size":"201.39"}, {"price":"0.75", "size":"116"}, {"price":"0.74", "size":"100.6"}, {"price":"0.73", "size":"95.2"}, {"price":"0.72", "size":"94.9"}, {"price":"0.71", "size":"199.6"}, {"price":"0.7", "size":"94.3"}, {"price":"0.69", "size":"108.28"}, {"price":"0.68", "size":"98.8"}, {"price":"0.67", "size":"118.6"}, {"price":"0.66", "size":"398.4"}, {"price":"0.65", "size":"507.3"}, {"price":"0.64", "size":"893"}, {"price":"0.63", "size":"892.9"}, {"price":"0.62", "size":"297.7"}, {"price":"0.61", "size":"397.6"}, {"price":"0.6", "size":"356.93"}, {"price":"0.59", "size":"297.4"}, {"price":"0.58", "size":"109.6"}, {"price":"0.57", "size":"131.48"}, {"price":"0.56", "size":"413.97"}, {"price":"0.55", "size":"334.2"}, {"price":"0.54", "size":"375.6"}, {"price":"0.53", "size":"292"}, {"price":"0.52", "size":"297.12"}, {"price":"0.51", "size":"402"}, {"price":"0.5", "size":"340.91"}, {"price":"0.49", "size":"798"}, {"price":"0.48", "size":"317"}, {"price":"0.47", "size":"337"}, {"price":"0.46", "size":"451.54"}, {"price":"0.45", "size":"346.64"}, {"price":"0.44", "size":"341.45"}, {"price":"0.43", "size":"444.89"}, {"price":"0.42", "size":"724.36"}, {"price":"0.41", "size":"412.4"}, {"price":"0.4", "size":"328.83"}, {"price":"0.39", "size":"297.6"}, {"price":"0.38", "size":"318.44"}, {"price":"0.37", "size":"576.9"}, {"price":"0.36", "size":"203"}, {"price":"0.35", "size":"340.14"}, {"price":"0.34", "size":"350.9"}, {"price":"0.33", "size":"363.6"}, {"price":"0.32", "size":"2065.88"}, {"price":"0.31", "size":"559"}, {"price":"0.3", "size":"234.3"}, {"price":"0.29", "size":"616.38"}, {"price":"0.28", "size":"134.9"}, {"price":"0.27", "size":"460.2"}, {"price":"0.26", "size":"250.6"}, {"price":"0.25", "size":"496"}, {"price":"0.24", "size":"211.39"}, {"price":"0.23", "size":"246.89"}, {"price":"0.22", "size":"349.5"}, {"price":"0.21", "size":"275.44"}, {"price":"0.2", "size":"148.8"}, {"price":"0.19", "size":"102.35"}, {"price":"0.18", "size":"393.05"}, {"price":"0.17", "size":"33.97"}, {"price":"0.16", "size":"51.5"}], "hash":"80bbd1cb31b026745118a5579e41153d0647f69a", "timestamp":"1778784200893", "event_type":"book"}
{"market":"0x2a903c589141bce4a1e50fb98b73397af6820942542793ab10b1df477e912b6e", "price_changes":[{"asset_id":"20436996072316278452977393149218961565084965483366669504673105646378938504388", "price":"0.92", "size":"694.53", "side":"SELL", "hash":"fd8361b17b5ba7cd77c462e827b8abc5f7eb74b8", "best_bid":"0.84", "best_ask":"0.85"}, {"asset_id":"68919878716222388542639225642064847629616106443780159680232863841946753372582", "price":"0.08", "size":"694.53", "side":"BUY", "hash":"e409871c14d0062f51256ac29c848cdbe4aab5cb", "best_bid":"0.15", "best_ask":"0.16"}], "timestamp":"1778784200894", "event_type":"price_change"}
{"market":"0x2a903c589141bce4a1e50fb98b73397af6820942542793ab10b1df477e912b6e", "price_changes":[{"asset_id":"20436996072316278452977393149218961565084965483366669504673105646378938504388", "price":"0.84", "size":"66.5", "side":"BUY", "hash":"2acbc1e486870a1e2fe94c683a4f2ce24d84613f", "best_bid":"0.84", "best_ask":"0.85"}, {"asset_id":"68919878716222388542639225642064847629616106443780159680232863841946753372582", "price":"0.16", "size":"66.5", "side":"SELL", "hash":"a0179ed6c219db6bbc1b4538496493cecdef9ded", "best_bid":"0.15", "best_ask":"0.16"}], "timestamp":"1778784200895", "event_type":"price_change"}
{"market":"0x2a903c589141bce4a1e50fb98b73397af6820942542793ab10b1df477e912b6e", "price_changes":[{"asset_id":"68919878716222388542639225642064847629616106443780159680232863841946753372582", "price":"0.14", "size":"178.88", "side":"BUY", "hash":"0754840166759b40e5bce3c0a585f294c0c9f11a", "best_bid":"0.15", "best_ask":"0.16"}, {"asset_id":"20436996072316278452977393149218961565084965483366669504673105646378938504388", "price":"0.86", "size":"178.88", "side":"SELL", "hash":"6a0ac0e285ca319c3e752b0ab3c6428d1a435fce", "best_bid":"0.84", "best_ask":"0.85"}], "timestamp":"1778784200896", "event_type":"price_change"}
{"market":"0x2a903c589141bce4a1e50fb98b73397af6820942542793ab10b1df477e912b6e", "price_changes":[{"asset_id":"20436996072316278452977393149218961565084965483366669504673105646378938504388", "price":"0.87", "size":"105", "side":"SELL", "hash":"87b3aafe04dbceb9c8ba25403e62060e0ebdb102", "best_bid":"0.84", "best_ask":"0.85"}, {"asset_id":"68919878716222388542639225642064847629616106443780159680232863841946753372582", "price":"0.13", "size":"105", "side":"BUY", "hash":"6b02a4cd0b863d12124f1e86cdd1bc94123e3ab0", "best_bid":"0.15", "best_ask":"0.16"}], "timestamp":"1778784200897", "event_type":"price_change"}
{"market":"0x2a903c589141bce4a1e50fb98b73397af6820942542793ab10b1df477e912b6e", "price_changes":[{"asset_id":"68919878716222388542639225642064847629616106443780159680232863841946753372582", "price":"0.15", "size":"125.96", "side":"BUY", "hash":"22549cac70aa999d8ff81b7315ab54b264d2dc2f", "best_bid":"0.15", "best_ask":"0.16"}, {"asset_id":"20436996072316278452977393149218961565084965483366669504673105646378938504388", "price":"0.85", "size":"125.96", "side":"SELL", "hash":"d8409c7cd830beb60dae660fac4e01830cfb168d", "best_bid":"0.84", "best_ask":"0.85"}], "timestamp":"1778784200899", "event_type":"price_change"}
{"market":"0x2a903c589141bce4a1e50fb98b73397af6820942542793ab10b1df477e912b6e", "asset_id":"68919878716222388542639225642064847629616106443780159680232863841946753372582", "bids":[{"price":"0.01", "size":"11333.83"}, {"price":"0.02", "size":"1397.82"}, {"price":"0.03", "size":"1100.78"}, {"price":"0.04", "size":"1237.82"}, {"price":"0.05", "size":"835.73"}, {"price":"0.06", "size":"297.2"}, {"price":"0.07", "size":"347.1"}, {"price":"0.08", "size":"694.53"}, {"price":"0.09", "size":"357.1"}, {"price":"0.1", "size":"507"}, {"price":"0.11", "size":"426.62"}, {"price":"0.12", "size":"486.64"}, {"price":"0.13", "size":"105"}, {"price":"0.14", "size":"178.88"}, {"price":"0.15", "size":"125.96"}], "asks":[{"price":"0.99", "size":"11995.61"}, {"price":"0.98", "size":"1219.45"}, {"price":"0.97", "size":"1096.98"}, {"price":"0.96", "size":"670.05"}, {"price":"0.95", "size":"549.45"}, {"price":"0.94", "size":"346.2"}, {"price":"0.93", "size":"902.05"}, {"price":"0.92", "size":"170.79"}, {"price":"0.91", "size":"234.6"}, {"price":"0.9", "size":"128"}, {"price":"0.89", "size":"142.6"}, {"price":"0.88", "size":"141.8"}, {"price":"0.87", "size":"144.81"}, {"price":"0.86", "size":"204.9"}, {"price":"0.85", "size":"113.5"}, {"price":"0.84", "size":"102.3"}, {"price":"0.83", "size":"101.3"}, {"price":"0.82", "size":"105.3"}, {"price":"0.81", "size":"199.5"}, {"price":"0.8", "size":"103.8"}, {"price":"0.79", "size":"98.1"}, {"price":"0.78", "size":"97.5"}, {"price":"0.77", "size":"96.89"}, {"price":"0.76", "size":"201.39"}, {"price":"0.75", "size":"116"}, {"price":"0.74", "size":"100.6"}, {"price":"0.73", "size":"95.2"}, {"price":"0.72", "size":"94.9"}, {"price":"0.71", "size":"199.6"}, {"price":"0.7", "size":"94.3"}, {"price":"0.69", "size":"108.28"}, {"price":"0.68", "size":"98.8"}, {"price":"0.67", "size":"118.6"}, {"price":"0.66", "size":"398.4"}, {"price":"0.65", "size":"507.3"}, {"price":"0.64", "size":"893"}, {"price":"0.63", "size":"892.9"}, {"price":"0.62", "size":"297.7"}, {"price":"0.61", "size":"397.6"}, {"price":"0.6", "size":"356.93"}, {"price":"0.59", "size":"297.4"}, {"price":"0.58", "size":"109.6"}, {"price":"0.57", "size":"131.48"}, {"price":"0.56", "size":"413.97"}, {"price":"0.55", "size":"334.2"}, {"price":"0.54", "size":"375.6"}, {"price":"0.53", "size":"292"}, {"price":"0.52", "size":"297.12"}, {"price":"0.51", "size":"402"}, {"price":"0.5", "size":"340.91"}, {"price":"0.49", "size":"798"}, {"price":"0.48", "size":"317"}, {"price":"0.47", "size":"337"}, {"price":"0.46", "size":"451.54"}, {"price":"0.45", "size":"346.64"}, {"price":"0.44", "size":"341.45"}, {"price":"0.43", "size":"444.89"}, {"price":"0.42", "size":"724.36"}, {"price":"0.41", "size":"412.4"}, {"price":"0.4", "size":"328.83"}, {"price":"0.39", "size":"297.6"}, {"price":"0.38", "size":"318.44"}, {"price":"0.37", "size":"576.9"}, {"price":"0.36", "size":"203"}, {"price":"0.35", "size":"340.14"}, {"price":"0.34", "size":"350.9"}, {"price":"0.33", "size":"363.6"}, {"price":"0.32", "size":"2065.88"}, {"price":"0.31", "size":"559"}, {"price":"0.3", "size":"234.3"}, {"price":"0.29", "size":"616.38"}, {"price":"0.28", "size":"134.9"}, {"price":"0.27", "size":"460.2"}, {"price":"0.26", "size":"250.6"}, {"price":"0.25", "size":"496"}, {"price":"0.24", "size":"211.39"}, {"price":"0.23", "size":"246.89"}, {"price":"0.22", "size":"349.5"}, {"price":"0.21", "size":"275.44"}, {"price":"0.2", "size":"148.8"}, {"price":"0.19", "size":"102.35"}, {"price":"0.18", "size":"393.05"}, {"price":"0.17", "size":"33.97"}, {"price":"0.16", "size":"66.5"}], "hash":"22549cac70aa999d8ff81b7315ab54b264d2dc2f", "timestamp":"1778784200899", "event_type":"book"}
{"market":"0x2a903c589141bce4a1e50fb98b73397af6820942542793ab10b1df477e912b6e", "price_changes":[{"asset_id":"20436996072316278452977393149218961565084965483366669504673105646378938504388", "price":"0.76", "size":"511.39", "side":"BUY", "hash":"d2253e8e81ceff3f33a3274365d390a7ce4f5904", "best_bid":"0.84", "best_ask":"0.85"}, {"asset_id":"68919878716222388542639225642064847629616106443780159680232863841946753372582", "price":"0.24", "size":"511.39", "side":"SELL", "hash":"83a065c2de4a838bc12531d4dec5053fed60d693", "best_bid":"0.15", "best_ask":"0.16"}], "timestamp":"1778784200901", "event_type":"price_change"}
{"market":"0x2a903c589141bce4a1e50fb98b73397af6820942542793ab10b1df477e912b6e", "price_changes":[{"asset_id":"68919878716222388542639225642064847629616106443780159680232863841946753372582", "price":"0.07", "size":"647.1", "side":"BUY", "hash":"7e7334d7c211ba2cd5b497c9a9f229a98cfbeade", "best_bid":"0.15", "best_ask":"0.16"}, {"asset_id":"20436996072316278452977393149218961565084965483366669504673105646378938504388", "price":"0.93", "size":"647.1", "side":"SELL", "hash":"c7da76e7b9161583e00671fb083e1b8bce9eba96", "best_bid":"0.84", "best_ask":"0.85"}], "timestamp":"1778784200903", "event_type":"price_change"}
{"market":"0x2a903c589141bce4a1e50fb98b73397af6820942542793ab10b1df477e912b6e", "price_changes":[{"asset_id":"20436996072316278452977393149218961565084965483366669504673105646378938504388", "price":"0.84", "size":"81.5", "side":"BUY", "hash":"244f915aa45b032da20b4c4f810c0ee69a68f1e8", "best_bid":"0.84", "best_ask":"0.85"}, {"asset_id":"68919878716222388542639225642064847629616106443780159680232863841946753372582", "price":"0.16", "size":"81.5", "side":"SELL", "hash":"d7b7932708a57c0581e744f5164b2969e9e27b08", "best_bid":"0.15", "best_ask":"0.16"}], "timestamp":"1778784200904", "event_type":"price_change"}
{"market":"0x2a903c589141bce4a1e50fb98b73397af6820942542793ab10b1df477e912b6e", "price_changes":[{"asset_id":"20436996072316278452977393149218961565084965483366669504673105646378938504388", "price":"0.75", "size":"526", "side":"BUY", "hash":"18ad583d3a3f5a09a72614f9dc4b9a33f541ee93", "best_bid":"0.84", "best_ask":"0.85"}, {"asset_id":"68919878716222388542639225642064847629616106443780159680232863841946753372582", "price":"0.25", "size":"526", "side":"SELL", "hash":"ea5dde57c3b53b5f37fdb4086d0c4927b0e36c8b", "best_bid":"0.15", "best_ask":"0.16"}], "timestamp":"1778784200905", "event_type":"price_change"}
{"market":"0x2a903c589141bce4a1e50fb98b73397af6820942542793ab10b1df477e912b6e", "price_changes":[{"asset_id":"68919878716222388542639225642064847629616106443780159680232863841946753372582", "price":"0.15", "size":"149.96", "side":"BUY", "hash":"a1079595518a943f85b9444905fdcd51bf4f2827", "best_bid":"0.15", "best_ask":"0.16"}, {"asset_id":"20436996072316278452977393149218961565084965483366669504673105646378938504388", "price":"0.85", "size":"149.96", "side":"SELL", "hash":"9bfe65c88c9983e92f771c2031e5fe512345d5b9", "best_bid":"0.84", "best_ask":"0.85"}], "timestamp":"1778784200907", "event_type":"price_change"}
{"market":"0x2a903c589141bce4a1e50fb98b73397af6820942542793ab10b1df477e912b6e", "price_changes":[{"asset_id":"20436996072316278452977393149218961565084965483366669504673105646378938504388", "price":"0.84", "size":"102.5", "side":"BUY", "hash":"ddd48733c1a6f2362b10214eb8e79f3228b3c8e3", "best_bid":"0.84", "best_ask":"0.85"}, {"asset_id":"68919878716222388542639225642064847629616106443780159680232863841946753372582", "price":"0.16", "size":"102.5", "side":"SELL", "hash":"3b5aa5a8be8d5248a93e0d828ba7fc8980173a0e", "best_bid":"0.15", "best_ask":"0.16"}], "timestamp":"1778784200908", "event_type":"price_change"}
{"market":"0x2a903c589141bce4a1e50fb98b73397af6820942542793ab10b1df477e912b6e", "price_changes":[{"asset_id":"20436996072316278452977393149218961565084965483366669504673105646378938504388", "price":"0.84", "size":"112.5", "side":"BUY", "hash":"0e0a9ccaac66274a5f77a66e548ba8b9b3f2540c", "best_bid":"0.84", "best_ask":"0.85"}, {"asset_id":"68919878716222388542639225642064847629616106443780159680232863841946753372582", "price":"0.16", "size":"112.5", "side":"SELL", "hash":"5fca7ef7da9c4ce6fd77a566f42b5047b4fa081f", "best_bid":"0.15", "best_ask":"0.16"}], "timestamp":"1778784200910", "event_type":"price_change"}
{"market":"0x2a903c589141bce4a1e50fb98b73397af6820942542793ab10b1df477e912b6e", "price_changes":[{"asset_id":"68919878716222388542639225642064847629616106443780159680232863841946753372582", "price":"0.01", "size":"11343.83", "side":"BUY", "hash":"53e091a72262e977e46af264eecd73a7b985b089", "best_bid":"0.15", "best_ask":"0.16"}, {"asset_id":"20436996072316278452977393149218961565084965483366669504673105646378938504388", "price":"0.99", "size":"11343.83", "side":"SELL", "hash":"7f721d256bb4d6defa8da00bdffbeea6a73fd7e1", "best_bid":"0.84", "best_ask":"0.85"}], "timestamp":"1778784200912", "event_type":"price_change"}
{"market":"0x2a903c589141bce4a1e50fb98b73397af6820942542793ab10b1df477e912b6e", "price_changes":[{"asset_id":"20436996072316278452977393149218961565084965483366669504673105646378938504388", "price":"0.82", "size":"319.82", "side":"BUY", "hash":"f12085f9eb735903cc68066205b53f2fcc1b4a7e", "best_bid":"0.84", "best_ask":"0.85"}, {"asset_id":"68919878716222388542639225642064847629616106443780159680232863841946753372582", "price":"0.18", "size":"319.82", "side":"SELL", "hash":"57367059b38f402e804fde24d248a4f86cf29f6b", "best_bid":"0.15", "best_ask":"0.16"}], "timestamp":"1778784200912", "event_type":"price_change"}
{"market":"0x2a903c589141bce4a1e50fb98b73397af6820942542793ab10b1df477e912b6e", "price_changes":[{"asset_id":"20436996072316278452977393149218961565084965483366669504673105646378938504388", "price":"0.65", "size":"330.14", "side":"BUY", "hash":"7372cd391f0ef222a9e870c6576404a469902621", "best_bid":"0.84", "best_ask":"0.85"}, {"asset_id":"68919878716222388542639225642064847629616106443780159680232863841946753372582", "price":"0.35", "size":"330.14", "side":"SELL", "hash":"165bb7a50408a85b8300243bd3f73a84cfa88dbd", "best_bid":"0.15", "best_ask":"0.16"}], "timestamp":"1778784200914", "event_type":"price_change"}
{"market":"0x2a903c589141bce4a1e50fb98b73397af6820942542793ab10b1df477e912b6e", "asset_id":"68919878716222388542639225642064847629616106443780159680232863841946753372582", "price":"0.16", "size":"10", "fee_rate_bps":"0", "side":"BUY", "timestamp":"1778784200913", "event_type":"last_trade_price", "transaction_hash":"0x0960fb12f13f231e17a91782159d086221a990fc7191ed3cb16c3594428cff62"}
{"market":"0x2a903c589141bce4a1e50fb98b73397af6820942542793ab10b1df477e912b6e", "price_changes":[{"asset_id":"20436996072316278452977393149218961565084965483366669504673105646378938504388", "price":"0.8", "size":"123.8", "side":"BUY", "hash":"7527011bce1240664adc6443266b54a28a86e1cb", "best_bid":"0.84", "best_ask":"0.85"}, {"asset_id":"68919878716222388542639225642064847629616106443780159680232863841946753372582", "price":"0.2", "size":"123.8", "side":"SELL", "hash":"a644b90b40b873dc0d9922eb0ac4cc51c84858b4", "best_bid":"0.15", "best_ask":"0.16"}], "timestamp":"1778784200915", "event_type":"price_change"}
{"market":"0x2a903c589141bce4a1e50fb98b73397af6820942542793ab10b1df477e912b6e", "price_changes":[{"asset_id":"68919878716222388542639225642064847629616106443780159680232863841946753372582", "price":"0.01", "size":"11338.83", "side":"BUY", "hash":"e4a2b993d68cd178d5d0035811b5b7caca81412d", "best_bid":"0.15", "best_ask":"0.16"}, {"asset_id":"20436996072316278452977393149218961565084965483366669504673105646378938504388", "price":"0.99", "size":"11338.83", "side":"SELL", "hash":"4e3392a0c01451ddd99b1a7016d076c6a06ce6ef", "best_bid":"0.84", "best_ask":"0.85"}], "timestamp":"1778784200916", "event_type":"price_change"}
{"market":"0x2a903c589141bce4a1e50fb98b73397af6820942542793ab10b1df477e912b6e", "price_changes":[{"asset_id":"68919878716222388542639225642064847629616106443780159680232863841946753372582", "price":"0.14", "size":"155.88", "side":"BUY", "hash":"c4530eec16ba7460b5e96b6f1ed505e7de2efa71", "best_bid":"0.15", "best_ask":"0.16"}, {"asset_id":"20436996072316278452977393149218961565084965483366669504673105646378938504388", "price":"0.86", "size":"155.88", "side":"SELL", "hash":"a896344ff52aa0c61dbe3cd39b5447df53ebe7b5", "best_bid":"0.84", "best_ask":"0.85"}], "timestamp":"1778784200917", "event_type":"price_change"}
{"market":"0x2a903c589141bce4a1e50fb98b73397af6820942542793ab10b1df477e912b6e", "price_changes":[{"asset_id":"20436996072316278452977393149218961565084965483366669504673105646378938504388", "price":"0.57", "size":"434.89", "side":"BUY", "hash":"24fa8d2e86faf25b8ec759f295fda8ffd4f319dc", "best_bid":"0.84", "best_ask":"0.85"}, {"asset_id":"68919878716222388542639225642064847629616106443780159680232863841946753372582", "price":"0.43", "size":"434.89", "side":"SELL", "hash":"b7ef9236215c2623d4c0ec274bb7946abb6b8873", "best_bid":"0.15", "best_ask":"0.16"}], "timestamp":"1778784200918", "event_type":"price_change"}
{"market":"0x2a903c589141bce4a1e50fb98b73397af6820942542793ab10b1df477e912b6e", "price_changes":[{"asset_id":"68919878716222388542639225642064847629616106443780159680232863841946753372582", "price":"0.01", "size":"11343.83", "side":"BUY", "hash":"b84128772b79d3c85b13ed0256eea6e7dfe83c20", "best_bid":"0.15", "best_ask":"0.16"}, {"asset_id":"20436996072316278452977393149218961565084965483366669504673105646378938504388", "price":"0.99", "size":"11343.83", "side":"SELL", "hash":"1e236a5fffb84617200ba255509c9b3b7a762965", "best_bid":"0.84", "best_ask":"0.85"}], "timestamp":"1778784200919", "event_type":"price_change"}
{"market":"0x2a903c589141bce4a1e50fb98b73397af6820942542793ab10b1df477e912b6e", "price_changes":[{"asset_id":"68919878716222388542639225642064847629616106443780159680232863841946753372582", "price":"0.14", "size":"182.57", "side":"BUY", "hash":"eae060d467994ecca9c31d49ea2365f53735fa79", "best_bid":"0.15", "best_ask":"0.16"}, {"asset_id":"20436996072316278452977393149218961565084965483366669504673105646378938504388", "price":"0.86", "size":"182.57", "side":"SELL", "hash":"b708b2715e88a5573d63cd378edbf12eae9177e1", "best_bid":"0.84", "best_ask":"0.85"}], "timestamp":"1778784200920", "event_type":"price_change"}
{"market":"0x2a903c589141bce4a1e50fb98b73397af6820942542793ab10b1df477e912b6e", "asset_id":"68919878716222388542639225642064847629616106443780159680232863841946753372582", "price":"0.15", "size":"8.1", "fee_rate_bps":"0", "side":"SELL", "timestamp":"1778784200919", "event_type":"last_trade_price", "transaction_hash":"0x299b38b14def61a37394bc4b936500a861817dcf21787261202f022e8ff644a0"}
{"market":"0x2a903c589141bce4a1e50fb98b73397af6820942542793ab10b1df477e912b6e", "price_changes":[{"asset_id":"20436996072316278452977393149218961565084965483366669504673105646378938504388", "price":"0.71", "size":"621.38", "side":"BUY", "hash":"c0846589662dd5747b64a0850bbe721e40e07fdf", "best_bid":"0.84", "best_ask":"0.85"}, {"asset_id":"68919878716222388542639225642064847629616106443780159680232863841946753372582", "price":"0.29", "size":"621.38", "side":"SELL", "hash":"9050d49886215ede196c8e85316e6be85ae546fc", "best_bid":"0.15", "best_ask":"0.16"}], "timestamp":"1778784200921", "event_type":"price_change"}
{"market":"0x2a903c589141bce4a1e50fb98b73397af6820942542793ab10b1df477e912b6e", "price_changes":[{"asset_id":"20436996072316278452977393149218961565084965483366669504673105646378938504388", "price":"0.84", "size":"117.5", "side":"BUY", "hash":"110ae5ddf795b97cf31c4cf34ee8aa004987f969", "best_bid":"0.84", "best_ask":"0.85"}, {"asset_id":"68919878716222388542639225642064847629616106443780159680232863841946753372582", "price":"0.16", "size":"117.5", "side":"SELL", "hash":"07fdb70ca77923c6da7322c1167d42d0e964edf1", "best_bid":"0.15", "best_ask":"0.16"}], "timestamp":"1778784200922", "event_type":"price_change"}
{"market":"0x2a903c589141bce4a1e50fb98b73397af6820942542793ab10b1df477e912b6e", "price_changes":[{"asset_id":"20436996072316278452977393149218961565084965483366669504673105646378938504388", "price":"0.75", "size":"496", "side":"BUY", "hash":"d83386533f878ffb93e328400f7b4c382ef34e7c", "best_bid":"0.84", "best_ask":"0.85"}, {"asset_id":"68919878716222388542639225642064847629616106443780159680232863841946753372582", "price":"0.25", "size":"496", "side":"SELL", "hash":"4b59d1adb90cc383fd68910930dcc9644a566795", "best_bid":"0.15", "best_ask":"0.16"}], "timestamp":"1778784200935", "event_type":"price_change"}
{"market":"0x2a903c589141bce4a1e50fb98b73397af6820942542793ab10b1df477e912b6e", "price_changes":[{"asset_id":"20436996072316278452977393149218961565084965483366669504673105646378938504388", "price":"0.84", "size":"137.5", "side":"BUY", "hash":"46692e67c4f6fd0e9f6724bc3c515e855a7d70d8", "best_bid":"0.84", "best_ask":"0.85"}, {"asset_id":"68919878716222388542639225642064847629616106443780159680232863841946753372582", "price":"0.16", "size":"137.5", "side":"SELL", "hash":"8cb9cf4ff62b9914465a1222c10bd1ac5f139b1b", "best_bid":"0.15", "best_ask":"0.16"}], "timestamp":"1778784200937", "event_type":"price_change"}
{"market":"0x2a903c589141bce4a1e50fb98b73397af6820942542793ab10b1df477e912b6e", "price_changes":[{"asset_id":"20436996072316278452977393149218961565084965483366669504673105646378938504388", "price":"0.83", "size":"33.97", "side":"BUY", "hash":"c00ca41722c90196708fbaf3fc0aba4d9f4979e7", "best_bid":"0.84", "best_ask":"0.85"}, {"asset_id":"68919878716222388542639225642064847629616106443780159680232863841946753372582", "price":"0.17", "size":"33.97", "side":"SELL", "hash":"8327d75c3e656bd17b2761a0b94e750d23b3d151", "best_bid":"0.15", "best_ask":"0.16"}], "timestamp":"1778784200939", "event_type":"price_change"}
{"market":"0x2a903c589141bce4a1e50fb98b73397af6820942542793ab10b1df477e912b6e", "price_changes":[{"asset_id":"20436996072316278452977393149218961565084965483366669504673105646378938504388", "price":"0.84", "size":"126.46", "side":"BUY", "hash":"0b924618d7b20b83f282865b536e4bf13d32ee65", "best_bid":"0.84", "best_ask":"0.85"}, {"asset_id":"68919878716222388542639225642064847629616106443780159680232863841946753372582", "price":"0.16", "size":"126.46", "side":"SELL", "hash":"2b1a026cfdd250bdd82871fad32e28888fc06abd", "best_bid":"0.15", "best_ask":"0.16"}], "timestamp":"1778784200943", "event_type":"price_change"}
{"market":"0x2a903c589141bce4a1e50fb98b73397af6820942542793ab10b1df477e912b6e", "asset_id":"68919878716222388542639225642064847629616106443780159680232863841946753372582", "bids":[{"price":"0.01", "size":"11343.83"}, {"price":"0.02", "size":"1397.82"}, {"price":"0.03", "size":"1100.78"}, {"price":"0.04", "size":"1237.82"}, {"price":"0.05", "size":"835.73"}, {"price":"0.06", "size":"297.2"}, {"price":"0.07", "size":"647.1"}, {"price":"0.08", "size":"694.53"}, {"price":"0.09", "size":"357.1"}, {"price":"0.1", "size":"507"}, {"price":"0.11", "size":"426.62"}, {"price":"0.12", "size":"486.64"}, {"price":"0.13", "size":"105"}, {"price":"0.14", "size":"182.57"}, {"price":"0.15", "size":"149.96"}], "asks":[{"price":"0.99", "size":"11995.61"}, {"price":"0.98", "size":"1219.45"}, {"price":"0.97", "size":"1096.98"}, {"price":"0.96", "size":"670.05"}, {"price":"0.95", "size":"549.45"}, {"price":"0.94", "size":"346.2"}, {"price":"0.93", "size":"902.05"}, {"price":"0.92", "size":"170.79"}, {"price":"0.91", "size":"234.6"}, {"price":"0.9", "size":"128"}, {"price":"0.89", "size":"142.6"}, {"price":"0.88", "size":"141.8"}, {"price":"0.87", "size":"144.81"}, {"price":"0.86", "size":"204.9"}, {"price":"0.85", "size":"113.5"}, {"price":"0.84", "size":"102.3"}, {"price":"0.83", "size":"101.3"}, {"price":"0.82", "size":"105.3"}, {"price":"0.81", "size":"199.5"}, {"price":"0.8", "size":"103.8"}, {"price":"0.79", "size":"98.1"}, {"price":"0.78", "size":"97.5"}, {"price":"0.77", "size":"96.89"}, {"price":"0.76", "size":"201.39"}, {"price":"0.75", "size":"116"}, {"price":"0.74", "size":"100.6"}, {"price":"0.73", "size":"95.2"}, {"price":"0.72", "size":"94.9"}, {"price":"0.71", "size":"199.6"}, {"price":"0.7", "size":"94.3"}, {"price":"0.69", "size":"108.28"}, {"price":"0.68", "size":"98.8"}, {"price":"0.67", "size":"118.6"}, {"price":"0.66", "size":"398.4"}, {"price":"0.65", "size":"507.3"}, {"price":"0.64", "size":"893"}, {"price":"0.63", "size":"892.9"}, {"price":"0.62", "size":"297.7"}, {"price":"0.61", "size":"397.6"}, {"price":"0.6", "size":"356.93"}, {"price":"0.59", "size":"297.4"}, {"price":"0.58", "size":"109.6"}, {"price":"0.57", "size":"131.48"}, {"price":"0.56", "size":"413.97"}, {"price":"0.55", "size":"334.2"}, {"price":"0.54", "size":"375.6"}, {"price":"0.53", "size":"292"}, {"price":"0.52", "size":"297.12"}, {"price":"0.51", "size":"402"}, {"price":"0.5", "size":"340.91"}, {"price":"0.49", "size":"798"}, {"price":"0.48", "size":"317"}, {"price":"0.47", "size":"337"}, {"price":"0.46", "size":"451.54"}, {"price":"0.45", "size":"346.64"}, {"price":"0.44", "size":"341.45"}, {"price":"0.43", "size":"434.89"}, {"price":"0.42", "size":"724.36"}, {"price":"0.41", "size":"412.4"}, {"price":"0.4", "size":"328.83"}, {"price":"0.39", "size":"297.6"}, {"price":"0.38", "size":"318.44"}, {"price":"0.37", "size":"576.9"}, {"price":"0.36", "size":"203"}, {"price":"0.35", "size":"330.14"}, {"price":"0.34", "size":"350.9"}, {"price":"0.33", "size":"363.6"}, {"price":"0.32", "size":"2065.88"}, {"price":"0.31", "size":"559"}, {"price":"0.3", "size":"234.3"}, {"price":"0.29", "size":"621.38"}, {"price":"0.28", "size":"134.9"}, {"price":"0.27", "size":"460.2"}, {"price":"0.26", "size":"250.6"}, {"price":"0.25", "size":"496"}, {"price":"0.24", "size":"511.39"}, {"price":"0.23", "size":"246.89"}, {"price":"0.22", "size":"349.5"}, {"price":"0.21", "size":"275.44"}, {"price":"0.2", "size":"123.8"}, {"price":"0.19", "size":"102.35"}, {"price":"0.18", "size":"319.82"}, {"price":"0.17", "size":"33.97"}, {"price":"0.16", "size":"126.46"}], "hash":"2b1a026cfdd250bdd82871fad32e28888fc06abd", "timestamp":"1778784200943", "event_type":"book"}
{"market":"0x2a903c589141bce4a1e50fb98b73397af6820942542793ab10b1df477e912b6e", "price_changes":[{"asset_id":"68919878716222388542639225642064847629616106443780159680232863841946753372582", "price":"0.12", "size":"478.23", "side":"BUY", "hash":"4a3f842a4809d381dd3a0d217e1a27c64bcb5316", "best_bid":"0.15", "best_ask":"0.16"}, {"asset_id":"20436996072316278452977393149218961565084965483366669504673105646378938504388", "price":"0.88", "size":"478.23", "side":"SELL", "hash":"60b42491ba9c2a4bd81a3a9ff2dfa223f21e6686", "best_bid":"0.84", "best_ask":"0.85"}], "timestamp":"1778784200945", "event_type":"price_change"}
{"market":"0x2a903c589141bce4a1e50fb98b73397af6820942542793ab10b1df477e912b6e", "price_changes":[{"asset_id":"68919878716222388542639225642064847629616106443780159680232863841946753372582", "price":"0.05", "size":"856.73", "side":"BUY", "hash":"63e85946be8597d8eb4820effda2483d30fda755", "best_bid":"0.15", "best_ask":"0.16"}, {"asset_id":"20436996072316278452977393149218961565084965483366669504673105646378938504388", "price":"0.95", "size":"856.73", "side":"SELL", "hash":"e2df62c8aba37c0702ad130ed9d77a7fdf357c7e", "best_bid":"0.84", "best_ask":"0.85"}], "timestamp":"1778784200946", "event_type":"price_change"}
{"market":"0x2a903c589141bce4a1e50fb98b73397af6820942542793ab10b1df477e912b6e", "price_changes":[{"asset_id":"20436996072316278452977393149218961565084965483366669504673105646378938504388", "price":"0.83", "size":"28.97", "side":"BUY", "hash":"f64d3c7d79a4f18032a2f74a58451ea4c957c53b", "best_bid":"0.84", "best_ask":"0.85"}, {"asset_id":"68919878716222388542639225642064847629616106443780159680232863841946753372582", "price":"0.17", "size":"28.97", "side":"SELL", "hash":"c7f191907c5fa36addabe7f62e8a28f5ff05f3aa", "best_bid":"0.15", "best_ask":"0.16"}], "timestamp":"1778784200947", "event_type":"price_change"}
{"market":"0x2a903c589141bce4a1e50fb98b73397af6820942542793ab10b1df477e912b6e", "price_changes":[{"asset_id":"20436996072316278452977393149218961565084965483366669504673105646378938504388", "price":"0.82", "size":"289.82", "side":"BUY", "hash":"d03ea1846a79c99ff89860256f0ef449e3e1d8cc", "best_bid":"0.84", "best_ask":"0.85"}, {"asset_id":"68919878716222388542639225642064847629616106443780159680232863841946753372582", "price":"0.18", "size":"289.82", "side":"SELL", "hash":"152917e055b819b8902ecae89510477beace2fa6", "best_bid":"0.15", "best_ask":"0.16"}], "timestamp":"1778784200948", "event_type":"price_change"}
{"market":"0x2a903c589141bce4a1e50fb98b73397af6820942542793ab10b1df477e912b6e", "price_changes":[{"asset_id":"68919878716222388542639225642064847629616106443780159680232863841946753372582", "price":"0.15", "size":"179.96", "side":"BUY", "hash":"663685e0cebffff6181c42bf7b8d1b2a8f338481", "best_bid":"0.15", "best_ask":"0.16"}, {"asset_id":"20436996072316278452977393149218961565084965483366669504673105646378938504388", "price":"0.85", "size":"179.96", "side":"SELL", "hash":"16a581e4c51af9f5fb4cbc5c0aaa52ad6a163c84", "best_bid":"0.84", "best_ask":"0.85"}], "timestamp":"1778784200949", "event_type":"price_change"}
{"market":"0x2a903c589141bce4a1e50fb98b73397af6820942542793ab10b1df477e912b6e", "price_changes":[{"asset_id":"68919878716222388542639225642064847629616106443780159680232863841946753372582", "price":"0.12", "size":"578.23", "side":"BUY", "hash":"15155b22c6114b7490b932183a254f22754d8bd5", "best_bid":"0.15", "best_ask":"0.16"}, {"asset_id":"20436996072316278452977393149218961565084965483366669504673105646378938504388", "price":"0.88", "size":"578.23", "side":"SELL", "hash":"cfd19488d4c8c70e6875231d6e3db09b9a6793b5", "best_bid":"0.84", "best_ask":"0.85"}], "timestamp":"1778784200950", "event_type":"price_change"}
{"market":"0x2a903c589141bce4a1e50fb98b73397af6820942542793ab10b1df477e912b6e", "price_changes":[{"asset_id":"68919878716222388542639225642064847629616106443780159680232863841946753372582", "price":"0.13", "size":"125", "side":"BUY", "hash":"0fd844cdc75bac60b610634ad658fa456c692b91", "best_bid":"0.15", "best_ask":"0.16"}, {"asset_id":"20436996072316278452977393149218961565084965483366669504673105646378938504388", "price":"0.87", "size":"125", "side":"SELL", "hash":"a997c24068734eb79168dc72bd4aef3b09234114", "best_bid":"0.84", "best_ask":"0.85"}], "timestamp":"1778784200951", "event_type":"price_change"}
{"market":"0x2a903c589141bce4a1e50fb98b73397af6820942542793ab10b1df477e912b6e", "price_changes":[{"asset_id":"20436996072316278452977393149218961565084965483366669504673105646378938504388", "price":"0.71", "size":"626.38", "side":"BUY", "hash":"5e4bca8d4854bf0562c6357d4373e74b568e01f1", "best_bid":"0.84", "best_ask":"0.85"}, {"asset_id":"68919878716222388542639225642064847629616106443780159680232863841946753372582", "price":"0.29", "size":"626.38", "side":"SELL", "hash":"f98ba09e5bea48f40eca5da15052d92dfa5be114", "best_bid":"0.15", "best_ask":"0.16"}], "timestamp":"1778784200952", "event_type":"price_change"}
{"market":"0x2a903c589141bce4a1e50fb98b73397af6820942542793ab10b1df477e912b6e", "price_changes":[{"asset_id":"68919878716222388542639225642064847629616106443780159680232863841946753372582", "price":"0.14", "size":"232.57", "side":"BUY", "hash":"259b33ee490105b82359fecd64de92d1d7358541", "best_bid":"0.15", "best_ask":"0.16"}, {"asset_id":"20436996072316278452977393149218961565084965483366669504673105646378938504388", "price":"0.86", "size":"232.57", "side":"SELL", "hash":"4fd56cc12ae00acd821af5bbbea5cb17520a5d2e", "best_bid":"0.84", "best_ask":"0.85"}], "timestamp":"1778784200954", "event_type":"price_change"}
{"market":"0x2a903c589141bce4a1e50fb98b73397af6820942542793ab10b1df477e912b6e", "price_changes":[{"asset_id":"68919878716222388542639225642064847629616106443780159680232863841946753372582", "price":"0.15", "size":"168.96", "side":"BUY", "hash":"02e9a6237f0242478ac7a36b26690de788d105ea", "best_bid":"0.15", "best_ask":"0.16"}, {"asset_id":"20436996072316278452977393149218961565084965483366669504673105646378938504388", "price":"0.85", "size":"168.96", "side":"SELL", "hash":"bc6cac7d5574351017f9495ddc3108672b78919a", "best_bid":"0.84", "best_ask":"0.85"}], "timestamp":"1778784200956", "event_type":"price_change"}
{"market":"0x2a903c589141bce4a1e50fb98b73397af6820942542793ab10b1df477e912b6e", "price_changes":[{"asset_id":"20436996072316278452977393149218961565084965483366669504673105646378938504388", "price":"0.84", "size":"120.21", "side":"BUY", "hash":"4c7b8cbda283ccb8090f4124d738da6c01035c2a", "best_bid":"0.84", "best_ask":"0.85"}, {"asset_id":"68919878716222388542639225642064847629616106443780159680232863841946753372582", "price":"0.16", "size":"120.21", "side":"SELL", "hash":"a6d6ac985259a08350a9a0cacddf72356adfcbca", "best_bid":"0.15", "best_ask":"0.16"}], "timestamp":"1778784200959", "event_type":"price_change"}
{"market":"0x2a903c589141bce4a1e50fb98b73397af6820942542793ab10b1df477e912b6e", "asset_id":"68919878716222388542639225642064847629616106443780159680232863841946753372582", "bids":[{"price":"0.01", "size":"11343.83"}, {"price":"0.02", "size":"1397.82"}, {"price":"0.03", "size":"1100.78"}, {"price":"0.04", "size":"1237.82"}, {"price":"0.05", "size":"856.73"}, {"price":"0.06", "size":"297.2"}, {"price":"0.07", "size":"647.1"}, {"price":"0.08", "size":"694.53"}, {"price":"0.09", "size":"357.1"}, {"price":"0.1", "size":"507"}, {"price":"0.11", "size":"426.62"}, {"price":"0.12", "size":"578.23"}, {"price":"0.13", "size":"125"}, {"price":"0.14", "size":"232.57"}, {"price":"0.15", "size":"168.96"}], "asks":[{"price":"0.99", "size":"11995.61"}, {"price":"0.98", "size":"1219.45"}, {"price":"0.97", "size":"1096.98"}, {"price":"0.96", "size":"670.05"}, {"price":"0.95", "size":"549.45"}, {"price":"0.94", "size":"346.2"}, {"price":"0.93", "size":"902.05"}, {"price":"0.92", "size":"170.79"}, {"price":"0.91", "size":"234.6"}, {"price":"0.9", "size":"128"}, {"price":"0.89", "size":"142.6"}, {"price":"0.88", "size":"141.8"}, {"price":"0.87", "size":"144.81"}, {"price":"0.86", "size":"204.9"}, {"price":"0.85", "size":"113.5"}, {"price":"0.84", "size":"102.3"}, {"price":"0.83", "size":"101.3"}, {"price":"0.82", "size":"105.3"}, {"price":"0.81", "size":"199.5"}, {"price":"0.8", "size":"103.8"}, {"price":"0.79", "size":"98.1"}, {"price":"0.78", "size":"97.5"}, {"price":"0.77", "size":"96.89"}, {"price":"0.76", "size":"201.39"}, {"price":"0.75", "size":"116"}, {"price":"0.74", "size":"100.6"}, {"price":"0.73", "size":"95.2"}, {"price":"0.72", "size":"94.9"}, {"price":"0.71", "size":"199.6"}, {"price":"0.7", "size":"94.3"}, {"price":"0.69", "size":"108.28"}, {"price":"0.68", "size":"98.8"}, {"price":"0.67", "size":"118.6"}, {"price":"0.66", "size":"398.4"}, {"price":"0.65", "size":"507.3"}, {"price":"0.64", "size":"893"}, {"price":"0.63", "size":"892.9"}, {"price":"0.62", "size":"297.7"}, {"price":"0.61", "size":"397.6"}, {"price":"0.6", "size":"356.93"}, {"price":"0.59", "size":"297.4"}, {"price":"0.58", "size":"109.6"}, {"price":"0.57", "size":"131.48"}, {"price":"0.56", "size":"413.97"}, {"price":"0.55", "size":"334.2"}, {"price":"0.54", "size":"375.6"}, {"price":"0.53", "size":"292"}, {"price":"0.52", "size":"297.12"}, {"price":"0.51", "size":"402"}, {"price":"0.5", "size":"340.91"}, {"price":"0.49", "size":"798"}, {"price":"0.48", "size":"317"}, {"price":"0.47", "size":"337"}, {"price":"0.46", "size":"451.54"}, {"price":"0.45", "size":"346.64"}, {"price":"0.44", "size":"341.45"}, {"price":"0.43", "size":"434.89"}, {"price":"0.42", "size":"724.36"}, {"price":"0.41", "size":"412.4"}, {"price":"0.4", "size":"328.83"}, {"price":"0.39", "size":"297.6"}, {"price":"0.38", "size":"318.44"}, {"price":"0.37", "size":"576.9"}, {"price":"0.36", "size":"203"}, {"price":"0.35", "size":"330.14"}, {"price":"0.34", "size":"350.9"}, {"price":"0.33", "size":"363.6"}, {"price":"0.32", "size":"2065.88"}, {"price":"0.31", "size":"559"}, {"price":"0.3", "size":"234.3"}, {"price":"0.29", "size":"626.38"}, {"price":"0.28", "size":"134.9"}, {"price":"0.27", "size":"460.2"}, {"price":"0.26", "size":"250.6"}, {"price":"0.25", "size":"496"}, {"price":"0.24", "size":"511.39"}, {"price":"0.23", "size":"246.89"}, {"price":"0.22", "size":"349.5"}, {"price":"0.21", "size":"275.44"}, {"price":"0.2", "size":"123.8"}, {"price":"0.19", "size":"102.35"}, {"price":"0.18", "size":"289.82"}, {"price":"0.17", "size":"28.97"}, {"price":"0.16", "size":"120.21"}], "hash":"a6d6ac985259a08350a9a0cacddf72356adfcbca", "timestamp":"1778784200959", "event_type":"book"}
{"market":"0x2a903c589141bce4a1e50fb98b73397af6820942542793ab10b1df477e912b6e", "price_changes":[{"asset_id":"68919878716222388542639225642064847629616106443780159680232863841946753372582", "price":"0.06", "size":"347.21", "side":"BUY", "hash":"54496cc8360245ec4170483b48563d2bb48edd73", "best_bid":"0.15", "best_ask":"0.16"}, {"asset_id":"20436996072316278452977393149218961565084965483366669504673105646378938504388", "price":"0.94", "size":"347.21", "side":"SELL", "hash":"1765a290ab02a2d642f6358a83c2781f148478d1", "best_bid":"0.84", "best_ask":"0.85"}], "timestamp":"1778784200961", "event_type":"price_change"}
{"market":"0x2a903c589141bce4a1e50fb98b73397af6820942542793ab10b1df477e912b6e", "price_changes":[{"asset_id":"20436996072316278452977393149218961565084965483366669504673105646378938504388", "price":"0.84", "size":"135.21", "side":"BUY", "hash":"79e6245e73967aa4ae7a5326cc25a6b0c33b2b70", "best_bid":"0.84", "best_ask":"0.85"}, {"asset_id":"68919878716222388542639225642064847629616106443780159680232863841946753372582", "price":"0.16", "size":"135.21", "side":"SELL", "hash":"2a8617b15408c1b6920a42c35f95f0b9f07ffc80", "best_bid":"0.15", "best_ask":"0.16"}], "timestamp":"1778784200962", "event_type":"price_change"}
{"market":"0x2a903c589141bce4a1e50fb98b73397af6820942542793ab10b1df477e912b6e", "price_changes":[{"asset_id":"68919878716222388542639225642064847629616106443780159680232863841946753372582", "price":"0.11", "size":"416.62", "side":"BUY", "hash":"188f90d26ae63510a657239c83161f8e377b3275", "best_bid":"0.15", "best_ask":"0.16"}, {"asset_id":"20436996072316278452977393149218961565084965483366669504673105646378938504388", "price":"0.89", "size":"416.62", "side":"SELL", "hash":"de2e0ec6635f3aed31a580ade12f9273d4fa466c", "best_bid":"0.84", "best_ask":"0.85"}], "timestamp":"1778784200963", "event_type":"price_change"}
{"market":"0x2a903c589141bce4a1e50fb98b73397af6820942542793ab10b1df477e912b6e", "price_changes":[{"asset_id":"20436996072316278452977393149218961565084965483366669504673105646378938504388", "price":"0.81", "size":"72.35", "side":"BUY", "hash":"ea60524537a81c9947c2a815e42173b69a9d81ae", "best_bid":"0.84", "best_ask":"0.85"}, {"asset_id":"68919878716222388542639225642064847629616106443780159680232863841946753372582", "price":"0.19", "size":"72.35", "side":"SELL", "hash":"4fc7caa18e394ea8186259bf0b463b92b70e3642", "best_bid":"0.15", "best_ask":"0.16"}], "timestamp":"1778784200964", "event_type":"price_change"}
{"market":"0x2a903c589141bce4a1e50fb98b73397af6820942542793ab10b1df477e912b6e", "price_changes":[{"asset_id":"68919878716222388542639225642064847629616106443780159680232863841946753372582", "price":"0.11", "size":"442.62", "side":"BUY", "hash":"1a8efcd0220b12657aa86d5f7de835e7fd9e5311", "best_bid":"0.15", "best_ask":"0.16"}, {"asset_id":"20436996072316278452977393149218961565084965483366669504673105646378938504388", "price":"0.89", "size":"442.62", "side":"SELL", "hash":"401aa663eab11989f671c318098bcad0a1307414", "best_bid":"0.84", "best_ask":"0.85"}], "timestamp":"1778784200965", "event_type":"price_change"}
{"market":"0x2a903c589141bce4a1e50fb98b73397af6820942542793ab10b1df477e912b6e", "asset_id":"68919878716222388542639225642064847629616106443780159680232863841946753372582", "price":"0.16", "size":"11.04", "fee_rate_bps":"0", "side":"BUY", "timestamp":"1778784200964", "event_type":"last_trade_price", "transaction_hash":"0x5cc37a8e82c4a867e184822ad0c60055265137663a150941fcb94e9f6eae7693"}
{"market":"0x2a903c589141bce4a1e50fb98b73397af6820942542793ab10b1df477e912b6e", "price_changes":[{"asset_id":"68919878716222388542639225642064847629616106443780159680232863841946753372582", "price":"0.12", "size":"516.23", "side":"BUY", "hash":"13fd08d25b63ac9a1815942d26376c66f158dcc1", "best_bid":"0.15", "best_ask":"0.16"}, {"asset_id":"20436996072316278452977393149218961565084965483366669504673105646378938504388", "price":"0.88", "size":"516.23", "side":"SELL", "hash":"b8a58b6198778d04db2d861788aa900bcbf53d3a", "best_bid":"0.84", "best_ask":"0.85"}], "timestamp":"1778784200966", "event_type":"price_change"}
{"market":"0x2a903c589141bce4a1e50fb98b73397af6820942542793ab10b1df477e912b6e", "price_changes":[{"asset_id":"68919878716222388542639225642064847629616106443780159680232863841946753372582", "price":"0.15", "size":"185.96", "side":"BUY", "hash":"e2b355829d5943805149dc08ac12565ee693fff5", "best_bid":"0.15", "best_ask":"0.16"}, {"asset_id":"20436996072316278452977393149218961565084965483366669504673105646378938504388", "price":"0.85", "size":"185.96", "side":"SELL", "hash":"cdcbd881f1fb3c8e6130dfb32ab5c8b35ad29f1c", "best_bid":"0.84", "best_ask":"0.85"}], "timestamp":"1778784200967", "event_type":"price_change"}
{"market":"0x2a903c589141bce4a1e50fb98b73397af6820942542793ab10b1df477e912b6e", "price_changes":[{"asset_id":"20436996072316278452977393149218961565084965483366669504673105646378938504388", "price":"0.84", "size":"146.21", "side":"BUY", "hash":"7a6dcbb4bc3269b3f261b6c3b9fdf14e0518ad13", "best_bid":"0.84", "best_ask":"0.85"}, {"asset_id":"68919878716222388542639225642064847629616106443780159680232863841946753372582", "price":"0.16", "size":"146.21", "side":"SELL", "hash":"21f55ca73549f1ad1210387d5719d37bb9874007", "best_bid":"0.15", "best_ask":"0.16"}], "timestamp":"1778784200968", "event_type":"price_change"}
{"market":"0x2a903c589141bce4a1e50fb98b73397af6820942542793ab10b1df477e912b6e", "price_changes":[{"asset_id":"68919878716222388542639225642064847629616106443780159680232863841946753372582", "price":"0.15", "size":"195.96", "side":"BUY", "hash":"d679a9b397b829d7aa368bec3b755a5f41548c4d", "best_bid":"0.15", "best_ask":"0.16"}, {"asset_id":"20436996072316278452977393149218961565084965483366669504673105646378938504388", "price":"0.85", "size":"195.96", "side":"SELL", "hash":"9260a5bb73e11fd3d1da016bfc6adae35dc38131", "best_bid":"0.84", "best_ask":"0.85"}], "timestamp":"1778784200969", "event_type":"price_change"}
{"market":"0x2a903c589141bce4a1e50fb98b73397af6820942542793ab10b1df477e912b6e", "price_changes":[{"asset_id":"68919878716222388542639225642064847629616106443780159680232863841946753372582", "price":"0.15", "size":"205.96", "side":"BUY", "hash":"352c58df680ab8b576035dbd6fd06638627ebd43", "best_bid":"0.15", "best_ask":"0.16"}, {"asset_id":"20436996072316278452977393149218961565084965483366669504673105646378938504388", "price":"0.85", "size":"205.96", "side":"SELL", "hash":"482f4810ea0137b062fbad8f9139b639652d3cef", "best_bid":"0.84", "best_ask":"0.85"}], "timestamp":"1778784200970", "event_type":"price_change"}
{"market":"0x2a903c589141bce4a1e50fb98b73397af6820942542793ab10b1df477e912b6e", "price_changes":[{"asset_id":"68919878716222388542639225642064847629616106443780159680232863841946753372582", "price":"0.15", "size":"215.96", "side":"BUY", "hash":"7620b2b0519d93d1b35aee599b35449ab71814bd", "best_bid":"0.15", "best_ask":"0.16"}, {"asset_id":"20436996072316278452977393149218961565084965483366669504673105646378938504388", "price":"0.85", "size":"215.96", "side":"SELL", "hash":"f2ea7d283810f95c4fbcf70914815cf6e036fb59", "best_bid":"0.84", "best_ask":"0.85"}], "timestamp":"1778784200971", "event_type":"price_change"}
{"market":"0x2a903c589141bce4a1e50fb98b73397af6820942542793ab10b1df477e912b6e", "price_changes":[{"asset_id":"68919878716222388542639225642064847629616106443780159680232863841946753372582", "price":"0.15", "size":"225.96", "side":"BUY", "hash":"9ae8c254c62b28996cbda0b6aab95a2a17e85191", "best_bid":"0.15", "best_ask":"0.16"}, {"asset_id":"20436996072316278452977393149218961565084965483366669504673105646378938504388", "price":"0.85", "size":"225.96", "side":"SELL", "hash":"f56ecbc7ad44da977aa9ddecd5281e2769ef090d", "best_bid":"0.84", "best_ask":"0.85"}], "timestamp":"1778784200972", "event_type":"price_change"}
{"market":"0x2a903c589141bce4a1e50fb98b73397af6820942542793ab10b1df477e912b6e", "price_changes":[{"asset_id":"68919878716222388542639225642064847629616106443780159680232863841946753372582", "price":"0.15", "size":"242.96", "side":"BUY", "hash":"3113ce710ac4870894eaee8a17d47d0561d71e02", "best_bid":"0.15", "best_ask":"0.16"}, {"asset_id":"20436996072316278452977393149218961565084965483366669504673105646378938504388", "price":"0.85", "size":"242.96", "side":"SELL", "hash":"9bbb34029e1a9f7eb2d67adafe3eb301779b556f", "best_bid":"0.84", "best_ask":"0.85"}], "timestamp":"1778784200973", "event_type":"price_change"}
{"market":"0x2a903c589141bce4a1e50fb98b73397af6820942542793ab10b1df477e912b6e", "price_changes":[{"asset_id":"68919878716222388542639225642064847629616106443780159680232863841946753372582", "price":"0.15", "size":"252.96", "side":"BUY", "hash":"ad4a6a675b4f368c303019cd8f6875a3078ed9ef", "best_bid":"0.15", "best_ask":"0.16"}, {"asset_id":"20436996072316278452977393149218961565084965483366669504673105646378938504388", "price":"0.85", "size":"252.96", "side":"SELL", "hash":"84235c516e8a851d7e3fc391b1e020618656ff7f", "best_bid":"0.84", "best_ask":"0.85"}], "timestamp":"1778784200974", "event_type":"price_change"}
{"market":"0x2a903c589141bce4a1e50fb98b73397af6820942542793ab10b1df477e912b6e", "price_changes":[{"asset_id":"68919878716222388542639225642064847629616106443780159680232863841946753372582", "price":"0.15", "size":"262.96", "side":"BUY", "hash":"d7af6e9177c3458c0853c5228c9c4879e7591775", "best_bid":"0.15", "best_ask":"0.16"}, {"asset_id":"20436996072316278452977393149218961565084965483366669504673105646378938504388", "price":"0.85", "size":"262.96", "side":"SELL", "hash":"d26060a74efbdf401fca378e51a877b83b450292", "best_bid":"0.84", "best_ask":"0.85"}], "timestamp":"1778784200975", "event_type":"price_change"}
{"market":"0x2a903c589141bce4a1e50fb98b73397af6820942542793ab10b1df477e912b6e", "price_changes":[{"asset_id":"20436996072316278452977393149218961565084965483366669504673105646378938504388", "price":"0.84", "size":"156.21", "side":"BUY", "hash":"f1865f0f369f9e4ec0a5d0e5b8be88bf95d741d7", "best_bid":"0.84", "best_ask":"0.85"}, {"asset_id":"68919878716222388542639225642064847629616106443780159680232863841946753372582", "price":"0.16", "size":"156.21", "side":"SELL", "hash":"293d006c3794f37690c6e1a4c1d083b055867965", "best_bid":"0.15", "best_ask":"0.16"}], "timestamp":"1778784200975", "event_type":"price_change"}
{"market":"0x2a903c589141bce4a1e50fb98b73397af6820942542793ab10b1df477e912b6e", "price_changes":[{"asset_id":"20436996072316278452977393149218961565084965483366669504673105646378938504388", "price":"0.79", "size":"305.44", "side":"BUY", "hash":"d1e578837fc6d159c5aad7f3195493b11b52be82", "best_bid":"0.84", "best_ask":"0.85"}, {"asset_id":"68919878716222388542639225642064847629616106443780159680232863841946753372582", "price":"0.21", "size":"305.44", "side":"SELL", "hash":"1f641359b05ab56576c116475a686bab7eff1003", "best_bid":"0.15", "best_ask":"0.16"}], "timestamp":"1778784200976", "event_type":"price_change"}
{"market":"0x2a903c589141bce4a1e50fb98b73397af6820942542793ab10b1df477e912b6e", "price_changes":[{"asset_id":"20436996072316278452977393149218961565084965483366669504673105646378938504388", "price":"0.78", "size":"355.5", "side":"BUY", "hash":"a9cc22893205c5804d2fea714dcf13790016e94c", "best_bid":"0.84", "best_ask":"0.85"}, {"asset_id":"68919878716222388542639225642064847629616106443780159680232863841946753372582", "price":"0.22", "size":"355.5", "side":"SELL", "hash":"00226324274ab9e3dbb91f21ca38313b1e4f19e3", "best_bid":"0.15", "best_ask":"0.16"}], "timestamp":"1778784200978", "event_type":"price_change"}
{"market":"0x2a903c589141bce4a1e50fb98b73397af6820942542793ab10b1df477e912b6e", "price_changes":[{"asset_id":"68919878716222388542639225642064847629616106443780159680232863841946753372582", "price":"0.05", "size":"796.72", "side":"BUY", "hash":"a8e62aeed36aa75e2f43f0aab74f57b0788eb23e", "best_bid":"0.15", "best_ask":"0.16"}, {"asset_id":"20436996072316278452977393149218961565084965483366669504673105646378938504388", "price":"0.95", "size":"796.72", "side":"SELL", "hash":"9f79081b5c9e00ff165f7e9745c2d213c9dc72f8", "best_bid":"0.84", "best_ask":"0.85"}], "timestamp":"1778784200979", "event_type":"price_change"}
{"market":"0x2a903c589141bce4a1e50fb98b73397af6820942542793ab10b1df477e912b6e", "price_changes":[{"asset_id":"20436996072316278452977393149218961565084965483366669504673105646378938504388", "price":"0.84", "size":"166.21", "side":"BUY", "hash":"bf1977fae6157b8ed809894615f7204bf4743571", "best_bid":"0.84", "best_ask":"0.85"}, {"asset_id":"68919878716222388542639225642064847629616106443780159680232863841946753372582", "price":"0.16", "size":"166.21", "side":"SELL", "hash":"4396e21fc876286b997f525db094aef697dcfa12", "best_bid":"0.15", "best_ask":"0.16"}], "timestamp":"1778784200980", "event_type":"price_change"}
{"market":"0x2a903c589141bce4a1e50fb98b73397af6820942542793ab10b1df477e912b6e", "price_changes":[{"asset_id":"68919878716222388542639225642064847629616106443780159680232863841946753372582", "price":"0.12", "size":"511.23", "side":"BUY", "hash":"70d2a63bde0bfd1a880ad095c1f8e2eb66f68641", "best_bid":"0.15", "best_ask":"0.16"}, {"asset_id":"20436996072316278452977393149218961565084965483366669504673105646378938504388", "price":"0.88", "size":"511.23", "side":"SELL", "hash":"998969a08dcb09f0ede01f1ad287e87b2508b287", "best_bid":"0.84", "best_ask":"0.85"}], "timestamp":"1778784200981", "event_type":"price_change"}
{"market":"0x2a903c589141bce4a1e50fb98b73397af6820942542793ab10b1df477e912b6e", "asset_id":"68919878716222388542639225642064847629616106443780159680232863841946753372582", "price":"0.16", "size":"6.25", "fee_rate_bps":"0", "side":"BUY", "timestamp":"1778784200980", "event_type":"last_trade_price", "transaction_hash":"0x3ee0a549d72b1dd02a664d749a3de3f615466dc076b14640b8a9c045c051edca"}
{"market":"0x2a903c589141bce4a1e50fb98b73397af6820942542793ab10b1df477e912b6e", "price_changes":[{"asset_id":"20436996072316278452977393149218961565084965483366669504673105646378938504388", "price":"0.84", "size":"161.21", "side":"BUY", "hash":"8e8438346b1f0a8323470940e409daa8571e630f", "best_bid":"0.84", "best_ask":"0.85"}, {"asset_id":"68919878716222388542639225642064847629616106443780159680232863841946753372582", "price":"0.16", "size":"161.21", "side":"SELL", "hash":"f2c4ba7b106761e03c3c2000f626b820c784d05d", "best_bid":"0.15", "best_ask":"0.16"}], "timestamp":"1778784200988", "event_type":"price_change"}
