{"market":"0x2a903c589141bce4a1e50fb98b73397af6820942542793ab10b1df477e912b6e", "asset_id":"68919878716222388542639225642064847629616106443780159680232863841946753372582", "bids":[{"price":"0.01", "size":"11373.83"}, {"price":"0.02", "size":"1427.82"}, {"price":"0.03", "size":"1105.78"}, {"price":"0.04", "size":"837.82"}, {"price":"0.05", "size":"1055.72"}, {"price":"0.06", "size":"237.72"}, {"price":"0.07", "size":"337.1"}, {"price":"0.08", "size":"680.73"}, {"price":"0.09", "size":"312.7"}, {"price":"0.1", "size":"631.26"}, {"price":"0.11", "size":"271.97"}, {"price":"0.13", "size":"86.87"}, {"price":"0.14", "size":"27.67"}], "asks":[{"price":"0.99", "size":"12010.61"}, {"price":"0.98", "size":"1219.45"}, {"price":"0.97", "size":"1111.98"}, {"price":"0.96", "size":"670.05"}, {"price":"0.95", "size":"549.45"}, {"price":"0.94", "size":"346.2"}, {"price":"0.93", "size":"902.05"}, {"price":"0.92", "size":"170.79"}, {"price":"0.91", "size":"234.6"}, {"price":"0.9", "size":"128"}, {"price":"0.89", "size":"142.6"}, {"price":"0.88", "size":"141.8"}, {"price":"0.87", "size":"144.81"}, {"price":"0.86", "size":"204.9"}, {"price":"0.85", "size":"113.5"}, {"price":"0.84", "size":"102.3"}, {"price":"0.83", "size":"101.3"}, {"price":"0.82", "size":"105.3"}, {"price":"0.81", "size":"199.5"}, {"price":"0.8", "size":"103.8"}, {"price":"0.79", "size":"98.1"}, {"price":"0.78", "size":"97.5"}, {"price":"0.77", "size":"96.89"}, {"price":"0.76", "size":"201.39"}, {"price":"0.75", "size":"116"}, {"price":"0.74", "size":"100.6"}, {"price":"0.73", "size":"95.2"}, {"price":"0.72", "size":"94.9"}, {"price":"0.71", "size":"199.6"}, {"price":"0.7", "size":"94.3"}, {"price":"0.69", "size":"108.28"}, {"price":"0.68", "size":"98.8"}, {"price":"0.67", "size":"718.6"}, {"price":"0.66", "size":"998.4"}, {"price":"0.65", "size":"507.3"}, {"price":"0.64", "size":"293"}, {"price":"0.63", "size":"292.9"}, {"price":"0.62", "size":"897.7"}, {"price":"0.61", "size":"397.6"}, {"price":"0.6", "size":"356.93"}, {"price":"0.59", "size":"297.4"}, {"price":"0.58", "size":"109.6"}, {"price":"0.57", "size":"131.48"}, {"price":"0.56", "size":"413.97"}, {"price":"0.55", "size":"334.2"}, {"price":"0.54", "size":"375.6"}, {"price":"0.53", "size":"292"}, {"price":"0.52", "size":"292.12"}, {"price":"0.51", "size":"402"}, {"price":"0.5", "size":"355.91"}, {"price":"0.49", "size":"312"}, {"price":"0.48", "size":"317"}, {"price":"0.47", "size":"802"}, {"price":"0.46", "size":"651.54"}, {"price":"0.45", "size":"346.64"}, {"price":"0.44", "size":"337.45"}, {"price":"0.43", "size":"434.89"}, {"price":"0.42", "size":"724.36"}, {"price":"0.41", "size":"412.4"}, {"price":"0.4", "size":"328.83"}, {"price":"0.39", "size":"297.6"}, {"price":"0.38", "size":"618.44"}, {"price":"0.37", "size":"297.9"}, {"price":"0.36", "size":"208"}, {"price":"0.35", "size":"345.14"}, {"price":"0.34", "size":"355.9"}, {"price":"0.33", "size":"343.6"}, {"price":"0.32", "size":"2055.88"}, {"price":"0.31", "size":"559"}, {"price":"0.3", "size":"134.3"}, {"price":"0.29", "size":"316.38"}, {"price":"0.28", "size":"159.9"}, {"price":"0.27", "size":"165.2"}, {"price":"0.26", "size":"230.6"}, {"price":"0.25", "size":"696"}, {"price":"0.24", "size":"146.39"}, {"price":"0.23", "size":"166.89"}, {"price":"0.22", "size":"217.5"}, {"price":"0.21", "size":"275.44"}, {"price":"0.2", "size":"110"}, {"price":"0.19", "size":"72.35"}, {"price":"0.18", "size":"269.82"}, {"price":"0.17", "size":"30"}, {"price":"0.16", "size":"100"}, {"price":"0.15", "size":"31.67"}], "hash":"3b29fd954580df90937fddb98b2aaa2d8e2c68cf", "timestamp":"1778784200428", "event_type":"book"}
{"market":"0x2a903c589141bce4a1e50fb98b73397af6820942542793ab10b1df477e912b6e", "price_changes":[{"asset_id":"20436996072316278452977393149218961565084965483366669504673105646378938504388", "price":"0.01", "size":"12015.61", "side":"BUY", "hash":"95374d3877437b96f170a9e320665f89de3fce02", "best_bid":"0.85", "best_ask":"0.86"}, {"asset_id":"68919878716222388542639225642064847629616106443780159680232863841946753372582", "price":"0.99", "size":"12015.61", "side":"SELL", "hash":"eb8e1ec99a978f0fcfed53532bfdb894283aa91d", "best_bid":"0.14", "best_ask":"0.15"}], "timestamp":"1778784200429", "event_type":"price_change"}
{"market":"0x2a903c589141bce4a1e50fb98b73397af6820942542793ab10b1df477e912b6e", "price_changes":[{"asset_id":"20436996072316278452977393149218961565084965483366669504673105646378938504388", "price":"0.77", "size":"186.89", "side":"BUY", "hash":"d4d870c40d8829b2ba7003bdea6dece9e713781f", "best_bid":"0.85", "best_ask":"0.86"}, {"asset_id":"68919878716222388542639225642064847629616106443780159680232863841946753372582", "price":"0.23", "size":"186.89", "side":"SELL", "hash":"24f4958af104f77446a8712c720fdc8a76fc56b8", "best_bid":"0.14", "best_ask":"0.15"}], "timestamp":"1778784200431", "event_type":"price_change"}
{"market":"0x2a903c589141bce4a1e50fb98b73397af6820942542793ab10b1df477e912b6e", "price_changes":[{"asset_id":"20436996072316278452977393149218961565084965483366669504673105646378938504388", "price":"0.85", "size":"36.67", "side":"BUY", "hash":"8092280dffefe097ba640a9e4d6b4300e8bcd6aa", "best_bid":"0.85", "best_ask":"0.86"}, {"asset_id":"68919878716222388542639225642064847629616106443780159680232863841946753372582", "price":"0.15", "size":"36.67", "side":"SELL", "hash":"103981cd22b5fbae03d14fd246cbbf393742cf95", "best_bid":"0.14", "best_ask":"0.15"}], "timestamp":"1778784200432", "event_type":"price_change"}
{"market":"0x2a903c589141bce4a1e50fb98b73397af6820942542793ab10b1df477e912b6e", "price_changes":[{"asset_id":"20436996072316278452977393149218961565084965483366669504673105646378938504388", "price":"0.77", "size":"226.89", "side":"BUY", "hash":"425fa9272eec63369424f40bb8b09d717fa9a227", "best_bid":"0.85", "best_ask":"0.86"}, {"asset_id":"68919878716222388542639225642064847629616106443780159680232863841946753372582", "price":"0.23", "size":"226.89", "side":"SELL", "hash":"ae40f1299ea2bfd4adf25c2ed6e21af130a44c72", "best_bid":"0.14", "best_ask":"0.15"}], "timestamp":"1778784200434", "event_type":"price_change"}
{"market":"0x2a903c589141bce4a1e50fb98b73397af6820942542793ab10b1df477e912b6e", "price_changes":[{"asset_id":"20436996072316278452977393149218961565084965483366669504673105646378938504388", "price":"0.71", "size":"346.38", "side":"BUY", "hash":"37221ac12cfe8b625684d73555d10f99e1064a2a", "best_bid":"0.85", "best_ask":"0.86"}, {"asset_id":"68919878716222388542639225642064847629616106443780159680232863841946753372582", "price":"0.29", "size":"346.38", "side":"SELL", "hash":"fd61f66607aacdb0ed632ccb0fd7366fb2eaa7a0", "best_bid":"0.14", "best_ask":"0.15"}], "timestamp":"1778784200435", "event_type":"price_change"}
{"market":"0x2a903c589141bce4a1e50fb98b73397af6820942542793ab10b1df477e912b6e", "asset_id":"68919878716222388542639225642064847629616106443780159680232863841946753372582", "price":"0.12", "size":"5", "fee_rate_bps":"0", "side":"BUY", "timestamp":"1778784200434", "event_type":"last_trade_price", "transaction_hash":"0xb42118f381afcbbf0afed1c4ba4a2948b499fcebebfc31694d2bca9c01b155a1"}
{"market":"0x2a903c589141bce4a1e50fb98b73397af6820942542793ab10b1df477e912b6e", "price_changes":[{"asset_id":"68919878716222388542639225642064847629616106443780159680232863841946753372582", "price":"0.35", "size":"340.14", "side":"SELL", "hash":"2d20e56d6df95c8e5904d8379a4c611c1b4cb6e4", "best_bid":"0.14", "best_ask":"0.15"}, {"asset_id":"20436996072316278452977393149218961565084965483366669504673105646378938504388", "price":"0.65", "size":"340.14", "side":"BUY", "hash":"88894442ce70375f89a016f0d0c9674378e4dc6d", "best_bid":"0.85", "best_ask":"0.86"}], "timestamp":"1778784200436", "event_type":"price_change"}
{"market":"0x2a903c589141bce4a1e50fb98b73397af6820942542793ab10b1df477e912b6e", "price_changes":[{"asset_id":"20436996072316278452977393149218961565084965483366669504673105646378938504388", "price":"0.82", "size":"284.82", "side":"BUY", "hash":"99171da6ebfad87777a25cd7f3dc6c7156ceecb9", "best_bid":"0.85", "best_ask":"0.86"}, {"asset_id":"68919878716222388542639225642064847629616106443780159680232863841946753372582", "price":"0.18", "size":"284.82", "side":"SELL", "hash":"2967352df01f374e2dddde4c4b34d871e043bc9e", "best_bid":"0.14", "best_ask":"0.15"}], "timestamp":"1778784200437", "event_type":"price_change"}
{"market":"0x2a903c589141bce4a1e50fb98b73397af6820942542793ab10b1df477e912b6e", "price_changes":[{"asset_id":"68919878716222388542639225642064847629616106443780159680232863841946753372582", "price":"0.12", "size":"5", "side":"BUY", "hash":"a7dbedca24b7f08768bef28d6f41c4f0dc1b9e90", "best_bid":"0.14", "best_ask":"0.15"}, {"asset_id":"20436996072316278452977393149218961565084965483366669504673105646378938504388", "price":"0.88", "size":"5", "side":"SELL", "hash":"ef1d0b9cae2dcea6980d2f9e7836602dadff3fb4", "best_bid":"0.85", "best_ask":"0.86"}], "timestamp":"1778784200439", "event_type":"price_change"}
{"market":"0x2a903c589141bce4a1e50fb98b73397af6820942542793ab10b1df477e912b6e", "price_changes":[{"asset_id":"20436996072316278452977393149218961565084965483366669504673105646378938504388", "price":"0.68", "size":"2085.88", "side":"BUY", "hash":"c35c640c5bede4f8a08f84c33487398c485f0e3b", "best_bid":"0.85", "best_ask":"0.86"}, {"asset_id":"68919878716222388542639225642064847629616106443780159680232863841946753372582", "price":"0.32", "size":"2085.88", "side":"SELL", "hash":"7abeadfa24121805e82eea4f2cdc3d78daf587ec", "best_bid":"0.14", "best_ask":"0.15"}], "timestamp":"1778784200440", "event_type":"price_change"}
{"market":"0x2a903c589141bce4a1e50fb98b73397af6820942542793ab10b1df477e912b6e", "price_changes":[{"asset_id":"68919878716222388542639225642064847629616106443780159680232863841946753372582", "price":"0.14", "size":"26.5", "side":"BUY", "hash":"62dd1742133868643d7e088418844b88a43408ef", "best_bid":"0.14", "best_ask":"0.15"}, {"asset_id":"20436996072316278452977393149218961565084965483366669504673105646378938504388", "price":"0.86", "size":"26.5", "side":"SELL", "hash":"49e0d6d5b7eb7439bcbf30caf5c0266f15470b0e", "best_bid":"0.85", "best_ask":"0.86"}], "timestamp":"1778784200443", "event_type":"price_change"}
{"market":"0x2a903c589141bce4a1e50fb98b73397af6820942542793ab10b1df477e912b6e", "asset_id":"68919878716222388542639225642064847629616106443780159680232863841946753372582", "bids":[{"price":"0.01", "size":"11373.83"}, {"price":"0.02", "size":"1427.82"}, {"price":"0.03", "size":"1105.78"}, {"price":"0.04", "size":"837.82"}, {"price":"0.05", "size":"1055.72"}, {"price":"0.06", "size":"237.72"}, {"price":"0.07", "size":"337.1"}, {"price":"0.08", "size":"680.73"}, {"price":"0.09", "size":"312.7"}, {"price":"0.1", "size":"631.26"}, {"price":"0.11", "size":"271.97"}, {"price":"0.12", "size":"5"}, {"price":"0.13", "size":"86.87"}, {"price":"0.14", "size":"26.5"}], "asks":[{"price":"0.99", "size":"12015.61"}, {"price":"0.98", "size":"1219.45"}, {"price":"0.97", "size":"1111.98"}, {"price":"0.96", "size":"670.05"}, {"price":"0.95", "size":"549.45"}, {"price":"0.94", "size":"346.2"}, {"price":"0.93", "size":"902.05"}, {"price":"0.92", "size":"170.79"}, {"price":"0.91", "size":"234.6"}, {"price":"0.9", "size":"128"}, {"price":"0.89", "size":"142.6"}, {"price":"0.88", "size":"141.8"}, {"price":"0.87", "size":"144.81"}, {"price":"0.86", "size":"204.9"}, {"price":"0.85", "size":"113.5"}, {"price":"0.84", "size":"102.3"}, {"price":"0.83", "size":"101.3"}, {"price":"0.82", "size":"105.3"}, {"price":"0.81", "size":"199.5"}, {"price":"0.8", "size":"103.8"}, {"price":"0.79", "size":"98.1"}, {"price":"0.78", "size":"97.5"}, {"price":"0.77", "size":"96.89"}, {"price":"0.76", "size":"201.39"}, {"price":"0.75", "size":"116"}, {"price":"0.74", "size":"100.6"}, {"price":"0.73", "size":"95.2"}, {"price":"0.72", "size":"94.9"}, {"price":"0.71", "size":"199.6"}, {"price":"0.7", "size":"94.3"}, {"price":"0.69", "size":"108.28"}, {"price":"0.68", "size":"98.8"}, {"price":"0.67", "size":"718.6"}, {"price":"0.66", "size":"998.4"}, {"price":"0.65", "size":"507.3"}, {"price":"0.64", "size":"293"}, {"price":"0.63", "size":"292.9"}, {"price":"0.62", "size":"897.7"}, {"price":"0.61", "size":"397.6"}, {"price":"0.6", "size":"356.93"}, {"price":"0.59", "size":"297.4"}, {"price":"0.58", "size":"109.6"}, {"price":"0.57", "size":"131.48"}, {"price":"0.56", "size":"413.97"}, {"price":"0.55", "size":"334.2"}, {"price":"0.54", "size":"375.6"}, {"price":"0.53", "size":"292"}, {"price":"0.52", "size":"292.12"}, {"price":"0.51", "size":"402"}, {"price":"0.5", "size":"355.91"}, {"price":"0.49", "size":"312"}, {"price":"0.48", "size":"317"}, {"price":"0.47", "size":"802"}, {"price":"0.46", "size":"651.54"}, {"price":"0.45", "size":"346.64"}, {"price":"0.44", "size":"337.45"}, {"price":"0.43", "size":"434.89"}, {"price":"0.42", "size":"724.36"}, {"price":"0.41", "size":"412.4"}, {"price":"0.4", "size":"328.83"}, {"price":"0.39", "size":"297.6"}, {"price":"0.38", "size":"618.44"}, {"price":"0.37", "size":"297.9"}, {"price":"0.36", "size":"208"}, {"price":"0.35", "size":"340.14"}, {"price":"0.34", "size":"355.9"}, {"price":"0.33", "size":"343.6"}, {"price":"0.32", "size":"2085.88"}, {"price":"0.31", "size":"559"}, {"price":"0.3", "size":"134.3"}, {"price":"0.29", "size":"346.38"}, {"price":"0.28", "size":"159.9"}, {"price":"0.27", "size":"165.2"}, {"price":"0.26", "size":"230.6"}, {"price":"0.25", "size":"696"}, {"price":"0.24", "size":"146.39"}, {"price":"0.23", "size":"226.89"}, {"price":"0.22", "size":"217.5"}, {"price":"0.21", "size":"275.44"}, {"price":"0.2", "size":"110"}, {"price":"0.19", "size":"72.35"}, {"price":"0.18", "size":"284.82"}, {"price":"0.17", "size":"30"}, {"price":"0.16", "size":"100"}, {"price":"0.15", "size":"36.67"}], "hash":"62dd1742133868643d7e088418844b88a43408ef", "timestamp":"1778784200443", "event_type":"book"}
{"market":"0x2a903c589141bce4a1e50fb98b73397af6820942542793ab10b1df477e912b6e", "price_changes":[{"asset_id":"20436996072316278452977393149218961565084965483366669504673105646378938504388", "price":"0.65", "size":"335.14", "side":"BUY", "hash":"8c7224f62fad7da4560b03300f68be1583fba971", "best_bid":"0.85", "best_ask":"0.86"}, {"asset_id":"68919878716222388542639225642064847629616106443780159680232863841946753372582", "price":"0.35", "size":"335.14", "side":"SELL", "hash":"ce818eabcf4141effdcda08cc68ac28a9c4a08c7", "best_bid":"0.14", "best_ask":"0.15"}], "timestamp":"1778784200445", "event_type":"price_change"}
{"market":"0x2a903c589141bce4a1e50fb98b73397af6820942542793ab10b1df477e912b6e", "asset_id":"68919878716222388542639225642064847629616106443780159680232863841946753372582", "price":"0.12", "size":"13.13", "fee_rate_bps":"0", "side":"BUY", "timestamp":"1778784200444", "event_type":"last_trade_price", "transaction_hash":"0x84893e26074b9a4221c024a28b071fb4240ed705a5ab66d058a40adda5a99e3a"}
{"market":"0x2a903c589141bce4a1e50fb98b73397af6820942542793ab10b1df477e912b6e", "price_changes":[{"asset_id":"68919878716222388542639225642064847629616106443780159680232863841946753372582", "price":"0.12", "size":"14", "side":"BUY", "hash":"f3330b8e1962c4dbed10b8ddd2d3a2c9c6e2045a", "best_bid":"0.14", "best_ask":"0.15"}, {"asset_id":"20436996072316278452977393149218961565084965483366669504673105646378938504388", "price":"0.88", "size":"14", "side":"SELL", "hash":"bf2ee7d38f139359e798a0657c0963fa41eb3933", "best_bid":"0.85", "best_ask":"0.86"}], "timestamp":"1778784200446", "event_type":"price_change"}
{"market":"0x2a903c589141bce4a1e50fb98b73397af6820942542793ab10b1df477e912b6e", "price_changes":[{"asset_id":"20436996072316278452977393149218961565084965483366669504673105646378938504388", "price":"0.85", "size":"16.67", "side":"BUY", "hash":"b80acc498d875b4b75d211a84fbeed2fa47b7f69", "best_bid":"0.85", "best_ask":"0.86"}, {"asset_id":"68919878716222388542639225642064847629616106443780159680232863841946753372582", "price":"0.15", "size":"16.67", "side":"SELL", "hash":"c537b389bf99608e9b8e2d39dd4140c10b83d275", "best_bid":"0.14", "best_ask":"0.15"}], "timestamp":"1778784200448", "event_type":"price_change"}
{"market":"0x2a903c589141bce4a1e50fb98b73397af6820942542793ab10b1df477e912b6e", "asset_id":"68919878716222388542639225642064847629616106443780159680232863841946753372582", "bids":[{"price":"0.01", "size":"11373.83"}, {"price":"0.02", "size":"1427.82"}, {"price":"0.03", "size":"1105.78"}, {"price":"0.04", "size":"837.82"}, {"price":"0.05", "size":"1055.72"}, {"price":"0.06", "size":"237.72"}, {"price":"0.07", "size":"337.1"}, {"price":"0.08", "size":"680.73"}, {"price":"0.09", "size":"312.7"}, {"price":"0.1", "size":"631.26"}, {"price":"0.11", "size":"271.97"}, {"price":"0.12", "size":"14"}, {"price":"0.13", "size":"86.87"}, {"price":"0.14", "size":"26.5"}], "asks":[{"price":"0.99", "size":"12015.61"}, {"price":"0.98", "size":"1219.45"}, {"price":"0.97", "size":"1111.98"}, {"price":"0.96", "size":"670.05"}, {"price":"0.95", "size":"549.45"}, {"price":"0.94", "size":"346.2"}, {"price":"0.93", "size":"902.05"}, {"price":"0.92", "size":"170.79"}, {"price":"0.91", "size":"234.6"}, {"price":"0.9", "size":"128"}, {"price":"0.89", "size":"142.6"}, {"price":"0.88", "size":"141.8"}, {"price":"0.87", "size":"144.81"}, {"price":"0.86", "size":"204.9"}, {"price":"0.85", "size":"113.5"}, {"price":"0.84", "size":"102.3"}, {"price":"0.83", "size":"101.3"}, {"price":"0.82", "size":"105.3"}, {"price":"0.81", "size":"199.5"}, {"price":"0.8", "size":"103.8"}, {"price":"0.79", "size":"98.1"}, {"price":"0.78", "size":"97.5"}, {"price":"0.77", "size":"96.89"}, {"price":"0.76", "size":"201.39"}, {"price":"0.75", "size":"116"}, {"price":"0.74", "size":"100.6"}, {"price":"0.73", "size":"95.2"}, {"price":"0.72", "size":"94.9"}, {"price":"0.71", "size":"199.6"}, {"price":"0.7", "size":"94.3"}, {"price":"0.69", "size":"108.28"}, {"price":"0.68", "size":"98.8"}, {"price":"0.67", "size":"718.6"}, {"price":"0.66", "size":"998.4"}, {"price":"0.65", "size":"507.3"}, {"price":"0.64", "size":"293"}, {"price":"0.63", "size":"292.9"}, {"price":"0.62", "size":"897.7"}, {"price":"0.61", "size":"397.6"}, {"price":"0.6", "size":"356.93"}, {"price":"0.59", "size":"297.4"}, {"price":"0.58", "size":"109.6"}, {"price":"0.57", "size":"131.48"}, {"price":"0.56", "size":"413.97"}, {"price":"0.55", "size":"334.2"}, {"price":"0.54", "size":"375.6"}, {"price":"0.53", "size":"292"}, {"price":"0.52", "size":"292.12"}, {"price":"0.51", "size":"402"}, {"price":"0.5", "size":"355.91"}, {"price":"0.49", "size":"312"}, {"price":"0.48", "size":"317"}, {"price":"0.47", "size":"802"}, {"price":"0.46", "size":"651.54"}, {"price":"0.45", "size":"346.64"}, {"price":"0.44", "size":"337.45"}, {"price":"0.43", "size":"434.89"}, {"price":"0.42", "size":"724.36"}, {"price":"0.41", "size":"412.4"}, {"price":"0.4", "size":"328.83"}, {"price":"0.39", "size":"297.6"}, {"price":"0.38", "size":"618.44"}, {"price":"0.37", "size":"297.9"}, {"price":"0.36", "size":"208"}, {"price":"0.35", "size":"335.14"}, {"price":"0.34", "size":"355.9"}, {"price":"0.33", "size":"343.6"}, {"price":"0.32", "size":"2085.88"}, {"price":"0.31", "size":"559"}, {"price":"0.3", "size":"134.3"}, {"price":"0.29", "size":"346.38"}, {"price":"0.28", "size":"159.9"}, {"price":"0.27", "size":"165.2"}, {"price":"0.26", "size":"230.6"}, {"price":"0.25", "size":"696"}, {"price":"0.24", "size":"146.39"}, {"price":"0.23", "size":"226.89"}, {"price":"0.22", "size":"217.5"}, {"price":"0.21", "size":"275.44"}, {"price":"0.2", "size":"110"}, {"price":"0.19", "size":"72.35"}, {"price":"0.18", "size":"284.82"}, {"price":"0.17", "size":"30"}, {"price":"0.16", "size":"100"}, {"price":"0.15", "size":"16.67"}], "hash":"c537b389bf99608e9b8e2d39dd4140c10b83d275", "timestamp":"1778784200448", "event_type":"book"}
{"market":"0x2a903c589141bce4a1e50fb98b73397af6820942542793ab10b1df477e912b6e", "price_changes":[{"asset_id":"20436996072316278452977393149218961565084965483366669504673105646378938504388", "price":"0.84", "size":"105", "side":"BUY", "hash":"0930507c80a48e03b8ffc7c2bc1a4a27460ae84c", "best_bid":"0.85", "best_ask":"0.86"}, {"asset_id":"68919878716222388542639225642064847629616106443780159680232863841946753372582", "price":"0.16", "size":"105", "side":"SELL", "hash":"add80505119df7af274df4a8cc96f555710ad3de", "best_bid":"0.14", "best_ask":"0.15"}], "timestamp":"1778784200450", "event_type":"price_change"}
{"market":"0x2a903c589141bce4a1e50fb98b73397af6820942542793ab10b1df477e912b6e", "price_changes":[{"asset_id":"68919878716222388542639225642064847629616106443780159680232863841946753372582", "price":"0.14", "size":"226.5", "side":"BUY", "hash":"4395adbbd19d4053e093b44d60d8aed90dc42ca6", "best_bid":"0.14", "best_ask":"0.15"}, {"asset_id":"20436996072316278452977393149218961565084965483366669504673105646378938504388", "price":"0.86", "size":"226.5", "side":"SELL", "hash":"859b15b757153a80a47275f8980c9f5958bb533e", "best_bid":"0.85", "best_ask":"0.86"}], "timestamp":"1778784200451", "event_type":"price_change"}
{"market":"0x2a903c589141bce4a1e50fb98b73397af6820942542793ab10b1df477e912b6e", "price_changes":[{"asset_id":"20436996072316278452977393149218961565084965483366669504673105646378938504388", "price":"0.71", "size":"646.38", "side":"BUY", "hash":"bf43606bc630cb414e9912e72f3eee2d700c47ff", "best_bid":"0.85", "best_ask":"0.86"}, {"asset_id":"68919878716222388542639225642064847629616106443780159680232863841946753372582", "price":"0.29", "size":"646.38", "side":"SELL", "hash":"9d166416cae99a33b422cae9346e8ec59968bbf2", "best_bid":"0.14", "best_ask":"0.15"}], "timestamp":"1778784200452", "event_type":"price_change"}
{"market":"0x2a903c589141bce4a1e50fb98b73397af6820942542793ab10b1df477e912b6e", "price_changes":[{"asset_id":"20436996072316278452977393149218961565084965483366669504673105646378938504388", "price":"0.7", "size":"164.3", "side":"BUY", "hash":"ada64a7b6c2886e05bcfe9b4c7417b2e92ecd045", "best_bid":"0.85", "best_ask":"0.86"}, {"asset_id":"68919878716222388542639225642064847629616106443780159680232863841946753372582", "price":"0.3", "size":"164.3", "side":"SELL", "hash":"3b50792e38298bbb4889cde35fca20a1511d3ff4", "best_bid":"0.14", "best_ask":"0.15"}], "timestamp":"1778784200453", "event_type":"price_change"}
{"market":"0x2a903c589141bce4a1e50fb98b73397af6820942542793ab10b1df477e912b6e", "price_changes":[{"asset_id":"68919878716222388542639225642064847629616106443780159680232863841946753372582", "price":"0.11", "size":"303.97", "side":"BUY", "hash":"ac839b74b8966a8f0db9ccef7a2b3b2ca813ba28", "best_bid":"0.14", "best_ask":"0.15"}, {"asset_id":"20436996072316278452977393149218961565084965483366669504673105646378938504388", "price":"0.89", "size":"303.97", "side":"SELL", "hash":"d6d0ab3a68c9ad3c83a0cac9d90e3573e67ca1cd", "best_bid":"0.85", "best_ask":"0.86"}], "timestamp":"1778784200454", "event_type":"price_change"}
{"market":"0x2a903c589141bce4a1e50fb98b73397af6820942542793ab10b1df477e912b6e", "price_changes":[{"asset_id":"68919878716222388542639225642064847629616106443780159680232863841946753372582", "price":"0.08", "size":"380.73", "side":"BUY", "hash":"4d3e3e1e5d27a23c209699c1cc3c768e63930dd9", "best_bid":"0.14", "best_ask":"0.15"}, {"asset_id":"20436996072316278452977393149218961565084965483366669504673105646378938504388", "price":"0.92", "size":"380.73", "side":"SELL", "hash":"03e5424a42fb4524cbe7d72f7886fb2df6df0574", "best_bid":"0.85", "best_ask":"0.86"}], "timestamp":"1778784200455", "event_type":"price_change"}
{"market":"0x2a903c589141bce4a1e50fb98b73397af6820942542793ab10b1df477e912b6e", "price_changes":[{"asset_id":"68919878716222388542639225642064847629616106443780159680232863841946753372582", "price":"0.02", "size":"1452.82", "side":"BUY", "hash":"d8b0d1b790e401eea8ff9cefd22894dd70757a1e", "best_bid":"0.14", "best_ask":"0.15"}, {"asset_id":"20436996072316278452977393149218961565084965483366669504673105646378938504388", "price":"0.98", "size":"1452.82", "side":"SELL", "hash":"9c48e9f9b531e3bab35b5be2e4a8a7e2500f7d99", "best_bid":"0.85", "best_ask":"0.86"}], "timestamp":"1778784200456", "event_type":"price_change"}
{"market":"0x2a903c589141bce4a1e50fb98b73397af6820942542793ab10b1df477e912b6e", "price_changes":[{"asset_id":"20436996072316278452977393149218961565084965483366669504673105646378938504388", "price":"0.91", "size":"366.69", "side":"SELL", "hash":"8d2ed8abdccc47ce53a6c00e5ead74fae6e61265", "best_bid":"0.85", "best_ask":"0.86"}, {"asset_id":"68919878716222388542639225642064847629616106443780159680232863841946753372582", "price":"0.09", "size":"366.69", "side":"BUY", "hash":"a428d819385c2b90578b532a707d2afbfeda85c2", "best_bid":"0.14", "best_ask":"0.15"}], "timestamp":"1778784200457", "event_type":"price_change"}
{"market":"0x2a903c589141bce4a1e50fb98b73397af6820942542793ab10b1df477e912b6e", "price_changes":[{"asset_id":"68919878716222388542639225642064847629616106443780159680232863841946753372582", "price":"0.1", "size":"531.26", "side":"BUY", "hash":"5c06cf8d7b78ab8425ca243b3ad04a3fe1837249", "best_bid":"0.14", "best_ask":"0.15"}, {"asset_id":"20436996072316278452977393149218961565084965483366669504673105646378938504388", "price":"0.9", "size":"531.26", "side":"SELL", "hash":"66aaf0b479ed8d42facfc4977f7ed54a0574ff8d", "best_bid":"0.85", "best_ask":"0.86"}], "timestamp":"1778784200458", "event_type":"price_change"}
{"market":"0x2a903c589141bce4a1e50fb98b73397af6820942542793ab10b1df477e912b6e", "price_changes":[{"asset_id":"20436996072316278452977393149218961565084965483366669504673105646378938504388", "price":"0.8", "size":"105", "side":"BUY", "hash":"a9a3515842231118b5e1c5fb9fde548b184cc7fd", "best_bid":"0.85", "best_ask":"0.86"}, {"asset_id":"68919878716222388542639225642064847629616106443780159680232863841946753372582", "price":"0.2", "size":"105", "side":"SELL", "hash":"b94b127e70afc151871757f6cd30ef71b7e0742a", "best_bid":"0.14", "best_ask":"0.15"}], "timestamp":"1778784200459", "event_type":"price_change"}
{"market":"0x2a903c589141bce4a1e50fb98b73397af6820942542793ab10b1df477e912b6e", "price_changes":[{"asset_id":"68919878716222388542639225642064847629616106443780159680232863841946753372582", "price":"0.14", "size":"225.33", "side":"BUY", "hash":"8fa480856fb27da9718293eebc723280df020a38", "best_bid":"0.14", "best_ask":"0.15"}, {"asset_id":"20436996072316278452977393149218961565084965483366669504673105646378938504388", "price":"0.86", "size":"225.33", "side":"SELL", "hash":"11c87457c5074a29924a83bc26fed07a37927434", "best_bid":"0.85", "best_ask":"0.86"}], "timestamp":"1778784200463", "event_type":"price_change"}
{"market":"0x2a903c589141bce4a1e50fb98b73397af6820942542793ab10b1df477e912b6e", "asset_id":"68919878716222388542639225642064847629616106443780159680232863841946753372582", "bids":[{"price":"0.01", "size":"11373.83"}, {"price":"0.02", "size":"1452.82"}, {"price":"0.03", "size":"1105.78"}, {"price":"0.04", "size":"837.82"}, {"price":"0.05", "size":"1055.72"}, {"price":"0.06", "size":"237.72"}, {"price":"0.07", "size":"337.1"}, {"price":"0.08", "size":"380.73"}, {"price":"0.09", "size":"366.69"}, {"price":"0.1", "size":"531.26"}, {"price":"0.11", "size":"303.97"}, {"price":"0.12", "size":"14"}, {"price":"0.13", "size":"86.87"}, {"price":"0.14", "size":"225.33"}], "asks":[{"price":"0.99", "size":"12015.61"}, {"price":"0.98", "size":"1219.45"}, {"price":"0.97", "size":"1111.98"}, {"price":"0.96", "size":"670.05"}, {"price":"0.95", "size":"549.45"}, {"price":"0.94", "size":"346.2"}, {"price":"0.93", "size":"902.05"}, {"price":"0.92", "size":"170.79"}, {"price":"0.91", "size":"234.6"}, {"price":"0.9", "size":"128"}, {"price":"0.89", "size":"142.6"}, {"price":"0.88", "size":"141.8"}, {"price":"0.87", "size":"144.81"}, {"price":"0.86", "size":"204.9"}, {"price":"0.85", "size":"113.5"}, {"price":"0.84", "size":"102.3"}, {"price":"0.83", "size":"101.3"}, {"price":"0.82", "size":"105.3"}, {"price":"0.81", "size":"199.5"}, {"price":"0.8", "size":"103.8"}, {"price":"0.79", "size":"98.1"}, {"price":"0.78", "size":"97.5"}, {"price":"0.77", "size":"96.89"}, {"price":"0.76", "size":"201.39"}, {"price":"0.75", "size":"116"}, {"price":"0.74", "size":"100.6"}, {"price":"0.73", "size":"95.2"}, {"price":"0.72", "size":"94.9"}, {"price":"0.71", "size":"199.6"}, {"price":"0.7", "size":"94.3"}, {"price":"0.69", "size":"108.28"}, {"price":"0.68", "size":"98.8"}, {"price":"0.67", "size":"718.6"}, {"price":"0.66", "size":"998.4"}, {"price":"0.65", "size":"507.3"}, {"price":"0.64", "size":"293"}, {"price":"0.63", "size":"292.9"}, {"price":"0.62", "size":"897.7"}, {"price":"0.61", "size":"397.6"}, {"price":"0.6", "size":"356.93"}, {"price":"0.59", "size":"297.4"}, {"price":"0.58", "size":"109.6"}, {"price":"0.57", "size":"131.48"}, {"price":"0.56", "size":"413.97"}, {"price":"0.55", "size":"334.2"}, {"price":"0.54", "size":"375.6"}, {"price":"0.53", "size":"292"}, {"price":"0.52", "size":"292.12"}, {"price":"0.51", "size":"402"}, {"price":"0.5", "size":"355.91"}, {"price":"0.49", "size":"312"}, {"price":"0.48", "size":"317"}, {"price":"0.47", "size":"802"}, {"price":"0.46", "size":"651.54"}, {"price":"0.45", "size":"346.64"}, {"price":"0.44", "size":"337.45"}, {"price":"0.43", "size":"434.89"}, {"price":"0.42", "size":"724.36"}, {"price":"0.41", "size":"412.4"}, {"price":"0.4", "size":"328.83"}, {"price":"0.39", "size":"297.6"}, {"price":"0.38", "size":"618.44"}, {"price":"0.37", "size":"297.9"}, {"price":"0.36", "size":"208"}, {"price":"0.35", "size":"335.14"}, {"price":"0.34", "size":"355.9"}, {"price":"0.33", "size":"343.6"}, {"price":"0.32", "size":"2085.88"}, {"price":"0.31", "size":"559"}, {"price":"0.3", "size":"164.3"}, {"price":"0.29", "size":"646.38"}, {"price":"0.28", "size":"159.9"}, {"price":"0.27", "size":"165.2"}, {"price":"0.26", "size":"230.6"}, {"price":"0.25", "size":"696"}, {"price":"0.24", "size":"146.39"}, {"price":"0.23", "size":"226.89"}, {"price":"0.22", "size":"217.5"}, {"price":"0.21", "size":"275.44"}, {"price":"0.2", "size":"105"}, {"price":"0.19", "size":"72.35"}, {"price":"0.18", "size":"284.82"}, {"price":"0.17", "size":"30"}, {"price":"0.16", "size":"105"}, {"price":"0.15", "size":"16.67"}], "hash":"8fa480856fb27da9718293eebc723280df020a38", "timestamp":"1778784200463", "event_type":"book"}
{"market":"0x2a903c589141bce4a1e50fb98b73397af6820942542793ab10b1df477e912b6e", "price_changes":[{"asset_id":"20436996072316278452977393149218961565084965483366669504673105646378938504388", "price":"0.01", "size":"12010.61", "side":"BUY", "hash":"3139a94fb88d4130ecf3055064a69882de377ba7", "best_bid":"0.85", "best_ask":"0.86"}, {"asset_id":"68919878716222388542639225642064847629616106443780159680232863841946753372582", "price":"0.99", "size":"12010.61", "side":"SELL", "hash":"48cae775d098995f2b04b1aa25f1f7e1b656f169", "best_bid":"0.14", "best_ask":"0.15"}], "timestamp":"1778784200465", "event_type":"price_change"}
{"market":"0x2a903c589141bce4a1e50fb98b73397af6820942542793ab10b1df477e912b6e", "price_changes":[{"asset_id":"68919878716222388542639225642064847629616106443780159680232863841946753372582", "price":"0.01", "size":"11378.83", "side":"BUY", "hash":"3b9ffc0f0eda6ec332d8b93ddd9fa0c327f8bddb", "best_bid":"0.14", "best_ask":"0.15"}, {"asset_id":"20436996072316278452977393149218961565084965483366669504673105646378938504388", "price":"0.99", "size":"11378.83", "side":"SELL", "hash":"916c1bd73eeabe470fc8d9a8d4158d633ca08677", "best_bid":"0.85", "best_ask":"0.86"}], "timestamp":"1778784200466", "event_type":"price_change"}
{"market":"0x2a903c589141bce4a1e50fb98b73397af6820942542793ab10b1df477e912b6e", "asset_id":"68919878716222388542639225642064847629616106443780159680232863841946753372582", "price":"0.15", "size":"20", "fee_rate_bps":"0", "side":"BUY", "timestamp":"1778784200465", "event_type":"last_trade_price", "transaction_hash":"0x3f793c5e499dcff6de95a4c02c7621ace8d6cc96f91a4d5b757244e57b5c9eb3"}
{"market":"0x2a903c589141bce4a1e50fb98b73397af6820942542793ab10b1df477e912b6e", "price_changes":[{"asset_id":"20436996072316278452977393149218961565084965483366669504673105646378938504388", "price":"0.84", "size":"101.67", "side":"BUY", "hash":"e5e1a794e350ae286b22b56fa88aa690f808a5bf", "best_bid":"0.84", "best_ask":"0.86"}, {"asset_id":"68919878716222388542639225642064847629616106443780159680232863841946753372582", "price":"0.16", "size":"101.67", "side":"SELL", "hash":"c1f2e3aed8208b97dc5133e1fee61cd050c4374d", "best_bid":"0.14", "best_ask":"0.16"}], "timestamp":"1778784200475", "event_type":"price_change"}
{"market":"0x2a903c589141bce4a1e50fb98b73397af6820942542793ab10b1df477e912b6e", "price_changes":[{"asset_id":"20436996072316278452977393149218961565084965483366669504673105646378938504388", "price":"0.85", "size":"0", "side":"BUY", "hash":"e5e1a794e350ae286b22b56fa88aa690f808a5bf", "best_bid":"0.84", "best_ask":"0.86"}, {"asset_id":"68919878716222388542639225642064847629616106443780159680232863841946753372582", "price":"0.15", "size":"0", "side":"SELL", "hash":"c1f2e3aed8208b97dc5133e1fee61cd050c4374d", "best_bid":"0.14", "best_ask":"0.16"}], "timestamp":"1778784200475", "event_type":"price_change"}
{"market":"0x2a903c589141bce4a1e50fb98b73397af6820942542793ab10b1df477e912b6e", "price_changes":[{"asset_id":"68919878716222388542639225642064847629616106443780159680232863841946753372582", "price":"0.15", "size":"0", "side":"SELL", "hash":"c1f2e3aed8208b97dc5133e1fee61cd050c4374d", "best_bid":"0.14", "best_ask":"0.16"}, {"asset_id":"20436996072316278452977393149218961565084965483366669504673105646378938504388", "price":"0.85", "size":"0", "side":"BUY", "hash":"e5e1a794e350ae286b22b56fa88aa690f808a5bf", "best_bid":"0.84", "best_ask":"0.86"}], "timestamp":"1778784200475", "event_type":"price_change"}
{"market":"0x2a903c589141bce4a1e50fb98b73397af6820942542793ab10b1df477e912b6e", "asset_id":"68919878716222388542639225642064847629616106443780159680232863841946753372582", "bids":[{"price":"0.01", "size":"11378.83"}, {"price":"0.02", "size":"1452.82"}, {"price":"0.03", "size":"1105.78"}, {"price":"0.04", "size":"837.82"}, {"price":"0.05", "size":"1055.72"}, {"price":"0.06", "size":"237.72"}, {"price":"0.07", "size":"337.1"}, {"price":"0.08", "size":"380.73"}, {"price":"0.09", "size":"366.69"}, {"price":"0.1", "size":"531.26"}, {"price":"0.11", "size":"303.97"}, {"price":"0.12", "size":"14"}, {"price":"0.13", "size":"86.87"}, {"price":"0.14", "size":"225.33"}], "asks":[{"price":"0.99", "size":"12010.61"}, {"price":"0.98", "size":"1219.45"}, {"price":"0.97", "size":"1111.98"}, {"price":"0.96", "size":"670.05"}, {"price":"0.95", "size":"549.45"}, {"price":"0.94", "size":"346.2"}, {"price":"0.93", "size":"902.05"}, {"price":"0.92", "size":"170.79"}, {"price":"0.91", "size":"234.6"}, {"price":"0.9", "size":"128"}, {"price":"0.89", "size":"142.6"}, {"price":"0.88", "size":"141.8"}, {"price":"0.87", "size":"144.81"}, {"price":"0.86", "size":"204.9"}, {"price":"0.85", "size":"113.5"}, {"price":"0.84", "size":"102.3"}, {"price":"0.83", "size":"101.3"}, {"price":"0.82", "size":"105.3"}, {"price":"0.81", "size":"199.5"}, {"price":"0.8", "size":"103.8"}, {"price":"0.79", "size":"98.1"}, {"price":"0.78", "size":"97.5"}, {"price":"0.77", "size":"96.89"}, {"price":"0.76", "size":"201.39"}, {"price":"0.75", "size":"116"}, {"price":"0.74", "size":"100.6"}, {"price":"0.73", "size":"95.2"}, {"price":"0.72", "size":"94.9"}, {"price":"0.71", "size":"199.6"}, {"price":"0.7", "size":"94.3"}, {"price":"0.69", "size":"108.28"}, {"price":"0.68", "size":"98.8"}, {"price":"0.67", "size":"718.6"}, {"price":"0.66", "size":"998.4"}, {"price":"0.65", "size":"507.3"}, {"price":"0.64", "size":"293"}, {"price":"0.63", "size":"292.9"}, {"price":"0.62", "size":"897.7"}, {"price":"0.61", "size":"397.6"}, {"price":"0.6", "size":"356.93"}, {"price":"0.59", "size":"297.4"}, {"price":"0.58", "size":"109.6"}, {"price":"0.57", "size":"131.48"}, {"price":"0.56", "size":"413.97"}, {"price":"0.55", "size":"334.2"}, {"price":"0.54", "size":"375.6"}, {"price":"0.53", "size":"292"}, {"price":"0.52", "size":"292.12"}, {"price":"0.51", "size":"402"}, {"price":"0.5", "size":"355.91"}, {"price":"0.49", "size":"312"}, {"price":"0.48", "size":"317"}, {"price":"0.47", "size":"802"}, {"price":"0.46", "size":"651.54"}, {"price":"0.45", "size":"346.64"}, {"price":"0.44", "size":"337.45"}, {"price":"0.43", "size":"434.89"}, {"price":"0.42", "size":"724.36"}, {"price":"0.41", "size":"412.4"}, {"price":"0.4", "size":"328.83"}, {"price":"0.39", "size":"297.6"}, {"price":"0.38", "size":"618.44"}, {"price":"0.37", "size":"297.9"}, {"price":"0.36", "size":"208"}, {"price":"0.35", "size":"335.14"}, {"price":"0.34", "size":"355.9"}, {"price":"0.33", "size":"343.6"}, {"price":"0.32", "size":"2085.88"}, {"price":"0.31", "size":"559"}, {"price":"0.3", "size":"164.3"}, {"price":"0.29", "size":"646.38"}, {"price":"0.28", "size":"159.9"}, {"price":"0.27", "size":"165.2"}, {"price":"0.26", "size":"230.6"}, {"price":"0.25", "size":"696"}, {"price":"0.24", "size":"146.39"}, {"price":"0.23", "size":"226.89"}, {"price":"0.22", "size":"217.5"}, {"price":"0.21", "size":"275.44"}, {"price":"0.2", "size":"105"}, {"price":"0.19", "size":"72.35"}, {"price":"0.18", "size":"284.82"}, {"price":"0.17", "size":"30"}, {"price":"0.16", "size":"101.67"}], "hash":"c1f2e3aed8208b97dc5133e1fee61cd050c4374d", "timestamp":"1778784200475", "event_type":"book"}
{"market":"0x2a903c589141bce4a1e50fb98b73397af6820942542793ab10b1df477e912b6e", "price_changes":[{"asset_id":"68919878716222388542639225642064847629616106443780159680232863841946753372582", "price":"0.18", "size":"289.82", "side":"SELL", "hash":"7ce7b1d4d39de9e73e14de0a263884850cdcb87e", "best_bid":"0.14", "best_ask":"0.16"}, {"asset_id":"20436996072316278452977393149218961565084965483366669504673105646378938504388", "price":"0.82", "size":"289.82", "side":"BUY", "hash":"68eeae04d9582b11a5172913a04a5b6ba04f0647", "best_bid":"0.84", "best_ask":"0.86"}], "timestamp":"1778784200477", "event_type":"price_change"}
{"market":"0x2a903c589141bce4a1e50fb98b73397af6820942542793ab10b1df477e912b6e", "price_changes":[{"asset_id":"68919878716222388542639225642064847629616106443780159680232863841946753372582", "price":"0.02", "size":"1427.82", "side":"BUY", "hash":"01699e2642512091a5965202478eabf07123a912", "best_bid":"0.14", "best_ask":"0.16"}, {"asset_id":"20436996072316278452977393149218961565084965483366669504673105646378938504388", "price":"0.98", "size":"1427.82", "side":"SELL", "hash":"aa2195aa24df1a9d613644b1543f8e5c7194c167", "best_bid":"0.84", "best_ask":"0.86"}], "timestamp":"1778784200482", "event_type":"price_change"}
{"market":"0x2a903c589141bce4a1e50fb98b73397af6820942542793ab10b1df477e912b6e", "price_changes":[{"asset_id":"20436996072316278452977393149218961565084965483366669504673105646378938504388", "price":"0.84", "size":"91.67", "side":"BUY", "hash":"fc2e5cd8cf5dcbcabb027d76907957ae847af31f", "best_bid":"0.84", "best_ask":"0.86"}, {"asset_id":"68919878716222388542639225642064847629616106443780159680232863841946753372582", "price":"0.16", "size":"91.67", "side":"SELL", "hash":"76160fdce5fc906bda3425880ec104f1de1a2b99", "best_bid":"0.14", "best_ask":"0.16"}], "timestamp":"1778784200484", "event_type":"price_change"}
{"market":"0x2a903c589141bce4a1e50fb98b73397af6820942542793ab10b1df477e912b6e", "asset_id":"68919878716222388542639225642064847629616106443780159680232863841946753372582", "bids":[{"price":"0.01", "size":"11378.83"}, {"price":"0.02", "size":"1427.82"}, {"price":"0.03", "size":"1105.78"}, {"price":"0.04", "size":"837.82"}, {"price":"0.05", "size":"1055.72"}, {"price":"0.06", "size":"237.72"}, {"price":"0.07", "size":"337.1"}, {"price":"0.08", "size":"380.73"}, {"price":"0.09", "size":"366.69"}, {"price":"0.1", "size":"531.26"}, {"price":"0.11", "size":"303.97"}, {"price":"0.12", "size":"14"}, {"price":"0.13", "size":"86.87"}, {"price":"0.14", "size":"225.33"}], "asks":[{"price":"0.99", "size":"12010.61"}, {"price":"0.98", "size":"1219.45"}, {"price":"0.97", "size":"1111.98"}, {"price":"0.96", "size":"670.05"}, {"price":"0.95", "size":"549.45"}, {"price":"0.94", "size":"346.2"}, {"price":"0.93", "size":"902.05"}, {"price":"0.92", "size":"170.79"}, {"price":"0.91", "size":"234.6"}, {"price":"0.9", "size":"128"}, {"price":"0.89", "size":"142.6"}, {"price":"0.88", "size":"141.8"}, {"price":"0.87", "size":"144.81"}, {"price":"0.86", "size":"204.9"}, {"price":"0.85", "size":"113.5"}, {"price":"0.84", "size":"102.3"}, {"price":"0.83", "size":"101.3"}, {"price":"0.82", "size":"105.3"}, {"price":"0.81", "size":"199.5"}, {"price":"0.8", "size":"103.8"}, {"price":"0.79", "size":"98.1"}, {"price":"0.78", "size":"97.5"}, {"price":"0.77", "size":"96.89"}, {"price":"0.76", "size":"201.39"}, {"price":"0.75", "size":"116"}, {"price":"0.74", "size":"100.6"}, {"price":"0.73", "size":"95.2"}, {"price":"0.72", "size":"94.9"}, {"price":"0.71", "size":"199.6"}, {"price":"0.7", "size":"94.3"}, {"price":"0.69", "size":"108.28"}, {"price":"0.68", "size":"98.8"}, {"price":"0.67", "size":"718.6"}, {"price":"0.66", "size":"998.4"}, {"price":"0.65", "size":"507.3"}, {"price":"0.64", "size":"293"}, {"price":"0.63", "size":"292.9"}, {"price":"0.62", "size":"897.7"}, {"price":"0.61", "size":"397.6"}, {"price":"0.6", "size":"356.93"}, {"price":"0.59", "size":"297.4"}, {"price":"0.58", "size":"109.6"}, {"price":"0.57", "size":"131.48"}, {"price":"0.56", "size":"413.97"}, {"price":"0.55", "size":"334.2"}, {"price":"0.54", "size":"375.6"}, {"price":"0.53", "size":"292"}, {"price":"0.52", "size":"292.12"}, {"price":"0.51", "size":"402"}, {"price":"0.5", "size":"355.91"}, {"price":"0.49", "size":"312"}, {"price":"0.48", "size":"317"}, {"price":"0.47", "size":"802"}, {"price":"0.46", "size":"651.54"}, {"price":"0.45", "size":"346.64"}, {"price":"0.44", "size":"337.45"}, {"price":"0.43", "size":"434.89"}, {"price":"0.42", "size":"724.36"}, {"price":"0.41", "size":"412.4"}, {"price":"0.4", "size":"328.83"}, {"price":"0.39", "size":"297.6"}, {"price":"0.38", "size":"618.44"}, {"price":"0.37", "size":"297.9"}, {"price":"0.36", "size":"208"}, {"price":"0.35", "size":"335.14"}, {"price":"0.34", "size":"355.9"}, {"price":"0.33", "size":"343.6"}, {"price":"0.32", "size":"2085.88"}, {"price":"0.31", "size":"559"}, {"price":"0.3", "size":"164.3"}, {"price":"0.29", "size":"646.38"}, {"price":"0.28", "size":"159.9"}, {"price":"0.27", "size":"165.2"}, {"price":"0.26", "size":"230.6"}, {"price":"0.25", "size":"696"}, {"price":"0.24", "size":"146.39"}, {"price":"0.23", "size":"226.89"}, {"price":"0.22", "size":"217.5"}, {"price":"0.21", "size":"275.44"}, {"price":"0.2", "size":"105"}, {"price":"0.19", "size":"72.35"}, {"price":"0.18", "size":"289.82"}, {"price":"0.17", "size":"30"}, {"price":"0.16", "size":"91.67"}], "hash":"76160fdce5fc906bda3425880ec104f1de1a2b99", "timestamp":"1778784200484", "event_type":"book"}
{"market":"0x2a903c589141bce4a1e50fb98b73397af6820942542793ab10b1df477e912b6e", "price_changes":[{"asset_id":"20436996072316278452977393149218961565084965483366669504673105646378938504388", "price":"0.76", "size":"166.39", "side":"BUY", "hash":"21f8c1d07a9215a44e24ea5ef5b38d35b9dbd782", "best_bid":"0.84", "best_ask":"0.86"}, {"asset_id":"68919878716222388542639225642064847629616106443780159680232863841946753372582", "price":"0.24", "size":"166.39", "side":"SELL", "hash":"c0f1800e3dd59ecdf87539d00ddd1aae019e6d48", "best_bid":"0.14", "best_ask":"0.16"}], "timestamp":"1778784200486", "event_type":"price_change"}
{"market":"0x2a903c589141bce4a1e50fb98b73397af6820942542793ab10b1df477e912b6e", "price_changes":[{"asset_id":"20436996072316278452977393149218961565084965483366669504673105646378938504388", "price":"0.84", "size":"81.67", "side":"BUY", "hash":"e24125568af5b5627ff5c5ecc4ff12603dc48319", "best_bid":"0.84", "best_ask":"0.86"}, {"asset_id":"68919878716222388542639225642064847629616106443780159680232863841946753372582", "price":"0.16", "size":"81.67", "side":"SELL", "hash":"85c49f8a6ebb772e734c5941a6f29f8ab613c7bb", "best_bid":"0.14", "best_ask":"0.16"}], "timestamp":"1778784200489", "event_type":"price_change"}
{"market":"0x2a903c589141bce4a1e50fb98b73397af6820942542793ab10b1df477e912b6e", "asset_id":"68919878716222388542639225642064847629616106443780159680232863841946753372582", "bids":[{"price":"0.01", "size":"11378.83"}, {"price":"0.02", "size":"1427.82"}, {"price":"0.03", "size":"1105.78"}, {"price":"0.04", "size":"837.82"}, {"price":"0.05", "size":"1055.72"}, {"price":"0.06", "size":"237.72"}, {"price":"0.07", "size":"337.1"}, {"price":"0.08", "size":"380.73"}, {"price":"0.09", "size":"366.69"}, {"price":"0.1", "size":"531.26"}, {"price":"0.11", "size":"303.97"}, {"price":"0.12", "size":"14"}, {"price":"0.13", "size":"86.87"}, {"price":"0.14", "size":"225.33"}], "asks":[{"price":"0.99", "size":"12010.61"}, {"price":"0.98", "size":"1219.45"}, {"price":"0.97", "size":"1111.98"}, {"price":"0.96", "size":"670.05"}, {"price":"0.95", "size":"549.45"}, {"price":"0.94", "size":"346.2"}, {"price":"0.93", "size":"902.05"}, {"price":"0.92", "size":"170.79"}, {"price":"0.91", "size":"234.6"}, {"price":"0.9", "size":"128"}, {"price":"0.89", "size":"142.6"}, {"price":"0.88", "size":"141.8"}, {"price":"0.87", "size":"144.81"}, {"price":"0.86", "size":"204.9"}, {"price":"0.85", "size":"113.5"}, {"price":"0.84", "size":"102.3"}, {"price":"0.83", "size":"101.3"}, {"price":"0.82", "size":"105.3"}, {"price":"0.81", "size":"199.5"}, {"price":"0.8", "size":"103.8"}, {"price":"0.79", "size":"98.1"}, {"price":"0.78", "size":"97.5"}, {"price":"0.77", "size":"96.89"}, {"price":"0.76", "size":"201.39"}, {"price":"0.75", "size":"116"}, {"price":"0.74", "size":"100.6"}, {"price":"0.73", "size":"95.2"}, {"price":"0.72", "size":"94.9"}, {"price":"0.71", "size":"199.6"}, {"price":"0.7", "size":"94.3"}, {"price":"0.69", "size":"108.28"}, {"price":"0.68", "size":"98.8"}, {"price":"0.67", "size":"718.6"}, {"price":"0.66", "size":"998.4"}, {"price":"0.65", "size":"507.3"}, {"price":"0.64", "size":"293"}, {"price":"0.63", "size":"292.9"}, {"price":"0.62", "size":"897.7"}, {"price":"0.61", "size":"397.6"}, {"price":"0.6", "size":"356.93"}, {"price":"0.59", "size":"297.4"}, {"price":"0.58", "size":"109.6"}, {"price":"0.57", "size":"131.48"}, {"price":"0.56", "size":"413.97"}, {"price":"0.55", "size":"334.2"}, {"price":"0.54", "size":"375.6"}, {"price":"0.53", "size":"292"}, {"price":"0.52", "size":"292.12"}, {"price":"0.51", "size":"402"}, {"price":"0.5", "size":"355.91"}, {"price":"0.49", "size":"312"}, {"price":"0.48", "size":"317"}, {"price":"0.47", "size":"802"}, {"price":"0.46", "size":"651.54"}, {"price":"0.45", "size":"346.64"}, {"price":"0.44", "size":"337.45"}, {"price":"0.43", "size":"434.89"}, {"price":"0.42", "size":"724.36"}, {"price":"0.41", "size":"412.4"}, {"price":"0.4", "size":"328.83"}, {"price":"0.39", "size":"297.6"}, {"price":"0.38", "size":"618.44"}, {"price":"0.37", "size":"297.9"}, {"price":"0.36", "size":"208"}, {"price":"0.35", "size":"335.14"}, {"price":"0.34", "size":"355.9"}, {"price":"0.33", "size":"343.6"}, {"price":"0.32", "size":"2085.88"}, {"price":"0.31", "size":"559"}, {"price":"0.3", "size":"164.3"}, {"price":"0.29", "size":"646.38"}, {"price":"0.28", "size":"159.9"}, {"price":"0.27", "size":"165.2"}, {"price":"0.26", "size":"230.6"}, {"price":"0.25", "size":"696"}, {"price":"0.24", "size":"166.39"}, {"price":"0.23", "size":"226.89"}, {"price":"0.22", "size":"217.5"}, {"price":"0.21", "size":"275.44"}, {"price":"0.2", "size":"105"}, {"price":"0.19", "size":"72.35"}, {"price":"0.18", "size":"289.82"}, {"price":"0.17", "size":"30"}, {"price":"0.16", "size":"81.67"}], "hash":"85c49f8a6ebb772e734c5941a6f29f8ab613c7bb", "timestamp":"1778784200489", "event_type":"book"}
{"market":"0x2a903c589141bce4a1e50fb98b73397af6820942542793ab10b1df477e912b6e", "price_changes":[{"asset_id":"20436996072316278452977393149218961565084965483366669504673105646378938504388", "price":"0.64", "size":"203", "side":"BUY", "hash":"e5432199fd058b94973d0420002f9b945146974b", "best_bid":"0.84", "best_ask":"0.86"}, {"asset_id":"68919878716222388542639225642064847629616106443780159680232863841946753372582", "price":"0.36", "size":"203", "side":"SELL", "hash":"06550e4a39c29946a6a43206488e7c8774483075", "best_bid":"0.14", "best_ask":"0.16"}], "timestamp":"1778784200491", "event_type":"price_change"}
{"market":"0x2a903c589141bce4a1e50fb98b73397af6820942542793ab10b1df477e912b6e", "price_changes":[{"asset_id":"20436996072316278452977393149218961565084965483366669504673105646378938504388", "price":"0.76", "size":"206.39", "side":"BUY", "hash":"9081c81bd4da5d4d3fd22c4f91471bdb0fdd989e", "best_bid":"0.84", "best_ask":"0.86"}, {"asset_id":"68919878716222388542639225642064847629616106443780159680232863841946753372582", "price":"0.24", "size":"206.39", "side":"SELL", "hash":"91dfd6eb4760ccbf75c761ee366f32f408b8a7e1", "best_bid":"0.14", "best_ask":"0.16"}], "timestamp":"1778784200492", "event_type":"price_change"}
{"market":"0x2a903c589141bce4a1e50fb98b73397af6820942542793ab10b1df477e912b6e", "price_changes":[{"asset_id":"20436996072316278452977393149218961565084965483366669504673105646378938504388", "price":"0.01", "size":"12015.61", "side":"BUY", "hash":"1da36c2ac9089a74f1b943a50981a978c133f223", "best_bid":"0.84", "best_ask":"0.86"}, {"asset_id":"68919878716222388542639225642064847629616106443780159680232863841946753372582", "price":"0.99", "size":"12015.61", "side":"SELL", "hash":"a3121bea7d0786774b666846312fa10931c48f65", "best_bid":"0.14", "best_ask":"0.16"}], "timestamp":"1778784200494", "event_type":"price_change"}
{"market":"0x2a903c589141bce4a1e50fb98b73397af6820942542793ab10b1df477e912b6e", "price_changes":[{"asset_id":"68919878716222388542639225642064847629616106443780159680232863841946753372582", "price":"0.01", "size":"11368.83", "side":"BUY", "hash":"b191f540f4761e7cc34cb0123ed924b536d9a252", "best_bid":"0.14", "best_ask":"0.16"}, {"asset_id":"20436996072316278452977393149218961565084965483366669504673105646378938504388", "price":"0.99", "size":"11368.83", "side":"SELL", "hash":"28ccafb705b4881081fd0cb88d9bf7b66e0ffe1f", "best_bid":"0.84", "best_ask":"0.86"}], "timestamp":"1778784200495", "event_type":"price_change"}
{"market":"0x2a903c589141bce4a1e50fb98b73397af6820942542793ab10b1df477e912b6e", "price_changes":[{"asset_id":"20436996072316278452977393149218961565084965483366669504673105646378938504388", "price":"0.83", "size":"60", "side":"BUY", "hash":"20d4c1056fcd91e6864c5d059658a85709176aca", "best_bid":"0.84", "best_ask":"0.86"}, {"asset_id":"68919878716222388542639225642064847629616106443780159680232863841946753372582", "price":"0.17", "size":"60", "side":"SELL", "hash":"ac9fe53088bedda2492392f6f85703e3b084495b", "best_bid":"0.14", "best_ask":"0.16"}], "timestamp":"1778784200496", "event_type":"price_change"}
{"market":"0x2a903c589141bce4a1e50fb98b73397af6820942542793ab10b1df477e912b6e", "price_changes":[{"asset_id":"20436996072316278452977393149218961565084965483366669504673105646378938504388", "price":"0.8", "size":"205", "side":"BUY", "hash":"f8b50aba46dfcf7715d0d834ae962c272b79958b", "best_bid":"0.84", "best_ask":"0.86"}, {"asset_id":"68919878716222388542639225642064847629616106443780159680232863841946753372582", "price":"0.2", "size":"205", "side":"SELL", "hash":"4114fe1c012d499b1215f1fc35a4a747a72ef7cb", "best_bid":"0.14", "best_ask":"0.16"}], "timestamp":"1778784200497", "event_type":"price_change"}
{"market":"0x2a903c589141bce4a1e50fb98b73397af6820942542793ab10b1df477e912b6e", "price_changes":[{"asset_id":"20436996072316278452977393149218961565084965483366669504673105646378938504388", "price":"0.82", "size":"314.82", "side":"BUY", "hash":"9491e893f93ee37a399aa07edb390465348eae2f", "best_bid":"0.84", "best_ask":"0.86"}, {"asset_id":"68919878716222388542639225642064847629616106443780159680232863841946753372582", "price":"0.18", "size":"314.82", "side":"SELL", "hash":"f1187c35a8cc10fa66a45e55d3bba7572df89c09", "best_bid":"0.14", "best_ask":"0.16"}], "timestamp":"1778784200499", "event_type":"price_change"}
{"market":"0x2a903c589141bce4a1e50fb98b73397af6820942542793ab10b1df477e912b6e", "price_changes":[{"asset_id":"20436996072316278452977393149218961565084965483366669504673105646378938504388", "price":"0.9", "size":"524", "side":"SELL", "hash":"50c76c35ccb60bdfcc429a3bafc5427701788447", "best_bid":"0.84", "best_ask":"0.86"}, {"asset_id":"68919878716222388542639225642064847629616106443780159680232863841946753372582", "price":"0.1", "size":"524", "side":"BUY", "hash":"40b60f9cc9c65f07bba9bc9ad59cacb597c89e6d", "best_bid":"0.14", "best_ask":"0.16"}], "timestamp":"1778784200500", "event_type":"price_change"}
{"market":"0x2a903c589141bce4a1e50fb98b73397af6820942542793ab10b1df477e912b6e", "asset_id":"68919878716222388542639225642064847629616106443780159680232863841946753372582", "price":"0.15", "size":"20", "fee_rate_bps":"0", "side":"BUY", "timestamp":"1778784200499", "event_type":"last_trade_price", "transaction_hash":"0x428b1cee594acb322ff54ac6e32e3d2ba6609365826a04a4a6884398590c5cc2"}
{"market":"0x2a903c589141bce4a1e50fb98b73397af6820942542793ab10b1df477e912b6e", "price_changes":[{"asset_id":"68919878716222388542639225642064847629616106443780159680232863841946753372582", "price":"0.22", "size":"224.5", "side":"SELL", "hash":"90e524b9366fb9a1921e741fd0e3646d60e00f7f", "best_bid":"0.14", "best_ask":"0.16"}, {"asset_id":"20436996072316278452977393149218961565084965483366669504673105646378938504388", "price":"0.78", "size":"224.5", "side":"BUY", "hash":"41076022ca9e3376afc5662dd2ddbf25af725f53", "best_bid":"0.84", "best_ask":"0.86"}], "timestamp":"1778784200501", "event_type":"price_change"}
{"market":"0x2a903c589141bce4a1e50fb98b73397af6820942542793ab10b1df477e912b6e", "asset_id":"68919878716222388542639225642064847629616106443780159680232863841946753372582", "price":"0.16", "size":"10", "fee_rate_bps":"0", "side":"BUY", "timestamp":"1778784200502", "event_type":"last_trade_price", "transaction_hash":"0x9fee196451e6f5b03cf903d285b177d47b46bc9ec5aae612cd15db5009278f09"}
{"market":"0x2a903c589141bce4a1e50fb98b73397af6820942542793ab10b1df477e912b6e", "price_changes":[{"asset_id":"68919878716222388542639225642064847629616106443780159680232863841946753372582", "price":"0.14", "size":"223.02", "side":"BUY", "hash":"461c4b71b08d66d635d40797d677563b3f87820f", "best_bid":"0.14", "best_ask":"0.16"}, {"asset_id":"20436996072316278452977393149218961565084965483366669504673105646378938504388", "price":"0.86", "size":"223.02", "side":"SELL", "hash":"e7f95966c6286cf1a6967adf4d3081de9cd1fd81", "best_bid":"0.84", "best_ask":"0.86"}], "timestamp":"1778784200505", "event_type":"price_change"}
{"market":"0x2a903c589141bce4a1e50fb98b73397af6820942542793ab10b1df477e912b6e", "asset_id":"68919878716222388542639225642064847629616106443780159680232863841946753372582", "bids":[{"price":"0.01", "size":"11368.83"}, {"price":"0.02", "size":"1427.82"}, {"price":"0.03", "size":"1105.78"}, {"price":"0.04", "size":"837.82"}, {"price":"0.05", "size":"1055.72"}, {"price":"0.06", "size":"237.72"}, {"price":"0.07", "size":"337.1"}, {"price":"0.08", "size":"380.73"}, {"price":"0.09", "size":"366.69"}, {"price":"0.1", "size":"524"}, {"price":"0.11", "size":"303.97"}, {"price":"0.12", "size":"14"}, {"price":"0.13", "size":"86.87"}, {"price":"0.14", "size":"223.02"}], "asks":[{"price":"0.99", "size":"12015.61"}, {"price":"0.98", "size":"1219.45"}, {"price":"0.97", "size":"1111.98"}, {"price":"0.96", "size":"670.05"}, {"price":"0.95", "size":"549.45"}, {"price":"0.94", "size":"346.2"}, {"price":"0.93", "size":"902.05"}, {"price":"0.92", "size":"170.79"}, {"price":"0.91", "size":"234.6"}, {"price":"0.9", "size":"128"}, {"price":"0.89", "size":"142.6"}, {"price":"0.88", "size":"141.8"}, {"price":"0.87", "size":"144.81"}, {"price":"0.86", "size":"204.9"}, {"price":"0.85", "size":"113.5"}, {"price":"0.84", "size":"102.3"}, {"price":"0.83", "size":"101.3"}, {"price":"0.82", "size":"105.3"}, {"price":"0.81", "size":"199.5"}, {"price":"0.8", "size":"103.8"}, {"price":"0.79", "size":"98.1"}, {"price":"0.78", "size":"97.5"}, {"price":"0.77", "size":"96.89"}, {"price":"0.76", "size":"201.39"}, {"price":"0.75", "size":"116"}, {"price":"0.74", "size":"100.6"}, {"price":"0.73", "size":"95.2"}, {"price":"0.72", "size":"94.9"}, {"price":"0.71", "size":"199.6"}, {"price":"0.7", "size":"94.3"}, {"price":"0.69", "size":"108.28"}, {"price":"0.68", "size":"98.8"}, {"price":"0.67", "size":"718.6"}, {"price":"0.66", "size":"998.4"}, {"price":"0.65", "size":"507.3"}, {"price":"0.64", "size":"293"}, {"price":"0.63", "size":"292.9"}, {"price":"0.62", "size":"897.7"}, {"price":"0.61", "size":"397.6"}, {"price":"0.6", "size":"356.93"}, {"price":"0.59", "size":"297.4"}, {"price":"0.58", "size":"109.6"}, {"price":"0.57", "size":"131.48"}, {"price":"0.56", "size":"413.97"}, {"price":"0.55", "size":"334.2"}, {"price":"0.54", "size":"375.6"}, {"price":"0.53", "size":"292"}, {"price":"0.52", "size":"292.12"}, {"price":"0.51", "size":"402"}, {"price":"0.5", "size":"355.91"}, {"price":"0.49", "size":"312"}, {"price":"0.48", "size":"317"}, {"price":"0.47", "size":"802"}, {"price":"0.46", "size":"651.54"}, {"price":"0.45", "size":"346.64"}, {"price":"0.44", "size":"337.45"}, {"price":"0.43", "size":"434.89"}, {"price":"0.42", "size":"724.36"}, {"price":"0.41", "size":"412.4"}, {"price":"0.4", "size":"328.83"}, {"price":"0.39", "size":"297.6"}, {"price":"0.38", "size":"618.44"}, {"price":"0.37", "size":"297.9"}, {"price":"0.36", "size":"203"}, {"price":"0.35", "size":"335.14"}, {"price":"0.34", "size":"355.9"}, {"price":"0.33", "size":"343.6"}, {"price":"0.32", "size":"2085.88"}, {"price":"0.31", "size":"559"}, {"price":"0.3", "size":"164.3"}, {"price":"0.29", "size":"646.38"}, {"price":"0.28", "size":"159.9"}, {"price":"0.27", "size":"165.2"}, {"price":"0.26", "size":"230.6"}, {"price":"0.25", "size":"696"}, {"price":"0.24", "size":"206.39"}, {"price":"0.23", "size":"226.89"}, {"price":"0.22", "size":"224.5"}, {"price":"0.21", "size":"275.44"}, {"price":"0.2", "size":"205"}, {"price":"0.19", "size":"72.35"}, {"price":"0.18", "size":"314.82"}, {"price":"0.17", "size":"60"}, {"price":"0.16", "size":"81.67"}], "hash":"461c4b71b08d66d635d40797d677563b3f87820f", "timestamp":"1778784200505", "event_type":"book"}
{"market":"0x2a903c589141bce4a1e50fb98b73397af6820942542793ab10b1df477e912b6e", "price_changes":[{"asset_id":"20436996072316278452977393149218961565084965483366669504673105646378938504388", "price":"0.85", "size":"50", "side":"BUY", "hash":"de02c4e54a9b20e5292cc4ce51c58106daeffe23", "best_bid":"0.85", "best_ask":"0.86"}, {"asset_id":"68919878716222388542639225642064847629616106443780159680232863841946753372582", "price":"0.15", "size":"50", "side":"SELL", "hash":"9932ee43976bd8c0c85ae57bd0c06d13f6483558", "best_bid":"0.14", "best_ask":"0.15"}], "timestamp":"1778784200507", "event_type":"price_change"}
{"market":"0x2a903c589141bce4a1e50fb98b73397af6820942542793ab10b1df477e912b6e", "asset_id":"68919878716222388542639225642064847629616106443780159680232863841946753372582", "price":"0.16", "size":"10", "fee_rate_bps":"0", "side":"BUY", "timestamp":"1778784200507", "event_type":"last_trade_price", "transaction_hash":"0xe99e8aa2a6fb94319bf8f714e043a1cb64b64fc5cc7500537831de4ed01b1af6"}
{"market":"0x2a903c589141bce4a1e50fb98b73397af6820942542793ab10b1df477e912b6e", "price_changes":[{"asset_id":"20436996072316278452977393149218961565084965483366669504673105646378938504388", "price":"0.83", "size":"30", "side":"BUY", "hash":"d453d501fcad258c63f2c407c5ddf656ca13dfeb", "best_bid":"0.85", "best_ask":"0.86"}, {"asset_id":"68919878716222388542639225642064847629616106443780159680232863841946753372582", "price":"0.17", "size":"30", "side":"SELL", "hash":"a81b67b9798b484f6fa7afca7e65d156c430a902", "best_bid":"0.14", "best_ask":"0.15"}], "timestamp":"1778784200515", "event_type":"price_change"}
{"market":"0x2a903c589141bce4a1e50fb98b73397af6820942542793ab10b1df477e912b6e", "price_changes":[{"asset_id":"20436996072316278452977393149218961565084965483366669504673105646378938504388", "price":"0.8", "size":"105", "side":"BUY", "hash":"d453d501fcad258c63f2c407c5ddf656ca13dfeb", "best_bid":"0.85", "best_ask":"0.86"}, {"asset_id":"68919878716222388542639225642064847629616106443780159680232863841946753372582", "price":"0.2", "size":"105", "side":"SELL", "hash":"a81b67b9798b484f6fa7afca7e65d156c430a902", "best_bid":"0.14", "best_ask":"0.15"}], "timestamp":"1778784200515", "event_type":"price_change"}
{"market":"0x2a903c589141bce4a1e50fb98b73397af6820942542793ab10b1df477e912b6e", "price_changes":[{"asset_id":"20436996072316278452977393149218961565084965483366669504673105646378938504388", "price":"0.84", "size":"79.04", "side":"BUY", "hash":"f68912340136adb67552e104139f71df0a24087d", "best_bid":"0.84", "best_ask":"0.86"}, {"asset_id":"68919878716222388542639225642064847629616106443780159680232863841946753372582", "price":"0.16", "size":"79.04", "side":"SELL", "hash":"b14430ed2f48117164d20e0720d00398210de485", "best_bid":"0.14", "best_ask":"0.16"}], "timestamp":"1778784200519", "event_type":"price_change"}
{"market":"0x2a903c589141bce4a1e50fb98b73397af6820942542793ab10b1df477e912b6e", "price_changes":[{"asset_id":"20436996072316278452977393149218961565084965483366669504673105646378938504388", "price":"0.85", "size":"0", "side":"BUY", "hash":"f68912340136adb67552e104139f71df0a24087d", "best_bid":"0.84", "best_ask":"0.86"}, {"asset_id":"68919878716222388542639225642064847629616106443780159680232863841946753372582", "price":"0.15", "size":"0", "side":"SELL", "hash":"b14430ed2f48117164d20e0720d00398210de485", "best_bid":"0.14", "best_ask":"0.16"}], "timestamp":"1778784200519", "event_type":"price_change"}
{"market":"0x2a903c589141bce4a1e50fb98b73397af6820942542793ab10b1df477e912b6e", "asset_id":"68919878716222388542639225642064847629616106443780159680232863841946753372582", "bids":[{"price":"0.01", "size":"11368.83"}, {"price":"0.02", "size":"1427.82"}, {"price":"0.03", "size":"1105.78"}, {"price":"0.04", "size":"837.82"}, {"price":"0.05", "size":"1055.72"}, {"price":"0.06", "size":"237.72"}, {"price":"0.07", "size":"337.1"}, {"price":"0.08", "size":"380.73"}, {"price":"0.09", "size":"366.69"}, {"price":"0.1", "size":"524"}, {"price":"0.11", "size":"303.97"}, {"price":"0.12", "size":"14"}, {"price":"0.13", "size":"86.87"}, {"price":"0.14", "size":"223.02"}], "asks":[{"price":"0.99", "size":"12015.61"}, {"price":"0.98", "size":"1219.45"}, {"price":"0.97", "size":"1111.98"}, {"price":"0.96", "size":"670.05"}, {"price":"0.95", "size":"549.45"}, {"price":"0.94", "size":"346.2"}, {"price":"0.93", "size":"902.05"}, {"price":"0.92", "size":"170.79"}, {"price":"0.91", "size":"234.6"}, {"price":"0.9", "size":"128"}, {"price":"0.89", "size":"142.6"}, {"price":"0.88", "size":"141.8"}, {"price":"0.87", "size":"144.81"}, {"price":"0.86", "size":"204.9"}, {"price":"0.85", "size":"113.5"}, {"price":"0.84", "size":"102.3"}, {"price":"0.83", "size":"101.3"}, {"price":"0.82", "size":"105.3"}, {"price":"0.81", "size":"199.5"}, {"price":"0.8", "size":"103.8"}, {"price":"0.79", "size":"98.1"}, {"price":"0.78", "size":"97.5"}, {"price":"0.77", "size":"96.89"}, {"price":"0.76", "size":"201.39"}, {"price":"0.75", "size":"116"}, {"price":"0.74", "size":"100.6"}, {"price":"0.73", "size":"95.2"}, {"price":"0.72", "size":"94.9"}, {"price":"0.71", "size":"199.6"}, {"price":"0.7", "size":"94.3"}, {"price":"0.69", "size":"108.28"}, {"price":"0.68", "size":"98.8"}, {"price":"0.67", "size":"718.6"}, {"price":"0.66", "size":"998.4"}, {"price":"0.65", "size":"507.3"}, {"price":"0.64", "size":"293"}, {"price":"0.63", "size":"292.9"}, {"price":"0.62", "size":"897.7"}, {"price":"0.61", "size":"397.6"}, {"price":"0.6", "size":"356.93"}, {"price":"0.59", "size":"297.4"}, {"price":"0.58", "size":"109.6"}, {"price":"0.57", "size":"131.48"}, {"price":"0.56", "size":"413.97"}, {"price":"0.55", "size":"334.2"}, {"price":"0.54", "size":"375.6"}, {"price":"0.53", "size":"292"}, {"price":"0.52", "size":"292.12"}, {"price":"0.51", "size":"402"}, {"price":"0.5", "size":"355.91"}, {"price":"0.49", "size":"312"}, {"price":"0.48", "size":"317"}, {"price":"0.47", "size":"802"}, {"price":"0.46", "size":"651.54"}, {"price":"0.45", "size":"346.64"}, {"price":"0.44", "size":"337.45"}, {"price":"0.43", "size":"434.89"}, {"price":"0.42", "size":"724.36"}, {"price":"0.41", "size":"412.4"}, {"price":"0.4", "size":"328.83"}, {"price":"0.39", "size":"297.6"}, {"price":"0.38", "size":"618.44"}, {"price":"0.37", "size":"297.9"}, {"price":"0.36", "size":"203"}, {"price":"0.35", "size":"335.14"}, {"price":"0.34", "size":"355.9"}, {"price":"0.33", "size":"343.6"}, {"price":"0.32", "size":"2085.88"}, {"price":"0.31", "size":"559"}, {"price":"0.3", "size":"164.3"}, {"price":"0.29", "size":"646.38"}, {"price":"0.28", "size":"159.9"}, {"price":"0.27", "size":"165.2"}, {"price":"0.26", "size":"230.6"}, {"price":"0.25", "size":"696"}, {"price":"0.24", "size":"206.39"}, {"price":"0.23", "size":"226.89"}, {"price":"0.22", "size":"224.5"}, {"price":"0.21", "size":"275.44"}, {"price":"0.2", "size":"105"}, {"price":"0.19", "size":"72.35"}, {"price":"0.18", "size":"314.82"}, {"price":"0.17", "size":"30"}, {"price":"0.16", "size":"79.04"}], "hash":"b14430ed2f48117164d20e0720d00398210de485", "timestamp":"1778784200519", "event_type":"book"}
{"market":"0x2a903c589141bce4a1e50fb98b73397af6820942542793ab10b1df477e912b6e", "price_changes":[{"asset_id":"68919878716222388542639225642064847629616106443780159680232863841946753372582", "price":"0.1", "size":"512", "side":"BUY", "hash":"38509ccdf4ab0e0f338adefd626376048ab25799", "best_bid":"0.14", "best_ask":"0.16"}, {"asset_id":"20436996072316278452977393149218961565084965483366669504673105646378938504388", "price":"0.9", "size":"512", "side":"SELL", "hash":"527a8e4e1ee4857a2bb9bd4b74eeb7ab83c2965b", "best_bid":"0.84", "best_ask":"0.86"}], "timestamp":"1778784200520", "event_type":"price_change"}
{"market":"0x2a903c589141bce4a1e50fb98b73397af6820942542793ab10b1df477e912b6e", "price_changes":[{"asset_id":"68919878716222388542639225642064847629616106443780159680232863841946753372582", "price":"0.07", "size":"347.1", "side":"BUY", "hash":"6ba87a0687eb19b0db0fef2f37498fe495615feb", "best_bid":"0.14", "best_ask":"0.16"}, {"asset_id":"20436996072316278452977393149218961565084965483366669504673105646378938504388", "price":"0.93", "size":"347.1", "side":"SELL", "hash":"0009a8a71a63d55899f9dcfeb34f42e2544950ef", "best_bid":"0.84", "best_ask":"0.86"}], "timestamp":"1778784200521", "event_type":"price_change"}
{"market":"0x2a903c589141bce4a1e50fb98b73397af6820942542793ab10b1df477e912b6e", "price_changes":[{"asset_id":"68919878716222388542639225642064847629616106443780159680232863841946753372582", "price":"0.11", "size":"308.97", "side":"BUY", "hash":"cee642dd985150c1952b2a28cb03f5462b86c790", "best_bid":"0.14", "best_ask":"0.16"}, {"asset_id":"20436996072316278452977393149218961565084965483366669504673105646378938504388", "price":"0.89", "size":"308.97", "side":"SELL", "hash":"6b5deea14d09662a6588bac9e266599b0d3c7234", "best_bid":"0.84", "best_ask":"0.86"}], "timestamp":"1778784200522", "event_type":"price_change"}
{"market":"0x2a903c589141bce4a1e50fb98b73397af6820942542793ab10b1df477e912b6e", "price_changes":[{"asset_id":"20436996072316278452977393149218961565084965483366669504673105646378938504388", "price":"0.75", "size":"706", "side":"BUY", "hash":"e1f5fc35a44bc5a2555d2fd5a266889b86f5cc88", "best_bid":"0.84", "best_ask":"0.86"}, {"asset_id":"68919878716222388542639225642064847629616106443780159680232863841946753372582", "price":"0.25", "size":"706", "side":"SELL", "hash":"aec45d0d01e62c74d4a6841656d0e5f0830936bf", "best_bid":"0.14", "best_ask":"0.16"}], "timestamp":"1778784200522", "event_type":"price_change"}
{"market":"0x2a903c589141bce4a1e50fb98b73397af6820942542793ab10b1df477e912b6e", "price_changes":[{"asset_id":"68919878716222388542639225642064847629616106443780159680232863841946753372582", "price":"0.01", "size":"11358.83", "side":"BUY", "hash":"74987b921363843bcb284239e0c2affa512005c1", "best_bid":"0.14", "best_ask":"0.16"}, {"asset_id":"20436996072316278452977393149218961565084965483366669504673105646378938504388", "price":"0.99", "size":"11358.83", "side":"SELL", "hash":"e03a70523df155ef0a6031b3d63d07b172275545", "best_bid":"0.84", "best_ask":"0.86"}], "timestamp":"1778784200523", "event_type":"price_change"}
{"market":"0x2a903c589141bce4a1e50fb98b73397af6820942542793ab10b1df477e912b6e", "price_changes":[{"asset_id":"68919878716222388542639225642064847629616106443780159680232863841946753372582", "price":"0.02", "size":"1397.82", "side":"BUY", "hash":"9223bf39733afa4a581f089425fd288449a91929", "best_bid":"0.14", "best_ask":"0.16"}, {"asset_id":"20436996072316278452977393149218961565084965483366669504673105646378938504388", "price":"0.98", "size":"1397.82", "side":"SELL", "hash":"ff40065146dd895e85010ffc6bc8f092a3d04804", "best_bid":"0.84", "best_ask":"0.86"}], "timestamp":"1778784200524", "event_type":"price_change"}
{"market":"0x2a903c589141bce4a1e50fb98b73397af6820942542793ab10b1df477e912b6e", "price_changes":[{"asset_id":"20436996072316278452977393149218961565084965483366669504673105646378938504388", "price":"0.37", "size":"892.9", "side":"BUY", "hash":"5630e9b8e69097bb65a3d60efb3bbb42b178d059", "best_bid":"0.84", "best_ask":"0.86"}, {"asset_id":"68919878716222388542639225642064847629616106443780159680232863841946753372582", "price":"0.63", "size":"892.9", "side":"SELL", "hash":"5dc4cec4085ccfcc70e7f1766cca578a5b1ab9c9", "best_bid":"0.14", "best_ask":"0.16"}], "timestamp":"1778784200525", "event_type":"price_change"}
{"market":"0x2a903c589141bce4a1e50fb98b73397af6820942542793ab10b1df477e912b6e", "price_changes":[{"asset_id":"20436996072316278452977393149218961565084965483366669504673105646378938504388", "price":"0.83", "size":"50", "side":"BUY", "hash":"5cb9ac3c5255a8c41a0d6b8f3d670c46248b196f", "best_bid":"0.84", "best_ask":"0.86"}, {"asset_id":"68919878716222388542639225642064847629616106443780159680232863841946753372582", "price":"0.17", "size":"50", "side":"SELL", "hash":"57548e816583eab5eaab3847cba9e40ee0b821e6", "best_bid":"0.14", "best_ask":"0.16"}], "timestamp":"1778784200526", "event_type":"price_change"}
{"market":"0x2a903c589141bce4a1e50fb98b73397af6820942542793ab10b1df477e912b6e", "price_changes":[{"asset_id":"20436996072316278452977393149218961565084965483366669504673105646378938504388", "price":"0.82", "size":"334.82", "side":"BUY", "hash":"be17e770324ea60e5981a0ee9fdfb3f9f825c259", "best_bid":"0.84", "best_ask":"0.86"}, {"asset_id":"68919878716222388542639225642064847629616106443780159680232863841946753372582", "price":"0.18", "size":"334.82", "side":"SELL", "hash":"cba8b656e014eb5c8aa9b073febf39753e7b9735", "best_bid":"0.14", "best_ask":"0.16"}], "timestamp":"1778784200528", "event_type":"price_change"}
{"market":"0x2a903c589141bce4a1e50fb98b73397af6820942542793ab10b1df477e912b6e", "price_changes":[{"asset_id":"20436996072316278452977393149218961565084965483366669504673105646378938504388", "price":"0.56", "size":"346.45", "side":"BUY", "hash":"c4685343289576ccef71bf99fcd37918a9cd5fec", "best_bid":"0.84", "best_ask":"0.86"}, {"asset_id":"68919878716222388542639225642064847629616106443780159680232863841946753372582", "price":"0.44", "size":"346.45", "side":"SELL", "hash":"16d2e109b69a1fe913b47dbc1d140c744cc0e844", "best_bid":"0.14", "best_ask":"0.16"}], "timestamp":"1778784200529", "event_type":"price_change"}
{"market":"0x2a903c589141bce4a1e50fb98b73397af6820942542793ab10b1df477e912b6e", "price_changes":[{"asset_id":"68919878716222388542639225642064847629616106443780159680232863841946753372582", "price":"0.08", "size":"410.73", "side":"BUY", "hash":"791d158d8a1c7b22e7f1c430af999b5113b68bb8", "best_bid":"0.14", "best_ask":"0.16"}, {"asset_id":"20436996072316278452977393149218961565084965483366669504673105646378938504388", "price":"0.92", "size":"410.73", "side":"SELL", "hash":"885b985584bf5bbc0b5b7226460804b35fb7a298", "best_bid":"0.84", "best_ask":"0.86"}], "timestamp":"1778784200530", "event_type":"price_change"}
{"market":"0x2a903c589141bce4a1e50fb98b73397af6820942542793ab10b1df477e912b6e", "price_changes":[{"asset_id":"68919878716222388542639225642064847629616106443780159680232863841946753372582", "price":"0.04", "size":"1237.82", "side":"BUY", "hash":"5a50988f5d9a52a487604ea3fa84b53e84afc7c9", "best_bid":"0.14", "best_ask":"0.16"}, {"asset_id":"20436996072316278452977393149218961565084965483366669504673105646378938504388", "price":"0.96", "size":"1237.82", "side":"SELL", "hash":"7e841cac9b583a4e1badfd5beea723d00ac809de", "best_bid":"0.84", "best_ask":"0.86"}], "timestamp":"1778784200531", "event_type":"price_change"}
{"market":"0x2a903c589141bce4a1e50fb98b73397af6820942542793ab10b1df477e912b6e", "price_changes":[{"asset_id":"68919878716222388542639225642064847629616106443780159680232863841946753372582", "price":"0.11", "size":"328.97", "side":"BUY", "hash":"a08dd108e8ff1e60247070cc5b656111ee08a98c", "best_bid":"0.14", "best_ask":"0.16"}, {"asset_id":"20436996072316278452977393149218961565084965483366669504673105646378938504388", "price":"0.89", "size":"328.97", "side":"SELL", "hash":"cd53ffc8520f1cd2d49f6789d6b35533f534a611", "best_bid":"0.84", "best_ask":"0.86"}], "timestamp":"1778784200532", "event_type":"price_change"}
{"market":"0x2a903c589141bce4a1e50fb98b73397af6820942542793ab10b1df477e912b6e", "price_changes":[{"asset_id":"68919878716222388542639225642064847629616106443780159680232863841946753372582", "price":"0.06", "size":"197.2", "side":"BUY", "hash":"9a34eac5314c90e98952160ceb5fbded31a4737c", "best_bid":"0.14", "best_ask":"0.16"}, {"asset_id":"20436996072316278452977393149218961565084965483366669504673105646378938504388", "price":"0.94", "size":"197.2", "side":"SELL", "hash":"2546fd45317e7ca8d78fcf8731cc637664f3e2a3", "best_bid":"0.84", "best_ask":"0.86"}], "timestamp":"1778784200533", "event_type":"price_change"}
{"market":"0x2a903c589141bce4a1e50fb98b73397af6820942542793ab10b1df477e912b6e", "price_changes":[{"asset_id":"20436996072316278452977393149218961565084965483366669504673105646378938504388", "price":"0.89", "size":"368.97", "side":"SELL", "hash":"119b21abeeaf532d6ec78eac26e390574c98b82a", "best_bid":"0.84", "best_ask":"0.86"}, {"asset_id":"68919878716222388542639225642064847629616106443780159680232863841946753372582", "price":"0.11", "size":"368.97", "side":"BUY", "hash":"4b75a246533513974fc103149f9813fbcea3f1ae", "best_bid":"0.14", "best_ask":"0.16"}], "timestamp":"1778784200533", "event_type":"price_change"}
{"market":"0x2a903c589141bce4a1e50fb98b73397af6820942542793ab10b1df477e912b6e", "price_changes":[{"asset_id":"20436996072316278452977393149218961565084965483366669504673105646378938504388", "price":"0.85", "size":"12", "side":"BUY", "hash":"d854489e3f020459dbf08e48f0f2103e91acf698", "best_bid":"0.85", "best_ask":"0.86"}, {"asset_id":"68919878716222388542639225642064847629616106443780159680232863841946753372582", "price":"0.15", "size":"12", "side":"SELL", "hash":"5fcdf4308793d4bf585f15d23dead0345474cad6", "best_bid":"0.14", "best_ask":"0.15"}], "timestamp":"1778784200534", "event_type":"price_change"}
{"market":"0x2a903c589141bce4a1e50fb98b73397af6820942542793ab10b1df477e912b6e", "price_changes":[{"asset_id":"68919878716222388542639225642064847629616106443780159680232863841946753372582", "price":"0.01", "size":"11363.83", "side":"BUY", "hash":"36e1c29b5aa208494499542ca28f400d6cc45aec", "best_bid":"0.14", "best_ask":"0.15"}, {"asset_id":"20436996072316278452977393149218961565084965483366669504673105646378938504388", "price":"0.99", "size":"11363.83", "side":"SELL", "hash":"33b64d1f9d07a9a4c0e8c830339cde13cd1e6071", "best_bid":"0.85", "best_ask":"0.86"}], "timestamp":"1778784200536", "event_type":"price_change"}
{"market":"0x2a903c589141bce4a1e50fb98b73397af6820942542793ab10b1df477e912b6e", "price_changes":[{"asset_id":"20436996072316278452977393149218961565084965483366669504673105646378938504388", "price":"0.84", "size":"95.04", "side":"BUY", "hash":"3a427e95367b4db20287f819401c0bdce80fbc34", "best_bid":"0.85", "best_ask":"0.86"}, {"asset_id":"68919878716222388542639225642064847629616106443780159680232863841946753372582", "price":"0.16", "size":"95.04", "side":"SELL", "hash":"111b2c719fca478758c4fe85517a298156540753", "best_bid":"0.14", "best_ask":"0.15"}], "timestamp":"1778784200536", "event_type":"price_change"}
{"market":"0x2a903c589141bce4a1e50fb98b73397af6820942542793ab10b1df477e912b6e", "price_changes":[{"asset_id":"68919878716222388542639225642064847629616106443780159680232863841946753372582", "price":"0.14", "size":"203.02", "side":"BUY", "hash":"8960d73f59d73bfa4b701896c03fd26e183fa3eb", "best_bid":"0.14", "best_ask":"0.15"}, {"asset_id":"20436996072316278452977393149218961565084965483366669504673105646378938504388", "price":"0.86", "size":"203.02", "side":"SELL", "hash":"d4882276220dbd104ad2200f2fce6fa079ae44fd", "best_bid":"0.85", "best_ask":"0.86"}], "timestamp":"1778784200539", "event_type":"price_change"}
{"market":"0x2a903c589141bce4a1e50fb98b73397af6820942542793ab10b1df477e912b6e", "asset_id":"68919878716222388542639225642064847629616106443780159680232863841946753372582", "bids":[{"price":"0.01", "size":"11363.83"}, {"price":"0.02", "size":"1397.82"}, {"price":"0.03", "size":"1105.78"}, {"price":"0.04", "size":"1237.82"}, {"price":"0.05", "size":"1055.72"}, {"price":"0.06", "size":"197.2"}, {"price":"0.07", "size":"347.1"}, {"price":"0.08", "size":"410.73"}, {"price":"0.09", "size":"366.69"}, {"price":"0.1", "size":"512"}, {"price":"0.11", "size":"368.97"}, {"price":"0.12", "size":"14"}, {"price":"0.13", "size":"86.87"}, {"price":"0.14", "size":"203.02"}], "asks":[{"price":"0.99", "size":"12015.61"}, {"price":"0.98", "size":"1219.45"}, {"price":"0.97", "size":"1111.98"}, {"price":"0.96", "size":"670.05"}, {"price":"0.95", "size":"549.45"}, {"price":"0.94", "size":"346.2"}, {"price":"0.93", "size":"902.05"}, {"price":"0.92", "size":"170.79"}, {"price":"0.91", "size":"234.6"}, {"price":"0.9", "size":"128"}, {"price":"0.89", "size":"142.6"}, {"price":"0.88", "size":"141.8"}, {"price":"0.87", "size":"144.81"}, {"price":"0.86", "size":"204.9"}, {"price":"0.85", "size":"113.5"}, {"price":"0.84", "size":"102.3"}, {"price":"0.83", "size":"101.3"}, {"price":"0.82", "size":"105.3"}, {"price":"0.81", "size":"199.5"}, {"price":"0.8", "size":"103.8"}, {"price":"0.79", "size":"98.1"}, {"price":"0.78", "size":"97.5"}, {"price":"0.77", "size":"96.89"}, {"price":"0.76", "size":"201.39"}, {"price":"0.75", "size":"116"}, {"price":"0.74", "size":"100.6"}, {"price":"0.73", "size":"95.2"}, {"price":"0.72", "size":"94.9"}, {"price":"0.71", "size":"199.6"}, {"price":"0.7", "size":"94.3"}, {"price":"0.69", "size":"108.28"}, {"price":"0.68", "size":"98.8"}, {"price":"0.67", "size":"718.6"}, {"price":"0.66", "size":"998.4"}, {"price":"0.65", "size":"507.3"}, {"price":"0.64", "size":"293"}, {"price":"0.63", "size":"892.9"}, {"price":"0.62", "size":"897.7"}, {"price":"0.61", "size":"397.6"}, {"price":"0.6", "size":"356.93"}, {"price":"0.59", "size":"297.4"}, {"price":"0.58", "size":"109.6"}, {"price":"0.57", "size":"131.48"}, {"price":"0.56", "size":"413.97"}, {"price":"0.55", "size":"334.2"}, {"price":"0.54", "size":"375.6"}, {"price":"0.53", "size":"292"}, {"price":"0.52", "size":"292.12"}, {"price":"0.51", "size":"402"}, {"price":"0.5", "size":"355.91"}, {"price":"0.49", "size":"312"}, {"price":"0.48", "size":"317"}, {"price":"0.47", "size":"802"}, {"price":"0.46", "size":"651.54"}, {"price":"0.45", "size":"346.64"}, {"price":"0.44", "size":"346.45"}, {"price":"0.43", "size":"434.89"}, {"price":"0.42", "size":"724.36"}, {"price":"0.41", "size":"412.4"}, {"price":"0.4", "size":"328.83"}, {"price":"0.39", "size":"297.6"}, {"price":"0.38", "size":"618.44"}, {"price":"0.37", "size":"297.9"}, {"price":"0.36", "size":"203"}, {"price":"0.35", "size":"335.14"}, {"price":"0.34", "size":"355.9"}, {"price":"0.33", "size":"343.6"}, {"price":"0.32", "size":"2085.88"}, {"price":"0.31", "size":"559"}, {"price":"0.3", "size":"164.3"}, {"price":"0.29", "size":"646.38"}, {"price":"0.28", "size":"159.9"}, {"price":"0.27", "size":"165.2"}, {"price":"0.26", "size":"230.6"}, {"price":"0.25", "size":"706"}, {"price":"0.24", "size":"206.39"}, {"price":"0.23", "size":"226.89"}, {"price":"0.22", "size":"224.5"}, {"price":"0.21", "size":"275.44"}, {"price":"0.2", "size":"105"}, {"price":"0.19", "size":"72.35"}, {"price":"0.18", "size":"334.82"}, {"price":"0.17", "size":"50"}, {"price":"0.16", "size":"95.04"}, {"price":"0.15", "size":"12"}], "hash":"8960d73f59d73bfa4b701896c03fd26e183fa3eb", "timestamp":"1778784200539", "event_type":"book"}
{"market":"0x2a903c589141bce4a1e50fb98b73397af6820942542793ab10b1df477e912b6e", "price_changes":[{"asset_id":"20436996072316278452977393149218961565084965483366669504673105646378938504388", "price":"0.84", "size":"109.04", "side":"BUY", "hash":"fd6d84134ee7aad5096b53b607436ede89c6a182", "best_bid":"0.85", "best_ask":"0.86"}, {"asset_id":"68919878716222388542639225642064847629616106443780159680232863841946753372582", "price":"0.16", "size":"109.04", "side":"SELL", "hash":"9d2a2040e684ebea2d4f5628b2bd42db6a971dee", "best_bid":"0.14", "best_ask":"0.15"}], "timestamp":"1778784200541", "event_type":"price_change"}
{"market":"0x2a903c589141bce4a1e50fb98b73397af6820942542793ab10b1df477e912b6e", "price_changes":[{"asset_id":"68919878716222388542639225642064847629616106443780159680232863841946753372582", "price":"0.14", "size":"194.92", "side":"BUY", "hash":"3ec8b4c7b815916c961a8f85a8aab35a57a7b4d1", "best_bid":"0.14", "best_ask":"0.15"}, {"asset_id":"20436996072316278452977393149218961565084965483366669504673105646378938504388", "price":"0.86", "size":"194.92", "side":"SELL", "hash":"0fb910485f6546d1aafd8566a48033a0d1037a7a", "best_bid":"0.85", "best_ask":"0.86"}], "timestamp":"1778784200543", "event_type":"price_change"}
{"market":"0x2a903c589141bce4a1e50fb98b73397af6820942542793ab10b1df477e912b6e", "asset_id":"68919878716222388542639225642064847629616106443780159680232863841946753372582", "bids":[{"price":"0.01", "size":"11363.83"}, {"price":"0.02", "size":"1397.82"}, {"price":"0.03", "size":"1105.78"}, {"price":"0.04", "size":"1237.82"}, {"price":"0.05", "size":"1055.72"}, {"price":"0.06", "size":"197.2"}, {"price":"0.07", "size":"347.1"}, {"price":"0.08", "size":"410.73"}, {"price":"0.09", "size":"366.69"}, {"price":"0.1", "size":"512"}, {"price":"0.11", "size":"368.97"}, {"price":"0.12", "size":"14"}, {"price":"0.13", "size":"86.87"}, {"price":"0.14", "size":"194.92"}], "asks":[{"price":"0.99", "size":"12015.61"}, {"price":"0.98", "size":"1219.45"}, {"price":"0.97", "size":"1111.98"}, {"price":"0.96", "size":"670.05"}, {"price":"0.95", "size":"549.45"}, {"price":"0.94", "size":"346.2"}, {"price":"0.93", "size":"902.05"}, {"price":"0.92", "size":"170.79"}, {"price":"0.91", "size":"234.6"}, {"price":"0.9", "size":"128"}, {"price":"0.89", "size":"142.6"}, {"price":"0.88", "size":"141.8"}, {"price":"0.87", "size":"144.81"}, {"price":"0.86", "size":"204.9"}, {"price":"0.85", "size":"113.5"}, {"price":"0.84", "size":"102.3"}, {"price":"0.83", "size":"101.3"}, {"price":"0.82", "size":"105.3"}, {"price":"0.81", "size":"199.5"}, {"price":"0.8", "size":"103.8"}, {"price":"0.79", "size":"98.1"}, {"price":"0.78", "size":"97.5"}, {"price":"0.77", "size":"96.89"}, {"price":"0.76", "size":"201.39"}, {"price":"0.75", "size":"116"}, {"price":"0.74", "size":"100.6"}, {"price":"0.73", "size":"95.2"}, {"price":"0.72", "size":"94.9"}, {"price":"0.71", "size":"199.6"}, {"price":"0.7", "size":"94.3"}, {"price":"0.69", "size":"108.28"}, {"price":"0.68", "size":"98.8"}, {"price":"0.67", "size":"718.6"}, {"price":"0.66", "size":"998.4"}, {"price":"0.65", "size":"507.3"}, {"price":"0.64", "size":"293"}, {"price":"0.63", "size":"892.9"}, {"price":"0.62", "size":"897.7"}, {"price":"0.61", "size":"397.6"}, {"price":"0.6", "size":"356.93"}, {"price":"0.59", "size":"297.4"}, {"price":"0.58", "size":"109.6"}, {"price":"0.57", "size":"131.48"}, {"price":"0.56", "size":"413.97"}, {"price":"0.55", "size":"334.2"}, {"price":"0.54", "size":"375.6"}, {"price":"0.53", "size":"292"}, {"price":"0.52", "size":"292.12"}, {"price":"0.51", "size":"402"}, {"price":"0.5", "size":"355.91"}, {"price":"0.49", "size":"312"}, {"price":"0.48", "size":"317"}, {"price":"0.47", "size":"802"}, {"price":"0.46", "size":"651.54"}, {"price":"0.45", "size":"346.64"}, {"price":"0.44", "size":"346.45"}, {"price":"0.43", "size":"434.89"}, {"price":"0.42", "size":"724.36"}, {"price":"0.41", "size":"412.4"}, {"price":"0.4", "size":"328.83"}, {"price":"0.39", "size":"297.6"}, {"price":"0.38", "size":"618.44"}, {"price":"0.37", "size":"297.9"}, {"price":"0.36", "size":"203"}, {"price":"0.35", "size":"335.14"}, {"price":"0.34", "size":"355.9"}, {"price":"0.33", "size":"343.6"}, {"price":"0.32", "size":"2085.88"}, {"price":"0.31", "size":"559"}, {"price":"0.3", "size":"164.3"}, {"price":"0.29", "size":"646.38"}, {"price":"0.28", "size":"159.9"}, {"price":"0.27", "size":"165.2"}, {"price":"0.26", "size":"230.6"}, {"price":"0.25", "size":"706"}, {"price":"0.24", "size":"206.39"}, {"price":"0.23", "size":"226.89"}, {"price":"0.22", "size":"224.5"}, {"price":"0.21", "size":"275.44"}, {"price":"0.2", "size":"105"}, {"price":"0.19", "size":"72.35"}, {"price":"0.18", "size":"334.82"}, {"price":"0.17", "size":"50"}, {"price":"0.16", "size":"109.04"}, {"price":"0.15", "size":"12"}], "hash":"3ec8b4c7b815916c961a8f85a8aab35a57a7b4d1", "timestamp":"1778784200543", "event_type":"book"}
{"market":"0x2a903c589141bce4a1e50fb98b73397af6820942542793ab10b1df477e912b6e", "price_changes":[{"asset_id":"68919878716222388542639225642064847629616106443780159680232863841946753372582", "price":"0.11", "size":"373.97", "side":"BUY", "hash":"6a602e85d4ff5cee3ba456491317b842d9233c11", "best_bid":"0.14", "best_ask":"0.15"}, {"asset_id":"20436996072316278452977393149218961565084965483366669504673105646378938504388", "price":"0.89", "size":"373.97", "side":"SELL", "hash":"28b1c6e315342e831b6a98fa404012364b6ce876", "best_bid":"0.85", "best_ask":"0.86"}], "timestamp":"1778784200545", "event_type":"price_change"}
{"market":"0x2a903c589141bce4a1e50fb98b73397af6820942542793ab10b1df477e912b6e", "price_changes":[{"asset_id":"68919878716222388542639225642064847629616106443780159680232863841946753372582", "price":"0.11", "size":"378.97", "side":"BUY", "hash":"fe3c2bb4dd0f4cfd286c92593ebe94d643524b1a", "best_bid":"0.14", "best_ask":"0.15"}, {"asset_id":"20436996072316278452977393149218961565084965483366669504673105646378938504388", "price":"0.89", "size":"378.97", "side":"SELL", "hash":"70fa4ed481482675ba1a9395ca20e3b30e0450e0", "best_bid":"0.85", "best_ask":"0.86"}], "timestamp":"1778784200546", "event_type":"price_change"}
{"market":"0x2a903c589141bce4a1e50fb98b73397af6820942542793ab10b1df477e912b6e", "price_changes":[{"asset_id":"20436996072316278452977393149218961565084965483366669504673105646378938504388", "price":"0.72", "size":"139.9", "side":"BUY", "hash":"d5dd6c5bdad3bc413d025324531903ff41ce74f4", "best_bid":"0.85", "best_ask":"0.86"}, {"asset_id":"68919878716222388542639225642064847629616106443780159680232863841946753372582", "price":"0.28", "size":"139.9", "side":"SELL", "hash":"fee6fed56d775312708749fe9cdb3a0104a6d997", "best_bid":"0.14", "best_ask":"0.15"}], "timestamp":"1778784200547", "event_type":"price_change"}
{"market":"0x2a903c589141bce4a1e50fb98b73397af6820942542793ab10b1df477e912b6e", "price_changes":[{"asset_id":"20436996072316278452977393149218961565084965483366669504673105646378938504388", "price":"0.85", "size":"5.33", "side":"BUY", "hash":"079658dca8e117dceff7728652e49286be2f3325", "best_bid":"0.85", "best_ask":"0.86"}, {"asset_id":"68919878716222388542639225642064847629616106443780159680232863841946753372582", "price":"0.15", "size":"5.33", "side":"SELL", "hash":"8bd12e6fdcab65bd1e31268b7ad240c572511b9b", "best_bid":"0.14", "best_ask":"0.15"}], "timestamp":"1778784200550", "event_type":"price_change"}
{"market":"0x2a903c589141bce4a1e50fb98b73397af6820942542793ab10b1df477e912b6e", "asset_id":"68919878716222388542639225642064847629616106443780159680232863841946753372582", "bids":[{"price":"0.01", "size":"11363.83"}, {"price":"0.02", "size":"1397.82"}, {"price":"0.03", "size":"1105.78"}, {"price":"0.04", "size":"1237.82"}, {"price":"0.05", "size":"1055.72"}, {"price":"0.06", "size":"197.2"}, {"price":"0.07", "size":"347.1"}, {"price":"0.08", "size":"410.73"}, {"price":"0.09", "size":"366.69"}, {"price":"0.1", "size":"512"}, {"price":"0.11", "size":"378.97"}, {"price":"0.12", "size":"14"}, {"price":"0.13", "size":"86.87"}, {"price":"0.14", "size":"194.92"}], "asks":[{"price":"0.99", "size":"12015.61"}, {"price":"0.98", "size":"1219.45"}, {"price":"0.97", "size":"1111.98"}, {"price":"0.96", "size":"670.05"}, {"price":"0.95", "size":"549.45"}, {"price":"0.94", "size":"346.2"}, {"price":"0.93", "size":"902.05"}, {"price":"0.92", "size":"170.79"}, {"price":"0.91", "size":"234.6"}, {"price":"0.9", "size":"128"}, {"price":"0.89", "size":"142.6"}, {"price":"0.88", "size":"141.8"}, {"price":"0.87", "size":"144.81"}, {"price":"0.86", "size":"204.9"}, {"price":"0.85", "size":"113.5"}, {"price":"0.84", "size":"102.3"}, {"price":"0.83", "size":"101.3"}, {"price":"0.82", "size":"105.3"}, {"price":"0.81", "size":"199.5"}, {"price":"0.8", "size":"103.8"}, {"price":"0.79", "size":"98.1"}, {"price":"0.78", "size":"97.5"}, {"price":"0.77", "size":"96.89"}, {"price":"0.76", "size":"201.39"}, {"price":"0.75", "size":"116"}, {"price":"0.74", "size":"100.6"}, {"price":"0.73", "size":"95.2"}, {"price":"0.72", "size":"94.9"}, {"price":"0.71", "size":"199.6"}, {"price":"0.7", "size":"94.3"}, {"price":"0.69", "size":"108.28"}, {"price":"0.68", "size":"98.8"}, {"price":"0.67", "size":"718.6"}, {"price":"0.66", "size":"998.4"}, {"price":"0.65", "size":"507.3"}, {"price":"0.64", "size":"293"}, {"price":"0.63", "size":"892.9"}, {"price":"0.62", "size":"897.7"}, {"price":"0.61", "size":"397.6"}, {"price":"0.6", "size":"356.93"}, {"price":"0.59", "size":"297.4"}, {"price":"0.58", "size":"109.6"}, {"price":"0.57", "size":"131.48"}, {"price":"0.56", "size":"413.97"}, {"price":"0.55", "size":"334.2"}, {"price":"0.54", "size":"375.6"}, {"price":"0.53", "size":"292"}, {"price":"0.52", "size":"292.12"}, {"price":"0.51", "size":"402"}, {"price":"0.5", "size":"355.91"}, {"price":"0.49", "size":"312"}, {"price":"0.48", "size":"317"}, {"price":"0.47", "size":"802"}, {"price":"0.46", "size":"651.54"}, {"price":"0.45", "size":"346.64"}, {"price":"0.44", "size":"346.45"}, {"price":"0.43", "size":"434.89"}, {"price":"0.42", "size":"724.36"}, {"price":"0.41", "size":"412.4"}, {"price":"0.4", "size":"328.83"}, {"price":"0.39", "size":"297.6"}, {"price":"0.38", "size":"618.44"}, {"price":"0.37", "size":"297.9"}, {"price":"0.36", "size":"203"}, {"price":"0.35", "size":"335.14"}, {"price":"0.34", "size":"355.9"}, {"price":"0.33", "size":"343.6"}, {"price":"0.32", "size":"2085.88"}, {"price":"0.31", "size":"559"}, {"price":"0.3", "size":"164.3"}, {"price":"0.29", "size":"646.38"}, {"price":"0.28", "size":"139.9"}, {"price":"0.27", "size":"165.2"}, {"price":"0.26", "size":"230.6"}, {"price":"0.25", "size":"706"}, {"price":"0.24", "size":"206.39"}, {"price":"0.23", "size":"226.89"}, {"price":"0.22", "size":"224.5"}, {"price":"0.21", "size":"275.44"}, {"price":"0.2", "size":"105"}, {"price":"0.19", "size":"72.35"}, {"price":"0.18", "size":"334.82"}, {"price":"0.17", "size":"50"}, {"price":"0.16", "size":"109.04"}, {"price":"0.15", "size":"5.33"}], "hash":"8bd12e6fdcab65bd1e31268b7ad240c572511b9b", "timestamp":"1778784200550", "event_type":"book"}
{"market":"0x2a903c589141bce4a1e50fb98b73397af6820942542793ab10b1df477e912b6e", "price_changes":[{"asset_id":"20436996072316278452977393149218961565084965483366669504673105646378938504388", "price":"0.56", "size":"341.45", "side":"BUY", "hash":"6c5341b8cbc4387b4bdce8fef7eee67988c24867", "best_bid":"0.85", "best_ask":"0.86"}, {"asset_id":"68919878716222388542639225642064847629616106443780159680232863841946753372582", "price":"0.44", "size":"341.45", "side":"SELL", "hash":"fb904937a33b4557e87a4d2d7eff4d064ef67761", "best_bid":"0.14", "best_ask":"0.15"}], "timestamp":"1778784200552", "event_type":"price_change"}
{"market":"0x2a903c589141bce4a1e50fb98b73397af6820942542793ab10b1df477e912b6e", "price_changes":[{"asset_id":"68919878716222388542639225642064847629616106443780159680232863841946753372582", "price":"0.11", "size":"393.97", "side":"BUY", "hash":"d24d48ac148acd962202c84ac10e8e78d23a3532", "best_bid":"0.14", "best_ask":"0.15"}, {"asset_id":"20436996072316278452977393149218961565084965483366669504673105646378938504388", "price":"0.89", "size":"393.97", "side":"SELL", "hash":"73843c6143825d71ca3053c489cad205c10b6040", "best_bid":"0.85", "best_ask":"0.86"}], "timestamp":"1778784200554", "event_type":"price_change"}
{"market":"0x2a903c589141bce4a1e50fb98b73397af6820942542793ab10b1df477e912b6e", "price_changes":[{"asset_id":"68919878716222388542639225642064847629616106443780159680232863841946753372582", "price":"0.11", "size":"398.97", "side":"BUY", "hash":"0fe3eafb51070f3e20f10f6335a667e9bfef90dd", "best_bid":"0.14", "best_ask":"0.15"}, {"asset_id":"20436996072316278452977393149218961565084965483366669504673105646378938504388", "price":"0.89", "size":"398.97", "side":"SELL", "hash":"1700be12fd06b40a7b4419fcb1f02f53ab350866", "best_bid":"0.85", "best_ask":"0.86"}], "timestamp":"1778784200555", "event_type":"price_change"}
{"market":"0x2a903c589141bce4a1e50fb98b73397af6820942542793ab10b1df477e912b6e", "price_changes":[{"asset_id":"20436996072316278452977393149218961565084965483366669504673105646378938504388", "price":"0.84", "size":"82.78", "side":"BUY", "hash":"3de0d01043515c378cabd27d8cf549c4ad819e58", "best_bid":"0.84", "best_ask":"0.86"}, {"asset_id":"68919878716222388542639225642064847629616106443780159680232863841946753372582", "price":"0.16", "size":"82.78", "side":"SELL", "hash":"2631ae9ddd9b04ff6ba27314825bf70ffbfe43f3", "best_bid":"0.14", "best_ask":"0.16"}], "timestamp":"1778784200558", "event_type":"price_change"}
{"market":"0x2a903c589141bce4a1e50fb98b73397af6820942542793ab10b1df477e912b6e", "price_changes":[{"asset_id":"20436996072316278452977393149218961565084965483366669504673105646378938504388", "price":"0.85", "size":"0", "side":"BUY", "hash":"3de0d01043515c378cabd27d8cf549c4ad819e58", "best_bid":"0.84", "best_ask":"0.86"}, {"asset_id":"68919878716222388542639225642064847629616106443780159680232863841946753372582", "price":"0.15", "size":"0", "side":"SELL", "hash":"2631ae9ddd9b04ff6ba27314825bf70ffbfe43f3", "best_bid":"0.14", "best_ask":"0.16"}], "timestamp":"1778784200558", "event_type":"price_change"}
{"market":"0x2a903c589141bce4a1e50fb98b73397af6820942542793ab10b1df477e912b6e", "asset_id":"68919878716222388542639225642064847629616106443780159680232863841946753372582", "bids":[{"price":"0.01", "size":"11363.83"}, {"price":"0.02", "size":"1397.82"}, {"price":"0.03", "size":"1105.78"}, {"price":"0.04", "size":"1237.82"}, {"price":"0.05", "size":"1055.72"}, {"price":"0.06", "size":"197.2"}, {"price":"0.07", "size":"347.1"}, {"price":"0.08", "size":"410.73"}, {"price":"0.09", "size":"366.69"}, {"price":"0.1", "size":"512"}, {"price":"0.11", "size":"398.97"}, {"price":"0.12", "size":"14"}, {"price":"0.13", "size":"86.87"}, {"price":"0.14", "size":"194.92"}], "asks":[{"price":"0.99", "size":"12015.61"}, {"price":"0.98", "size":"1219.45"}, {"price":"0.97", "size":"1111.98"}, {"price":"0.96", "size":"670.05"}, {"price":"0.95", "size":"549.45"}, {"price":"0.94", "size":"346.2"}, {"price":"0.93", "size":"902.05"}, {"price":"0.92", "size":"170.79"}, {"price":"0.91", "size":"234.6"}, {"price":"0.9", "size":"128"}, {"price":"0.89", "size":"142.6"}, {"price":"0.88", "size":"141.8"}, {"price":"0.87", "size":"144.81"}, {"price":"0.86", "size":"204.9"}, {"price":"0.85", "size":"113.5"}, {"price":"0.84", "size":"102.3"}, {"price":"0.83", "size":"101.3"}, {"price":"0.82", "size":"105.3"}, {"price":"0.81", "size":"199.5"}, {"price":"0.8", "size":"103.8"}, {"price":"0.79", "size":"98.1"}, {"price":"0.78", "size":"97.5"}, {"price":"0.77", "size":"96.89"}, {"price":"0.76", "size":"201.39"}, {"price":"0.75", "size":"116"}, {"price":"0.74", "size":"100.6"}, {"price":"0.73", "size":"95.2"}, {"price":"0.72", "size":"94.9"}, {"price":"0.71", "size":"199.6"}, {"price":"0.7", "size":"94.3"}, {"price":"0.69", "size":"108.28"}, {"price":"0.68", "size":"98.8"}, {"price":"0.67", "size":"718.6"}, {"price":"0.66", "size":"998.4"}, {"price":"0.65", "size":"507.3"}, {"price":"0.64", "size":"293"}, {"price":"0.63", "size":"892.9"}, {"price":"0.62", "size":"897.7"}, {"price":"0.61", "size":"397.6"}, {"price":"0.6", "size":"356.93"}, {"price":"0.59", "size":"297.4"}, {"price":"0.58", "size":"109.6"}, {"price":"0.57", "size":"131.48"}, {"price":"0.56", "size":"413.97"}, {"price":"0.55", "size":"334.2"}, {"price":"0.54", "size":"375.6"}, {"price":"0.53", "size":"292"}, {"price":"0.52", "size":"292.12"}, {"price":"0.51", "size":"402"}, {"price":"0.5", "size":"355.91"}, {"price":"0.49", "size":"312"}, {"price":"0.48", "size":"317"}, {"price":"0.47", "size":"802"}, {"price":"0.46", "size":"651.54"}, {"price":"0.45", "size":"346.64"}, {"price":"0.44", "size":"341.45"}, {"price":"0.43", "size":"434.89"}, {"price":"0.42", "size":"724.36"}, {"price":"0.41", "size":"412.4"}, {"price":"0.4", "size":"328.83"}, {"price":"0.39", "size":"297.6"}, {"price":"0.38", "size":"618.44"}, {"price":"0.37", "size":"297.9"}, {"price":"0.36", "size":"203"}, {"price":"0.35", "size":"335.14"}, {"price":"0.34", "size":"355.9"}, {"price":"0.33", "size":"343.6"}, {"price":"0.32", "size":"2085.88"}, {"price":"0.31", "size":"559"}, {"price":"0.3", "size":"164.3"}, {"price":"0.29", "size":"646.38"}, {"price":"0.28", "size":"139.9"}, {"price":"0.27", "size":"165.2"}, {"price":"0.26", "size":"230.6"}, {"price":"0.25", "size":"706"}, {"price":"0.24", "size":"206.39"}, {"price":"0.23", "size":"226.89"}, {"price":"0.22", "size":"224.5"}, {"price":"0.21", "size":"275.44"}, {"price":"0.2", "size":"105"}, {"price":"0.19", "size":"72.35"}, {"price":"0.18", "size":"334.82"}, {"price":"0.17", "size":"50"}, {"price":"0.16", "size":"82.78"}], "hash":"2631ae9ddd9b04ff6ba27314825bf70ffbfe43f3", "timestamp":"1778784200558", "event_type":"book"}
{"market":"0x2a903c589141bce4a1e50fb98b73397af6820942542793ab10b1df477e912b6e", "price_changes":[{"asset_id":"68919878716222388542639225642064847629616106443780159680232863841946753372582", "price":"0.11", "size":"418.97", "side":"BUY", "hash":"c93dde743c3a3d5614aea6d256aced50754df4a1", "best_bid":"0.14", "best_ask":"0.16"}, {"asset_id":"20436996072316278452977393149218961565084965483366669504673105646378938504388", "price":"0.89", "size":"418.97", "side":"SELL", "hash":"0785c0c60ccef7ddfec8962306e2836c463ce97d", "best_bid":"0.84", "best_ask":"0.86"}], "timestamp":"1778784200561", "event_type":"price_change"}
{"market":"0x2a903c589141bce4a1e50fb98b73397af6820942542793ab10b1df477e912b6e", "price_changes":[{"asset_id":"68919878716222388542639225642064847629616106443780159680232863841946753372582", "price":"0.11", "size":"423.97", "side":"BUY", "hash":"10b985a8453de0ef30692d90282d5ae4ea494b25", "best_bid":"0.14", "best_ask":"0.16"}, {"asset_id":"20436996072316278452977393149218961565084965483366669504673105646378938504388", "price":"0.89", "size":"423.97", "side":"SELL", "hash":"5357274792d1c8adfcae337276d26367d77fe562", "best_bid":"0.84", "best_ask":"0.86"}], "timestamp":"1778784200562", "event_type":"price_change"}
{"market":"0x2a903c589141bce4a1e50fb98b73397af6820942542793ab10b1df477e912b6e", "price_changes":[{"asset_id":"68919878716222388542639225642064847629616106443780159680232863841946753372582", "price":"0.01", "size":"11358.83", "side":"BUY", "hash":"e181557f2ded30be00c9fc68c4210223d8869502", "best_bid":"0.14", "best_ask":"0.16"}, {"asset_id":"20436996072316278452977393149218961565084965483366669504673105646378938504388", "price":"0.99", "size":"11358.83", "side":"SELL", "hash":"2bcc26d1b8848bc21ad6590905c6aacf105aa350", "best_bid":"0.84", "best_ask":"0.86"}], "timestamp":"1778784200562", "event_type":"price_change"}
{"market":"0x2a903c589141bce4a1e50fb98b73397af6820942542793ab10b1df477e912b6e", "asset_id":"68919878716222388542639225642064847629616106443780159680232863841946753372582", "price":"0.14", "size":"8.1", "fee_rate_bps":"0", "side":"SELL", "timestamp":"1778784200560", "event_type":"last_trade_price", "transaction_hash":"0x54cad43f6a9fe3d62d6a2ea3462fa8dea5e943246ed0b090adbcade7a2d918cc"}
{"market":"0x2a903c589141bce4a1e50fb98b73397af6820942542793ab10b1df477e912b6e", "price_changes":[{"asset_id":"20436996072316278452977393149218961565084965483366669504673105646378938504388", "price":"0.8", "size":"123.8", "side":"BUY", "hash":"ef4d0bc2ca18429067524e5bac24c4fb2bfe7032", "best_bid":"0.84", "best_ask":"0.86"}, {"asset_id":"68919878716222388542639225642064847629616106443780159680232863841946753372582", "price":"0.2", "size":"123.8", "side":"SELL", "hash":"bf6e431857487159173c9c1c1c250ed9fa1dd7af", "best_bid":"0.14", "best_ask":"0.16"}], "timestamp":"1778784200564", "event_type":"price_change"}
{"market":"0x2a903c589141bce4a1e50fb98b73397af6820942542793ab10b1df477e912b6e", "price_changes":[{"asset_id":"68919878716222388542639225642064847629616106443780159680232863841946753372582", "price":"0.01", "size":"11363.83", "side":"BUY", "hash":"642e6b1d7818c1b8da8d54b5af8b557dce63bb75", "best_bid":"0.14", "best_ask":"0.16"}, {"asset_id":"20436996072316278452977393149218961565084965483366669504673105646378938504388", "price":"0.99", "size":"11363.83", "side":"SELL", "hash":"a97b3219908b046bfaf2b87f5d08075d4a622877", "best_bid":"0.84", "best_ask":"0.86"}], "timestamp":"1778784200565", "event_type":"price_change"}
{"market":"0x2a903c589141bce4a1e50fb98b73397af6820942542793ab10b1df477e912b6e", "price_changes":[{"asset_id":"68919878716222388542639225642064847629616106443780159680232863841946753372582", "price":"0.11", "size":"441.97", "side":"BUY", "hash":"c11a78bae84d1a2b0da5746e31493988c1a6cdc6", "best_bid":"0.14", "best_ask":"0.16"}, {"asset_id":"20436996072316278452977393149218961565084965483366669504673105646378938504388", "price":"0.89", "size":"441.97", "side":"SELL", "hash":"a9e104fc67d36362521a7997b61b4460e17ffcd4", "best_bid":"0.84", "best_ask":"0.86"}], "timestamp":"1778784200566", "event_type":"price_change"}
{"market":"0x2a903c589141bce4a1e50fb98b73397af6820942542793ab10b1df477e912b6e", "price_changes":[{"asset_id":"20436996072316278452977393149218961565084965483366669504673105646378938504388", "price":"0.8", "size":"128.8", "side":"BUY", "hash":"29ee249fc55f2919961302faef42a1ac9c87f176", "best_bid":"0.84", "best_ask":"0.86"}, {"asset_id":"68919878716222388542639225642064847629616106443780159680232863841946753372582", "price":"0.2", "size":"128.8", "side":"SELL", "hash":"78f2837ce38a914dff13c3a01d530ac911e544b4", "best_bid":"0.14", "best_ask":"0.16"}], "timestamp":"1778784200566", "event_type":"price_change"}
{"market":"0x2a903c589141bce4a1e50fb98b73397af6820942542793ab10b1df477e912b6e", "price_changes":[{"asset_id":"20436996072316278452977393149218961565084965483366669504673105646378938504388", "price":"0.68", "size":"2095.88", "side":"BUY", "hash":"a3843a72b44372b9661ffb9b10f327ce368f1003", "best_bid":"0.84", "best_ask":"0.86"}, {"asset_id":"68919878716222388542639225642064847629616106443780159680232863841946753372582", "price":"0.32", "size":"2095.88", "side":"SELL", "hash":"67ee543396811c4f25999e2630d9c50674641343", "best_bid":"0.14", "best_ask":"0.16"}], "timestamp":"1778784200568", "event_type":"price_change"}
{"market":"0x2a903c589141bce4a1e50fb98b73397af6820942542793ab10b1df477e912b6e", "price_changes":[{"asset_id":"20436996072316278452977393149218961565084965483366669504673105646378938504388", "price":"0.83", "size":"30", "side":"BUY", "hash":"ed4ecbceae998f7d1a5cd47501a047a316771b95", "best_bid":"0.84", "best_ask":"0.86"}, {"asset_id":"68919878716222388542639225642064847629616106443780159680232863841946753372582", "price":"0.17", "size":"30", "side":"SELL", "hash":"d0805820679200cf18b04c1c5e9d22971e98ab72", "best_bid":"0.14", "best_ask":"0.16"}], "timestamp":"1778784200569", "event_type":"price_change"}
{"market":"0x2a903c589141bce4a1e50fb98b73397af6820942542793ab10b1df477e912b6e", "price_changes":[{"asset_id":"20436996072316278452977393149218961565084965483366669504673105646378938504388", "price":"0.89", "size":"421.97", "side":"SELL", "hash":"96cf230e5d4170f6de011cec0de9690f9529e3e5", "best_bid":"0.84", "best_ask":"0.86"}, {"asset_id":"68919878716222388542639225642064847629616106443780159680232863841946753372582", "price":"0.11", "size":"421.97", "side":"BUY", "hash":"cb97fdd094d3b56a278754fa79767176650f7a49", "best_bid":"0.14", "best_ask":"0.16"}], "timestamp":"1778784200570", "event_type":"price_change"}
{"market":"0x2a903c589141bce4a1e50fb98b73397af6820942542793ab10b1df477e912b6e", "price_changes":[{"asset_id":"20436996072316278452977393149218961565084965483366669504673105646378938504388", "price":"0.01", "size":"12010.61", "side":"BUY", "hash":"4814b36e5ac9e9adf1a78698ef6c33eeb238e357", "best_bid":"0.84", "best_ask":"0.86"}, {"asset_id":"68919878716222388542639225642064847629616106443780159680232863841946753372582", "price":"0.99", "size":"12010.61", "side":"SELL", "hash":"4a74a5febe0c378554b78a762dfa0e6b9b8b23c4", "best_bid":"0.14", "best_ask":"0.16"}], "timestamp":"1778784200571", "event_type":"price_change"}
{"market":"0x2a903c589141bce4a1e50fb98b73397af6820942542793ab10b1df477e912b6e", "asset_id":"68919878716222388542639225642064847629616106443780159680232863841946753372582", "price":"0.15", "size":"6.666665", "fee_rate_bps":"0", "side":"BUY", "timestamp":"1778784200571", "event_type":"last_trade_price", "transaction_hash":"0xb765b593a31e6b12b42520f08c7bccf60c46e44d45c6afe65ece137ee35c420e"}
{"market":"0x2a903c589141bce4a1e50fb98b73397af6820942542793ab10b1df477e912b6e", "price_changes":[{"asset_id":"20436996072316278452977393149218961565084965483366669504673105646378938504388", "price":"0.01", "size":"12005.61", "side":"BUY", "hash":"797dcefcba073cb5bcb5ff0265b97ca0974b1da2", "best_bid":"0.84", "best_ask":"0.86"}, {"asset_id":"68919878716222388542639225642064847629616106443780159680232863841946753372582", "price":"0.99", "size":"12005.61", "side":"SELL", "hash":"2309e07e7fcc08eec09a05085da855ae8c19f151", "best_bid":"0.14", "best_ask":"0.16"}], "timestamp":"1778784200572", "event_type":"price_change"}
{"market":"0x2a903c589141bce4a1e50fb98b73397af6820942542793ab10b1df477e912b6e", "price_changes":[{"asset_id":"20436996072316278452977393149218961565084965483366669504673105646378938504388", "price":"0.01", "size":"12000.61", "side":"BUY", "hash":"0bc92a26844f71fc27071e00bb695e5438ba590a", "best_bid":"0.84", "best_ask":"0.86"}, {"asset_id":"68919878716222388542639225642064847629616106443780159680232863841946753372582", "price":"0.99", "size":"12000.61", "side":"SELL", "hash":"24c80f5d5b976937d1deb8a9d849c4be1a45987c", "best_bid":"0.14", "best_ask":"0.16"}], "timestamp":"1778784200573", "event_type":"price_change"}
{"market":"0x2a903c589141bce4a1e50fb98b73397af6820942542793ab10b1df477e912b6e", "price_changes":[{"asset_id":"68919878716222388542639225642064847629616106443780159680232863841946753372582", "price":"0.11", "size":"410.39", "side":"BUY", "hash":"e0777ba3a4fe01b30c4154362a664d3c800ebaca", "best_bid":"0.14", "best_ask":"0.16"}, {"asset_id":"20436996072316278452977393149218961565084965483366669504673105646378938504388", "price":"0.89", "size":"410.39", "side":"SELL", "hash":"e432880d8de45555d83058dcfee1a3e0a0c022c9", "best_bid":"0.84", "best_ask":"0.86"}], "timestamp":"1778784200575", "event_type":"price_change"}
{"market":"0x2a903c589141bce4a1e50fb98b73397af6820942542793ab10b1df477e912b6e", "price_changes":[{"asset_id":"68919878716222388542639225642064847629616106443780159680232863841946753372582", "price":"0.05", "size":"755.72", "side":"BUY", "hash":"cb829e69066bef0c17d5022cdb9a8e496dda5a1b", "best_bid":"0.14", "best_ask":"0.16"}, {"asset_id":"20436996072316278452977393149218961565084965483366669504673105646378938504388", "price":"0.95", "size":"755.72", "side":"SELL", "hash":"5d491173455d71df1f8152b89cccf933fe5af0da", "best_bid":"0.84", "best_ask":"0.86"}], "timestamp":"1778784200575", "event_type":"price_change"}
{"market":"0x2a903c589141bce4a1e50fb98b73397af6820942542793ab10b1df477e912b6e", "price_changes":[{"asset_id":"20436996072316278452977393149218961565084965483366669504673105646378938504388", "price":"0.62", "size":"318.44", "side":"BUY", "hash":"28ee8ad794d76ff0373f242a0c8cdc66e4eefb63", "best_bid":"0.84", "best_ask":"0.86"}, {"asset_id":"68919878716222388542639225642064847629616106443780159680232863841946753372582", "price":"0.38", "size":"318.44", "side":"SELL", "hash":"ece3e9e88866c19266aa70ccde901a1333cb3bd0", "best_bid":"0.14", "best_ask":"0.16"}], "timestamp":"1778784200576", "event_type":"price_change"}
{"market":"0x2a903c589141bce4a1e50fb98b73397af6820942542793ab10b1df477e912b6e", "price_changes":[{"asset_id":"68919878716222388542639225642064847629616106443780159680232863841946753372582", "price":"0.14", "size":"214.92", "side":"BUY", "hash":"911148936336650b1b4b0656b7532174262015c4", "best_bid":"0.14", "best_ask":"0.16"}, {"asset_id":"20436996072316278452977393149218961565084965483366669504673105646378938504388", "price":"0.86", "size":"214.92", "side":"SELL", "hash":"b7958f4310d62e12ac0c99b5e926f50bce92a9d9", "best_bid":"0.84", "best_ask":"0.86"}], "timestamp":"1778784200578", "event_type":"price_change"}
{"market":"0x2a903c589141bce4a1e50fb98b73397af6820942542793ab10b1df477e912b6e", "price_changes":[{"asset_id":"20436996072316278452977393149218961565084965483366669504673105646378938504388", "price":"0.01", "size":"11995.61", "side":"BUY", "hash":"42119a6a54cd068e586e25d2a310a7332ff52c9d", "best_bid":"0.84", "best_ask":"0.86"}, {"asset_id":"68919878716222388542639225642064847629616106443780159680232863841946753372582", "price":"0.99", "size":"11995.61", "side":"SELL", "hash":"36fa2de117c94fa7fcdfcab588a40884ce43d320", "best_bid":"0.14", "best_ask":"0.16"}], "timestamp":"1778784200578", "event_type":"price_change"}
{"market":"0x2a903c589141bce4a1e50fb98b73397af6820942542793ab10b1df477e912b6e", "asset_id":"68919878716222388542639225642064847629616106443780159680232863841946753372582", "price":"0.16", "size":"31.583125", "fee_rate_bps":"0", "side":"BUY", "timestamp":"1778784200581", "event_type":"last_trade_price", "transaction_hash":"0x0c89209db42c41c480377e9605d3ad1fdb31bcca2943fb9a9f9373a3e5940214"}
{"market":"0x2a903c589141bce4a1e50fb98b73397af6820942542793ab10b1df477e912b6e", "price_changes":[{"asset_id":"68919878716222388542639225642064847629616106443780159680232863841946753372582", "price":"0.14", "size":"211.43", "side":"BUY", "hash":"283e1429056c7e1e1ee90b347d669a1e90e83a8d", "best_bid":"0.14", "best_ask":"0.16"}, {"asset_id":"20436996072316278452977393149218961565084965483366669504673105646378938504388", "price":"0.86", "size":"211.43", "side":"SELL", "hash":"57ec3bb6a30e59d08dede2000895c7ca0bf664c8", "best_bid":"0.84", "best_ask":"0.86"}], "timestamp":"1778784200583", "event_type":"price_change"}
{"market":"0x2a903c589141bce4a1e50fb98b73397af6820942542793ab10b1df477e912b6e", "asset_id":"68919878716222388542639225642064847629616106443780159680232863841946753372582", "bids":[{"price":"0.01", "size":"11363.83"}, {"price":"0.02", "size":"1397.82"}, {"price":"0.03", "size":"1105.78"}, {"price":"0.04", "size":"1237.82"}, {"price":"0.05", "size":"755.72"}, {"price":"0.06", "size":"197.2"}, {"price":"0.07", "size":"347.1"}, {"price":"0.08", "size":"410.73"}, {"price":"0.09", "size":"366.69"}, {"price":"0.1", "size":"512"}, {"price":"0.11", "size":"410.39"}, {"price":"0.12", "size":"14"}, {"price":"0.13", "size":"86.87"}, {"price":"0.14", "size":"211.43"}], "asks":[{"price":"0.99", "size":"11995.61"}, {"price":"0.98", "size":"1219.45"}, {"price":"0.97", "size":"1111.98"}, {"price":"0.96", "size":"670.05"}, {"price":"0.95", "size":"549.45"}, {"price":"0.94", "size":"346.2"}, {"price":"0.93", "size":"902.05"}, {"price":"0.92", "size":"170.79"}, {"price":"0.91", "size":"234.6"}, {"price":"0.9", "size":"128"}, {"price":"0.89", "size":"142.6"}, {"price":"0.88", "size":"141.8"}, {"price":"0.87", "size":"144.81"}, {"price":"0.86", "size":"204.9"}, {"price":"0.85", "size":"113.5"}, {"price":"0.84", "size":"102.3"}, {"price":"0.83", "size":"101.3"}, {"price":"0.82", "size":"105.3"}, {"price":"0.81", "size":"199.5"}, {"price":"0.8", "size":"103.8"}, {"price":"0.79", "size":"98.1"}, {"price":"0.78", "size":"97.5"}, {"price":"0.77", "size":"96.89"}, {"price":"0.76", "size":"201.39"}, {"price":"0.75", "size":"116"}, {"price":"0.74", "size":"100.6"}, {"price":"0.73", "size":"95.2"}, {"price":"0.72", "size":"94.9"}, {"price":"0.71", "size":"199.6"}, {"price":"0.7", "size":"94.3"}, {"price":"0.69", "size":"108.28"}, {"price":"0.68", "size":"98.8"}, {"price":"0.67", "size":"718.6"}, {"price":"0.66", "size":"998.4"}, {"price":"0.65", "size":"507.3"}, {"price":"0.64", "size":"293"}, {"price":"0.63", "size":"892.9"}, {"price":"0.62", "size":"897.7"}, {"price":"0.61", "size":"397.6"}, {"price":"0.6", "size":"356.93"}, {"price":"0.59", "size":"297.4"}, {"price":"0.58", "size":"109.6"}, {"price":"0.57", "size":"131.48"}, {"price":"0.56", "size":"413.97"}, {"price":"0.55", "size":"334.2"}, {"price":"0.54", "size":"375.6"}, {"price":"0.53", "size":"292"}, {"price":"0.52", "size":"292.12"}, {"price":"0.51", "size":"402"}, {"price":"0.5", "size":"355.91"}, {"price":"0.49", "size":"312"}, {"price":"0.48", "size":"317"}, {"price":"0.47", "size":"802"}, {"price":"0.46", "size":"651.54"}, {"price":"0.45", "size":"346.64"}, {"price":"0.44", "size":"341.45"}, {"price":"0.43", "size":"434.89"}, {"price":"0.42", "size":"724.36"}, {"price":"0.41", "size":"412.4"}, {"price":"0.4", "size":"328.83"}, {"price":"0.39", "size":"297.6"}, {"price":"0.38", "size":"318.44"}, {"price":"0.37", "size":"297.9"}, {"price":"0.36", "size":"203"}, {"price":"0.35", "size":"335.14"}, {"price":"0.34", "size":"355.9"}, {"price":"0.33", "size":"343.6"}, {"price":"0.32", "size":"2095.88"}, {"price":"0.31", "size":"559"}, {"price":"0.3", "size":"164.3"}, {"price":"0.29", "size":"646.38"}, {"price":"0.28", "size":"139.9"}, {"price":"0.27", "size":"165.2"}, {"price":"0.26", "size":"230.6"}, {"price":"0.25", "size":"706"}, {"price":"0.24", "size":"206.39"}, {"price":"0.23", "size":"226.89"}, {"price":"0.22", "size":"224.5"}, {"price":"0.21", "size":"275.44"}, {"price":"0.2", "size":"128.8"}, {"price":"0.19", "size":"72.35"}, {"price":"0.18", "size":"334.82"}, {"price":"0.17", "size":"30"}, {"price":"0.16", "size":"82.78"}], "hash":"283e1429056c7e1e1ee90b347d669a1e90e83a8d", "timestamp":"1778784200583", "event_type":"book"}
{"market":"0x2a903c589141bce4a1e50fb98b73397af6820942542793ab10b1df477e912b6e", "price_changes":[{"asset_id":"20436996072316278452977393149218961565084965483366669504673105646378938504388", "price":"0.54", "size":"451.54", "side":"BUY", "hash":"4c597235c16a22542a587c570a81d626d1b8451e", "best_bid":"0.84", "best_ask":"0.86"}, {"asset_id":"68919878716222388542639225642064847629616106443780159680232863841946753372582", "price":"0.46", "size":"451.54", "side":"SELL", "hash":"ff7f6019e5e1765dc94c2168568911f08e1b0651", "best_bid":"0.14", "best_ask":"0.16"}], "timestamp":"1778784200584", "event_type":"price_change"}
{"market":"0x2a903c589141bce4a1e50fb98b73397af6820942542793ab10b1df477e912b6e", "price_changes":[{"asset_id":"20436996072316278452977393149218961565084965483366669504673105646378938504388", "price":"0.01", "size":"11990.61", "side":"BUY", "hash":"298896d43d67ae48a6c5da046764871cbe114683", "best_bid":"0.84", "best_ask":"0.86"}, {"asset_id":"68919878716222388542639225642064847629616106443780159680232863841946753372582", "price":"0.99", "size":"11990.61", "side":"SELL", "hash":"f76fe706bd1ebb52461eae738f1d390a53c4087e", "best_bid":"0.14", "best_ask":"0.16"}], "timestamp":"1778784200585", "event_type":"price_change"}
{"market":"0x2a903c589141bce4a1e50fb98b73397af6820942542793ab10b1df477e912b6e", "price_changes":[{"asset_id":"20436996072316278452977393149218961565084965483366669504673105646378938504388", "price":"0.92", "size":"356.74", "side":"SELL", "hash":"7f618307a5cc3e26bcdffefc3891960e87e1278a", "best_bid":"0.84", "best_ask":"0.86"}, {"asset_id":"68919878716222388542639225642064847629616106443780159680232863841946753372582", "price":"0.08", "size":"356.74", "side":"BUY", "hash":"7e67bd8fae89a25bfcd9d9efb7f7ff5deb9a0809", "best_bid":"0.14", "best_ask":"0.16"}], "timestamp":"1778784200586", "event_type":"price_change"}
{"market":"0x2a903c589141bce4a1e50fb98b73397af6820942542793ab10b1df477e912b6e", "price_changes":[{"asset_id":"68919878716222388542639225642064847629616106443780159680232863841946753372582", "price":"0.11", "size":"415.39", "side":"BUY", "hash":"90d069907c439a2b3506bfd764faf3657fac1fcc", "best_bid":"0.14", "best_ask":"0.16"}, {"asset_id":"20436996072316278452977393149218961565084965483366669504673105646378938504388", "price":"0.89", "size":"415.39", "side":"SELL", "hash":"1a99354d1199b95d59783fbdbd2a43007df01ed4", "best_bid":"0.84", "best_ask":"0.86"}], "timestamp":"1778784200587", "event_type":"price_change"}
{"market":"0x2a903c589141bce4a1e50fb98b73397af6820942542793ab10b1df477e912b6e", "price_changes":[{"asset_id":"20436996072316278452977393149218961565084965483366669504673105646378938504388", "price":"0.01", "size":"11995.61", "side":"BUY", "hash":"2b0daacdc6d175d4c5080dc1135117bb6e0aeeaa", "best_bid":"0.84", "best_ask":"0.86"}, {"asset_id":"68919878716222388542639225642064847629616106443780159680232863841946753372582", "price":"0.99", "size":"11995.61", "side":"SELL", "hash":"39ad279cdce38edc0b86e4fe88feb091c2d2ebd0", "best_bid":"0.14", "best_ask":"0.16"}], "timestamp":"1778784200588", "event_type":"price_change"}
{"market":"0x2a903c589141bce4a1e50fb98b73397af6820942542793ab10b1df477e912b6e", "price_changes":[{"asset_id":"68919878716222388542639225642064847629616106443780159680232863841946753372582", "price":"0.17", "size":"36", "side":"SELL", "hash":"378df43d71e89e8e3dc364d29b55540da729b163", "best_bid":"0.14", "best_ask":"0.16"}, {"asset_id":"20436996072316278452977393149218961565084965483366669504673105646378938504388", "price":"0.83", "size":"36", "side":"BUY", "hash":"1291ae6782ccd933aa80218dc92b26b7d7e1656d", "best_bid":"0.84", "best_ask":"0.86"}], "timestamp":"1778784200589", "event_type":"price_change"}
{"market":"0x2a903c589141bce4a1e50fb98b73397af6820942542793ab10b1df477e912b6e", "price_changes":[{"asset_id":"20436996072316278452977393149218961565084965483366669504673105646378938504388", "price":"0.34", "size":"898.4", "side":"BUY", "hash":"dc200d90581677b27e06b736fbcc3677bec549b0", "best_bid":"0.84", "best_ask":"0.86"}, {"asset_id":"68919878716222388542639225642064847629616106443780159680232863841946753372582", "price":"0.66", "size":"898.4", "side":"SELL", "hash":"de378936d5fd0b1e69024479b0ee7add2bcc46f0", "best_bid":"0.14", "best_ask":"0.16"}], "timestamp":"1778784200591", "event_type":"price_change"}
{"market":"0x2a903c589141bce4a1e50fb98b73397af6820942542793ab10b1df477e912b6e", "price_changes":[{"asset_id":"68919878716222388542639225642064847629616106443780159680232863841946753372582", "price":"0.01", "size":"11338.83", "side":"BUY", "hash":"03bf2000bd49c5ac7b4032555446148303a1733a", "best_bid":"0.14", "best_ask":"0.16"}, {"asset_id":"20436996072316278452977393149218961565084965483366669504673105646378938504388", "price":"0.99", "size":"11338.83", "side":"SELL", "hash":"29f40906d9565d2289e65ed533d854a4bfc6212f", "best_bid":"0.84", "best_ask":"0.86"}], "timestamp":"1778784200592", "event_type":"price_change"}
{"market":"0x2a903c589141bce4a1e50fb98b73397af6820942542793ab10b1df477e912b6e", "price_changes":[{"asset_id":"68919878716222388542639225642064847629616106443780159680232863841946753372582", "price":"0.14", "size":"198.22", "side":"BUY", "hash":"37aaad7e60018d9d3775647236b41c8cefa5fa21", "best_bid":"0.14", "best_ask":"0.16"}, {"asset_id":"20436996072316278452977393149218961565084965483366669504673105646378938504388", "price":"0.86", "size":"198.22", "side":"SELL", "hash":"56210a9d6c4596163212c824b1fe6543c7c0d79b", "best_bid":"0.84", "best_ask":"0.86"}], "timestamp":"1778784200595", "event_type":"price_change"}
{"market":"0x2a903c589141bce4a1e50fb98b73397af6820942542793ab10b1df477e912b6e", "asset_id":"68919878716222388542639225642064847629616106443780159680232863841946753372582", "bids":[{"price":"0.01", "size":"11338.83"}, {"price":"0.02", "size":"1397.82"}, {"price":"0.03", "size":"1105.78"}, {"price":"0.04", "size":"1237.82"}, {"price":"0.05", "size":"755.72"}, {"price":"0.06", "size":"197.2"}, {"price":"0.07", "size":"347.1"}, {"price":"0.08", "size":"356.74"}, {"price":"0.09", "size":"366.69"}, {"price":"0.1", "size":"512"}, {"price":"0.11", "size":"415.39"}, {"price":"0.12", "size":"14"}, {"price":"0.13", "size":"86.87"}, {"price":"0.14", "size":"198.22"}], "asks":[{"price":"0.99", "size":"11995.61"}, {"price":"0.98", "size":"1219.45"}, {"price":"0.97", "size":"1111.98"}, {"price":"0.96", "size":"670.05"}, {"price":"0.95", "size":"549.45"}, {"price":"0.94", "size":"346.2"}, {"price":"0.93", "size":"902.05"}, {"price":"0.92", "size":"170.79"}, {"price":"0.91", "size":"234.6"}, {"price":"0.9", "size":"128"}, {"price":"0.89", "size":"142.6"}, {"price":"0.88", "size":"141.8"}, {"price":"0.87", "size":"144.81"}, {"price":"0.86", "size":"204.9"}, {"price":"0.85", "size":"113.5"}, {"price":"0.84", "size":"102.3"}, {"price":"0.83", "size":"101.3"}, {"price":"0.82", "size":"105.3"}, {"price":"0.81", "size":"199.5"}, {"price":"0.8", "size":"103.8"}, {"price":"0.79", "size":"98.1"}, {"price":"0.78", "size":"97.5"}, {"price":"0.77", "size":"96.89"}, {"price":"0.76", "size":"201.39"}, {"price":"0.75", "size":"116"}, {"price":"0.74", "size":"100.6"}, {"price":"0.73", "size":"95.2"}, {"price":"0.72", "size":"94.9"}, {"price":"0.71", "size":"199.6"}, {"price":"0.7", "size":"94.3"}, {"price":"0.69", "size":"108.28"}, {"price":"0.68", "size":"98.8"}, {"price":"0.67", "size":"718.6"}, {"price":"0.66", "size":"898.4"}, {"price":"0.65", "size":"507.3"}, {"price":"0.64", "size":"293"}, {"price":"0.63", "size":"892.9"}, {"price":"0.62", "size":"897.7"}, {"price":"0.61", "size":"397.6"}, {"price":"0.6", "size":"356.93"}, {"price":"0.59", "size":"297.4"}, {"price":"0.58", "size":"109.6"}, {"price":"0.57", "size":"131.48"}, {"price":"0.56", "size":"413.97"}, {"price":"0.55", "size":"334.2"}, {"price":"0.54", "size":"375.6"}, {"price":"0.53", "size":"292"}, {"price":"0.52", "size":"292.12"}, {"price":"0.51", "size":"402"}, {"price":"0.5", "size":"355.91"}, {"price":"0.49", "size":"312"}, {"price":"0.48", "size":"317"}, {"price":"0.47", "size":"802"}, {"price":"0.46", "size":"451.54"}, {"price":"0.45", "size":"346.64"}, {"price":"0.44", "size":"341.45"}, {"price":"0.43", "size":"434.89"}, {"price":"0.42", "size":"724.36"}, {"price":"0.41", "size":"412.4"}, {"price":"0.4", "size":"328.83"}, {"price":"0.39", "size":"297.6"}, {"price":"0.38", "size":"318.44"}, {"price":"0.37", "size":"297.9"}, {"price":"0.36", "size":"203"}, {"price":"0.35", "size":"335.14"}, {"price":"0.34", "size":"355.9"}, {"price":"0.33", "size":"343.6"}, {"price":"0.32", "size":"2095.88"}, {"price":"0.31", "size":"559"}, {"price":"0.3", "size":"164.3"}, {"price":"0.29", "size":"646.38"}, {"price":"0.28", "size":"139.9"}, {"price":"0.27", "size":"165.2"}, {"price":"0.26", "size":"230.6"}, {"price":"0.25", "size":"706"}, {"price":"0.24", "size":"206.39"}, {"price":"0.23", "size":"226.89"}, {"price":"0.22", "size":"224.5"}, {"price":"0.21", "size":"275.44"}, {"price":"0.2", "size":"128.8"}, {"price":"0.19", "size":"72.35"}, {"price":"0.18", "size":"334.82"}, {"price":"0.17", "size":"36"}, {"price":"0.16", "size":"82.78"}], "hash":"37aaad7e60018d9d3775647236b41c8cefa5fa21", "timestamp":"1778784200595", "event_type":"book"}
{"market":"0x2a903c589141bce4a1e50fb98b73397af6820942542793ab10b1df477e912b6e", "price_changes":[{"asset_id":"20436996072316278452977393149218961565084965483366669504673105646378938504388", "price":"0.65", "size":"345.14", "side":"BUY", "hash":"988910368d66e34eb722450f70ee495e61f4ead8", "best_bid":"0.84", "best_ask":"0.86"}, {"asset_id":"68919878716222388542639225642064847629616106443780159680232863841946753372582", "price":"0.35", "size":"345.14", "side":"SELL", "hash":"c735c1d0ddba3591a8ad13074ea2b4dc1fb08755", "best_bid":"0.14", "best_ask":"0.16"}], "timestamp":"1778784200596", "event_type":"price_change"}
{"market":"0x2a903c589141bce4a1e50fb98b73397af6820942542793ab10b1df477e912b6e", "price_changes":[{"asset_id":"68919878716222388542639225642064847629616106443780159680232863841946753372582", "price":"0.35", "size":"340.14", "side":"SELL", "hash":"18cc2ac8df855bcc8cca6a2e3a69c4b4e7fb285d", "best_bid":"0.14", "best_ask":"0.16"}, {"asset_id":"20436996072316278452977393149218961565084965483366669504673105646378938504388", "price":"0.65", "size":"340.14", "side":"BUY", "hash":"6bedfd436b673109ff3f02ce9fda39925059654c", "best_bid":"0.84", "best_ask":"0.86"}], "timestamp":"1778784200597", "event_type":"price_change"}
{"market":"0x2a903c589141bce4a1e50fb98b73397af6820942542793ab10b1df477e912b6e", "price_changes":[{"asset_id":"20436996072316278452977393149218961565084965483366669504673105646378938504388", "price":"0.66", "size":"350.9", "side":"BUY", "hash":"ca38e942942fde3c989813e4ec63b5b6566abca5", "best_bid":"0.84", "best_ask":"0.86"}, {"asset_id":"68919878716222388542639225642064847629616106443780159680232863841946753372582", "price":"0.34", "size":"350.9", "side":"SELL", "hash":"8461b39cbacf229084f407e65455aefeaacd53f7", "best_bid":"0.14", "best_ask":"0.16"}], "timestamp":"1778784200599", "event_type":"price_change"}
{"market":"0x2a903c589141bce4a1e50fb98b73397af6820942542793ab10b1df477e912b6e", "price_changes":[{"asset_id":"20436996072316278452977393149218961565084965483366669504673105646378938504388", "price":"0.77", "size":"221.89", "side":"BUY", "hash":"0bc5e57562c2962dc54e72f8a3a53887884ad679", "best_bid":"0.84", "best_ask":"0.86"}, {"asset_id":"68919878716222388542639225642064847629616106443780159680232863841946753372582", "price":"0.23", "size":"221.89", "side":"SELL", "hash":"ca8c6cfac827f2443374eec7a61ddc5352c43abe", "best_bid":"0.14", "best_ask":"0.16"}], "timestamp":"1778784200600", "event_type":"price_change"}
{"market":"0x2a903c589141bce4a1e50fb98b73397af6820942542793ab10b1df477e912b6e", "price_changes":[{"asset_id":"68919878716222388542639225642064847629616106443780159680232863841946753372582", "price":"0.08", "size":"326.74", "side":"BUY", "hash":"16fbd6dce13cf1bf012dc6a1f4910f84404415cf", "best_bid":"0.14", "best_ask":"0.16"}, {"asset_id":"20436996072316278452977393149218961565084965483366669504673105646378938504388", "price":"0.92", "size":"326.74", "side":"SELL", "hash":"435e384130fbad72ced7111fae2bb3059f2e989a", "best_bid":"0.84", "best_ask":"0.86"}], "timestamp":"1778784200601", "event_type":"price_change"}
{"market":"0x2a903c589141bce4a1e50fb98b73397af6820942542793ab10b1df477e912b6e", "price_changes":[{"asset_id":"20436996072316278452977393149218961565084965483366669504673105646378938504388", "price":"0.78", "size":"249.5", "side":"BUY", "hash":"15fb0e7fe5868b0d65e296877236bb7ddab50604", "best_bid":"0.84", "best_ask":"0.86"}, {"asset_id":"68919878716222388542639225642064847629616106443780159680232863841946753372582", "price":"0.22", "size":"249.5", "side":"SELL", "hash":"fb654d288b1e74bea32fbc8a742daf3a607610a9", "best_bid":"0.14", "best_ask":"0.16"}], "timestamp":"1778784200601", "event_type":"price_change"}
{"market":"0x2a903c589141bce4a1e50fb98b73397af6820942542793ab10b1df477e912b6e", "price_changes":[{"asset_id":"20436996072316278452977393149218961565084965483366669504673105646378938504388", "price":"0.77", "size":"246.89", "side":"BUY", "hash":"4b1d476c30bca8c4035acb5fff7471234f96dd70", "best_bid":"0.84", "best_ask":"0.86"}, {"asset_id":"68919878716222388542639225642064847629616106443780159680232863841946753372582", "price":"0.23", "size":"246.89", "side":"SELL", "hash":"960b90586d20e3a4fc01b5006f802f824752d04e", "best_bid":"0.14", "best_ask":"0.16"}], "timestamp":"1778784200602", "event_type":"price_change"}
{"market":"0x2a903c589141bce4a1e50fb98b73397af6820942542793ab10b1df477e912b6e", "price_changes":[{"asset_id":"20436996072316278452977393149218961565084965483366669504673105646378938504388", "price":"0.34", "size":"998.4", "side":"BUY", "hash":"99f9d92d612b0c7c37886bf3bd19391d37519c62", "best_bid":"0.84", "best_ask":"0.86"}, {"asset_id":"68919878716222388542639225642064847629616106443780159680232863841946753372582", "price":"0.66", "size":"998.4", "side":"SELL", "hash":"fd222330d8dda24484e44b87ac6342f74fe8a36a", "best_bid":"0.14", "best_ask":"0.16"}], "timestamp":"1778784200604", "event_type":"price_change"}
{"market":"0x2a903c589141bce4a1e50fb98b73397af6820942542793ab10b1df477e912b6e", "price_changes":[{"asset_id":"68919878716222388542639225642064847629616106443780159680232863841946753372582", "price":"0.03", "size":"1090.78", "side":"BUY", "hash":"8fae02888d08ffb314cf94b114df8da47858ede7", "best_bid":"0.14", "best_ask":"0.16"}, {"asset_id":"20436996072316278452977393149218961565084965483366669504673105646378938504388", "price":"0.97", "size":"1090.78", "side":"SELL", "hash":"a7e9803e590275bf3777e76ccf39392920b17977", "best_bid":"0.84", "best_ask":"0.86"}], "timestamp":"1778784200605", "event_type":"price_change"}
{"market":"0x2a903c589141bce4a1e50fb98b73397af6820942542793ab10b1df477e912b6e", "price_changes":[{"asset_id":"20436996072316278452977393149218961565084965483366669504673105646378938504388", "price":"0.56", "size":"346.45", "side":"BUY", "hash":"bf56ed97fe0e960705f20612915ba1846aacac7c", "best_bid":"0.84", "best_ask":"0.86"}, {"asset_id":"68919878716222388542639225642064847629616106443780159680232863841946753372582", "price":"0.44", "size":"346.45", "side":"SELL", "hash":"95aafb663e37d1635355b233b4c4bd406dae76ff", "best_bid":"0.14", "best_ask":"0.16"}], "timestamp":"1778784200605", "event_type":"price_change"}
{"market":"0x2a903c589141bce4a1e50fb98b73397af6820942542793ab10b1df477e912b6e", "price_changes":[{"asset_id":"68919878716222388542639225642064847629616106443780159680232863841946753372582", "price":"0.14", "size":"174.37", "side":"BUY", "hash":"b4094cf290da383680be864668bdc4e49c0dc6c8", "best_bid":"0.14", "best_ask":"0.16"}, {"asset_id":"20436996072316278452977393149218961565084965483366669504673105646378938504388", "price":"0.86", "size":"174.37", "side":"SELL", "hash":"8ae7064d65462d347ee2631c540ea3c29a5aa111", "best_bid":"0.84", "best_ask":"0.86"}], "timestamp":"1778784200609", "event_type":"price_change"}
{"market":"0x2a903c589141bce4a1e50fb98b73397af6820942542793ab10b1df477e912b6e", "asset_id":"68919878716222388542639225642064847629616106443780159680232863841946753372582", "bids":[{"price":"0.01", "size":"11338.83"}, {"price":"0.02", "size":"1397.82"}, {"price":"0.03", "size":"1090.78"}, {"price":"0.04", "size":"1237.82"}, {"price":"0.05", "size":"755.72"}, {"price":"0.06", "size":"197.2"}, {"price":"0.07", "size":"347.1"}, {"price":"0.08", "size":"326.74"}, {"price":"0.09", "size":"366.69"}, {"price":"0.1", "size":"512"}, {"price":"0.11", "size":"415.39"}, {"price":"0.12", "size":"14"}, {"price":"0.13", "size":"86.87"}, {"price":"0.14", "size":"174.37"}], "asks":[{"price":"0.99", "size":"11995.61"}, {"price":"0.98", "size":"1219.45"}, {"price":"0.97", "size":"1111.98"}, {"price":"0.96", "size":"670.05"}, {"price":"0.95", "size":"549.45"}, {"price":"0.94", "size":"346.2"}, {"price":"0.93", "size":"902.05"}, {"price":"0.92", "size":"170.79"}, {"price":"0.91", "size":"234.6"}, {"price":"0.9", "size":"128"}, {"price":"0.89", "size":"142.6"}, {"price":"0.88", "size":"141.8"}, {"price":"0.87", "size":"144.81"}, {"price":"0.86", "size":"204.9"}, {"price":"0.85", "size":"113.5"}, {"price":"0.84", "size":"102.3"}, {"price":"0.83", "size":"101.3"}, {"price":"0.82", "size":"105.3"}, {"price":"0.81", "size":"199.5"}, {"price":"0.8", "size":"103.8"}, {"price":"0.79", "size":"98.1"}, {"price":"0.78", "size":"97.5"}, {"price":"0.77", "size":"96.89"}, {"price":"0.76", "size":"201.39"}, {"price":"0.75", "size":"116"}, {"price":"0.74", "size":"100.6"}, {"price":"0.73", "size":"95.2"}, {"price":"0.72", "size":"94.9"}, {"price":"0.71", "size":"199.6"}, {"price":"0.7", "size":"94.3"}, {"price":"0.69", "size":"108.28"}, {"price":"0.68", "size":"98.8"}, {"price":"0.67", "size":"718.6"}, {"price":"0.66", "size":"998.4"}, {"price":"0.65", "size":"507.3"}, {"price":"0.64", "size":"293"}, {"price":"0.63", "size":"892.9"}, {"price":"0.62", "size":"897.7"}, {"price":"0.61", "size":"397.6"}, {"price":"0.6", "size":"356.93"}, {"price":"0.59", "size":"297.4"}, {"price":"0.58", "size":"109.6"}, {"price":"0.57", "size":"131.48"}, {"price":"0.56", "size":"413.97"}, {"price":"0.55", "size":"334.2"}, {"price":"0.54", "size":"375.6"}, {"price":"0.53", "size":"292"}, {"price":"0.52", "size":"292.12"}, {"price":"0.51", "size":"402"}, {"price":"0.5", "size":"355.91"}, {"price":"0.49", "size":"312"}, {"price":"0.48", "size":"317"}, {"price":"0.47", "size":"802"}, {"price":"0.46", "size":"451.54"}, {"price":"0.45", "size":"346.64"}, {"price":"0.44", "size":"346.45"}, {"price":"0.43", "size":"434.89"}, {"price":"0.42", "size":"724.36"}, {"price":"0.41", "size":"412.4"}, {"price":"0.4", "size":"328.83"}, {"price":"0.39", "size":"297.6"}, {"price":"0.38", "size":"318.44"}, {"price":"0.37", "size":"297.9"}, {"price":"0.36", "size":"203"}, {"price":"0.35", "size":"340.14"}, {"price":"0.34", "size":"350.9"}, {"price":"0.33", "size":"343.6"}, {"price":"0.32", "size":"2095.88"}, {"price":"0.31", "size":"559"}, {"price":"0.3", "size":"164.3"}, {"price":"0.29", "size":"646.38"}, {"price":"0.28", "size":"139.9"}, {"price":"0.27", "size":"165.2"}, {"price":"0.26", "size":"230.6"}, {"price":"0.25", "size":"706"}, {"price":"0.24", "size":"206.39"}, {"price":"0.23", "size":"246.89"}, {"price":"0.22", "size":"249.5"}, {"price":"0.21", "size":"275.44"}, {"price":"0.2", "size":"128.8"}, {"price":"0.19", "size":"72.35"}, {"price":"0.18", "size":"334.82"}, {"price":"0.17", "size":"36"}, {"price":"0.16", "size":"82.78"}], "hash":"b4094cf290da383680be864668bdc4e49c0dc6c8", "timestamp":"1778784200609", "event_type":"book"}
{"market":"0x2a903c589141bce4a1e50fb98b73397af6820942542793ab10b1df477e912b6e", "price_changes":[{"asset_id":"68919878716222388542639225642064847629616106443780159680232863841946753372582", "price":"0.11", "size":"420.39", "side":"BUY", "hash":"aa6617990951011a2e44764307c7647f76cd51cf", "best_bid":"0.14", "best_ask":"0.16"}, {"asset_id":"20436996072316278452977393149218961565084965483366669504673105646378938504388", "price":"0.89", "size":"420.39", "side":"SELL", "hash":"17019b39d57caeed3a6e28f235c9020d8e08f0be", "best_bid":"0.84", "best_ask":"0.86"}], "timestamp":"1778784200610", "event_type":"price_change"}
{"market":"0x2a903c589141bce4a1e50fb98b73397af6820942542793ab10b1df477e912b6e", "price_changes":[{"asset_id":"68919878716222388542639225642064847629616106443780159680232863841946753372582", "price":"0.14", "size":"170.88", "side":"BUY", "hash":"4ae04f5812bc1ec4076b78084b186533ee407436", "best_bid":"0.14", "best_ask":"0.16"}, {"asset_id":"20436996072316278452977393149218961565084965483366669504673105646378938504388", "price":"0.86", "size":"170.88", "side":"SELL", "hash":"cf5791f76685adb473670865627eff79f4c390d7", "best_bid":"0.84", "best_ask":"0.86"}], "timestamp":"1778784200612", "event_type":"price_change"}
{"market":"0x2a903c589141bce4a1e50fb98b73397af6820942542793ab10b1df477e912b6e", "asset_id":"68919878716222388542639225642064847629616106443780159680232863841946753372582", "bids":[{"price":"0.01", "size":"11338.83"}, {"price":"0.02", "size":"1397.82"}, {"price":"0.03", "size":"1090.78"}, {"price":"0.04", "size":"1237.82"}, {"price":"0.05", "size":"755.72"}, {"price":"0.06", "size":"197.2"}, {"price":"0.07", "size":"347.1"}, {"price":"0.08", "size":"326.74"}, {"price":"0.09", "size":"366.69"}, {"price":"0.1", "size":"512"}, {"price":"0.11", "size":"420.39"}, {"price":"0.12", "size":"14"}, {"price":"0.13", "size":"86.87"}, {"price":"0.14", "size":"170.88"}], "asks":[{"price":"0.99", "size":"11995.61"}, {"price":"0.98", "size":"1219.45"}, {"price":"0.97", "size":"1111.98"}, {"price":"0.96", "size":"670.05"}, {"price":"0.95", "size":"549.45"}, {"price":"0.94", "size":"346.2"}, {"price":"0.93", "size":"902.05"}, {"price":"0.92", "size":"170.79"}, {"price":"0.91", "size":"234.6"}, {"price":"0.9", "size":"128"}, {"price":"0.89", "size":"142.6"}, {"price":"0.88", "size":"141.8"}, {"price":"0.87", "size":"144.81"}, {"price":"0.86", "size":"204.9"}, {"price":"0.85", "size":"113.5"}, {"price":"0.84", "size":"102.3"}, {"price":"0.83", "size":"101.3"}, {"price":"0.82", "size":"105.3"}, {"price":"0.81", "size":"199.5"}, {"price":"0.8", "size":"103.8"}, {"price":"0.79", "size":"98.1"}, {"price":"0.78", "size":"97.5"}, {"price":"0.77", "size":"96.89"}, {"price":"0.76", "size":"201.39"}, {"price":"0.75", "size":"116"}, {"price":"0.74", "size":"100.6"}, {"price":"0.73", "size":"95.2"}, {"price":"0.72", "size":"94.9"}, {"price":"0.71", "size":"199.6"}, {"price":"0.7", "size":"94.3"}, {"price":"0.69", "size":"108.28"}, {"price":"0.68", "size":"98.8"}, {"price":"0.67", "size":"718.6"}, {"price":"0.66", "size":"998.4"}, {"price":"0.65", "size":"507.3"}, {"price":"0.64", "size":"293"}, {"price":"0.63", "size":"892.9"}, {"price":"0.62", "size":"897.7"}, {"price":"0.61", "size":"397.6"}, {"price":"0.6", "size":"356.93"}, {"price":"0.59", "size":"297.4"}, {"price":"0.58", "size":"109.6"}, {"price":"0.57", "size":"131.48"}, {"price":"0.56", "size":"413.97"}, {"price":"0.55", "size":"334.2"}, {"price":"0.54", "size":"375.6"}, {"price":"0.53", "size":"292"}, {"price":"0.52", "size":"292.12"}, {"price":"0.51", "size":"402"}, {"price":"0.5", "size":"355.91"}, {"price":"0.49", "size":"312"}, {"price":"0.48", "size":"317"}, {"price":"0.47", "size":"802"}, {"price":"0.46", "size":"451.54"}, {"price":"0.45", "size":"346.64"}, {"price":"0.44", "size":"346.45"}, {"price":"0.43", "size":"434.89"}, {"price":"0.42", "size":"724.36"}, {"price":"0.41", "size":"412.4"}, {"price":"0.4", "size":"328.83"}, {"price":"0.39", "size":"297.6"}, {"price":"0.38", "size":"318.44"}, {"price":"0.37", "size":"297.9"}, {"price":"0.36", "size":"203"}, {"price":"0.35", "size":"340.14"}, {"price":"0.34", "size":"350.9"}, {"price":"0.33", "size":"343.6"}, {"price":"0.32", "size":"2095.88"}, {"price":"0.31", "size":"559"}, {"price":"0.3", "size":"164.3"}, {"price":"0.29", "size":"646.38"}, {"price":"0.28", "size":"139.9"}, {"price":"0.27", "size":"165.2"}, {"price":"0.26", "size":"230.6"}, {"price":"0.25", "size":"706"}, {"price":"0.24", "size":"206.39"}, {"price":"0.23", "size":"246.89"}, {"price":"0.22", "size":"249.5"}, {"price":"0.21", "size":"275.44"}, {"price":"0.2", "size":"128.8"}, {"price":"0.19", "size":"72.35"}, {"price":"0.18", "size":"334.82"}, {"price":"0.17", "size":"36"}, {"price":"0.16", "size":"82.78"}], "hash":"4ae04f5812bc1ec4076b78084b186533ee407436", "timestamp":"1778784200612", "event_type":"book"}
{"market":"0x2a903c589141bce4a1e50fb98b73397af6820942542793ab10b1df477e912b6e", "price_changes":[{"asset_id":"68919878716222388542639225642064847629616106443780159680232863841946753372582", "price":"0.11", "size":"429.57", "side":"BUY", "hash":"0f0e107b9f5fcac1b44a3856cb5cd46240527834", "best_bid":"0.14", "best_ask":"0.16"}, {"asset_id":"20436996072316278452977393149218961565084965483366669504673105646378938504388", "price":"0.89", "size":"429.57", "side":"SELL", "hash":"42fe9f2bdeade6b0cb7eea61e710bb61a104f9ea", "best_bid":"0.84", "best_ask":"0.86"}], "timestamp":"1778784200614", "event_type":"price_change"}
{"market":"0x2a903c589141bce4a1e50fb98b73397af6820942542793ab10b1df477e912b6e", "price_changes":[{"asset_id":"68919878716222388542639225642064847629616106443780159680232863841946753372582", "price":"0.11", "size":"529.57", "side":"BUY", "hash":"3ec87ea420af4eebbbe93268ba066aae2785f6dd", "best_bid":"0.14", "best_ask":"0.16"}, {"asset_id":"20436996072316278452977393149218961565084965483366669504673105646378938504388", "price":"0.89", "size":"529.57", "side":"SELL", "hash":"d256d76398e8b9d190900d345f25c62af2d3bf38", "best_bid":"0.84", "best_ask":"0.86"}], "timestamp":"1778784200615", "event_type":"price_change"}
{"market":"0x2a903c589141bce4a1e50fb98b73397af6820942542793ab10b1df477e912b6e", "price_changes":[{"asset_id":"68919878716222388542639225642064847629616106443780159680232863841946753372582", "price":"0.07", "size":"352.1", "side":"BUY", "hash":"7ab112be3f6169bcf2d352b5bab551953e555e38", "best_bid":"0.14", "best_ask":"0.16"}, {"asset_id":"20436996072316278452977393149218961565084965483366669504673105646378938504388", "price":"0.93", "size":"352.1", "side":"SELL", "hash":"83347616a23272d1d228d47e03a4042b649af348", "best_bid":"0.84", "best_ask":"0.86"}], "timestamp":"1778784200616", "event_type":"price_change"}
{"market":"0x2a903c589141bce4a1e50fb98b73397af6820942542793ab10b1df477e912b6e", "price_changes":[{"asset_id":"20436996072316278452977393149218961565084965483366669504673105646378938504388", "price":"0.73", "size":"170.2", "side":"BUY", "hash":"3486ed3158ddba9494593bfa58445c2f7565d24c", "best_bid":"0.84", "best_ask":"0.86"}, {"asset_id":"68919878716222388542639225642064847629616106443780159680232863841946753372582", "price":"0.27", "size":"170.2", "side":"SELL", "hash":"fae4640c5faeddb289629e8ab1141110a7e1d1d1", "best_bid":"0.14", "best_ask":"0.16"}], "timestamp":"1778784200616", "event_type":"price_change"}
{"market":"0x2a903c589141bce4a1e50fb98b73397af6820942542793ab10b1df477e912b6e", "price_changes":[{"asset_id":"68919878716222388542639225642064847629616106443780159680232863841946753372582", "price":"0.08", "size":"348.74", "side":"BUY", "hash":"08790a8a342925e3d60473c6dd992533a0743153", "best_bid":"0.14", "best_ask":"0.16"}, {"asset_id":"20436996072316278452977393149218961565084965483366669504673105646378938504388", "price":"0.92", "size":"348.74", "side":"SELL", "hash":"b216858453d0b2888573ef8bcc751c967e9e6be0", "best_bid":"0.84", "best_ask":"0.86"}], "timestamp":"1778784200618", "event_type":"price_change"}
{"market":"0x2a903c589141bce4a1e50fb98b73397af6820942542793ab10b1df477e912b6e", "price_changes":[{"asset_id":"20436996072316278452977393149218961565084965483366669504673105646378938504388", "price":"0.91", "size":"357.1", "side":"SELL", "hash":"99981e76168050b0354de073168c63127cad5d1c", "best_bid":"0.84", "best_ask":"0.86"}, {"asset_id":"68919878716222388542639225642064847629616106443780159680232863841946753372582", "price":"0.09", "size":"357.1", "side":"BUY", "hash":"6881910e8d24be4d49d15c589949aee476eeb749", "best_bid":"0.14", "best_ask":"0.16"}], "timestamp":"1778784200618", "event_type":"price_change"}
{"market":"0x2a903c589141bce4a1e50fb98b73397af6820942542793ab10b1df477e912b6e", "price_changes":[{"asset_id":"20436996072316278452977393149218961565084965483366669504673105646378938504388", "price":"0.75", "size":"406", "side":"BUY", "hash":"c4dbc7c4d8750fe2922d1a794e643a4c771e4c30", "best_bid":"0.84", "best_ask":"0.86"}, {"asset_id":"68919878716222388542639225642064847629616106443780159680232863841946753372582", "price":"0.25", "size":"406", "side":"SELL", "hash":"4e7662bfcaf612fe0b38232fd340f5fc049bbf1b", "best_bid":"0.14", "best_ask":"0.16"}], "timestamp":"1778784200619", "event_type":"price_change"}
{"market":"0x2a903c589141bce4a1e50fb98b73397af6820942542793ab10b1df477e912b6e", "price_changes":[{"asset_id":"68919878716222388542639225642064847629616106443780159680232863841946753372582", "price":"0.06", "size":"297.2", "side":"BUY", "hash":"d509a9ec21afb42d78e794347f42709c8063599f", "best_bid":"0.14", "best_ask":"0.16"}, {"asset_id":"20436996072316278452977393149218961565084965483366669504673105646378938504388", "price":"0.94", "size":"297.2", "side":"SELL", "hash":"b9ba6ef5c3e2642a0d566df45cd212f9f19f1944", "best_bid":"0.84", "best_ask":"0.86"}], "timestamp":"1778784200620", "event_type":"price_change"}
{"market":"0x2a903c589141bce4a1e50fb98b73397af6820942542793ab10b1df477e912b6e", "price_changes":[{"asset_id":"68919878716222388542639225642064847629616106443780159680232863841946753372582", "price":"0.1", "size":"517", "side":"BUY", "hash":"8cfe08d536b0485b2520c49ccdb016327e91e164", "best_bid":"0.14", "best_ask":"0.16"}, {"asset_id":"20436996072316278452977393149218961565084965483366669504673105646378938504388", "price":"0.9", "size":"517", "side":"SELL", "hash":"230166cebe39063a2ebe096ad14c46e4a7ca1d7d", "best_bid":"0.84", "best_ask":"0.86"}], "timestamp":"1778784200621", "event_type":"price_change"}
{"market":"0x2a903c589141bce4a1e50fb98b73397af6820942542793ab10b1df477e912b6e", "price_changes":[{"asset_id":"20436996072316278452977393149218961565084965483366669504673105646378938504388", "price":"0.34", "size":"398.4", "side":"BUY", "hash":"56964b3be942975cd33309d216b0e403f45f98b6", "best_bid":"0.84", "best_ask":"0.86"}, {"asset_id":"68919878716222388542639225642064847629616106443780159680232863841946753372582", "price":"0.66", "size":"398.4", "side":"SELL", "hash":"94cc4dd831ab4c939573caae325c6f9879ebdfda", "best_bid":"0.14", "best_ask":"0.16"}], "timestamp":"1778784200622", "event_type":"price_change"}
{"market":"0x2a903c589141bce4a1e50fb98b73397af6820942542793ab10b1df477e912b6e", "price_changes":[{"asset_id":"20436996072316278452977393149218961565084965483366669504673105646378938504388", "price":"0.33", "size":"118.6", "side":"BUY", "hash":"81f6d43f158d622c851e9e4abbe8a4e9e74e8822", "best_bid":"0.84", "best_ask":"0.86"}, {"asset_id":"68919878716222388542639225642064847629616106443780159680232863841946753372582", "price":"0.67", "size":"118.6", "side":"SELL", "hash":"3731f0c49c54d334bc8ea676347e9c19a11e0c7d", "best_bid":"0.14", "best_ask":"0.16"}], "timestamp":"1778784200623", "event_type":"price_change"}
{"market":"0x2a903c589141bce4a1e50fb98b73397af6820942542793ab10b1df477e912b6e", "price_changes":[{"asset_id":"20436996072316278452977393149218961565084965483366669504673105646378938504388", "price":"0.73", "size":"165.2", "side":"BUY", "hash":"996af9925241f0b38b43aa9567d5e4e7b84099d4", "best_bid":"0.84", "best_ask":"0.86"}, {"asset_id":"68919878716222388542639225642064847629616106443780159680232863841946753372582", "price":"0.27", "size":"165.2", "side":"SELL", "hash":"479f90e2f84fc4bb6f3cf3e584351f6821144946", "best_bid":"0.14", "best_ask":"0.16"}], "timestamp":"1778784200624", "event_type":"price_change"}
{"market":"0x2a903c589141bce4a1e50fb98b73397af6820942542793ab10b1df477e912b6e", "price_changes":[{"asset_id":"68919878716222388542639225642064847629616106443780159680232863841946753372582", "price":"0.07", "size":"362.1", "side":"BUY", "hash":"09a6472e3e12d3e25d3b6e4543f2238ff56dc59c", "best_bid":"0.14", "best_ask":"0.16"}, {"asset_id":"20436996072316278452977393149218961565084965483366669504673105646378938504388", "price":"0.93", "size":"362.1", "side":"SELL", "hash":"5dec83bbce6bdaac122eeb4c42b63f690762c334", "best_bid":"0.84", "best_ask":"0.86"}], "timestamp":"1778784200625", "event_type":"price_change"}
{"market":"0x2a903c589141bce4a1e50fb98b73397af6820942542793ab10b1df477e912b6e", "price_changes":[{"asset_id":"20436996072316278452977393149218961565084965483366669504673105646378938504388", "price":"0.38", "size":"297.7", "side":"BUY", "hash":"04a6f5269eaaf360654671b43f37e703e697aceb", "best_bid":"0.84", "best_ask":"0.86"}, {"asset_id":"68919878716222388542639225642064847629616106443780159680232863841946753372582", "price":"0.62", "size":"297.7", "side":"SELL", "hash":"397b8a6f770fbc41d396dc3cb1a67cbd44cc3e12", "best_bid":"0.14", "best_ask":"0.16"}], "timestamp":"1778784200626", "event_type":"price_change"}
{"market":"0x2a903c589141bce4a1e50fb98b73397af6820942542793ab10b1df477e912b6e", "price_changes":[{"asset_id":"20436996072316278452977393149218961565084965483366669504673105646378938504388", "price":"0.83", "size":"6", "side":"BUY", "hash":"eef61a28be966e68cdfc46e67d2c740d17b2d6d7", "best_bid":"0.84", "best_ask":"0.86"}, {"asset_id":"68919878716222388542639225642064847629616106443780159680232863841946753372582", "price":"0.17", "size":"6", "side":"SELL", "hash":"1b861f2424681b5e6763058069845ee338c2387e", "best_bid":"0.14", "best_ask":"0.16"}], "timestamp":"1778784200627", "event_type":"price_change"}
{"market":"0x2a903c589141bce4a1e50fb98b73397af6820942542793ab10b1df477e912b6e", "price_changes":[{"asset_id":"68919878716222388542639225642064847629616106443780159680232863841946753372582", "price":"0.11", "size":"552.57", "side":"BUY", "hash":"e3213412ffb2329a844ab274742adb8d63639dc1", "best_bid":"0.14", "best_ask":"0.16"}, {"asset_id":"20436996072316278452977393149218961565084965483366669504673105646378938504388", "price":"0.89", "size":"552.57", "side":"SELL", "hash":"533bd44823c9fedc224a5044cd43416b3f2cda69", "best_bid":"0.84", "best_ask":"0.86"}], "timestamp":"1778784200629", "event_type":"price_change"}
{"market":"0x2a903c589141bce4a1e50fb98b73397af6820942542793ab10b1df477e912b6e", "price_changes":[{"asset_id":"20436996072316278452977393149218961565084965483366669504673105646378938504388", "price":"0.84", "size":"35", "side":"BUY", "hash":"73cf0e509126dde193f0e34383985bcfed820677", "best_bid":"0.84", "best_ask":"0.86"}, {"asset_id":"68919878716222388542639225642064847629616106443780159680232863841946753372582", "price":"0.16", "size":"35", "side":"SELL", "hash":"67f9b6ca42742aba4a294b46258de7b36153b747", "best_bid":"0.14", "best_ask":"0.16"}], "timestamp":"1778784200630", "event_type":"price_change"}
{"market":"0x2a903c589141bce4a1e50fb98b73397af6820942542793ab10b1df477e912b6e", "price_changes":[{"asset_id":"68919878716222388542639225642064847629616106443780159680232863841946753372582", "price":"0.47", "size":"337", "side":"SELL", "hash":"2d25c000ba534439ba51d13aaf1ed4260de83896", "best_bid":"0.14", "best_ask":"0.16"}, {"asset_id":"20436996072316278452977393149218961565084965483366669504673105646378938504388", "price":"0.53", "size":"337", "side":"BUY", "hash":"1fa7fa20a5c195881c5bd30fff5ff0ea5bfd5599", "best_bid":"0.84", "best_ask":"0.86"}], "timestamp":"1778784200631", "event_type":"price_change"}
{"market":"0x2a903c589141bce4a1e50fb98b73397af6820942542793ab10b1df477e912b6e", "price_changes":[{"asset_id":"20436996072316278452977393149218961565084965483366669504673105646378938504388", "price":"0.83", "size":"11", "side":"BUY", "hash":"253d95872c8029a461bd12a63a1f28961b83ff38", "best_bid":"0.84", "best_ask":"0.86"}, {"asset_id":"68919878716222388542639225642064847629616106443780159680232863841946753372582", "price":"0.17", "size":"11", "side":"SELL", "hash":"483927e9f2d2ca59d32bf59971fc80ceb66efa21", "best_bid":"0.14", "best_ask":"0.16"}], "timestamp":"1778784200632", "event_type":"price_change"}
{"market":"0x2a903c589141bce4a1e50fb98b73397af6820942542793ab10b1df477e912b6e", "price_changes":[{"asset_id":"68919878716222388542639225642064847629616106443780159680232863841946753372582", "price":"0.13", "size":"116.87", "side":"BUY", "hash":"e55e4930aa49b02d7f450ba2195ba418d7bb8308", "best_bid":"0.14", "best_ask":"0.16"}, {"asset_id":"20436996072316278452977393149218961565084965483366669504673105646378938504388", "price":"0.87", "size":"116.87", "side":"SELL", "hash":"c8bd92594a2325b802adb8b31ec22f6bcabb0196", "best_bid":"0.84", "best_ask":"0.86"}], "timestamp":"1778784200634", "event_type":"price_change"}
{"market":"0x2a903c589141bce4a1e50fb98b73397af6820942542793ab10b1df477e912b6e", "price_changes":[{"asset_id":"68919878716222388542639225642064847629616106443780159680232863841946753372582", "price":"0.12", "size":"22.41", "side":"BUY", "hash":"2d463422e403d2bb2c0331bf839ac3dc74e7fb27", "best_bid":"0.14", "best_ask":"0.16"}, {"asset_id":"20436996072316278452977393149218961565084965483366669504673105646378938504388", "price":"0.88", "size":"22.41", "side":"SELL", "hash":"10ecbf94938266ba66ac3efb5d0c475fa5ce7eb4", "best_bid":"0.84", "best_ask":"0.86"}], "timestamp":"1778784200635", "event_type":"price_change"}
{"market":"0x2a903c589141bce4a1e50fb98b73397af6820942542793ab10b1df477e912b6e", "price_changes":[{"asset_id":"68919878716222388542639225642064847629616106443780159680232863841946753372582", "price":"0.01", "size":"11333.83", "side":"BUY", "hash":"31839bd8df210322a18d6b88aeea6635b4343b99", "best_bid":"0.14", "best_ask":"0.16"}, {"asset_id":"20436996072316278452977393149218961565084965483366669504673105646378938504388", "price":"0.99", "size":"11333.83", "side":"SELL", "hash":"b56a2ba95f31294441a7b537aa7f7c9db0aa9eaf", "best_bid":"0.84", "best_ask":"0.86"}], "timestamp":"1778784200636", "event_type":"price_change"}
{"market":"0x2a903c589141bce4a1e50fb98b73397af6820942542793ab10b1df477e912b6e", "price_changes":[{"asset_id":"20436996072316278452977393149218961565084965483366669504673105646378938504388", "price":"0.48", "size":"297.12", "side":"BUY", "hash":"39edcdf0d5bd043522b4007218ecc130f4109625", "best_bid":"0.84", "best_ask":"0.86"}, {"asset_id":"68919878716222388542639225642064847629616106443780159680232863841946753372582", "price":"0.52", "size":"297.12", "side":"SELL", "hash":"9e75c3933d115daf63aaeeb84193f812162b07cb", "best_bid":"0.14", "best_ask":"0.16"}], "timestamp":"1778784200637", "event_type":"price_change"}
{"market":"0x2a903c589141bce4a1e50fb98b73397af6820942542793ab10b1df477e912b6e", "price_changes":[{"asset_id":"68919878716222388542639225642064847629616106443780159680232863841946753372582", "price":"0.01", "size":"11338.83", "side":"BUY", "hash":"e697c0d28112f243464b37a541ecef2a0bffd76f", "best_bid":"0.14", "best_ask":"0.16"}, {"asset_id":"20436996072316278452977393149218961565084965483366669504673105646378938504388", "price":"0.99", "size":"11338.83", "side":"SELL", "hash":"13f0b50e184c6d03b1de7053c7d98889b111bf98", "best_bid":"0.84", "best_ask":"0.86"}], "timestamp":"1778784200638", "event_type":"price_change"}
{"market":"0x2a903c589141bce4a1e50fb98b73397af6820942542793ab10b1df477e912b6e", "price_changes":[{"asset_id":"20436996072316278452977393149218961565084965483366669504673105646378938504388", "price":"0.84", "size":"28.75", "side":"BUY", "hash":"08e8c739681fabe7736624d6933e03ec148496a4", "best_bid":"0.84", "best_ask":"0.86"}, {"asset_id":"68919878716222388542639225642064847629616106443780159680232863841946753372582", "price":"0.16", "size":"28.75", "side":"SELL", "hash":"4a596979a620ed417cbfa6e4f361df5a0b5798ce", "best_bid":"0.14", "best_ask":"0.16"}], "timestamp":"1778784200644", "event_type":"price_change"}
{"market":"0x2a903c589141bce4a1e50fb98b73397af6820942542793ab10b1df477e912b6e", "asset_id":"68919878716222388542639225642064847629616106443780159680232863841946753372582", "bids":[{"price":"0.01", "size":"11338.83"}, {"price":"0.02", "size":"1397.82"}, {"price":"0.03", "size":"1090.78"}, {"price":"0.04", "size":"1237.82"}, {"price":"0.05", "size":"755.72"}, {"price":"0.06", "size":"297.2"}, {"price":"0.07", "size":"362.1"}, {"price":"0.08", "size":"348.74"}, {"price":"0.09", "size":"357.1"}, {"price":"0.1", "size":"517"}, {"price":"0.11", "size":"552.57"}, {"price":"0.12", "size":"22.41"}, {"price":"0.13", "size":"116.87"}, {"price":"0.14", "size":"170.88"}], "asks":[{"price":"0.99", "size":"11995.61"}, {"price":"0.98", "size":"1219.45"}, {"price":"0.97", "size":"1111.98"}, {"price":"0.96", "size":"670.05"}, {"price":"0.95", "size":"549.45"}, {"price":"0.94", "size":"346.2"}, {"price":"0.93", "size":"902.05"}, {"price":"0.92", "size":"170.79"}, {"price":"0.91", "size":"234.6"}, {"price":"0.9", "size":"128"}, {"price":"0.89", "size":"142.6"}, {"price":"0.88", "size":"141.8"}, {"price":"0.87", "size":"144.81"}, {"price":"0.86", "size":"204.9"}, {"price":"0.85", "size":"113.5"}, {"price":"0.84", "size":"102.3"}, {"price":"0.83", "size":"101.3"}, {"price":"0.82", "size":"105.3"}, {"price":"0.81", "size":"199.5"}, {"price":"0.8", "size":"103.8"}, {"price":"0.79", "size":"98.1"}, {"price":"0.78", "size":"97.5"}, {"price":"0.77", "size":"96.89"}, {"price":"0.76", "size":"201.39"}, {"price":"0.75", "size":"116"}, {"price":"0.74", "size":"100.6"}, {"price":"0.73", "size":"95.2"}, {"price":"0.72", "size":"94.9"}, {"price":"0.71", "size":"199.6"}, {"price":"0.7", "size":"94.3"}, {"price":"0.69", "size":"108.28"}, {"price":"0.68", "size":"98.8"}, {"price":"0.67", "size":"118.6"}, {"price":"0.66", "size":"398.4"}, {"price":"0.65", "size":"507.3"}, {"price":"0.64", "size":"293"}, {"price":"0.63", "size":"892.9"}, {"price":"0.62", "size":"297.7"}, {"price":"0.61", "size":"397.6"}, {"price":"0.6", "size":"356.93"}, {"price":"0.59", "size":"297.4"}, {"price":"0.58", "size":"109.6"}, {"price":"0.57", "size":"131.48"}, {"price":"0.56", "size":"413.97"}, {"price":"0.55", "size":"334.2"}, {"price":"0.54", "size":"375.6"}, {"price":"0.53", "size":"292"}, {"price":"0.52", "size":"297.12"}, {"price":"0.51", "size":"402"}, {"price":"0.5", "size":"355.91"}, {"price":"0.49", "size":"312"}, {"price":"0.48", "size":"317"}, {"price":"0.47", "size":"337"}, {"price":"0.46", "size":"451.54"}, {"price":"0.45", "size":"346.64"}, {"price":"0.44", "size":"346.45"}, {"price":"0.43", "size":"434.89"}, {"price":"0.42", "size":"724.36"}, {"price":"0.41", "size":"412.4"}, {"price":"0.4", "size":"328.83"}, {"price":"0.39", "size":"297.6"}, {"price":"0.38", "size":"318.44"}, {"price":"0.37", "size":"297.9"}, {"price":"0.36", "size":"203"}, {"price":"0.35", "size":"340.14"}, {"price":"0.34", "size":"350.9"}, {"price":"0.33", "size":"343.6"}, {"price":"0.32", "size":"2095.88"}, {"price":"0.31", "size":"559"}, {"price":"0.3", "size":"164.3"}, {"price":"0.29", "size":"646.38"}, {"price":"0.28", "size":"139.9"}, {"price":"0.27", "size":"165.2"}, {"price":"0.26", "size":"230.6"}, {"price":"0.25", "size":"406"}, {"price":"0.24", "size":"206.39"}, {"price":"0.23", "size":"246.89"}, {"price":"0.22", "size":"249.5"}, {"price":"0.21", "size":"275.44"}, {"price":"0.2", "size":"128.8"}, {"price":"0.19", "size":"72.35"}, {"price":"0.18", "size":"334.82"}, {"price":"0.17", "size":"11"}, {"price":"0.16", "size":"28.75"}], "hash":"4a596979a620ed417cbfa6e4f361df5a0b5798ce", "timestamp":"1778784200644", "event_type":"book"}
{"market":"0x2a903c589141bce4a1e50fb98b73397af6820942542793ab10b1df477e912b6e", "price_changes":[{"asset_id":"68919878716222388542639225642064847629616106443780159680232863841946753372582", "price":"0.12", "size":"42.41", "side":"BUY", "hash":"89366ef7a61999fe0317d58dfc26433bf2652b36", "best_bid":"0.14", "best_ask":"0.16"}, {"asset_id":"20436996072316278452977393149218961565084965483366669504673105646378938504388", "price":"0.88", "size":"42.41", "side":"SELL", "hash":"df81b2cb8c1ccc5e711652d391ff14f4540d1603", "best_bid":"0.84", "best_ask":"0.86"}], "timestamp":"1778784200645", "event_type":"price_change"}
{"market":"0x2a903c589141bce4a1e50fb98b73397af6820942542793ab10b1df477e912b6e", "price_changes":[{"asset_id":"68919878716222388542639225642064847629616106443780159680232863841946753372582", "price":"0.11", "size":"547.57", "side":"BUY", "hash":"c5575ef0a44d0d5c4b31d08832a5ff645192f286", "best_bid":"0.14", "best_ask":"0.16"}, {"asset_id":"20436996072316278452977393149218961565084965483366669504673105646378938504388", "price":"0.89", "size":"547.57", "side":"SELL", "hash":"cf8cd76870a24da60f90b00c7b786163afc01cbb", "best_bid":"0.84", "best_ask":"0.86"}], "timestamp":"1778784200646", "event_type":"price_change"}
{"market":"0x2a903c589141bce4a1e50fb98b73397af6820942542793ab10b1df477e912b6e", "price_changes":[{"asset_id":"68919878716222388542639225642064847629616106443780159680232863841946753372582", "price":"0.11", "size":"552.57", "side":"BUY", "hash":"5eb52d010d6667cbb27a05a4286c1f5f46e816ea", "best_bid":"0.14", "best_ask":"0.16"}, {"asset_id":"20436996072316278452977393149218961565084965483366669504673105646378938504388", "price":"0.89", "size":"552.57", "side":"SELL", "hash":"698aa0a3b6c28e09a832010a57683ef1b141489c", "best_bid":"0.84", "best_ask":"0.86"}], "timestamp":"1778784200647", "event_type":"price_change"}
{"market":"0x2a903c589141bce4a1e50fb98b73397af6820942542793ab10b1df477e912b6e", "price_changes":[{"asset_id":"68919878716222388542639225642064847629616106443780159680232863841946753372582", "price":"0.12", "size":"242.41", "side":"BUY", "hash":"d42e27c9955e94fd82326ab68034e04fc7bfa4b6", "best_bid":"0.14", "best_ask":"0.16"}, {"asset_id":"20436996072316278452977393149218961565084965483366669504673105646378938504388", "price":"0.88", "size":"242.41", "side":"SELL", "hash":"ea08e737a73bf10f9605cd4726d3a7e1533cf466", "best_bid":"0.84", "best_ask":"0.86"}], "timestamp":"1778784200648", "event_type":"price_change"}
{"market":"0x2a903c589141bce4a1e50fb98b73397af6820942542793ab10b1df477e912b6e", "price_changes":[{"asset_id":"20436996072316278452977393149218961565084965483366669504673105646378938504388", "price":"0.63", "size":"576.9", "side":"BUY", "hash":"3d3422b366b02cb473258df8ebcd5242eb134e04", "best_bid":"0.84", "best_ask":"0.86"}, {"asset_id":"68919878716222388542639225642064847629616106443780159680232863841946753372582", "price":"0.37", "size":"576.9", "side":"SELL", "hash":"bea4337a222fe880dc6008612d7e556416330b44", "best_bid":"0.14", "best_ask":"0.16"}], "timestamp":"1778784200648", "event_type":"price_change"}
{"market":"0x2a903c589141bce4a1e50fb98b73397af6820942542793ab10b1df477e912b6e", "price_changes":[{"asset_id":"68919878716222388542639225642064847629616106443780159680232863841946753372582", "price":"0.11", "size":"579.57", "side":"BUY", "hash":"ffcc72cb1b1ce81940b1b473cd56c96562845c0f", "best_bid":"0.14", "best_ask":"0.16"}, {"asset_id":"20436996072316278452977393149218961565084965483366669504673105646378938504388", "price":"0.89", "size":"579.57", "side":"SELL", "hash":"76d9a674a12a09c65c22e8e171c3ff79f5dee3df", "best_bid":"0.84", "best_ask":"0.86"}], "timestamp":"1778784200650", "event_type":"price_change"}
{"market":"0x2a903c589141bce4a1e50fb98b73397af6820942542793ab10b1df477e912b6e", "price_changes":[{"asset_id":"20436996072316278452977393149218961565084965483366669504673105646378938504388", "price":"0.87", "size":"141.87", "side":"SELL", "hash":"e316748a657a6311d78f1df5c605dc2d71f6eefb", "best_bid":"0.84", "best_ask":"0.86"}, {"asset_id":"68919878716222388542639225642064847629616106443780159680232863841946753372582", "price":"0.13", "size":"141.87", "side":"BUY", "hash":"f325d7f484ad8ab69985286d66526815547b25ba", "best_bid":"0.14", "best_ask":"0.16"}], "timestamp":"1778784200651", "event_type":"price_change"}
{"market":"0x2a903c589141bce4a1e50fb98b73397af6820942542793ab10b1df477e912b6e", "price_changes":[{"asset_id":"20436996072316278452977393149218961565084965483366669504673105646378938504388", "price":"0.71", "size":"616.38", "side":"BUY", "hash":"7fcb210b816d4e6604f89d5fef4321c1e6e3ab31", "best_bid":"0.84", "best_ask":"0.86"}, {"asset_id":"68919878716222388542639225642064847629616106443780159680232863841946753372582", "price":"0.29", "size":"616.38", "side":"SELL", "hash":"6321858e5ec9d40d84e44ddaa73e0ee4d49e9602", "best_bid":"0.14", "best_ask":"0.16"}], "timestamp":"1778784200651", "event_type":"price_change"}
{"market":"0x2a903c589141bce4a1e50fb98b73397af6820942542793ab10b1df477e912b6e", "price_changes":[{"asset_id":"20436996072316278452977393149218961565084965483366669504673105646378938504388", "price":"0.9", "size":"570.99", "side":"SELL", "hash":"bea6bc5079c9ff6a57e8bcc33aa55958d59ca5bc", "best_bid":"0.84", "best_ask":"0.86"}, {"asset_id":"68919878716222388542639225642064847629616106443780159680232863841946753372582", "price":"0.1", "size":"570.99", "side":"BUY", "hash":"33d0b1cb9f26afa692d1619aae5a16c95d593cf3", "best_bid":"0.14", "best_ask":"0.16"}], "timestamp":"1778784200653", "event_type":"price_change"}
{"market":"0x2a903c589141bce4a1e50fb98b73397af6820942542793ab10b1df477e912b6e", "price_changes":[{"asset_id":"20436996072316278452977393149218961565084965483366669504673105646378938504388", "price":"0.68", "size":"2065.88", "side":"BUY", "hash":"07e8a9ac924edef171a42861cdaf289cb00f65f9", "best_bid":"0.84", "best_ask":"0.86"}, {"asset_id":"68919878716222388542639225642064847629616106443780159680232863841946753372582", "price":"0.32", "size":"2065.88", "side":"SELL", "hash":"7184091a7bd9e53c989098a9abf9139cce58c21f", "best_bid":"0.14", "best_ask":"0.16"}], "timestamp":"1778784200653", "event_type":"price_change"}
{"market":"0x2a903c589141bce4a1e50fb98b73397af6820942542793ab10b1df477e912b6e", "price_changes":[{"asset_id":"68919878716222388542639225642064847629616106443780159680232863841946753372582", "price":"0.11", "size":"449.18", "side":"BUY", "hash":"3486186c3bcb6b83ede918d1cbdde90aa1e46f5c", "best_bid":"0.14", "best_ask":"0.16"}, {"asset_id":"20436996072316278452977393149218961565084965483366669504673105646378938504388", "price":"0.89", "size":"449.18", "side":"SELL", "hash":"53f1f6ed57a63b0e930fa57d4e66882f627a470d", "best_bid":"0.84", "best_ask":"0.86"}], "timestamp":"1778784200654", "event_type":"price_change"}
{"market":"0x2a903c589141bce4a1e50fb98b73397af6820942542793ab10b1df477e912b6e", "price_changes":[{"asset_id":"20436996072316278452977393149218961565084965483366669504673105646378938504388", "price":"0.66", "size":"320.9", "side":"BUY", "hash":"dfe843c47ed4b91412c532e2a114caab74495b45", "best_bid":"0.84", "best_ask":"0.86"}, {"asset_id":"68919878716222388542639225642064847629616106443780159680232863841946753372582", "price":"0.34", "size":"320.9", "side":"SELL", "hash":"998650b89319cccd911c0ad82ce5e65c162b3306", "best_bid":"0.14", "best_ask":"0.16"}], "timestamp":"1778784200655", "event_type":"price_change"}
{"market":"0x2a903c589141bce4a1e50fb98b73397af6820942542793ab10b1df477e912b6e", "price_changes":[{"asset_id":"68919878716222388542639225642064847629616106443780159680232863841946753372582", "price":"0.33", "size":"348.6", "side":"SELL", "hash":"03084896296d0f7bea011229cfad7cbaabd92e80", "best_bid":"0.14", "best_ask":"0.16"}, {"asset_id":"20436996072316278452977393149218961565084965483366669504673105646378938504388", "price":"0.67", "size":"348.6", "side":"BUY", "hash":"23fa54135b369395debf7536ba930653b0c29eb0", "best_bid":"0.84", "best_ask":"0.86"}], "timestamp":"1778784200657", "event_type":"price_change"}
{"market":"0x2a903c589141bce4a1e50fb98b73397af6820942542793ab10b1df477e912b6e", "price_changes":[{"asset_id":"68919878716222388542639225642064847629616106443780159680232863841946753372582", "price":"0.12", "size":"233.41", "side":"BUY", "hash":"3730cbeab3e1a24f679e9a893c8339d3fa6c8304", "best_bid":"0.14", "best_ask":"0.16"}, {"asset_id":"20436996072316278452977393149218961565084965483366669504673105646378938504388", "price":"0.88", "size":"233.41", "side":"SELL", "hash":"1b2757104f79044af54813d0b6f586105f01d3cf", "best_bid":"0.84", "best_ask":"0.86"}], "timestamp":"1778784200659", "event_type":"price_change"}
{"market":"0x2a903c589141bce4a1e50fb98b73397af6820942542793ab10b1df477e912b6e", "price_changes":[{"asset_id":"20436996072316278452977393149218961565084965483366669504673105646378938504388", "price":"0.67", "size":"353.6", "side":"BUY", "hash":"99fe9b78a42a3662410e69926799f26816e9d4ae", "best_bid":"0.84", "best_ask":"0.86"}, {"asset_id":"68919878716222388542639225642064847629616106443780159680232863841946753372582", "price":"0.33", "size":"353.6", "side":"SELL", "hash":"3e71e0c68efded5f1b9513f2f3f5c0cd7888b98c", "best_bid":"0.14", "best_ask":"0.16"}], "timestamp":"1778784200659", "event_type":"price_change"}
{"market":"0x2a903c589141bce4a1e50fb98b73397af6820942542793ab10b1df477e912b6e", "price_changes":[{"asset_id":"20436996072316278452977393149218961565084965483366669504673105646378938504388", "price":"0.7", "size":"134.3", "side":"BUY", "hash":"e68878028aa882436c611a247be76c9843eae72b", "best_bid":"0.84", "best_ask":"0.86"}, {"asset_id":"68919878716222388542639225642064847629616106443780159680232863841946753372582", "price":"0.3", "size":"134.3", "side":"SELL", "hash":"336db1c237b37a01633e8f0d99b580f4b1b9593e", "best_bid":"0.14", "best_ask":"0.16"}], "timestamp":"1778784200661", "event_type":"price_change"}
{"market":"0x2a903c589141bce4a1e50fb98b73397af6820942542793ab10b1df477e912b6e", "price_changes":[{"asset_id":"20436996072316278452977393149218961565084965483366669504673105646378938504388", "price":"0.67", "size":"323.6", "side":"BUY", "hash":"15d73a5560be38a166fa7c05069d5166fac62c82", "best_bid":"0.84", "best_ask":"0.86"}, {"asset_id":"68919878716222388542639225642064847629616106443780159680232863841946753372582", "price":"0.33", "size":"323.6", "side":"SELL", "hash":"f78293aba863fbbf8386ffb496f9106bbce0227a", "best_bid":"0.14", "best_ask":"0.16"}], "timestamp":"1778784200662", "event_type":"price_change"}
{"market":"0x2a903c589141bce4a1e50fb98b73397af6820942542793ab10b1df477e912b6e", "price_changes":[{"asset_id":"20436996072316278452977393149218961565084965483366669504673105646378938504388", "price":"0.8", "size":"110", "side":"BUY", "hash":"3c3cbad419dc32b52407ce6b6e3f9b40657c2a12", "best_bid":"0.84", "best_ask":"0.86"}, {"asset_id":"68919878716222388542639225642064847629616106443780159680232863841946753372582", "price":"0.2", "size":"110", "side":"SELL", "hash":"030fb6e751ace51702375ccff7d09af774bb6deb", "best_bid":"0.14", "best_ask":"0.16"}], "timestamp":"1778784200664", "event_type":"price_change"}
{"market":"0x2a903c589141bce4a1e50fb98b73397af6820942542793ab10b1df477e912b6e", "price_changes":[{"asset_id":"68919878716222388542639225642064847629616106443780159680232863841946753372582", "price":"0.11", "size":"417.18", "side":"BUY", "hash":"9a0f69b39a8f71badbc63edbcf200c07a532f10d", "best_bid":"0.14", "best_ask":"0.16"}, {"asset_id":"20436996072316278452977393149218961565084965483366669504673105646378938504388", "price":"0.89", "size":"417.18", "side":"SELL", "hash":"f2a12355c5a748197545d6e6a29a1205d6b64178", "best_bid":"0.84", "best_ask":"0.86"}], "timestamp":"1778784200665", "event_type":"price_change"}
{"market":"0x2a903c589141bce4a1e50fb98b73397af6820942542793ab10b1df477e912b6e", "price_changes":[{"asset_id":"68919878716222388542639225642064847629616106443780159680232863841946753372582", "price":"0.15", "size":"30", "side":"BUY", "hash":"f2abc2d48f0f586b058227a7f0a68d10a7265c79", "best_bid":"0.15", "best_ask":"0.16"}, {"asset_id":"20436996072316278452977393149218961565084965483366669504673105646378938504388", "price":"0.85", "size":"30", "side":"SELL", "hash":"15d3b1fad34bde91dc7261fc3b61fe73d9c5a86a", "best_bid":"0.84", "best_ask":"0.85"}], "timestamp":"1778784200666", "event_type":"price_change"}
{"market":"0x2a903c589141bce4a1e50fb98b73397af6820942542793ab10b1df477e912b6e", "price_changes":[{"asset_id":"68919878716222388542639225642064847629616106443780159680232863841946753372582", "price":"0.13", "size":"55", "side":"BUY", "hash":"ce2e5db67a0868c3167a7941ca987ebc910497b8", "best_bid":"0.15", "best_ask":"0.16"}, {"asset_id":"20436996072316278452977393149218961565084965483366669504673105646378938504388", "price":"0.87", "size":"55", "side":"SELL", "hash":"d1e68a60639956ae1a59713e1d0c5f8981797c0f", "best_bid":"0.84", "best_ask":"0.85"}], "timestamp":"1778784200667", "event_type":"price_change"}
{"market":"0x2a903c589141bce4a1e50fb98b73397af6820942542793ab10b1df477e912b6e", "asset_id":"68919878716222388542639225642064847629616106443780159680232863841946753372582", "price":"0.16", "size":"6.25", "fee_rate_bps":"0", "side":"BUY", "timestamp":"1778784200666", "event_type":"last_trade_price", "transaction_hash":"0x18a8b22fa772118b037bb9666047647c936ef0fee4e85a251c3ad5ca5ea80954"}
{"market":"0x2a903c589141bce4a1e50fb98b73397af6820942542793ab10b1df477e912b6e", "price_changes":[{"asset_id":"20436996072316278452977393149218961565084965483366669504673105646378938504388", "price":"0.83", "size":"31", "side":"BUY", "hash":"c3bd0c79e007b9b3636ebf18ee64fb70bd366572", "best_bid":"0.84", "best_ask":"0.85"}, {"asset_id":"68919878716222388542639225642064847629616106443780159680232863841946753372582", "price":"0.17", "size":"31", "side":"SELL", "hash":"40e9481fc600ed543dbfa49b3da103a0093817fe", "best_bid":"0.15", "best_ask":"0.16"}], "timestamp":"1778784200668", "event_type":"price_change"}
{"market":"0x2a903c589141bce4a1e50fb98b73397af6820942542793ab10b1df477e912b6e", "price_changes":[{"asset_id":"20436996072316278452977393149218961565084965483366669504673105646378938504388", "price":"0.82", "size":"364.82", "side":"BUY", "hash":"f0568359593226528312db1c6223120a06c0d3c3", "best_bid":"0.84", "best_ask":"0.85"}, {"asset_id":"68919878716222388542639225642064847629616106443780159680232863841946753372582", "price":"0.18", "size":"364.82", "side":"SELL", "hash":"75f55489571a6405a4fa77947bb0458270a2905a", "best_bid":"0.15", "best_ask":"0.16"}], "timestamp":"1778784200670", "event_type":"price_change"}
{"market":"0x2a903c589141bce4a1e50fb98b73397af6820942542793ab10b1df477e912b6e", "price_changes":[{"asset_id":"20436996072316278452977393149218961565084965483366669504673105646378938504388", "price":"0.81", "size":"172.35", "side":"BUY", "hash":"88d8b847520928c4299c596c74460fc77e17a81e", "best_bid":"0.84", "best_ask":"0.85"}, {"asset_id":"68919878716222388542639225642064847629616106443780159680232863841946753372582", "price":"0.19", "size":"172.35", "side":"SELL", "hash":"7c421cac2353c10c41fd32be543512402727db6b", "best_bid":"0.15", "best_ask":"0.16"}], "timestamp":"1778784200671", "event_type":"price_change"}
{"market":"0x2a903c589141bce4a1e50fb98b73397af6820942542793ab10b1df477e912b6e", "price_changes":[{"asset_id":"20436996072316278452977393149218961565084965483366669504673105646378938504388", "price":"0.81", "size":"197.35", "side":"BUY", "hash":"5baffd8d8d6a777c38ced1abbf903ec480bfb2f3", "best_bid":"0.84", "best_ask":"0.85"}, {"asset_id":"68919878716222388542639225642064847629616106443780159680232863841946753372582", "price":"0.19", "size":"197.35", "side":"SELL", "hash":"083b930eda5543cbadac4552d69257a792115ab7", "best_bid":"0.15", "best_ask":"0.16"}], "timestamp":"1778784200672", "event_type":"price_change"}
{"market":"0x2a903c589141bce4a1e50fb98b73397af6820942542793ab10b1df477e912b6e", "price_changes":[{"asset_id":"20436996072316278452977393149218961565084965483366669504673105646378938504388", "price":"0.84", "size":"18.75", "side":"BUY", "hash":"72bc2a20b27d120bcef4e0d0fc8148c9c02a5d6a", "best_bid":"0.84", "best_ask":"0.85"}, {"asset_id":"68919878716222388542639225642064847629616106443780159680232863841946753372582", "price":"0.16", "size":"18.75", "side":"SELL", "hash":"1510e987f1a611654275e9177bd2068df21cbbc0", "best_bid":"0.15", "best_ask":"0.16"}], "timestamp":"1778784200675", "event_type":"price_change"}
{"market":"0x2a903c589141bce4a1e50fb98b73397af6820942542793ab10b1df477e912b6e", "asset_id":"68919878716222388542639225642064847629616106443780159680232863841946753372582", "bids":[{"price":"0.01", "size":"11338.83"}, {"price":"0.02", "size":"1397.82"}, {"price":"0.03", "size":"1090.78"}, {"price":"0.04", "size":"1237.82"}, {"price":"0.05", "size":"755.72"}, {"price":"0.06", "size":"297.2"}, {"price":"0.07", "size":"362.1"}, {"price":"0.08", "size":"348.74"}, {"price":"0.09", "size":"357.1"}, {"price":"0.1", "size":"570.99"}, {"price":"0.11", "size":"417.18"}, {"price":"0.12", "size":"233.41"}, {"price":"0.13", "size":"55"}, {"price":"0.14", "size":"170.88"}, {"price":"0.15", "size":"30"}], "asks":[{"price":"0.99", "size":"11995.61"}, {"price":"0.98", "size":"1219.45"}, {"price":"0.97", "size":"1111.98"}, {"price":"0.96", "size":"670.05"}, {"price":"0.95", "size":"549.45"}, {"price":"0.94", "size":"346.2"}, {"price":"0.93", "size":"902.05"}, {"price":"0.92", "size":"170.79"}, {"price":"0.91", "size":"234.6"}, {"price":"0.9", "size":"128"}, {"price":"0.89", "size":"142.6"}, {"price":"0.88", "size":"141.8"}, {"price":"0.87", "size":"144.81"}, {"price":"0.86", "size":"204.9"}, {"price":"0.85", "size":"113.5"}, {"price":"0.84", "size":"102.3"}, {"price":"0.83", "size":"101.3"}, {"price":"0.82", "size":"105.3"}, {"price":"0.81", "size":"199.5"}, {"price":"0.8", "size":"103.8"}, {"price":"0.79", "size":"98.1"}, {"price":"0.78", "size":"97.5"}, {"price":"0.77", "size":"96.89"}, {"price":"0.76", "size":"201.39"}, {"price":"0.75", "size":"116"}, {"price":"0.74", "size":"100.6"}, {"price":"0.73", "size":"95.2"}, {"price":"0.72", "size":"94.9"}, {"price":"0.71", "size":"199.6"}, {"price":"0.7", "size":"94.3"}, {"price":"0.69", "size":"108.28"}, {"price":"0.68", "size":"98.8"}, {"price":"0.67", "size":"118.6"}, {"price":"0.66", "size":"398.4"}, {"price":"0.65", "size":"507.3"}, {"price":"0.64", "size":"293"}, {"price":"0.63", "size":"892.9"}, {"price":"0.62", "size":"297.7"}, {"price":"0.61", "size":"397.6"}, {"price":"0.6", "size":"356.93"}, {"price":"0.59", "size":"297.4"}, {"price":"0.58", "size":"109.6"}, {"price":"0.57", "size":"131.48"}, {"price":"0.56", "size":"413.97"}, {"price":"0.55", "size":"334.2"}, {"price":"0.54", "size":"375.6"}, {"price":"0.53", "size":"292"}, {"price":"0.52", "size":"297.12"}, {"price":"0.51", "size":"402"}, {"price":"0.5", "size":"355.91"}, {"price":"0.49", "size":"312"}, {"price":"0.48", "size":"317"}, {"price":"0.47", "size":"337"}, {"price":"0.46", "size":"451.54"}, {"price":"0.45", "size":"346.64"}, {"price":"0.44", "size":"346.45"}, {"price":"0.43", "size":"434.89"}, {"price":"0.42", "size":"724.36"}, {"price":"0.41", "size":"412.4"}, {"price":"0.4", "size":"328.83"}, {"price":"0.39", "size":"297.6"}, {"price":"0.38", "size":"318.44"}, {"price":"0.37", "size":"576.9"}, {"price":"0.36", "size":"203"}, {"price":"0.35", "size":"340.14"}, {"price":"0.34", "size":"320.9"}, {"price":"0.33", "size":"323.6"}, {"price":"0.32", "size":"2065.88"}, {"price":"0.31", "size":"559"}, {"price":"0.3", "size":"134.3"}, {"price":"0.29", "size":"616.38"}, {"price":"0.28", "size":"139.9"}, {"price":"0.27", "size":"165.2"}, {"price":"0.26", "size":"230.6"}, {"price":"0.25", "size":"406"}, {"price":"0.24", "size":"206.39"}, {"price":"0.23", "size":"246.89"}, {"price":"0.22", "size":"249.5"}, {"price":"0.21", "size":"275.44"}, {"price":"0.2", "size":"110"}, {"price":"0.19", "size":"197.35"}, {"price":"0.18", "size":"364.82"}, {"price":"0.17", "size":"31"}, {"price":"0.16", "size":"18.75"}], "hash":"1510e987f1a611654275e9177bd2068df21cbbc0", "timestamp":"1778784200675", "event_type":"book"}
{"market":"0x2a903c589141bce4a1e50fb98b73397af6820942542793ab10b1df477e912b6e", "price_changes":[{"asset_id":"68919878716222388542639225642064847629616106443780159680232863841946753372582", "price":"0.15", "size":"18.74", "side":"BUY", "hash":"f6902b1a5b55dbfdb9ca541622bfaa4a052ef19e", "best_bid":"0.15", "best_ask":"0.16"}, {"asset_id":"20436996072316278452977393149218961565084965483366669504673105646378938504388", "price":"0.85", "size":"18.74", "side":"SELL", "hash":"cbb953e779155125d2ad523612f5fc011c38e5c4", "best_bid":"0.84", "best_ask":"0.85"}], "timestamp":"1778784200678", "event_type":"price_change"}
{"market":"0x2a903c589141bce4a1e50fb98b73397af6820942542793ab10b1df477e912b6e", "asset_id":"68919878716222388542639225642064847629616106443780159680232863841946753372582", "bids":[{"price":"0.01", "size":"11338.83"}, {"price":"0.02", "size":"1397.82"}, {"price":"0.03", "size":"1090.78"}, {"price":"0.04", "size":"1237.82"}, {"price":"0.05", "size":"755.72"}, {"price":"0.06", "size":"297.2"}, {"price":"0.07", "size":"362.1"}, {"price":"0.08", "size":"348.74"}, {"price":"0.09", "size":"357.1"}, {"price":"0.1", "size":"570.99"}, {"price":"0.11", "size":"417.18"}, {"price":"0.12", "size":"233.41"}, {"price":"0.13", "size":"55"}, {"price":"0.14", "size":"170.88"}, {"price":"0.15", "size":"18.74"}], "asks":[{"price":"0.99", "size":"11995.61"}, {"price":"0.98", "size":"1219.45"}, {"price":"0.97", "size":"1111.98"}, {"price":"0.96", "size":"670.05"}, {"price":"0.95", "size":"549.45"}, {"price":"0.94", "size":"346.2"}, {"price":"0.93", "size":"902.05"}, {"price":"0.92", "size":"170.79"}, {"price":"0.91", "size":"234.6"}, {"price":"0.9", "size":"128"}, {"price":"0.89", "size":"142.6"}, {"price":"0.88", "size":"141.8"}, {"price":"0.87", "size":"144.81"}, {"price":"0.86", "size":"204.9"}, {"price":"0.85", "size":"113.5"}, {"price":"0.84", "size":"102.3"}, {"price":"0.83", "size":"101.3"}, {"price":"0.82", "size":"105.3"}, {"price":"0.81", "size":"199.5"}, {"price":"0.8", "size":"103.8"}, {"price":"0.79", "size":"98.1"}, {"price":"0.78", "size":"97.5"}, {"price":"0.77", "size":"96.89"}, {"price":"0.76", "size":"201.39"}, {"price":"0.75", "size":"116"}, {"price":"0.74", "size":"100.6"}, {"price":"0.73", "size":"95.2"}, {"price":"0.72", "size":"94.9"}, {"price":"0.71", "size":"199.6"}, {"price":"0.7", "size":"94.3"}, {"price":"0.69", "size":"108.28"}, {"price":"0.68", "size":"98.8"}, {"price":"0.67", "size":"118.6"}, {"price":"0.66", "size":"398.4"}, {"price":"0.65", "size":"507.3"}, {"price":"0.64", "size":"293"}, {"price":"0.63", "size":"892.9"}, {"price":"0.62", "size":"297.7"}, {"price":"0.61", "size":"397.6"}, {"price":"0.6", "size":"356.93"}, {"price":"0.59", "size":"297.4"}, {"price":"0.58", "size":"109.6"}, {"price":"0.57", "size":"131.48"}, {"price":"0.56", "size":"413.97"}, {"price":"0.55", "size":"334.2"}, {"price":"0.54", "size":"375.6"}, {"price":"0.53", "size":"292"}, {"price":"0.52", "size":"297.12"}, {"price":"0.51", "size":"402"}, {"price":"0.5", "size":"355.91"}, {"price":"0.49", "size":"312"}, {"price":"0.48", "size":"317"}, {"price":"0.47", "size":"337"}, {"price":"0.46", "size":"451.54"}, {"price":"0.45", "size":"346.64"}, {"price":"0.44", "size":"346.45"}, {"price":"0.43", "size":"434.89"}, {"price":"0.42", "size":"724.36"}, {"price":"0.41", "size":"412.4"}, {"price":"0.4", "size":"328.83"}, {"price":"0.39", "size":"297.6"}, {"price":"0.38", "size":"318.44"}, {"price":"0.37", "size":"576.9"}, {"price":"0.36", "size":"203"}, {"price":"0.35", "size":"340.14"}, {"price":"0.34", "size":"320.9"}, {"price":"0.33", "size":"323.6"}, {"price":"0.32", "size":"2065.88"}, {"price":"0.31", "size":"559"}, {"price":"0.3", "size":"134.3"}, {"price":"0.29", "size":"616.38"}, {"price":"0.28", "size":"139.9"}, {"price":"0.27", "size":"165.2"}, {"price":"0.26", "size":"230.6"}, {"price":"0.25", "size":"406"}, {"price":"0.24", "size":"206.39"}, {"price":"0.23", "size":"246.89"}, {"price":"0.22", "size":"249.5"}, {"price":"0.21", "size":"275.44"}, {"price":"0.2", "size":"110"}, {"price":"0.19", "size":"197.35"}, {"price":"0.18", "size":"364.82"}, {"price":"0.17", "size":"31"}, {"price":"0.16", "size":"18.75"}], "hash":"f6902b1a5b55dbfdb9ca541622bfaa4a052ef19e", "timestamp":"1778784200678", "event_type":"book"}
{"market":"0x2a903c589141bce4a1e50fb98b73397af6820942542793ab10b1df477e912b6e", "price_changes":[{"asset_id":"68919878716222388542639225642064847629616106443780159680232863841946753372582", "price":"0.11", "size":"467.18", "side":"BUY", "hash":"27e7d0591a5aeec77d3dc54cc1da756dddcdf663", "best_bid":"0.15", "best_ask":"0.16"}, {"asset_id":"20436996072316278452977393149218961565084965483366669504673105646378938504388", "price":"0.89", "size":"467.18", "side":"SELL", "hash":"ee09d29d44aac58a2519399f3ce28ce8c0cfb6dd", "best_bid":"0.84", "best_ask":"0.85"}], "timestamp":"1778784200680", "event_type":"price_change"}
{"market":"0x2a903c589141bce4a1e50fb98b73397af6820942542793ab10b1df477e912b6e", "price_changes":[{"asset_id":"68919878716222388542639225642064847629616106443780159680232863841946753372582", "price":"0.5", "size":"345.91", "side":"SELL", "hash":"19a29342353dba48c69ce3eb8a967e53b9a08d4e", "best_bid":"0.15", "best_ask":"0.16"}, {"asset_id":"20436996072316278452977393149218961565084965483366669504673105646378938504388", "price":"0.5", "size":"345.91", "side":"BUY", "hash":"341459cee8e0717e2214ca468cefc007a5bd0abb", "best_bid":"0.84", "best_ask":"0.85"}], "timestamp":"1778784200681", "event_type":"price_change"}
{"market":"0x2a903c589141bce4a1e50fb98b73397af6820942542793ab10b1df477e912b6e", "price_changes":[{"asset_id":"68919878716222388542639225642064847629616106443780159680232863841946753372582", "price":"0.15", "size":"12.85", "side":"BUY", "hash":"84d99464727b77d1cbbd7121e5973746f955a4f9", "best_bid":"0.15", "best_ask":"0.16"}, {"asset_id":"20436996072316278452977393149218961565084965483366669504673105646378938504388", "price":"0.85", "size":"12.85", "side":"SELL", "hash":"71f08cd28decbd171dbb87202fbf33eb80c4158a", "best_bid":"0.84", "best_ask":"0.85"}], "timestamp":"1778784200684", "event_type":"price_change"}
