[{"market":"0x2a903c589141bce4a1e50fb98b73397af6820942542793ab10b1df477e912b6e","asset_id":"68919878716222388542639225642064847629616106443780159680232863841946753372582","timestamp":"1778784196672","hash":"89fd40d68c783b50ef054cec576d17e05185f4f5","bids":[{"price":"0.01","size":"11330.74"},{"price":"0.02","size":"1462.32"},{"price":"0.03","size":"1105.78"},{"price":"0.04","size":"607.82"},{"price":"0.05","size":"755.72"},{"price":"0.06","size":"237.72"},{"price":"0.07","size":"357.1"},{"price":"0.08","size":"737.74"},{"price":"0.09","size":"318.11"},{"price":"0.1","size":"227.76"},{"price":"0.11","size":"128.47"}],"asks":[{"price":"0.99","size":"12086.57"},{"price":"0.98","size":"1219.45"},{"price":"0.97","size":"1111.98"},{"price":"0.96","size":"670.05"},{"price":"0.95","size":"549.45"},{"price":"0.94","size":"346.2"},{"price":"0.93","size":"902.05"},{"price":"0.92","size":"170.79"},{"price":"0.91","size":"234.6"},{"price":"0.9","size":"128"},{"price":"0.89","size":"142.6"},{"price":"0.88","size":"141.8"},{"price":"0.87","size":"144.81"},{"price":"0.86","size":"204.9"},{"price":"0.85","size":"113.5"},{"price":"0.84","size":"102.3"},{"price":"0.83","size":"101.3"},{"price":"0.82","size":"105.3"},{"price":"0.81","size":"199.5"},{"price":"0.8","size":"103.8"},{"price":"0.79","size":"98.1"},{"price":"0.78","size":"97.5"},{"price":"0.77","size":"96.89"},{"price":"0.76","size":"201.39"},{"price":"0.75","size":"116"},{"price":"0.74","size":"100.6"},{"price":"0.73","size":"95.2"},{"price":"0.72","size":"94.9"},{"price":"0.71","size":"199.6"},{"price":"0.7","size":"94.3"},{"price":"0.69","size":"108.28"},{"price":"0.68","size":"98.8"},{"price":"0.67","size":"718.6"},{"price":"0.66","size":"898.4"},{"price":"0.65","size":"407.3"},{"price":"0.64","size":"93"},{"price":"0.63","size":"292.9"},{"price":"0.62","size":"297.7"},{"price":"0.61","size":"397.6"},{"price":"0.6","size":"356.93"},{"price":"0.59","size":"297.4"},{"price":"0.58","size":"109.6"},{"price":"0.57","size":"131.48"},{"price":"0.56","size":"413.97"},{"price":"0.55","size":"934.2"},{"price":"0.54","size":"375.6"},{"price":"0.53","size":"292"},{"price":"0.52","size":"297.12"},{"price":"0.51","size":"402"},{"price":"0.5","size":"340.91"},{"price":"0.49","size":"362"},{"price":"0.48","size":"317"},{"price":"0.47","size":"337"},{"price":"0.46","size":"607.1"},{"price":"0.45","size":"346.64"},{"price":"0.44","size":"384.31"},{"price":"0.43","size":"867.89"},{"price":"0.42","size":"324.36"},{"price":"0.41","size":"412.4"},{"price":"0.4","size":"328.83"},{"price":"0.39","size":"297.6"},{"price":"0.38","size":"636.5"},{"price":"0.37","size":"297.9"},{"price":"0.36","size":"208"},{"price":"0.35","size":"330.14"},{"price":"0.34","size":"330.9"},{"price":"0.33","size":"313.6"},{"price":"0.32","size":"2025.88"},{"price":"0.31","size":"409"},{"price":"0.3","size":"134.3"},{"price":"0.29","size":"316.38"},{"price":"0.28","size":"154.9"},{"price":"0.27","size":"180.2"},{"price":"0.26","size":"230.6"},{"price":"0.25","size":"451"},{"price":"0.24","size":"146.39"},{"price":"0.23","size":"121.89"},{"price":"0.22","size":"117.5"},{"price":"0.21","size":"300.44"},{"price":"0.2","size":"108.8"},{"price":"0.19","size":"242.35"},{"price":"0.18","size":"486.2"},{"price":"0.17","size":"170"},{"price":"0.16","size":"283.7"},{"price":"0.15","size":"241.53"},{"price":"0.14","size":"231.53"},{"price":"0.13","size":"66.77"},{"price":"0.12","size":"179"}],"tick_size":"0.01","event_type":"book","last_trade_price":"0.110"}]

{"market":"0x2a903c589141bce4a1e50fb98b73397af6820942542793ab10b1df477e912b6e", "price_changes":[{"asset_id":"20436996072316278452977393149218961565084965483366669504673105646378938504388", "price":"0.86", "size":"231.53", "side":"BUY", "hash":"73e72177c538f3dd5563d7cf1b16b4b4b9954c21", "best_bid":"0.88", "best_ask":"0.89"}, {"asset_id":"68919878716222388542639225642064847629616106443780159680232863841946753372582", "price":"0.14", "size":"231.53", "side":"SELL", "hash":"89fd40d68c783b50ef054cec576d17e05185f4f5", "best_bid":"0.11", "best_ask":"0.12"}], "timestamp":"1778784196672", "event_type":"price_change"}
{"market":"0x2a903c589141bce4a1e50fb98b73397af6820942542793ab10b1df477e912b6e", "price_changes":[{"asset_id":"20436996072316278452977393149218961565084965483366669504673105646378938504388", "price":"0.81", "size":"212.35", "side":"BUY", "hash":"8af03e9d640fd0c71b8380ba34b22e84a1640d66", "best_bid":"0.88", "best_ask":"0.89"}, {"asset_id":"68919878716222388542639225642064847629616106443780159680232863841946753372582", "price":"0.19", "size":"212.35", "side":"SELL", "hash":"cb9ecd243f4e3d8f9bd44e4d9d5a378fe956548c", "best_bid":"0.11", "best_ask":"0.12"}], "timestamp":"1778784196706", "event_type":"price_change"}
{"market":"0x2a903c589141bce4a1e50fb98b73397af6820942542793ab10b1df477e912b6e", "price_changes":[{"asset_id":"68919878716222388542639225642064847629616106443780159680232863841946753372582", "price":"0.08", "size":"715.74", "side":"BUY", "hash":"bb57ae8d0e45eac1c146104b6f4b279861cf0d32", "best_bid":"0.11", "best_ask":"0.12"}, {"asset_id":"20436996072316278452977393149218961565084965483366669504673105646378938504388", "price":"0.92", "size":"715.74", "side":"SELL", "hash":"4ca99f11815a054933d5017437fc3badb6ab4cf4", "best_bid":"0.88", "best_ask":"0.89"}], "timestamp":"1778784196740", "event_type":"price_change"}
{"market":"0x2a903c589141bce4a1e50fb98b73397af6820942542793ab10b1df477e912b6e", "price_changes":[{"asset_id":"20436996072316278452977393149218961565084965483366669504673105646378938504388", "price":"0.87", "size":"46.77", "side":"BUY", "hash":"3cd9cda05b433aa48e522565be503759f91ee40a", "best_bid":"0.88", "best_ask":"0.89"}, {"asset_id":"68919878716222388542639225642064847629616106443780159680232863841946753372582", "price":"0.13", "size":"46.77", "side":"SELL", "hash":"901f18e1da185e56f70070c9e839d71823227daf", "best_bid":"0.11", "best_ask":"0.12"}], "timestamp":"1778784196742", "event_type":"price_change"}
{"market":"0x2a903c589141bce4a1e50fb98b73397af6820942542793ab10b1df477e912b6e", "price_changes":[{"asset_id":"20436996072316278452977393149218961565084965483366669504673105646378938504388", "price":"0.76", "size":"121.39", "side":"BUY", "hash":"4f152367971f29f1b902e4e1223b703fc5a37c28", "best_bid":"0.88", "best_ask":"0.89"}, {"asset_id":"68919878716222388542639225642064847629616106443780159680232863841946753372582", "price":"0.24", "size":"121.39", "side":"SELL", "hash":"93f19b8e1838aa58c2f23fa819dd76113936b255", "best_bid":"0.11", "best_ask":"0.12"}], "timestamp":"1778784196770", "event_type":"price_change"}
{"market":"0x2a903c589141bce4a1e50fb98b73397af6820942542793ab10b1df477e912b6e", "price_changes":[{"asset_id":"68919878716222388542639225642064847629616106443780159680232863841946753372582", "price":"0.08", "size":"415.74", "side":"BUY", "hash":"daee4f608b966ddf708cdf7f08d6e0c7dbd3e335", "best_bid":"0.11", "best_ask":"0.12"}, {"asset_id":"20436996072316278452977393149218961565084965483366669504673105646378938504388", "price":"0.92", "size":"415.74", "side":"SELL", "hash":"e0739698d7f3f7d765641ed4c5ff4378285cfe8b", "best_bid":"0.88", "best_ask":"0.89"}], "timestamp":"1778784196812", "event_type":"price_change"}
{"market":"0x2a903c589141bce4a1e50fb98b73397af6820942542793ab10b1df477e912b6e", "price_changes":[{"asset_id":"20436996072316278452977393149218961565084965483366669504673105646378938504388", "price":"0.75", "size":"456", "side":"BUY", "hash":"6d28c5dcb7570c0a4235f935c4daea9e7b6acbd9", "best_bid":"0.88", "best_ask":"0.89"}, {"asset_id":"68919878716222388542639225642064847629616106443780159680232863841946753372582", "price":"0.25", "size":"456", "side":"SELL", "hash":"35e8c09eecc15c8bda81a432eb7e29a2c358d700", "best_bid":"0.11", "best_ask":"0.12"}], "timestamp":"1778784196836", "event_type":"price_change"}
{"market":"0x2a903c589141bce4a1e50fb98b73397af6820942542793ab10b1df477e912b6e", "price_changes":[{"asset_id":"20436996072316278452977393149218961565084965483366669504673105646378938504388", "price":"0.85", "size":"191.53", "side":"BUY", "hash":"68b841dff6544f2ec6de69957b15a12a00cb7771", "best_bid":"0.88", "best_ask":"0.89"}, {"asset_id":"68919878716222388542639225642064847629616106443780159680232863841946753372582", "price":"0.15", "size":"191.53", "side":"SELL", "hash":"4d90bd415eb225f80fac6d5d93e2f589d3c8631c", "best_bid":"0.11", "best_ask":"0.12"}], "timestamp":"1778784196857", "event_type":"price_change"}
{"market":"0x2a903c589141bce4a1e50fb98b73397af6820942542793ab10b1df477e912b6e", "price_changes":[{"asset_id":"20436996072316278452977393149218961565084965483366669504673105646378938504388", "price":"0.86", "size":"191.53", "side":"BUY", "hash":"022ceca435d08125ad202468f76eb47ca1418453", "best_bid":"0.88", "best_ask":"0.89"}, {"asset_id":"68919878716222388542639225642064847629616106443780159680232863841946753372582", "price":"0.14", "size":"191.53", "side":"SELL", "hash":"8eee04de542ce3eeec2c9562e4db9600c771026e", "best_bid":"0.11", "best_ask":"0.12"}], "timestamp":"1778784196885", "event_type":"price_change"}
{"market":"0x2a903c589141bce4a1e50fb98b73397af6820942542793ab10b1df477e912b6e", "price_changes":[{"asset_id":"20436996072316278452977393149218961565084965483366669504673105646378938504388", "price":"0.79", "size":"200.44", "side":"BUY", "hash":"43c4c2d4e4ea2e8d16a089b429931a0e3696f29e", "best_bid":"0.88", "best_ask":"0.89"}, {"asset_id":"68919878716222388542639225642064847629616106443780159680232863841946753372582", "price":"0.21", "size":"200.44", "side":"SELL", "hash":"242ed3a9c6ca6a82b402a36387ec6245c9bb114f", "best_bid":"0.11", "best_ask":"0.12"}], "timestamp":"1778784196913", "event_type":"price_change"}
{"market":"0x2a903c589141bce4a1e50fb98b73397af6820942542793ab10b1df477e912b6e", "price_changes":[{"asset_id":"20436996072316278452977393149218961565084965483366669504673105646378938504388", "price":"0.85", "size":"151.53", "side":"BUY", "hash":"5a99bc0cffc09d87ef6a15d965dcc430843c5544", "best_bid":"0.88", "best_ask":"0.89"}, {"asset_id":"68919878716222388542639225642064847629616106443780159680232863841946753372582", "price":"0.15", "size":"151.53", "side":"SELL", "hash":"c5f74913e41e70d1a97205a7f6ed874c616d47d7", "best_bid":"0.11", "best_ask":"0.12"}], "timestamp":"1778784196923", "event_type":"price_change"}
{"market":"0x2a903c589141bce4a1e50fb98b73397af6820942542793ab10b1df477e912b6e", "price_changes":[{"asset_id":"68919878716222388542639225642064847629616106443780159680232863841946753372582", "price":"0.1", "size":"127.76", "side":"BUY", "hash":"5e2209b4f781a909e73271d60e731c48fc4582c8", "best_bid":"0.11", "best_ask":"0.12"}, {"asset_id":"20436996072316278452977393149218961565084965483366669504673105646378938504388", "price":"0.9", "size":"127.76", "side":"SELL", "hash":"e3c16d1a6ef50d0920b0ca549d586c2d6da4faed", "best_bid":"0.88", "best_ask":"0.89"}], "timestamp":"1778784196927", "event_type":"price_change"}
{"market":"0x2a903c589141bce4a1e50fb98b73397af6820942542793ab10b1df477e912b6e", "price_changes":[{"asset_id":"68919878716222388542639225642064847629616106443780159680232863841946753372582", "price":"0.08", "size":"315.74", "side":"BUY", "hash":"f92b881c9f45680b3cfc55f4a0a3541122631b34", "best_bid":"0.11", "best_ask":"0.12"}, {"asset_id":"20436996072316278452977393149218961565084965483366669504673105646378938504388", "price":"0.92", "size":"315.74", "side":"SELL", "hash":"c2e176198251bef94e8ac2ebf943403005429770", "best_bid":"0.88", "best_ask":"0.89"}], "timestamp":"1778784196929", "event_type":"price_change"}
{"market":"0x2a903c589141bce4a1e50fb98b73397af6820942542793ab10b1df477e912b6e", "price_changes":[{"asset_id":"68919878716222388542639225642064847629616106443780159680232863841946753372582", "price":"0.11", "size":"217.35", "side":"BUY", "hash":"d7aba16f892f065b88a7bd32f80acae3789f6577", "best_bid":"0.11", "best_ask":"0.12"}, {"asset_id":"20436996072316278452977393149218961565084965483366669504673105646378938504388", "price":"0.89", "size":"217.35", "side":"SELL", "hash":"56b942c471c9616595214c3cf8145c5c2fa98de7", "best_bid":"0.88", "best_ask":"0.89"}], "timestamp":"1778784196932", "event_type":"price_change"}
{"market":"0x2a903c589141bce4a1e50fb98b73397af6820942542793ab10b1df477e912b6e", "price_changes":[{"asset_id":"20436996072316278452977393149218961565084965483366669504673105646378938504388", "price":"0.86", "size":"166.53", "side":"BUY", "hash":"3a38655236684960b512772004b330e1fa444758", "best_bid":"0.88", "best_ask":"0.89"}, {"asset_id":"68919878716222388542639225642064847629616106443780159680232863841946753372582", "price":"0.14", "size":"166.53", "side":"SELL", "hash":"acdef88bbfb2ccc114959e775f7c425c4265ff85", "best_bid":"0.11", "best_ask":"0.12"}], "timestamp":"1778784196974", "event_type":"price_change"}
{"market":"0x2a903c589141bce4a1e50fb98b73397af6820942542793ab10b1df477e912b6e", "price_changes":[{"asset_id":"20436996072316278452977393149218961565084965483366669504673105646378938504388", "price":"0.36", "size":"293", "side":"BUY", "hash":"6adbc99d24c8b3972b2d219c10ea212af5dbd528", "best_bid":"0.88", "best_ask":"0.89"}, {"asset_id":"68919878716222388542639225642064847629616106443780159680232863841946753372582", "price":"0.64", "size":"293", "side":"SELL", "hash":"7e6a0a50dd8dce54bacc617b96b12ba144cf21b1", "best_bid":"0.11", "best_ask":"0.12"}], "timestamp":"1778784197022", "event_type":"price_change"}
{"market":"0x2a903c589141bce4a1e50fb98b73397af6820942542793ab10b1df477e912b6e", "price_changes":[{"asset_id":"20436996072316278452977393149218961565084965483366669504673105646378938504388", "price":"0.56", "size":"341.45", "side":"BUY", "hash":"8872d69088e0dac21c721f8b894f31bcd2a4300c", "best_bid":"0.88", "best_ask":"0.89"}, {"asset_id":"68919878716222388542639225642064847629616106443780159680232863841946753372582", "price":"0.44", "size":"341.45", "side":"SELL", "hash":"ac23a3d6bbc526692e9f47a233429645ce737a55", "best_bid":"0.11", "best_ask":"0.12"}], "timestamp":"1778784197034", "event_type":"price_change"}
{"market":"0x2a903c589141bce4a1e50fb98b73397af6820942542793ab10b1df477e912b6e", "price_changes":[{"asset_id":"20436996072316278452977393149218961565084965483366669504673105646378938504388", "price":"0.86", "size":"157.53", "side":"BUY", "hash":"e7fbeba359e157efcb5486c7750f391dd13e5fcc", "best_bid":"0.88", "best_ask":"0.89"}, {"asset_id":"68919878716222388542639225642064847629616106443780159680232863841946753372582", "price":"0.14", "size":"157.53", "side":"SELL", "hash":"81841e8a07c7ea1d4cdb8c096dcb1133d1412713", "best_bid":"0.11", "best_ask":"0.12"}], "timestamp":"1778784197044", "event_type":"price_change"}
{"market":"0x2a903c589141bce4a1e50fb98b73397af6820942542793ab10b1df477e912b6e", "price_changes":[{"asset_id":"20436996072316278452977393149218961565084965483366669504673105646378938504388", "price":"0.87", "size":"38.77", "side":"BUY", "hash":"e7fbeba359e157efcb5486c7750f391dd13e5fcc", "best_bid":"0.88", "best_ask":"0.89"}, {"asset_id":"68919878716222388542639225642064847629616106443780159680232863841946753372582", "price":"0.13", "size":"38.77", "side":"SELL", "hash":"81841e8a07c7ea1d4cdb8c096dcb1133d1412713", "best_bid":"0.11", "best_ask":"0.12"}], "timestamp":"1778784197044", "event_type":"price_change"}
{"market":"0x2a903c589141bce4a1e50fb98b73397af6820942542793ab10b1df477e912b6e", "price_changes":[{"asset_id":"20436996072316278452977393149218961565084965483366669504673105646378938504388", "price":"0.88", "size":"171", "side":"BUY", "hash":"e7fbeba359e157efcb5486c7750f391dd13e5fcc", "best_bid":"0.88", "best_ask":"0.89"}, {"asset_id":"68919878716222388542639225642064847629616106443780159680232863841946753372582", "price":"0.12", "size":"171", "side":"SELL", "hash":"81841e8a07c7ea1d4cdb8c096dcb1133d1412713", "best_bid":"0.11", "best_ask":"0.12"}], "timestamp":"1778784197044", "event_type":"price_change"}
{"market":"0x2a903c589141bce4a1e50fb98b73397af6820942542793ab10b1df477e912b6e", "price_changes":[{"asset_id":"20436996072316278452977393149218961565084965483366669504673105646378938504388", "price":"0.84", "size":"183.7", "side":"BUY", "hash":"e5805c75d255aae27e7715e9f485526b0d08a91b", "best_bid":"0.88", "best_ask":"0.89"}, {"asset_id":"68919878716222388542639225642064847629616106443780159680232863841946753372582", "price":"0.16", "size":"183.7", "side":"SELL", "hash":"b9053440aa64eda9e20407ad0fac0a3c5f046fb9", "best_bid":"0.11", "best_ask":"0.12"}], "timestamp":"1778784197047", "event_type":"price_change"}
{"market":"0x2a903c589141bce4a1e50fb98b73397af6820942542793ab10b1df477e912b6e", "price_changes":[{"asset_id":"20436996072316278452977393149218961565084965483366669504673105646378938504388", "price":"0.86", "size":"148.53", "side":"BUY", "hash":"a78cd94efd28c4a06ee0b21caf55f11769275ab2", "best_bid":"0.88", "best_ask":"0.89"}, {"asset_id":"68919878716222388542639225642064847629616106443780159680232863841946753372582", "price":"0.14", "size":"148.53", "side":"SELL", "hash":"23b1d573c9699a7b05d2e69a98072827b1e10b1e", "best_bid":"0.11", "best_ask":"0.12"}], "timestamp":"1778784197050", "event_type":"price_change"}
{"market":"0x2a903c589141bce4a1e50fb98b73397af6820942542793ab10b1df477e912b6e", "price_changes":[{"asset_id":"20436996072316278452977393149218961565084965483366669504673105646378938504388", "price":"0.87", "size":"30.77", "side":"BUY", "hash":"a78cd94efd28c4a06ee0b21caf55f11769275ab2", "best_bid":"0.88", "best_ask":"0.89"}, {"asset_id":"68919878716222388542639225642064847629616106443780159680232863841946753372582", "price":"0.13", "size":"30.77", "side":"SELL", "hash":"23b1d573c9699a7b05d2e69a98072827b1e10b1e", "best_bid":"0.11", "best_ask":"0.12"}], "timestamp":"1778784197050", "event_type":"price_change"}
{"market":"0x2a903c589141bce4a1e50fb98b73397af6820942542793ab10b1df477e912b6e", "price_changes":[{"asset_id":"20436996072316278452977393149218961565084965483366669504673105646378938504388", "price":"0.88", "size":"163", "side":"BUY", "hash":"a78cd94efd28c4a06ee0b21caf55f11769275ab2", "best_bid":"0.88", "best_ask":"0.89"}, {"asset_id":"68919878716222388542639225642064847629616106443780159680232863841946753372582", "price":"0.12", "size":"163", "side":"SELL", "hash":"23b1d573c9699a7b05d2e69a98072827b1e10b1e", "best_bid":"0.11", "best_ask":"0.12"}], "timestamp":"1778784197050", "event_type":"price_change"}
{"market":"0x2a903c589141bce4a1e50fb98b73397af6820942542793ab10b1df477e912b6e", "price_changes":[{"asset_id":"20436996072316278452977393149218961565084965483366669504673105646378938504388", "price":"0.85", "size":"111.53", "side":"BUY", "hash":"633e497d125cd891541e7414796645fce66a25fe", "best_bid":"0.88", "best_ask":"0.89"}, {"asset_id":"68919878716222388542639225642064847629616106443780159680232863841946753372582", "price":"0.15", "size":"111.53", "side":"SELL", "hash":"837311018f6da7896b6915ae75ebc735f534891d", "best_bid":"0.11", "best_ask":"0.12"}], "timestamp":"1778784197052", "event_type":"price_change"}
{"market":"0x2a903c589141bce4a1e50fb98b73397af6820942542793ab10b1df477e912b6e", "price_changes":[{"asset_id":"20436996072316278452977393149218961565084965483366669504673105646378938504388", "price":"0.86", "size":"118.53", "side":"BUY", "hash":"5b83b77e62ccf1fee8e831b4dd09f3836e671320", "best_bid":"0.88", "best_ask":"0.89"}, {"asset_id":"68919878716222388542639225642064847629616106443780159680232863841946753372582", "price":"0.14", "size":"118.53", "side":"SELL", "hash":"43bd723d3feaa949dbda53d95c852a7584817d2d", "best_bid":"0.11", "best_ask":"0.12"}], "timestamp":"1778784197063", "event_type":"price_change"}
{"market":"0x2a903c589141bce4a1e50fb98b73397af6820942542793ab10b1df477e912b6e", "price_changes":[{"asset_id":"20436996072316278452977393149218961565084965483366669504673105646378938504388", "price":"0.9", "size":"280.33", "side":"SELL", "hash":"10e156fdd43135c0f2475ebea4e48e5a876e516a", "best_bid":"0.88", "best_ask":"0.89"}, {"asset_id":"68919878716222388542639225642064847629616106443780159680232863841946753372582", "price":"0.1", "size":"280.33", "side":"BUY", "hash":"e12e6f11adffb53aae94903fda931454abf097ef", "best_bid":"0.11", "best_ask":"0.12"}], "timestamp":"1778784197074", "event_type":"price_change"}
{"market":"0x2a903c589141bce4a1e50fb98b73397af6820942542793ab10b1df477e912b6e", "price_changes":[{"asset_id":"20436996072316278452977393149218961565084965483366669504673105646378938504388", "price":"0.84", "size":"143.7", "side":"BUY", "hash":"c7e4401faac313ff7492e4ec594bd7dee9011b7e", "best_bid":"0.88", "best_ask":"0.89"}, {"asset_id":"68919878716222388542639225642064847629616106443780159680232863841946753372582", "price":"0.16", "size":"143.7", "side":"SELL", "hash":"1714066b9fe111d0a534f8ba8ae3b44dba611d09", "best_bid":"0.11", "best_ask":"0.12"}], "timestamp":"1778784197082", "event_type":"price_change"}
{"market":"0x2a903c589141bce4a1e50fb98b73397af6820942542793ab10b1df477e912b6e", "price_changes":[{"asset_id":"20436996072316278452977393149218961565084965483366669504673105646378938504388", "price":"0.81", "size":"172.35", "side":"BUY", "hash":"7d9965214810d55086a21f850f9cc7d013bacc4b", "best_bid":"0.88", "best_ask":"0.89"}, {"asset_id":"68919878716222388542639225642064847629616106443780159680232863841946753372582", "price":"0.19", "size":"172.35", "side":"SELL", "hash":"3003d0624b35bfd68205b0f9dcd46210fa8c20e9", "best_bid":"0.11", "best_ask":"0.12"}], "timestamp":"1778784197092", "event_type":"price_change"}
{"market":"0x2a903c589141bce4a1e50fb98b73397af6820942542793ab10b1df477e912b6e", "price_changes":[{"asset_id":"68919878716222388542639225642064847629616106443780159680232863841946753372582", "price":"0.09", "size":"286.11", "side":"BUY", "hash":"2e3788b47ef703b41154ef68b0126df6b969a715", "best_bid":"0.11", "best_ask":"0.12"}, {"asset_id":"20436996072316278452977393149218961565084965483366669504673105646378938504388", "price":"0.91", "size":"286.11", "side":"SELL", "hash":"39381872ecb76846cea9a0912b90cdca9360942e", "best_bid":"0.88", "best_ask":"0.89"}], "timestamp":"1778784197114", "event_type":"price_change"}
{"market":"0x2a903c589141bce4a1e50fb98b73397af6820942542793ab10b1df477e912b6e", "price_changes":[{"asset_id":"20436996072316278452977393149218961565084965483366669504673105646378938504388", "price":"0.81", "size":"72.35", "side":"BUY", "hash":"0ac360c6cd8bbb3d8f36a1256c233d23044f0011", "best_bid":"0.88", "best_ask":"0.89"}, {"asset_id":"68919878716222388542639225642064847629616106443780159680232863841946753372582", "price":"0.19", "size":"72.35", "side":"SELL", "hash":"87c63e126f39f12aefedde8ce805565a533a6ba8", "best_bid":"0.11", "best_ask":"0.12"}], "timestamp":"1778784197131", "event_type":"price_change"}
{"market":"0x2a903c589141bce4a1e50fb98b73397af6820942542793ab10b1df477e912b6e", "price_changes":[{"asset_id":"68919878716222388542639225642064847629616106443780159680232863841946753372582", "price":"0.1", "size":"320.33", "side":"BUY", "hash":"9df493464316e2d2d4674dc5bfdefef2758e7dad", "best_bid":"0.11", "best_ask":"0.12"}, {"asset_id":"20436996072316278452977393149218961565084965483366669504673105646378938504388", "price":"0.9", "size":"320.33", "side":"SELL", "hash":"75c33f0bea19af0f003bf39fbcc3c813a9ea5a36", "best_bid":"0.88", "best_ask":"0.89"}], "timestamp":"1778784197154", "event_type":"price_change"}
{"market":"0x2a903c589141bce4a1e50fb98b73397af6820942542793ab10b1df477e912b6e", "price_changes":[{"asset_id":"68919878716222388542639225642064847629616106443780159680232863841946753372582", "price":"0.43", "size":"434.89", "side":"SELL", "hash":"def751c64dbdee86189f18b6fc5d4722ea2a311b", "best_bid":"0.11", "best_ask":"0.12"}, {"asset_id":"20436996072316278452977393149218961565084965483366669504673105646378938504388", "price":"0.57", "size":"434.89", "side":"BUY", "hash":"a3a181ea04a437373e80f6c303b0b5428b7910be", "best_bid":"0.88", "best_ask":"0.89"}], "timestamp":"1778784197156", "event_type":"price_change"}
{"market":"0x2a903c589141bce4a1e50fb98b73397af6820942542793ab10b1df477e912b6e", "price_changes":[{"asset_id":"20436996072316278452977393149218961565084965483366669504673105646378938504388", "price":"0.82", "size":"446.2", "side":"BUY", "hash":"a801d2f77990e724cdcb10b1e59e8f2ec2f160e0", "best_bid":"0.88", "best_ask":"0.89"}, {"asset_id":"68919878716222388542639225642064847629616106443780159680232863841946753372582", "price":"0.18", "size":"446.2", "side":"SELL", "hash":"131b67c7bb6f7720abce049f1a151d3b803f0049", "best_bid":"0.11", "best_ask":"0.12"}], "timestamp":"1778784197178", "event_type":"price_change"}
{"market":"0x2a903c589141bce4a1e50fb98b73397af6820942542793ab10b1df477e912b6e", "price_changes":[{"asset_id":"20436996072316278452977393149218961565084965483366669504673105646378938504388", "price":"0.88", "size":"143", "side":"BUY", "hash":"fa4999e6f5388ec967b406fb332b0441e04e1b98", "best_bid":"0.88", "best_ask":"0.89"}, {"asset_id":"68919878716222388542639225642064847629616106443780159680232863841946753372582", "price":"0.12", "size":"143", "side":"SELL", "hash":"ac6500b02c9463cfc4a32c10dc5a27a71c7092c6", "best_bid":"0.11", "best_ask":"0.12"}], "timestamp":"1778784197188", "event_type":"price_change"}
{"market":"0x2a903c589141bce4a1e50fb98b73397af6820942542793ab10b1df477e912b6e", "price_changes":[{"asset_id":"20436996072316278452977393149218961565084965483366669504673105646378938504388", "price":"0.83", "size":"130", "side":"BUY", "hash":"77d6644f34c6d9a540db8119ad0122a94f8d45b2", "best_bid":"0.88", "best_ask":"0.89"}, {"asset_id":"68919878716222388542639225642064847629616106443780159680232863841946753372582", "price":"0.17", "size":"130", "side":"SELL", "hash":"8925619e7287a313704b3f17f76631b3b951f6f6", "best_bid":"0.11", "best_ask":"0.12"}], "timestamp":"1778784197190", "event_type":"price_change"}
{"market":"0x2a903c589141bce4a1e50fb98b73397af6820942542793ab10b1df477e912b6e", "price_changes":[{"asset_id":"20436996072316278452977393149218961565084965483366669504673105646378938504388", "price":"0.82", "size":"426.2", "side":"BUY", "hash":"3a13d7844d907ce37227e6eb614bdf12c6a3a230", "best_bid":"0.88", "best_ask":"0.89"}, {"asset_id":"68919878716222388542639225642064847629616106443780159680232863841946753372582", "price":"0.18", "size":"426.2", "side":"SELL", "hash":"22f837fcc3106e21609523e252bdc5395156bd22", "best_bid":"0.11", "best_ask":"0.12"}], "timestamp":"1778784197205", "event_type":"price_change"}
{"market":"0x2a903c589141bce4a1e50fb98b73397af6820942542793ab10b1df477e912b6e", "price_changes":[{"asset_id":"20436996072316278452977393149218961565084965483366669504673105646378938504388", "price":"0.76", "size":"126.39", "side":"BUY", "hash":"970d3eb5a50b8bc4f3a31eafc69eb402fe944970", "best_bid":"0.88", "best_ask":"0.89"}, {"asset_id":"68919878716222388542639225642064847629616106443780159680232863841946753372582", "price":"0.24", "size":"126.39", "side":"SELL", "hash":"1dd95b64eb2601fa06a780ff890be9d34fc1a218", "best_bid":"0.11", "best_ask":"0.12"}], "timestamp":"1778784197208", "event_type":"price_change"}
{"market":"0x2a903c589141bce4a1e50fb98b73397af6820942542793ab10b1df477e912b6e", "price_changes":[{"asset_id":"20436996072316278452977393149218961565084965483366669504673105646378938504388", "price":"0.84", "size":"123.7", "side":"BUY", "hash":"10e544682035635b0347626cc67b42e1e11fd201", "best_bid":"0.88", "best_ask":"0.89"}, {"asset_id":"68919878716222388542639225642064847629616106443780159680232863841946753372582", "price":"0.16", "size":"123.7", "side":"SELL", "hash":"c3601d3cfb16c6c58ccd294bff5e984e253afe76", "best_bid":"0.11", "best_ask":"0.12"}], "timestamp":"1778784197224", "event_type":"price_change"}
{"market":"0x2a903c589141bce4a1e50fb98b73397af6820942542793ab10b1df477e912b6e", "price_changes":[{"asset_id":"20436996072316278452977393149218961565084965483366669504673105646378938504388", "price":"0.85", "size":"71.53", "side":"BUY", "hash":"595b99b61e491d3ec4084943edc8b7b5e1e2bbaf", "best_bid":"0.88", "best_ask":"0.89"}, {"asset_id":"68919878716222388542639225642064847629616106443780159680232863841946753372582", "price":"0.15", "size":"71.53", "side":"SELL", "hash":"bf2f26eba1516f8a6f7f6ef158d73624f1519a97", "best_bid":"0.11", "best_ask":"0.12"}], "timestamp":"1778784197235", "event_type":"price_change"}
{"market":"0x2a903c589141bce4a1e50fb98b73397af6820942542793ab10b1df477e912b6e", "price_changes":[{"asset_id":"20436996072316278452977393149218961565084965483366669504673105646378938504388", "price":"0.81", "size":"67.35", "side":"BUY", "hash":"d4a1aac10e213b6d1a1f97660a191c016de25bf0", "best_bid":"0.88", "best_ask":"0.89"}, {"asset_id":"68919878716222388542639225642064847629616106443780159680232863841946753372582", "price":"0.19", "size":"67.35", "side":"SELL", "hash":"532eda74039fb5184ffcba75a72875177e350bcc", "best_bid":"0.11", "best_ask":"0.12"}], "timestamp":"1778784197237", "event_type":"price_change"}
{"market":"0x2a903c589141bce4a1e50fb98b73397af6820942542793ab10b1df477e912b6e", "price_changes":[{"asset_id":"20436996072316278452977393149218961565084965483366669504673105646378938504388", "price":"0.75", "size":"356", "side":"BUY", "hash":"065a3ead61239b4b409a37890df37dee765e2f07", "best_bid":"0.88", "best_ask":"0.89"}, {"asset_id":"68919878716222388542639225642064847629616106443780159680232863841946753372582", "price":"0.25", "size":"356", "side":"SELL", "hash":"ab751447e9d39e98b11439c450258060c19243af", "best_bid":"0.11", "best_ask":"0.12"}], "timestamp":"1778784197253", "event_type":"price_change"}
{"market":"0x2a903c589141bce4a1e50fb98b73397af6820942542793ab10b1df477e912b6e", "price_changes":[{"asset_id":"20436996072316278452977393149218961565084965483366669504673105646378938504388", "price":"0.85", "size":"51.53", "side":"BUY", "hash":"4c102a4525cacf45899639a222ff608511b4e656", "best_bid":"0.88", "best_ask":"0.89"}, {"asset_id":"68919878716222388542639225642064847629616106443780159680232863841946753372582", "price":"0.15", "size":"51.53", "side":"SELL", "hash":"a0112e8a381b6f48347c5ebc2548638d61745ba7", "best_bid":"0.11", "best_ask":"0.12"}], "timestamp":"1778784197264", "event_type":"price_change"}
{"market":"0x2a903c589141bce4a1e50fb98b73397af6820942542793ab10b1df477e912b6e", "price_changes":[{"asset_id":"68919878716222388542639225642064847629616106443780159680232863841946753372582", "price":"0.1", "size":"360.33", "side":"BUY", "hash":"95c1d7a81b186c8166feb326d270cad0e149d13a", "best_bid":"0.11", "best_ask":"0.12"}, {"asset_id":"20436996072316278452977393149218961565084965483366669504673105646378938504388", "price":"0.9", "size":"360.33", "side":"SELL", "hash":"2029658cdfb9b8ecfc0ee736a2822484a87a8349", "best_bid":"0.88", "best_ask":"0.89"}], "timestamp":"1778784197274", "event_type":"price_change"}
{"market":"0x2a903c589141bce4a1e50fb98b73397af6820942542793ab10b1df477e912b6e", "price_changes":[{"asset_id":"20436996072316278452977393149218961565084965483366669504673105646378938504388", "price":"0.86", "size":"118.53", "side":"BUY", "hash":"287495180381b06549c542f7ba33b8f2fea51e64", "best_bid":"0.88", "best_ask":"0.89"}, {"asset_id":"68919878716222388542639225642064847629616106443780159680232863841946753372582", "price":"0.14", "size":"118.53", "side":"SELL", "hash":"35a0f424c08def236176af6ed261fb5e60fbd1a3", "best_bid":"0.11", "best_ask":"0.12"}], "timestamp":"1778784197410", "event_type":"price_change"}
{"market":"0x2a903c589141bce4a1e50fb98b73397af6820942542793ab10b1df477e912b6e", "price_changes":[{"asset_id":"20436996072316278452977393149218961565084965483366669504673105646378938504388", "price":"0.84", "size":"123.7", "side":"BUY", "hash":"287495180381b06549c542f7ba33b8f2fea51e64", "best_bid":"0.88", "best_ask":"0.89"}, {"asset_id":"68919878716222388542639225642064847629616106443780159680232863841946753372582", "price":"0.16", "size":"123.7", "side":"SELL", "hash":"35a0f424c08def236176af6ed261fb5e60fbd1a3", "best_bid":"0.11", "best_ask":"0.12"}], "timestamp":"1778784197410", "event_type":"price_change"}
{"market":"0x2a903c589141bce4a1e50fb98b73397af6820942542793ab10b1df477e912b6e", "price_changes":[{"asset_id":"20436996072316278452977393149218961565084965483366669504673105646378938504388", "price":"0.82", "size":"351.2", "side":"BUY", "hash":"287495180381b06549c542f7ba33b8f2fea51e64", "best_bid":"0.88", "best_ask":"0.89"}, {"asset_id":"68919878716222388542639225642064847629616106443780159680232863841946753372582", "price":"0.18", "size":"351.2", "side":"SELL", "hash":"35a0f424c08def236176af6ed261fb5e60fbd1a3", "best_bid":"0.11", "best_ask":"0.12"}], "timestamp":"1778784197410", "event_type":"price_change"}
{"market":"0x2a903c589141bce4a1e50fb98b73397af6820942542793ab10b1df477e912b6e", "price_changes":[{"asset_id":"20436996072316278452977393149218961565084965483366669504673105646378938504388", "price":"0.8", "size":"90", "side":"BUY", "hash":"287495180381b06549c542f7ba33b8f2fea51e64", "best_bid":"0.88", "best_ask":"0.89"}, {"asset_id":"68919878716222388542639225642064847629616106443780159680232863841946753372582", "price":"0.2", "size":"90", "side":"SELL", "hash":"35a0f424c08def236176af6ed261fb5e60fbd1a3", "best_bid":"0.11", "best_ask":"0.12"}], "timestamp":"1778784197410", "event_type":"price_change"}
{"market":"0x2a903c589141bce4a1e50fb98b73397af6820942542793ab10b1df477e912b6e", "price_changes":[{"asset_id":"20436996072316278452977393149218961565084965483366669504673105646378938504388", "price":"0.68", "size":"2055.88", "side":"BUY", "hash":"da01497536f98a664b2bd24e1a802f7084fff6ab", "best_bid":"0.88", "best_ask":"0.89"}, {"asset_id":"68919878716222388542639225642064847629616106443780159680232863841946753372582", "price":"0.32", "size":"2055.88", "side":"SELL", "hash":"be1a81b36d9c4f47d028fbd42e7772e80964d174", "best_bid":"0.11", "best_ask":"0.12"}], "timestamp":"1778784197432", "event_type":"price_change"}
{"market":"0x2a903c589141bce4a1e50fb98b73397af6820942542793ab10b1df477e912b6e", "price_changes":[{"asset_id":"20436996072316278452977393149218961565084965483366669504673105646378938504388", "price":"0.83", "size":"110", "side":"BUY", "hash":"52f69ea70fd96af42b8ab2017d926190f1b03fc3", "best_bid":"0.88", "best_ask":"0.89"}, {"asset_id":"68919878716222388542639225642064847629616106443780159680232863841946753372582", "price":"0.17", "size":"110", "side":"SELL", "hash":"faa95be7095aa1fd1ddd8c8a8632e05ebdcf9c8f", "best_bid":"0.11", "best_ask":"0.12"}], "timestamp":"1778784197451", "event_type":"price_change"}
{"market":"0x2a903c589141bce4a1e50fb98b73397af6820942542793ab10b1df477e912b6e", "price_changes":[{"asset_id":"68919878716222388542639225642064847629616106443780159680232863841946753372582", "price":"0.06", "size":"337.72", "side":"BUY", "hash":"a1cbd3db30b8040be54a9e04dca4e5ee9c53de1f", "best_bid":"0.11", "best_ask":"0.12"}, {"asset_id":"20436996072316278452977393149218961565084965483366669504673105646378938504388", "price":"0.94", "size":"337.72", "side":"SELL", "hash":"9531c989a3e1c6e9135ee2ab81c6b8601312e507", "best_bid":"0.88", "best_ask":"0.89"}], "timestamp":"1778784197461", "event_type":"price_change"}
{"market":"0x2a903c589141bce4a1e50fb98b73397af6820942542793ab10b1df477e912b6e", "price_changes":[{"asset_id":"68919878716222388542639225642064847629616106443780159680232863841946753372582", "price":"0.1", "size":"410.33", "side":"BUY", "hash":"6f429a00c559feb6a6fe69de6a7234b1c66d5e95", "best_bid":"0.11", "best_ask":"0.12"}, {"asset_id":"20436996072316278452977393149218961565084965483366669504673105646378938504388", "price":"0.9", "size":"410.33", "side":"SELL", "hash":"8c99a8daa8496d622844c01715dbfb7cf6e5969b", "best_bid":"0.88", "best_ask":"0.89"}], "timestamp":"1778784197482", "event_type":"price_change"}
{"market":"0x2a903c589141bce4a1e50fb98b73397af6820942542793ab10b1df477e912b6e", "price_changes":[{"asset_id":"68919878716222388542639225642064847629616106443780159680232863841946753372582", "price":"0.14", "size":"111.38", "side":"SELL", "hash":"65129ac597ce7e5f85e5bcebc384053ee78ae8ea", "best_bid":"0.11", "best_ask":"0.12"}, {"asset_id":"20436996072316278452977393149218961565084965483366669504673105646378938504388", "price":"0.86", "size":"111.38", "side":"BUY", "hash":"123b53bc8ff588292877d99f46daab316d119716", "best_bid":"0.88", "best_ask":"0.89"}], "timestamp":"1778784197513", "event_type":"price_change"}
{"market":"0x2a903c589141bce4a1e50fb98b73397af6820942542793ab10b1df477e912b6e", "price_changes":[{"asset_id":"68919878716222388542639225642064847629616106443780159680232863841946753372582", "price":"0.08", "size":"320.74", "side":"BUY", "hash":"b708ff5eca1785fde26ec284057405fea03ad911", "best_bid":"0.11", "best_ask":"0.12"}, {"asset_id":"20436996072316278452977393149218961565084965483366669504673105646378938504388", "price":"0.92", "size":"320.74", "side":"SELL", "hash":"d90de9f5362bd7ae96e383158d1ad4cc51c56a66", "best_bid":"0.88", "best_ask":"0.89"}], "timestamp":"1778784197560", "event_type":"price_change"}
{"market":"0x2a903c589141bce4a1e50fb98b73397af6820942542793ab10b1df477e912b6e", "price_changes":[{"asset_id":"68919878716222388542639225642064847629616106443780159680232863841946753372582", "price":"0.1", "size":"450.33", "side":"BUY", "hash":"5e68b874e88cd520dd274a75b216ef3cc95eaf8c", "best_bid":"0.11", "best_ask":"0.12"}, {"asset_id":"20436996072316278452977393149218961565084965483366669504673105646378938504388", "price":"0.9", "size":"450.33", "side":"SELL", "hash":"713d619f3ff108e8648abe0b3ea6bd2635e6c815", "best_bid":"0.88", "best_ask":"0.89"}], "timestamp":"1778784197613", "event_type":"price_change"}
{"market":"0x2a903c589141bce4a1e50fb98b73397af6820942542793ab10b1df477e912b6e", "price_changes":[{"asset_id":"20436996072316278452977393149218961565084965483366669504673105646378938504388", "price":"0.9", "size":"475.33", "side":"SELL", "hash":"9d38ae663b9c701e4b90139b3e567f3d34d0af13", "best_bid":"0.88", "best_ask":"0.89"}, {"asset_id":"68919878716222388542639225642064847629616106443780159680232863841946753372582", "price":"0.1", "size":"475.33", "side":"BUY", "hash":"81ab84be2c191d90198ae5e0ab99cf539c679173", "best_bid":"0.11", "best_ask":"0.12"}], "timestamp":"1778784197624", "event_type":"price_change"}
{"market":"0x2a903c589141bce4a1e50fb98b73397af6820942542793ab10b1df477e912b6e", "price_changes":[{"asset_id":"68919878716222388542639225642064847629616106443780159680232863841946753372582", "price":"0.22", "size":"142.5", "side":"SELL", "hash":"2c50dbf83d4354a69601f40df5a9f60df3e79948", "best_bid":"0.11", "best_ask":"0.12"}, {"asset_id":"20436996072316278452977393149218961565084965483366669504673105646378938504388", "price":"0.78", "size":"142.5", "side":"BUY", "hash":"55935bca6b782213dea55a596c84e46d2679b7c2", "best_bid":"0.88", "best_ask":"0.89"}], "timestamp":"1778784197636", "event_type":"price_change"}
{"market":"0x2a903c589141bce4a1e50fb98b73397af6820942542793ab10b1df477e912b6e", "price_changes":[{"asset_id":"68919878716222388542639225642064847629616106443780159680232863841946753372582", "price":"0.1", "size":"487.33", "side":"BUY", "hash":"75ea34217a209a5e6217cc1ca28d5885ca06db17", "best_bid":"0.11", "best_ask":"0.12"}, {"asset_id":"20436996072316278452977393149218961565084965483366669504673105646378938504388", "price":"0.9", "size":"487.33", "side":"SELL", "hash":"fb490f2d85d11b95f575e8eff7495244f838d0a6", "best_bid":"0.88", "best_ask":"0.89"}], "timestamp":"1778784197661", "event_type":"price_change"}
{"market":"0x2a903c589141bce4a1e50fb98b73397af6820942542793ab10b1df477e912b6e", "price_changes":[{"asset_id":"68919878716222388542639225642064847629616106443780159680232863841946753372582", "price":"0.1", "size":"507.33", "side":"BUY", "hash":"87b850d433886d4fe7e3fccbe918933e46791e20", "best_bid":"0.11", "best_ask":"0.12"}, {"asset_id":"20436996072316278452977393149218961565084965483366669504673105646378938504388", "price":"0.9", "size":"507.33", "side":"SELL", "hash":"bb871058e800b6a4639de6c6420bbeb461ae6c95", "best_bid":"0.88", "best_ask":"0.89"}], "timestamp":"1778784197670", "event_type":"price_change"}
{"market":"0x2a903c589141bce4a1e50fb98b73397af6820942542793ab10b1df477e912b6e", "price_changes":[{"asset_id":"68919878716222388542639225642064847629616106443780159680232863841946753372582", "price":"0.21", "size":"175.44", "side":"SELL", "hash":"10f1d8a19f5fae8654ea8c8021ddd280e285c48b", "best_bid":"0.11", "best_ask":"0.12"}, {"asset_id":"20436996072316278452977393149218961565084965483366669504673105646378938504388", "price":"0.79", "size":"175.44", "side":"BUY", "hash":"80128c9d66e429552e99c116e1d458a4cff46818", "best_bid":"0.88", "best_ask":"0.89"}], "timestamp":"1778784197695", "event_type":"price_change"}
{"market":"0x2a903c589141bce4a1e50fb98b73397af6820942542793ab10b1df477e912b6e", "price_changes":[{"asset_id":"68919878716222388542639225642064847629616106443780159680232863841946753372582", "price":"0.01", "size":"11325.74", "side":"BUY", "hash":"4e10e0d33ce678eca9ce628a6d884e849f31125a", "best_bid":"0.11", "best_ask":"0.12"}, {"asset_id":"20436996072316278452977393149218961565084965483366669504673105646378938504388", "price":"0.99", "size":"11325.74", "side":"SELL", "hash":"ff561c3197aa6d7bd1b2f66fd4447d243478e97a", "best_bid":"0.88", "best_ask":"0.89"}], "timestamp":"1778784197698", "event_type":"price_change"}
{"market":"0x2a903c589141bce4a1e50fb98b73397af6820942542793ab10b1df477e912b6e", "price_changes":[{"asset_id":"68919878716222388542639225642064847629616106443780159680232863841946753372582", "price":"0.1", "size":"547.33", "side":"BUY", "hash":"b8b80e4e2cd06cff0c60b129694966bd91e675c4", "best_bid":"0.11", "best_ask":"0.12"}, {"asset_id":"20436996072316278452977393149218961565084965483366669504673105646378938504388", "price":"0.9", "size":"547.33", "side":"SELL", "hash":"2a85f05aeb3ba50206c7a202dbdc34217c34ed5f", "best_bid":"0.88", "best_ask":"0.89"}], "timestamp":"1778784197701", "event_type":"price_change"}
{"market":"0x2a903c589141bce4a1e50fb98b73397af6820942542793ab10b1df477e912b6e", "price_changes":[{"asset_id":"68919878716222388542639225642064847629616106443780159680232863841946753372582", "price":"0.03", "size":"1130.78", "side":"BUY", "hash":"6b709ad33129984873854597fda962169dd6df08", "best_bid":"0.11", "best_ask":"0.12"}, {"asset_id":"20436996072316278452977393149218961565084965483366669504673105646378938504388", "price":"0.97", "size":"1130.78", "side":"SELL", "hash":"9b30e99c6a66a50736c7dda20ade4b6f3fb2e91d", "best_bid":"0.88", "best_ask":"0.89"}], "timestamp":"1778784197716", "event_type":"price_change"}
{"market":"0x2a903c589141bce4a1e50fb98b73397af6820942542793ab10b1df477e912b6e", "price_changes":[{"asset_id":"20436996072316278452977393149218961565084965483366669504673105646378938504388", "price":"0.88", "size":"101.33", "side":"BUY", "hash":"5e871855898adeda39a2f626455e96ddedadaa0f", "best_bid":"0.88", "best_ask":"0.89"}, {"asset_id":"68919878716222388542639225642064847629616106443780159680232863841946753372582", "price":"0.12", "size":"101.33", "side":"SELL", "hash":"6f5f4e599a7d76646ff56a4ada184c8341a4e1ad", "best_bid":"0.11", "best_ask":"0.12"}], "timestamp":"1778784197790", "event_type":"price_change"}
{"market":"0x2a903c589141bce4a1e50fb98b73397af6820942542793ab10b1df477e912b6e", "asset_id":"68919878716222388542639225642064847629616106443780159680232863841946753372582", "bids":[{"price":"0.01", "size":"11325.74"}, {"price":"0.02", "size":"1462.32"}, {"price":"0.03", "size":"1130.78"}, {"price":"0.04", "size":"607.82"}, {"price":"0.05", "size":"755.72"}, {"price":"0.06", "size":"337.72"}, {"price":"0.07", "size":"357.1"}, {"price":"0.08", "size":"320.74"}, {"price":"0.09", "size":"286.11"}, {"price":"0.1", "size":"547.33"}, {"price":"0.11", "size":"217.35"}], "asks":[{"price":"0.99", "size":"12086.57"}, {"price":"0.98", "size":"1219.45"}, {"price":"0.97", "size":"1111.98"}, {"price":"0.96", "size":"670.05"}, {"price":"0.95", "size":"549.45"}, {"price":"0.94", "size":"346.2"}, {"price":"0.93", "size":"902.05"}, {"price":"0.92", "size":"170.79"}, {"price":"0.91", "size":"234.6"}, {"price":"0.9", "size":"128"}, {"price":"0.89", "size":"142.6"}, {"price":"0.88", "size":"141.8"}, {"price":"0.87", "size":"144.81"}, {"price":"0.86", "size":"204.9"}, {"price":"0.85", "size":"113.5"}, {"price":"0.84", "size":"102.3"}, {"price":"0.83", "size":"101.3"}, {"price":"0.82", "size":"105.3"}, {"price":"0.81", "size":"199.5"}, {"price":"0.8", "size":"103.8"}, {"price":"0.79", "size":"98.1"}, {"price":"0.78", "size":"97.5"}, {"price":"0.77", "size":"96.89"}, {"price":"0.76", "size":"201.39"}, {"price":"0.75", "size":"116"}, {"price":"0.74", "size":"100.6"}, {"price":"0.73", "size":"95.2"}, {"price":"0.72", "size":"94.9"}, {"price":"0.71", "size":"199.6"}, {"price":"0.7", "size":"94.3"}, {"price":"0.69", "size":"108.28"}, {"price":"0.68", "size":"98.8"}, {"price":"0.67", "size":"718.6"}, {"price":"0.66", "size":"898.4"}, {"price":"0.65", "size":"407.3"}, {"price":"0.64", "size":"293"}, {"price":"0.63", "size":"292.9"}, {"price":"0.62", "size":"297.7"}, {"price":"0.61", "size":"397.6"}, {"price":"0.6", "size":"356.93"}, {"price":"0.59", "size":"297.4"}, {"price":"0.58", "size":"109.6"}, {"price":"0.57", "size":"131.48"}, {"price":"0.56", "size":"413.97"}, {"price":"0.55", "size":"934.2"}, {"price":"0.54", "size":"375.6"}, {"price":"0.53", "size":"292"}, {"price":"0.52", "size":"297.12"}, {"price":"0.51", "size":"402"}, {"price":"0.5", "size":"340.91"}, {"price":"0.49", "size":"362"}, {"price":"0.48", "size":"317"}, {"price":"0.47", "size":"337"}, {"price":"0.46", "size":"607.1"}, {"price":"0.45", "size":"346.64"}, {"price":"0.44", "size":"341.45"}, {"price":"0.43", "size":"434.89"}, {"price":"0.42", "size":"324.36"}, {"price":"0.41", "size":"412.4"}, {"price":"0.4", "size":"328.83"}, {"price":"0.39", "size":"297.6"}, {"price":"0.38", "size":"636.5"}, {"price":"0.37", "size":"297.9"}, {"price":"0.36", "size":"208"}, {"price":"0.35", "size":"330.14"}, {"price":"0.34", "size":"330.9"}, {"price":"0.33", "size":"313.6"}, {"price":"0.32", "size":"2055.88"}, {"price":"0.31", "size":"409"}, {"price":"0.3", "size":"134.3"}, {"price":"0.29", "size":"316.38"}, {"price":"0.28", "size":"154.9"}, {"price":"0.27", "size":"180.2"}, {"price":"0.26", "size":"230.6"}, {"price":"0.25", "size":"356"}, {"price":"0.24", "size":"126.39"}, {"price":"0.23", "size":"121.89"}, {"price":"0.22", "size":"142.5"}, {"price":"0.21", "size":"175.44"}, {"price":"0.2", "size":"90"}, {"price":"0.19", "size":"67.35"}, {"price":"0.18", "size":"351.2"}, {"price":"0.17", "size":"110"}, {"price":"0.16", "size":"123.7"}, {"price":"0.15", "size":"51.53"}, {"price":"0.14", "size":"111.38"}, {"price":"0.13", "size":"30.77"}, {"price":"0.12", "size":"101.33"}], "hash":"6f5f4e599a7d76646ff56a4ada184c8341a4e1ad", "timestamp":"1778784197790", "event_type":"book"}
{"market":"0x2a903c589141bce4a1e50fb98b73397af6820942542793ab10b1df477e912b6e", "price_changes":[{"asset_id":"68919878716222388542639225642064847629616106443780159680232863841946753372582", "price":"0.1", "size":"610.33", "side":"BUY", "hash":"28cd1aaca82c245d2a2f3650bb56ba51ddd97630", "best_bid":"0.11", "best_ask":"0.12"}, {"asset_id":"20436996072316278452977393149218961565084965483366669504673105646378938504388", "price":"0.9", "size":"610.33", "side":"SELL", "hash":"3d316121dc77300a920164673a34592569a8ead7", "best_bid":"0.88", "best_ask":"0.89"}], "timestamp":"1778784197836", "event_type":"price_change"}
{"market":"0x2a903c589141bce4a1e50fb98b73397af6820942542793ab10b1df477e912b6e", "price_changes":[{"asset_id":"20436996072316278452977393149218961565084965483366669504673105646378938504388", "price":"0.84", "size":"118.7", "side":"BUY", "hash":"0523bcfd853c708d238b0ca7de93e56abbfd4c12", "best_bid":"0.88", "best_ask":"0.89"}, {"asset_id":"68919878716222388542639225642064847629616106443780159680232863841946753372582", "price":"0.16", "size":"118.7", "side":"SELL", "hash":"cf334644e1a582414ed882c6c63ae51402317717", "best_bid":"0.11", "best_ask":"0.12"}], "timestamp":"1778784197846", "event_type":"price_change"}
{"market":"0x2a903c589141bce4a1e50fb98b73397af6820942542793ab10b1df477e912b6e", "price_changes":[{"asset_id":"20436996072316278452977393149218961565084965483366669504673105646378938504388", "price":"0.85", "size":"46.53", "side":"BUY", "hash":"9c104cdccabbffc991b658b17846dda4c0485c79", "best_bid":"0.88", "best_ask":"0.89"}, {"asset_id":"68919878716222388542639225642064847629616106443780159680232863841946753372582", "price":"0.15", "size":"46.53", "side":"SELL", "hash":"5c7724bbcabb770ac615877591308f6f26b984d6", "best_bid":"0.11", "best_ask":"0.12"}], "timestamp":"1778784197864", "event_type":"price_change"}
{"market":"0x2a903c589141bce4a1e50fb98b73397af6820942542793ab10b1df477e912b6e", "price_changes":[{"asset_id":"20436996072316278452977393149218961565084965483366669504673105646378938504388", "price":"0.75", "size":"331", "side":"BUY", "hash":"29a735d5c21df99cb27018921d9a450aa327cc54", "best_bid":"0.88", "best_ask":"0.89"}, {"asset_id":"68919878716222388542639225642064847629616106443780159680232863841946753372582", "price":"0.25", "size":"331", "side":"SELL", "hash":"47e4e635a5df0b78b7b627e2b81bd7c9d49be3f4", "best_bid":"0.11", "best_ask":"0.12"}], "timestamp":"1778784197866", "event_type":"price_change"}
{"market":"0x2a903c589141bce4a1e50fb98b73397af6820942542793ab10b1df477e912b6e", "asset_id":"68919878716222388542639225642064847629616106443780159680232863841946753372582", "price":"0.12", "size":"41.666665", "fee_rate_bps":"0", "side":"BUY", "timestamp":"1778784197863", "event_type":"last_trade_price", "transaction_hash":"0x2d8579997f1c2519be7f78ddd3621a14a8612b424a9e8eb016ca6434e0128c87"}
{"market":"0x2a903c589141bce4a1e50fb98b73397af6820942542793ab10b1df477e912b6e", "price_changes":[{"asset_id":"68919878716222388542639225642064847629616106443780159680232863841946753372582", "price":"0.11", "size":"317.35", "side":"BUY", "hash":"80bda9a41a4111d8db827a5e4c810d7a76de2747", "best_bid":"0.11", "best_ask":"0.12"}, {"asset_id":"20436996072316278452977393149218961565084965483366669504673105646378938504388", "price":"0.89", "size":"317.35", "side":"SELL", "hash":"e740aa155bbd248ad3f80cabac953dc133c5e24e", "best_bid":"0.88", "best_ask":"0.89"}], "timestamp":"1778784197876", "event_type":"price_change"}
{"market":"0x2a903c589141bce4a1e50fb98b73397af6820942542793ab10b1df477e912b6e", "price_changes":[{"asset_id":"20436996072316278452977393149218961565084965483366669504673105646378938504388", "price":"0.82", "size":"346.2", "side":"BUY", "hash":"1bfae697663d866c56a15a8a3df37726da4e6878", "best_bid":"0.88", "best_ask":"0.89"}, {"asset_id":"68919878716222388542639225642064847629616106443780159680232863841946753372582", "price":"0.18", "size":"346.2", "side":"SELL", "hash":"ec5ff323cb918e3972f7755d70876b959c7a61d1", "best_bid":"0.11", "best_ask":"0.12"}], "timestamp":"1778784197878", "event_type":"price_change"}
{"market":"0x2a903c589141bce4a1e50fb98b73397af6820942542793ab10b1df477e912b6e", "price_changes":[{"asset_id":"20436996072316278452977393149218961565084965483366669504673105646378938504388", "price":"0.83", "size":"105", "side":"BUY", "hash":"1bfae697663d866c56a15a8a3df37726da4e6878", "best_bid":"0.88", "best_ask":"0.89"}, {"asset_id":"68919878716222388542639225642064847629616106443780159680232863841946753372582", "price":"0.17", "size":"105", "side":"SELL", "hash":"ec5ff323cb918e3972f7755d70876b959c7a61d1", "best_bid":"0.11", "best_ask":"0.12"}], "timestamp":"1778784197878", "event_type":"price_change"}
{"market":"0x2a903c589141bce4a1e50fb98b73397af6820942542793ab10b1df477e912b6e", "price_changes":[{"asset_id":"68919878716222388542639225642064847629616106443780159680232863841946753372582", "price":"0.11", "size":"311.73", "side":"BUY", "hash":"b05359606d5cf868a9db5f40219c66603dc3ee13", "best_bid":"0.11", "best_ask":"0.12"}, {"asset_id":"20436996072316278452977393149218961565084965483366669504673105646378938504388", "price":"0.89", "size":"311.73", "side":"SELL", "hash":"503b6f0055c6376dc4b3db5bc948dcfd68e32bc7", "best_bid":"0.88", "best_ask":"0.89"}], "timestamp":"1778784197910", "event_type":"price_change"}
{"market":"0x2a903c589141bce4a1e50fb98b73397af6820942542793ab10b1df477e912b6e", "asset_id":"68919878716222388542639225642064847629616106443780159680232863841946753372582", "bids":[{"price":"0.01", "size":"11325.74"}, {"price":"0.02", "size":"1462.32"}, {"price":"0.03", "size":"1130.78"}, {"price":"0.04", "size":"607.82"}, {"price":"0.05", "size":"755.72"}, {"price":"0.06", "size":"337.72"}, {"price":"0.07", "size":"357.1"}, {"price":"0.08", "size":"320.74"}, {"price":"0.09", "size":"286.11"}, {"price":"0.1", "size":"610.33"}, {"price":"0.11", "size":"311.73"}], "asks":[{"price":"0.99", "size":"12086.57"}, {"price":"0.98", "size":"1219.45"}, {"price":"0.97", "size":"1111.98"}, {"price":"0.96", "size":"670.05"}, {"price":"0.95", "size":"549.45"}, {"price":"0.94", "size":"346.2"}, {"price":"0.93", "size":"902.05"}, {"price":"0.92", "size":"170.79"}, {"price":"0.91", "size":"234.6"}, {"price":"0.9", "size":"128"}, {"price":"0.89", "size":"142.6"}, {"price":"0.88", "size":"141.8"}, {"price":"0.87", "size":"144.81"}, {"price":"0.86", "size":"204.9"}, {"price":"0.85", "size":"113.5"}, {"price":"0.84", "size":"102.3"}, {"price":"0.83", "size":"101.3"}, {"price":"0.82", "size":"105.3"}, {"price":"0.81", "size":"199.5"}, {"price":"0.8", "size":"103.8"}, {"price":"0.79", "size":"98.1"}, {"price":"0.78", "size":"97.5"}, {"price":"0.77", "size":"96.89"}, {"price":"0.76", "size":"201.39"}, {"price":"0.75", "size":"116"}, {"price":"0.74", "size":"100.6"}, {"price":"0.73", "size":"95.2"}, {"price":"0.72", "size":"94.9"}, {"price":"0.71", "size":"199.6"}, {"price":"0.7", "size":"94.3"}, {"price":"0.69", "size":"108.28"}, {"price":"0.68", "size":"98.8"}, {"price":"0.67", "size":"718.6"}, {"price":"0.66", "size":"898.4"}, {"price":"0.65", "size":"407.3"}, {"price":"0.64", "size":"293"}, {"price":"0.63", "size":"292.9"}, {"price":"0.62", "size":"297.7"}, {"price":"0.61", "size":"397.6"}, {"price":"0.6", "size":"356.93"}, {"price":"0.59", "size":"297.4"}, {"price":"0.58", "size":"109.6"}, {"price":"0.57", "size":"131.48"}, {"price":"0.56", "size":"413.97"}, {"price":"0.55", "size":"934.2"}, {"price":"0.54", "size":"375.6"}, {"price":"0.53", "size":"292"}, {"price":"0.52", "size":"297.12"}, {"price":"0.51", "size":"402"}, {"price":"0.5", "size":"340.91"}, {"price":"0.49", "size":"362"}, {"price":"0.48", "size":"317"}, {"price":"0.47", "size":"337"}, {"price":"0.46", "size":"607.1"}, {"price":"0.45", "size":"346.64"}, {"price":"0.44", "size":"341.45"}, {"price":"0.43", "size":"434.89"}, {"price":"0.42", "size":"324.36"}, {"price":"0.41", "size":"412.4"}, {"price":"0.4", "size":"328.83"}, {"price":"0.39", "size":"297.6"}, {"price":"0.38", "size":"636.5"}, {"price":"0.37", "size":"297.9"}, {"price":"0.36", "size":"208"}, {"price":"0.35", "size":"330.14"}, {"price":"0.34", "size":"330.9"}, {"price":"0.33", "size":"313.6"}, {"price":"0.32", "size":"2055.88"}, {"price":"0.31", "size":"409"}, {"price":"0.3", "size":"134.3"}, {"price":"0.29", "size":"316.38"}, {"price":"0.28", "size":"154.9"}, {"price":"0.27", "size":"180.2"}, {"price":"0.26", "size":"230.6"}, {"price":"0.25", "size":"331"}, {"price":"0.24", "size":"126.39"}, {"price":"0.23", "size":"121.89"}, {"price":"0.22", "size":"142.5"}, {"price":"0.21", "size":"175.44"}, {"price":"0.2", "size":"90"}, {"price":"0.19", "size":"67.35"}, {"price":"0.18", "size":"346.2"}, {"price":"0.17", "size":"105"}, {"price":"0.16", "size":"118.7"}, {"price":"0.15", "size":"46.53"}, {"price":"0.14", "size":"111.38"}, {"price":"0.13", "size":"30.77"}, {"price":"0.12", "size":"101.33"}], "hash":"b05359606d5cf868a9db5f40219c66603dc3ee13", "timestamp":"1778784197910", "event_type":"book"}
{"market":"0x2a903c589141bce4a1e50fb98b73397af6820942542793ab10b1df477e912b6e", "price_changes":[{"asset_id":"68919878716222388542639225642064847629616106443780159680232863841946753372582", "price":"0.08", "size":"620.74", "side":"BUY", "hash":"9cb49145fa9430ba579334b78d422f6af8797990", "best_bid":"0.11", "best_ask":"0.12"}, {"asset_id":"20436996072316278452977393149218961565084965483366669504673105646378938504388", "price":"0.92", "size":"620.74", "side":"SELL", "hash":"7c8d47d9559e4459a18ce7c1fa2c938227f68529", "best_bid":"0.88", "best_ask":"0.89"}], "timestamp":"1778784197914", "event_type":"price_change"}
{"market":"0x2a903c589141bce4a1e50fb98b73397af6820942542793ab10b1df477e912b6e", "price_changes":[{"asset_id":"68919878716222388542639225642064847629616106443780159680232863841946753372582", "price":"0.01", "size":"11330.74", "side":"BUY", "hash":"97cfb03d7a59fabcdc6c9ed7677e5ba9bbab6947", "best_bid":"0.11", "best_ask":"0.12"}, {"asset_id":"20436996072316278452977393149218961565084965483366669504673105646378938504388", "price":"0.99", "size":"11330.74", "side":"SELL", "hash":"3dcc06a254ac07d54c4806e22175f6ee70192f55", "best_bid":"0.88", "best_ask":"0.89"}], "timestamp":"1778784197924", "event_type":"price_change"}
{"market":"0x2a903c589141bce4a1e50fb98b73397af6820942542793ab10b1df477e912b6e", "price_changes":[{"asset_id":"20436996072316278452977393149218961565084965483366669504673105646378938504388", "price":"0.9", "size":"585.33", "side":"SELL", "hash":"0cf216a8082fea44775d369a190c2cafc94d8015", "best_bid":"0.88", "best_ask":"0.89"}, {"asset_id":"68919878716222388542639225642064847629616106443780159680232863841946753372582", "price":"0.1", "size":"585.33", "side":"BUY", "hash":"4fef426a7a8d6594fec074b62d6b4af9fafac2ca", "best_bid":"0.11", "best_ask":"0.12"}], "timestamp":"1778784197947", "event_type":"price_change"}
{"market":"0x2a903c589141bce4a1e50fb98b73397af6820942542793ab10b1df477e912b6e", "price_changes":[{"asset_id":"68919878716222388542639225642064847629616106443780159680232863841946753372582", "price":"0.03", "size":"1105.78", "side":"BUY", "hash":"d2e1ebf98e4c6de90e6efcb8eb0022f07fc87600", "best_bid":"0.11", "best_ask":"0.12"}, {"asset_id":"20436996072316278452977393149218961565084965483366669504673105646378938504388", "price":"0.97", "size":"1105.78", "side":"SELL", "hash":"2784dbf032165b1750586decd64e9771178a25a7", "best_bid":"0.88", "best_ask":"0.89"}], "timestamp":"1778784197948", "event_type":"price_change"}
{"market":"0x2a903c589141bce4a1e50fb98b73397af6820942542793ab10b1df477e912b6e", "price_changes":[{"asset_id":"20436996072316278452977393149218961565084965483366669504673105646378938504388", "price":"0.87", "size":"12.1", "side":"BUY", "hash":"b991585aa284757165423d4157d64897bf759450", "best_bid":"0.87", "best_ask":"0.89"}, {"asset_id":"68919878716222388542639225642064847629616106443780159680232863841946753372582", "price":"0.13", "size":"12.1", "side":"SELL", "hash":"d6fca3319f5340a73df114db7a5251fa4b02fd9d", "best_bid":"0.11", "best_ask":"0.13"}], "timestamp":"1778784197951", "event_type":"price_change"}
{"market":"0x2a903c589141bce4a1e50fb98b73397af6820942542793ab10b1df477e912b6e", "price_changes":[{"asset_id":"20436996072316278452977393149218961565084965483366669504673105646378938504388", "price":"0.88", "size":"0", "side":"BUY", "hash":"b991585aa284757165423d4157d64897bf759450", "best_bid":"0.87", "best_ask":"0.89"}, {"asset_id":"68919878716222388542639225642064847629616106443780159680232863841946753372582", "price":"0.12", "size":"0", "side":"SELL", "hash":"d6fca3319f5340a73df114db7a5251fa4b02fd9d", "best_bid":"0.11", "best_ask":"0.13"}], "timestamp":"1778784197951", "event_type":"price_change"}
{"market":"0x2a903c589141bce4a1e50fb98b73397af6820942542793ab10b1df477e912b6e", "asset_id":"68919878716222388542639225642064847629616106443780159680232863841946753372582", "bids":[{"price":"0.01", "size":"11330.74"}, {"price":"0.02", "size":"1462.32"}, {"price":"0.03", "size":"1105.78"}, {"price":"0.04", "size":"607.82"}, {"price":"0.05", "size":"755.72"}, {"price":"0.06", "size":"337.72"}, {"price":"0.07", "size":"357.1"}, {"price":"0.08", "size":"620.74"}, {"price":"0.09", "size":"286.11"}, {"price":"0.1", "size":"585.33"}, {"price":"0.11", "size":"311.73"}], "asks":[{"price":"0.99", "size":"12086.57"}, {"price":"0.98", "size":"1219.45"}, {"price":"0.97", "size":"1111.98"}, {"price":"0.96", "size":"670.05"}, {"price":"0.95", "size":"549.45"}, {"price":"0.94", "size":"346.2"}, {"price":"0.93", "size":"902.05"}, {"price":"0.92", "size":"170.79"}, {"price":"0.91", "size":"234.6"}, {"price":"0.9", "size":"128"}, {"price":"0.89", "size":"142.6"}, {"price":"0.88", "size":"141.8"}, {"price":"0.87", "size":"144.81"}, {"price":"0.86", "size":"204.9"}, {"price":"0.85", "size":"113.5"}, {"price":"0.84", "size":"102.3"}, {"price":"0.83", "size":"101.3"}, {"price":"0.82", "size":"105.3"}, {"price":"0.81", "size":"199.5"}, {"price":"0.8", "size":"103.8"}, {"price":"0.79", "size":"98.1"}, {"price":"0.78", "size":"97.5"}, {"price":"0.77", "size":"96.89"}, {"price":"0.76", "size":"201.39"}, {"price":"0.75", "size":"116"}, {"price":"0.74", "size":"100.6"}, {"price":"0.73", "size":"95.2"}, {"price":"0.72", "size":"94.9"}, {"price":"0.71", "size":"199.6"}, {"price":"0.7", "size":"94.3"}, {"price":"0.69", "size":"108.28"}, {"price":"0.68", "size":"98.8"}, {"price":"0.67", "size":"718.6"}, {"price":"0.66", "size":"898.4"}, {"price":"0.65", "size":"407.3"}, {"price":"0.64", "size":"293"}, {"price":"0.63", "size":"292.9"}, {"price":"0.62", "size":"297.7"}, {"price":"0.61", "size":"397.6"}, {"price":"0.6", "size":"356.93"}, {"price":"0.59", "size":"297.4"}, {"price":"0.58", "size":"109.6"}, {"price":"0.57", "size":"131.48"}, {"price":"0.56", "size":"413.97"}, {"price":"0.55", "size":"934.2"}, {"price":"0.54", "size":"375.6"}, {"price":"0.53", "size":"292"}, {"price":"0.52", "size":"297.12"}, {"price":"0.51", "size":"402"}, {"price":"0.5", "size":"340.91"}, {"price":"0.49", "size":"362"}, {"price":"0.48", "size":"317"}, {"price":"0.47", "size":"337"}, {"price":"0.46", "size":"607.1"}, {"price":"0.45", "size":"346.64"}, {"price":"0.44", "size":"341.45"}, {"price":"0.43", "size":"434.89"}, {"price":"0.42", "size":"324.36"}, {"price":"0.41", "size":"412.4"}, {"price":"0.4", "size":"328.83"}, {"price":"0.39", "size":"297.6"}, {"price":"0.38", "size":"636.5"}, {"price":"0.37", "size":"297.9"}, {"price":"0.36", "size":"208"}, {"price":"0.35", "size":"330.14"}, {"price":"0.34", "size":"330.9"}, {"price":"0.33", "size":"313.6"}, {"price":"0.32", "size":"2055.88"}, {"price":"0.31", "size":"409"}, {"price":"0.3", "size":"134.3"}, {"price":"0.29", "size":"316.38"}, {"price":"0.28", "size":"154.9"}, {"price":"0.27", "size":"180.2"}, {"price":"0.26", "size":"230.6"}, {"price":"0.25", "size":"331"}, {"price":"0.24", "size":"126.39"}, {"price":"0.23", "size":"121.89"}, {"price":"0.22", "size":"142.5"}, {"price":"0.21", "size":"175.44"}, {"price":"0.2", "size":"90"}, {"price":"0.19", "size":"67.35"}, {"price":"0.18", "size":"346.2"}, {"price":"0.17", "size":"105"}, {"price":"0.16", "size":"118.7"}, {"price":"0.15", "size":"46.53"}, {"price":"0.14", "size":"111.38"}, {"price":"0.13", "size":"12.1"}], "hash":"d6fca3319f5340a73df114db7a5251fa4b02fd9d", "timestamp":"1778784197951", "event_type":"book"}
{"market":"0x2a903c589141bce4a1e50fb98b73397af6820942542793ab10b1df477e912b6e", "price_changes":[{"asset_id":"68919878716222388542639225642064847629616106443780159680232863841946753372582", "price":"0.11", "size":"341.73", "side":"BUY", "hash":"4190b77f61bbcf2797481342f4ff58ae73c5b220", "best_bid":"0.11", "best_ask":"0.13"}, {"asset_id":"20436996072316278452977393149218961565084965483366669504673105646378938504388", "price":"0.89", "size":"341.73", "side":"SELL", "hash":"c8dbffef091b9b269322b9149ba92d11fe56098a", "best_bid":"0.87", "best_ask":"0.89"}], "timestamp":"1778784197977", "event_type":"price_change"}
{"market":"0x2a903c589141bce4a1e50fb98b73397af6820942542793ab10b1df477e912b6e", "asset_id":"68919878716222388542639225642064847629616106443780159680232863841946753372582", "price":"0.12", "size":"120", "fee_rate_bps":"0", "side":"BUY", "timestamp":"1778784198029", "event_type":"last_trade_price", "transaction_hash":"0xf7fdbd6314196d10571263b9f8ba8d3b48d209ec991b486f0d733d117dcca297"}
{"market":"0x2a903c589141bce4a1e50fb98b73397af6820942542793ab10b1df477e912b6e", "price_changes":[{"asset_id":"68919878716222388542639225642064847629616106443780159680232863841946753372582", "price":"0.22", "size":"117.5", "side":"SELL", "hash":"c463128db2c26a93183b74317404bb75d67e9dd6", "best_bid":"0.11", "best_ask":"0.13"}, {"asset_id":"20436996072316278452977393149218961565084965483366669504673105646378938504388", "price":"0.78", "size":"117.5", "side":"BUY", "hash":"92b5143c30134ec4ebe582d8c7f5f10d690dae9b", "best_bid":"0.87", "best_ask":"0.89"}], "timestamp":"1778784198024", "event_type":"price_change"}
{"market":"0x2a903c589141bce4a1e50fb98b73397af6820942542793ab10b1df477e912b6e", "price_changes":[{"asset_id":"20436996072316278452977393149218961565084965483366669504673105646378938504388", "price":"0.87", "size":"2.1", "side":"BUY", "hash":"6177eeedbcb9cb95851b6523b7e23b4235f0e16b", "best_bid":"0.87", "best_ask":"0.89"}, {"asset_id":"68919878716222388542639225642064847629616106443780159680232863841946753372582", "price":"0.13", "size":"2.1", "side":"SELL", "hash":"a34379dc3fbc0fc12210f91eeeb86f3c571ce34c", "best_bid":"0.11", "best_ask":"0.13"}], "timestamp":"1778784198034", "event_type":"price_change"}
{"market":"0x2a903c589141bce4a1e50fb98b73397af6820942542793ab10b1df477e912b6e", "asset_id":"68919878716222388542639225642064847629616106443780159680232863841946753372582", "bids":[{"price":"0.01", "size":"11330.74"}, {"price":"0.02", "size":"1462.32"}, {"price":"0.03", "size":"1105.78"}, {"price":"0.04", "size":"607.82"}, {"price":"0.05", "size":"755.72"}, {"price":"0.06", "size":"337.72"}, {"price":"0.07", "size":"357.1"}, {"price":"0.08", "size":"620.74"}, {"price":"0.09", "size":"286.11"}, {"price":"0.1", "size":"585.33"}, {"price":"0.11", "size":"341.73"}], "asks":[{"price":"0.99", "size":"12086.57"}, {"price":"0.98", "size":"1219.45"}, {"price":"0.97", "size":"1111.98"}, {"price":"0.96", "size":"670.05"}, {"price":"0.95", "size":"549.45"}, {"price":"0.94", "size":"346.2"}, {"price":"0.93", "size":"902.05"}, {"price":"0.92", "size":"170.79"}, {"price":"0.91", "size":"234.6"}, {"price":"0.9", "size":"128"}, {"price":"0.89", "size":"142.6"}, {"price":"0.88", "size":"141.8"}, {"price":"0.87", "size":"144.81"}, {"price":"0.86", "size":"204.9"}, {"price":"0.85", "size":"113.5"}, {"price":"0.84", "size":"102.3"}, {"price":"0.83", "size":"101.3"}, {"price":"0.82", "size":"105.3"}, {"price":"0.81", "size":"199.5"}, {"price":"0.8", "size":"103.8"}, {"price":"0.79", "size":"98.1"}, {"price":"0.78", "size":"97.5"}, {"price":"0.77", "size":"96.89"}, {"price":"0.76", "size":"201.39"}, {"price":"0.75", "size":"116"}, {"price":"0.74", "size":"100.6"}, {"price":"0.73", "size":"95.2"}, {"price":"0.72", "size":"94.9"}, {"price":"0.71", "size":"199.6"}, {"price":"0.7", "size":"94.3"}, {"price":"0.69", "size":"108.28"}, {"price":"0.68", "size":"98.8"}, {"price":"0.67", "size":"718.6"}, {"price":"0.66", "size":"798.4"}, {"price":"0.65", "size":"107.3"}, {"price":"0.64", "size":"293"}, {"price":"0.63", "size":"292.9"}, {"price":"0.62", "size":"297.7"}, {"price":"0.61", "size":"397.6"}, {"price":"0.6", "size":"356.93"}, {"price":"0.59", "size":"297.4"}, {"price":"0.58", "size":"109.6"}, {"price":"0.57", "size":"131.48"}, {"price":"0.56", "size":"413.97"}, {"price":"0.55", "size":"934.2"}, {"price":"0.54", "size":"375.6"}, {"price":"0.53", "size":"292"}, {"price":"0.52", "size":"297.12"}, {"price":"0.51", "size":"402"}, {"price":"0.5", "size":"340.91"}, {"price":"0.49", "size":"362"}, {"price":"0.48", "size":"317"}, {"price":"0.47", "size":"337"}, {"price":"0.46", "size":"607.1"}, {"price":"0.45", "size":"346.64"}, {"price":"0.44", "size":"341.45"}, {"price":"0.43", "size":"434.89"}, {"price":"0.42", "size":"324.36"}, {"price":"0.41", "size":"412.4"}, {"price":"0.4", "size":"328.83"}, {"price":"0.39", "size":"297.6"}, {"price":"0.38", "size":"636.5"}, {"price":"0.37", "size":"297.9"}, {"price":"0.36", "size":"208"}, {"price":"0.35", "size":"330.14"}, {"price":"0.34", "size":"330.9"}, {"price":"0.33", "size":"313.6"}, {"price":"0.32", "size":"2055.88"}, {"price":"0.31", "size":"409"}, {"price":"0.3", "size":"134.3"}, {"price":"0.29", "size":"316.38"}, {"price":"0.28", "size":"154.9"}, {"price":"0.27", "size":"180.2"}, {"price":"0.26", "size":"230.6"}, {"price":"0.25", "size":"331"}, {"price":"0.24", "size":"126.39"}, {"price":"0.23", "size":"121.89"}, {"price":"0.22", "size":"117.5"}, {"price":"0.21", "size":"175.44"}, {"price":"0.2", "size":"90"}, {"price":"0.19", "size":"67.35"}, {"price":"0.18", "size":"346.2"}, {"price":"0.17", "size":"105"}, {"price":"0.16", "size":"118.7"}, {"price":"0.15", "size":"46.53"}, {"price":"0.14", "size":"111.38"}, {"price":"0.13", "size":"2.1"}], "hash":"a34379dc3fbc0fc12210f91eeeb86f3c571ce34c", "timestamp":"1778784198034", "event_type":"book"}
{"market":"0x2a903c589141bce4a1e50fb98b73397af6820942542793ab10b1df477e912b6e", "price_changes":[{"asset_id":"20436996072316278452977393149218961565084965483366669504673105646378938504388", "price":"0.01", "size":"12081.57", "side":"BUY", "hash":"f11d8915272f9a12d94236f783a962ce2db81a94", "best_bid":"0.87", "best_ask":"0.89"}, {"asset_id":"68919878716222388542639225642064847629616106443780159680232863841946753372582", "price":"0.99", "size":"12081.57", "side":"SELL", "hash":"ed5d9ea7b5f3c43e408cf841c3137c0b29e2070f", "best_bid":"0.11", "best_ask":"0.13"}], "timestamp":"1778784198037", "event_type":"price_change"}
{"market":"0x2a903c589141bce4a1e50fb98b73397af6820942542793ab10b1df477e912b6e", "price_changes":[{"asset_id":"68919878716222388542639225642064847629616106443780159680232863841946753372582", "price":"0.04", "size":"632.82", "side":"BUY", "hash":"695495cdc302f386c11f73cc17219903d5ad26e3", "best_bid":"0.11", "best_ask":"0.13"}, {"asset_id":"20436996072316278452977393149218961565084965483366669504673105646378938504388", "price":"0.96", "size":"632.82", "side":"SELL", "hash":"3b142318abb2bb66fda9b7c2d9e7b7c3f4d4a0a6", "best_bid":"0.87", "best_ask":"0.89"}], "timestamp":"1778784198043", "event_type":"price_change"}
{"market":"0x2a903c589141bce4a1e50fb98b73397af6820942542793ab10b1df477e912b6e", "asset_id":"68919878716222388542639225642064847629616106443780159680232863841946753372582", "price":"0.13", "size":"10", "fee_rate_bps":"0", "side":"BUY", "timestamp":"1778784198065", "event_type":"last_trade_price", "transaction_hash":"0xe9a6384e445ff39fb8a1f91bdb99d9aa8ab9cd75fb3defb047cc3c8dad30cadc"}
{"market":"0x2a903c589141bce4a1e50fb98b73397af6820942542793ab10b1df477e912b6e", "price_changes":[{"asset_id":"20436996072316278452977393149218961565084965483366669504673105646378938504388", "price":"0.35", "size":"107.3", "side":"BUY", "hash":"e453e8cf960282cd55b9af5cb2c1baa57262f89f", "best_bid":"0.87", "best_ask":"0.89"}, {"asset_id":"68919878716222388542639225642064847629616106443780159680232863841946753372582", "price":"0.65", "size":"107.3", "side":"SELL", "hash":"95ebaa47f6a187cb012139bfdc1661a43edf6957", "best_bid":"0.11", "best_ask":"0.13"}], "timestamp":"1778784198077", "event_type":"price_change"}
{"market":"0x2a903c589141bce4a1e50fb98b73397af6820942542793ab10b1df477e912b6e", "price_changes":[{"asset_id":"20436996072316278452977393149218961565084965483366669504673105646378938504388", "price":"0.34", "size":"798.4", "side":"BUY", "hash":"e453e8cf960282cd55b9af5cb2c1baa57262f89f", "best_bid":"0.87", "best_ask":"0.89"}, {"asset_id":"68919878716222388542639225642064847629616106443780159680232863841946753372582", "price":"0.66", "size":"798.4", "side":"SELL", "hash":"95ebaa47f6a187cb012139bfdc1661a43edf6957", "best_bid":"0.11", "best_ask":"0.13"}], "timestamp":"1778784198077", "event_type":"price_change"}
{"market":"0x2a903c589141bce4a1e50fb98b73397af6820942542793ab10b1df477e912b6e", "price_changes":[{"asset_id":"20436996072316278452977393149218961565084965483366669504673105646378938504388", "price":"0.86", "size":"96.04", "side":"BUY", "hash":"79b83738d79ea92076adbe232285baf1d2b9b52b", "best_bid":"0.86", "best_ask":"0.89"}, {"asset_id":"68919878716222388542639225642064847629616106443780159680232863841946753372582", "price":"0.14", "size":"96.04", "side":"SELL", "hash":"7e7658027398b7feaf06a2bf9a27dad37a91a555", "best_bid":"0.11", "best_ask":"0.14"}], "timestamp":"1778784198099", "event_type":"price_change"}
{"market":"0x2a903c589141bce4a1e50fb98b73397af6820942542793ab10b1df477e912b6e", "price_changes":[{"asset_id":"20436996072316278452977393149218961565084965483366669504673105646378938504388", "price":"0.87", "size":"0", "side":"BUY", "hash":"79b83738d79ea92076adbe232285baf1d2b9b52b", "best_bid":"0.86", "best_ask":"0.89"}, {"asset_id":"68919878716222388542639225642064847629616106443780159680232863841946753372582", "price":"0.13", "size":"0", "side":"SELL", "hash":"7e7658027398b7feaf06a2bf9a27dad37a91a555", "best_bid":"0.11", "best_ask":"0.14"}], "timestamp":"1778784198099", "event_type":"price_change"}
{"market":"0x2a903c589141bce4a1e50fb98b73397af6820942542793ab10b1df477e912b6e", "asset_id":"68919878716222388542639225642064847629616106443780159680232863841946753372582", "bids":[{"price":"0.01", "size":"11330.74"}, {"price":"0.02", "size":"1462.32"}, {"price":"0.03", "size":"1105.78"}, {"price":"0.04", "size":"632.82"}, {"price":"0.05", "size":"755.72"}, {"price":"0.06", "size":"337.72"}, {"price":"0.07", "size":"357.1"}, {"price":"0.08", "size":"620.74"}, {"price":"0.09", "size":"286.11"}, {"price":"0.1", "size":"585.33"}, {"price":"0.11", "size":"341.73"}], "asks":[{"price":"0.99", "size":"12081.57"}, {"price":"0.98", "size":"1219.45"}, {"price":"0.97", "size":"1111.98"}, {"price":"0.96", "size":"670.05"}, {"price":"0.95", "size":"549.45"}, {"price":"0.94", "size":"346.2"}, {"price":"0.93", "size":"902.05"}, {"price":"0.92", "size":"170.79"}, {"price":"0.91", "size":"234.6"}, {"price":"0.9", "size":"128"}, {"price":"0.89", "size":"142.6"}, {"price":"0.88", "size":"141.8"}, {"price":"0.87", "size":"144.81"}, {"price":"0.86", "size":"204.9"}, {"price":"0.85", "size":"113.5"}, {"price":"0.84", "size":"102.3"}, {"price":"0.83", "size":"101.3"}, {"price":"0.82", "size":"105.3"}, {"price":"0.81", "size":"199.5"}, {"price":"0.8", "size":"103.8"}, {"price":"0.79", "size":"98.1"}, {"price":"0.78", "size":"97.5"}, {"price":"0.77", "size":"96.89"}, {"price":"0.76", "size":"201.39"}, {"price":"0.75", "size":"116"}, {"price":"0.74", "size":"100.6"}, {"price":"0.73", "size":"95.2"}, {"price":"0.72", "size":"94.9"}, {"price":"0.71", "size":"199.6"}, {"price":"0.7", "size":"94.3"}, {"price":"0.69", "size":"108.28"}, {"price":"0.68", "size":"98.8"}, {"price":"0.67", "size":"718.6"}, {"price":"0.66", "size":"798.4"}, {"price":"0.65", "size":"107.3"}, {"price":"0.64", "size":"293"}, {"price":"0.63", "size":"292.9"}, {"price":"0.62", "size":"297.7"}, {"price":"0.61", "size":"397.6"}, {"price":"0.6", "size":"356.93"}, {"price":"0.59", "size":"297.4"}, {"price":"0.58", "size":"109.6"}, {"price":"0.57", "size":"131.48"}, {"price":"0.56", "size":"413.97"}, {"price":"0.55", "size":"934.2"}, {"price":"0.54", "size":"375.6"}, {"price":"0.53", "size":"292"}, {"price":"0.52", "size":"297.12"}, {"price":"0.51", "size":"402"}, {"price":"0.5", "size":"340.91"}, {"price":"0.49", "size":"362"}, {"price":"0.48", "size":"317"}, {"price":"0.47", "size":"337"}, {"price":"0.46", "size":"607.1"}, {"price":"0.45", "size":"346.64"}, {"price":"0.44", "size":"341.45"}, {"price":"0.43", "size":"434.89"}, {"price":"0.42", "size":"324.36"}, {"price":"0.41", "size":"412.4"}, {"price":"0.4", "size":"328.83"}, {"price":"0.39", "size":"297.6"}, {"price":"0.38", "size":"636.5"}, {"price":"0.37", "size":"297.9"}, {"price":"0.36", "size":"208"}, {"price":"0.35", "size":"330.14"}, {"price":"0.34", "size":"330.9"}, {"price":"0.33", "size":"313.6"}, {"price":"0.32", "size":"2055.88"}, {"price":"0.31", "size":"409"}, {"price":"0.3", "size":"134.3"}, {"price":"0.29", "size":"316.38"}, {"price":"0.28", "size":"154.9"}, {"price":"0.27", "size":"180.2"}, {"price":"0.26", "size":"230.6"}, {"price":"0.25", "size":"331"}, {"price":"0.24", "size":"126.39"}, {"price":"0.23", "size":"121.89"}, {"price":"0.22", "size":"117.5"}, {"price":"0.21", "size":"175.44"}, {"price":"0.2", "size":"90"}, {"price":"0.19", "size":"67.35"}, {"price":"0.18", "size":"346.2"}, {"price":"0.17", "size":"105"}, {"price":"0.16", "size":"118.7"}, {"price":"0.15", "size":"46.53"}, {"price":"0.14", "size":"96.04"}], "hash":"7e7658027398b7feaf06a2bf9a27dad37a91a555", "timestamp":"1778784198099", "event_type":"book"}
{"market":"0x2a903c589141bce4a1e50fb98b73397af6820942542793ab10b1df477e912b6e", "asset_id":"68919878716222388542639225642064847629616106443780159680232863841946753372582", "price":"0.14", "size":"17.435713", "fee_rate_bps":"0", "side":"BUY", "timestamp":"1778784198166", "event_type":"last_trade_price", "transaction_hash":"0xac47f16a9b24e1b0f3d07ee76b597d053518e82ff3986747736a7b6a8cfab70c"}
{"market":"0x2a903c589141bce4a1e50fb98b73397af6820942542793ab10b1df477e912b6e", "price_changes":[{"asset_id":"68919878716222388542639225642064847629616106443780159680232863841946753372582", "price":"0.11", "size":"332.74", "side":"BUY", "hash":"212102256d963a5bc67d5801b9aa2deae8d7b247", "best_bid":"0.11", "best_ask":"0.14"}, {"asset_id":"20436996072316278452977393149218961565084965483366669504673105646378938504388", "price":"0.89", "size":"332.74", "side":"SELL", "hash":"81b5238f3457f21ac07ef79e2b3d1e364faec4d2", "best_bid":"0.86", "best_ask":"0.89"}], "timestamp":"1778784198136", "event_type":"price_change"}
{"market":"0x2a903c589141bce4a1e50fb98b73397af6820942542793ab10b1df477e912b6e", "asset_id":"68919878716222388542639225642064847629616106443780159680232863841946753372582", "bids":[{"price":"0.01", "size":"11330.74"}, {"price":"0.02", "size":"1462.32"}, {"price":"0.03", "size":"1105.78"}, {"price":"0.04", "size":"632.82"}, {"price":"0.05", "size":"755.72"}, {"price":"0.06", "size":"337.72"}, {"price":"0.07", "size":"357.1"}, {"price":"0.08", "size":"620.74"}, {"price":"0.09", "size":"286.11"}, {"price":"0.1", "size":"585.33"}, {"price":"0.11", "size":"332.74"}], "asks":[{"price":"0.99", "size":"12081.57"}, {"price":"0.98", "size":"1219.45"}, {"price":"0.97", "size":"1111.98"}, {"price":"0.96", "size":"670.05"}, {"price":"0.95", "size":"549.45"}, {"price":"0.94", "size":"346.2"}, {"price":"0.93", "size":"902.05"}, {"price":"0.92", "size":"170.79"}, {"price":"0.91", "size":"234.6"}, {"price":"0.9", "size":"128"}, {"price":"0.89", "size":"142.6"}, {"price":"0.88", "size":"141.8"}, {"price":"0.87", "size":"144.81"}, {"price":"0.86", "size":"204.9"}, {"price":"0.85", "size":"113.5"}, {"price":"0.84", "size":"102.3"}, {"price":"0.83", "size":"101.3"}, {"price":"0.82", "size":"105.3"}, {"price":"0.81", "size":"199.5"}, {"price":"0.8", "size":"103.8"}, {"price":"0.79", "size":"98.1"}, {"price":"0.78", "size":"97.5"}, {"price":"0.77", "size":"96.89"}, {"price":"0.76", "size":"201.39"}, {"price":"0.75", "size":"116"}, {"price":"0.74", "size":"100.6"}, {"price":"0.73", "size":"95.2"}, {"price":"0.72", "size":"94.9"}, {"price":"0.71", "size":"199.6"}, {"price":"0.7", "size":"94.3"}, {"price":"0.69", "size":"108.28"}, {"price":"0.68", "size":"98.8"}, {"price":"0.67", "size":"718.6"}, {"price":"0.66", "size":"798.4"}, {"price":"0.65", "size":"107.3"}, {"price":"0.64", "size":"293"}, {"price":"0.63", "size":"292.9"}, {"price":"0.62", "size":"297.7"}, {"price":"0.61", "size":"397.6"}, {"price":"0.6", "size":"356.93"}, {"price":"0.59", "size":"297.4"}, {"price":"0.58", "size":"109.6"}, {"price":"0.57", "size":"131.48"}, {"price":"0.56", "size":"413.97"}, {"price":"0.55", "size":"934.2"}, {"price":"0.54", "size":"375.6"}, {"price":"0.53", "size":"292"}, {"price":"0.52", "size":"297.12"}, {"price":"0.51", "size":"402"}, {"price":"0.5", "size":"340.91"}, {"price":"0.49", "size":"362"}, {"price":"0.48", "size":"317"}, {"price":"0.47", "size":"337"}, {"price":"0.46", "size":"607.1"}, {"price":"0.45", "size":"346.64"}, {"price":"0.44", "size":"341.45"}, {"price":"0.43", "size":"434.89"}, {"price":"0.42", "size":"324.36"}, {"price":"0.41", "size":"412.4"}, {"price":"0.4", "size":"328.83"}, {"price":"0.39", "size":"297.6"}, {"price":"0.38", "size":"636.5"}, {"price":"0.37", "size":"297.9"}, {"price":"0.36", "size":"208"}, {"price":"0.35", "size":"330.14"}, {"price":"0.34", "size":"330.9"}, {"price":"0.33", "size":"313.6"}, {"price":"0.32", "size":"2055.88"}, {"price":"0.31", "size":"409"}, {"price":"0.3", "size":"134.3"}, {"price":"0.29", "size":"316.38"}, {"price":"0.28", "size":"154.9"}, {"price":"0.27", "size":"180.2"}, {"price":"0.26", "size":"230.6"}, {"price":"0.25", "size":"331"}, {"price":"0.24", "size":"126.39"}, {"price":"0.23", "size":"121.89"}, {"price":"0.22", "size":"117.5"}, {"price":"0.21", "size":"175.44"}, {"price":"0.2", "size":"90"}, {"price":"0.19", "size":"67.35"}, {"price":"0.18", "size":"346.2"}, {"price":"0.17", "size":"105"}, {"price":"0.16", "size":"118.7"}, {"price":"0.15", "size":"46.53"}, {"price":"0.14", "size":"96.04"}], "hash":"212102256d963a5bc67d5801b9aa2deae8d7b247", "timestamp":"1778784198136", "event_type":"book"}
{"market":"0x2a903c589141bce4a1e50fb98b73397af6820942542793ab10b1df477e912b6e", "price_changes":[{"asset_id":"68919878716222388542639225642064847629616106443780159680232863841946753372582", "price":"0.1", "size":"625.33", "side":"BUY", "hash":"13269d26702fe26f3b10ff9ccfc31175ad1fadbb", "best_bid":"0.11", "best_ask":"0.14"}, {"asset_id":"20436996072316278452977393149218961565084965483366669504673105646378938504388", "price":"0.9", "size":"625.33", "side":"SELL", "hash":"f85fa0e4916c4a06130a7f773a36e7516c2a8d2c", "best_bid":"0.86", "best_ask":"0.89"}], "timestamp":"1778784198165", "event_type":"price_change"}
{"market":"0x2a903c589141bce4a1e50fb98b73397af6820942542793ab10b1df477e912b6e", "price_changes":[{"asset_id":"20436996072316278452977393149218961565084965483366669504673105646378938504388", "price":"0.92", "size":"674.73", "side":"SELL", "hash":"7fa23172bcca7dff30de4a16cd0d30bb3e2d659c", "best_bid":"0.86", "best_ask":"0.89"}, {"asset_id":"68919878716222388542639225642064847629616106443780159680232863841946753372582", "price":"0.08", "size":"674.73", "side":"BUY", "hash":"f5fb67418710b5bdd404b774f9ef5fcb47914f3b", "best_bid":"0.11", "best_ask":"0.14"}], "timestamp":"1778784198188", "event_type":"price_change"}
{"market":"0x2a903c589141bce4a1e50fb98b73397af6820942542793ab10b1df477e912b6e", "price_changes":[{"asset_id":"20436996072316278452977393149218961565084965483366669504673105646378938504388", "price":"0.85", "size":"15.07", "side":"BUY", "hash":"9d07dc7295e909241cf9ee0b41a0e15b25c9c029", "best_bid":"0.85", "best_ask":"0.89"}, {"asset_id":"68919878716222388542639225642064847629616106443780159680232863841946753372582", "price":"0.15", "size":"15.07", "side":"SELL", "hash":"800a74d628ea7c309ec5e65f5069541002d5d5b2", "best_bid":"0.11", "best_ask":"0.15"}], "timestamp":"1778784198256", "event_type":"price_change"}
{"market":"0x2a903c589141bce4a1e50fb98b73397af6820942542793ab10b1df477e912b6e", "price_changes":[{"asset_id":"20436996072316278452977393149218961565084965483366669504673105646378938504388", "price":"0.86", "size":"0", "side":"BUY", "hash":"9d07dc7295e909241cf9ee0b41a0e15b25c9c029", "best_bid":"0.85", "best_ask":"0.89"}, {"asset_id":"68919878716222388542639225642064847629616106443780159680232863841946753372582", "price":"0.14", "size":"0", "side":"SELL", "hash":"800a74d628ea7c309ec5e65f5069541002d5d5b2", "best_bid":"0.11", "best_ask":"0.15"}], "timestamp":"1778784198256", "event_type":"price_change"}
{"market":"0x2a903c589141bce4a1e50fb98b73397af6820942542793ab10b1df477e912b6e", "asset_id":"68919878716222388542639225642064847629616106443780159680232863841946753372582", "bids":[{"price":"0.01", "size":"11330.74"}, {"price":"0.02", "size":"1462.32"}, {"price":"0.03", "size":"1105.78"}, {"price":"0.04", "size":"632.82"}, {"price":"0.05", "size":"755.72"}, {"price":"0.06", "size":"337.72"}, {"price":"0.07", "size":"357.1"}, {"price":"0.08", "size":"674.73"}, {"price":"0.09", "size":"286.11"}, {"price":"0.1", "size":"625.33"}, {"price":"0.11", "size":"332.74"}], "asks":[{"price":"0.99", "size":"12081.57"}, {"price":"0.98", "size":"1219.45"}, {"price":"0.97", "size":"1111.98"}, {"price":"0.96", "size":"670.05"}, {"price":"0.95", "size":"549.45"}, {"price":"0.94", "size":"346.2"}, {"price":"0.93", "size":"902.05"}, {"price":"0.92", "size":"170.79"}, {"price":"0.91", "size":"234.6"}, {"price":"0.9", "size":"128"}, {"price":"0.89", "size":"142.6"}, {"price":"0.88", "size":"141.8"}, {"price":"0.87", "size":"144.81"}, {"price":"0.86", "size":"204.9"}, {"price":"0.85", "size":"113.5"}, {"price":"0.84", "size":"102.3"}, {"price":"0.83", "size":"101.3"}, {"price":"0.82", "size":"105.3"}, {"price":"0.81", "size":"199.5"}, {"price":"0.8", "size":"103.8"}, {"price":"0.79", "size":"98.1"}, {"price":"0.78", "size":"97.5"}, {"price":"0.77", "size":"96.89"}, {"price":"0.76", "size":"201.39"}, {"price":"0.75", "size":"116"}, {"price":"0.74", "size":"100.6"}, {"price":"0.73", "size":"95.2"}, {"price":"0.72", "size":"94.9"}, {"price":"0.71", "size":"199.6"}, {"price":"0.7", "size":"94.3"}, {"price":"0.69", "size":"108.28"}, {"price":"0.68", "size":"98.8"}, {"price":"0.67", "size":"718.6"}, {"price":"0.66", "size":"798.4"}, {"price":"0.65", "size":"107.3"}, {"price":"0.64", "size":"293"}, {"price":"0.63", "size":"292.9"}, {"price":"0.62", "size":"297.7"}, {"price":"0.61", "size":"397.6"}, {"price":"0.6", "size":"356.93"}, {"price":"0.59", "size":"297.4"}, {"price":"0.58", "size":"109.6"}, {"price":"0.57", "size":"131.48"}, {"price":"0.56", "size":"413.97"}, {"price":"0.55", "size":"934.2"}, {"price":"0.54", "size":"375.6"}, {"price":"0.53", "size":"292"}, {"price":"0.52", "size":"297.12"}, {"price":"0.51", "size":"402"}, {"price":"0.5", "size":"340.91"}, {"price":"0.49", "size":"362"}, {"price":"0.48", "size":"317"}, {"price":"0.47", "size":"337"}, {"price":"0.46", "size":"607.1"}, {"price":"0.45", "size":"346.64"}, {"price":"0.44", "size":"341.45"}, {"price":"0.43", "size":"434.89"}, {"price":"0.42", "size":"324.36"}, {"price":"0.41", "size":"412.4"}, {"price":"0.4", "size":"328.83"}, {"price":"0.39", "size":"297.6"}, {"price":"0.38", "size":"636.5"}, {"price":"0.37", "size":"297.9"}, {"price":"0.36", "size":"208"}, {"price":"0.35", "size":"330.14"}, {"price":"0.34", "size":"330.9"}, {"price":"0.33", "size":"313.6"}, {"price":"0.32", "size":"2055.88"}, {"price":"0.31", "size":"409"}, {"price":"0.3", "size":"134.3"}, {"price":"0.29", "size":"316.38"}, {"price":"0.28", "size":"154.9"}, {"price":"0.27", "size":"180.2"}, {"price":"0.26", "size":"230.6"}, {"price":"0.25", "size":"331"}, {"price":"0.24", "size":"126.39"}, {"price":"0.23", "size":"121.89"}, {"price":"0.22", "size":"117.5"}, {"price":"0.21", "size":"175.44"}, {"price":"0.2", "size":"90"}, {"price":"0.19", "size":"67.35"}, {"price":"0.18", "size":"346.2"}, {"price":"0.17", "size":"105"}, {"price":"0.16", "size":"118.7"}, {"price":"0.15", "size":"15.07"}], "hash":"800a74d628ea7c309ec5e65f5069541002d5d5b2", "timestamp":"1778784198256", "event_type":"book"}
{"market":"0x2a903c589141bce4a1e50fb98b73397af6820942542793ab10b1df477e912b6e", "price_changes":[{"asset_id":"68919878716222388542639225642064847629616106443780159680232863841946753372582", "price":"0.1", "size":"645.33", "side":"BUY", "hash":"da90b9265dadc61418e88721e4143b17cb6ba5e2", "best_bid":"0.11", "best_ask":"0.15"}, {"asset_id":"20436996072316278452977393149218961565084965483366669504673105646378938504388", "price":"0.9", "size":"645.33", "side":"SELL", "hash":"29a3bda2908ab4ecfd49ac7bf7d50bc5134967c6", "best_bid":"0.85", "best_ask":"0.89"}], "timestamp":"1778784198320", "event_type":"price_change"}
{"market":"0x2a903c589141bce4a1e50fb98b73397af6820942542793ab10b1df477e912b6e", "price_changes":[{"asset_id":"20436996072316278452977393149218961565084965483366669504673105646378938504388", "price":"0.35", "size":"107.3", "side":"BUY", "hash":"d17dcd648d6bb08f12a592ae51292f78e3e65d12", "best_bid":"0.85", "best_ask":"0.89"}, {"asset_id":"68919878716222388542639225642064847629616106443780159680232863841946753372582", "price":"0.65", "size":"107.3", "side":"SELL", "hash":"53b0b381d49f6949fdb911e47a86431f030e52af", "best_bid":"0.11", "best_ask":"0.15"}], "timestamp":"1778784198355", "event_type":"price_change"}
{"market":"0x2a903c589141bce4a1e50fb98b73397af6820942542793ab10b1df477e912b6e", "price_changes":[{"asset_id":"20436996072316278452977393149218961565084965483366669504673105646378938504388", "price":"0.34", "size":"798.4", "side":"BUY", "hash":"d17dcd648d6bb08f12a592ae51292f78e3e65d12", "best_bid":"0.85", "best_ask":"0.89"}, {"asset_id":"68919878716222388542639225642064847629616106443780159680232863841946753372582", "price":"0.66", "size":"798.4", "side":"SELL", "hash":"53b0b381d49f6949fdb911e47a86431f030e52af", "best_bid":"0.11", "best_ask":"0.15"}], "timestamp":"1778784198355", "event_type":"price_change"}
{"market":"0x2a903c589141bce4a1e50fb98b73397af6820942542793ab10b1df477e912b6e", "asset_id":"68919878716222388542639225642064847629616106443780159680232863841946753372582", "price":"0.14", "size":"127.5", "fee_rate_bps":"0", "side":"BUY", "timestamp":"1778784198366", "event_type":"last_trade_price", "transaction_hash":"0x55266a3f7d2cc9a8b48adc271d6fd6f66cf85830e9fa06b349ade864302f35c5"}
{"market":"0x2a903c589141bce4a1e50fb98b73397af6820942542793ab10b1df477e912b6e", "price_changes":[{"asset_id":"20436996072316278452977393149218961565084965483366669504673105646378938504388", "price":"0.84", "size":"117.7", "side":"BUY", "hash":"180d087c1e9e1c8051d1afc7468600fa8c9b3dd9", "best_bid":"0.84", "best_ask":"0.89"}, {"asset_id":"68919878716222388542639225642064847629616106443780159680232863841946753372582", "price":"0.16", "size":"117.7", "side":"SELL", "hash":"cd32f21da7807464fc902c34102482d1c61cbc6e", "best_bid":"0.11", "best_ask":"0.16"}], "timestamp":"1778784198367", "event_type":"price_change"}
{"market":"0x2a903c589141bce4a1e50fb98b73397af6820942542793ab10b1df477e912b6e", "price_changes":[{"asset_id":"20436996072316278452977393149218961565084965483366669504673105646378938504388", "price":"0.85", "size":"0", "side":"BUY", "hash":"180d087c1e9e1c8051d1afc7468600fa8c9b3dd9", "best_bid":"0.84", "best_ask":"0.89"}, {"asset_id":"68919878716222388542639225642064847629616106443780159680232863841946753372582", "price":"0.15", "size":"0", "side":"SELL", "hash":"cd32f21da7807464fc902c34102482d1c61cbc6e", "best_bid":"0.11", "best_ask":"0.16"}], "timestamp":"1778784198367", "event_type":"price_change"}
{"market":"0x2a903c589141bce4a1e50fb98b73397af6820942542793ab10b1df477e912b6e", "asset_id":"68919878716222388542639225642064847629616106443780159680232863841946753372582", "bids":[{"price":"0.01", "size":"11330.74"}, {"price":"0.02", "size":"1462.32"}, {"price":"0.03", "size":"1105.78"}, {"price":"0.04", "size":"632.82"}, {"price":"0.05", "size":"755.72"}, {"price":"0.06", "size":"337.72"}, {"price":"0.07", "size":"357.1"}, {"price":"0.08", "size":"674.73"}, {"price":"0.09", "size":"286.11"}, {"price":"0.1", "size":"645.33"}, {"price":"0.11", "size":"332.74"}], "asks":[{"price":"0.99", "size":"12081.57"}, {"price":"0.98", "size":"1219.45"}, {"price":"0.97", "size":"1111.98"}, {"price":"0.96", "size":"670.05"}, {"price":"0.95", "size":"549.45"}, {"price":"0.94", "size":"346.2"}, {"price":"0.93", "size":"902.05"}, {"price":"0.92", "size":"170.79"}, {"price":"0.91", "size":"234.6"}, {"price":"0.9", "size":"128"}, {"price":"0.89", "size":"142.6"}, {"price":"0.88", "size":"141.8"}, {"price":"0.87", "size":"144.81"}, {"price":"0.86", "size":"204.9"}, {"price":"0.85", "size":"113.5"}, {"price":"0.84", "size":"102.3"}, {"price":"0.83", "size":"101.3"}, {"price":"0.82", "size":"105.3"}, {"price":"0.81", "size":"199.5"}, {"price":"0.8", "size":"103.8"}, {"price":"0.79", "size":"98.1"}, {"price":"0.78", "size":"97.5"}, {"price":"0.77", "size":"96.89"}, {"price":"0.76", "size":"201.39"}, {"price":"0.75", "size":"116"}, {"price":"0.74", "size":"100.6"}, {"price":"0.73", "size":"95.2"}, {"price":"0.72", "size":"94.9"}, {"price":"0.71", "size":"199.6"}, {"price":"0.7", "size":"94.3"}, {"price":"0.69", "size":"108.28"}, {"price":"0.68", "size":"98.8"}, {"price":"0.67", "size":"718.6"}, {"price":"0.66", "size":"798.4"}, {"price":"0.65", "size":"107.3"}, {"price":"0.64", "size":"293"}, {"price":"0.63", "size":"292.9"}, {"price":"0.62", "size":"297.7"}, {"price":"0.61", "size":"397.6"}, {"price":"0.6", "size":"356.93"}, {"price":"0.59", "size":"297.4"}, {"price":"0.58", "size":"109.6"}, {"price":"0.57", "size":"131.48"}, {"price":"0.56", "size":"413.97"}, {"price":"0.55", "size":"934.2"}, {"price":"0.54", "size":"375.6"}, {"price":"0.53", "size":"292"}, {"price":"0.52", "size":"297.12"}, {"price":"0.51", "size":"402"}, {"price":"0.5", "size":"340.91"}, {"price":"0.49", "size":"362"}, {"price":"0.48", "size":"317"}, {"price":"0.47", "size":"337"}, {"price":"0.46", "size":"607.1"}, {"price":"0.45", "size":"346.64"}, {"price":"0.44", "size":"341.45"}, {"price":"0.43", "size":"434.89"}, {"price":"0.42", "size":"324.36"}, {"price":"0.41", "size":"412.4"}, {"price":"0.4", "size":"328.83"}, {"price":"0.39", "size":"297.6"}, {"price":"0.38", "size":"636.5"}, {"price":"0.37", "size":"297.9"}, {"price":"0.36", "size":"208"}, {"price":"0.35", "size":"330.14"}, {"price":"0.34", "size":"330.9"}, {"price":"0.33", "size":"313.6"}, {"price":"0.32", "size":"2055.88"}, {"price":"0.31", "size":"409"}, {"price":"0.3", "size":"134.3"}, {"price":"0.29", "size":"316.38"}, {"price":"0.28", "size":"154.9"}, {"price":"0.27", "size":"180.2"}, {"price":"0.26", "size":"230.6"}, {"price":"0.25", "size":"331"}, {"price":"0.24", "size":"126.39"}, {"price":"0.23", "size":"121.89"}, {"price":"0.22", "size":"117.5"}, {"price":"0.21", "size":"175.44"}, {"price":"0.2", "size":"90"}, {"price":"0.19", "size":"67.35"}, {"price":"0.18", "size":"346.2"}, {"price":"0.17", "size":"105"}, {"price":"0.16", "size":"117.7"}], "hash":"cd32f21da7807464fc902c34102482d1c61cbc6e", "timestamp":"1778784198367", "event_type":"book"}
{"market":"0x2a903c589141bce4a1e50fb98b73397af6820942542793ab10b1df477e912b6e", "price_changes":[{"asset_id":"68919878716222388542639225642064847629616106443780159680232863841946753372582", "price":"0.1", "size":"685.33", "side":"BUY", "hash":"ae1e73d94855f5767f2640a27d06d41db3bcff52", "best_bid":"0.11", "best_ask":"0.16"}, {"asset_id":"20436996072316278452977393149218961565084965483366669504673105646378938504388", "price":"0.9", "size":"685.33", "side":"SELL", "hash":"3c2f9e5dbbf30a4253927d062734ad95ec3f7e8f", "best_bid":"0.84", "best_ask":"0.89"}], "timestamp":"1778784198425", "event_type":"price_change"}
{"market":"0x2a903c589141bce4a1e50fb98b73397af6820942542793ab10b1df477e912b6e", "price_changes":[{"asset_id":"68919878716222388542639225642064847629616106443780159680232863841946753372582", "price":"0.11", "size":"341.74", "side":"BUY", "hash":"f71777b197f1d93c0fb262cf2d5d5d07f121abc0", "best_bid":"0.11", "best_ask":"0.16"}, {"asset_id":"20436996072316278452977393149218961565084965483366669504673105646378938504388", "price":"0.89", "size":"341.74", "side":"SELL", "hash":"00f393146a5065f55400548bb1907006995e4459", "best_bid":"0.84", "best_ask":"0.89"}], "timestamp":"1778784198439", "event_type":"price_change"}
{"market":"0x2a903c589141bce4a1e50fb98b73397af6820942542793ab10b1df477e912b6e", "asset_id":"68919878716222388542639225642064847629616106443780159680232863841946753372582", "price":"0.15", "size":"16.066875", "fee_rate_bps":"0", "side":"BUY", "timestamp":"1778784198472", "event_type":"last_trade_price", "transaction_hash":"0x96fa81cd1aa313b8d424fa16de8f124988e6f99de4ea9224519ef87c27283650"}
{"market":"0x2a903c589141bce4a1e50fb98b73397af6820942542793ab10b1df477e912b6e", "price_changes":[{"asset_id":"68919878716222388542639225642064847629616106443780159680232863841946753372582", "price":"0.35", "size":"335.14", "side":"SELL", "hash":"902f9a4d19f39ceb7aced868694c00238b669c31", "best_bid":"0.11", "best_ask":"0.16"}, {"asset_id":"20436996072316278452977393149218961565084965483366669504673105646378938504388", "price":"0.65", "size":"335.14", "side":"BUY", "hash":"792e6021a9c72164fc28bf19ea65e726eb4cae45", "best_bid":"0.84", "best_ask":"0.89"}], "timestamp":"1778784198450", "event_type":"price_change"}
{"market":"0x2a903c589141bce4a1e50fb98b73397af6820942542793ab10b1df477e912b6e", "price_changes":[{"asset_id":"20436996072316278452977393149218961565084965483366669504673105646378938504388", "price":"0.83", "size":"100", "side":"BUY", "hash":"ec6361108635f17f12f332100cbe87f9207877bd", "best_bid":"0.84", "best_ask":"0.89"}, {"asset_id":"68919878716222388542639225642064847629616106443780159680232863841946753372582", "price":"0.17", "size":"100", "side":"SELL", "hash":"9011e342a7da4c81d00d3654b0cedf8a9a46fa3e", "best_bid":"0.11", "best_ask":"0.16"}], "timestamp":"1778784198471", "event_type":"price_change"}
{"market":"0x2a903c589141bce4a1e50fb98b73397af6820942542793ab10b1df477e912b6e", "price_changes":[{"asset_id":"68919878716222388542639225642064847629616106443780159680232863841946753372582", "price":"0.11", "size":"346.74", "side":"BUY", "hash":"cba1e7a644eba1c7702ebf7bb52b66f61330e75d", "best_bid":"0.11", "best_ask":"0.16"}, {"asset_id":"20436996072316278452977393149218961565084965483366669504673105646378938504388", "price":"0.89", "size":"346.74", "side":"SELL", "hash":"5eed8df63d272b61c08890c22c9a13945b88b856", "best_bid":"0.84", "best_ask":"0.89"}], "timestamp":"1778784198475", "event_type":"price_change"}
{"market":"0x2a903c589141bce4a1e50fb98b73397af6820942542793ab10b1df477e912b6e", "price_changes":[{"asset_id":"68919878716222388542639225642064847629616106443780159680232863841946753372582", "price":"0.1", "size":"715.33", "side":"BUY", "hash":"23b225f104e5635deb1461dfe9fcc2c9aaabd972", "best_bid":"0.11", "best_ask":"0.16"}, {"asset_id":"20436996072316278452977393149218961565084965483366669504673105646378938504388", "price":"0.9", "size":"715.33", "side":"SELL", "hash":"dd5890629d863e3e33b0524237edfabcb4d9fcb1", "best_bid":"0.84", "best_ask":"0.89"}], "timestamp":"1778784198477", "event_type":"price_change"}
{"market":"0x2a903c589141bce4a1e50fb98b73397af6820942542793ab10b1df477e912b6e", "price_changes":[{"asset_id":"20436996072316278452977393149218961565084965483366669504673105646378938504388", "price":"0.84", "size":"107.7", "side":"BUY", "hash":"2b139971370903cafd1dfd6af3bfbcc8cee5cbdc", "best_bid":"0.84", "best_ask":"0.89"}, {"asset_id":"68919878716222388542639225642064847629616106443780159680232863841946753372582", "price":"0.16", "size":"107.7", "side":"SELL", "hash":"6d948fdaf658a0f8181fddf2ae093c8be2f39465", "best_bid":"0.11", "best_ask":"0.16"}], "timestamp":"1778784198584", "event_type":"price_change"}
{"market":"0x2a903c589141bce4a1e50fb98b73397af6820942542793ab10b1df477e912b6e", "asset_id":"68919878716222388542639225642064847629616106443780159680232863841946753372582", "bids":[{"price":"0.01", "size":"11330.74"}, {"price":"0.02", "size":"1462.32"}, {"price":"0.03", "size":"1105.78"}, {"price":"0.04", "size":"632.82"}, {"price":"0.05", "size":"755.72"}, {"price":"0.06", "size":"337.72"}, {"price":"0.07", "size":"357.1"}, {"price":"0.08", "size":"674.73"}, {"price":"0.09", "size":"286.11"}, {"price":"0.1", "size":"715.33"}, {"price":"0.11", "size":"346.74"}], "asks":[{"price":"0.99", "size":"12081.57"}, {"price":"0.98", "size":"1219.45"}, {"price":"0.97", "size":"1111.98"}, {"price":"0.96", "size":"670.05"}, {"price":"0.95", "size":"549.45"}, {"price":"0.94", "size":"346.2"}, {"price":"0.93", "size":"902.05"}, {"price":"0.92", "size":"170.79"}, {"price":"0.91", "size":"234.6"}, {"price":"0.9", "size":"128"}, {"price":"0.89", "size":"142.6"}, {"price":"0.88", "size":"141.8"}, {"price":"0.87", "size":"144.81"}, {"price":"0.86", "size":"204.9"}, {"price":"0.85", "size":"113.5"}, {"price":"0.84", "size":"102.3"}, {"price":"0.83", "size":"101.3"}, {"price":"0.82", "size":"105.3"}, {"price":"0.81", "size":"199.5"}, {"price":"0.8", "size":"103.8"}, {"price":"0.79", "size":"98.1"}, {"price":"0.78", "size":"97.5"}, {"price":"0.77", "size":"96.89"}, {"price":"0.76", "size":"201.39"}, {"price":"0.75", "size":"116"}, {"price":"0.74", "size":"100.6"}, {"price":"0.73", "size":"95.2"}, {"price":"0.72", "size":"94.9"}, {"price":"0.71", "size":"199.6"}, {"price":"0.7", "size":"94.3"}, {"price":"0.69", "size":"108.28"}, {"price":"0.68", "size":"98.8"}, {"price":"0.67", "size":"718.6"}, {"price":"0.66", "size":"798.4"}, {"price":"0.65", "size":"107.3"}, {"price":"0.64", "size":"293"}, {"price":"0.63", "size":"292.9"}, {"price":"0.62", "size":"297.7"}, {"price":"0.61", "size":"397.6"}, {"price":"0.6", "size":"356.93"}, {"price":"0.59", "size":"297.4"}, {"price":"0.58", "size":"109.6"}, {"price":"0.57", "size":"131.48"}, {"price":"0.56", "size":"413.97"}, {"price":"0.55", "size":"934.2"}, {"price":"0.54", "size":"375.6"}, {"price":"0.53", "size":"292"}, {"price":"0.52", "size":"297.12"}, {"price":"0.51", "size":"402"}, {"price":"0.5", "size":"340.91"}, {"price":"0.49", "size":"362"}, {"price":"0.48", "size":"317"}, {"price":"0.47", "size":"337"}, {"price":"0.46", "size":"607.1"}, {"price":"0.45", "size":"346.64"}, {"price":"0.44", "size":"341.45"}, {"price":"0.43", "size":"434.89"}, {"price":"0.42", "size":"324.36"}, {"price":"0.41", "size":"412.4"}, {"price":"0.4", "size":"328.83"}, {"price":"0.39", "size":"297.6"}, {"price":"0.38", "size":"636.5"}, {"price":"0.37", "size":"297.9"}, {"price":"0.36", "size":"208"}, {"price":"0.35", "size":"335.14"}, {"price":"0.34", "size":"330.9"}, {"price":"0.33", "size":"313.6"}, {"price":"0.32", "size":"2055.88"}, {"price":"0.31", "size":"409"}, {"price":"0.3", "size":"134.3"}, {"price":"0.29", "size":"316.38"}, {"price":"0.28", "size":"154.9"}, {"price":"0.27", "size":"180.2"}, {"price":"0.26", "size":"230.6"}, {"price":"0.25", "size":"331"}, {"price":"0.24", "size":"126.39"}, {"price":"0.23", "size":"121.89"}, {"price":"0.22", "size":"117.5"}, {"price":"0.21", "size":"175.44"}, {"price":"0.2", "size":"90"}, {"price":"0.19", "size":"67.35"}, {"price":"0.18", "size":"346.2"}, {"price":"0.17", "size":"100"}, {"price":"0.16", "size":"107.7"}], "hash":"6d948fdaf658a0f8181fddf2ae093c8be2f39465", "timestamp":"1778784198584", "event_type":"book"}
{"market":"0x2a903c589141bce4a1e50fb98b73397af6820942542793ab10b1df477e912b6e", "price_changes":[{"asset_id":"20436996072316278452977393149218961565084965483366669504673105646378938504388", "price":"0.65", "size":"340.14", "side":"BUY", "hash":"d4d17662758985aefde7d7d9084c12434183f30e", "best_bid":"0.84", "best_ask":"0.89"}, {"asset_id":"68919878716222388542639225642064847629616106443780159680232863841946753372582", "price":"0.35", "size":"340.14", "side":"SELL", "hash":"2a960665152d1ab3f8ffdb68da446763fb7c07fb", "best_bid":"0.11", "best_ask":"0.16"}], "timestamp":"1778784198597", "event_type":"price_change"}
{"market":"0x2a903c589141bce4a1e50fb98b73397af6820942542793ab10b1df477e912b6e", "price_changes":[{"asset_id":"68919878716222388542639225642064847629616106443780159680232863841946753372582", "price":"0.11", "size":"341.12", "side":"BUY", "hash":"70e047abf07529fe0be68c042bbbfc07934d1888", "best_bid":"0.11", "best_ask":"0.16"}, {"asset_id":"20436996072316278452977393149218961565084965483366669504673105646378938504388", "price":"0.89", "size":"341.12", "side":"SELL", "hash":"4ef3b5346c56b648d13728ea7aec9bd0b065913e", "best_bid":"0.84", "best_ask":"0.89"}], "timestamp":"1778784198638", "event_type":"price_change"}
{"market":"0x2a903c589141bce4a1e50fb98b73397af6820942542793ab10b1df477e912b6e", "asset_id":"68919878716222388542639225642064847629616106443780159680232863841946753372582", "bids":[{"price":"0.01", "size":"11330.74"}, {"price":"0.02", "size":"1462.32"}, {"price":"0.03", "size":"1105.78"}, {"price":"0.04", "size":"632.82"}, {"price":"0.05", "size":"755.72"}, {"price":"0.06", "size":"337.72"}, {"price":"0.07", "size":"357.1"}, {"price":"0.08", "size":"674.73"}, {"price":"0.09", "size":"286.11"}, {"price":"0.1", "size":"715.33"}, {"price":"0.11", "size":"341.12"}], "asks":[{"price":"0.99", "size":"12081.57"}, {"price":"0.98", "size":"1219.45"}, {"price":"0.97", "size":"1111.98"}, {"price":"0.96", "size":"670.05"}, {"price":"0.95", "size":"549.45"}, {"price":"0.94", "size":"346.2"}, {"price":"0.93", "size":"902.05"}, {"price":"0.92", "size":"170.79"}, {"price":"0.91", "size":"234.6"}, {"price":"0.9", "size":"128"}, {"price":"0.89", "size":"142.6"}, {"price":"0.88", "size":"141.8"}, {"price":"0.87", "size":"144.81"}, {"price":"0.86", "size":"204.9"}, {"price":"0.85", "size":"113.5"}, {"price":"0.84", "size":"102.3"}, {"price":"0.83", "size":"101.3"}, {"price":"0.82", "size":"105.3"}, {"price":"0.81", "size":"199.5"}, {"price":"0.8", "size":"103.8"}, {"price":"0.79", "size":"98.1"}, {"price":"0.78", "size":"97.5"}, {"price":"0.77", "size":"96.89"}, {"price":"0.76", "size":"201.39"}, {"price":"0.75", "size":"116"}, {"price":"0.74", "size":"100.6"}, {"price":"0.73", "size":"95.2"}, {"price":"0.72", "size":"94.9"}, {"price":"0.71", "size":"199.6"}, {"price":"0.7", "size":"94.3"}, {"price":"0.69", "size":"108.28"}, {"price":"0.68", "size":"98.8"}, {"price":"0.67", "size":"718.6"}, {"price":"0.66", "size":"798.4"}, {"price":"0.65", "size":"107.3"}, {"price":"0.64", "size":"293"}, {"price":"0.63", "size":"292.9"}, {"price":"0.62", "size":"297.7"}, {"price":"0.61", "size":"397.6"}, {"price":"0.6", "size":"356.93"}, {"price":"0.59", "size":"297.4"}, {"price":"0.58", "size":"109.6"}, {"price":"0.57", "size":"131.48"}, {"price":"0.56", "size":"413.97"}, {"price":"0.55", "size":"934.2"}, {"price":"0.54", "size":"375.6"}, {"price":"0.53", "size":"292"}, {"price":"0.52", "size":"297.12"}, {"price":"0.51", "size":"402"}, {"price":"0.5", "size":"340.91"}, {"price":"0.49", "size":"362"}, {"price":"0.48", "size":"317"}, {"price":"0.47", "size":"337"}, {"price":"0.46", "size":"607.1"}, {"price":"0.45", "size":"346.64"}, {"price":"0.44", "size":"341.45"}, {"price":"0.43", "size":"434.89"}, {"price":"0.42", "size":"324.36"}, {"price":"0.41", "size":"412.4"}, {"price":"0.4", "size":"328.83"}, {"price":"0.39", "size":"297.6"}, {"price":"0.38", "size":"636.5"}, {"price":"0.37", "size":"297.9"}, {"price":"0.36", "size":"208"}, {"price":"0.35", "size":"340.14"}, {"price":"0.34", "size":"330.9"}, {"price":"0.33", "size":"313.6"}, {"price":"0.32", "size":"2055.88"}, {"price":"0.31", "size":"409"}, {"price":"0.3", "size":"134.3"}, {"price":"0.29", "size":"316.38"}, {"price":"0.28", "size":"154.9"}, {"price":"0.27", "size":"180.2"}, {"price":"0.26", "size":"230.6"}, {"price":"0.25", "size":"331"}, {"price":"0.24", "size":"126.39"}, {"price":"0.23", "size":"121.89"}, {"price":"0.22", "size":"117.5"}, {"price":"0.21", "size":"175.44"}, {"price":"0.2", "size":"90"}, {"price":"0.19", "size":"67.35"}, {"price":"0.18", "size":"346.2"}, {"price":"0.17", "size":"100"}, {"price":"0.16", "size":"107.7"}], "hash":"70e047abf07529fe0be68c042bbbfc07934d1888", "timestamp":"1778784198638", "event_type":"book"}
{"market":"0x2a903c589141bce4a1e50fb98b73397af6820942542793ab10b1df477e912b6e", "asset_id":"68919878716222388542639225642064847629616106443780159680232863841946753372582", "price":"0.16", "size":"10", "fee_rate_bps":"0", "side":"BUY", "timestamp":"1778784198648", "event_type":"last_trade_price", "transaction_hash":"0x160401b688d87781c30f1d92850413655ce5d0623f443a8ad6333a350998aabd"}
{"market":"0x2a903c589141bce4a1e50fb98b73397af6820942542793ab10b1df477e912b6e", "price_changes":[{"asset_id":"68919878716222388542639225642064847629616106443780159680232863841946753372582", "price":"0.04", "size":"607.82", "side":"BUY", "hash":"ec0421249f90323c42a5eeec2726a367e7823bb8", "best_bid":"0.11", "best_ask":"0.16"}, {"asset_id":"20436996072316278452977393149218961565084965483366669504673105646378938504388", "price":"0.96", "size":"607.82", "side":"SELL", "hash":"8c328a0c6c4d57efac481d4eb95bda9ccaa88485", "best_bid":"0.84", "best_ask":"0.89"}], "timestamp":"1778784198668", "event_type":"price_change"}
{"market":"0x2a903c589141bce4a1e50fb98b73397af6820942542793ab10b1df477e912b6e", "price_changes":[{"asset_id":"68919878716222388542639225642064847629616106443780159680232863841946753372582", "price":"0.02", "size":"1437.32", "side":"BUY", "hash":"ec0421249f90323c42a5eeec2726a367e7823bb8", "best_bid":"0.11", "best_ask":"0.16"}, {"asset_id":"20436996072316278452977393149218961565084965483366669504673105646378938504388", "price":"0.98", "size":"1437.32", "side":"SELL", "hash":"8c328a0c6c4d57efac481d4eb95bda9ccaa88485", "best_bid":"0.84", "best_ask":"0.89"}], "timestamp":"1778784198668", "event_type":"price_change"}
{"market":"0x2a903c589141bce4a1e50fb98b73397af6820942542793ab10b1df477e912b6e", "price_changes":[{"asset_id":"20436996072316278452977393149218961565084965483366669504673105646378938504388", "price":"0.84", "size":"87.7", "side":"BUY", "hash":"f698a960fe52e241c897b7529bf61e6dc2c87168", "best_bid":"0.84", "best_ask":"0.89"}, {"asset_id":"68919878716222388542639225642064847629616106443780159680232863841946753372582", "price":"0.16", "size":"87.7", "side":"SELL", "hash":"fac2272e953b930064d62c78288ffd3f58bbbc8b", "best_bid":"0.11", "best_ask":"0.16"}], "timestamp":"1778784198728", "event_type":"price_change"}
{"market":"0x2a903c589141bce4a1e50fb98b73397af6820942542793ab10b1df477e912b6e", "asset_id":"68919878716222388542639225642064847629616106443780159680232863841946753372582", "bids":[{"price":"0.01", "size":"11330.74"}, {"price":"0.02", "size":"1437.32"}, {"price":"0.03", "size":"1105.78"}, {"price":"0.04", "size":"607.82"}, {"price":"0.05", "size":"755.72"}, {"price":"0.06", "size":"337.72"}, {"price":"0.07", "size":"357.1"}, {"price":"0.08", "size":"674.73"}, {"price":"0.09", "size":"286.11"}, {"price":"0.1", "size":"715.33"}, {"price":"0.11", "size":"341.12"}], "asks":[{"price":"0.99", "size":"12081.57"}, {"price":"0.98", "size":"1219.45"}, {"price":"0.97", "size":"1111.98"}, {"price":"0.96", "size":"670.05"}, {"price":"0.95", "size":"549.45"}, {"price":"0.94", "size":"346.2"}, {"price":"0.93", "size":"902.05"}, {"price":"0.92", "size":"170.79"}, {"price":"0.91", "size":"234.6"}, {"price":"0.9", "size":"128"}, {"price":"0.89", "size":"142.6"}, {"price":"0.88", "size":"141.8"}, {"price":"0.87", "size":"144.81"}, {"price":"0.86", "size":"204.9"}, {"price":"0.85", "size":"113.5"}, {"price":"0.84", "size":"102.3"}, {"price":"0.83", "size":"101.3"}, {"price":"0.82", "size":"105.3"}, {"price":"0.81", "size":"199.5"}, {"price":"0.8", "size":"103.8"}, {"price":"0.79", "size":"98.1"}, {"price":"0.78", "size":"97.5"}, {"price":"0.77", "size":"96.89"}, {"price":"0.76", "size":"201.39"}, {"price":"0.75", "size":"116"}, {"price":"0.74", "size":"100.6"}, {"price":"0.73", "size":"95.2"}, {"price":"0.72", "size":"94.9"}, {"price":"0.71", "size":"199.6"}, {"price":"0.7", "size":"94.3"}, {"price":"0.69", "size":"108.28"}, {"price":"0.68", "size":"98.8"}, {"price":"0.67", "size":"718.6"}, {"price":"0.66", "size":"798.4"}, {"price":"0.65", "size":"107.3"}, {"price":"0.64", "size":"293"}, {"price":"0.63", "size":"292.9"}, {"price":"0.62", "size":"297.7"}, {"price":"0.61", "size":"397.6"}, {"price":"0.6", "size":"356.93"}, {"price":"0.59", "size":"297.4"}, {"price":"0.58", "size":"109.6"}, {"price":"0.57", "size":"131.48"}, {"price":"0.56", "size":"413.97"}, {"price":"0.55", "size":"934.2"}, {"price":"0.54", "size":"375.6"}, {"price":"0.53", "size":"292"}, {"price":"0.52", "size":"297.12"}, {"price":"0.51", "size":"402"}, {"price":"0.5", "size":"340.91"}, {"price":"0.49", "size":"362"}, {"price":"0.48", "size":"317"}, {"price":"0.47", "size":"337"}, {"price":"0.46", "size":"607.1"}, {"price":"0.45", "size":"346.64"}, {"price":"0.44", "size":"341.45"}, {"price":"0.43", "size":"434.89"}, {"price":"0.42", "size":"324.36"}, {"price":"0.41", "size":"412.4"}, {"price":"0.4", "size":"328.83"}, {"price":"0.39", "size":"297.6"}, {"price":"0.38", "size":"636.5"}, {"price":"0.37", "size":"297.9"}, {"price":"0.36", "size":"208"}, {"price":"0.35", "size":"340.14"}, {"price":"0.34", "size":"330.9"}, {"price":"0.33", "size":"313.6"}, {"price":"0.32", "size":"2055.88"}, {"price":"0.31", "size":"409"}, {"price":"0.3", "size":"134.3"}, {"price":"0.29", "size":"316.38"}, {"price":"0.28", "size":"154.9"}, {"price":"0.27", "size":"180.2"}, {"price":"0.26", "size":"230.6"}, {"price":"0.25", "size":"331"}, {"price":"0.24", "size":"126.39"}, {"price":"0.23", "size":"121.89"}, {"price":"0.22", "size":"117.5"}, {"price":"0.21", "size":"175.44"}, {"price":"0.2", "size":"90"}, {"price":"0.19", "size":"67.35"}, {"price":"0.18", "size":"346.2"}, {"price":"0.17", "size":"100"}, {"price":"0.16", "size":"87.7"}], "hash":"fac2272e953b930064d62c78288ffd3f58bbbc8b", "timestamp":"1778784198728", "event_type":"book"}
{"market":"0x2a903c589141bce4a1e50fb98b73397af6820942542793ab10b1df477e912b6e", "price_changes":[{"asset_id":"20436996072316278452977393149218961565084965483366669504673105646378938504388", "price":"0.84", "size":"37.7", "side":"BUY", "hash":"45a3342a3ef5ec5a7ffa8a50994b34f88ebabab0", "best_bid":"0.84", "best_ask":"0.89"}, {"asset_id":"68919878716222388542639225642064847629616106443780159680232863841946753372582", "price":"0.16", "size":"37.7", "side":"SELL", "hash":"b71bbfd565983fa0579106b2296175dfe65bd1ec", "best_bid":"0.11", "best_ask":"0.16"}], "timestamp":"1778784198757", "event_type":"price_change"}
{"market":"0x2a903c589141bce4a1e50fb98b73397af6820942542793ab10b1df477e912b6e", "asset_id":"68919878716222388542639225642064847629616106443780159680232863841946753372582", "price":"0.16", "size":"20", "fee_rate_bps":"0", "side":"BUY", "timestamp":"1778784198775", "event_type":"last_trade_price", "transaction_hash":"0x9f8bc58a08d56c7172d160069ad001d03b6a817940cd2ec34257f77cc09889fc"}
{"market":"0x2a903c589141bce4a1e50fb98b73397af6820942542793ab10b1df477e912b6e", "price_changes":[{"asset_id":"20436996072316278452977393149218961565084965483366669504673105646378938504388", "price":"0.88", "size":"8", "side":"BUY", "hash":"5636c34d7726062cdca71163754c6837c5291bc4", "best_bid":"0.88", "best_ask":"0.89"}, {"asset_id":"68919878716222388542639225642064847629616106443780159680232863841946753372582", "price":"0.12", "size":"8", "side":"SELL", "hash":"196fb4725569de568ecc7779ea160b1004fd84ec", "best_bid":"0.11", "best_ask":"0.12"}], "timestamp":"1778784198770", "event_type":"price_change"}
{"market":"0x2a903c589141bce4a1e50fb98b73397af6820942542793ab10b1df477e912b6e", "price_changes":[{"asset_id":"20436996072316278452977393149218961565084965483366669504673105646378938504388", "price":"0.84", "size":"15.7", "side":"BUY", "hash":"41ee2ecf514f789d78b1e37f449a08dac3ae2482", "best_bid":"0.84", "best_ask":"0.89"}, {"asset_id":"68919878716222388542639225642064847629616106443780159680232863841946753372582", "price":"0.16", "size":"15.7", "side":"SELL", "hash":"e3332c1ed42a3666e959fe198f7f90cefa0138a1", "best_bid":"0.11", "best_ask":"0.16"}], "timestamp":"1778784198783", "event_type":"price_change"}
{"market":"0x2a903c589141bce4a1e50fb98b73397af6820942542793ab10b1df477e912b6e", "price_changes":[{"asset_id":"20436996072316278452977393149218961565084965483366669504673105646378938504388", "price":"0.88", "size":"0", "side":"BUY", "hash":"41ee2ecf514f789d78b1e37f449a08dac3ae2482", "best_bid":"0.84", "best_ask":"0.89"}, {"asset_id":"68919878716222388542639225642064847629616106443780159680232863841946753372582", "price":"0.12", "size":"0", "side":"SELL", "hash":"e3332c1ed42a3666e959fe198f7f90cefa0138a1", "best_bid":"0.11", "best_ask":"0.16"}], "timestamp":"1778784198783", "event_type":"price_change"}
{"market":"0x2a903c589141bce4a1e50fb98b73397af6820942542793ab10b1df477e912b6e", "asset_id":"68919878716222388542639225642064847629616106443780159680232863841946753372582", "bids":[{"price":"0.01", "size":"11330.74"}, {"price":"0.02", "size":"1437.32"}, {"price":"0.03", "size":"1105.78"}, {"price":"0.04", "size":"607.82"}, {"price":"0.05", "size":"755.72"}, {"price":"0.06", "size":"337.72"}, {"price":"0.07", "size":"357.1"}, {"price":"0.08", "size":"674.73"}, {"price":"0.09", "size":"286.11"}, {"price":"0.1", "size":"715.33"}, {"price":"0.11", "size":"341.12"}], "asks":[{"price":"0.99", "size":"12081.57"}, {"price":"0.98", "size":"1219.45"}, {"price":"0.97", "size":"1111.98"}, {"price":"0.96", "size":"670.05"}, {"price":"0.95", "size":"549.45"}, {"price":"0.94", "size":"346.2"}, {"price":"0.93", "size":"902.05"}, {"price":"0.92", "size":"170.79"}, {"price":"0.91", "size":"234.6"}, {"price":"0.9", "size":"128"}, {"price":"0.89", "size":"142.6"}, {"price":"0.88", "size":"141.8"}, {"price":"0.87", "size":"144.81"}, {"price":"0.86", "size":"204.9"}, {"price":"0.85", "size":"113.5"}, {"price":"0.84", "size":"102.3"}, {"price":"0.83", "size":"101.3"}, {"price":"0.82", "size":"105.3"}, {"price":"0.81", "size":"199.5"}, {"price":"0.8", "size":"103.8"}, {"price":"0.79", "size":"98.1"}, {"price":"0.78", "size":"97.5"}, {"price":"0.77", "size":"96.89"}, {"price":"0.76", "size":"201.39"}, {"price":"0.75", "size":"116"}, {"price":"0.74", "size":"100.6"}, {"price":"0.73", "size":"95.2"}, {"price":"0.72", "size":"94.9"}, {"price":"0.71", "size":"199.6"}, {"price":"0.7", "size":"94.3"}, {"price":"0.69", "size":"108.28"}, {"price":"0.68", "size":"98.8"}, {"price":"0.67", "size":"718.6"}, {"price":"0.66", "size":"798.4"}, {"price":"0.65", "size":"107.3"}, {"price":"0.64", "size":"293"}, {"price":"0.63", "size":"292.9"}, {"price":"0.62", "size":"297.7"}, {"price":"0.61", "size":"397.6"}, {"price":"0.6", "size":"356.93"}, {"price":"0.59", "size":"297.4"}, {"price":"0.58", "size":"109.6"}, {"price":"0.57", "size":"131.48"}, {"price":"0.56", "size":"413.97"}, {"price":"0.55", "size":"934.2"}, {"price":"0.54", "size":"375.6"}, {"price":"0.53", "size":"292"}, {"price":"0.52", "size":"297.12"}, {"price":"0.51", "size":"402"}, {"price":"0.5", "size":"340.91"}, {"price":"0.49", "size":"362"}, {"price":"0.48", "size":"317"}, {"price":"0.47", "size":"337"}, {"price":"0.46", "size":"607.1"}, {"price":"0.45", "size":"346.64"}, {"price":"0.44", "size":"341.45"}, {"price":"0.43", "size":"434.89"}, {"price":"0.42", "size":"324.36"}, {"price":"0.41", "size":"412.4"}, {"price":"0.4", "size":"328.83"}, {"price":"0.39", "size":"297.6"}, {"price":"0.38", "size":"636.5"}, {"price":"0.37", "size":"297.9"}, {"price":"0.36", "size":"208"}, {"price":"0.35", "size":"340.14"}, {"price":"0.34", "size":"330.9"}, {"price":"0.33", "size":"313.6"}, {"price":"0.32", "size":"2055.88"}, {"price":"0.31", "size":"409"}, {"price":"0.3", "size":"134.3"}, {"price":"0.29", "size":"316.38"}, {"price":"0.28", "size":"154.9"}, {"price":"0.27", "size":"180.2"}, {"price":"0.26", "size":"230.6"}, {"price":"0.25", "size":"331"}, {"price":"0.24", "size":"126.39"}, {"price":"0.23", "size":"121.89"}, {"price":"0.22", "size":"117.5"}, {"price":"0.21", "size":"175.44"}, {"price":"0.2", "size":"90"}, {"price":"0.19", "size":"67.35"}, {"price":"0.18", "size":"346.2"}, {"price":"0.17", "size":"100"}, {"price":"0.16", "size":"15.7"}], "hash":"e3332c1ed42a3666e959fe198f7f90cefa0138a1", "timestamp":"1778784198783", "event_type":"book"}
{"market":"0x2a903c589141bce4a1e50fb98b73397af6820942542793ab10b1df477e912b6e", "price_changes":[{"asset_id":"68919878716222388542639225642064847629616106443780159680232863841946753372582", "price":"0.11", "size":"355.12", "side":"BUY", "hash":"4943526f75cc47e6f795c464b3d1bd015681ccdb", "best_bid":"0.11", "best_ask":"0.16"}, {"asset_id":"20436996072316278452977393149218961565084965483366669504673105646378938504388", "price":"0.89", "size":"355.12", "side":"SELL", "hash":"4a9be295e8ab39e67be72361e5cf0bea4853a2d0", "best_bid":"0.84", "best_ask":"0.89"}], "timestamp":"1778784198787", "event_type":"price_change"}
{"market":"0x2a903c589141bce4a1e50fb98b73397af6820942542793ab10b1df477e912b6e", "asset_id":"68919878716222388542639225642064847629616106443780159680232863841946753372582", "price":"0.16", "size":"50", "fee_rate_bps":"0", "side":"BUY", "timestamp":"1778784198803", "event_type":"last_trade_price", "transaction_hash":"0xd80e51575e77fabbaf5c0f20c3b04731d9a3a4b865a845d30211afefc410adbb"}
{"market":"0x2a903c589141bce4a1e50fb98b73397af6820942542793ab10b1df477e912b6e", "price_changes":[{"asset_id":"20436996072316278452977393149218961565084965483366669504673105646378938504388", "price":"0.83", "size":"62.89", "side":"BUY", "hash":"fdb8b13f77860e9fd7e1da2b0e9958b0bc837465", "best_bid":"0.83", "best_ask":"0.89"}, {"asset_id":"68919878716222388542639225642064847629616106443780159680232863841946753372582", "price":"0.17", "size":"62.89", "side":"SELL", "hash":"afdc872128835b2f53a48e41efac7562134487d1", "best_bid":"0.11", "best_ask":"0.17"}], "timestamp":"1778784198799", "event_type":"price_change"}
{"market":"0x2a903c589141bce4a1e50fb98b73397af6820942542793ab10b1df477e912b6e", "price_changes":[{"asset_id":"20436996072316278452977393149218961565084965483366669504673105646378938504388", "price":"0.84", "size":"0", "side":"BUY", "hash":"fdb8b13f77860e9fd7e1da2b0e9958b0bc837465", "best_bid":"0.83", "best_ask":"0.89"}, {"asset_id":"68919878716222388542639225642064847629616106443780159680232863841946753372582", "price":"0.16", "size":"0", "side":"SELL", "hash":"afdc872128835b2f53a48e41efac7562134487d1", "best_bid":"0.11", "best_ask":"0.17"}], "timestamp":"1778784198799", "event_type":"price_change"}
{"market":"0x2a903c589141bce4a1e50fb98b73397af6820942542793ab10b1df477e912b6e", "asset_id":"68919878716222388542639225642064847629616106443780159680232863841946753372582", "bids":[{"price":"0.01", "size":"11330.74"}, {"price":"0.02", "size":"1437.32"}, {"price":"0.03", "size":"1105.78"}, {"price":"0.04", "size":"607.82"}, {"price":"0.05", "size":"755.72"}, {"price":"0.06", "size":"337.72"}, {"price":"0.07", "size":"357.1"}, {"price":"0.08", "size":"674.73"}, {"price":"0.09", "size":"286.11"}, {"price":"0.1", "size":"715.33"}, {"price":"0.11", "size":"355.12"}], "asks":[{"price":"0.99", "size":"12081.57"}, {"price":"0.98", "size":"1219.45"}, {"price":"0.97", "size":"1111.98"}, {"price":"0.96", "size":"670.05"}, {"price":"0.95", "size":"549.45"}, {"price":"0.94", "size":"346.2"}, {"price":"0.93", "size":"902.05"}, {"price":"0.92", "size":"170.79"}, {"price":"0.91", "size":"234.6"}, {"price":"0.9", "size":"128"}, {"price":"0.89", "size":"142.6"}, {"price":"0.88", "size":"141.8"}, {"price":"0.87", "size":"144.81"}, {"price":"0.86", "size":"204.9"}, {"price":"0.85", "size":"113.5"}, {"price":"0.84", "size":"102.3"}, {"price":"0.83", "size":"101.3"}, {"price":"0.82", "size":"105.3"}, {"price":"0.81", "size":"199.5"}, {"price":"0.8", "size":"103.8"}, {"price":"0.79", "size":"98.1"}, {"price":"0.78", "size":"97.5"}, {"price":"0.77", "size":"96.89"}, {"price":"0.76", "size":"201.39"}, {"price":"0.75", "size":"116"}, {"price":"0.74", "size":"100.6"}, {"price":"0.73", "size":"95.2"}, {"price":"0.72", "size":"94.9"}, {"price":"0.71", "size":"199.6"}, {"price":"0.7", "size":"94.3"}, {"price":"0.69", "size":"108.28"}, {"price":"0.68", "size":"98.8"}, {"price":"0.67", "size":"718.6"}, {"price":"0.66", "size":"798.4"}, {"price":"0.65", "size":"107.3"}, {"price":"0.64", "size":"293"}, {"price":"0.63", "size":"292.9"}, {"price":"0.62", "size":"297.7"}, {"price":"0.61", "size":"397.6"}, {"price":"0.6", "size":"356.93"}, {"price":"0.59", "size":"297.4"}, {"price":"0.58", "size":"109.6"}, {"price":"0.57", "size":"131.48"}, {"price":"0.56", "size":"413.97"}, {"price":"0.55", "size":"934.2"}, {"price":"0.54", "size":"375.6"}, {"price":"0.53", "size":"292"}, {"price":"0.52", "size":"297.12"}, {"price":"0.51", "size":"402"}, {"price":"0.5", "size":"340.91"}, {"price":"0.49", "size":"362"}, {"price":"0.48", "size":"317"}, {"price":"0.47", "size":"337"}, {"price":"0.46", "size":"607.1"}, {"price":"0.45", "size":"346.64"}, {"price":"0.44", "size":"341.45"}, {"price":"0.43", "size":"434.89"}, {"price":"0.42", "size":"324.36"}, {"price":"0.41", "size":"412.4"}, {"price":"0.4", "size":"328.83"}, {"price":"0.39", "size":"297.6"}, {"price":"0.38", "size":"636.5"}, {"price":"0.37", "size":"297.9"}, {"price":"0.36", "size":"208"}, {"price":"0.35", "size":"340.14"}, {"price":"0.34", "size":"330.9"}, {"price":"0.33", "size":"313.6"}, {"price":"0.32", "size":"2055.88"}, {"price":"0.31", "size":"409"}, {"price":"0.3", "size":"134.3"}, {"price":"0.29", "size":"316.38"}, {"price":"0.28", "size":"154.9"}, {"price":"0.27", "size":"180.2"}, {"price":"0.26", "size":"230.6"}, {"price":"0.25", "size":"331"}, {"price":"0.24", "size":"126.39"}, {"price":"0.23", "size":"121.89"}, {"price":"0.22", "size":"117.5"}, {"price":"0.21", "size":"175.44"}, {"price":"0.2", "size":"90"}, {"price":"0.19", "size":"67.35"}, {"price":"0.18", "size":"346.2"}, {"price":"0.17", "size":"62.89"}], "hash":"afdc872128835b2f53a48e41efac7562134487d1", "timestamp":"1778784198799", "event_type":"book"}
{"market":"0x2a903c589141bce4a1e50fb98b73397af6820942542793ab10b1df477e912b6e", "asset_id":"68919878716222388542639225642064847629616106443780159680232863841946753372582", "price":"0.15", "size":"30", "fee_rate_bps":"0", "side":"BUY", "timestamp":"1778784198810", "event_type":"last_trade_price", "transaction_hash":"0xdfaea1a81bc732e124b62d2c337993f60086da4c2f6d8df81f0cbe15161ae47f"}
{"market":"0x2a903c589141bce4a1e50fb98b73397af6820942542793ab10b1df477e912b6e", "price_changes":[{"asset_id":"68919878716222388542639225642064847629616106443780159680232863841946753372582", "price":"0.11", "size":"352.87", "side":"BUY", "hash":"c0c6a1982839648ab71d2eaed43c73e384e44db8", "best_bid":"0.11", "best_ask":"0.17"}, {"asset_id":"20436996072316278452977393149218961565084965483366669504673105646378938504388", "price":"0.89", "size":"352.87", "side":"SELL", "hash":"dd197c460cb32f90fcd4a6351144ee352b80e307", "best_bid":"0.83", "best_ask":"0.89"}], "timestamp":"1778784198820", "event_type":"price_change"}
{"market":"0x2a903c589141bce4a1e50fb98b73397af6820942542793ab10b1df477e912b6e", "price_changes":[{"asset_id":"68919878716222388542639225642064847629616106443780159680232863841946753372582", "price":"0.01", "size":"11325.74", "side":"BUY", "hash":"4604952941dafd2d5ea7e2f8ccd9d37da4f2fafc", "best_bid":"0.11", "best_ask":"0.17"}, {"asset_id":"20436996072316278452977393149218961565084965483366669504673105646378938504388", "price":"0.99", "size":"11325.74", "side":"SELL", "hash":"7c8ee98cff35fda5baa8b14ccc3c10f3b64a0f47", "best_bid":"0.83", "best_ask":"0.89"}], "timestamp":"1778784198824", "event_type":"price_change"}
{"market":"0x2a903c589141bce4a1e50fb98b73397af6820942542793ab10b1df477e912b6e", "asset_id":"68919878716222388542639225642064847629616106443780159680232863841946753372582", "bids":[{"price":"0.01", "size":"11325.74"}, {"price":"0.02", "size":"1437.32"}, {"price":"0.03", "size":"1105.78"}, {"price":"0.04", "size":"607.82"}, {"price":"0.05", "size":"755.72"}, {"price":"0.06", "size":"337.72"}, {"price":"0.07", "size":"357.1"}, {"price":"0.08", "size":"674.73"}, {"price":"0.09", "size":"286.11"}, {"price":"0.1", "size":"715.33"}, {"price":"0.11", "size":"352.87"}], "asks":[{"price":"0.99", "size":"12081.57"}, {"price":"0.98", "size":"1219.45"}, {"price":"0.97", "size":"1111.98"}, {"price":"0.96", "size":"670.05"}, {"price":"0.95", "size":"549.45"}, {"price":"0.94", "size":"346.2"}, {"price":"0.93", "size":"902.05"}, {"price":"0.92", "size":"170.79"}, {"price":"0.91", "size":"234.6"}, {"price":"0.9", "size":"128"}, {"price":"0.89", "size":"142.6"}, {"price":"0.88", "size":"141.8"}, {"price":"0.87", "size":"144.81"}, {"price":"0.86", "size":"204.9"}, {"price":"0.85", "size":"113.5"}, {"price":"0.84", "size":"102.3"}, {"price":"0.83", "size":"101.3"}, {"price":"0.82", "size":"105.3"}, {"price":"0.81", "size":"199.5"}, {"price":"0.8", "size":"103.8"}, {"price":"0.79", "size":"98.1"}, {"price":"0.78", "size":"97.5"}, {"price":"0.77", "size":"96.89"}, {"price":"0.76", "size":"201.39"}, {"price":"0.75", "size":"116"}, {"price":"0.74", "size":"100.6"}, {"price":"0.73", "size":"95.2"}, {"price":"0.72", "size":"94.9"}, {"price":"0.71", "size":"199.6"}, {"price":"0.7", "size":"94.3"}, {"price":"0.69", "size":"108.28"}, {"price":"0.68", "size":"98.8"}, {"price":"0.67", "size":"718.6"}, {"price":"0.66", "size":"798.4"}, {"price":"0.65", "size":"107.3"}, {"price":"0.64", "size":"293"}, {"price":"0.63", "size":"292.9"}, {"price":"0.62", "size":"297.7"}, {"price":"0.61", "size":"397.6"}, {"price":"0.6", "size":"356.93"}, {"price":"0.59", "size":"297.4"}, {"price":"0.58", "size":"109.6"}, {"price":"0.57", "size":"131.48"}, {"price":"0.56", "size":"413.97"}, {"price":"0.55", "size":"934.2"}, {"price":"0.54", "size":"375.6"}, {"price":"0.53", "size":"292"}, {"price":"0.52", "size":"297.12"}, {"price":"0.51", "size":"402"}, {"price":"0.5", "size":"340.91"}, {"price":"0.49", "size":"362"}, {"price":"0.48", "size":"317"}, {"price":"0.47", "size":"337"}, {"price":"0.46", "size":"607.1"}, {"price":"0.45", "size":"346.64"}, {"price":"0.44", "size":"341.45"}, {"price":"0.43", "size":"434.89"}, {"price":"0.42", "size":"324.36"}, {"price":"0.41", "size":"412.4"}, {"price":"0.4", "size":"328.83"}, {"price":"0.39", "size":"297.6"}, {"price":"0.38", "size":"636.5"}, {"price":"0.37", "size":"297.9"}, {"price":"0.36", "size":"208"}, {"price":"0.35", "size":"340.14"}, {"price":"0.34", "size":"330.9"}, {"price":"0.33", "size":"313.6"}, {"price":"0.32", "size":"2055.88"}, {"price":"0.31", "size":"409"}, {"price":"0.3", "size":"134.3"}, {"price":"0.29", "size":"316.38"}, {"price":"0.28", "size":"154.9"}, {"price":"0.27", "size":"180.2"}, {"price":"0.26", "size":"230.6"}, {"price":"0.25", "size":"331"}, {"price":"0.24", "size":"126.39"}, {"price":"0.23", "size":"121.89"}, {"price":"0.22", "size":"117.5"}, {"price":"0.21", "size":"175.44"}, {"price":"0.2", "size":"90"}, {"price":"0.19", "size":"67.35"}, {"price":"0.18", "size":"346.2"}, {"price":"0.17", "size":"62.89"}], "hash":"4604952941dafd2d5ea7e2f8ccd9d37da4f2fafc", "timestamp":"1778784198824", "event_type":"book"}
{"market":"0x2a903c589141bce4a1e50fb98b73397af6820942542793ab10b1df477e912b6e", "price_changes":[{"asset_id":"20436996072316278452977393149218961565084965483366669504673105646378938504388", "price":"0.83", "size":"12.89", "side":"BUY", "hash":"cda32810c0c806af252470373a41d93b475b4a6a", "best_bid":"0.83", "best_ask":"0.89"}, {"asset_id":"68919878716222388542639225642064847629616106443780159680232863841946753372582", "price":"0.17", "size":"12.89", "side":"SELL", "hash":"80f7af6334d6e05d522d71df2a12fc439c6618bb", "best_bid":"0.11", "best_ask":"0.17"}], "timestamp":"1778784198828", "event_type":"price_change"}
{"market":"0x2a903c589141bce4a1e50fb98b73397af6820942542793ab10b1df477e912b6e", "asset_id":"68919878716222388542639225642064847629616106443780159680232863841946753372582", "bids":[{"price":"0.01", "size":"11325.74"}, {"price":"0.02", "size":"1437.32"}, {"price":"0.03", "size":"1105.78"}, {"price":"0.04", "size":"607.82"}, {"price":"0.05", "size":"755.72"}, {"price":"0.06", "size":"337.72"}, {"price":"0.07", "size":"357.1"}, {"price":"0.08", "size":"674.73"}, {"price":"0.09", "size":"286.11"}, {"price":"0.1", "size":"715.33"}, {"price":"0.11", "size":"352.87"}], "asks":[{"price":"0.99", "size":"12081.57"}, {"price":"0.98", "size":"1219.45"}, {"price":"0.97", "size":"1111.98"}, {"price":"0.96", "size":"670.05"}, {"price":"0.95", "size":"549.45"}, {"price":"0.94", "size":"346.2"}, {"price":"0.93", "size":"902.05"}, {"price":"0.92", "size":"170.79"}, {"price":"0.91", "size":"234.6"}, {"price":"0.9", "size":"128"}, {"price":"0.89", "size":"142.6"}, {"price":"0.88", "size":"141.8"}, {"price":"0.87", "size":"144.81"}, {"price":"0.86", "size":"204.9"}, {"price":"0.85", "size":"113.5"}, {"price":"0.84", "size":"102.3"}, {"price":"0.83", "size":"101.3"}, {"price":"0.82", "size":"105.3"}, {"price":"0.81", "size":"199.5"}, {"price":"0.8", "size":"103.8"}, {"price":"0.79", "size":"98.1"}, {"price":"0.78", "size":"97.5"}, {"price":"0.77", "size":"96.89"}, {"price":"0.76", "size":"201.39"}, {"price":"0.75", "size":"116"}, {"price":"0.74", "size":"100.6"}, {"price":"0.73", "size":"95.2"}, {"price":"0.72", "size":"94.9"}, {"price":"0.71", "size":"199.6"}, {"price":"0.7", "size":"94.3"}, {"price":"0.69", "size":"108.28"}, {"price":"0.68", "size":"98.8"}, {"price":"0.67", "size":"718.6"}, {"price":"0.66", "size":"798.4"}, {"price":"0.65", "size":"107.3"}, {"price":"0.64", "size":"293"}, {"price":"0.63", "size":"292.9"}, {"price":"0.62", "size":"297.7"}, {"price":"0.61", "size":"397.6"}, {"price":"0.6", "size":"356.93"}, {"price":"0.59", "size":"297.4"}, {"price":"0.58", "size":"109.6"}, {"price":"0.57", "size":"131.48"}, {"price":"0.56", "size":"413.97"}, {"price":"0.55", "size":"934.2"}, {"price":"0.54", "size":"375.6"}, {"price":"0.53", "size":"292"}, {"price":"0.52", "size":"297.12"}, {"price":"0.51", "size":"402"}, {"price":"0.5", "size":"340.91"}, {"price":"0.49", "size":"362"}, {"price":"0.48", "size":"317"}, {"price":"0.47", "size":"337"}, {"price":"0.46", "size":"607.1"}, {"price":"0.45", "size":"346.64"}, {"price":"0.44", "size":"341.45"}, {"price":"0.43", "size":"434.89"}, {"price":"0.42", "size":"324.36"}, {"price":"0.41", "size":"412.4"}, {"price":"0.4", "size":"328.83"}, {"price":"0.39", "size":"297.6"}, {"price":"0.38", "size":"636.5"}, {"price":"0.37", "size":"297.9"}, {"price":"0.36", "size":"208"}, {"price":"0.35", "size":"340.14"}, {"price":"0.34", "size":"330.9"}, {"price":"0.33", "size":"313.6"}, {"price":"0.32", "size":"2055.88"}, {"price":"0.31", "size":"409"}, {"price":"0.3", "size":"134.3"}, {"price":"0.29", "size":"316.38"}, {"price":"0.28", "size":"154.9"}, {"price":"0.27", "size":"180.2"}, {"price":"0.26", "size":"230.6"}, {"price":"0.25", "size":"331"}, {"price":"0.24", "size":"126.39"}, {"price":"0.23", "size":"121.89"}, {"price":"0.22", "size":"117.5"}, {"price":"0.21", "size":"175.44"}, {"price":"0.2", "size":"90"}, {"price":"0.19", "size":"67.35"}, {"price":"0.18", "size":"346.2"}, {"price":"0.17", "size":"12.89"}], "hash":"80f7af6334d6e05d522d71df2a12fc439c6618bb", "timestamp":"1778784198828", "event_type":"book"}
{"market":"0x2a903c589141bce4a1e50fb98b73397af6820942542793ab10b1df477e912b6e", "price_changes":[{"asset_id":"20436996072316278452977393149218961565084965483366669504673105646378938504388", "price":"0.01", "size":"12086.57", "side":"BUY", "hash":"8c722bac93c1007d30afd3b5909ce219b534f573", "best_bid":"0.83", "best_ask":"0.89"}, {"asset_id":"68919878716222388542639225642064847629616106443780159680232863841946753372582", "price":"0.99", "size":"12086.57", "side":"SELL", "hash":"946a68324cbdf1f6522feaf4f42e0578d752a918", "best_bid":"0.11", "best_ask":"0.17"}], "timestamp":"1778784198836", "event_type":"price_change"}
{"market":"0x2a903c589141bce4a1e50fb98b73397af6820942542793ab10b1df477e912b6e", "price_changes":[{"asset_id":"20436996072316278452977393149218961565084965483366669504673105646378938504388", "price":"0.56", "size":"332.45", "side":"BUY", "hash":"a58fa995e8996df8827a65104305e01cb0b40693", "best_bid":"0.83", "best_ask":"0.89"}, {"asset_id":"68919878716222388542639225642064847629616106443780159680232863841946753372582", "price":"0.44", "size":"332.45", "side":"SELL", "hash":"e29754c18a323ea1ca5913adbd1ad8985389ee2a", "best_bid":"0.11", "best_ask":"0.17"}], "timestamp":"1778784198839", "event_type":"price_change"}
{"market":"0x2a903c589141bce4a1e50fb98b73397af6820942542793ab10b1df477e912b6e", "price_changes":[{"asset_id":"20436996072316278452977393149218961565084965483366669504673105646378938504388", "price":"0.62", "size":"626.5", "side":"BUY", "hash":"c7c2530b5a61002a8e414e559c9a86ce27cdfc6c", "best_bid":"0.83", "best_ask":"0.89"}, {"asset_id":"68919878716222388542639225642064847629616106443780159680232863841946753372582", "price":"0.38", "size":"626.5", "side":"SELL", "hash":"d02c787b868d02eb4b4cd1c56d76b16d6fa222cb", "best_bid":"0.11", "best_ask":"0.17"}], "timestamp":"1778784198846", "event_type":"price_change"}
{"market":"0x2a903c589141bce4a1e50fb98b73397af6820942542793ab10b1df477e912b6e", "asset_id":"68919878716222388542639225642064847629616106443780159680232863841946753372582", "price":"0.17", "size":"52.805881", "fee_rate_bps":"0", "side":"BUY", "timestamp":"1778784198853", "event_type":"last_trade_price", "transaction_hash":"0x494ca06d14ff34304a23f57aaa22136954f363698dcb8ab5587a22c245aeb7b0"}
{"market":"0x2a903c589141bce4a1e50fb98b73397af6820942542793ab10b1df477e912b6e", "asset_id":"68919878716222388542639225642064847629616106443780159680232863841946753372582", "price":"0.17", "size":"50", "fee_rate_bps":"0", "side":"BUY", "timestamp":"1778784198856", "event_type":"last_trade_price", "transaction_hash":"0x41709dd4ebf53a558e3477f6df83d7a67b8b25bf51bafe072f7c19cd1914adec"}
{"market":"0x2a903c589141bce4a1e50fb98b73397af6820942542793ab10b1df477e912b6e", "price_changes":[{"asset_id":"68919878716222388542639225642064847629616106443780159680232863841946753372582", "price":"0.11", "size":"324.78", "side":"BUY", "hash":"ef4c6ba7eec8f9632cacf9b30b30f2e432ccef35", "best_bid":"0.11", "best_ask":"0.17"}, {"asset_id":"20436996072316278452977393149218961565084965483366669504673105646378938504388", "price":"0.89", "size":"324.78", "side":"SELL", "hash":"bea2057c6cb40c2f5d130dc197767d0ca458d3a0", "best_bid":"0.83", "best_ask":"0.89"}], "timestamp":"1778784198858", "event_type":"price_change"}
{"market":"0x2a903c589141bce4a1e50fb98b73397af6820942542793ab10b1df477e912b6e", "asset_id":"68919878716222388542639225642064847629616106443780159680232863841946753372582", "bids":[{"price":"0.01", "size":"11325.74"}, {"price":"0.02", "size":"1437.32"}, {"price":"0.03", "size":"1105.78"}, {"price":"0.04", "size":"607.82"}, {"price":"0.05", "size":"755.72"}, {"price":"0.06", "size":"337.72"}, {"price":"0.07", "size":"357.1"}, {"price":"0.08", "size":"674.73"}, {"price":"0.09", "size":"286.11"}, {"price":"0.1", "size":"715.33"}, {"price":"0.11", "size":"324.78"}], "asks":[{"price":"0.99", "size":"12086.57"}, {"price":"0.98", "size":"1219.45"}, {"price":"0.97", "size":"1111.98"}, {"price":"0.96", "size":"670.05"}, {"price":"0.95", "size":"549.45"}, {"price":"0.94", "size":"346.2"}, {"price":"0.93", "size":"902.05"}, {"price":"0.92", "size":"170.79"}, {"price":"0.91", "size":"234.6"}, {"price":"0.9", "size":"128"}, {"price":"0.89", "size":"142.6"}, {"price":"0.88", "size":"141.8"}, {"price":"0.87", "size":"144.81"}, {"price":"0.86", "size":"204.9"}, {"price":"0.85", "size":"113.5"}, {"price":"0.84", "size":"102.3"}, {"price":"0.83", "size":"101.3"}, {"price":"0.82", "size":"105.3"}, {"price":"0.81", "size":"199.5"}, {"price":"0.8", "size":"103.8"}, {"price":"0.79", "size":"98.1"}, {"price":"0.78", "size":"97.5"}, {"price":"0.77", "size":"96.89"}, {"price":"0.76", "size":"201.39"}, {"price":"0.75", "size":"116"}, {"price":"0.74", "size":"100.6"}, {"price":"0.73", "size":"95.2"}, {"price":"0.72", "size":"94.9"}, {"price":"0.71", "size":"199.6"}, {"price":"0.7", "size":"94.3"}, {"price":"0.69", "size":"108.28"}, {"price":"0.68", "size":"98.8"}, {"price":"0.67", "size":"718.6"}, {"price":"0.66", "size":"798.4"}, {"price":"0.65", "size":"107.3"}, {"price":"0.64", "size":"293"}, {"price":"0.63", "size":"292.9"}, {"price":"0.62", "size":"297.7"}, {"price":"0.61", "size":"397.6"}, {"price":"0.6", "size":"356.93"}, {"price":"0.59", "size":"297.4"}, {"price":"0.58", "size":"109.6"}, {"price":"0.57", "size":"131.48"}, {"price":"0.56", "size":"413.97"}, {"price":"0.55", "size":"934.2"}, {"price":"0.54", "size":"375.6"}, {"price":"0.53", "size":"292"}, {"price":"0.52", "size":"297.12"}, {"price":"0.51", "size":"402"}, {"price":"0.5", "size":"340.91"}, {"price":"0.49", "size":"362"}, {"price":"0.48", "size":"317"}, {"price":"0.47", "size":"337"}, {"price":"0.46", "size":"607.1"}, {"price":"0.45", "size":"346.64"}, {"price":"0.44", "size":"332.45"}, {"price":"0.43", "size":"434.89"}, {"price":"0.42", "size":"324.36"}, {"price":"0.41", "size":"412.4"}, {"price":"0.4", "size":"328.83"}, {"price":"0.39", "size":"297.6"}, {"price":"0.38", "size":"626.5"}, {"price":"0.37", "size":"297.9"}, {"price":"0.36", "size":"208"}, {"price":"0.35", "size":"340.14"}, {"price":"0.34", "size":"330.9"}, {"price":"0.33", "size":"313.6"}, {"price":"0.32", "size":"2055.88"}, {"price":"0.31", "size":"409"}, {"price":"0.3", "size":"134.3"}, {"price":"0.29", "size":"316.38"}, {"price":"0.28", "size":"154.9"}, {"price":"0.27", "size":"180.2"}, {"price":"0.26", "size":"230.6"}, {"price":"0.25", "size":"331"}, {"price":"0.24", "size":"126.39"}, {"price":"0.23", "size":"121.89"}, {"price":"0.22", "size":"117.5"}, {"price":"0.21", "size":"175.44"}, {"price":"0.2", "size":"90"}, {"price":"0.19", "size":"67.35"}, {"price":"0.18", "size":"346.2"}, {"price":"0.17", "size":"12.89"}], "hash":"ef4c6ba7eec8f9632cacf9b30b30f2e432ccef35", "timestamp":"1778784198858", "event_type":"book"}
{"market":"0x2a903c589141bce4a1e50fb98b73397af6820942542793ab10b1df477e912b6e", "price_changes":[{"asset_id":"20436996072316278452977393149218961565084965483366669504673105646378938504388", "price":"0.81", "size":"72.35", "side":"BUY", "hash":"91d9f267487c849b2f234b9be93aa6b5919f3906", "best_bid":"0.83", "best_ask":"0.89"}, {"asset_id":"68919878716222388542639225642064847629616106443780159680232863841946753372582", "price":"0.19", "size":"72.35", "side":"SELL", "hash":"afae684c796725ac640a2ea79262038eaa0ef462", "best_bid":"0.11", "best_ask":"0.17"}], "timestamp":"1778784198879", "event_type":"price_change"}
{"market":"0x2a903c589141bce4a1e50fb98b73397af6820942542793ab10b1df477e912b6e", "price_changes":[{"asset_id":"20436996072316278452977393149218961565084965483366669504673105646378938504388", "price":"0.82", "size":"337.54", "side":"BUY", "hash":"19a4fca9def1ec2979d79fae12b6c700a7cdb052", "best_bid":"0.82", "best_ask":"0.89"}, {"asset_id":"68919878716222388542639225642064847629616106443780159680232863841946753372582", "price":"0.18", "size":"337.54", "side":"SELL", "hash":"656b7d816cc48c6bdfb86d91ea966b756965b331", "best_bid":"0.11", "best_ask":"0.18"}], "timestamp":"1778784199070", "event_type":"price_change"}
{"market":"0x2a903c589141bce4a1e50fb98b73397af6820942542793ab10b1df477e912b6e", "price_changes":[{"asset_id":"20436996072316278452977393149218961565084965483366669504673105646378938504388", "price":"0.83", "size":"0", "side":"BUY", "hash":"19a4fca9def1ec2979d79fae12b6c700a7cdb052", "best_bid":"0.82", "best_ask":"0.89"}, {"asset_id":"68919878716222388542639225642064847629616106443780159680232863841946753372582", "price":"0.17", "size":"0", "side":"SELL", "hash":"656b7d816cc48c6bdfb86d91ea966b756965b331", "best_bid":"0.11", "best_ask":"0.18"}], "timestamp":"1778784199070", "event_type":"price_change"}
{"market":"0x2a903c589141bce4a1e50fb98b73397af6820942542793ab10b1df477e912b6e", "asset_id":"68919878716222388542639225642064847629616106443780159680232863841946753372582", "bids":[{"price":"0.01", "size":"11325.74"}, {"price":"0.02", "size":"1437.32"}, {"price":"0.03", "size":"1105.78"}, {"price":"0.04", "size":"607.82"}, {"price":"0.05", "size":"755.72"}, {"price":"0.06", "size":"337.72"}, {"price":"0.07", "size":"357.1"}, {"price":"0.08", "size":"674.73"}, {"price":"0.09", "size":"286.11"}, {"price":"0.1", "size":"715.33"}, {"price":"0.11", "size":"324.78"}], "asks":[{"price":"0.99", "size":"12086.57"}, {"price":"0.98", "size":"1219.45"}, {"price":"0.97", "size":"1111.98"}, {"price":"0.96", "size":"670.05"}, {"price":"0.95", "size":"549.45"}, {"price":"0.94", "size":"346.2"}, {"price":"0.93", "size":"902.05"}, {"price":"0.92", "size":"170.79"}, {"price":"0.91", "size":"234.6"}, {"price":"0.9", "size":"128"}, {"price":"0.89", "size":"142.6"}, {"price":"0.88", "size":"141.8"}, {"price":"0.87", "size":"144.81"}, {"price":"0.86", "size":"204.9"}, {"price":"0.85", "size":"113.5"}, {"price":"0.84", "size":"102.3"}, {"price":"0.83", "size":"101.3"}, {"price":"0.82", "size":"105.3"}, {"price":"0.81", "size":"199.5"}, {"price":"0.8", "size":"103.8"}, {"price":"0.79", "size":"98.1"}, {"price":"0.78", "size":"97.5"}, {"price":"0.77", "size":"96.89"}, {"price":"0.76", "size":"201.39"}, {"price":"0.75", "size":"116"}, {"price":"0.74", "size":"100.6"}, {"price":"0.73", "size":"95.2"}, {"price":"0.72", "size":"94.9"}, {"price":"0.71", "size":"199.6"}, {"price":"0.7", "size":"94.3"}, {"price":"0.69", "size":"108.28"}, {"price":"0.68", "size":"98.8"}, {"price":"0.67", "size":"718.6"}, {"price":"0.66", "size":"798.4"}, {"price":"0.65", "size":"107.3"}, {"price":"0.64", "size":"293"}, {"price":"0.63", "size":"292.9"}, {"price":"0.62", "size":"297.7"}, {"price":"0.61", "size":"397.6"}, {"price":"0.6", "size":"356.93"}, {"price":"0.59", "size":"297.4"}, {"price":"0.58", "size":"109.6"}, {"price":"0.57", "size":"131.48"}, {"price":"0.56", "size":"413.97"}, {"price":"0.55", "size":"934.2"}, {"price":"0.54", "size":"375.6"}, {"price":"0.53", "size":"292"}, {"price":"0.52", "size":"297.12"}, {"price":"0.51", "size":"402"}, {"price":"0.5", "size":"340.91"}, {"price":"0.49", "size":"362"}, {"price":"0.48", "size":"317"}, {"price":"0.47", "size":"337"}, {"price":"0.46", "size":"607.1"}, {"price":"0.45", "size":"346.64"}, {"price":"0.44", "size":"332.45"}, {"price":"0.43", "size":"434.89"}, {"price":"0.42", "size":"324.36"}, {"price":"0.41", "size":"412.4"}, {"price":"0.4", "size":"328.83"}, {"price":"0.39", "size":"297.6"}, {"price":"0.38", "size":"626.5"}, {"price":"0.37", "size":"297.9"}, {"price":"0.36", "size":"208"}, {"price":"0.35", "size":"340.14"}, {"price":"0.34", "size":"330.9"}, {"price":"0.33", "size":"313.6"}, {"price":"0.32", "size":"2055.88"}, {"price":"0.31", "size":"409"}, {"price":"0.3", "size":"134.3"}, {"price":"0.29", "size":"316.38"}, {"price":"0.28", "size":"154.9"}, {"price":"0.27", "size":"180.2"}, {"price":"0.26", "size":"230.6"}, {"price":"0.25", "size":"331"}, {"price":"0.24", "size":"126.39"}, {"price":"0.23", "size":"121.89"}, {"price":"0.22", "size":"117.5"}, {"price":"0.21", "size":"175.44"}, {"price":"0.2", "size":"90"}, {"price":"0.19", "size":"72.35"}, {"price":"0.18", "size":"337.54"}], "hash":"656b7d816cc48c6bdfb86d91ea966b756965b331", "timestamp":"1778784199070", "event_type":"book"}
{"market":"0x2a903c589141bce4a1e50fb98b73397af6820942542793ab10b1df477e912b6e", "price_changes":[{"asset_id":"68919878716222388542639225642064847629616106443780159680232863841946753372582", "price":"0.16", "size":"8.85", "side":"BUY", "hash":"8c1d8a8b2d901080c6cfc384533c8bc21077150f", "best_bid":"0.16", "best_ask":"0.18"}, {"asset_id":"20436996072316278452977393149218961565084965483366669504673105646378938504388", "price":"0.84", "size":"8.85", "side":"SELL", "hash":"36d3003bfbde5a7e351865f25e9482ea6f91aa89", "best_bid":"0.82", "best_ask":"0.84"}], "timestamp":"1778784199085", "event_type":"price_change"}
{"market":"0x2a903c589141bce4a1e50fb98b73397af6820942542793ab10b1df477e912b6e", "asset_id":"68919878716222388542639225642064847629616106443780159680232863841946753372582", "price":"0.17", "size":"21.549443", "fee_rate_bps":"0", "side":"BUY", "timestamp":"1778784199110", "event_type":"last_trade_price", "transaction_hash":"0x6bfec4d9e57d95f6b8096d39368d1fce5b13a5b4eb51d7a674c46fb986b0f672"}
{"market":"0x2a903c589141bce4a1e50fb98b73397af6820942542793ab10b1df477e912b6e", "price_changes":[{"asset_id":"68919878716222388542639225642064847629616106443780159680232863841946753372582", "price":"0.11", "size":"322.13", "side":"BUY", "hash":"6b8b2879a8d87dccc2b930194a98b1b361509e31", "best_bid":"0.11", "best_ask":"0.18"}, {"asset_id":"20436996072316278452977393149218961565084965483366669504673105646378938504388", "price":"0.89", "size":"322.13", "side":"SELL", "hash":"f8be150b38cb0f1459c38ec0e89cbac362cc50c6", "best_bid":"0.82", "best_ask":"0.89"}], "timestamp":"1778784199100", "event_type":"price_change"}
{"market":"0x2a903c589141bce4a1e50fb98b73397af6820942542793ab10b1df477e912b6e", "price_changes":[{"asset_id":"68919878716222388542639225642064847629616106443780159680232863841946753372582", "price":"0.16", "size":"0", "side":"BUY", "hash":"6b8b2879a8d87dccc2b930194a98b1b361509e31", "best_bid":"0.11", "best_ask":"0.18"}, {"asset_id":"20436996072316278452977393149218961565084965483366669504673105646378938504388", "price":"0.84", "size":"0", "side":"SELL", "hash":"f8be150b38cb0f1459c38ec0e89cbac362cc50c6", "best_bid":"0.82", "best_ask":"0.89"}], "timestamp":"1778784199100", "event_type":"price_change"}
{"market":"0x2a903c589141bce4a1e50fb98b73397af6820942542793ab10b1df477e912b6e", "asset_id":"68919878716222388542639225642064847629616106443780159680232863841946753372582", "bids":[{"price":"0.01", "size":"11325.74"}, {"price":"0.02", "size":"1437.32"}, {"price":"0.03", "size":"1105.78"}, {"price":"0.04", "size":"607.82"}, {"price":"0.05", "size":"755.72"}, {"price":"0.06", "size":"337.72"}, {"price":"0.07", "size":"357.1"}, {"price":"0.08", "size":"674.73"}, {"price":"0.09", "size":"286.11"}, {"price":"0.1", "size":"715.33"}, {"price":"0.11", "size":"322.13"}], "asks":[{"price":"0.99", "size":"12086.57"}, {"price":"0.98", "size":"1219.45"}, {"price":"0.97", "size":"1111.98"}, {"price":"0.96", "size":"670.05"}, {"price":"0.95", "size":"549.45"}, {"price":"0.94", "size":"346.2"}, {"price":"0.93", "size":"902.05"}, {"price":"0.92", "size":"170.79"}, {"price":"0.91", "size":"234.6"}, {"price":"0.9", "size":"128"}, {"price":"0.89", "size":"142.6"}, {"price":"0.88", "size":"141.8"}, {"price":"0.87", "size":"144.81"}, {"price":"0.86", "size":"204.9"}, {"price":"0.85", "size":"113.5"}, {"price":"0.84", "size":"102.3"}, {"price":"0.83", "size":"101.3"}, {"price":"0.82", "size":"105.3"}, {"price":"0.81", "size":"199.5"}, {"price":"0.8", "size":"103.8"}, {"price":"0.79", "size":"98.1"}, {"price":"0.78", "size":"97.5"}, {"price":"0.77", "size":"96.89"}, {"price":"0.76", "size":"201.39"}, {"price":"0.75", "size":"116"}, {"price":"0.74", "size":"100.6"}, {"price":"0.73", "size":"95.2"}, {"price":"0.72", "size":"94.9"}, {"price":"0.71", "size":"199.6"}, {"price":"0.7", "size":"94.3"}, {"price":"0.69", "size":"108.28"}, {"price":"0.68", "size":"98.8"}, {"price":"0.67", "size":"718.6"}, {"price":"0.66", "size":"798.4"}, {"price":"0.65", "size":"107.3"}, {"price":"0.64", "size":"293"}, {"price":"0.63", "size":"292.9"}, {"price":"0.62", "size":"297.7"}, {"price":"0.61", "size":"397.6"}, {"price":"0.6", "size":"356.93"}, {"price":"0.59", "size":"297.4"}, {"price":"0.58", "size":"109.6"}, {"price":"0.57", "size":"131.48"}, {"price":"0.56", "size":"413.97"}, {"price":"0.55", "size":"934.2"}, {"price":"0.54", "size":"375.6"}, {"price":"0.53", "size":"292"}, {"price":"0.52", "size":"297.12"}, {"price":"0.51", "size":"402"}, {"price":"0.5", "size":"340.91"}, {"price":"0.49", "size":"362"}, {"price":"0.48", "size":"317"}, {"price":"0.47", "size":"337"}, {"price":"0.46", "size":"607.1"}, {"price":"0.45", "size":"346.64"}, {"price":"0.44", "size":"332.45"}, {"price":"0.43", "size":"434.89"}, {"price":"0.42", "size":"324.36"}, {"price":"0.41", "size":"412.4"}, {"price":"0.4", "size":"328.83"}, {"price":"0.39", "size":"297.6"}, {"price":"0.38", "size":"626.5"}, {"price":"0.37", "size":"297.9"}, {"price":"0.36", "size":"208"}, {"price":"0.35", "size":"340.14"}, {"price":"0.34", "size":"330.9"}, {"price":"0.33", "size":"313.6"}, {"price":"0.32", "size":"2055.88"}, {"price":"0.31", "size":"409"}, {"price":"0.3", "size":"134.3"}, {"price":"0.29", "size":"316.38"}, {"price":"0.28", "size":"154.9"}, {"price":"0.27", "size":"180.2"}, {"price":"0.26", "size":"230.6"}, {"price":"0.25", "size":"331"}, {"price":"0.24", "size":"126.39"}, {"price":"0.23", "size":"121.89"}, {"price":"0.22", "size":"117.5"}, {"price":"0.21", "size":"175.44"}, {"price":"0.2", "size":"90"}, {"price":"0.19", "size":"72.35"}, {"price":"0.18", "size":"337.54"}], "hash":"6b8b2879a8d87dccc2b930194a98b1b361509e31", "timestamp":"1778784199100", "event_type":"book"}
{"market":"0x2a903c589141bce4a1e50fb98b73397af6820942542793ab10b1df477e912b6e", "price_changes":[{"asset_id":"68919878716222388542639225642064847629616106443780159680232863841946753372582", "price":"0.35", "size":"345.14", "side":"SELL", "hash":"34f03b6911f5ba79f554933da43327b79256f2ef", "best_bid":"0.11", "best_ask":"0.18"}, {"asset_id":"20436996072316278452977393149218961565084965483366669504673105646378938504388", "price":"0.65", "size":"345.14", "side":"BUY", "hash":"f2e010ef703a772acd2e3c90386e8eff54d20bea", "best_bid":"0.82", "best_ask":"0.89"}], "timestamp":"1778784199116", "event_type":"price_change"}
{"market":"0x2a903c589141bce4a1e50fb98b73397af6820942542793ab10b1df477e912b6e", "price_changes":[{"asset_id":"20436996072316278452977393149218961565084965483366669504673105646378938504388", "price":"0.01", "size":"12081.57", "side":"BUY", "hash":"cee83f5b541719c59ff07126b2e88038a05332f1", "best_bid":"0.82", "best_ask":"0.89"}, {"asset_id":"68919878716222388542639225642064847629616106443780159680232863841946753372582", "price":"0.99", "size":"12081.57", "side":"SELL", "hash":"dc689730385601d6f05b441f86ef0e293c4e899b", "best_bid":"0.11", "best_ask":"0.18"}], "timestamp":"1778784199131", "event_type":"price_change"}
{"market":"0x2a903c589141bce4a1e50fb98b73397af6820942542793ab10b1df477e912b6e", "price_changes":[{"asset_id":"68919878716222388542639225642064847629616106443780159680232863841946753372582", "price":"0.1", "size":"735.33", "side":"BUY", "hash":"6cc05cc9531267c54ed63c4d646f5dbd8088184c", "best_bid":"0.11", "best_ask":"0.18"}, {"asset_id":"20436996072316278452977393149218961565084965483366669504673105646378938504388", "price":"0.9", "size":"735.33", "side":"SELL", "hash":"8750602d0a40ded570e33f56309279fd95e13b3a", "best_bid":"0.82", "best_ask":"0.89"}], "timestamp":"1778784199142", "event_type":"price_change"}
{"market":"0x2a903c589141bce4a1e50fb98b73397af6820942542793ab10b1df477e912b6e", "price_changes":[{"asset_id":"20436996072316278452977393149218961565084965483366669504673105646378938504388", "price":"0.69", "size":"439", "side":"BUY", "hash":"f67bf3a3af9f11abce66e6988f1eb4bef0a14662", "best_bid":"0.82", "best_ask":"0.89"}, {"asset_id":"68919878716222388542639225642064847629616106443780159680232863841946753372582", "price":"0.31", "size":"439", "side":"SELL", "hash":"b732bad22220ec70a7801c5dc229e9c81e4537da", "best_bid":"0.11", "best_ask":"0.18"}], "timestamp":"1778784199147", "event_type":"price_change"}
{"market":"0x2a903c589141bce4a1e50fb98b73397af6820942542793ab10b1df477e912b6e", "price_changes":[{"asset_id":"68919878716222388542639225642064847629616106443780159680232863841946753372582", "price":"0.11", "size":"319.1", "side":"BUY", "hash":"5b182b4bdb1b66fc3a65b5ff2b1f0f9c27fc8359", "best_bid":"0.11", "best_ask":"0.18"}, {"asset_id":"20436996072316278452977393149218961565084965483366669504673105646378938504388", "price":"0.89", "size":"319.1", "side":"SELL", "hash":"39bbed9783a08b5aeff52c6b997746824d881a59", "best_bid":"0.82", "best_ask":"0.89"}], "timestamp":"1778784199174", "event_type":"price_change"}
{"market":"0x2a903c589141bce4a1e50fb98b73397af6820942542793ab10b1df477e912b6e", "asset_id":"68919878716222388542639225642064847629616106443780159680232863841946753372582", "bids":[{"price":"0.01", "size":"11325.74"}, {"price":"0.02", "size":"1437.32"}, {"price":"0.03", "size":"1105.78"}, {"price":"0.04", "size":"607.82"}, {"price":"0.05", "size":"755.72"}, {"price":"0.06", "size":"337.72"}, {"price":"0.07", "size":"357.1"}, {"price":"0.08", "size":"674.73"}, {"price":"0.09", "size":"286.11"}, {"price":"0.1", "size":"735.33"}, {"price":"0.11", "size":"319.1"}], "asks":[{"price":"0.99", "size":"12081.57"}, {"price":"0.98", "size":"1219.45"}, {"price":"0.97", "size":"1111.98"}, {"price":"0.96", "size":"670.05"}, {"price":"0.95", "size":"549.45"}, {"price":"0.94", "size":"346.2"}, {"price":"0.93", "size":"902.05"}, {"price":"0.92", "size":"170.79"}, {"price":"0.91", "size":"234.6"}, {"price":"0.9", "size":"128"}, {"price":"0.89", "size":"142.6"}, {"price":"0.88", "size":"141.8"}, {"price":"0.87", "size":"144.81"}, {"price":"0.86", "size":"204.9"}, {"price":"0.85", "size":"113.5"}, {"price":"0.84", "size":"102.3"}, {"price":"0.83", "size":"101.3"}, {"price":"0.82", "size":"105.3"}, {"price":"0.81", "size":"199.5"}, {"price":"0.8", "size":"103.8"}, {"price":"0.79", "size":"98.1"}, {"price":"0.78", "size":"97.5"}, {"price":"0.77", "size":"96.89"}, {"price":"0.76", "size":"201.39"}, {"price":"0.75", "size":"116"}, {"price":"0.74", "size":"100.6"}, {"price":"0.73", "size":"95.2"}, {"price":"0.72", "size":"94.9"}, {"price":"0.71", "size":"199.6"}, {"price":"0.7", "size":"94.3"}, {"price":"0.69", "size":"108.28"}, {"price":"0.68", "size":"98.8"}, {"price":"0.67", "size":"718.6"}, {"price":"0.66", "size":"798.4"}, {"price":"0.65", "size":"107.3"}, {"price":"0.64", "size":"293"}, {"price":"0.63", "size":"292.9"}, {"price":"0.62", "size":"297.7"}, {"price":"0.61", "size":"397.6"}, {"price":"0.6", "size":"356.93"}, {"price":"0.59", "size":"297.4"}, {"price":"0.58", "size":"109.6"}, {"price":"0.57", "size":"131.48"}, {"price":"0.56", "size":"413.97"}, {"price":"0.55", "size":"934.2"}, {"price":"0.54", "size":"375.6"}, {"price":"0.53", "size":"292"}, {"price":"0.52", "size":"297.12"}, {"price":"0.51", "size":"402"}, {"price":"0.5", "size":"340.91"}, {"price":"0.49", "size":"362"}, {"price":"0.48", "size":"317"}, {"price":"0.47", "size":"337"}, {"price":"0.46", "size":"607.1"}, {"price":"0.45", "size":"346.64"}, {"price":"0.44", "size":"332.45"}, {"price":"0.43", "size":"434.89"}, {"price":"0.42", "size":"324.36"}, {"price":"0.41", "size":"412.4"}, {"price":"0.4", "size":"328.83"}, {"price":"0.39", "size":"297.6"}, {"price":"0.38", "size":"626.5"}, {"price":"0.37", "size":"297.9"}, {"price":"0.36", "size":"208"}, {"price":"0.35", "size":"345.14"}, {"price":"0.34", "size":"330.9"}, {"price":"0.33", "size":"313.6"}, {"price":"0.32", "size":"2055.88"}, {"price":"0.31", "size":"439"}, {"price":"0.3", "size":"134.3"}, {"price":"0.29", "size":"316.38"}, {"price":"0.28", "size":"154.9"}, {"price":"0.27", "size":"180.2"}, {"price":"0.26", "size":"230.6"}, {"price":"0.25", "size":"331"}, {"price":"0.24", "size":"126.39"}, {"price":"0.23", "size":"121.89"}, {"price":"0.22", "size":"117.5"}, {"price":"0.21", "size":"175.44"}, {"price":"0.2", "size":"90"}, {"price":"0.19", "size":"72.35"}, {"price":"0.18", "size":"337.54"}], "hash":"5b182b4bdb1b66fc3a65b5ff2b1f0f9c27fc8359", "timestamp":"1778784199174", "event_type":"book"}
{"market":"0x2a903c589141bce4a1e50fb98b73397af6820942542793ab10b1df477e912b6e", "price_changes":[{"asset_id":"68919878716222388542639225642064847629616106443780159680232863841946753372582", "price":"0.1", "size":"775.33", "side":"BUY", "hash":"33069b09643c5d5d71ac2a2378cec592f6da473d", "best_bid":"0.11", "best_ask":"0.18"}, {"asset_id":"20436996072316278452977393149218961565084965483366669504673105646378938504388", "price":"0.9", "size":"775.33", "side":"SELL", "hash":"c647b0ce6cb9315ab50418450dab308828374477", "best_bid":"0.82", "best_ask":"0.89"}], "timestamp":"1778784199197", "event_type":"price_change"}
{"market":"0x2a903c589141bce4a1e50fb98b73397af6820942542793ab10b1df477e912b6e", "price_changes":[{"asset_id":"68919878716222388542639225642064847629616106443780159680232863841946753372582", "price":"0.11", "size":"313.11", "side":"BUY", "hash":"3d87dd12b61735d7442b2d6dd85f9d58f77eb1a1", "best_bid":"0.11", "best_ask":"0.18"}, {"asset_id":"20436996072316278452977393149218961565084965483366669504673105646378938504388", "price":"0.89", "size":"313.11", "side":"SELL", "hash":"7de3445e891fee897646ac92612f867a73b1cf6b", "best_bid":"0.82", "best_ask":"0.89"}], "timestamp":"1778784199214", "event_type":"price_change"}
{"market":"0x2a903c589141bce4a1e50fb98b73397af6820942542793ab10b1df477e912b6e", "asset_id":"68919878716222388542639225642064847629616106443780159680232863841946753372582", "bids":[{"price":"0.01", "size":"11325.74"}, {"price":"0.02", "size":"1437.32"}, {"price":"0.03", "size":"1105.78"}, {"price":"0.04", "size":"607.82"}, {"price":"0.05", "size":"755.72"}, {"price":"0.06", "size":"337.72"}, {"price":"0.07", "size":"357.1"}, {"price":"0.08", "size":"674.73"}, {"price":"0.09", "size":"286.11"}, {"price":"0.1", "size":"775.33"}, {"price":"0.11", "size":"313.11"}], "asks":[{"price":"0.99", "size":"12081.57"}, {"price":"0.98", "size":"1219.45"}, {"price":"0.97", "size":"1111.98"}, {"price":"0.96", "size":"670.05"}, {"price":"0.95", "size":"549.45"}, {"price":"0.94", "size":"346.2"}, {"price":"0.93", "size":"902.05"}, {"price":"0.92", "size":"170.79"}, {"price":"0.91", "size":"234.6"}, {"price":"0.9", "size":"128"}, {"price":"0.89", "size":"142.6"}, {"price":"0.88", "size":"141.8"}, {"price":"0.87", "size":"144.81"}, {"price":"0.86", "size":"204.9"}, {"price":"0.85", "size":"113.5"}, {"price":"0.84", "size":"102.3"}, {"price":"0.83", "size":"101.3"}, {"price":"0.82", "size":"105.3"}, {"price":"0.81", "size":"199.5"}, {"price":"0.8", "size":"103.8"}, {"price":"0.79", "size":"98.1"}, {"price":"0.78", "size":"97.5"}, {"price":"0.77", "size":"96.89"}, {"price":"0.76", "size":"201.39"}, {"price":"0.75", "size":"116"}, {"price":"0.74", "size":"100.6"}, {"price":"0.73", "size":"95.2"}, {"price":"0.72", "size":"94.9"}, {"price":"0.71", "size":"199.6"}, {"price":"0.7", "size":"94.3"}, {"price":"0.69", "size":"108.28"}, {"price":"0.68", "size":"98.8"}, {"price":"0.67", "size":"718.6"}, {"price":"0.66", "size":"798.4"}, {"price":"0.65", "size":"107.3"}, {"price":"0.64", "size":"293"}, {"price":"0.63", "size":"292.9"}, {"price":"0.62", "size":"297.7"}, {"price":"0.61", "size":"397.6"}, {"price":"0.6", "size":"356.93"}, {"price":"0.59", "size":"297.4"}, {"price":"0.58", "size":"109.6"}, {"price":"0.57", "size":"131.48"}, {"price":"0.56", "size":"413.97"}, {"price":"0.55", "size":"934.2"}, {"price":"0.54", "size":"375.6"}, {"price":"0.53", "size":"292"}, {"price":"0.52", "size":"297.12"}, {"price":"0.51", "size":"402"}, {"price":"0.5", "size":"340.91"}, {"price":"0.49", "size":"362"}, {"price":"0.48", "size":"317"}, {"price":"0.47", "size":"337"}, {"price":"0.46", "size":"607.1"}, {"price":"0.45", "size":"346.64"}, {"price":"0.44", "size":"332.45"}, {"price":"0.43", "size":"434.89"}, {"price":"0.42", "size":"324.36"}, {"price":"0.41", "size":"412.4"}, {"price":"0.4", "size":"328.83"}, {"price":"0.39", "size":"297.6"}, {"price":"0.38", "size":"626.5"}, {"price":"0.37", "size":"297.9"}, {"price":"0.36", "size":"208"}, {"price":"0.35", "size":"345.14"}, {"price":"0.34", "size":"330.9"}, {"price":"0.33", "size":"313.6"}, {"price":"0.32", "size":"2055.88"}, {"price":"0.31", "size":"439"}, {"price":"0.3", "size":"134.3"}, {"price":"0.29", "size":"316.38"}, {"price":"0.28", "size":"154.9"}, {"price":"0.27", "size":"180.2"}, {"price":"0.26", "size":"230.6"}, {"price":"0.25", "size":"331"}, {"price":"0.24", "size":"126.39"}, {"price":"0.23", "size":"121.89"}, {"price":"0.22", "size":"117.5"}, {"price":"0.21", "size":"175.44"}, {"price":"0.2", "size":"90"}, {"price":"0.19", "size":"72.35"}, {"price":"0.18", "size":"337.54"}], "hash":"3d87dd12b61735d7442b2d6dd85f9d58f77eb1a1", "timestamp":"1778784199214", "event_type":"book"}
{"market":"0x2a903c589141bce4a1e50fb98b73397af6820942542793ab10b1df477e912b6e", "price_changes":[{"asset_id":"68919878716222388542639225642064847629616106443780159680232863841946753372582", "price":"0.01", "size":"11335.74", "side":"BUY", "hash":"df37dd079422d6bbc9d6bd5539e562abc4172e55", "best_bid":"0.11", "best_ask":"0.18"}, {"asset_id":"20436996072316278452977393149218961565084965483366669504673105646378938504388", "price":"0.99", "size":"11335.74", "side":"SELL", "hash":"47094c4e3691d1ad78758d3317f0a74f54ab251f", "best_bid":"0.82", "best_ask":"0.89"}], "timestamp":"1778784199254", "event_type":"price_change"}
{"market":"0x2a903c589141bce4a1e50fb98b73397af6820942542793ab10b1df477e912b6e", "price_changes":[{"asset_id":"68919878716222388542639225642064847629616106443780159680232863841946753372582", "price":"0.04", "size":"637.82", "side":"BUY", "hash":"3abf9d0ea79e34452bfe07e3fa6e6c39e3902fd5", "best_bid":"0.11", "best_ask":"0.18"}, {"asset_id":"20436996072316278452977393149218961565084965483366669504673105646378938504388", "price":"0.96", "size":"637.82", "side":"SELL", "hash":"1de808558d6fc8e479cab3237710e8fe98c58bf5", "best_bid":"0.82", "best_ask":"0.89"}], "timestamp":"1778784199271", "event_type":"price_change"}
{"market":"0x2a903c589141bce4a1e50fb98b73397af6820942542793ab10b1df477e912b6e", "price_changes":[{"asset_id":"20436996072316278452977393149218961565084965483366669504673105646378938504388", "price":"0.82", "size":"437.54", "side":"BUY", "hash":"693d64e771860220b93fb5fde390f7f047f3de6c", "best_bid":"0.82", "best_ask":"0.89"}, {"asset_id":"68919878716222388542639225642064847629616106443780159680232863841946753372582", "price":"0.18", "size":"437.54", "side":"SELL", "hash":"0f58de57ef0985fae20df29e34f3bfe0bd76091c", "best_bid":"0.11", "best_ask":"0.18"}], "timestamp":"1778784199275", "event_type":"price_change"}
{"market":"0x2a903c589141bce4a1e50fb98b73397af6820942542793ab10b1df477e912b6e", "asset_id":"68919878716222388542639225642064847629616106443780159680232863841946753372582", "price":"0.11", "size":"5.99", "fee_rate_bps":"0", "side":"SELL", "timestamp":"1778784199284", "event_type":"last_trade_price", "transaction_hash":"0xdaca05728aa0c3d9c03777ecfea463fb9fabf10361bb557a3ac204e0691ab7af"}
{"market":"0x2a903c589141bce4a1e50fb98b73397af6820942542793ab10b1df477e912b6e", "price_changes":[{"asset_id":"68919878716222388542639225642064847629616106443780159680232863841946753372582", "price":"0.11", "size":"288.11", "side":"BUY", "hash":"22904fff4c237f91176cda34885d0e216995891f", "best_bid":"0.11", "best_ask":"0.18"}, {"asset_id":"20436996072316278452977393149218961565084965483366669504673105646378938504388", "price":"0.89", "size":"288.11", "side":"SELL", "hash":"bbc07d7ae28df22e7713052c8a37e224205c3e2f", "best_bid":"0.82", "best_ask":"0.89"}], "timestamp":"1778784199291", "event_type":"price_change"}
{"market":"0x2a903c589141bce4a1e50fb98b73397af6820942542793ab10b1df477e912b6e", "asset_id":"68919878716222388542639225642064847629616106443780159680232863841946753372582", "bids":[{"price":"0.01", "size":"11335.74"}, {"price":"0.02", "size":"1437.32"}, {"price":"0.03", "size":"1105.78"}, {"price":"0.04", "size":"637.82"}, {"price":"0.05", "size":"755.72"}, {"price":"0.06", "size":"337.72"}, {"price":"0.07", "size":"357.1"}, {"price":"0.08", "size":"674.73"}, {"price":"0.09", "size":"286.11"}, {"price":"0.1", "size":"775.33"}, {"price":"0.11", "size":"288.11"}], "asks":[{"price":"0.99", "size":"12081.57"}, {"price":"0.98", "size":"1219.45"}, {"price":"0.97", "size":"1111.98"}, {"price":"0.96", "size":"670.05"}, {"price":"0.95", "size":"549.45"}, {"price":"0.94", "size":"346.2"}, {"price":"0.93", "size":"902.05"}, {"price":"0.92", "size":"170.79"}, {"price":"0.91", "size":"234.6"}, {"price":"0.9", "size":"128"}, {"price":"0.89", "size":"142.6"}, {"price":"0.88", "size":"141.8"}, {"price":"0.87", "size":"144.81"}, {"price":"0.86", "size":"204.9"}, {"price":"0.85", "size":"113.5"}, {"price":"0.84", "size":"102.3"}, {"price":"0.83", "size":"101.3"}, {"price":"0.82", "size":"105.3"}, {"price":"0.81", "size":"199.5"}, {"price":"0.8", "size":"103.8"}, {"price":"0.79", "size":"98.1"}, {"price":"0.78", "size":"97.5"}, {"price":"0.77", "size":"96.89"}, {"price":"0.76", "size":"201.39"}, {"price":"0.75", "size":"116"}, {"price":"0.74", "size":"100.6"}, {"price":"0.73", "size":"95.2"}, {"price":"0.72", "size":"94.9"}, {"price":"0.71", "size":"199.6"}, {"price":"0.7", "size":"94.3"}, {"price":"0.69", "size":"108.28"}, {"price":"0.68", "size":"98.8"}, {"price":"0.67", "size":"718.6"}, {"price":"0.66", "size":"798.4"}, {"price":"0.65", "size":"107.3"}, {"price":"0.64", "size":"293"}, {"price":"0.63", "size":"292.9"}, {"price":"0.62", "size":"297.7"}, {"price":"0.61", "size":"397.6"}, {"price":"0.6", "size":"356.93"}, {"price":"0.59", "size":"297.4"}, {"price":"0.58", "size":"109.6"}, {"price":"0.57", "size":"131.48"}, {"price":"0.56", "size":"413.97"}, {"price":"0.55", "size":"934.2"}, {"price":"0.54", "size":"375.6"}, {"price":"0.53", "size":"292"}, {"price":"0.52", "size":"297.12"}, {"price":"0.51", "size":"402"}, {"price":"0.5", "size":"340.91"}, {"price":"0.49", "size":"362"}, {"price":"0.48", "size":"317"}, {"price":"0.47", "size":"337"}, {"price":"0.46", "size":"607.1"}, {"price":"0.45", "size":"346.64"}, {"price":"0.44", "size":"332.45"}, {"price":"0.43", "size":"434.89"}, {"price":"0.42", "size":"324.36"}, {"price":"0.41", "size":"412.4"}, {"price":"0.4", "size":"328.83"}, {"price":"0.39", "size":"297.6"}, {"price":"0.38", "size":"626.5"}, {"price":"0.37", "size":"297.9"}, {"price":"0.36", "size":"208"}, {"price":"0.35", "size":"345.14"}, {"price":"0.34", "size":"330.9"}, {"price":"0.33", "size":"313.6"}, {"price":"0.32", "size":"2055.88"}, {"price":"0.31", "size":"439"}, {"price":"0.3", "size":"134.3"}, {"price":"0.29", "size":"316.38"}, {"price":"0.28", "size":"154.9"}, {"price":"0.27", "size":"180.2"}, {"price":"0.26", "size":"230.6"}, {"price":"0.25", "size":"331"}, {"price":"0.24", "size":"126.39"}, {"price":"0.23", "size":"121.89"}, {"price":"0.22", "size":"117.5"}, {"price":"0.21", "size":"175.44"}, {"price":"0.2", "size":"90"}, {"price":"0.19", "size":"72.35"}, {"price":"0.18", "size":"437.54"}], "hash":"22904fff4c237f91176cda34885d0e216995891f", "timestamp":"1778784199291", "event_type":"book"}
{"market":"0x2a903c589141bce4a1e50fb98b73397af6820942542793ab10b1df477e912b6e", "price_changes":[{"asset_id":"68919878716222388542639225642064847629616106443780159680232863841946753372582", "price":"0.06", "size":"378.24", "side":"BUY", "hash":"a762dd198d0b8ec215065afed29f5c335d9d88b6", "best_bid":"0.11", "best_ask":"0.18"}, {"asset_id":"20436996072316278452977393149218961565084965483366669504673105646378938504388", "price":"0.94", "size":"378.24", "side":"SELL", "hash":"9884c6aec214732a67105b9e235f192a081e8df4", "best_bid":"0.82", "best_ask":"0.89"}], "timestamp":"1778784199309", "event_type":"price_change"}
{"market":"0x2a903c589141bce4a1e50fb98b73397af6820942542793ab10b1df477e912b6e", "price_changes":[{"asset_id":"68919878716222388542639225642064847629616106443780159680232863841946753372582", "price":"0.1", "size":"825.33", "side":"BUY", "hash":"779e5fc3588f23d8bd4ef9a513347f1ff3371554", "best_bid":"0.11", "best_ask":"0.18"}, {"asset_id":"20436996072316278452977393149218961565084965483366669504673105646378938504388", "price":"0.9", "size":"825.33", "side":"SELL", "hash":"f57ca87b5b7f351a966c1fff895f5fdd0a2616f2", "best_bid":"0.82", "best_ask":"0.89"}], "timestamp":"1778784199317", "event_type":"price_change"}
{"market":"0x2a903c589141bce4a1e50fb98b73397af6820942542793ab10b1df477e912b6e", "price_changes":[{"asset_id":"20436996072316278452977393149218961565084965483366669504673105646378938504388", "price":"0.66", "size":"360.9", "side":"BUY", "hash":"36e9646b6b396e69f8d0c6d942e5d4104afc5b70", "best_bid":"0.82", "best_ask":"0.89"}, {"asset_id":"68919878716222388542639225642064847629616106443780159680232863841946753372582", "price":"0.34", "size":"360.9", "side":"SELL", "hash":"d679e8c362e31f98f53df1c61e6c104fdf52b9be", "best_bid":"0.11", "best_ask":"0.18"}], "timestamp":"1778784199328", "event_type":"price_change"}
{"market":"0x2a903c589141bce4a1e50fb98b73397af6820942542793ab10b1df477e912b6e", "price_changes":[{"asset_id":"20436996072316278452977393149218961565084965483366669504673105646378938504388", "price":"0.85", "size":"15", "side":"BUY", "hash":"35843b7a701acc362b46a58f9e8bd854116f7e8e", "best_bid":"0.85", "best_ask":"0.89"}, {"asset_id":"68919878716222388542639225642064847629616106443780159680232863841946753372582", "price":"0.15", "size":"15", "side":"SELL", "hash":"e6a2d484f4cd052451cb1a21f90bb02673ff2da3", "best_bid":"0.11", "best_ask":"0.15"}], "timestamp":"1778784199396", "event_type":"price_change"}
{"market":"0x2a903c589141bce4a1e50fb98b73397af6820942542793ab10b1df477e912b6e", "price_changes":[{"asset_id":"20436996072316278452977393149218961565084965483366669504673105646378938504388", "price":"0.67", "size":"343.6", "side":"BUY", "hash":"9b10d33d84ab3744b50e2d421030ace38ae4e33d", "best_bid":"0.85", "best_ask":"0.89"}, {"asset_id":"68919878716222388542639225642064847629616106443780159680232863841946753372582", "price":"0.33", "size":"343.6", "side":"SELL", "hash":"3beffba5621f23562a16cd50eb29590a451574f0", "best_bid":"0.11", "best_ask":"0.15"}], "timestamp":"1778784199423", "event_type":"price_change"}
{"market":"0x2a903c589141bce4a1e50fb98b73397af6820942542793ab10b1df477e912b6e", "price_changes":[{"asset_id":"68919878716222388542639225642064847629616106443780159680232863841946753372582", "price":"0.11", "size":"286.98", "side":"BUY", "hash":"bf3a1b07b1ac3f316e29b948d873e6346aef96b7", "best_bid":"0.11", "best_ask":"0.15"}, {"asset_id":"20436996072316278452977393149218961565084965483366669504673105646378938504388", "price":"0.89", "size":"286.98", "side":"SELL", "hash":"472c97617495b0e0e3399bb5fb0d67944571d5d0", "best_bid":"0.85", "best_ask":"0.89"}], "timestamp":"1778784199452", "event_type":"price_change"}
{"market":"0x2a903c589141bce4a1e50fb98b73397af6820942542793ab10b1df477e912b6e", "asset_id":"68919878716222388542639225642064847629616106443780159680232863841946753372582", "bids":[{"price":"0.01", "size":"11335.74"}, {"price":"0.02", "size":"1437.32"}, {"price":"0.03", "size":"1105.78"}, {"price":"0.04", "size":"637.82"}, {"price":"0.05", "size":"755.72"}, {"price":"0.06", "size":"378.24"}, {"price":"0.07", "size":"357.1"}, {"price":"0.08", "size":"674.73"}, {"price":"0.09", "size":"286.11"}, {"price":"0.1", "size":"825.33"}, {"price":"0.11", "size":"286.98"}], "asks":[{"price":"0.99", "size":"12081.57"}, {"price":"0.98", "size":"1219.45"}, {"price":"0.97", "size":"1111.98"}, {"price":"0.96", "size":"670.05"}, {"price":"0.95", "size":"549.45"}, {"price":"0.94", "size":"346.2"}, {"price":"0.93", "size":"902.05"}, {"price":"0.92", "size":"170.79"}, {"price":"0.91", "size":"234.6"}, {"price":"0.9", "size":"128"}, {"price":"0.89", "size":"142.6"}, {"price":"0.88", "size":"141.8"}, {"price":"0.87", "size":"144.81"}, {"price":"0.86", "size":"204.9"}, {"price":"0.85", "size":"113.5"}, {"price":"0.84", "size":"102.3"}, {"price":"0.83", "size":"101.3"}, {"price":"0.82", "size":"105.3"}, {"price":"0.81", "size":"199.5"}, {"price":"0.8", "size":"103.8"}, {"price":"0.79", "size":"98.1"}, {"price":"0.78", "size":"97.5"}, {"price":"0.77", "size":"96.89"}, {"price":"0.76", "size":"201.39"}, {"price":"0.75", "size":"116"}, {"price":"0.74", "size":"100.6"}, {"price":"0.73", "size":"95.2"}, {"price":"0.72", "size":"94.9"}, {"price":"0.71", "size":"199.6"}, {"price":"0.7", "size":"94.3"}, {"price":"0.69", "size":"108.28"}, {"price":"0.68", "size":"98.8"}, {"price":"0.67", "size":"718.6"}, {"price":"0.66", "size":"798.4"}, {"price":"0.65", "size":"107.3"}, {"price":"0.64", "size":"293"}, {"price":"0.63", "size":"292.9"}, {"price":"0.62", "size":"297.7"}, {"price":"0.61", "size":"397.6"}, {"price":"0.6", "size":"356.93"}, {"price":"0.59", "size":"297.4"}, {"price":"0.58", "size":"109.6"}, {"price":"0.57", "size":"131.48"}, {"price":"0.56", "size":"413.97"}, {"price":"0.55", "size":"934.2"}, {"price":"0.54", "size":"375.6"}, {"price":"0.53", "size":"292"}, {"price":"0.52", "size":"297.12"}, {"price":"0.51", "size":"402"}, {"price":"0.5", "size":"340.91"}, {"price":"0.49", "size":"362"}, {"price":"0.48", "size":"317"}, {"price":"0.47", "size":"337"}, {"price":"0.46", "size":"607.1"}, {"price":"0.45", "size":"346.64"}, {"price":"0.44", "size":"332.45"}, {"price":"0.43", "size":"434.89"}, {"price":"0.42", "size":"324.36"}, {"price":"0.41", "size":"412.4"}, {"price":"0.4", "size":"328.83"}, {"price":"0.39", "size":"297.6"}, {"price":"0.38", "size":"626.5"}, {"price":"0.37", "size":"297.9"}, {"price":"0.36", "size":"208"}, {"price":"0.35", "size":"345.14"}, {"price":"0.34", "size":"360.9"}, {"price":"0.33", "size":"343.6"}, {"price":"0.32", "size":"2055.88"}, {"price":"0.31", "size":"439"}, {"price":"0.3", "size":"134.3"}, {"price":"0.29", "size":"316.38"}, {"price":"0.28", "size":"154.9"}, {"price":"0.27", "size":"180.2"}, {"price":"0.26", "size":"230.6"}, {"price":"0.25", "size":"331"}, {"price":"0.24", "size":"126.39"}, {"price":"0.23", "size":"121.89"}, {"price":"0.22", "size":"117.5"}, {"price":"0.21", "size":"175.44"}, {"price":"0.2", "size":"90"}, {"price":"0.19", "size":"72.35"}, {"price":"0.18", "size":"437.54"}, {"price":"0.15", "size":"15"}], "hash":"bf3a1b07b1ac3f316e29b948d873e6346aef96b7", "timestamp":"1778784199452", "event_type":"book"}
{"market":"0x2a903c589141bce4a1e50fb98b73397af6820942542793ab10b1df477e912b6e", "price_changes":[{"asset_id":"68919878716222388542639225642064847629616106443780159680232863841946753372582", "price":"0.1", "size":"830.33", "side":"BUY", "hash":"97d1a01253cd216e8cd819cee96191896df43e5f", "best_bid":"0.11", "best_ask":"0.15"}, {"asset_id":"20436996072316278452977393149218961565084965483366669504673105646378938504388", "price":"0.9", "size":"830.33", "side":"SELL", "hash":"b61ce95b1a2a08eff3d82ecf827898ddccdfb3c5", "best_bid":"0.85", "best_ask":"0.89"}], "timestamp":"1778784199456", "event_type":"price_change"}
{"market":"0x2a903c589141bce4a1e50fb98b73397af6820942542793ab10b1df477e912b6e", "price_changes":[{"asset_id":"68919878716222388542639225642064847629616106443780159680232863841946753372582", "price":"0.11", "size":"274.21", "side":"BUY", "hash":"08db1afaa04f15ccedc10262e0d80c4293bcba67", "best_bid":"0.11", "best_ask":"0.15"}, {"asset_id":"20436996072316278452977393149218961565084965483366669504673105646378938504388", "price":"0.89", "size":"274.21", "side":"SELL", "hash":"3e226504979b165cf5c84fb8ccfe8563ee4f4d8e", "best_bid":"0.85", "best_ask":"0.89"}], "timestamp":"1778784199507", "event_type":"price_change"}
{"market":"0x2a903c589141bce4a1e50fb98b73397af6820942542793ab10b1df477e912b6e", "asset_id":"68919878716222388542639225642064847629616106443780159680232863841946753372582", "bids":[{"price":"0.01", "size":"11335.74"}, {"price":"0.02", "size":"1437.32"}, {"price":"0.03", "size":"1105.78"}, {"price":"0.04", "size":"637.82"}, {"price":"0.05", "size":"755.72"}, {"price":"0.06", "size":"378.24"}, {"price":"0.07", "size":"357.1"}, {"price":"0.08", "size":"674.73"}, {"price":"0.09", "size":"286.11"}, {"price":"0.1", "size":"830.33"}, {"price":"0.11", "size":"274.21"}], "asks":[{"price":"0.99", "size":"12081.57"}, {"price":"0.98", "size":"1219.45"}, {"price":"0.97", "size":"1111.98"}, {"price":"0.96", "size":"670.05"}, {"price":"0.95", "size":"549.45"}, {"price":"0.94", "size":"346.2"}, {"price":"0.93", "size":"902.05"}, {"price":"0.92", "size":"170.79"}, {"price":"0.91", "size":"234.6"}, {"price":"0.9", "size":"128"}, {"price":"0.89", "size":"142.6"}, {"price":"0.88", "size":"141.8"}, {"price":"0.87", "size":"144.81"}, {"price":"0.86", "size":"204.9"}, {"price":"0.85", "size":"113.5"}, {"price":"0.84", "size":"102.3"}, {"price":"0.83", "size":"101.3"}, {"price":"0.82", "size":"105.3"}, {"price":"0.81", "size":"199.5"}, {"price":"0.8", "size":"103.8"}, {"price":"0.79", "size":"98.1"}, {"price":"0.78", "size":"97.5"}, {"price":"0.77", "size":"96.89"}, {"price":"0.76", "size":"201.39"}, {"price":"0.75", "size":"116"}, {"price":"0.74", "size":"100.6"}, {"price":"0.73", "size":"95.2"}, {"price":"0.72", "size":"94.9"}, {"price":"0.71", "size":"199.6"}, {"price":"0.7", "size":"94.3"}, {"price":"0.69", "size":"108.28"}, {"price":"0.68", "size":"98.8"}, {"price":"0.67", "size":"718.6"}, {"price":"0.66", "size":"798.4"}, {"price":"0.65", "size":"107.3"}, {"price":"0.64", "size":"293"}, {"price":"0.63", "size":"292.9"}, {"price":"0.62", "size":"297.7"}, {"price":"0.61", "size":"397.6"}, {"price":"0.6", "size":"356.93"}, {"price":"0.59", "size":"297.4"}, {"price":"0.58", "size":"109.6"}, {"price":"0.57", "size":"131.48"}, {"price":"0.56", "size":"413.97"}, {"price":"0.55", "size":"934.2"}, {"price":"0.54", "size":"375.6"}, {"price":"0.53", "size":"292"}, {"price":"0.52", "size":"297.12"}, {"price":"0.51", "size":"402"}, {"price":"0.5", "size":"340.91"}, {"price":"0.49", "size":"362"}, {"price":"0.48", "size":"317"}, {"price":"0.47", "size":"337"}, {"price":"0.46", "size":"607.1"}, {"price":"0.45", "size":"346.64"}, {"price":"0.44", "size":"332.45"}, {"price":"0.43", "size":"434.89"}, {"price":"0.42", "size":"324.36"}, {"price":"0.41", "size":"412.4"}, {"price":"0.4", "size":"328.83"}, {"price":"0.39", "size":"297.6"}, {"price":"0.38", "size":"626.5"}, {"price":"0.37", "size":"297.9"}, {"price":"0.36", "size":"208"}, {"price":"0.35", "size":"345.14"}, {"price":"0.34", "size":"360.9"}, {"price":"0.33", "size":"343.6"}, {"price":"0.32", "size":"2055.88"}, {"price":"0.31", "size":"439"}, {"price":"0.3", "size":"134.3"}, {"price":"0.29", "size":"316.38"}, {"price":"0.28", "size":"154.9"}, {"price":"0.27", "size":"180.2"}, {"price":"0.26", "size":"230.6"}, {"price":"0.25", "size":"331"}, {"price":"0.24", "size":"126.39"}, {"price":"0.23", "size":"121.89"}, {"price":"0.22", "size":"117.5"}, {"price":"0.21", "size":"175.44"}, {"price":"0.2", "size":"90"}, {"price":"0.19", "size":"72.35"}, {"price":"0.18", "size":"437.54"}, {"price":"0.15", "size":"15"}], "hash":"08db1afaa04f15ccedc10262e0d80c4293bcba67", "timestamp":"1778784199507", "event_type":"book"}
{"market":"0x2a903c589141bce4a1e50fb98b73397af6820942542793ab10b1df477e912b6e", "price_changes":[{"asset_id":"20436996072316278452977393149218961565084965483366669504673105646378938504388", "price":"0.88", "size":"5", "side":"BUY", "hash":"68807b00a7708fd73c5ef37873489a1ae491f602", "best_bid":"0.88", "best_ask":"0.89"}, {"asset_id":"68919878716222388542639225642064847629616106443780159680232863841946753372582", "price":"0.12", "size":"5", "side":"SELL", "hash":"d27754e01d416a7d376ab137b0dcc954c4039d7a", "best_bid":"0.11", "best_ask":"0.12"}], "timestamp":"1778784199514", "event_type":"price_change"}
{"market":"0x2a903c589141bce4a1e50fb98b73397af6820942542793ab10b1df477e912b6e", "price_changes":[{"asset_id":"20436996072316278452977393149218961565084965483366669504673105646378938504388", "price":"0.38", "size":"897.7", "side":"BUY", "hash":"c8e53035b2092b3489617629bd8e42df91677985", "best_bid":"0.88", "best_ask":"0.89"}, {"asset_id":"68919878716222388542639225642064847629616106443780159680232863841946753372582", "price":"0.62", "size":"897.7", "side":"SELL", "hash":"e2cd17f7fd77ecdd64411df1d48a65b6ccb900d8", "best_bid":"0.11", "best_ask":"0.12"}], "timestamp":"1778784199545", "event_type":"price_change"}
{"market":"0x2a903c589141bce4a1e50fb98b73397af6820942542793ab10b1df477e912b6e", "price_changes":[{"asset_id":"68919878716222388542639225642064847629616106443780159680232863841946753372582", "price":"0.01", "size":"11345.74", "side":"BUY", "hash":"fb5096c1ef3edf973105aad19b2bad313aed799e", "best_bid":"0.11", "best_ask":"0.12"}, {"asset_id":"20436996072316278452977393149218961565084965483366669504673105646378938504388", "price":"0.99", "size":"11345.74", "side":"SELL", "hash":"b6a3e385e9046a53072b80eac6abfde85f53bdc0", "best_bid":"0.88", "best_ask":"0.89"}], "timestamp":"1778784199553", "event_type":"price_change"}
{"market":"0x2a903c589141bce4a1e50fb98b73397af6820942542793ab10b1df477e912b6e", "price_changes":[{"asset_id":"68919878716222388542639225642064847629616106443780159680232863841946753372582", "price":"0.17", "size":"16", "side":"BUY", "hash":"d2ff6453c485846c742d823750076b1ad9a60f8e", "best_bid":"0.17", "best_ask":"0.18"}, {"asset_id":"20436996072316278452977393149218961565084965483366669504673105646378938504388", "price":"0.83", "size":"16", "side":"SELL", "hash":"d50f31274902a03c8d9f7e704666519938c2a9ee", "best_bid":"0.82", "best_ask":"0.83"}], "timestamp":"1778784199576", "event_type":"price_change"}
{"market":"0x2a903c589141bce4a1e50fb98b73397af6820942542793ab10b1df477e912b6e", "price_changes":[{"asset_id":"20436996072316278452977393149218961565084965483366669504673105646378938504388", "price":"0.88", "size":"0", "side":"BUY", "hash":"d50f31274902a03c8d9f7e704666519938c2a9ee", "best_bid":"0.82", "best_ask":"0.83"}, {"asset_id":"68919878716222388542639225642064847629616106443780159680232863841946753372582", "price":"0.12", "size":"0", "side":"SELL", "hash":"d2ff6453c485846c742d823750076b1ad9a60f8e", "best_bid":"0.17", "best_ask":"0.18"}], "timestamp":"1778784199576", "event_type":"price_change"}
{"market":"0x2a903c589141bce4a1e50fb98b73397af6820942542793ab10b1df477e912b6e", "price_changes":[{"asset_id":"20436996072316278452977393149218961565084965483366669504673105646378938504388", "price":"0.85", "size":"0", "side":"BUY", "hash":"d50f31274902a03c8d9f7e704666519938c2a9ee", "best_bid":"0.82", "best_ask":"0.83"}, {"asset_id":"68919878716222388542639225642064847629616106443780159680232863841946753372582", "price":"0.15", "size":"0", "side":"SELL", "hash":"d2ff6453c485846c742d823750076b1ad9a60f8e", "best_bid":"0.17", "best_ask":"0.18"}], "timestamp":"1778784199576", "event_type":"price_change"}
{"market":"0x2a903c589141bce4a1e50fb98b73397af6820942542793ab10b1df477e912b6e", "asset_id":"68919878716222388542639225642064847629616106443780159680232863841946753372582", "bids":[{"price":"0.01", "size":"11345.74"}, {"price":"0.02", "size":"1437.32"}, {"price":"0.03", "size":"1105.78"}, {"price":"0.04", "size":"637.82"}, {"price":"0.05", "size":"755.72"}, {"price":"0.06", "size":"378.24"}, {"price":"0.07", "size":"357.1"}, {"price":"0.08", "size":"674.73"}, {"price":"0.09", "size":"286.11"}, {"price":"0.1", "size":"830.33"}, {"price":"0.11", "size":"274.21"}, {"price":"0.17", "size":"16"}], "asks":[{"price":"0.99", "size":"12081.57"}, {"price":"0.98", "size":"1219.45"}, {"price":"0.97", "size":"1111.98"}, {"price":"0.96", "size":"670.05"}, {"price":"0.95", "size":"549.45"}, {"price":"0.94", "size":"346.2"}, {"price":"0.93", "size":"902.05"}, {"price":"0.92", "size":"170.79"}, {"price":"0.91", "size":"234.6"}, {"price":"0.9", "size":"128"}, {"price":"0.89", "size":"142.6"}, {"price":"0.88", "size":"141.8"}, {"price":"0.87", "size":"144.81"}, {"price":"0.86", "size":"204.9"}, {"price":"0.85", "size":"113.5"}, {"price":"0.84", "size":"102.3"}, {"price":"0.83", "size":"101.3"}, {"price":"0.82", "size":"105.3"}, {"price":"0.81", "size":"199.5"}, {"price":"0.8", "size":"103.8"}, {"price":"0.79", "size":"98.1"}, {"price":"0.78", "size":"97.5"}, {"price":"0.77", "size":"96.89"}, {"price":"0.76", "size":"201.39"}, {"price":"0.75", "size":"116"}, {"price":"0.74", "size":"100.6"}, {"price":"0.73", "size":"95.2"}, {"price":"0.72", "size":"94.9"}, {"price":"0.71", "size":"199.6"}, {"price":"0.7", "size":"94.3"}, {"price":"0.69", "size":"108.28"}, {"price":"0.68", "size":"98.8"}, {"price":"0.67", "size":"718.6"}, {"price":"0.66", "size":"798.4"}, {"price":"0.65", "size":"107.3"}, {"price":"0.64", "size":"293"}, {"price":"0.63", "size":"292.9"}, {"price":"0.62", "size":"897.7"}, {"price":"0.61", "size":"397.6"}, {"price":"0.6", "size":"356.93"}, {"price":"0.59", "size":"297.4"}, {"price":"0.58", "size":"109.6"}, {"price":"0.57", "size":"131.48"}, {"price":"0.56", "size":"413.97"}, {"price":"0.55", "size":"934.2"}, {"price":"0.54", "size":"375.6"}, {"price":"0.53", "size":"292"}, {"price":"0.52", "size":"297.12"}, {"price":"0.51", "size":"402"}, {"price":"0.5", "size":"340.91"}, {"price":"0.49", "size":"362"}, {"price":"0.48", "size":"317"}, {"price":"0.47", "size":"337"}, {"price":"0.46", "size":"607.1"}, {"price":"0.45", "size":"346.64"}, {"price":"0.44", "size":"332.45"}, {"price":"0.43", "size":"434.89"}, {"price":"0.42", "size":"324.36"}, {"price":"0.41", "size":"412.4"}, {"price":"0.4", "size":"328.83"}, {"price":"0.39", "size":"297.6"}, {"price":"0.38", "size":"626.5"}, {"price":"0.37", "size":"297.9"}, {"price":"0.36", "size":"208"}, {"price":"0.35", "size":"345.14"}, {"price":"0.34", "size":"360.9"}, {"price":"0.33", "size":"343.6"}, {"price":"0.32", "size":"2055.88"}, {"price":"0.31", "size":"439"}, {"price":"0.3", "size":"134.3"}, {"price":"0.29", "size":"316.38"}, {"price":"0.28", "size":"154.9"}, {"price":"0.27", "size":"180.2"}, {"price":"0.26", "size":"230.6"}, {"price":"0.25", "size":"331"}, {"price":"0.24", "size":"126.39"}, {"price":"0.23", "size":"121.89"}, {"price":"0.22", "size":"117.5"}, {"price":"0.21", "size":"175.44"}, {"price":"0.2", "size":"90"}, {"price":"0.19", "size":"72.35"}, {"price":"0.18", "size":"437.54"}], "hash":"d2ff6453c485846c742d823750076b1ad9a60f8e", "timestamp":"1778784199576", "event_type":"book"}
{"market":"0x2a903c589141bce4a1e50fb98b73397af6820942542793ab10b1df477e912b6e", "price_changes":[{"asset_id":"20436996072316278452977393149218961565084965483366669504673105646378938504388", "price":"0.01", "size":"12076.51", "side":"BUY", "hash":"4fa365b84a39a8f231a92d8ef04329cd666186c0", "best_bid":"0.82", "best_ask":"0.83"}, {"asset_id":"68919878716222388542639225642064847629616106443780159680232863841946753372582", "price":"0.99", "size":"12076.51", "side":"SELL", "hash":"52ccfb4b4a6e0a42553819256d687323dddd3e89", "best_bid":"0.17", "best_ask":"0.18"}], "timestamp":"1778784199580", "event_type":"price_change"}
{"market":"0x2a903c589141bce4a1e50fb98b73397af6820942542793ab10b1df477e912b6e", "price_changes":[{"asset_id":"68919878716222388542639225642064847629616106443780159680232863841946753372582", "price":"0.11", "size":"279.21", "side":"BUY", "hash":"1e56337b6cabdc9194676a96253ac5f6f8a27b8b", "best_bid":"0.17", "best_ask":"0.18"}, {"asset_id":"20436996072316278452977393149218961565084965483366669504673105646378938504388", "price":"0.89", "size":"279.21", "side":"SELL", "hash":"69363f8404da0b1ad2ce487efc34fc8aabeffd09", "best_bid":"0.82", "best_ask":"0.83"}], "timestamp":"1778784199583", "event_type":"price_change"}
{"market":"0x2a903c589141bce4a1e50fb98b73397af6820942542793ab10b1df477e912b6e", "asset_id":"68919878716222388542639225642064847629616106443780159680232863841946753372582", "price":"0.14", "size":"20", "fee_rate_bps":"0", "side":"BUY", "timestamp":"1778784199624", "event_type":"last_trade_price", "transaction_hash":"0x5af139e882d9fd28891696a159d608b8a7ee1bcd28bc15914e398faa3eaa49f2"}
{"market":"0x2a903c589141bce4a1e50fb98b73397af6820942542793ab10b1df477e912b6e", "price_changes":[{"asset_id":"68919878716222388542639225642064847629616106443780159680232863841946753372582", "price":"0.11", "size":"181.77", "side":"BUY", "hash":"276934e91ddf2608ebaae4d17707108899060c51", "best_bid":"0.11", "best_ask":"0.18"}, {"asset_id":"20436996072316278452977393149218961565084965483366669504673105646378938504388", "price":"0.89", "size":"181.77", "side":"SELL", "hash":"1e124ee39d0253946779ac810ecedc775f5f3248", "best_bid":"0.82", "best_ask":"0.89"}], "timestamp":"1778784199631", "event_type":"price_change"}
{"market":"0x2a903c589141bce4a1e50fb98b73397af6820942542793ab10b1df477e912b6e", "price_changes":[{"asset_id":"68919878716222388542639225642064847629616106443780159680232863841946753372582", "price":"0.17", "size":"0", "side":"BUY", "hash":"276934e91ddf2608ebaae4d17707108899060c51", "best_bid":"0.11", "best_ask":"0.18"}, {"asset_id":"20436996072316278452977393149218961565084965483366669504673105646378938504388", "price":"0.83", "size":"0", "side":"SELL", "hash":"1e124ee39d0253946779ac810ecedc775f5f3248", "best_bid":"0.82", "best_ask":"0.89"}], "timestamp":"1778784199631", "event_type":"price_change"}
{"market":"0x2a903c589141bce4a1e50fb98b73397af6820942542793ab10b1df477e912b6e", "asset_id":"68919878716222388542639225642064847629616106443780159680232863841946753372582", "bids":[{"price":"0.01", "size":"11345.74"}, {"price":"0.02", "size":"1437.32"}, {"price":"0.03", "size":"1105.78"}, {"price":"0.04", "size":"637.82"}, {"price":"0.05", "size":"755.72"}, {"price":"0.06", "size":"378.24"}, {"price":"0.07", "size":"357.1"}, {"price":"0.08", "size":"674.73"}, {"price":"0.09", "size":"286.11"}, {"price":"0.1", "size":"830.33"}, {"price":"0.11", "size":"181.77"}], "asks":[{"price":"0.99", "size":"12076.51"}, {"price":"0.98", "size":"1219.45"}, {"price":"0.97", "size":"1111.98"}, {"price":"0.96", "size":"670.05"}, {"price":"0.95", "size":"549.45"}, {"price":"0.94", "size":"346.2"}, {"price":"0.93", "size":"902.05"}, {"price":"0.92", "size":"170.79"}, {"price":"0.91", "size":"234.6"}, {"price":"0.9", "size":"128"}, {"price":"0.89", "size":"142.6"}, {"price":"0.88", "size":"141.8"}, {"price":"0.87", "size":"144.81"}, {"price":"0.86", "size":"204.9"}, {"price":"0.85", "size":"113.5"}, {"price":"0.84", "size":"102.3"}, {"price":"0.83", "size":"101.3"}, {"price":"0.82", "size":"105.3"}, {"price":"0.81", "size":"199.5"}, {"price":"0.8", "size":"103.8"}, {"price":"0.79", "size":"98.1"}, {"price":"0.78", "size":"97.5"}, {"price":"0.77", "size":"96.89"}, {"price":"0.76", "size":"201.39"}, {"price":"0.75", "size":"116"}, {"price":"0.74", "size":"100.6"}, {"price":"0.73", "size":"95.2"}, {"price":"0.72", "size":"94.9"}, {"price":"0.71", "size":"199.6"}, {"price":"0.7", "size":"94.3"}, {"price":"0.69", "size":"108.28"}, {"price":"0.68", "size":"98.8"}, {"price":"0.67", "size":"718.6"}, {"price":"0.66", "size":"798.4"}, {"price":"0.65", "size":"107.3"}, {"price":"0.64", "size":"293"}, {"price":"0.63", "size":"292.9"}, {"price":"0.62", "size":"897.7"}, {"price":"0.61", "size":"397.6"}, {"price":"0.6", "size":"356.93"}, {"price":"0.59", "size":"297.4"}, {"price":"0.58", "size":"109.6"}, {"price":"0.57", "size":"131.48"}, {"price":"0.56", "size":"413.97"}, {"price":"0.55", "size":"934.2"}, {"price":"0.54", "size":"375.6"}, {"price":"0.53", "size":"292"}, {"price":"0.52", "size":"297.12"}, {"price":"0.51", "size":"402"}, {"price":"0.5", "size":"340.91"}, {"price":"0.49", "size":"362"}, {"price":"0.48", "size":"317"}, {"price":"0.47", "size":"337"}, {"price":"0.46", "size":"607.1"}, {"price":"0.45", "size":"346.64"}, {"price":"0.44", "size":"332.45"}, {"price":"0.43", "size":"434.89"}, {"price":"0.42", "size":"324.36"}, {"price":"0.41", "size":"412.4"}, {"price":"0.4", "size":"328.83"}, {"price":"0.39", "size":"297.6"}, {"price":"0.38", "size":"626.5"}, {"price":"0.37", "size":"297.9"}, {"price":"0.36", "size":"208"}, {"price":"0.35", "size":"345.14"}, {"price":"0.34", "size":"360.9"}, {"price":"0.33", "size":"343.6"}, {"price":"0.32", "size":"2055.88"}, {"price":"0.31", "size":"439"}, {"price":"0.3", "size":"134.3"}, {"price":"0.29", "size":"316.38"}, {"price":"0.28", "size":"154.9"}, {"price":"0.27", "size":"180.2"}, {"price":"0.26", "size":"230.6"}, {"price":"0.25", "size":"331"}, {"price":"0.24", "size":"126.39"}, {"price":"0.23", "size":"121.89"}, {"price":"0.22", "size":"117.5"}, {"price":"0.21", "size":"175.44"}, {"price":"0.2", "size":"90"}, {"price":"0.19", "size":"72.35"}, {"price":"0.18", "size":"437.54"}], "hash":"276934e91ddf2608ebaae4d17707108899060c51", "timestamp":"1778784199631", "event_type":"book"}
{"market":"0x2a903c589141bce4a1e50fb98b73397af6820942542793ab10b1df477e912b6e", "price_changes":[{"asset_id":"68919878716222388542639225642064847629616106443780159680232863841946753372582", "price":"0.11", "size":"13.23", "side":"BUY", "hash":"50555f6e1ea24e89513e50b79efaabaa96106be6", "best_bid":"0.11", "best_ask":"0.18"}, {"asset_id":"20436996072316278452977393149218961565084965483366669504673105646378938504388", "price":"0.89", "size":"13.23", "side":"SELL", "hash":"c372fefeffbb67367a2205e69af72343ce9fa093", "best_bid":"0.82", "best_ask":"0.89"}], "timestamp":"1778784199660", "event_type":"price_change"}
